ts_recv,ts_event,rtype,publisher_id,instrument_id,action,side,price,size,channel_id,order_id,flags,ts_in_delta,sequence,symbol,depth,price,size,flags,ts_in_delta,sequence,bid_px_00,bid_sz_00,bid_ct_00,ask_px_00,ask_sz_00,ask_ct_00,bid_px_01,bid_sz_01,bid_ct_01,ask_px_01,ask_sz_01,ask_ct_01,bid_px_02,bid_sz_02,bid_ct_02,ask_px_02,ask_sz_02,ask_ct_02,bid_px_03,bid_sz_03,bid_ct_03,ask_px_03,ask_sz_03,ask_ct_03,bid_px_04,bid_sz_04,bid_ct_04,ask_px_04,ask_sz_04,ask_ct_04,bid_px_05,bid_sz_05,bid_ct_05,ask_px_05,ask_sz_05,ask_ct_05,bid_px_06,bid_sz_06,bid_ct_06,ask_px_06,ask_sz_06,ask_ct_06,bid_px_07,bid_sz_07,bid_ct_07,ask_px_07,ask_sz_07,ask_ct_07,bid_px_08,bid_sz_08,bid_ct_08,ask_px_08,ask_sz_08,ask_ct_08,bid_px_09,bid_sz_09,bid_ct_09,ask_px_09,ask_sz_09,ask_ct_09,symbol,order_id
2025-07-17T15:58:30.906412286Z,2025-07-17T15:58:30.906246950Z,160,2,1108,A,A,14.980000000,100,0,320839149,130,165336,267919540,ARL,0,14.98,100,130,165336,267919540,9.55,1700,17,9.68,100,1,10.61,200,2,11.27,100,1,11.4,100,1,11.76,100,1,11.93,200,2,12.23,100,1,12.34,200,2,12.36,200,2,13.89,15,1,13.9,100,1,14.1,2,1,14.26,100,1,14.28,100,1,14.4,100,1,14.56,800,2,14.6,700,1,14.68,1400,2,14.72,100,1,ARL,320839149
2025-07-17T15:58:30.916726353Z,2025-07-17T15:58:30.916561264Z,160,2,1108,C,A,14.260000000,100,0,320487025,130,165089,267919917,ARL,0,14.26,100,130,165089,267919917,9.55,1700,17,9.68,100,1,10.61,200,2,11.27,100,1,11.4,100,1,11.76,100,1,11.93,200,2,12.23,100,1,12.34,200,2,12.36,200,2,13.89,15,1,13.9,100,1,14.1,2,1,14.28,100,1,14.4,100,1,14.56,800,2,14.6,700,1,14.68,1400,2,14.72,100,1,14.87,100,1,ARL,320487025
2025-07-17T15:58:30.916784278Z,2025-07-17T15:58:30.916619122Z,160,2,1108,A,A,14.180000000,100,0,320839577,130,165156,267919919,ARL,0,14.18,100,130,165156,267919919,9.55,1700,17,9.68,100,1,10.61,200,2,11.27,100,1,11.4,100,1,11.76,100,1,11.93,200,2,12.23,100,1,12.34,200,2,12.36,200,2,13.89,15,1,13.9,100,1,14.1,2,1,14.18,100,1,14.28,100,1,14.4,100,1,14.56,800,2,14.6,700,1,14.68,1400,2,14.72,100,1,ARL,320839577
2025-07-17T15:58:31.124388717Z,2025-07-17T15:58:31.124222733Z,160,2,1108,C,A,14.870000000,100,0,320504473,0,165984,267925564,ARL,0,14.87,100,0,165984,267925564,9.55,1700,17,9.68,100,1,10.61,200,2,11.27,100,1,11.4,100,1,11.76,100,1,11.93,200,2,12.23,100,1,12.34,200,2,12.36,200,2,13.89,15,1,13.9,100,1,14.1,2,1,14.18,100,1,14.28,100,1,14.4,100,1,14.56,800,2,14.6,700,1,14.68,1400,2,14.72,100,1,ARL,320504473
2025-07-17T15:58:31.124388717Z,2025-07-17T15:58:31.124222733Z,160,2,1108,A,A,14.760000000,100,0,320845893,130,165984,267925564,ARL,0,14.76,100,130,165984,267925564,9.55,1700,17,9.68,100,1,10.61,200,2,11.27,100,1,11.4,100,1,11.76,100,1,11.93,200,2,12.23,100,1,12.34,200,2,12.36,200,2,13.89,15,1,13.9,100,1,14.1,2,1,14.18,100,1,14.28,100,1,14.4,100,1,14.56,800,2,14.6,700,1,14.68,1400,2,14.72,100,1,ARL,320845893
2025-07-17T15:58:31.136439248Z,2025-07-17T15:58:31.136273403Z,160,2,1108,C,A,14.880000000,100,0,320504609,0,165845,267925951,ARL,0,14.88,100,0,165845,267925951,9.55,1700,17,9.68,100,1,10.61,200,2,11.27,100,1,11.4,100,1,11.76,100,1,11.93,200,2,12.23,100,1,12.34,200,2,12.36,200,2,13.89,15,1,13.9,100,1,14.1,2,1,14.18,100,1,14.28,100,1,14.4,100,1,14.56,800,2,14.6,700,1,14.68,1400,2,14.72,100,1,ARL,320504609
2025-07-17T15:58:31.136439248Z,2025-07-17T15:58:31.136273403Z,160,2,1108,A,A,14.770000000,100,0,320846429,130,165845,267925951,ARL,0,14.77,100,130,165845,267925951,9.55,1700,17,9.68,100,1,10.61,200,2,11.27,100,1,11.4,100,1,11.76,100,1,11.93,200,2,12.23,100,1,12.34,200,2,12.36,200,2,13.89,15,1,13.9,100,1,14.1,2,1,14.18,100,1,14.28,100,1,14.4,100,1,14.56,800,2,14.6,700,1,14.68,1400,2,14.72,100,1,ARL,320846429
2025-07-17T15:58:40.799952243Z,2025-07-17T15:58:40.799787018Z,160,2,1108,A,A,13.830000000,15,0,321038033,130,165225,268074431,ARL,0,13.83,15,130,165225,268074431,9.55,1700,17,9.68,100,1,10.61,200,2,11.27,100,1,11.4,100,1,11.76,100,1,11.93,200,2,12.23,100,1,12.34,200,2,12.36,200,2,13.83,15,1,13.89,15,1,13.9,100,1,14.1,2,1,14.18,100,1,14.28,100,1,14.4,100,1,14.56,800,2,14.6,700,1,14.68,1400,2,ARL,321038033
2025-07-17T15:58:43.690244473Z,2025-07-17T15:58:43.690078924Z,160,2,1108,C,A,13.900000000,100,0,320839125,0,165549,268115228,ARL,0,13.9,100,0,165549,268115228,9.55,1700,17,9.68,100,1,10.61,200,2,11.27,100,1,11.4,100,1,11.76,100,1,11.93,200,2,12.23,100,1,12.34,200,2,12.36,200,2,13.83,15,1,13.89,15,1,14.1,2,1,14.18,100,1,14.28,100,1,14.4,100,1,14.56,800,2,14.6,700,1,14.68,1400,2,14.72,100,1,ARL,320839125
2025-07-17T15:58:43.690244473Z,2025-07-17T15:58:43.690078924Z,160,2,1108,A,A,13.840000000,100,0,321096769,130,165549,268115228,ARL,0,13.84,100,130,165549,268115228,9.55,1700,17,9.68,100,1,10.61,200,2,11.27,100,1,11.4,100,1,11.76,100,1,11.93,200,2,12.23,100,1,12.34,200,2,12.36,200,2,13.83,15,1,13.84,100,1,13.89,15,1,14.1,2,1,14.18,100,1,14.28,100,1,14.4,100,1,14.56,800,2,14.6,700,1,14.68,1400,2,ARL,321096769
2025-07-17T15:58:43.690988921Z,2025-07-17T15:58:43.690823184Z,160,2,1108,C,A,14.980000000,100,0,320839149,0,165737,268115235,ARL,0,14.98,100,0,165737,268115235,9.55,1700,17,9.68,100,1,10.61,200,2,11.27,100,1,11.4,100,1,11.76,100,1,11.93,200,2,12.23,100,1,12.34,200,2,12.36,200,2,13.83,15,1,13.84,100,1,13.89,15,1,14.1,2,1,14.18,100,1,14.28,100,1,14.4,100,1,14.56,800,2,14.6,700,1,14.68,1400,2,ARL,320839149
2025-07-17T15:58:43.690988921Z,2025-07-17T15:58:43.690823184Z,160,2,1108,A,A,14.910000000,100,0,321096793,130,165737,268115235,ARL,0,14.91,100,130,165737,268115235,9.55,1700,17,9.68,100,1,10.61,200,2,11.27,100,1,11.4,100,1,11.76,100,1,11.93,200,2,12.23,100,1,12.34,200,2,12.36,200,2,13.83,15,1,13.84,100,1,13.89,15,1,14.1,2,1,14.18,100,1,14.28,100,1,14.4,100,1,14.56,800,2,14.6,700,1,14.68,1400,2,ARL,321096793
2025-07-17T15:58:43.693394500Z,2025-07-17T15:58:43.693228946Z,160,2,1108,C,A,17.760000000,100,0,320486937,0,165554,268115265,ARL,0,17.76,100,0,165554,268115265,9.55,1700,17,9.68,100,1,10.61,200,2,11.27,100,1,11.4,100,1,11.76,100,1,11.93,200,2,12.23,100,1,12.34,200,2,12.36,200,2,13.83,15,1,13.84,100,1,13.89,15,1,14.1,2,1,14.18,100,1,14.28,100,1,14.4,100,1,14.56,800,2,14.6,700,1,14.68,1400,2,ARL,320486937
2025-07-17T15:58:43.693394500Z,2025-07-17T15:58:43.693228946Z,160,2,1108,A,A,17.580000000,100,0,321096825,130,165554,268115265,ARL,0,17.58,100,130,165554,268115265,9.55,1700,17,9.68,100,1,10.61,200,2,11.27,100,1,11.4,100,1,11.76,100,1,11.93,200,2,12.23,100,1,12.34,200,2,12.36,200,2,13.83,15,1,13.84,100,1,13.89,15,1,14.1,2,1,14.18,100,1,14.28,100,1,14.4,100,1,14.56,800,2,14.6,700,1,14.68,1400,2,ARL,321096825
2025-07-17T15:58:43.695055785Z,2025-07-17T15:58:43.694890264Z,160,2,1108,C,A,16.080000000,100,0,320486945,0,165521,268115287,ARL,0,16.08,100,0,165521,268115287,9.55,1700,17,9.68,100,1,10.61,200,2,11.27,100,1,11.4,100,1,11.76,100,1,11.93,200,2,12.23,100,1,12.34,200,2,12.36,200,2,13.83,15,1,13.84,100,1,13.89,15,1,14.1,2,1,14.18,100,1,14.28,100,1,14.4,100,1,14.56,800,2,14.6,700,1,14.68,1400,2,ARL,320486945
2025-07-17T15:58:43.695055785Z,2025-07-17T15:58:43.694890264Z,160,2,1108,A,A,15.920000000,100,0,321096889,130,165521,268115287,ARL,0,15.92,100,130,165521,268115287,9.55,1700,17,9.68,100,1,10.61,200,2,11.27,100,1,11.4,100,1,11.76,100,1,11.93,200,2,12.23,100,1,12.34,200,2,12.36,200,2,13.83,15,1,13.84,100,1,13.89,15,1,14.1,2,1,14.18,100,1,14.28,100,1,14.4,100,1,14.56,800,2,14.6,700,1,14.68,1400,2,ARL,321096889
2025-07-17T15:58:43.716437124Z,2025-07-17T15:58:43.716271172Z,160,2,1108,C,A,14.960000000,100,0,320487105,0,165952,268115456,ARL,0,14.96,100,0,165952,268115456,9.55,1700,17,9.68,100,1,10.61,200,2,11.27,100,1,11.4,100,1,11.76,100,1,11.93,200,2,12.23,100,1,12.34,200,2,12.36,200,2,13.83,15,1,13.84,100,1,13.89,15,1,14.1,2,1,14.18,100,1,14.28,100,1,14.4,100,1,14.56,800,2,14.6,700,1,14.68,1400,2,ARL,320487105
2025-07-17T15:58:43.716437124Z,2025-07-17T15:58:43.716271172Z,160,2,1108,A,A,14.810000000,100,0,321097197,130,165952,268115456,ARL,0,14.81,100,130,165952,268115456,9.55,1700,17,9.68,100,1,10.61,200,2,11.27,100,1,11.4,100,1,11.76,100,1,11.93,200,2,12.23,100,1,12.34,200,2,12.36,200,2,13.83,15,1,13.84,100,1,13.89,15,1,14.1,2,1,14.18,100,1,14.28,100,1,14.4,100,1,14.56,800,2,14.6,700,1,14.68,1400,2,ARL,321097197
2025-07-17T15:58:44.903740109Z,2025-07-17T15:58:44.903574654Z,160,2,1108,A,A,13.830000000,100,0,321114473,130,165455,268129040,ARL,0,13.83,100,130,165455,268129040,9.55,1700,17,9.68,100,1,10.61,200,2,11.27,100,1,11.4,100,1,11.76,100,1,11.93,200,2,12.23,100,1,12.34,200,2,12.36,200,2,13.83,115,2,13.84,100,1,13.89,15,1,14.1,2,1,14.18,100,1,14.28,100,1,14.4,100,1,14.56,800,2,14.6,700,1,14.68,1400,2,ARL,321114473
2025-07-17T15:58:44.924114268Z,2025-07-17T15:58:44.923948853Z,160,2,1108,C,A,14.180000000,100,0,320839577,130,165415,268129217,ARL,0,14.18,100,130,165415,268129217,9.55,1700,17,9.68,100,1,10.61,200,2,11.27,100,1,11.4,100,1,11.76,100,1,11.93,200,2,12.23,100,1,12.34,200,2,12.36,200,2,13.83,115,2,13.84,100,1,13.89,15,1,14.1,2,1,14.28,100,1,14.4,100,1,14.56,800,2,14.6,700,1,14.68,1400,2,14.72,100,1,ARL,320839577
2025-07-17T15:58:44.924165875Z,2025-07-17T15:58:44.924000519Z,160,2,1108,A,A,14.110000000,100,0,321114729,130,165356,268129218,ARL,0,14.11,100,130,165356,268129218,9.55,1700,17,9.68,100,1,10.61,200,2,11.27,100,1,11.4,100,1,11.76,100,1,11.93,200,2,12.23,100,1,12.34,200,2,12.36,200,2,13.83,115,2,13.84,100,1,13.89,15,1,14.1,2,1,14.11,100,1,14.28,100,1,14.4,100,1,14.56,800,2,14.6,700,1,14.68,1400,2,ARL,321114729
2025-07-17T15:58:51.241342265Z,2025-07-17T15:58:51.241176997Z,160,2,1108,C,A,13.890000000,15,0,320833897,130,165268,268212338,ARL,0,13.89,15,130,165268,268212338,9.55,1700,17,9.68,100,1,10.61,200,2,11.27,100,1,11.4,100,1,11.76,100,1,11.93,200,2,12.23,100,1,12.34,200,2,12.36,200,2,13.83,115,2,13.84,100,1,14.1,2,1,14.11,100,1,14.28,100,1,14.4,100,1,14.56,800,2,14.6,700,1,14.68,1400,2,14.72,100,1,ARL,320833897
2025-07-17T15:58:51.254127339Z,2025-07-17T15:58:51.253961905Z,160,2,1108,A,A,13.800000000,100,0,321225725,130,165434,268212497,ARL,0,13.8,100,130,165434,268212497,9.55,1700,17,9.68,100,1,10.61,200,2,11.27,100,1,11.4,100,1,11.76,100,1,11.93,200,2,12.23,100,1,12.34,200,2,12.36,200,2,13.8,100,1,13.83,115,2,13.84,100,1,14.1,2,1,14.11,100,1,14.28,100,1,14.4,100,1,14.56,800,2,14.6,700,1,14.68,1400,2,ARL,321225725
2025-07-17T15:58:51.254871890Z,2025-07-17T15:58:51.254706004Z,160,2,1108,C,A,14.910000000,100,0,321096793,0,165886,268212499,ARL,0,14.91,100,0,165886,268212499,9.55,1700,17,9.68,100,1,10.61,200,2,11.27,100,1,11.4,100,1,11.76,100,1,11.93,200,2,12.23,100,1,12.34,200,2,12.36,200,2,13.8,100,1,13.83,115,2,13.84,100,1,14.1,2,1,14.11,100,1,14.28,100,1,14.4,100,1,14.56,800,2,14.6,700,1,14.68,1400,2,ARL,321096793
2025-07-17T15:58:51.254871890Z,2025-07-17T15:58:51.254706004Z,160,2,1108,A,A,14.870000000,100,0,321225745,130,165886,268212499,ARL,0,14.87,100,130,165886,268212499,9.55,1700,17,9.68,100,1,10.61,200,2,11.27,100,1,11.4,100,1,11.76,100,1,11.93,200,2,12.23,100,1,12.34,200,2,12.36,200,2,13.8,100,1,13.83,115,2,13.84,100,1,14.1,2,1,14.11,100,1,14.28,100,1,14.4,100,1,14.56,800,2,14.6,700,1,14.68,1400,2,ARL,321225745
2025-07-17T15:58:51.260753179Z,2025-07-17T15:58:51.260587778Z,160,2,1108,C,A,13.830000000,100,0,321114473,130,165401,268212534,ARL,0,13.83,100,130,165401,268212534,9.55,1700,17,9.68,100,1,10.61,200,2,11.27,100,1,11.4,100,1,11.76,100,1,11.93,200,2,12.23,100,1,12.34,200,2,12.36,200,2,13.8,100,1,13.83,15,1,13.84,100,1,14.1,2,1,14.11,100,1,14.28,100,1,14.4,100,1,14.56,800,2,14.6,700,1,14.68,1400,2,ARL,321114473
2025-07-17T15:58:53.579628288Z,2025-07-17T15:58:53.579462029Z,160,2,1108,C,A,13.830000000,15,0,321038033,130,166259,268250290,ARL,0,13.83,15,130,166259,268250290,9.55,1700,17,9.68,100,1,10.61,200,2,11.27,100,1,11.4,100,1,11.76,100,1,11.93,200,2,12.23,100,1,12.34,200,2,12.36,200,2,13.8,100,1,13.84,100,1,14.1,2,1,14.11,100,1,14.28,100,1,14.4,100,1,14.56,800,2,14.6,700,1,14.68,1400,2,14.72,100,1,ARL,321038033
2025-07-17T15:58:53.580217445Z,2025-07-17T15:58:53.580052014Z,160,2,1108,C,A,13.840000000,100,0,321096769,0,165431,268250346,ARL,0,13.84,100,0,165431,268250346,9.55,1700,17,9.68,100,1,10.61,200,2,11.27,100,1,11.4,100,1,11.76,100,1,11.93,200,2,12.23,100,1,12.34,200,2,12.36,200,2,13.8,100,1,14.1,2,1,14.11,100,1,14.28,100,1,14.4,100,1,14.56,800,2,14.6,700,1,14.68,1400,2,14.72,100,1,14.76,100,1,ARL,321096769
2025-07-17T15:58:53.580217445Z,2025-07-17T15:58:53.580052014Z,160,2,1108,A,A,13.810000000,100,0,321272581,130,165431,268250346,ARL,0,13.81,100,130,165431,268250346,9.55,1700,17,9.68,100,1,10.61,200,2,11.27,100,1,11.4,100,1,11.76,100,1,11.93,200,2,12.23,100,1,12.34,200,2,12.36,200,2,13.8,100,1,13.81,100,1,14.1,2,1,14.11,100,1,14.28,100,1,14.4,100,1,14.56,800,2,14.6,700,1,14.68,1400,2,14.72,100,1,ARL,321272581
2025-07-17T15:58:54.584124215Z,2025-07-17T15:58:54.583958582Z,160,2,1108,C,A,14.770000000,100,0,320846429,0,165633,268265585,ARL,0,14.77,100,0,165633,268265585,9.55,1700,17,9.68,100,1,10.61,200,2,11.27,100,1,11.4,100,1,11.76,100,1,11.93,200,2,12.23,100,1,12.34,200,2,12.36,200,2,13.8,100,1,13.81,100,1,14.1,2,1,14.11,100,1,14.28,100,1,14.4,100,1,14.56,800,2,14.6,700,1,14.68,1400,2,14.72,100,1,ARL,320846429
2025-07-17T15:58:54.584124215Z,2025-07-17T15:58:54.583958582Z,160,2,1108,A,A,14.650000000,100,0,321293737,130,165633,268265585,ARL,0,14.65,100,130,165633,268265585,9.55,1700,17,9.68,100,1,10.61,200,2,11.27,100,1,11.4,100,1,11.76,100,1,11.93,200,2,12.23,100,1,12.34,200,2,12.36,200,2,13.8,100,1,13.81,100,1,14.1,2,1,14.11,100,1,14.28,100,1,14.4,100,1,14.56,800,2,14.6,700,1,14.65,100,1,14.68,1400,2,ARL,321293737
2025-07-17T15:58:54.584260712Z,2025-07-17T15:58:54.584094980Z,160,2,1108,C,A,14.760000000,100,0,320845893,0,165732,268265586,ARL,0,14.76,100,0,165732,268265586,9.55,1700,17,9.68,100,1,10.61,200,2,11.27,100,1,11.4,100,1,11.76,100,1,11.93,200,2,12.23,100,1,12.34,200,2,12.36,200,2,13.8,100,1,13.81,100,1,14.1,2,1,14.11,100,1,14.28,100,1,14.4,100,1,14.56,800,2,14.6,700,1,14.65,100,1,14.68,1400,2,ARL,320845893
2025-07-17T15:58:54.584260712Z,2025-07-17T15:58:54.584094980Z,160,2,1108,A,A,14.640000000,100,0,321293741,130,165732,268265586,ARL,0,14.64,100,130,165732,268265586,9.55,1700,17,9.68,100,1,10.61,200,2,11.27,100,1,11.4,100,1,11.76,100,1,11.93,200,2,12.23,100,1,12.34,200,2,12.36,200,2,13.8,100,1,13.81,100,1,14.1,2,1,14.11,100,1,14.28,100,1,14.4,100,1,14.56,800,2,14.6,700,1,14.64,100,1,14.65,100,1,ARL,321293741
2025-07-17T15:58:55.305104029Z,2025-07-17T15:58:55.304938318Z,160,2,1108,A,A,13.780000000,100,0,321309865,130,165711,268277940,ARL,0,13.78,100,130,165711,268277940,9.55,1700,17,9.68,100,1,10.61,200,2,11.27,100,1,11.4,100,1,11.76,100,1,11.93,200,2,12.23,100,1,12.34,200,2,12.36,200,2,13.78,100,1,13.8,100,1,13.81,100,1,14.1,2,1,14.11,100,1,14.28,100,1,14.4,100,1,14.56,800,2,14.6,700,1,14.64,100,1,ARL,321309865
2025-07-17T15:58:55.307508305Z,2025-07-17T15:58:55.307342971Z,160,2,1108,C,A,14.720000000,100,0,312772061,130,165334,268277999,ARL,0,14.72,100,130,165334,268277999,9.55,1700,17,9.68,100,1,10.61,200,2,11.27,100,1,11.4,100,1,11.76,100,1,11.93,200,2,12.23,100,1,12.34,200,2,12.36,200,2,13.78,100,1,13.8,100,1,13.81,100,1,14.1,2,1,14.11,100,1,14.28,100,1,14.4,100,1,14.56,800,2,14.6,700,1,14.64,100,1,ARL,312772061
2025-07-17T15:58:55.307637209Z,2025-07-17T15:58:55.307472032Z,160,2,1108,A,A,14.580000000,100,0,321309941,130,165177,268278004,ARL,0,14.58,100,130,165177,268278004,9.55,1700,17,9.68,100,1,10.61,200,2,11.27,100,1,11.4,100,1,11.76,100,1,11.93,200,2,12.23,100,1,12.34,200,2,12.36,200,2,13.78,100,1,13.8,100,1,13.81,100,1,14.1,2,1,14.11,100,1,14.28,100,1,14.4,100,1,14.56,800,2,14.58,100,1,14.6,700,1,ARL,321309941
2025-07-17T15:58:55.311899965Z,2025-07-17T15:58:55.311734700Z,160,2,1108,C,A,13.800000000,100,0,321225725,130,165265,268278030,ARL,0,13.8,100,130,165265,268278030,9.55,1700,17,9.68,100,1,10.61,200,2,11.27,100,1,11.4,100,1,11.76,100,1,11.93,200,2,12.23,100,1,12.34,200,2,12.36,200,2,13.78,100,1,13.81,100,1,14.1,2,1,14.11,100,1,14.28,100,1,14.4,100,1,14.56,800,2,14.58,100,1,14.6,700,1,14.64,100,1,ARL,321225725
2025-07-17T15:58:58.668252306Z,2025-07-17T15:58:58.668086788Z,160,2,1108,C,A,13.810000000,100,0,321272581,0,165518,268321684,ARL,0,13.81,100,0,165518,268321684,9.55,1700,17,9.68,100,1,10.61,200,2,11.27,100,1,11.4,100,1,11.76,100,1,11.93,200,2,12.23,100,1,12.34,200,2,12.36,200,2,13.78,100,1,14.1,2,1,14.11,100,1,14.28,100,1,14.4,100,1,14.56,800,2,14.58,100,1,14.6,700,1,14.64,100,1,14.65,100,1,ARL,321272581
2025-07-17T15:58:58.668252306Z,2025-07-17T15:58:58.668086788Z,160,2,1108,A,A,13.790000000,100,0,321364281,130,165518,268321684,ARL,0,13.79,100,130,165518,268321684,9.55,1700,17,9.68,100,1,10.61,200,2,11.27,100,1,11.4,100,1,11.76,100,1,11.93,200,2,12.23,100,1,12.34,200,2,12.36,200,2,13.78,100,1,13.79,100,1,14.1,2,1,14.11,100,1,14.28,100,1,14.4,100,1,14.56,800,2,14.58,100,1,14.6,700,1,14.64,100,1,ARL,321364281
2025-07-17T15:59:03.613692913Z,2025-07-17T15:59:03.613527621Z,160,2,1108,A,A,13.720000000,15,0,321500117,130,165292,268437919,ARL,0,13.72,15,130,165292,268437919,9.55,1700,17,9.68,100,1,10.61,200,2,11.27,100,1,11.4,100,1,11.76,100,1,11.93,200,2,12.23,100,1,12.34,200,2,12.36,200,2,13.72,15,1,13.78,100,1,13.79,100,1,14.1,2,1,14.11,100,1,14.28,100,1,14.4,100,1,14.56,800,2,14.58,100,1,14.6,700,1,ARL,321500117
2025-07-17T15:59:03.626346616Z,2025-07-17T15:59:03.626181384Z,160,2,1108,A,A,13.760000000,100,0,321500317,130,165232,268438110,ARL,0,13.76,100,130,165232,268438110,9.55,1700,17,9.68,100,1,10.61,200,2,11.27,100,1,11.4,100,1,11.76,100,1,11.93,200,2,12.23,100,1,12.34,200,2,12.36,200,2,13.72,15,1,13.76,100,1,13.78,100,1,13.79,100,1,14.1,2,1,14.11,100,1,14.28,100,1,14.4,100,1,14.56,800,2,14.58,100,1,ARL,321500317
2025-07-17T15:59:03.627086888Z,2025-07-17T15:59:03.626920954Z,160,2,1108,C,A,14.870000000,100,0,321225745,0,165934,268438112,ARL,0,14.87,100,0,165934,268438112,9.55,1700,17,9.68,100,1,10.61,200,2,11.27,100,1,11.4,100,1,11.76,100,1,11.93,200,2,12.23,100,1,12.34,200,2,12.36,200,2,13.72,15,1,13.76,100,1,13.78,100,1,13.79,100,1,14.1,2,1,14.11,100,1,14.28,100,1,14.4,100,1,14.56,800,2,14.58,100,1,ARL,321225745
2025-07-17T15:59:03.627086888Z,2025-07-17T15:59:03.626920954Z,160,2,1108,A,A,14.830000000,100,0,321500333,130,165934,268438112,ARL,0,14.83,100,130,165934,268438112,9.55,1700,17,9.68,100,1,10.61,200,2,11.27,100,1,11.4,100,1,11.76,100,1,11.93,200,2,12.23,100,1,12.34,200,2,12.36,200,2,13.72,15,1,13.76,100,1,13.78,100,1,13.79,100,1,14.1,2,1,14.11,100,1,14.28,100,1,14.4,100,1,14.56,800,2,14.58,100,1,ARL,321500333
2025-07-17T15:59:03.628945278Z,2025-07-17T15:59:03.628779364Z,160,2,1108,C,A,14.890000000,100,0,312771785,0,165914,268438129,ARL,0,14.89,100,0,165914,268438129,9.55,1700,17,9.68,100,1,10.61,200,2,11.27,100,1,11.4,100,1,11.76,100,1,11.93,200,2,12.23,100,1,12.34,200,2,12.36,200,2,13.72,15,1,13.76,100,1,13.78,100,1,13.79,100,1,14.1,2,1,14.11,100,1,14.28,100,1,14.4,100,1,14.56,800,2,14.58,100,1,ARL,312771785
2025-07-17T15:59:03.628945278Z,2025-07-17T15:59:03.628779364Z,160,2,1108,A,A,14.730000000,100,0,321500349,130,165914,268438129,ARL,0,14.73,100,130,165914,268438129,9.55,1700,17,9.68,100,1,10.61,200,2,11.27,100,1,11.4,100,1,11.76,100,1,11.93,200,2,12.23,100,1,12.34,200,2,12.36,200,2,13.72,15,1,13.76,100,1,13.78,100,1,13.79,100,1,14.1,2,1,14.11,100,1,14.28,100,1,14.4,100,1,14.56,800,2,14.58,100,1,ARL,321500349
2025-07-17T15:59:03.633093258Z,2025-07-17T15:59:03.632928023Z,160,2,1108,C,A,13.780000000,100,0,321309865,130,165235,268438149,ARL,0,13.78,100,130,165235,268438149,9.55,1700,17,9.68,100,1,10.61,200,2,11.27,100,1,11.4,100,1,11.76,100,1,11.93,200,2,12.23,100,1,12.34,200,2,12.36,200,2,13.72,15,1,13.76,100,1,13.79,100,1,14.1,2,1,14.11,100,1,14.28,100,1,14.4,100,1,14.56,800,2,14.58,100,1,14.6,700,1,ARL,321309865
2025-07-17T15:59:03.649282063Z,2025-07-17T15:59:03.649116452Z,160,2,1108,C,A,14.110000000,100,0,321114729,130,165611,268438330,ARL,0,14.11,100,130,165611,268438330,9.55,1700,17,9.68,100,1,10.61,200,2,11.27,100,1,11.4,100,1,11.76,100,1,11.93,200,2,12.23,100,1,12.34,200,2,12.36,200,2,13.72,15,1,13.76,100,1,13.79,100,1,14.1,2,1,14.28,100,1,14.4,100,1,14.56,800,2,14.58,100,1,14.6,700,1,14.64,100,1,ARL,321114729
2025-07-17T15:59:03.649332873Z,2025-07-17T15:59:03.649167617Z,160,2,1108,A,A,14.040000000,100,0,321500957,130,165256,268438331,ARL,0,14.04,100,130,165256,268438331,9.55,1700,17,9.68,100,1,10.61,200,2,11.27,100,1,11.4,100,1,11.76,100,1,11.93,200,2,12.23,100,1,12.34,200,2,12.36,200,2,13.72,15,1,13.76,100,1,13.79,100,1,14.04,100,1,14.1,2,1,14.28,100,1,14.4,100,1,14.56,800,2,14.58,100,1,14.6,700,1,ARL,321500957
2025-07-17T15:59:04.224000805Z,2025-07-17T15:59:04.223835151Z,160,2,1108,C,A,13.790000000,100,0,321364281,0,165654,268447989,ARL,0,13.79,100,0,165654,268447989,9.55,1700,17,9.68,100,1,10.61,200,2,11.27,100,1,11.4,100,1,11.76,100,1,11.93,200,2,12.23,100,1,12.34,200,2,12.36,200,2,13.72,15,1,13.76,100,1,14.04,100,1,14.1,2,1,14.28,100,1,14.4,100,1,14.56,800,2,14.58,100,1,14.6,700,1,14.64,100,1,ARL,321364281
2025-07-17T15:59:04.224000805Z,2025-07-17T15:59:04.223835151Z,160,2,1108,A,A,13.730000000,100,0,321511377,130,165654,268447989,ARL,0,13.73,100,130,165654,268447989,9.55,1700,17,9.68,100,1,10.61,200,2,11.27,100,1,11.4,100,1,11.76,100,1,11.93,200,2,12.23,100,1,12.34,200,2,12.36,200,2,13.72,15,1,13.73,100,1,13.76,100,1,14.04,100,1,14.1,2,1,14.28,100,1,14.4,100,1,14.56,800,2,14.58,100,1,14.6,700,1,ARL,321511377
2025-07-17T15:59:04.224749333Z,2025-07-17T15:59:04.224583946Z,160,2,1108,C,A,14.830000000,100,0,321500333,0,165387,268448014,ARL,0,14.83,100,0,165387,268448014,9.55,1700,17,9.68,100,1,10.61,200,2,11.27,100,1,11.4,100,1,11.76,100,1,11.93,200,2,12.23,100,1,12.34,200,2,12.36,200,2,13.72,15,1,13.73,100,1,13.76,100,1,14.04,100,1,14.1,2,1,14.28,100,1,14.4,100,1,14.56,800,2,14.58,100,1,14.6,700,1,ARL,321500333
2025-07-17T15:59:04.224749333Z,2025-07-17T15:59:04.224583946Z,160,2,1108,A,A,14.790000000,100,0,321511477,130,165387,268448014,ARL,0,14.79,100,130,165387,268448014,9.55,1700,17,9.68,100,1,10.61,200,2,11.27,100,1,11.4,100,1,11.76,100,1,11.93,200,2,12.23,100,1,12.34,200,2,12.36,200,2,13.72,15,1,13.73,100,1,13.76,100,1,14.04,100,1,14.1,2,1,14.28,100,1,14.4,100,1,14.56,800,2,14.58,100,1,14.6,700,1,ARL,321511477
2025-07-17T15:59:04.799998642Z,2025-07-17T15:59:04.799833206Z,160,2,1108,C,A,13.720000000,15,0,321500117,130,165436,268457531,ARL,0,13.72,15,130,165436,268457531,9.55,1700,17,9.68,100,1,10.61,200,2,11.27,100,1,11.4,100,1,11.76,100,1,11.93,200,2,12.23,100,1,12.34,200,2,12.36,200,2,13.73,100,1,13.76,100,1,14.04,100,1,14.1,2,1,14.28,100,1,14.4,100,1,14.56,800,2,14.58,100,1,14.6,700,1,14.64,100,1,ARL,321500117
2025-07-17T16:00:13.989937414Z,2025-07-17T16:00:13.989771852Z,160,2,1108,C,A,14.100000000,2,0,316098525,0,165562,269514876,ARL,0,14.1,2,0,165562,269514876,9.55,1700,17,9.68,100,1,10.61,200,2,11.27,100,1,11.4,100,1,11.76,100,1,11.93,200,2,12.23,100,1,12.34,200,2,12.36,200,2,13.73,100,1,13.76,100,1,14.04,100,1,14.28,100,1,14.4,100,1,14.56,800,2,14.58,100,1,14.6,700,1,14.64,100,1,14.65,100,1,ARL,316098525
2025-07-17T16:00:13.989937414Z,2025-07-17T16:00:13.989771852Z,160,2,1108,A,A,14.010000000,2,0,322898193,130,165562,269514876,ARL,0,14.01,2,130,165562,269514876,9.55,1700,17,9.68,100,1,10.61,200,2,11.27,100,1,11.4,100,1,11.76,100,1,11.93,200,2,12.23,100,1,12.34,200,2,12.36,200,2,13.73,100,1,13.76,100,1,14.01,2,1,14.04,100,1,14.28,100,1,14.4,100,1,14.56,800,2,14.58,100,1,14.6,700,1,14.64,100,1,ARL,322898193
2025-07-17T16:00:28.803015930Z,2025-07-17T16:00:28.802849928Z,160,2,1108,A,A,13.720000000,15,0,323238809,130,166002,269765653,ARL,0,13.72,15,130,166002,269765653,9.55,1700,17,9.68,100,1,10.61,200,2,11.27,100,1,11.4,100,1,11.76,100,1,11.93,200,2,12.23,100,1,12.34,200,2,12.36,200,2,13.72,15,1,13.73,100,1,13.76,100,1,14.01,2,1,14.04,100,1,14.28,100,1,14.4,100,1,14.56,800,2,14.58,100,1,14.6,700,1,ARL,323238809
2025-07-17T16:00:32.549412616Z,2025-07-17T16:00:32.549247168Z,160,2,1108,A,A,13.740000000,100,0,323370569,130,165448,269878282,ARL,0,13.74,100,130,165448,269878282,9.55,1700,17,9.68,100,1,10.61,200,2,11.27,100,1,11.4,100,1,11.76,100,1,11.93,200,2,12.23,100,1,12.34,200,2,12.36,200,2,13.72,15,1,13.73,100,1,13.74,100,1,13.76,100,1,14.01,2,1,14.04,100,1,14.28,100,1,14.4,100,1,14.56,800,2,14.58,100,1,ARL,323370569
2025-07-17T16:00:32.560989093Z,2025-07-17T16:00:32.560823786Z,160,2,1108,C,A,13.760000000,100,0,321500317,130,165307,269878639,ARL,0,13.76,100,130,165307,269878639,9.55,1700,17,9.68,100,1,10.61,200,2,11.27,100,1,11.4,100,1,11.76,100,1,11.93,200,2,12.23,100,1,12.34,200,2,12.36,200,2,13.72,15,1,13.73,100,1,13.74,100,1,14.01,2,1,14.04,100,1,14.28,100,1,14.4,100,1,14.56,800,2,14.58,100,1,14.6,700,1,ARL,321500317
2025-07-17T16:00:35.513164458Z,2025-07-17T16:00:35.512999155Z,160,2,1108,A,A,13.690000000,15,0,323455221,130,165303,269940539,ARL,0,13.69,15,130,165303,269940539,9.55,1700,17,9.68,100,1,10.61,200,2,11.27,100,1,11.4,100,1,11.76,100,1,11.93,200,2,12.23,100,1,12.34,200,2,12.36,200,2,13.69,15,1,13.72,15,1,13.73,100,1,13.74,100,1,14.01,2,1,14.04,100,1,14.28,100,1,14.4,100,1,14.56,800,2,14.58,100,1,ARL,323455221
2025-07-17T16:00:42.614229184Z,2025-07-17T16:00:42.614063415Z,160,2,1108,C,A,13.730000000,100,0,321511377,0,165769,270051089,ARL,0,13.73,100,0,165769,270051089,9.55,1700,17,9.68,100,1,10.61,200,2,11.27,100,1,11.4,100,1,11.76,100,1,11.93,200,2,12.23,100,1,12.34,200,2,12.36,200,2,13.69,15,1,13.72,15,1,13.74,100,1,14.01,2,1,14.04,100,1,14.28,100,1,14.4,100,1,14.56,800,2,14.58,100,1,14.6,700,1,ARL,321511377
2025-07-17T16:00:42.614229184Z,2025-07-17T16:00:42.614063415Z,160,2,1108,A,A,13.700000000,100,0,323599605,130,165769,270051089,ARL,0,13.7,100,130,165769,270051089,9.55,1700,17,9.68,100,1,10.61,200,2,11.27,100,1,11.4,100,1,11.76,100,1,11.93,200,2,12.23,100,1,12.34,200,2,12.36,200,2,13.69,15,1,13.7,100,1,13.72,15,1,13.74,100,1,14.01,2,1,14.04,100,1,14.28,100,1,14.4,100,1,14.56,800,2,14.58,100,1,ARL,323599605
2025-07-17T16:00:42.614254199Z,2025-07-17T16:00:42.614088947Z,160,2,1108,A,A,13.720000000,100,0,323599609,130,165252,270051090,ARL,0,13.72,100,130,165252,270051090,9.55,1700,17,9.68,100,1,10.61,200,2,11.27,100,1,11.4,100,1,11.76,100,1,11.93,200,2,12.23,100,1,12.34,200,2,12.36,200,2,13.69,15,1,13.7,100,1,13.72,115,2,13.74,100,1,14.01,2,1,14.04,100,1,14.28,100,1,14.4,100,1,14.56,800,2,14.58,100,1,ARL,323599609
2025-07-17T16:00:42.614396214Z,2025-07-17T16:00:42.614231125Z,160,2,1108,C,A,13.740000000,100,0,323370569,130,165089,270051092,ARL,0,13.74,100,130,165089,270051092,9.55,1700,17,9.68,100,1,10.61,200,2,11.27,100,1,11.4,100,1,11.76,100,1,11.93,200,2,12.23,100,1,12.34,200,2,12.36,200,2,13.69,15,1,13.7,100,1,13.72,115,2,14.01,2,1,14.04,100,1,14.28,100,1,14.4,100,1,14.56,800,2,14.58,100,1,14.6,700,1,ARL,323370569
2025-07-17T16:00:42.616178962Z,2025-07-17T16:00:42.616013371Z,160,2,1108,C,A,14.810000000,100,0,321097197,0,165591,270051093,ARL,0,14.81,100,0,165591,270051093,9.55,1700,17,9.68,100,1,10.61,200,2,11.27,100,1,11.4,100,1,11.76,100,1,11.93,200,2,12.23,100,1,12.34,200,2,12.36,200,2,13.69,15,1,13.7,100,1,13.72,115,2,14.01,2,1,14.04,100,1,14.28,100,1,14.4,100,1,14.56,800,2,14.58,100,1,14.6,700,1,ARL,321097197
2025-07-17T16:00:42.616178962Z,2025-07-17T16:00:42.616013371Z,160,2,1108,A,A,14.660000000,100,0,323599625,130,165591,270051093,ARL,0,14.66,100,130,165591,270051093,9.55,1700,17,9.68,100,1,10.61,200,2,11.27,100,1,11.4,100,1,11.76,100,1,11.93,200,2,12.23,100,1,12.34,200,2,12.36,200,2,13.69,15,1,13.7,100,1,13.72,115,2,14.01,2,1,14.04,100,1,14.28,100,1,14.4,100,1,14.56,800,2,14.58,100,1,14.6,700,1,ARL,323599625
2025-07-17T16:00:42.616321879Z,2025-07-17T16:00:42.616156310Z,160,2,1108,C,A,15.920000000,100,0,321096889,0,165569,270051094,ARL,0,15.92,100,0,165569,270051094,9.55,1700,17,9.68,100,1,10.61,200,2,11.27,100,1,11.4,100,1,11.76,100,1,11.93,200,2,12.23,100,1,12.34,200,2,12.36,200,2,13.69,15,1,13.7,100,1,13.72,115,2,14.01,2,1,14.04,100,1,14.28,100,1,14.4,100,1,14.56,800,2,14.58,100,1,14.6,700,1,ARL,321096889
2025-07-17T16:00:42.616321879Z,2025-07-17T16:00:42.616156310Z,160,2,1108,A,A,15.760000000,100,0,323599629,130,165569,270051094,ARL,0,15.76,100,130,165569,270051094,9.55,1700,17,9.68,100,1,10.61,200,2,11.27,100,1,11.4,100,1,11.76,100,1,11.93,200,2,12.23,100,1,12.34,200,2,12.36,200,2,13.69,15,1,13.7,100,1,13.72,115,2,14.01,2,1,14.04,100,1,14.28,100,1,14.4,100,1,14.56,800,2,14.58,100,1,14.6,700,1,ARL,323599629
2025-07-17T16:00:42.616352247Z,2025-07-17T16:00:42.616186901Z,160,2,1108,C,A,17.580000000,100,0,321096825,0,165346,270051095,ARL,0,17.58,100,0,165346,270051095,9.55,1700,17,9.68,100,1,10.61,200,2,11.27,100,1,11.4,100,1,11.76,100,1,11.93,200,2,12.23,100,1,12.34,200,2,12.36,200,2,13.69,15,1,13.7,100,1,13.72,115,2,14.01,2,1,14.04,100,1,14.28,100,1,14.4,100,1,14.56,800,2,14.58,100,1,14.6,700,1,ARL,321096825
2025-07-17T16:00:42.616352247Z,2025-07-17T16:00:42.616186901Z,160,2,1108,A,A,17.400000000,100,0,323599633,130,165346,270051095,ARL,0,17.4,100,130,165346,270051095,9.55,1700,17,9.68,100,1,10.61,200,2,11.27,100,1,11.4,100,1,11.76,100,1,11.93,200,2,12.23,100,1,12.34,200,2,12.36,200,2,13.69,15,1,13.7,100,1,13.72,115,2,14.01,2,1,14.04,100,1,14.28,100,1,14.4,100,1,14.56,800,2,14.58,100,1,14.6,700,1,ARL,323599633
2025-07-17T16:00:42.636761176Z,2025-07-17T16:00:42.636595817Z,160,2,1108,C,A,14.040000000,100,0,321500957,130,165359,270051179,ARL,0,14.04,100,130,165359,270051179,9.55,1700,17,9.68,100,1,10.61,200,2,11.27,100,1,11.4,100,1,11.76,100,1,11.93,200,2,12.23,100,1,12.34,200,2,12.36,200,2,13.69,15,1,13.7,100,1,13.72,115,2,14.01,2,1,14.28,100,1,14.4,100,1,14.56,800,2,14.58,100,1,14.6,700,1,14.64,100,1,ARL,321500957
2025-07-17T16:00:42.636814704Z,2025-07-17T16:00:42.636649389Z,160,2,1108,A,A,13.970000000,100,0,323599765,130,165315,270051181,ARL,0,13.97,100,130,165315,270051181,9.55,1700,17,9.68,100,1,10.61,200,2,11.27,100,1,11.4,100,1,11.76,100,1,11.93,200,2,12.23,100,1,12.34,200,2,12.36,200,2,13.69,15,1,13.7,100,1,13.72,115,2,13.97,100,1,14.01,2,1,14.28,100,1,14.4,100,1,14.56,800,2,14.58,100,1,14.6,700,1,ARL,323599765
2025-07-17T16:00:46.803262460Z,2025-07-17T16:00:46.803097192Z,160,2,1108,C,A,13.720000000,15,0,323238809,130,165268,270102799,ARL,0,13.72,15,130,165268,270102799,9.55,1700,17,9.68,100,1,10.61,200,2,11.27,100,1,11.4,100,1,11.76,100,1,11.93,200,2,12.23,100,1,12.34,200,2,12.36,200,2,13.69,15,1,13.7,100,1,13.72,100,1,13.97,100,1,14.01,2,1,14.28,100,1,14.4,100,1,14.56,800,2,14.58,100,1,14.6,700,1,ARL,323238809
2025-07-17T16:00:49.255631264Z,2025-07-17T16:00:49.255465939Z,160,2,1108,A,A,13.660000000,15,0,323720189,130,165325,270140405,ARL,0,13.66,15,130,165325,270140405,9.55,1700,17,9.68,100,1,10.61,200,2,11.27,100,1,11.4,100,1,11.76,100,1,11.93,200,2,12.23,100,1,12.34,200,2,12.36,200,2,13.66,15,1,13.69,15,1,13.7,100,1,13.72,100,1,13.97,100,1,14.01,2,1,14.28,100,1,14.4,100,1,14.56,800,2,14.58,100,1,ARL,323720189
2025-07-17T16:00:49.739644604Z,2025-07-17T16:00:49.739479408Z,160,2,1108,A,A,13.700000000,100,0,323730309,130,165196,270146528,ARL,0,13.7,100,130,165196,270146528,9.55,1700,17,9.68,100,1,10.61,200,2,11.27,100,1,11.4,100,1,11.76,100,1,11.93,200,2,12.23,100,1,12.34,200,2,12.36,200,2,13.66,15,1,13.69,15,1,13.7,200,2,13.72,100,1,13.97,100,1,14.01,2,1,14.28,100,1,14.4,100,1,14.56,800,2,14.58,100,1,ARL,323730309
2025-07-17T16:00:49.745038261Z,2025-07-17T16:00:49.744872763Z,160,2,1108,C,A,13.700000000,100,0,323599605,0,165498,270146577,ARL,0,13.7,100,0,165498,270146577,9.55,1700,17,9.68,100,1,10.61,200,2,11.27,100,1,11.4,100,1,11.76,100,1,11.93,200,2,12.23,100,1,12.34,200,2,12.36,200,2,13.66,15,1,13.69,15,1,13.7,100,1,13.72,100,1,13.97,100,1,14.01,2,1,14.28,100,1,14.4,100,1,14.56,800,2,14.58,100,1,ARL,323599605
2025-07-17T16:00:49.745038261Z,2025-07-17T16:00:49.744872763Z,160,2,1108,A,A,13.670000000,100,0,323730353,130,165498,270146577,ARL,0,13.67,100,130,165498,270146577,9.55,1700,17,9.68,100,1,10.61,200,2,11.27,100,1,11.4,100,1,11.76,100,1,11.93,200,2,12.23,100,1,12.34,200,2,12.36,200,2,13.66,15,1,13.67,100,1,13.69,15,1,13.7,100,1,13.72,100,1,13.97,100,1,14.01,2,1,14.28,100,1,14.4,100,1,14.56,800,2,ARL,323730353
2025-07-17T16:00:49.745778725Z,2025-07-17T16:00:49.745613051Z,160,2,1108,C,A,14.790000000,100,0,321511477,0,165674,270146581,ARL,0,14.79,100,0,165674,270146581,9.55,1700,17,9.68,100,1,10.61,200,2,11.27,100,1,11.4,100,1,11.76,100,1,11.93,200,2,12.23,100,1,12.34,200,2,12.36,200,2,13.66,15,1,13.67,100,1,13.69,15,1,13.7,100,1,13.72,100,1,13.97,100,1,14.01,2,1,14.28,100,1,14.4,100,1,14.56,800,2,ARL,321511477
2025-07-17T16:00:49.745778725Z,2025-07-17T16:00:49.745613051Z,160,2,1108,A,A,14.730000000,100,0,323730369,130,165674,270146581,ARL,0,14.73,100,130,165674,270146581,9.55,1700,17,9.68,100,1,10.61,200,2,11.27,100,1,11.4,100,1,11.76,100,1,11.93,200,2,12.23,100,1,12.34,200,2,12.36,200,2,13.66,15,1,13.67,100,1,13.69,15,1,13.7,100,1,13.72,100,1,13.97,100,1,14.01,2,1,14.28,100,1,14.4,100,1,14.56,800,2,ARL,323730369
2025-07-17T16:00:49.746422142Z,2025-07-17T16:00:49.746256906Z,160,2,1108,C,A,13.720000000,100,0,323599609,130,165236,270146586,ARL,0,13.72,100,130,165236,270146586,9.55,1700,17,9.68,100,1,10.61,200,2,11.27,100,1,11.4,100,1,11.76,100,1,11.93,200,2,12.23,100,1,12.34,200,2,12.36,200,2,13.66,15,1,13.67,100,1,13.69,15,1,13.7,100,1,13.97,100,1,14.01,2,1,14.28,100,1,14.4,100,1,14.56,800,2,14.58,100,1,ARL,323599609
2025-07-17T16:00:49.772631967Z,2025-07-17T16:00:49.772466772Z,160,2,1108,A,A,15.590000000,100,0,323730697,130,165195,270146838,ARL,0,15.59,100,130,165195,270146838,9.55,1700,17,9.68,100,1,10.61,200,2,11.27,100,1,11.4,100,1,11.76,100,1,11.93,200,2,12.23,100,1,12.34,200,2,12.36,200,2,13.66,15,1,13.67,100,1,13.69,15,1,13.7,100,1,13.97,100,1,14.01,2,1,14.28,100,1,14.4,100,1,14.56,800,2,14.58,100,1,ARL,323730697
2025-07-17T16:00:49.772645303Z,2025-07-17T16:00:49.772479921Z,160,2,1108,C,A,15.860000000,100,0,312771645,130,165382,270146839,ARL,0,15.86,100,130,165382,270146839,9.55,1700,17,9.68,100,1,10.61,200,2,11.27,100,1,11.4,100,1,11.76,100,1,11.93,200,2,12.23,100,1,12.34,200,2,12.36,200,2,13.66,15,1,13.67,100,1,13.69,15,1,13.7,100,1,13.97,100,1,14.01,2,1,14.28,100,1,14.4,100,1,14.56,800,2,14.58,100,1,ARL,312771645
2025-07-17T16:00:51.624811889Z,2025-07-17T16:00:51.624646272Z,160,2,1108,C,A,14.650000000,100,0,321293737,0,165617,270181394,ARL,0,14.65,100,0,165617,270181394,9.55,1700,17,9.68,100,1,10.61,200,2,11.27,100,1,11.4,100,1,11.76,100,1,11.93,200,2,12.23,100,1,12.34,200,2,12.36,200,2,13.66,15,1,13.67,100,1,13.69,15,1,13.7,100,1,13.97,100,1,14.01,2,1,14.28,100,1,14.4,100,1,14.56,800,2,14.58,100,1,ARL,321293737
2025-07-17T16:00:51.624811889Z,2025-07-17T16:00:51.624646272Z,160,2,1108,A,A,14.540000000,100,0,323775433,130,165617,270181394,ARL,0,14.54,100,130,165617,270181394,9.55,1700,17,9.68,100,1,10.61,200,2,11.27,100,1,11.4,100,1,11.76,100,1,11.93,200,2,12.23,100,1,12.34,200,2,12.36,200,2,13.66,15,1,13.67,100,1,13.69,15,1,13.7,100,1,13.97,100,1,14.01,2,1,14.28,100,1,14.4,100,1,14.54,100,1,14.56,800,2,ARL,323775433
2025-07-17T16:00:51.625372516Z,2025-07-17T16:00:51.625206675Z,160,2,1108,C,A,14.640000000,100,0,321293741,0,165841,270181399,ARL,0,14.64,100,0,165841,270181399,9.55,1700,17,9.68,100,1,10.61,200,2,11.27,100,1,11.4,100,1,11.76,100,1,11.93,200,2,12.23,100,1,12.34,200,2,12.36,200,2,13.66,15,1,13.67,100,1,13.69,15,1,13.7,100,1,13.97,100,1,14.01,2,1,14.28,100,1,14.4,100,1,14.54,100,1,14.56,800,2,ARL,321293741
2025-07-17T16:00:51.625372516Z,2025-07-17T16:00:51.625206675Z,160,2,1108,A,A,14.530000000,100,0,323775457,130,165841,270181399,ARL,0,14.53,100,130,165841,270181399,9.55,1700,17,9.68,100,1,10.61,200,2,11.27,100,1,11.4,100,1,11.76,100,1,11.93,200,2,12.23,100,1,12.34,200,2,12.36,200,2,13.66,15,1,13.67,100,1,13.69,15,1,13.7,100,1,13.97,100,1,14.01,2,1,14.28,100,1,14.4,100,1,14.53,100,1,14.54,100,1,ARL,323775457
2025-07-17T16:00:53.749335010Z,2025-07-17T16:00:53.749169565Z,160,2,1108,A,A,13.670000000,100,0,323803301,130,165445,270204567,ARL,0,13.67,100,130,165445,270204567,9.55,1700,17,9.68,100,1,10.61,200,2,11.27,100,1,11.4,100,1,11.76,100,1,11.93,200,2,12.23,100,1,12.34,200,2,12.36,200,2,13.66,15,1,13.67,200,2,13.69,15,1,13.7,100,1,13.97,100,1,14.01,2,1,14.28,100,1,14.4,100,1,14.53,100,1,14.54,100,1,ARL,323803301
2025-07-17T16:00:53.755966680Z,2025-07-17T16:00:53.755801462Z,160,2,1108,C,A,13.700000000,100,0,323730309,130,165218,270204616,ARL,0,13.7,100,130,165218,270204616,9.55,1700,17,9.68,100,1,10.61,200,2,11.27,100,1,11.4,100,1,11.76,100,1,11.93,200,2,12.23,100,1,12.34,200,2,12.36,200,2,13.66,15,1,13.67,200,2,13.69,15,1,13.97,100,1,14.01,2,1,14.28,100,1,14.4,100,1,14.53,100,1,14.54,100,1,14.56,800,2,ARL,323730309
2025-07-17T16:01:00.801342739Z,2025-07-17T16:01:00.801177403Z,160,2,1108,C,A,13.690000000,15,0,323455221,130,165336,270319932,ARL,0,13.69,15,130,165336,270319932,9.55,1700,17,9.68,100,1,10.61,200,2,11.27,100,1,11.4,100,1,11.76,100,1,11.93,200,2,12.23,100,1,12.34,200,2,12.36,200,2,13.66,15,1,13.67,200,2,13.97,100,1,14.01,2,1,14.28,100,1,14.4,100,1,14.53,100,1,14.54,100,1,14.56,800,2,14.58,100,1,ARL,323455221
2025-07-17T16:01:10.802877570Z,2025-07-17T16:01:10.802712247Z,160,2,1108,A,A,13.620000000,15,0,324161541,130,165323,270493149,ARL,0,13.62,15,130,165323,270493149,9.55,1700,17,9.68,100,1,10.61,200,2,11.27,100,1,11.4,100,1,11.76,100,1,11.93,200,2,12.23,100,1,12.34,200,2,12.36,200,2,13.62,15,1,13.66,15,1,13.67,200,2,13.97,100,1,14.01,2,1,14.28,100,1,14.4,100,1,14.53,100,1,14.54,100,1,14.56,800,2,ARL,324161541
2025-07-17T16:01:11.418837472Z,2025-07-17T16:01:11.418671671Z,160,2,1108,A,A,13.650000000,100,0,324175569,130,165801,270503944,ARL,0,13.65,100,130,165801,270503944,9.55,1700,17,9.68,100,1,10.61,200,2,11.27,100,1,11.4,100,1,11.76,100,1,11.93,200,2,12.23,100,1,12.34,200,2,12.36,200,2,13.62,15,1,13.65,100,1,13.66,15,1,13.67,200,2,13.97,100,1,14.01,2,1,14.28,100,1,14.4,100,1,14.53,100,1,14.54,100,1,ARL,324175569
2025-07-17T16:01:11.425922184Z,2025-07-17T16:01:11.425757014Z,160,2,1108,C,A,13.670000000,100,0,323803301,130,165170,270504009,ARL,0,13.67,100,130,165170,270504009,9.55,1700,17,9.68,100,1,10.61,200,2,11.27,100,1,11.4,100,1,11.76,100,1,11.93,200,2,12.23,100,1,12.34,200,2,12.36,200,2,13.62,15,1,13.65,100,1,13.66,15,1,13.67,100,1,13.97,100,1,14.01,2,1,14.28,100,1,14.4,100,1,14.53,100,1,14.54,100,1,ARL,323803301
2025-07-17T16:01:11.820753616Z,2025-07-17T16:01:11.820588141Z,160,2,1108,C,A,13.670000000,100,0,323730353,0,165475,270509970,ARL,0,13.67,100,0,165475,270509970,9.55,1700,17,9.68,100,1,10.61,200,2,11.27,100,1,11.4,100,1,11.76,100,1,11.93,200,2,12.23,100,1,12.34,200,2,12.36,200,2,13.62,15,1,13.65,100,1,13.66,15,1,13.97,100,1,14.01,2,1,14.28,100,1,14.4,100,1,14.53,100,1,14.54,100,1,14.56,800,2,ARL,323730353
2025-07-17T16:01:11.820753616Z,2025-07-17T16:01:11.820588141Z,160,2,1108,A,A,13.630000000,100,0,324186213,130,165475,270509970,ARL,0,13.63,100,130,165475,270509970,9.55,1700,17,9.68,100,1,10.61,200,2,11.27,100,1,11.4,100,1,11.76,100,1,11.93,200,2,12.23,100,1,12.34,200,2,12.36,200,2,13.62,15,1,13.63,100,1,13.65,100,1,13.66,15,1,13.97,100,1,14.01,2,1,14.28,100,1,14.4,100,1,14.53,100,1,14.54,100,1,ARL,324186213
2025-07-17T16:01:11.821515043Z,2025-07-17T16:01:11.821349600Z,160,2,1108,C,A,14.730000000,100,0,323730369,0,165443,270509983,ARL,0,14.73,100,0,165443,270509983,9.55,1700,17,9.68,100,1,10.61,200,2,11.27,100,1,11.4,100,1,11.76,100,1,11.93,200,2,12.23,100,1,12.34,200,2,12.36,200,2,13.62,15,1,13.63,100,1,13.65,100,1,13.66,15,1,13.97,100,1,14.01,2,1,14.28,100,1,14.4,100,1,14.53,100,1,14.54,100,1,ARL,323730369
2025-07-17T16:01:11.821515043Z,2025-07-17T16:01:11.821349600Z,160,2,1108,A,A,14.690000000,100,0,324186233,130,165443,270509983,ARL,0,14.69,100,130,165443,270509983,9.55,1700,17,9.68,100,1,10.61,200,2,11.27,100,1,11.4,100,1,11.76,100,1,11.93,200,2,12.23,100,1,12.34,200,2,12.36,200,2,13.62,15,1,13.63,100,1,13.65,100,1,13.66,15,1,13.97,100,1,14.01,2,1,14.28,100,1,14.4,100,1,14.53,100,1,14.54,100,1,ARL,324186233
2025-07-17T16:01:11.826399871Z,2025-07-17T16:01:11.826234488Z,160,2,1108,C,A,13.970000000,100,0,323599765,130,165383,270510142,ARL,0,13.97,100,130,165383,270510142,9.55,1700,17,9.68,100,1,10.61,200,2,11.27,100,1,11.4,100,1,11.76,100,1,11.93,200,2,12.23,100,1,12.34,200,2,12.36,200,2,13.62,15,1,13.63,100,1,13.65,100,1,13.66,15,1,14.01,2,1,14.28,100,1,14.4,100,1,14.53,100,1,14.54,100,1,14.56,800,2,ARL,323599765
2025-07-17T16:01:11.826451447Z,2025-07-17T16:01:11.826286284Z,160,2,1108,A,A,13.900000000,100,0,324186721,130,165163,270510143,ARL,0,13.9,100,130,165163,270510143,9.55,1700,17,9.68,100,1,10.61,200,2,11.27,100,1,11.4,100,1,11.76,100,1,11.93,200,2,12.23,100,1,12.34,200,2,12.36,200,2,13.62,15,1,13.63,100,1,13.65,100,1,13.66,15,1,13.9,100,1,14.01,2,1,14.28,100,1,14.4,100,1,14.53,100,1,14.54,100,1,ARL,324186721
2025-07-17T16:01:11.828630414Z,2025-07-17T16:01:11.828464891Z,160,2,1108,C,A,14.580000000,100,0,321309941,0,165523,270510182,ARL,0,14.58,100,0,165523,270510182,9.55,1700,17,9.68,100,1,10.61,200,2,11.27,100,1,11.4,100,1,11.76,100,1,11.93,200,2,12.23,100,1,12.34,200,2,12.36,200,2,13.62,15,1,13.63,100,1,13.65,100,1,13.66,15,1,13.9,100,1,14.01,2,1,14.28,100,1,14.4,100,1,14.53,100,1,14.54,100,1,ARL,321309941
2025-07-17T16:01:11.828630414Z,2025-07-17T16:01:11.828464891Z,160,2,1108,A,A,14.430000000,100,0,324186781,130,165523,270510182,ARL,0,14.43,100,130,165523,270510182,9.55,1700,17,9.68,100,1,10.61,200,2,11.27,100,1,11.4,100,1,11.76,100,1,11.93,200,2,12.23,100,1,12.34,200,2,12.36,200,2,13.62,15,1,13.63,100,1,13.65,100,1,13.66,15,1,13.9,100,1,14.01,2,1,14.28,100,1,14.4,100,1,14.43,100,1,14.53,100,1,ARL,324186781
2025-07-17T16:01:22.802518536Z,2025-07-17T16:01:22.802353061Z,160,2,1108,C,A,13.660000000,15,0,323720189,130,165475,270674903,ARL,0,13.66,15,130,165475,270674903,9.55,1700,17,9.68,100,1,10.61,200,2,11.27,100,1,11.4,100,1,11.76,100,1,11.93,200,2,12.23,100,1,12.34,200,2,12.36,200,2,13.62,15,1,13.63,100,1,13.65,100,1,13.9,100,1,14.01,2,1,14.28,100,1,14.4,100,1,14.43,100,1,14.53,100,1,14.54,100,1,ARL,323720189
2025-07-17T16:01:32.804004639Z,2025-07-17T16:01:32.803839043Z,160,2,1108,A,A,13.600000000,15,0,324619361,130,165596,270824320,ARL,0,13.6,15,130,165596,270824320,9.55,1700,17,9.68,100,1,10.61,200,2,11.27,100,1,11.4,100,1,11.76,100,1,11.93,200,2,12.23,100,1,12.34,200,2,12.36,200,2,13.6,15,1,13.62,15,1,13.63,100,1,13.65,100,1,13.9,100,1,14.01,2,1,14.28,100,1,14.4,100,1,14.43,100,1,14.53,100,1,ARL,324619361
2025-07-17T16:01:32.804274168Z,2025-07-17T16:01:32.804108576Z,160,2,1108,C,A,13.630000000,100,0,324186213,0,165592,270824323,ARL,0,13.63,100,0,165592,270824323,9.55,1700,17,9.68,100,1,10.61,200,2,11.27,100,1,11.4,100,1,11.76,100,1,11.93,200,2,12.23,100,1,12.34,200,2,12.36,200,2,13.6,15,1,13.62,15,1,13.65,100,1,13.9,100,1,14.01,2,1,14.28,100,1,14.4,100,1,14.43,100,1,14.53,100,1,14.54,100,1,ARL,324186213
2025-07-17T16:01:32.804274168Z,2025-07-17T16:01:32.804108576Z,160,2,1108,A,A,13.610000000,100,0,324619369,130,165592,270824323,ARL,0,13.61,100,130,165592,270824323,9.55,1700,17,9.68,100,1,10.61,200,2,11.27,100,1,11.4,100,1,11.76,100,1,11.93,200,2,12.23,100,1,12.34,200,2,12.36,200,2,13.6,15,1,13.61,100,1,13.62,15,1,13.65,100,1,13.9,100,1,14.01,2,1,14.28,100,1,14.4,100,1,14.43,100,1,14.53,100,1,ARL,324619369
2025-07-17T16:01:32.806299464Z,2025-07-17T16:01:32.806134020Z,160,2,1108,C,A,14.730000000,100,0,321500349,0,165444,270824400,ARL,0,14.73,100,0,165444,270824400,9.55,1700,17,9.68,100,1,10.61,200,2,11.27,100,1,11.4,100,1,11.76,100,1,11.93,200,2,12.23,100,1,12.34,200,2,12.36,200,2,13.6,15,1,13.61,100,1,13.62,15,1,13.65,100,1,13.9,100,1,14.01,2,1,14.28,100,1,14.4,100,1,14.43,100,1,14.53,100,1,ARL,321500349
2025-07-17T16:01:32.806299464Z,2025-07-17T16:01:32.806134020Z,160,2,1108,A,A,14.570000000,100,0,324619409,130,165444,270824400,ARL,0,14.57,100,130,165444,270824400,9.55,1700,17,9.68,100,1,10.61,200,2,11.27,100,1,11.4,100,1,11.76,100,1,11.93,200,2,12.23,100,1,12.34,200,2,12.36,200,2,13.6,15,1,13.61,100,1,13.62,15,1,13.65,100,1,13.9,100,1,14.01,2,1,14.28,100,1,14.4,100,1,14.43,100,1,14.53,100,1,ARL,324619409
2025-07-17T16:01:32.815913520Z,2025-07-17T16:01:32.815748258Z,160,2,1108,A,A,13.630000000,100,0,324619837,130,165262,270824657,ARL,0,13.63,100,130,165262,270824657,9.55,1700,17,9.68,100,1,10.61,200,2,11.27,100,1,11.4,100,1,11.76,100,1,11.93,200,2,12.23,100,1,12.34,200,2,12.36,200,2,13.6,15,1,13.61,100,1,13.62,15,1,13.63,100,1,13.65,100,1,13.9,100,1,14.01,2,1,14.28,100,1,14.4,100,1,14.43,100,1,ARL,324619837
2025-07-17T16:01:32.822608966Z,2025-07-17T16:01:32.822443626Z,160,2,1108,C,A,13.650000000,100,0,324175569,130,165340,270824747,ARL,0,13.65,100,130,165340,270824747,9.55,1700,17,9.68,100,1,10.61,200,2,11.27,100,1,11.4,100,1,11.76,100,1,11.93,200,2,12.23,100,1,12.34,200,2,12.36,200,2,13.6,15,1,13.61,100,1,13.62,15,1,13.63,100,1,13.9,100,1,14.01,2,1,14.28,100,1,14.4,100,1,14.43,100,1,14.53,100,1,ARL,324175569
2025-07-17T16:01:37.242690420Z,2025-07-17T16:01:37.242525208Z,160,2,1108,C,A,13.620000000,15,0,324161541,130,165212,270889017,ARL,0,13.62,15,130,165212,270889017,9.55,1700,17,9.68,100,1,10.61,200,2,11.27,100,1,11.4,100,1,11.76,100,1,11.93,200,2,12.23,100,1,12.34,200,2,12.36,200,2,13.6,15,1,13.61,100,1,13.63,100,1,13.9,100,1,14.01,2,1,14.28,100,1,14.4,100,1,14.43,100,1,14.53,100,1,14.54,100,1,ARL,324161541
2025-07-17T16:01:40.605797765Z,2025-07-17T16:01:40.605632399Z,160,2,1108,A,A,13.610000000,100,0,324782841,130,165366,270946497,ARL,0,13.61,100,130,165366,270946497,9.55,1700,17,9.68,100,1,10.61,200,2,11.27,100,1,11.4,100,1,11.76,100,1,11.93,200,2,12.23,100,1,12.34,200,2,12.36,200,2,13.6,15,1,13.61,200,2,13.63,100,1,13.9,100,1,14.01,2,1,14.28,100,1,14.4,100,1,14.43,100,1,14.53,100,1,14.54,100,1,ARL,324782841
2025-07-17T16:01:40.653738176Z,2025-07-17T16:01:40.653572805Z,160,2,1108,C,A,13.630000000,100,0,324619837,130,165371,270946779,ARL,0,13.63,100,130,165371,270946779,9.55,1700,17,9.68,100,1,10.61,200,2,11.27,100,1,11.4,100,1,11.76,100,1,11.93,200,2,12.23,100,1,12.34,200,2,12.36,200,2,13.6,15,1,13.61,200,2,13.9,100,1,14.01,2,1,14.28,100,1,14.4,100,1,14.43,100,1,14.53,100,1,14.54,100,1,14.56,800,2,ARL,324619837
2025-07-17T16:01:47.565991684Z,2025-07-17T16:01:47.565825466Z,160,2,1108,A,A,13.570000000,15,0,324934601,128,166218,271062350,ARL,0,13.57,15,128,166218,271062350,9.55,1700,17,9.68,100,1,10.61,200,2,11.27,100,1,11.4,100,1,11.76,100,1,11.93,200,2,12.23,100,1,12.34,200,2,12.36,200,2,13.57,15,1,13.6,15,1,13.61,200,2,13.9,100,1,14.01,2,1,14.28,100,1,14.4,100,1,14.43,100,1,14.53,100,1,14.54,100,1,ARL,324934601
2025-07-17T16:01:47.902969773Z,2025-07-17T16:01:47.902804446Z,160,2,1108,C,A,13.610000000,100,0,324619369,0,165327,271068098,ARL,0,13.61,100,0,165327,271068098,9.55,1700,17,9.68,100,1,10.61,200,2,11.27,100,1,11.4,100,1,11.76,100,1,11.93,200,2,12.23,100,1,12.34,200,2,12.36,200,2,13.57,15,1,13.6,15,1,13.61,100,1,13.9,100,1,14.01,2,1,14.28,100,1,14.4,100,1,14.43,100,1,14.53,100,1,14.54,100,1,ARL,324619369
2025-07-17T16:01:47.902969773Z,2025-07-17T16:01:47.902804446Z,160,2,1108,A,A,13.580000000,100,0,324942229,130,165327,271068098,ARL,0,13.58,100,130,165327,271068098,9.55,1700,17,9.68,100,1,10.61,200,2,11.27,100,1,11.4,100,1,11.76,100,1,11.93,200,2,12.23,100,1,12.34,200,2,12.36,200,2,13.57,15,1,13.58,100,1,13.6,15,1,13.61,100,1,13.9,100,1,14.01,2,1,14.28,100,1,14.4,100,1,14.43,100,1,14.53,100,1,ARL,324942229
2025-07-17T16:01:47.903711757Z,2025-07-17T16:01:47.903546622Z,160,2,1108,C,A,14.400000000,100,0,289726421,130,165135,271068105,ARL,0,14.4,100,130,165135,271068105,9.55,1700,17,9.68,100,1,10.61,200,2,11.27,100,1,11.4,100,1,11.76,100,1,11.93,200,2,12.23,100,1,12.34,200,2,12.36,200,2,13.57,15,1,13.58,100,1,13.6,15,1,13.61,100,1,13.9,100,1,14.01,2,1,14.28,100,1,14.43,100,1,14.53,100,1,14.54,100,1,ARL,289726421
2025-07-17T16:01:47.903714323Z,2025-07-17T16:01:47.903548861Z,160,2,1108,C,A,14.690000000,100,0,324186233,0,165462,271068106,ARL,0,14.69,100,0,165462,271068106,9.55,1700,17,9.68,100,1,10.61,200,2,11.27,100,1,11.4,100,1,11.76,100,1,11.93,200,2,12.23,100,1,12.34,200,2,12.36,200,2,13.57,15,1,13.58,100,1,13.6,15,1,13.61,100,1,13.9,100,1,14.01,2,1,14.28,100,1,14.43,100,1,14.53,100,1,14.54,100,1,ARL,324186233
2025-07-17T16:01:47.903714323Z,2025-07-17T16:01:47.903548861Z,160,2,1108,A,A,14.630000000,100,0,324942257,130,165462,271068106,ARL,0,14.63,100,130,165462,271068106,9.55,1700,17,9.68,100,1,10.61,200,2,11.27,100,1,11.4,100,1,11.76,100,1,11.93,200,2,12.23,100,1,12.34,200,2,12.36,200,2,13.57,15,1,13.58,100,1,13.6,15,1,13.61,100,1,13.9,100,1,14.01,2,1,14.28,100,1,14.43,100,1,14.53,100,1,14.54,100,1,ARL,324942257
2025-07-17T16:01:47.904067686Z,2025-07-17T16:01:47.903902473Z,160,2,1108,A,A,14.190000000,100,0,324942273,130,165213,271068115,ARL,0,14.19,100,130,165213,271068115,9.55,1700,17,9.68,100,1,10.61,200,2,11.27,100,1,11.4,100,1,11.76,100,1,11.93,200,2,12.23,100,1,12.34,200,2,12.36,200,2,13.57,15,1,13.58,100,1,13.6,15,1,13.61,100,1,13.9,100,1,14.01,2,1,14.19,100,1,14.28,100,1,14.43,100,1,14.53,100,1,ARL,324942273
2025-07-17T16:01:47.905355779Z,2025-07-17T16:01:47.905189816Z,160,2,1108,C,A,15.230000000,100,0,282776017,0,165963,271068134,ARL,0,15.23,100,0,165963,271068134,9.55,1700,17,9.68,100,1,10.61,200,2,11.27,100,1,11.4,100,1,11.76,100,1,11.93,200,2,12.23,100,1,12.34,200,2,12.36,200,2,13.57,15,1,13.58,100,1,13.6,15,1,13.61,100,1,13.9,100,1,14.01,2,1,14.19,100,1,14.28,100,1,14.43,100,1,14.53,100,1,ARL,282776017
2025-07-17T16:01:47.905355779Z,2025-07-17T16:01:47.905189816Z,160,2,1108,A,A,14.940000000,100,0,324942277,130,165963,271068134,ARL,0,14.94,100,130,165963,271068134,9.55,1700,17,9.68,100,1,10.61,200,2,11.27,100,1,11.4,100,1,11.76,100,1,11.93,200,2,12.23,100,1,12.34,200,2,12.36,200,2,13.57,15,1,13.58,100,1,13.6,15,1,13.61,100,1,13.9,100,1,14.01,2,1,14.19,100,1,14.28,100,1,14.43,100,1,14.53,100,1,ARL,324942277
2025-07-17T16:01:47.909479724Z,2025-07-17T16:01:47.909314303Z,160,2,1108,C,A,17.400000000,100,0,323599633,0,165421,271068173,ARL,0,17.4,100,0,165421,271068173,9.55,1700,17,9.68,100,1,10.61,200,2,11.27,100,1,11.4,100,1,11.76,100,1,11.93,200,2,12.23,100,1,12.34,200,2,12.36,200,2,13.57,15,1,13.58,100,1,13.6,15,1,13.61,100,1,13.9,100,1,14.01,2,1,14.19,100,1,14.28,100,1,14.43,100,1,14.53,100,1,ARL,323599633
2025-07-17T16:01:47.909479724Z,2025-07-17T16:01:47.909314303Z,160,2,1108,A,A,17.250000000,100,0,324942361,130,165421,271068173,ARL,0,17.25,100,130,165421,271068173,9.55,1700,17,9.68,100,1,10.61,200,2,11.27,100,1,11.4,100,1,11.76,100,1,11.93,200,2,12.23,100,1,12.34,200,2,12.36,200,2,13.57,15,1,13.58,100,1,13.6,15,1,13.61,100,1,13.9,100,1,14.01,2,1,14.19,100,1,14.28,100,1,14.43,100,1,14.53,100,1,ARL,324942361
2025-07-17T16:01:50.799100504Z,2025-07-17T16:01:50.798934838Z,160,2,1108,A,A,13.590000000,100,0,325022101,130,165666,271131418,ARL,0,13.59,100,130,165666,271131418,9.55,1700,17,9.68,100,1,10.61,200,2,11.27,100,1,11.4,100,1,11.76,100,1,11.93,200,2,12.23,100,1,12.34,200,2,12.36,200,2,13.57,15,1,13.58,100,1,13.59,100,1,13.6,15,1,13.61,100,1,13.9,100,1,14.01,2,1,14.19,100,1,14.28,100,1,14.43,100,1,ARL,325022101
2025-07-17T16:01:50.805653961Z,2025-07-17T16:01:50.805488726Z,160,2,1108,C,A,13.610000000,100,0,324782841,130,165235,271131583,ARL,0,13.61,100,130,165235,271131583,9.55,1700,17,9.68,100,1,10.61,200,2,11.27,100,1,11.4,100,1,11.76,100,1,11.93,200,2,12.23,100,1,12.34,200,2,12.36,200,2,13.57,15,1,13.58,100,1,13.59,100,1,13.6,15,1,13.9,100,1,14.01,2,1,14.19,100,1,14.28,100,1,14.43,100,1,14.53,100,1,ARL,324782841
2025-07-17T16:01:52.133063761Z,2025-07-17T16:01:52.132898568Z,160,2,1108,C,A,13.600000000,15,0,324619361,130,165193,271153294,ARL,0,13.6,15,130,165193,271153294,9.55,1700,17,9.68,100,1,10.61,200,2,11.27,100,1,11.4,100,1,11.76,100,1,11.93,200,2,12.23,100,1,12.34,200,2,12.36,200,2,13.57,15,1,13.58,100,1,13.59,100,1,13.9,100,1,14.01,2,1,14.19,100,1,14.28,100,1,14.43,100,1,14.53,100,1,14.54,100,1,ARL,324619361
2025-07-17T16:01:53.137501962Z,2025-07-17T16:01:53.137336077Z,160,2,1108,A,A,13.550000000,15,0,325109165,130,165885,271200452,ARL,0,13.55,15,130,165885,271200452,9.55,1700,17,9.68,100,1,10.61,200,2,11.27,100,1,11.4,100,1,11.76,100,1,11.93,200,2,12.23,100,1,12.34,200,2,12.36,200,2,13.55,15,1,13.57,15,1,13.58,100,1,13.59,100,1,13.9,100,1,14.01,2,1,14.19,100,1,14.28,100,1,14.43,100,1,14.53,100,1,ARL,325109165
2025-07-17T16:01:56.264154095Z,2025-07-17T16:01:56.263988198Z,160,2,1108,C,A,13.580000000,100,0,324942229,0,165897,271251019,ARL,0,13.58,100,0,165897,271251019,9.55,1700,17,9.68,100,1,10.61,200,2,11.27,100,1,11.4,100,1,11.76,100,1,11.93,200,2,12.23,100,1,12.34,200,2,12.36,200,2,13.55,15,1,13.57,15,1,13.59,100,1,13.9,100,1,14.01,2,1,14.19,100,1,14.28,100,1,14.43,100,1,14.53,100,1,14.54,100,1,ARL,324942229
2025-07-17T16:01:56.264154095Z,2025-07-17T16:01:56.263988198Z,160,2,1108,A,A,13.560000000,100,0,325176181,130,165897,271251019,ARL,0,13.56,100,130,165897,271251019,9.55,1700,17,9.68,100,1,10.61,200,2,11.27,100,1,11.4,100,1,11.76,100,1,11.93,200,2,12.23,100,1,12.34,200,2,12.36,200,2,13.55,15,1,13.56,100,1,13.57,15,1,13.59,100,1,13.9,100,1,14.01,2,1,14.19,100,1,14.28,100,1,14.43,100,1,14.53,100,1,ARL,325176181
2025-07-17T16:01:56.269623788Z,2025-07-17T16:01:56.269458197Z,160,2,1108,C,A,13.900000000,100,0,324186721,130,165591,271251357,ARL,0,13.9,100,130,165591,271251357,9.55,1700,17,9.68,100,1,10.61,200,2,11.27,100,1,11.4,100,1,11.76,100,1,11.93,200,2,12.23,100,1,12.34,200,2,12.36,200,2,13.55,15,1,13.56,100,1,13.57,15,1,13.59,100,1,14.01,2,1,14.19,100,1,14.28,100,1,14.43,100,1,14.53,100,1,14.54,100,1,ARL,324186721
2025-07-17T16:01:56.269674232Z,2025-07-17T16:01:56.269508928Z,160,2,1108,A,A,13.830000000,100,0,325176373,130,165304,271251358,ARL,0,13.83,100,130,165304,271251358,9.55,1700,17,9.68,100,1,10.61,200,2,11.27,100,1,11.4,100,1,11.76,100,1,11.93,200,2,12.23,100,1,12.34,200,2,12.36,200,2,13.55,15,1,13.56,100,1,13.57,15,1,13.59,100,1,13.83,100,1,14.01,2,1,14.19,100,1,14.28,100,1,14.43,100,1,14.53,100,1,ARL,325176373
2025-07-17T16:01:56.272340730Z,2025-07-17T16:01:56.272175169Z,160,2,1108,C,A,15.760000000,100,0,323599629,0,165561,271251490,ARL,0,15.76,100,0,165561,271251490,9.55,1700,17,9.68,100,1,10.61,200,2,11.27,100,1,11.4,100,1,11.76,100,1,11.93,200,2,12.23,100,1,12.34,200,2,12.36,200,2,13.55,15,1,13.56,100,1,13.57,15,1,13.59,100,1,13.83,100,1,14.01,2,1,14.19,100,1,14.28,100,1,14.43,100,1,14.53,100,1,ARL,323599629
2025-07-17T16:01:56.272340730Z,2025-07-17T16:01:56.272175169Z,160,2,1108,A,A,15.600000000,100,0,325176677,130,165561,271251490,ARL,0,15.6,100,130,165561,271251490,9.55,1700,17,9.68,100,1,10.61,200,2,11.27,100,1,11.4,100,1,11.76,100,1,11.93,200,2,12.23,100,1,12.34,200,2,12.36,200,2,13.55,15,1,13.56,100,1,13.57,15,1,13.59,100,1,13.83,100,1,14.01,2,1,14.19,100,1,14.28,100,1,14.43,100,1,14.53,100,1,ARL,325176677
2025-07-17T16:01:56.300889378Z,2025-07-17T16:01:56.300723805Z,160,2,1108,C,A,14.660000000,100,0,323599625,0,165573,271252044,ARL,0,14.66,100,0,165573,271252044,9.55,1700,17,9.68,100,1,10.61,200,2,11.27,100,1,11.4,100,1,11.76,100,1,11.93,200,2,12.23,100,1,12.34,200,2,12.36,200,2,13.55,15,1,13.56,100,1,13.57,15,1,13.59,100,1,13.83,100,1,14.01,2,1,14.19,100,1,14.28,100,1,14.43,100,1,14.53,100,1,ARL,323599625
2025-07-17T16:01:56.300889378Z,2025-07-17T16:01:56.300723805Z,160,2,1108,A,A,14.510000000,100,0,325177757,130,165573,271252044,ARL,0,14.51,100,130,165573,271252044,9.55,1700,17,9.68,100,1,10.61,200,2,11.27,100,1,11.4,100,1,11.76,100,1,11.93,200,2,12.23,100,1,12.34,200,2,12.36,200,2,13.55,15,1,13.56,100,1,13.57,15,1,13.59,100,1,13.83,100,1,14.01,2,1,14.19,100,1,14.28,100,1,14.43,100,1,14.51,100,1,ARL,325177757
2025-07-17T16:01:56.776980244Z,2025-07-17T16:01:56.776814001Z,160,2,1108,T,N,13.410000000,16,0,0,130,166243,271255700,ARL,0,13.41,16,130,166243,271255700,9.55,1700,17,9.68,100,1,10.61,200,2,11.27,100,1,11.4,100,1,11.76,100,1,11.93,200,2,12.23,100,1,12.34,200,2,12.36,200,2,13.55,15,1,13.56,100,1,13.57,15,1,13.59,100,1,13.83,100,1,14.01,2,1,14.19,100,1,14.28,100,1,14.43,100,1,14.51,100,1,ARL,0
2025-07-17T16:01:56.777414332Z,2025-07-17T16:01:56.777248616Z,160,2,1108,T,N,13.410000000,16,0,0,130,165716,271255708,ARL,0,13.41,16,130,165716,271255708,9.55,1700,17,9.68,100,1,10.61,200,2,11.27,100,1,11.4,100,1,11.76,100,1,11.93,200,2,12.23,100,1,12.34,200,2,12.36,200,2,13.55,15,1,13.56,100,1,13.57,15,1,13.59,100,1,13.83,100,1,14.01,2,1,14.19,100,1,14.28,100,1,14.43,100,1,14.51,100,1,ARL,0
2025-07-17T16:01:56.777906069Z,2025-07-17T16:01:56.777739254Z,160,2,1108,T,N,13.410000000,4,0,0,130,166815,271255712,ARL,0,13.41,4,130,166815,271255712,9.55,1700,17,9.68,100,1,10.61,200,2,11.27,100,1,11.4,100,1,11.76,100,1,11.93,200,2,12.23,100,1,12.34,200,2,12.36,200,2,13.55,15,1,13.56,100,1,13.57,15,1,13.59,100,1,13.83,100,1,14.01,2,1,14.19,100,1,14.28,100,1,14.43,100,1,14.51,100,1,ARL,0
2025-07-17T16:02:01.992544607Z,2025-07-17T16:02:01.992379223Z,160,2,1108,C,A,14.010000000,2,0,322898193,0,165384,271343251,ARL,0,14.01,2,0,165384,271343251,9.55,1700,17,9.68,100,1,10.61,200,2,11.27,100,1,11.4,100,1,11.76,100,1,11.93,200,2,12.23,100,1,12.34,200,2,12.36,200,2,13.55,15,1,13.56,100,1,13.57,15,1,13.59,100,1,13.83,100,1,14.19,100,1,14.28,100,1,14.43,100,1,14.51,100,1,14.53,100,1,ARL,322898193
2025-07-17T16:02:01.992544607Z,2025-07-17T16:02:01.992379223Z,160,2,1108,A,A,13.920000000,2,0,325297093,130,165384,271343251,ARL,0,13.92,2,130,165384,271343251,9.55,1700,17,9.68,100,1,10.61,200,2,11.27,100,1,11.4,100,1,11.76,100,1,11.93,200,2,12.23,100,1,12.34,200,2,12.36,200,2,13.55,15,1,13.56,100,1,13.57,15,1,13.59,100,1,13.83,100,1,13.92,2,1,14.19,100,1,14.28,100,1,14.43,100,1,14.51,100,1,ARL,325297093
2025-07-17T16:02:03.207720826Z,2025-07-17T16:02:03.207555626Z,160,2,1108,C,A,13.570000000,15,0,324934601,130,165200,271367066,ARL,0,13.57,15,130,165200,271367066,9.55,1700,17,9.68,100,1,10.61,200,2,11.27,100,1,11.4,100,1,11.76,100,1,11.93,200,2,12.23,100,1,12.34,200,2,12.36,200,2,13.55,15,1,13.56,100,1,13.59,100,1,13.83,100,1,13.92,2,1,14.19,100,1,14.28,100,1,14.43,100,1,14.51,100,1,14.53,100,1,ARL,324934601
2025-07-17T16:02:04.212956339Z,2025-07-17T16:02:04.212791108Z,160,2,1108,A,A,13.530000000,15,0,325382429,130,165231,271415821,ARL,0,13.53,15,130,165231,271415821,9.55,1700,17,9.68,100,1,10.61,200,2,11.27,100,1,11.4,100,1,11.76,100,1,11.93,200,2,12.23,100,1,12.34,200,2,12.36,200,2,13.53,15,1,13.55,15,1,13.56,100,1,13.59,100,1,13.83,100,1,13.92,2,1,14.19,100,1,14.28,100,1,14.43,100,1,14.51,100,1,ARL,325382429
2025-07-17T16:02:04.214348814Z,2025-07-17T16:02:04.214183279Z,160,2,1108,C,A,14.540000000,100,0,323775433,0,165535,271415834,ARL,0,14.54,100,0,165535,271415834,9.55,1700,17,9.68,100,1,10.61,200,2,11.27,100,1,11.4,100,1,11.76,100,1,11.93,200,2,12.23,100,1,12.34,200,2,12.36,200,2,13.53,15,1,13.55,15,1,13.56,100,1,13.59,100,1,13.83,100,1,13.92,2,1,14.19,100,1,14.28,100,1,14.43,100,1,14.51,100,1,ARL,323775433
2025-07-17T16:02:04.214348814Z,2025-07-17T16:02:04.214183279Z,160,2,1108,A,A,14.430000000,100,0,325382437,130,165535,271415834,ARL,0,14.43,100,130,165535,271415834,9.55,1700,17,9.68,100,1,10.61,200,2,11.27,100,1,11.4,100,1,11.76,100,1,11.93,200,2,12.23,100,1,12.34,200,2,12.36,200,2,13.53,15,1,13.55,15,1,13.56,100,1,13.59,100,1,13.83,100,1,13.92,2,1,14.19,100,1,14.28,100,1,14.43,200,2,14.51,100,1,ARL,325382437
2025-07-17T16:02:04.840132668Z,2025-07-17T16:02:04.839967173Z,160,2,1108,C,A,13.560000000,100,0,325176181,0,165495,271432190,ARL,0,13.56,100,0,165495,271432190,9.55,1700,17,9.68,100,1,10.61,200,2,11.27,100,1,11.4,100,1,11.76,100,1,11.93,200,2,12.23,100,1,12.34,200,2,12.36,200,2,13.53,15,1,13.55,15,1,13.59,100,1,13.83,100,1,13.92,2,1,14.19,100,1,14.28,100,1,14.43,200,2,14.51,100,1,14.53,100,1,ARL,325176181
2025-07-17T16:02:04.840132668Z,2025-07-17T16:02:04.839967173Z,160,2,1108,A,A,13.540000000,100,0,325400045,130,165495,271432190,ARL,0,13.54,100,130,165495,271432190,9.55,1700,17,9.68,100,1,10.61,200,2,11.27,100,1,11.4,100,1,11.76,100,1,11.93,200,2,12.23,100,1,12.34,200,2,12.36,200,2,13.53,15,1,13.54,100,1,13.55,15,1,13.59,100,1,13.83,100,1,13.92,2,1,14.19,100,1,14.28,100,1,14.43,200,2,14.51,100,1,ARL,325400045
2025-07-17T16:02:04.840171240Z,2025-07-17T16:02:04.840006082Z,160,2,1108,A,A,14.270000000,700,0,325400053,130,165158,271432192,ARL,0,14.27,700,130,165158,271432192,9.55,1700,17,9.68,100,1,10.61,200,2,11.27,100,1,11.4,100,1,11.76,100,1,11.93,200,2,12.23,100,1,12.34,200,2,12.36,200,2,13.53,15,1,13.54,100,1,13.55,15,1,13.59,100,1,13.83,100,1,13.92,2,1,14.19,100,1,14.27,700,1,14.28,100,1,14.43,200,2,ARL,325400053
2025-07-17T16:02:04.840210880Z,2025-07-17T16:02:04.840045694Z,160,2,1108,C,A,14.680000000,700,0,283592941,130,165186,271432193,ARL,0,14.68,700,130,165186,271432193,9.55,1700,17,9.68,100,1,10.61,200,2,11.27,100,1,11.4,100,1,11.76,100,1,11.93,200,2,12.23,100,1,12.34,200,2,12.36,200,2,13.53,15,1,13.54,100,1,13.55,15,1,13.59,100,1,13.83,100,1,13.92,2,1,14.19,100,1,14.27,700,1,14.28,100,1,14.43,200,2,ARL,283592941
2025-07-17T16:02:04.840877603Z,2025-07-17T16:02:04.840711803Z,160,2,1108,C,A,14.630000000,100,0,324942257,0,165800,271432231,ARL,0,14.63,100,0,165800,271432231,9.55,1700,17,9.68,100,1,10.61,200,2,11.27,100,1,11.4,100,1,11.76,100,1,11.93,200,2,12.23,100,1,12.34,200,2,12.36,200,2,13.53,15,1,13.54,100,1,13.55,15,1,13.59,100,1,13.83,100,1,13.92,2,1,14.19,100,1,14.27,700,1,14.28,100,1,14.43,200,2,ARL,324942257
2025-07-17T16:02:04.840877603Z,2025-07-17T16:02:04.840711803Z,160,2,1108,A,A,14.590000000,100,0,325400105,130,165800,271432231,ARL,0,14.59,100,130,165800,271432231,9.55,1700,17,9.68,100,1,10.61,200,2,11.27,100,1,11.4,100,1,11.76,100,1,11.93,200,2,12.23,100,1,12.34,200,2,12.36,200,2,13.53,15,1,13.54,100,1,13.55,15,1,13.59,100,1,13.83,100,1,13.92,2,1,14.19,100,1,14.27,700,1,14.28,100,1,14.43,200,2,ARL,325400105
2025-07-17T16:02:11.249291142Z,2025-07-17T16:02:11.249125653Z,160,2,1108,C,A,14.530000000,100,0,323775457,0,165489,271526467,ARL,0,14.53,100,0,165489,271526467,9.55,1700,17,9.68,100,1,10.61,200,2,11.27,100,1,11.4,100,1,11.76,100,1,11.93,200,2,12.23,100,1,12.34,200,2,12.36,200,2,13.53,15,1,13.54,100,1,13.55,15,1,13.59,100,1,13.83,100,1,13.92,2,1,14.19,100,1,14.27,700,1,14.28,100,1,14.43,200,2,ARL,323775457
2025-07-17T16:02:11.249291142Z,2025-07-17T16:02:11.249125653Z,160,2,1108,A,A,14.420000000,100,0,325520705,130,165489,271526467,ARL,0,14.42,100,130,165489,271526467,9.55,1700,17,9.68,100,1,10.61,200,2,11.27,100,1,11.4,100,1,11.76,100,1,11.93,200,2,12.23,100,1,12.34,200,2,12.36,200,2,13.53,15,1,13.54,100,1,13.55,15,1,13.59,100,1,13.83,100,1,13.92,2,1,14.19,100,1,14.27,700,1,14.28,100,1,14.42,100,1,ARL,325520705
2025-07-17T16:02:15.062774661Z,2025-07-17T16:02:15.062605521Z,160,2,1108,C,A,13.530000000,15,0,325382429,128,169140,271576282,ARL,0,13.53,15,128,169140,271576282,9.55,1700,17,9.68,100,1,10.61,200,2,11.27,100,1,11.4,100,1,11.76,100,1,11.93,200,2,12.23,100,1,12.34,200,2,12.36,200,2,13.54,100,1,13.55,15,1,13.59,100,1,13.83,100,1,13.92,2,1,14.19,100,1,14.27,700,1,14.28,100,1,14.42,100,1,14.43,200,2,ARL,325382429
2025-07-17T16:02:15.068449048Z,2025-07-17T16:02:15.068283706Z,160,2,1108,C,A,13.550000000,15,0,325109165,130,165342,271577104,ARL,0,13.55,15,130,165342,271577104,9.55,1700,17,9.68,100,1,10.61,200,2,11.27,100,1,11.4,100,1,11.76,100,1,11.93,200,2,12.23,100,1,12.34,200,2,12.36,200,2,13.54,100,1,13.59,100,1,13.83,100,1,13.92,2,1,14.19,100,1,14.27,700,1,14.28,100,1,14.42,100,1,14.43,200,2,14.51,100,1,ARL,325109165
2025-07-17T16:02:20.635028489Z,2025-07-17T16:02:20.634863301Z,160,2,1108,C,A,13.540000000,100,0,325400045,130,165188,271675842,ARL,0,13.54,100,130,165188,271675842,9.55,1700,17,9.68,100,1,10.61,200,2,11.27,100,1,11.4,100,1,11.76,100,1,11.93,200,2,12.23,100,1,12.34,200,2,12.36,200,2,13.59,100,1,13.83,100,1,13.92,2,1,14.19,100,1,14.27,700,1,14.28,100,1,14.42,100,1,14.43,200,2,14.51,100,1,14.56,800,2,ARL,325400045
2025-07-17T16:02:20.635782472Z,2025-07-17T16:02:20.635616654Z,160,2,1108,C,A,14.590000000,100,0,325400105,0,165818,271675858,ARL,0,14.59,100,0,165818,271675858,9.55,1700,17,9.68,100,1,10.61,200,2,11.27,100,1,11.4,100,1,11.76,100,1,11.93,200,2,12.23,100,1,12.34,200,2,12.36,200,2,13.59,100,1,13.83,100,1,13.92,2,1,14.19,100,1,14.27,700,1,14.28,100,1,14.42,100,1,14.43,200,2,14.51,100,1,14.56,800,2,ARL,325400105
2025-07-17T16:02:20.635782472Z,2025-07-17T16:02:20.635616654Z,160,2,1108,A,A,14.640000000,100,0,325714169,130,165818,271675858,ARL,0,14.64,100,130,165818,271675858,9.55,1700,17,9.68,100,1,10.61,200,2,11.27,100,1,11.4,100,1,11.76,100,1,11.93,200,2,12.23,100,1,12.34,200,2,12.36,200,2,13.59,100,1,13.83,100,1,13.92,2,1,14.19,100,1,14.27,700,1,14.28,100,1,14.42,100,1,14.43,200,2,14.51,100,1,14.56,800,2,ARL,325714169
2025-07-17T16:02:20.650466751Z,2025-07-17T16:02:20.650301212Z,160,2,1108,C,A,13.590000000,100,0,325022101,130,165539,271676032,ARL,0,13.59,100,130,165539,271676032,9.55,1700,17,9.68,100,1,10.61,200,2,11.27,100,1,11.4,100,1,11.76,100,1,11.93,200,2,12.23,100,1,12.34,200,2,12.36,200,2,13.83,100,1,13.92,2,1,14.19,100,1,14.27,700,1,14.28,100,1,14.42,100,1,14.43,200,2,14.51,100,1,14.56,800,2,14.57,100,1,ARL,325022101
2025-07-17T16:02:20.650501448Z,2025-07-17T16:02:20.650335946Z,160,2,1108,C,A,14.270000000,700,0,325400053,130,165502,271676033,ARL,0,14.27,700,130,165502,271676033,9.55,1700,17,9.68,100,1,10.61,200,2,11.27,100,1,11.4,100,1,11.76,100,1,11.93,200,2,12.23,100,1,12.34,200,2,12.36,200,2,13.83,100,1,13.92,2,1,14.19,100,1,14.28,100,1,14.42,100,1,14.43,200,2,14.51,100,1,14.56,800,2,14.57,100,1,14.6,700,1,ARL,325400053
2025-07-17T16:02:20.650546483Z,2025-07-17T16:02:20.650381040Z,160,2,1108,A,A,14.530000000,700,0,325714545,130,165443,271676035,ARL,0,14.53,700,130,165443,271676035,9.55,1700,17,9.68,100,1,10.61,200,2,11.27,100,1,11.4,100,1,11.76,100,1,11.93,200,2,12.23,100,1,12.34,200,2,12.36,200,2,13.83,100,1,13.92,2,1,14.19,100,1,14.28,100,1,14.42,100,1,14.43,200,2,14.51,100,1,14.53,700,1,14.56,800,2,14.57,100,1,ARL,325714545
2025-07-17T16:02:20.651186537Z,2025-07-17T16:02:20.651020858Z,160,2,1108,C,A,14.420000000,100,0,325520705,0,165679,271676048,ARL,0,14.42,100,0,165679,271676048,9.55,1700,17,9.68,100,1,10.61,200,2,11.27,100,1,11.4,100,1,11.76,100,1,11.93,200,2,12.23,100,1,12.34,200,2,12.36,200,2,13.83,100,1,13.92,2,1,14.19,100,1,14.28,100,1,14.43,200,2,14.51,100,1,14.53,700,1,14.56,800,2,14.57,100,1,14.6,700,1,ARL,325520705
2025-07-17T16:02:20.651186537Z,2025-07-17T16:02:20.651020858Z,160,2,1108,A,A,14.730000000,100,0,325714577,130,165679,271676048,ARL,0,14.73,100,130,165679,271676048,9.55,1700,17,9.68,100,1,10.61,200,2,11.27,100,1,11.4,100,1,11.76,100,1,11.93,200,2,12.23,100,1,12.34,200,2,12.36,200,2,13.83,100,1,13.92,2,1,14.19,100,1,14.28,100,1,14.43,200,2,14.51,100,1,14.53,700,1,14.56,800,2,14.57,100,1,14.6,700,1,ARL,325714577
2025-07-17T16:02:20.651201182Z,2025-07-17T16:02:20.651035000Z,160,2,1108,C,A,14.190000000,100,0,324942273,130,166182,271676049,ARL,0,14.19,100,130,166182,271676049,9.55,1700,17,9.68,100,1,10.61,200,2,11.27,100,1,11.4,100,1,11.76,100,1,11.93,200,2,12.23,100,1,12.34,200,2,12.36,200,2,13.83,100,1,13.92,2,1,14.28,100,1,14.43,200,2,14.51,100,1,14.53,700,1,14.56,800,2,14.57,100,1,14.6,700,1,14.64,100,1,ARL,324942273
2025-07-17T16:02:20.651459317Z,2025-07-17T16:02:20.651293729Z,160,2,1108,C,A,17.250000000,100,0,324942361,0,165588,271676055,ARL,0,17.25,100,0,165588,271676055,9.55,1700,17,9.68,100,1,10.61,200,2,11.27,100,1,11.4,100,1,11.76,100,1,11.93,200,2,12.23,100,1,12.34,200,2,12.36,200,2,13.83,100,1,13.92,2,1,14.28,100,1,14.43,200,2,14.51,100,1,14.53,700,1,14.56,800,2,14.57,100,1,14.6,700,1,14.64,100,1,ARL,324942361
2025-07-17T16:02:20.651459317Z,2025-07-17T16:02:20.651293729Z,160,2,1108,A,A,17.570000000,100,0,325714589,130,165588,271676055,ARL,0,17.57,100,130,165588,271676055,9.55,1700,17,9.68,100,1,10.61,200,2,11.27,100,1,11.4,100,1,11.76,100,1,11.93,200,2,12.23,100,1,12.34,200,2,12.36,200,2,13.83,100,1,13.92,2,1,14.28,100,1,14.43,200,2,14.51,100,1,14.53,700,1,14.56,800,2,14.57,100,1,14.6,700,1,14.64,100,1,ARL,325714589
2025-07-17T16:02:20.651558948Z,2025-07-17T16:02:20.651393708Z,160,2,1108,A,A,14.450000000,100,0,325714601,130,165240,271676057,ARL,0,14.45,100,130,165240,271676057,9.55,1700,17,9.68,100,1,10.61,200,2,11.27,100,1,11.4,100,1,11.76,100,1,11.93,200,2,12.23,100,1,12.34,200,2,12.36,200,2,13.83,100,1,13.92,2,1,14.28,100,1,14.43,200,2,14.45,100,1,14.51,100,1,14.53,700,1,14.56,800,2,14.57,100,1,14.6,700,1,ARL,325714601
2025-07-17T16:02:20.651787813Z,2025-07-17T16:02:20.651618897Z,160,2,1108,C,A,14.430000000,100,0,325382437,0,168916,271676089,ARL,0,14.43,100,0,168916,271676089,9.55,1700,17,9.68,100,1,10.61,200,2,11.27,100,1,11.4,100,1,11.76,100,1,11.93,200,2,12.23,100,1,12.34,200,2,12.36,200,2,13.83,100,1,13.92,2,1,14.28,100,1,14.43,100,1,14.45,100,1,14.51,100,1,14.53,700,1,14.56,800,2,14.57,100,1,14.6,700,1,ARL,325382437
2025-07-17T16:02:20.651787813Z,2025-07-17T16:02:20.651618897Z,160,2,1108,A,A,14.730000000,100,0,325714613,128,168916,271676089,ARL,0,14.73,100,128,168916,271676089,9.55,1700,17,9.68,100,1,10.61,200,2,11.27,100,1,11.4,100,1,11.76,100,1,11.93,200,2,12.23,100,1,12.34,200,2,12.36,200,2,13.83,100,1,13.92,2,1,14.28,100,1,14.43,100,1,14.45,100,1,14.51,100,1,14.53,700,1,14.56,800,2,14.57,100,1,14.6,700,1,ARL,325714613
2025-07-17T16:02:20.652021618Z,2025-07-17T16:02:20.651854531Z,160,2,1108,C,A,14.570000000,100,0,324619409,0,167087,271676104,ARL,0,14.57,100,0,167087,271676104,9.55,1700,17,9.68,100,1,10.61,200,2,11.27,100,1,11.4,100,1,11.76,100,1,11.93,200,2,12.23,100,1,12.34,200,2,12.36,200,2,13.83,100,1,13.92,2,1,14.28,100,1,14.43,100,1,14.45,100,1,14.51,100,1,14.53,700,1,14.56,800,2,14.6,700,1,14.64,100,1,ARL,324619409
2025-07-17T16:02:20.652021618Z,2025-07-17T16:02:20.651854531Z,160,2,1108,A,A,14.800000000,100,0,325714629,130,167087,271676104,ARL,0,14.8,100,130,167087,271676104,9.55,1700,17,9.68,100,1,10.61,200,2,11.27,100,1,11.4,100,1,11.76,100,1,11.93,200,2,12.23,100,1,12.34,200,2,12.36,200,2,13.83,100,1,13.92,2,1,14.28,100,1,14.43,100,1,14.45,100,1,14.51,100,1,14.53,700,1,14.56,800,2,14.6,700,1,14.64,100,1,ARL,325714629
2025-07-17T16:02:20.652097288Z,2025-07-17T16:02:20.651932129Z,160,2,1108,C,A,14.430000000,100,0,324186781,130,165159,271676110,ARL,0,14.43,100,130,165159,271676110,9.55,1700,17,9.68,100,1,10.61,200,2,11.27,100,1,11.4,100,1,11.76,100,1,11.93,200,2,12.23,100,1,12.34,200,2,12.36,200,2,13.83,100,1,13.92,2,1,14.28,100,1,14.45,100,1,14.51,100,1,14.53,700,1,14.56,800,2,14.6,700,1,14.64,100,1,14.68,700,1,ARL,324186781
2025-07-17T16:02:20.652160470Z,2025-07-17T16:02:20.651994883Z,160,2,1108,C,A,15.600000000,100,0,325176677,0,165587,271676111,ARL,0,15.6,100,0,165587,271676111,9.55,1700,17,9.68,100,1,10.61,200,2,11.27,100,1,11.4,100,1,11.76,100,1,11.93,200,2,12.23,100,1,12.34,200,2,12.36,200,2,13.83,100,1,13.92,2,1,14.28,100,1,14.45,100,1,14.51,100,1,14.53,700,1,14.56,800,2,14.6,700,1,14.64,100,1,14.68,700,1,ARL,325176677
2025-07-17T16:02:20.652160470Z,2025-07-17T16:02:20.651994883Z,160,2,1108,A,A,15.910000000,100,0,325714633,130,165587,271676111,ARL,0,15.91,100,130,165587,271676111,9.55,1700,17,9.68,100,1,10.61,200,2,11.27,100,1,11.4,100,1,11.76,100,1,11.93,200,2,12.23,100,1,12.34,200,2,12.36,200,2,13.83,100,1,13.92,2,1,14.28,100,1,14.45,100,1,14.51,100,1,14.53,700,1,14.56,800,2,14.6,700,1,14.64,100,1,14.68,700,1,ARL,325714633
2025-07-17T16:02:20.652259931Z,2025-07-17T16:02:20.652094426Z,160,2,1108,A,A,14.630000000,100,0,325714653,130,165505,271676118,ARL,0,14.63,100,130,165505,271676118,9.55,1700,17,9.68,100,1,10.61,200,2,11.27,100,1,11.4,100,1,11.76,100,1,11.93,200,2,12.23,100,1,12.34,200,2,12.36,200,2,13.83,100,1,13.92,2,1,14.28,100,1,14.45,100,1,14.51,100,1,14.53,700,1,14.56,800,2,14.6,700,1,14.63,100,1,14.64,100,1,ARL,325714653
2025-07-17T16:02:20.653626391Z,2025-07-17T16:02:20.653460814Z,160,2,1108,A,B,13.270000000,10,0,325714717,130,165577,271676147,ARL,0,13.27,10,130,165577,271676147,9.55,1700,17,9.68,100,1,10.61,200,2,11.27,100,1,11.4,100,1,11.76,100,1,11.93,200,2,12.23,100,1,12.34,200,2,12.36,200,2,13.83,100,1,13.92,2,1,14.28,100,1,14.45,100,1,14.51,100,1,14.53,700,1,14.56,800,2,14.6,700,1,14.63,100,1,14.64,100,1,ARL,325714717
2025-07-17T16:02:20.653627232Z,2025-07-17T16:02:20.653461966Z,160,2,1108,A,A,13.830000000,15,0,325714721,130,165266,271676148,ARL,0,13.83,15,130,165266,271676148,9.55,1700,17,9.68,100,1,10.61,200,2,11.27,100,1,11.4,100,1,11.76,100,1,11.93,200,2,12.23,100,1,12.34,200,2,12.36,200,2,13.83,115,2,13.92,2,1,14.28,100,1,14.45,100,1,14.51,100,1,14.53,700,1,14.56,800,2,14.6,700,1,14.63,100,1,14.64,100,1,ARL,325714721
2025-07-17T16:02:20.653886896Z,2025-07-17T16:02:20.653721185Z,160,2,1108,C,B,13.020000000,100,0,320485385,0,165711,271676153,ARL,0,13.02,100,0,165711,271676153,9.55,1700,17,9.68,100,1,10.61,200,2,11.27,100,1,11.4,100,1,11.76,100,1,11.93,200,2,12.23,100,1,12.34,200,2,12.36,200,2,13.83,115,2,13.92,2,1,14.28,100,1,14.45,100,1,14.51,100,1,14.53,700,1,14.56,800,2,14.6,700,1,14.63,100,1,14.64,100,1,ARL,320485385
2025-07-17T16:02:20.653886896Z,2025-07-17T16:02:20.653721185Z,160,2,1108,A,B,13.260000000,100,0,325714729,130,165711,271676153,ARL,0,13.26,100,130,165711,271676153,9.55,1700,17,9.68,100,1,10.61,200,2,11.27,100,1,11.4,100,1,11.76,100,1,11.93,200,2,12.23,100,1,12.34,200,2,12.36,200,2,13.83,115,2,13.92,2,1,14.28,100,1,14.45,100,1,14.51,100,1,14.53,700,1,14.56,800,2,14.6,700,1,14.63,100,1,14.64,100,1,ARL,325714729
2025-07-17T16:02:20.655277066Z,2025-07-17T16:02:20.655111649Z,160,2,1108,C,B,13.040000000,2,0,293594281,0,165417,271676165,ARL,0,13.04,2,0,165417,271676165,9.55,1700,17,9.68,100,1,10.61,200,2,11.27,100,1,11.4,100,1,11.76,100,1,11.93,200,2,12.23,100,1,12.34,200,2,12.36,200,2,13.83,115,2,13.92,2,1,14.28,100,1,14.45,100,1,14.51,100,1,14.53,700,1,14.56,800,2,14.6,700,1,14.63,100,1,14.64,100,1,ARL,293594281
2025-07-17T16:02:20.655277066Z,2025-07-17T16:02:20.655111649Z,160,2,1108,A,B,12.910000000,2,0,325714741,130,165417,271676165,ARL,0,12.91,2,130,165417,271676165,9.55,1700,17,9.68,100,1,10.61,200,2,11.27,100,1,11.4,100,1,11.76,100,1,11.93,200,2,12.23,100,1,12.34,200,2,12.36,200,2,13.83,115,2,13.92,2,1,14.28,100,1,14.45,100,1,14.51,100,1,14.53,700,1,14.56,800,2,14.6,700,1,14.63,100,1,14.64,100,1,ARL,325714741
2025-07-17T16:02:20.663374576Z,2025-07-17T16:02:20.663209235Z,160,2,1108,C,A,13.830000000,100,0,325176373,130,165341,271676274,ARL,0,13.83,100,130,165341,271676274,9.55,1700,17,9.68,100,1,10.61,200,2,11.27,100,1,11.4,100,1,11.76,100,1,11.93,200,2,12.23,100,1,12.34,200,2,12.36,200,2,13.83,15,1,13.92,2,1,14.28,100,1,14.45,100,1,14.51,100,1,14.53,700,1,14.56,800,2,14.6,700,1,14.63,100,1,14.64,100,1,ARL,325176373
2025-07-17T16:02:20.663406861Z,2025-07-17T16:02:20.663241882Z,160,2,1108,C,A,14.530000000,700,0,325714545,130,164979,271676275,ARL,0,14.53,700,130,164979,271676275,9.55,1700,17,9.68,100,1,10.61,200,2,11.27,100,1,11.4,100,1,11.76,100,1,11.93,200,2,12.23,100,1,12.34,200,2,12.36,200,2,13.83,15,1,13.92,2,1,14.28,100,1,14.45,100,1,14.51,100,1,14.56,800,2,14.6,700,1,14.63,100,1,14.64,100,1,14.68,700,1,ARL,325714545
2025-07-17T16:02:20.663426974Z,2025-07-17T16:02:20.663261632Z,160,2,1108,A,A,14.110000000,100,0,325714905,130,165342,271676276,ARL,0,14.11,100,130,165342,271676276,9.55,1700,17,9.68,100,1,10.61,200,2,11.27,100,1,11.4,100,1,11.76,100,1,11.93,200,2,12.23,100,1,12.34,200,2,12.36,200,2,13.83,15,1,13.92,2,1,14.11,100,1,14.28,100,1,14.45,100,1,14.51,100,1,14.56,800,2,14.6,700,1,14.63,100,1,14.64,100,1,ARL,325714905
2025-07-17T16:02:20.663559466Z,2025-07-17T16:02:20.663394059Z,160,2,1108,A,A,15.940000000,100,0,325714909,130,165407,271676277,ARL,0,15.94,100,130,165407,271676277,9.55,1700,17,9.68,100,1,10.61,200,2,11.27,100,1,11.4,100,1,11.76,100,1,11.93,200,2,12.23,100,1,12.34,200,2,12.36,200,2,13.83,15,1,13.92,2,1,14.11,100,1,14.28,100,1,14.45,100,1,14.51,100,1,14.56,800,2,14.6,700,1,14.63,100,1,14.64,100,1,ARL,325714909
2025-07-17T16:02:20.663572634Z,2025-07-17T16:02:20.663407337Z,160,2,1108,C,A,15.590000000,100,0,323730697,130,165297,271676278,ARL,0,15.59,100,130,165297,271676278,9.55,1700,17,9.68,100,1,10.61,200,2,11.27,100,1,11.4,100,1,11.76,100,1,11.93,200,2,12.23,100,1,12.34,200,2,12.36,200,2,13.83,15,1,13.92,2,1,14.11,100,1,14.28,100,1,14.45,100,1,14.51,100,1,14.56,800,2,14.6,700,1,14.63,100,1,14.64,100,1,ARL,323730697
2025-07-17T16:02:20.664956400Z,2025-07-17T16:02:20.664790768Z,160,2,1108,C,A,17.570000000,100,0,325714589,0,165632,271676310,ARL,0,17.57,100,0,165632,271676310,9.55,1700,17,9.68,100,1,10.61,200,2,11.27,100,1,11.4,100,1,11.76,100,1,11.93,200,2,12.23,100,1,12.34,200,2,12.36,200,2,13.83,15,1,13.92,2,1,14.11,100,1,14.28,100,1,14.45,100,1,14.51,100,1,14.56,800,2,14.6,700,1,14.63,100,1,14.64,100,1,ARL,325714589
2025-07-17T16:02:20.664956400Z,2025-07-17T16:02:20.664790768Z,160,2,1108,A,A,17.760000000,100,0,325714949,130,165632,271676310,ARL,0,17.76,100,130,165632,271676310,9.55,1700,17,9.68,100,1,10.61,200,2,11.27,100,1,11.4,100,1,11.76,100,1,11.93,200,2,12.23,100,1,12.34,200,2,12.36,200,2,13.83,15,1,13.92,2,1,14.11,100,1,14.28,100,1,14.45,100,1,14.51,100,1,14.56,800,2,14.6,700,1,14.63,100,1,14.64,100,1,ARL,325714949
2025-07-17T16:02:20.665129279Z,2025-07-17T16:02:20.664963386Z,160,2,1108,C,A,14.800000000,100,0,325714629,0,165893,271676320,ARL,0,14.8,100,0,165893,271676320,9.55,1700,17,9.68,100,1,10.61,200,2,11.27,100,1,11.4,100,1,11.76,100,1,11.93,200,2,12.23,100,1,12.34,200,2,12.36,200,2,13.83,15,1,13.92,2,1,14.11,100,1,14.28,100,1,14.45,100,1,14.51,100,1,14.56,800,2,14.6,700,1,14.63,100,1,14.64,100,1,ARL,325714629
2025-07-17T16:02:20.665129279Z,2025-07-17T16:02:20.664963386Z,160,2,1108,A,A,14.960000000,100,0,325714953,130,165893,271676320,ARL,0,14.96,100,130,165893,271676320,9.55,1700,17,9.68,100,1,10.61,200,2,11.27,100,1,11.4,100,1,11.76,100,1,11.93,200,2,12.23,100,1,12.34,200,2,12.36,200,2,13.83,15,1,13.92,2,1,14.11,100,1,14.28,100,1,14.45,100,1,14.51,100,1,14.56,800,2,14.6,700,1,14.63,100,1,14.64,100,1,ARL,325714953
2025-07-17T16:02:20.665200392Z,2025-07-17T16:02:20.665034825Z,160,2,1108,C,A,15.910000000,100,0,325714633,0,165567,271676330,ARL,0,15.91,100,0,165567,271676330,9.55,1700,17,9.68,100,1,10.61,200,2,11.27,100,1,11.4,100,1,11.76,100,1,11.93,200,2,12.23,100,1,12.34,200,2,12.36,200,2,13.83,15,1,13.92,2,1,14.11,100,1,14.28,100,1,14.45,100,1,14.51,100,1,14.56,800,2,14.6,700,1,14.63,100,1,14.64,100,1,ARL,325714633
2025-07-17T16:02:20.665200392Z,2025-07-17T16:02:20.665034825Z,160,2,1108,A,A,16.080000000,100,0,325714957,130,165567,271676330,ARL,0,16.08,100,130,165567,271676330,9.55,1700,17,9.68,100,1,10.61,200,2,11.27,100,1,11.4,100,1,11.76,100,1,11.93,200,2,12.23,100,1,12.34,200,2,12.36,200,2,13.83,15,1,13.92,2,1,14.11,100,1,14.28,100,1,14.45,100,1,14.51,100,1,14.56,800,2,14.6,700,1,14.63,100,1,14.64,100,1,ARL,325714957
2025-07-17T16:02:20.665457595Z,2025-07-17T16:02:20.665292049Z,160,2,1108,C,A,14.940000000,100,0,324942277,0,165546,271676355,ARL,0,14.94,100,0,165546,271676355,9.55,1700,17,9.68,100,1,10.61,200,2,11.27,100,1,11.4,100,1,11.76,100,1,11.93,200,2,12.23,100,1,12.34,200,2,12.36,200,2,13.83,15,1,13.92,2,1,14.11,100,1,14.28,100,1,14.45,100,1,14.51,100,1,14.56,800,2,14.6,700,1,14.63,100,1,14.64,100,1,ARL,324942277
2025-07-17T16:02:20.665457595Z,2025-07-17T16:02:20.665292049Z,160,2,1108,A,A,15.380000000,100,0,325714965,130,165546,271676355,ARL,0,15.38,100,130,165546,271676355,9.55,1700,17,9.68,100,1,10.61,200,2,11.27,100,1,11.4,100,1,11.76,100,1,11.93,200,2,12.23,100,1,12.34,200,2,12.36,200,2,13.83,15,1,13.92,2,1,14.11,100,1,14.28,100,1,14.45,100,1,14.51,100,1,14.56,800,2,14.6,700,1,14.63,100,1,14.64,100,1,ARL,325714965
2025-07-17T16:02:20.669701452Z,2025-07-17T16:02:20.669536385Z,160,2,1108,C,A,14.110000000,100,0,325714905,130,165067,271676398,ARL,0,14.11,100,130,165067,271676398,9.55,1700,17,9.68,100,1,10.61,200,2,11.27,100,1,11.4,100,1,11.76,100,1,11.93,200,2,12.23,100,1,12.34,200,2,12.36,200,2,13.83,15,1,13.92,2,1,14.28,100,1,14.45,100,1,14.51,100,1,14.56,800,2,14.6,700,1,14.63,100,1,14.64,100,1,14.68,700,1,ARL,325714905
2025-07-17T16:02:20.669748954Z,2025-07-17T16:02:20.669583810Z,160,2,1108,A,A,14.260000000,100,0,325715045,130,165144,271676399,ARL,0,14.26,100,130,165144,271676399,9.55,1700,17,9.68,100,1,10.61,200,2,11.27,100,1,11.4,100,1,11.76,100,1,11.93,200,2,12.23,100,1,12.34,200,2,12.36,200,2,13.83,15,1,13.92,2,1,14.26,100,1,14.28,100,1,14.45,100,1,14.51,100,1,14.56,800,2,14.6,700,1,14.63,100,1,14.64,100,1,ARL,325715045
2025-07-17T16:02:20.669752979Z,2025-07-17T16:02:20.669587514Z,160,2,1108,C,A,14.510000000,100,0,325177757,0,165465,271676400,ARL,0,14.51,100,0,165465,271676400,9.55,1700,17,9.68,100,1,10.61,200,2,11.27,100,1,11.4,100,1,11.76,100,1,11.93,200,2,12.23,100,1,12.34,200,2,12.36,200,2,13.83,15,1,13.92,2,1,14.26,100,1,14.28,100,1,14.45,100,1,14.56,800,2,14.6,700,1,14.63,100,1,14.64,100,1,14.68,700,1,ARL,325177757
2025-07-17T16:02:20.669752979Z,2025-07-17T16:02:20.669587514Z,160,2,1108,A,A,14.960000000,100,0,325715053,130,165465,271676400,ARL,0,14.96,100,130,165465,271676400,9.55,1700,17,9.68,100,1,10.61,200,2,11.27,100,1,11.4,100,1,11.76,100,1,11.93,200,2,12.23,100,1,12.34,200,2,12.36,200,2,13.83,15,1,13.92,2,1,14.26,100,1,14.28,100,1,14.45,100,1,14.56,800,2,14.6,700,1,14.63,100,1,14.64,100,1,14.68,700,1,ARL,325715053
2025-07-17T16:02:20.685252049Z,2025-07-17T16:02:20.685086585Z,160,2,1108,C,A,14.640000000,100,0,325714169,0,165464,271676621,ARL,0,14.64,100,0,165464,271676621,9.55,1700,17,9.68,100,1,10.61,200,2,11.27,100,1,11.4,100,1,11.76,100,1,11.93,200,2,12.23,100,1,12.34,200,2,12.36,200,2,13.83,15,1,13.92,2,1,14.26,100,1,14.28,100,1,14.45,100,1,14.56,800,2,14.6,700,1,14.63,100,1,14.68,700,1,14.73,200,2,ARL,325714169
2025-07-17T16:02:20.685252049Z,2025-07-17T16:02:20.685086585Z,160,2,1108,A,A,15.060000000,100,0,325715113,130,165464,271676621,ARL,0,15.06,100,130,165464,271676621,9.55,1700,17,9.68,100,1,10.61,200,2,11.27,100,1,11.4,100,1,11.76,100,1,11.93,200,2,12.23,100,1,12.34,200,2,12.36,200,2,13.83,15,1,13.92,2,1,14.26,100,1,14.28,100,1,14.45,100,1,14.56,800,2,14.6,700,1,14.63,100,1,14.68,700,1,14.73,200,2,ARL,325715113
2025-07-17T16:02:20.832112637Z,2025-07-17T16:02:20.831947250Z,160,2,1108,A,A,14.680000000,700,0,325716945,130,165387,271678584,ARL,0,14.68,700,130,165387,271678584,9.55,1700,17,9.68,100,1,10.61,200,2,11.27,100,1,11.4,100,1,11.76,100,1,11.93,200,2,12.23,100,1,12.34,200,2,12.36,200,2,13.83,15,1,13.92,2,1,14.26,100,1,14.28,100,1,14.45,100,1,14.56,800,2,14.6,700,1,14.63,100,1,14.68,1400,2,14.73,200,2,ARL,325716945
2025-07-17T16:02:20.936787418Z,2025-07-17T16:02:20.936622241Z,160,2,1108,C,B,13.260000000,100,0,325714729,130,165177,271679553,ARL,0,13.26,100,130,165177,271679553,9.55,1700,17,9.68,100,1,10.61,200,2,11.27,100,1,11.4,100,1,11.76,100,1,11.93,200,2,12.23,100,1,12.34,200,2,12.36,200,2,13.83,15,1,13.92,2,1,14.26,100,1,14.28,100,1,14.45,100,1,14.56,800,2,14.6,700,1,14.63,100,1,14.68,1400,2,14.73,200,2,ARL,325714729
2025-07-17T16:02:20.936837611Z,2025-07-17T16:02:20.936672130Z,160,2,1108,A,A,13.910000000,5,0,325718477,130,165481,271679555,ARL,0,13.91,5,130,165481,271679555,9.55,1700,17,9.68,100,1,10.61,200,2,11.27,100,1,11.4,100,1,11.76,100,1,11.93,200,2,12.23,100,1,12.34,200,2,12.36,200,2,13.83,15,1,13.91,5,1,13.92,2,1,14.26,100,1,14.28,100,1,14.45,100,1,14.56,800,2,14.6,700,1,14.63,100,1,14.68,1400,2,ARL,325718477
2025-07-17T16:02:20.936914901Z,2025-07-17T16:02:20.936748894Z,160,2,1108,T,N,13.280000000,11,0,0,130,166007,271679557,ARL,0,13.28,11,130,166007,271679557,9.55,1700,17,9.68,100,1,10.61,200,2,11.27,100,1,11.4,100,1,11.76,100,1,11.93,200,2,12.23,100,1,12.34,200,2,12.36,200,2,13.83,15,1,13.91,5,1,13.92,2,1,14.26,100,1,14.28,100,1,14.45,100,1,14.56,800,2,14.6,700,1,14.63,100,1,14.68,1400,2,ARL,0
2025-07-17T16:02:20.936999211Z,2025-07-17T16:02:20.936833988Z,160,2,1108,A,A,13.840000000,100,0,325718485,130,165223,271679558,ARL,0,13.84,100,130,165223,271679558,9.55,1700,17,9.68,100,1,10.61,200,2,11.27,100,1,11.4,100,1,11.76,100,1,11.93,200,2,12.23,100,1,12.34,200,2,12.36,200,2,13.83,15,1,13.84,100,1,13.91,5,1,13.92,2,1,14.26,100,1,14.28,100,1,14.45,100,1,14.56,800,2,14.6,700,1,14.63,100,1,ARL,325718485
2025-07-17T16:02:20.937307935Z,2025-07-17T16:02:20.937142186Z,160,2,1108,T,N,13.280000000,11,0,0,130,165749,271679562,ARL,0,13.28,11,130,165749,271679562,9.55,1700,17,9.68,100,1,10.61,200,2,11.27,100,1,11.4,100,1,11.76,100,1,11.93,200,2,12.23,100,1,12.34,200,2,12.36,200,2,13.83,15,1,13.84,100,1,13.91,5,1,13.92,2,1,14.26,100,1,14.28,100,1,14.45,100,1,14.56,800,2,14.6,700,1,14.63,100,1,ARL,0
2025-07-17T16:02:20.937744264Z,2025-07-17T16:02:20.937578907Z,160,2,1108,C,A,15.060000000,100,0,325715113,0,165357,271679565,ARL,0,15.06,100,0,165357,271679565,9.55,1700,17,9.68,100,1,10.61,200,2,11.27,100,1,11.4,100,1,11.76,100,1,11.93,200,2,12.23,100,1,12.34,200,2,12.36,200,2,13.83,15,1,13.84,100,1,13.91,5,1,13.92,2,1,14.26,100,1,14.28,100,1,14.45,100,1,14.56,800,2,14.6,700,1,14.63,100,1,ARL,325715113
2025-07-17T16:02:20.937744264Z,2025-07-17T16:02:20.937578907Z,160,2,1108,A,A,14.910000000,100,0,325718509,130,165357,271679565,ARL,0,14.91,100,130,165357,271679565,9.55,1700,17,9.68,100,1,10.61,200,2,11.27,100,1,11.4,100,1,11.76,100,1,11.93,200,2,12.23,100,1,12.34,200,2,12.36,200,2,13.83,15,1,13.84,100,1,13.91,5,1,13.92,2,1,14.26,100,1,14.28,100,1,14.45,100,1,14.56,800,2,14.6,700,1,14.63,100,1,ARL,325718509
2025-07-17T16:02:20.937901293Z,2025-07-17T16:02:20.937736247Z,160,2,1108,C,A,13.910000000,5,0,325718477,130,165046,271679567,ARL,0,13.91,5,130,165046,271679567,9.55,1700,17,9.68,100,1,10.61,200,2,11.27,100,1,11.4,100,1,11.76,100,1,11.93,200,2,12.23,100,1,12.34,200,2,12.36,200,2,13.83,15,1,13.84,100,1,13.92,2,1,14.26,100,1,14.28,100,1,14.45,100,1,14.56,800,2,14.6,700,1,14.63,100,1,14.68,1400,2,ARL,325718477
2025-07-17T16:02:20.938093286Z,2025-07-17T16:02:20.937927380Z,160,2,1108,C,A,14.960000000,100,0,325715053,0,165906,271679569,ARL,0,14.96,100,0,165906,271679569,9.55,1700,17,9.68,100,1,10.61,200,2,11.27,100,1,11.4,100,1,11.76,100,1,11.93,200,2,12.23,100,1,12.34,200,2,12.36,200,2,13.83,15,1,13.84,100,1,13.92,2,1,14.26,100,1,14.28,100,1,14.45,100,1,14.56,800,2,14.6,700,1,14.63,100,1,14.68,1400,2,ARL,325715053
2025-07-17T16:02:20.938093286Z,2025-07-17T16:02:20.937927380Z,160,2,1108,A,A,14.810000000,100,0,325718517,130,165906,271679569,ARL,0,14.81,100,130,165906,271679569,9.55,1700,17,9.68,100,1,10.61,200,2,11.27,100,1,11.4,100,1,11.76,100,1,11.93,200,2,12.23,100,1,12.34,200,2,12.36,200,2,13.83,15,1,13.84,100,1,13.92,2,1,14.26,100,1,14.28,100,1,14.45,100,1,14.56,800,2,14.6,700,1,14.63,100,1,14.68,1400,2,ARL,325718517
2025-07-17T16:02:20.938297839Z,2025-07-17T16:02:20.938132716Z,160,2,1108,C,A,16.080000000,100,0,325714957,0,165123,271679571,ARL,0,16.08,100,0,165123,271679571,9.55,1700,17,9.68,100,1,10.61,200,2,11.27,100,1,11.4,100,1,11.76,100,1,11.93,200,2,12.23,100,1,12.34,200,2,12.36,200,2,13.83,15,1,13.84,100,1,13.92,2,1,14.26,100,1,14.28,100,1,14.45,100,1,14.56,800,2,14.6,700,1,14.63,100,1,14.68,1400,2,ARL,325714957
2025-07-17T16:02:20.938297839Z,2025-07-17T16:02:20.938132716Z,160,2,1108,A,A,15.920000000,100,0,325718525,130,165123,271679571,ARL,0,15.92,100,130,165123,271679571,9.55,1700,17,9.68,100,1,10.61,200,2,11.27,100,1,11.4,100,1,11.76,100,1,11.93,200,2,12.23,100,1,12.34,200,2,12.36,200,2,13.83,15,1,13.84,100,1,13.92,2,1,14.26,100,1,14.28,100,1,14.45,100,1,14.56,800,2,14.6,700,1,14.63,100,1,14.68,1400,2,ARL,325718525
2025-07-17T16:02:20.938616654Z,2025-07-17T16:02:20.938451331Z,160,2,1108,C,A,14.960000000,100,0,325714953,0,165323,271679575,ARL,0,14.96,100,0,165323,271679575,9.55,1700,17,9.68,100,1,10.61,200,2,11.27,100,1,11.4,100,1,11.76,100,1,11.93,200,2,12.23,100,1,12.34,200,2,12.36,200,2,13.83,15,1,13.84,100,1,13.92,2,1,14.26,100,1,14.28,100,1,14.45,100,1,14.56,800,2,14.6,700,1,14.63,100,1,14.68,1400,2,ARL,325714953
2025-07-17T16:02:20.938616654Z,2025-07-17T16:02:20.938451331Z,160,2,1108,A,A,14.810000000,100,0,325718549,130,165323,271679575,ARL,0,14.81,100,130,165323,271679575,9.55,1700,17,9.68,100,1,10.61,200,2,11.27,100,1,11.4,100,1,11.76,100,1,11.93,200,2,12.23,100,1,12.34,200,2,12.36,200,2,13.83,15,1,13.84,100,1,13.92,2,1,14.26,100,1,14.28,100,1,14.45,100,1,14.56,800,2,14.6,700,1,14.63,100,1,14.68,1400,2,ARL,325718549
2025-07-17T16:02:20.938889819Z,2025-07-17T16:02:20.938724516Z,160,2,1108,C,A,17.760000000,100,0,325714949,0,165303,271679576,ARL,0,17.76,100,0,165303,271679576,9.55,1700,17,9.68,100,1,10.61,200,2,11.27,100,1,11.4,100,1,11.76,100,1,11.93,200,2,12.23,100,1,12.34,200,2,12.36,200,2,13.83,15,1,13.84,100,1,13.92,2,1,14.26,100,1,14.28,100,1,14.45,100,1,14.56,800,2,14.6,700,1,14.63,100,1,14.68,1400,2,ARL,325714949
2025-07-17T16:02:20.938889819Z,2025-07-17T16:02:20.938724516Z,160,2,1108,A,A,17.580000000,100,0,325718557,130,165303,271679576,ARL,0,17.58,100,130,165303,271679576,9.55,1700,17,9.68,100,1,10.61,200,2,11.27,100,1,11.4,100,1,11.76,100,1,11.93,200,2,12.23,100,1,12.34,200,2,12.36,200,2,13.83,15,1,13.84,100,1,13.92,2,1,14.26,100,1,14.28,100,1,14.45,100,1,14.56,800,2,14.6,700,1,14.63,100,1,14.68,1400,2,ARL,325718557
2025-07-17T16:02:20.939554686Z,2025-07-17T16:02:20.939389367Z,160,2,1108,A,B,13.020000000,100,0,325718561,130,165319,271679578,ARL,0,13.02,100,130,165319,271679578,9.55,1700,17,9.68,100,1,10.61,200,2,11.27,100,1,11.4,100,1,11.76,100,1,11.93,200,2,12.23,100,1,12.34,200,2,12.36,200,2,13.83,15,1,13.84,100,1,13.92,2,1,14.26,100,1,14.28,100,1,14.45,100,1,14.56,800,2,14.6,700,1,14.63,100,1,14.68,1400,2,ARL,325718561
2025-07-17T16:02:20.946406202Z,2025-07-17T16:02:20.946240970Z,160,2,1108,C,A,14.260000000,100,0,325715045,130,165232,271679616,ARL,0,14.26,100,130,165232,271679616,9.55,1700,17,9.68,100,1,10.61,200,2,11.27,100,1,11.4,100,1,11.76,100,1,11.93,200,2,12.23,100,1,12.34,200,2,12.36,200,2,13.83,15,1,13.84,100,1,13.92,2,1,14.28,100,1,14.45,100,1,14.56,800,2,14.6,700,1,14.63,100,1,14.68,1400,2,14.73,200,2,ARL,325715045
2025-07-17T16:02:20.946456786Z,2025-07-17T16:02:20.946291345Z,160,2,1108,A,A,14.120000000,100,0,325718637,130,165441,271679617,ARL,0,14.12,100,130,165441,271679617,9.55,1700,17,9.68,100,1,10.61,200,2,11.27,100,1,11.4,100,1,11.76,100,1,11.93,200,2,12.23,100,1,12.34,200,2,12.36,200,2,13.83,15,1,13.84,100,1,13.92,2,1,14.12,100,1,14.28,100,1,14.45,100,1,14.56,800,2,14.6,700,1,14.63,100,1,14.68,1400,2,ARL,325718637
2025-07-17T16:02:20.957051613Z,2025-07-17T16:02:20.956886401Z,160,2,1108,C,B,13.020000000,100,0,325718561,0,165212,271679685,ARL,0,13.02,100,0,165212,271679685,9.55,1700,17,9.68,100,1,10.61,200,2,11.27,100,1,11.4,100,1,11.76,100,1,11.93,200,2,12.23,100,1,12.34,200,2,12.36,200,2,13.83,15,1,13.84,100,1,13.92,2,1,14.12,100,1,14.28,100,1,14.45,100,1,14.56,800,2,14.6,700,1,14.63,100,1,14.68,1400,2,ARL,325718561
2025-07-17T16:02:20.957051613Z,2025-07-17T16:02:20.956886401Z,160,2,1108,A,B,13.260000000,100,0,325718821,130,165212,271679685,ARL,0,13.26,100,130,165212,271679685,9.55,1700,17,9.68,100,1,10.61,200,2,11.27,100,1,11.4,100,1,11.76,100,1,11.93,200,2,12.23,100,1,12.34,200,2,12.36,200,2,13.83,15,1,13.84,100,1,13.92,2,1,14.12,100,1,14.28,100,1,14.45,100,1,14.56,800,2,14.6,700,1,14.63,100,1,14.68,1400,2,ARL,325718821
2025-07-17T16:02:20.957089143Z,2025-07-17T16:02:20.956923753Z,160,2,1108,A,B,13.120000000,100,0,325718833,130,165390,271679686,ARL,0,13.12,100,130,165390,271679686,9.55,1700,17,9.68,100,1,10.61,200,2,11.27,100,1,11.4,100,1,11.76,100,1,11.93,200,2,12.23,100,1,12.34,200,2,12.36,200,2,13.83,15,1,13.84,100,1,13.92,2,1,14.12,100,1,14.28,100,1,14.45,100,1,14.56,800,2,14.6,700,1,14.63,100,1,14.68,1400,2,ARL,325718833
2025-07-17T16:02:20.957090484Z,2025-07-17T16:02:20.956925447Z,160,2,1108,A,B,13.120000000,100,0,325718837,130,165037,271679687,ARL,0,13.12,100,130,165037,271679687,9.55,1700,17,9.68,100,1,10.61,200,2,11.27,100,1,11.4,100,1,11.76,100,1,11.93,200,2,12.23,100,1,12.34,200,2,12.36,200,2,13.83,15,1,13.84,100,1,13.92,2,1,14.12,100,1,14.28,100,1,14.45,100,1,14.56,800,2,14.6,700,1,14.63,100,1,14.68,1400,2,ARL,325718837
2025-07-17T16:02:20.988655870Z,2025-07-17T16:02:20.988490644Z,160,2,1108,A,A,13.980000000,100,0,325719353,130,165226,271679923,ARL,0,13.98,100,130,165226,271679923,9.55,1700,17,9.68,100,1,10.61,200,2,11.27,100,1,11.4,100,1,11.76,100,1,11.93,200,2,12.23,100,1,12.34,200,2,12.36,200,2,13.83,15,1,13.84,100,1,13.92,2,1,13.98,100,1,14.12,100,1,14.28,100,1,14.45,100,1,14.56,800,2,14.6,700,1,14.63,100,1,ARL,325719353
2025-07-17T16:02:20.988656944Z,2025-07-17T16:02:20.988491826Z,160,2,1108,A,A,13.980000000,100,0,325719357,130,165118,271679924,ARL,0,13.98,100,130,165118,271679924,9.55,1700,17,9.68,100,1,10.61,200,2,11.27,100,1,11.4,100,1,11.76,100,1,11.93,200,2,12.23,100,1,12.34,200,2,12.36,200,2,13.83,15,1,13.84,100,1,13.92,2,1,13.98,200,2,14.12,100,1,14.28,100,1,14.45,100,1,14.56,800,2,14.6,700,1,14.63,100,1,ARL,325719357
2025-07-17T16:02:30.805193695Z,2025-07-17T16:02:30.805028316Z,160,2,1108,C,B,13.270000000,10,0,325714717,130,165379,271818376,ARL,0,13.27,10,130,165379,271818376,9.55,1700,17,9.68,100,1,10.61,200,2,11.27,100,1,11.4,100,1,11.76,100,1,11.93,200,2,12.23,100,1,12.34,200,2,12.36,200,2,13.83,15,1,13.84,100,1,13.92,2,1,13.98,200,2,14.12,100,1,14.28,100,1,14.45,100,1,14.56,800,2,14.6,700,1,14.63,100,1,ARL,325714717
2025-07-17T16:02:34.987171397Z,2025-07-17T16:02:34.987005787Z,160,2,1108,C,B,12.910000000,2,0,325714741,0,165610,271871706,ARL,0,12.91,2,0,165610,271871706,9.55,1700,17,9.68,100,1,10.61,200,2,11.27,100,1,11.4,100,1,11.76,100,1,11.93,200,2,12.23,100,1,12.34,200,2,12.36,200,2,13.83,15,1,13.84,100,1,13.92,2,1,13.98,200,2,14.12,100,1,14.28,100,1,14.45,100,1,14.56,800,2,14.6,700,1,14.63,100,1,ARL,325714741
2025-07-17T16:02:34.987171397Z,2025-07-17T16:02:34.987005787Z,160,2,1108,A,B,13.000000000,2,0,325967705,130,165610,271871706,ARL,0,13,2,130,165610,271871706,9.55,1700,17,9.68,100,1,10.61,200,2,11.27,100,1,11.4,100,1,11.76,100,1,11.93,200,2,12.23,100,1,12.34,200,2,12.36,200,2,13.83,15,1,13.84,100,1,13.92,2,1,13.98,200,2,14.12,100,1,14.28,100,1,14.45,100,1,14.56,800,2,14.6,700,1,14.63,100,1,ARL,325967705
2025-07-17T16:02:39.809464961Z,2025-07-17T16:02:39.809299504Z,160,2,1108,A,A,13.790000000,15,0,326077141,130,165457,271952021,ARL,0,13.79,15,130,165457,271952021,9.55,1700,17,9.68,100,1,10.61,200,2,11.27,100,1,11.4,100,1,11.76,100,1,11.93,200,2,12.23,100,1,12.34,200,2,12.36,200,2,13.79,15,1,13.83,15,1,13.84,100,1,13.92,2,1,13.98,200,2,14.12,100,1,14.28,100,1,14.45,100,1,14.56,800,2,14.6,700,1,ARL,326077141
2025-07-17T16:02:40.007472020Z,2025-07-17T16:02:40.007306432Z,160,2,1108,C,A,13.840000000,100,0,325718485,0,165588,271957331,ARL,0,13.84,100,0,165588,271957331,9.55,1700,17,9.68,100,1,10.61,200,2,11.27,100,1,11.4,100,1,11.76,100,1,11.93,200,2,12.23,100,1,12.34,200,2,12.36,200,2,13.79,15,1,13.83,15,1,13.92,2,1,13.98,200,2,14.12,100,1,14.28,100,1,14.45,100,1,14.56,800,2,14.6,700,1,14.63,100,1,ARL,325718485
2025-07-17T16:02:40.007472020Z,2025-07-17T16:02:40.007306432Z,160,2,1108,A,A,13.800000000,100,0,326082329,130,165588,271957331,ARL,0,13.8,100,130,165588,271957331,9.55,1700,17,9.68,100,1,10.61,200,2,11.27,100,1,11.4,100,1,11.76,100,1,11.93,200,2,12.23,100,1,12.34,200,2,12.36,200,2,13.79,15,1,13.8,100,1,13.83,15,1,13.92,2,1,13.98,200,2,14.12,100,1,14.28,100,1,14.45,100,1,14.56,800,2,14.6,700,1,ARL,326082329
2025-07-17T16:02:40.008213654Z,2025-07-17T16:02:40.008048023Z,160,2,1108,C,A,14.910000000,100,0,325718509,0,165631,271957349,ARL,0,14.91,100,0,165631,271957349,9.55,1700,17,9.68,100,1,10.61,200,2,11.27,100,1,11.4,100,1,11.76,100,1,11.93,200,2,12.23,100,1,12.34,200,2,12.36,200,2,13.79,15,1,13.8,100,1,13.83,15,1,13.92,2,1,13.98,200,2,14.12,100,1,14.28,100,1,14.45,100,1,14.56,800,2,14.6,700,1,ARL,325718509
2025-07-17T16:02:40.008213654Z,2025-07-17T16:02:40.008048023Z,160,2,1108,A,A,14.870000000,100,0,326082353,130,165631,271957349,ARL,0,14.87,100,130,165631,271957349,9.55,1700,17,9.68,100,1,10.61,200,2,11.27,100,1,11.4,100,1,11.76,100,1,11.93,200,2,12.23,100,1,12.34,200,2,12.36,200,2,13.79,15,1,13.8,100,1,13.83,15,1,13.92,2,1,13.98,200,2,14.12,100,1,14.28,100,1,14.45,100,1,14.56,800,2,14.6,700,1,ARL,326082353
2025-07-17T16:02:40.795014471Z,2025-07-17T16:02:40.794847674Z,160,2,1108,C,A,13.790000000,15,0,326077141,130,166797,271972417,ARL,0,13.79,15,130,166797,271972417,9.55,1700,17,9.68,100,1,10.61,200,2,11.27,100,1,11.4,100,1,11.76,100,1,11.93,200,2,12.23,100,1,12.34,200,2,12.36,200,2,13.8,100,1,13.83,15,1,13.92,2,1,13.98,200,2,14.12,100,1,14.28,100,1,14.45,100,1,14.56,800,2,14.6,700,1,14.63,100,1,ARL,326077141
2025-07-17T16:02:40.806305895Z,2025-07-17T16:02:40.806140621Z,160,2,1108,C,A,13.830000000,15,0,325714721,130,165274,271973288,ARL,0,13.83,15,130,165274,271973288,9.55,1700,17,9.68,100,1,10.61,200,2,11.27,100,1,11.4,100,1,11.76,100,1,11.93,200,2,12.23,100,1,12.34,200,2,12.36,200,2,13.8,100,1,13.92,2,1,13.98,200,2,14.12,100,1,14.28,100,1,14.45,100,1,14.56,800,2,14.6,700,1,14.63,100,1,14.68,1400,2,ARL,325714721
2025-07-17T16:02:43.834428162Z,2025-07-17T16:02:43.834262065Z,160,2,1108,T,N,13.280000000,100,0,0,130,166097,272014629,ARL,0,13.28,100,130,166097,272014629,9.55,1700,17,9.68,100,1,10.61,200,2,11.27,100,1,11.4,100,1,11.76,100,1,11.93,200,2,12.23,100,1,12.34,200,2,12.36,200,2,13.8,100,1,13.92,2,1,13.98,200,2,14.12,100,1,14.28,100,1,14.45,100,1,14.56,800,2,14.6,700,1,14.63,100,1,14.68,1400,2,ARL,0
2025-07-17T16:02:43.841852430Z,2025-07-17T16:02:43.841686908Z,160,2,1108,C,B,13.260000000,100,0,325718821,130,165522,272014658,ARL,0,13.26,100,130,165522,272014658,9.55,1700,17,9.68,100,1,10.61,200,2,11.27,100,1,11.4,100,1,11.76,100,1,11.93,200,2,12.23,100,1,12.34,200,2,12.36,200,2,13.8,100,1,13.92,2,1,13.98,200,2,14.12,100,1,14.28,100,1,14.45,100,1,14.56,800,2,14.6,700,1,14.63,100,1,14.68,1400,2,ARL,325718821
2025-07-17T16:02:43.841912053Z,2025-07-17T16:02:43.841746626Z,160,2,1108,A,A,13.900000000,4,0,326158809,130,165427,272014659,ARL,0,13.9,4,130,165427,272014659,9.55,1700,17,9.68,100,1,10.61,200,2,11.27,100,1,11.4,100,1,11.76,100,1,11.93,200,2,12.23,100,1,12.34,200,2,12.36,200,2,13.8,100,1,13.9,4,1,13.92,2,1,13.98,200,2,14.12,100,1,14.28,100,1,14.45,100,1,14.56,800,2,14.6,700,1,14.63,100,1,ARL,326158809
2025-07-17T16:02:43.842295427Z,2025-07-17T16:02:43.842130114Z,160,2,1108,C,A,13.800000000,100,0,326082329,130,165313,272014661,ARL,0,13.8,100,130,165313,272014661,9.55,1700,17,9.68,100,1,10.61,200,2,11.27,100,1,11.4,100,1,11.76,100,1,11.93,200,2,12.23,100,1,12.34,200,2,12.36,200,2,13.9,4,1,13.92,2,1,13.98,200,2,14.12,100,1,14.28,100,1,14.45,100,1,14.56,800,2,14.6,700,1,14.63,100,1,14.68,1400,2,ARL,326082329
2025-07-17T16:02:43.843036936Z,2025-07-17T16:02:43.842871428Z,160,2,1108,C,A,14.870000000,100,0,326082353,0,165508,272014673,ARL,0,14.87,100,0,165508,272014673,9.55,1700,17,9.68,100,1,10.61,200,2,11.27,100,1,11.4,100,1,11.76,100,1,11.93,200,2,12.23,100,1,12.34,200,2,12.36,200,2,13.9,4,1,13.92,2,1,13.98,200,2,14.12,100,1,14.28,100,1,14.45,100,1,14.56,800,2,14.6,700,1,14.63,100,1,14.68,1400,2,ARL,326082353
2025-07-17T16:02:43.843036936Z,2025-07-17T16:02:43.842871428Z,160,2,1108,A,A,14.920000000,100,0,326158869,130,165508,272014673,ARL,0,14.92,100,130,165508,272014673,9.55,1700,17,9.68,100,1,10.61,200,2,11.27,100,1,11.4,100,1,11.76,100,1,11.93,200,2,12.23,100,1,12.34,200,2,12.36,200,2,13.9,4,1,13.92,2,1,13.98,200,2,14.12,100,1,14.28,100,1,14.45,100,1,14.56,800,2,14.6,700,1,14.63,100,1,14.68,1400,2,ARL,326158869
2025-07-17T16:02:43.843106749Z,2025-07-17T16:02:43.842941514Z,160,2,1108,A,B,13.110000000,100,0,326158877,130,165235,272014674,ARL,0,13.11,100,130,165235,272014674,9.55,1700,17,9.68,100,1,10.61,200,2,11.27,100,1,11.4,100,1,11.76,100,1,11.93,200,2,12.23,100,1,12.34,200,2,12.36,200,2,13.9,4,1,13.92,2,1,13.98,200,2,14.12,100,1,14.28,100,1,14.45,100,1,14.56,800,2,14.6,700,1,14.63,100,1,14.68,1400,2,ARL,326158877
2025-07-17T16:02:43.843109026Z,2025-07-17T16:02:43.842943173Z,160,2,1108,C,A,14.810000000,100,0,325718549,0,165853,272014675,ARL,0,14.81,100,0,165853,272014675,9.55,1700,17,9.68,100,1,10.61,200,2,11.27,100,1,11.4,100,1,11.76,100,1,11.93,200,2,12.23,100,1,12.34,200,2,12.36,200,2,13.9,4,1,13.92,2,1,13.98,200,2,14.12,100,1,14.28,100,1,14.45,100,1,14.56,800,2,14.6,700,1,14.63,100,1,14.68,1400,2,ARL,325718549
2025-07-17T16:02:43.843109026Z,2025-07-17T16:02:43.842943173Z,160,2,1108,A,A,14.960000000,100,0,326158881,130,165853,272014675,ARL,0,14.96,100,130,165853,272014675,9.55,1700,17,9.68,100,1,10.61,200,2,11.27,100,1,11.4,100,1,11.76,100,1,11.93,200,2,12.23,100,1,12.34,200,2,12.36,200,2,13.9,4,1,13.92,2,1,13.98,200,2,14.12,100,1,14.28,100,1,14.45,100,1,14.56,800,2,14.6,700,1,14.63,100,1,14.68,1400,2,ARL,326158881
2025-07-17T16:02:43.843204692Z,2025-07-17T16:02:43.843039530Z,160,2,1108,C,A,13.900000000,4,0,326158809,130,165162,272014681,ARL,0,13.9,4,130,165162,272014681,9.55,1700,17,9.68,100,1,10.61,200,2,11.27,100,1,11.4,100,1,11.76,100,1,11.93,200,2,12.23,100,1,12.34,200,2,12.36,200,2,13.92,2,1,13.98,200,2,14.12,100,1,14.28,100,1,14.45,100,1,14.56,800,2,14.6,700,1,14.63,100,1,14.68,1400,2,14.73,200,2,ARL,326158809
2025-07-17T16:02:43.843956820Z,2025-07-17T16:02:43.843791297Z,160,2,1108,C,A,17.580000000,100,0,325718557,0,165523,272014689,ARL,0,17.58,100,0,165523,272014689,9.55,1700,17,9.68,100,1,10.61,200,2,11.27,100,1,11.4,100,1,11.76,100,1,11.93,200,2,12.23,100,1,12.34,200,2,12.36,200,2,13.92,2,1,13.98,200,2,14.12,100,1,14.28,100,1,14.45,100,1,14.56,800,2,14.6,700,1,14.63,100,1,14.68,1400,2,14.73,200,2,ARL,325718557
2025-07-17T16:02:43.843956820Z,2025-07-17T16:02:43.843791297Z,160,2,1108,A,A,17.760000000,100,0,326158953,130,165523,272014689,ARL,0,17.76,100,130,165523,272014689,9.55,1700,17,9.68,100,1,10.61,200,2,11.27,100,1,11.4,100,1,11.76,100,1,11.93,200,2,12.23,100,1,12.34,200,2,12.36,200,2,13.92,2,1,13.98,200,2,14.12,100,1,14.28,100,1,14.45,100,1,14.56,800,2,14.6,700,1,14.63,100,1,14.68,1400,2,14.73,200,2,ARL,326158953
2025-07-17T16:02:43.844653014Z,2025-07-17T16:02:43.844487204Z,160,2,1108,C,A,15.920000000,100,0,325718525,0,165810,272014697,ARL,0,15.92,100,0,165810,272014697,9.55,1700,17,9.68,100,1,10.61,200,2,11.27,100,1,11.4,100,1,11.76,100,1,11.93,200,2,12.23,100,1,12.34,200,2,12.36,200,2,13.92,2,1,13.98,200,2,14.12,100,1,14.28,100,1,14.45,100,1,14.56,800,2,14.6,700,1,14.63,100,1,14.68,1400,2,14.73,200,2,ARL,325718525
2025-07-17T16:02:43.844653014Z,2025-07-17T16:02:43.844487204Z,160,2,1108,A,A,16.080000000,100,0,326158989,130,165810,272014697,ARL,0,16.08,100,130,165810,272014697,9.55,1700,17,9.68,100,1,10.61,200,2,11.27,100,1,11.4,100,1,11.76,100,1,11.93,200,2,12.23,100,1,12.34,200,2,12.36,200,2,13.92,2,1,13.98,200,2,14.12,100,1,14.28,100,1,14.45,100,1,14.56,800,2,14.6,700,1,14.63,100,1,14.68,1400,2,14.73,200,2,ARL,326158989
2025-07-17T16:02:43.844801951Z,2025-07-17T16:02:43.844636465Z,160,2,1108,C,A,14.810000000,100,0,325718517,0,165486,272014698,ARL,0,14.81,100,0,165486,272014698,9.55,1700,17,9.68,100,1,10.61,200,2,11.27,100,1,11.4,100,1,11.76,100,1,11.93,200,2,12.23,100,1,12.34,200,2,12.36,200,2,13.92,2,1,13.98,200,2,14.12,100,1,14.28,100,1,14.45,100,1,14.56,800,2,14.6,700,1,14.63,100,1,14.68,1400,2,14.73,200,2,ARL,325718517
2025-07-17T16:02:43.844801951Z,2025-07-17T16:02:43.844636465Z,160,2,1108,A,A,14.960000000,100,0,326158997,130,165486,272014698,ARL,0,14.96,100,130,165486,272014698,9.55,1700,17,9.68,100,1,10.61,200,2,11.27,100,1,11.4,100,1,11.76,100,1,11.93,200,2,12.23,100,1,12.34,200,2,12.36,200,2,13.92,2,1,13.98,200,2,14.12,100,1,14.28,100,1,14.45,100,1,14.56,800,2,14.6,700,1,14.63,100,1,14.68,1400,2,14.73,200,2,ARL,326158997
2025-07-17T16:02:43.847026795Z,2025-07-17T16:02:43.846861336Z,160,2,1108,C,A,13.920000000,2,0,325297093,0,165459,272014713,ARL,0,13.92,2,0,165459,272014713,9.55,1700,17,9.68,100,1,10.61,200,2,11.27,100,1,11.4,100,1,11.76,100,1,11.93,200,2,12.23,100,1,12.34,200,2,12.36,200,2,13.98,200,2,14.12,100,1,14.28,100,1,14.45,100,1,14.56,800,2,14.6,700,1,14.63,100,1,14.68,1400,2,14.73,200,2,14.92,100,1,ARL,325297093
2025-07-17T16:02:43.847026795Z,2025-07-17T16:02:43.846861336Z,160,2,1108,A,A,14.030000000,2,0,326159041,130,165459,272014713,ARL,0,14.03,2,130,165459,272014713,9.55,1700,17,9.68,100,1,10.61,200,2,11.27,100,1,11.4,100,1,11.76,100,1,11.93,200,2,12.23,100,1,12.34,200,2,12.36,200,2,13.98,200,2,14.03,2,1,14.12,100,1,14.28,100,1,14.45,100,1,14.56,800,2,14.6,700,1,14.63,100,1,14.68,1400,2,14.73,200,2,ARL,326159041
2025-07-17T16:02:43.847832258Z,2025-07-17T16:02:43.847666979Z,160,2,1108,C,A,14.730000000,100,0,325714613,0,165279,272014721,ARL,0,14.73,100,0,165279,272014721,9.55,1700,17,9.68,100,1,10.61,200,2,11.27,100,1,11.4,100,1,11.76,100,1,11.93,200,2,12.23,100,1,12.34,200,2,12.36,200,2,13.98,200,2,14.03,2,1,14.12,100,1,14.28,100,1,14.45,100,1,14.56,800,2,14.6,700,1,14.63,100,1,14.68,1400,2,14.73,100,1,ARL,325714613
2025-07-17T16:02:43.847832258Z,2025-07-17T16:02:43.847666979Z,160,2,1108,A,A,14.870000000,100,0,326159049,130,165279,272014721,ARL,0,14.87,100,130,165279,272014721,9.55,1700,17,9.68,100,1,10.61,200,2,11.27,100,1,11.4,100,1,11.76,100,1,11.93,200,2,12.23,100,1,12.34,200,2,12.36,200,2,13.98,200,2,14.03,2,1,14.12,100,1,14.28,100,1,14.45,100,1,14.56,800,2,14.6,700,1,14.63,100,1,14.68,1400,2,14.73,100,1,ARL,326159049
2025-07-17T16:02:43.848147198Z,2025-07-17T16:02:43.847981726Z,160,2,1108,C,A,14.730000000,100,0,325714577,0,165472,272014724,ARL,0,14.73,100,0,165472,272014724,9.55,1700,17,9.68,100,1,10.61,200,2,11.27,100,1,11.4,100,1,11.76,100,1,11.93,200,2,12.23,100,1,12.34,200,2,12.36,200,2,13.98,200,2,14.03,2,1,14.12,100,1,14.28,100,1,14.45,100,1,14.56,800,2,14.6,700,1,14.63,100,1,14.68,1400,2,14.87,100,1,ARL,325714577
2025-07-17T16:02:43.848147198Z,2025-07-17T16:02:43.847981726Z,160,2,1108,A,A,14.870000000,100,0,326159061,130,165472,272014724,ARL,0,14.87,100,130,165472,272014724,9.55,1700,17,9.68,100,1,10.61,200,2,11.27,100,1,11.4,100,1,11.76,100,1,11.93,200,2,12.23,100,1,12.34,200,2,12.36,200,2,13.98,200,2,14.03,2,1,14.12,100,1,14.28,100,1,14.45,100,1,14.56,800,2,14.6,700,1,14.63,100,1,14.68,1400,2,14.87,200,2,ARL,326159061
2025-07-17T16:02:43.860199647Z,2025-07-17T16:02:43.860034354Z,160,2,1108,C,A,14.120000000,100,0,325718637,130,165293,272014788,ARL,0,14.12,100,130,165293,272014788,9.55,1700,17,9.68,100,1,10.61,200,2,11.27,100,1,11.4,100,1,11.76,100,1,11.93,200,2,12.23,100,1,12.34,200,2,12.36,200,2,13.98,200,2,14.03,2,1,14.28,100,1,14.45,100,1,14.56,800,2,14.6,700,1,14.63,100,1,14.68,1400,2,14.87,200,2,14.92,100,1,ARL,325718637
2025-07-17T16:02:43.860252446Z,2025-07-17T16:02:43.860087215Z,160,2,1108,A,A,14.260000000,100,0,326159201,130,165231,272014789,ARL,0,14.26,100,130,165231,272014789,9.55,1700,17,9.68,100,1,10.61,200,2,11.27,100,1,11.4,100,1,11.76,100,1,11.93,200,2,12.23,100,1,12.34,200,2,12.36,200,2,13.98,200,2,14.03,2,1,14.26,100,1,14.28,100,1,14.45,100,1,14.56,800,2,14.6,700,1,14.63,100,1,14.68,1400,2,14.87,200,2,ARL,326159201
2025-07-17T16:02:43.893176312Z,2025-07-17T16:02:43.893011012Z,160,2,1108,C,A,14.920000000,100,0,326158869,0,165300,272014986,ARL,0,14.92,100,0,165300,272014986,9.55,1700,17,9.68,100,1,10.61,200,2,11.27,100,1,11.4,100,1,11.76,100,1,11.93,200,2,12.23,100,1,12.34,200,2,12.36,200,2,13.98,200,2,14.03,2,1,14.26,100,1,14.28,100,1,14.45,100,1,14.56,800,2,14.6,700,1,14.63,100,1,14.68,1400,2,14.87,200,2,ARL,326158869
2025-07-17T16:02:43.893176312Z,2025-07-17T16:02:43.893011012Z,160,2,1108,A,A,15.060000000,100,0,326159425,130,165300,272014986,ARL,0,15.06,100,130,165300,272014986,9.55,1700,17,9.68,100,1,10.61,200,2,11.27,100,1,11.4,100,1,11.76,100,1,11.93,200,2,12.23,100,1,12.34,200,2,12.36,200,2,13.98,200,2,14.03,2,1,14.26,100,1,14.28,100,1,14.45,100,1,14.56,800,2,14.6,700,1,14.63,100,1,14.68,1400,2,14.87,200,2,ARL,326159425
2025-07-17T16:02:43.946967137Z,2025-07-17T16:02:43.946801538Z,160,2,1108,C,A,14.630000000,100,0,325714653,0,165599,272015584,ARL,0,14.63,100,0,165599,272015584,9.55,1700,17,9.68,100,1,10.61,200,2,11.27,100,1,11.4,100,1,11.76,100,1,11.93,200,2,12.23,100,1,12.34,200,2,12.36,200,2,13.98,200,2,14.03,2,1,14.26,100,1,14.28,100,1,14.45,100,1,14.56,800,2,14.6,700,1,14.68,1400,2,14.87,200,2,14.96,200,2,ARL,325714653
2025-07-17T16:02:43.946967137Z,2025-07-17T16:02:43.946801538Z,160,2,1108,A,A,14.770000000,100,0,326160141,130,165599,272015584,ARL,0,14.77,100,130,165599,272015584,9.55,1700,17,9.68,100,1,10.61,200,2,11.27,100,1,11.4,100,1,11.76,100,1,11.93,200,2,12.23,100,1,12.34,200,2,12.36,200,2,13.98,200,2,14.03,2,1,14.26,100,1,14.28,100,1,14.45,100,1,14.56,800,2,14.6,700,1,14.68,1400,2,14.77,100,1,14.87,200,2,ARL,326160141
2025-07-17T16:02:44.664219784Z,2025-07-17T16:02:44.664054457Z,160,2,1108,A,A,13.990000000,100,0,326167529,130,165327,272021808,ARL,0,13.99,100,130,165327,272021808,9.55,1700,17,9.68,100,1,10.61,200,2,11.27,100,1,11.4,100,1,11.76,100,1,11.93,200,2,12.23,100,1,12.34,200,2,12.36,200,2,13.98,200,2,13.99,100,1,14.03,2,1,14.26,100,1,14.28,100,1,14.45,100,1,14.56,800,2,14.6,700,1,14.68,1400,2,14.77,100,1,ARL,326167529
2025-07-17T16:03:02.985987598Z,2025-07-17T16:03:02.985818199Z,160,2,1108,C,A,14.870000000,100,0,326159049,0,169399,272331833,ARL,0,14.87,100,0,169399,272331833,9.55,1700,17,9.68,100,1,10.61,200,2,11.27,100,1,11.4,100,1,11.76,100,1,11.93,200,2,12.23,100,1,12.34,200,2,12.36,200,2,13.98,200,2,13.99,100,1,14.03,2,1,14.26,100,1,14.28,100,1,14.45,100,1,14.56,800,2,14.6,700,1,14.68,1400,2,14.77,100,1,ARL,326159049
2025-07-17T16:03:02.985987598Z,2025-07-17T16:03:02.985818199Z,160,2,1108,A,A,14.700000000,100,0,326551237,128,169399,272331833,ARL,0,14.7,100,128,169399,272331833,9.55,1700,17,9.68,100,1,10.61,200,2,11.27,100,1,11.4,100,1,11.76,100,1,11.93,200,2,12.23,100,1,12.34,200,2,12.36,200,2,13.98,200,2,13.99,100,1,14.03,2,1,14.26,100,1,14.28,100,1,14.45,100,1,14.56,800,2,14.6,700,1,14.68,1400,2,14.7,100,1,ARL,326551237
2025-07-17T16:03:02.987969729Z,2025-07-17T16:03:02.987797728Z,160,2,1108,C,A,14.870000000,100,0,326159061,0,172001,272332718,ARL,0,14.87,100,0,172001,272332718,9.55,1700,17,9.68,100,1,10.61,200,2,11.27,100,1,11.4,100,1,11.76,100,1,11.93,200,2,12.23,100,1,12.34,200,2,12.36,200,2,13.98,200,2,13.99,100,1,14.03,2,1,14.26,100,1,14.28,100,1,14.45,100,1,14.56,800,2,14.6,700,1,14.68,1400,2,14.7,100,1,ARL,326159061
2025-07-17T16:03:02.987969729Z,2025-07-17T16:03:02.987797728Z,160,2,1108,A,A,14.700000000,100,0,326551829,128,172001,272332718,ARL,0,14.7,100,128,172001,272332718,9.55,1700,17,9.68,100,1,10.61,200,2,11.27,100,1,11.4,100,1,11.76,100,1,11.93,200,2,12.23,100,1,12.34,200,2,12.36,200,2,13.98,200,2,13.99,100,1,14.03,2,1,14.26,100,1,14.28,100,1,14.45,100,1,14.56,800,2,14.6,700,1,14.68,1400,2,14.7,200,2,ARL,326551829
2025-07-17T16:03:10.807446975Z,2025-07-17T16:03:10.807281669Z,160,2,1108,A,A,13.720000000,15,0,326729677,130,165306,272474575,ARL,0,13.72,15,130,165306,272474575,9.55,1700,17,9.68,100,1,10.61,200,2,11.27,100,1,11.4,100,1,11.76,100,1,11.93,200,2,12.23,100,1,12.34,200,2,12.36,200,2,13.72,15,1,13.98,200,2,13.99,100,1,14.03,2,1,14.26,100,1,14.28,100,1,14.45,100,1,14.56,800,2,14.6,700,1,14.68,1400,2,ARL,326729677
2025-07-17T16:03:10.807714421Z,2025-07-17T16:03:10.807548848Z,160,2,1108,C,A,13.990000000,100,0,326167529,0,165573,272474576,ARL,0,13.99,100,0,165573,272474576,9.55,1700,17,9.68,100,1,10.61,200,2,11.27,100,1,11.4,100,1,11.76,100,1,11.93,200,2,12.23,100,1,12.34,200,2,12.36,200,2,13.72,15,1,13.98,200,2,14.03,2,1,14.26,100,1,14.28,100,1,14.45,100,1,14.56,800,2,14.6,700,1,14.68,1400,2,14.7,200,2,ARL,326167529
2025-07-17T16:03:10.807714421Z,2025-07-17T16:03:10.807548848Z,160,2,1108,A,A,13.730000000,100,0,326729685,130,165573,272474576,ARL,0,13.73,100,130,165573,272474576,9.55,1700,17,9.68,100,1,10.61,200,2,11.27,100,1,11.4,100,1,11.76,100,1,11.93,200,2,12.23,100,1,12.34,200,2,12.36,200,2,13.72,15,1,13.73,100,1,13.98,200,2,14.03,2,1,14.26,100,1,14.28,100,1,14.45,100,1,14.56,800,2,14.6,700,1,14.68,1400,2,ARL,326729685
2025-07-17T16:03:10.808457278Z,2025-07-17T16:03:10.808290914Z,160,2,1108,C,A,15.060000000,100,0,326159425,0,166364,272474580,ARL,0,15.06,100,0,166364,272474580,9.55,1700,17,9.68,100,1,10.61,200,2,11.27,100,1,11.4,100,1,11.76,100,1,11.93,200,2,12.23,100,1,12.34,200,2,12.36,200,2,13.72,15,1,13.73,100,1,13.98,200,2,14.03,2,1,14.26,100,1,14.28,100,1,14.45,100,1,14.56,800,2,14.6,700,1,14.68,1400,2,ARL,326159425
2025-07-17T16:03:10.808457278Z,2025-07-17T16:03:10.808290914Z,160,2,1108,A,A,14.790000000,100,0,326729705,128,166364,272474580,ARL,0,14.79,100,128,166364,272474580,9.55,1700,17,9.68,100,1,10.61,200,2,11.27,100,1,11.4,100,1,11.76,100,1,11.93,200,2,12.23,100,1,12.34,200,2,12.36,200,2,13.72,15,1,13.73,100,1,13.98,200,2,14.03,2,1,14.26,100,1,14.28,100,1,14.45,100,1,14.56,800,2,14.6,700,1,14.68,1400,2,ARL,326729705
2025-07-17T16:03:10.809707274Z,2025-07-17T16:03:10.809541651Z,160,2,1108,C,A,14.960000000,100,0,326158881,0,165623,272474585,ARL,0,14.96,100,0,165623,272474585,9.55,1700,17,9.68,100,1,10.61,200,2,11.27,100,1,11.4,100,1,11.76,100,1,11.93,200,2,12.23,100,1,12.34,200,2,12.36,200,2,13.72,15,1,13.73,100,1,13.98,200,2,14.03,2,1,14.26,100,1,14.28,100,1,14.45,100,1,14.56,800,2,14.6,700,1,14.68,1400,2,ARL,326158881
2025-07-17T16:03:10.809707274Z,2025-07-17T16:03:10.809541651Z,160,2,1108,A,A,14.700000000,100,0,326729721,130,165623,272474585,ARL,0,14.7,100,130,165623,272474585,9.55,1700,17,9.68,100,1,10.61,200,2,11.27,100,1,11.4,100,1,11.76,100,1,11.93,200,2,12.23,100,1,12.34,200,2,12.36,200,2,13.72,15,1,13.73,100,1,13.98,200,2,14.03,2,1,14.26,100,1,14.28,100,1,14.45,100,1,14.56,800,2,14.6,700,1,14.68,1400,2,ARL,326729721
2025-07-17T16:03:10.809936821Z,2025-07-17T16:03:10.809771527Z,160,2,1108,C,A,14.770000000,100,0,326160141,130,165294,272474594,ARL,0,14.77,100,130,165294,272474594,9.55,1700,17,9.68,100,1,10.61,200,2,11.27,100,1,11.4,100,1,11.76,100,1,11.93,200,2,12.23,100,1,12.34,200,2,12.36,200,2,13.72,15,1,13.73,100,1,13.98,200,2,14.03,2,1,14.26,100,1,14.28,100,1,14.45,100,1,14.56,800,2,14.6,700,1,14.68,1400,2,ARL,326160141
2025-07-17T16:03:10.809963577Z,2025-07-17T16:03:10.809798084Z,160,2,1108,C,A,17.760000000,100,0,326158953,0,165493,272474595,ARL,0,17.76,100,0,165493,272474595,9.55,1700,17,9.68,100,1,10.61,200,2,11.27,100,1,11.4,100,1,11.76,100,1,11.93,200,2,12.23,100,1,12.34,200,2,12.36,200,2,13.72,15,1,13.73,100,1,13.98,200,2,14.03,2,1,14.26,100,1,14.28,100,1,14.45,100,1,14.56,800,2,14.6,700,1,14.68,1400,2,ARL,326158953
2025-07-17T16:03:10.809963577Z,2025-07-17T16:03:10.809798084Z,160,2,1108,A,A,17.440000000,100,0,326729725,130,165493,272474595,ARL,0,17.44,100,130,165493,272474595,9.55,1700,17,9.68,100,1,10.61,200,2,11.27,100,1,11.4,100,1,11.76,100,1,11.93,200,2,12.23,100,1,12.34,200,2,12.36,200,2,13.72,15,1,13.73,100,1,13.98,200,2,14.03,2,1,14.26,100,1,14.28,100,1,14.45,100,1,14.56,800,2,14.6,700,1,14.68,1400,2,ARL,326729725
2025-07-17T16:03:10.810059442Z,2025-07-17T16:03:10.809894317Z,160,2,1108,A,A,14.520000000,100,0,326729729,130,165125,272474597,ARL,0,14.52,100,130,165125,272474597,9.55,1700,17,9.68,100,1,10.61,200,2,11.27,100,1,11.4,100,1,11.76,100,1,11.93,200,2,12.23,100,1,12.34,200,2,12.36,200,2,13.72,15,1,13.73,100,1,13.98,200,2,14.03,2,1,14.26,100,1,14.28,100,1,14.45,100,1,14.52,100,1,14.56,800,2,14.6,700,1,ARL,326729729
2025-07-17T16:03:10.810478524Z,2025-07-17T16:03:10.810312923Z,160,2,1108,C,A,16.080000000,100,0,326158989,0,165601,272474600,ARL,0,16.08,100,0,165601,272474600,9.55,1700,17,9.68,100,1,10.61,200,2,11.27,100,1,11.4,100,1,11.76,100,1,11.93,200,2,12.23,100,1,12.34,200,2,12.36,200,2,13.72,15,1,13.73,100,1,13.98,200,2,14.03,2,1,14.26,100,1,14.28,100,1,14.45,100,1,14.52,100,1,14.56,800,2,14.6,700,1,ARL,326158989
2025-07-17T16:03:10.810478524Z,2025-07-17T16:03:10.810312923Z,160,2,1108,A,A,15.790000000,100,0,326729733,130,165601,272474600,ARL,0,15.79,100,130,165601,272474600,9.55,1700,17,9.68,100,1,10.61,200,2,11.27,100,1,11.4,100,1,11.76,100,1,11.93,200,2,12.23,100,1,12.34,200,2,12.36,200,2,13.72,15,1,13.73,100,1,13.98,200,2,14.03,2,1,14.26,100,1,14.28,100,1,14.45,100,1,14.52,100,1,14.56,800,2,14.6,700,1,ARL,326729733
2025-07-17T16:03:10.814646270Z,2025-07-17T16:03:10.814480532Z,160,2,1108,C,A,14.960000000,100,0,326158997,0,165738,272474635,ARL,0,14.96,100,0,165738,272474635,9.55,1700,17,9.68,100,1,10.61,200,2,11.27,100,1,11.4,100,1,11.76,100,1,11.93,200,2,12.23,100,1,12.34,200,2,12.36,200,2,13.72,15,1,13.73,100,1,13.98,200,2,14.03,2,1,14.26,100,1,14.28,100,1,14.45,100,1,14.52,100,1,14.56,800,2,14.6,700,1,ARL,326158997
2025-07-17T16:03:10.814646270Z,2025-07-17T16:03:10.814480532Z,160,2,1108,A,A,14.700000000,100,0,326729821,130,165738,272474635,ARL,0,14.7,100,130,165738,272474635,9.55,1700,17,9.68,100,1,10.61,200,2,11.27,100,1,11.4,100,1,11.76,100,1,11.93,200,2,12.23,100,1,12.34,200,2,12.36,200,2,13.72,15,1,13.73,100,1,13.98,200,2,14.03,2,1,14.26,100,1,14.28,100,1,14.45,100,1,14.52,100,1,14.56,800,2,14.6,700,1,ARL,326729821
2025-07-17T16:03:10.817866066Z,2025-07-17T16:03:10.817700664Z,160,2,1108,C,A,14.260000000,100,0,326159201,130,165402,272474675,ARL,0,14.26,100,130,165402,272474675,9.55,1700,17,9.68,100,1,10.61,200,2,11.27,100,1,11.4,100,1,11.76,100,1,11.93,200,2,12.23,100,1,12.34,200,2,12.36,200,2,13.72,15,1,13.73,100,1,13.98,200,2,14.03,2,1,14.28,100,1,14.45,100,1,14.52,100,1,14.56,800,2,14.6,700,1,14.68,1400,2,ARL,326159201
2025-07-17T16:03:10.817919970Z,2025-07-17T16:03:10.817754737Z,160,2,1108,A,A,14.000000000,100,0,326729929,130,165233,272474676,ARL,0,14,100,130,165233,272474676,9.55,1700,17,9.68,100,1,10.61,200,2,11.27,100,1,11.4,100,1,11.76,100,1,11.93,200,2,12.23,100,1,12.34,200,2,12.36,200,2,13.72,15,1,13.73,100,1,13.98,200,2,14,100,1,14.03,2,1,14.28,100,1,14.45,100,1,14.52,100,1,14.56,800,2,14.6,700,1,ARL,326729929
2025-07-17T16:03:10.843337845Z,2025-07-17T16:03:10.843172549Z,160,2,1108,A,A,15.660000000,100,0,326730513,130,165296,272474826,ARL,0,15.66,100,130,165296,272474826,9.55,1700,17,9.68,100,1,10.61,200,2,11.27,100,1,11.4,100,1,11.76,100,1,11.93,200,2,12.23,100,1,12.34,200,2,12.36,200,2,13.72,15,1,13.73,100,1,13.98,200,2,14,100,1,14.03,2,1,14.28,100,1,14.45,100,1,14.52,100,1,14.56,800,2,14.6,700,1,ARL,326730513
2025-07-17T16:03:10.843350160Z,2025-07-17T16:03:10.843184785Z,160,2,1108,C,A,15.940000000,100,0,325714909,130,165375,272474827,ARL,0,15.94,100,130,165375,272474827,9.55,1700,17,9.68,100,1,10.61,200,2,11.27,100,1,11.4,100,1,11.76,100,1,11.93,200,2,12.23,100,1,12.34,200,2,12.36,200,2,13.72,15,1,13.73,100,1,13.98,200,2,14,100,1,14.03,2,1,14.28,100,1,14.45,100,1,14.52,100,1,14.56,800,2,14.6,700,1,ARL,325714909
2025-07-17T16:03:10.843615537Z,2025-07-17T16:03:10.843448998Z,160,2,1108,C,A,13.980000000,100,0,325719357,0,166539,272474828,ARL,0,13.98,100,0,166539,272474828,9.55,1700,17,9.68,100,1,10.61,200,2,11.27,100,1,11.4,100,1,11.76,100,1,11.93,200,2,12.23,100,1,12.34,200,2,12.36,200,2,13.72,15,1,13.73,100,1,13.98,100,1,14,100,1,14.03,2,1,14.28,100,1,14.45,100,1,14.52,100,1,14.56,800,2,14.6,700,1,ARL,325719357
2025-07-17T16:03:10.843615537Z,2025-07-17T16:03:10.843449402Z,160,2,1108,C,A,13.980000000,100,0,325719353,130,166135,272474829,ARL,0,13.98,100,130,166135,272474829,9.55,1700,17,9.68,100,1,10.61,200,2,11.27,100,1,11.4,100,1,11.76,100,1,11.93,200,2,12.23,100,1,12.34,200,2,12.36,200,2,13.72,15,1,13.73,100,1,14,100,1,14.03,2,1,14.28,100,1,14.45,100,1,14.52,100,1,14.56,800,2,14.6,700,1,14.68,1400,2,ARL,325719353
2025-07-17T16:03:10.843628246Z,2025-07-17T16:03:10.843462898Z,160,2,1108,A,A,13.870000000,100,0,326730517,130,165348,272474830,ARL,0,13.87,100,130,165348,272474830,9.55,1700,17,9.68,100,1,10.61,200,2,11.27,100,1,11.4,100,1,11.76,100,1,11.93,200,2,12.23,100,1,12.34,200,2,12.36,200,2,13.72,15,1,13.73,100,1,13.87,100,1,14,100,1,14.03,2,1,14.28,100,1,14.45,100,1,14.52,100,1,14.56,800,2,14.6,700,1,ARL,326730517
2025-07-17T16:03:10.843629633Z,2025-07-17T16:03:10.843464369Z,160,2,1108,A,A,13.870000000,100,0,326730521,130,165264,272474831,ARL,0,13.87,100,130,165264,272474831,9.55,1700,17,9.68,100,1,10.61,200,2,11.27,100,1,11.4,100,1,11.76,100,1,11.93,200,2,12.23,100,1,12.34,200,2,12.36,200,2,13.72,15,1,13.73,100,1,13.87,200,2,14,100,1,14.03,2,1,14.28,100,1,14.45,100,1,14.52,100,1,14.56,800,2,14.6,700,1,ARL,326730521
2025-07-17T16:03:16.348189077Z,2025-07-17T16:03:16.348023740Z,160,2,1108,A,A,13.690000000,15,0,326835877,130,165337,272557172,ARL,0,13.69,15,130,165337,272557172,9.55,1700,17,9.68,100,1,10.61,200,2,11.27,100,1,11.4,100,1,11.76,100,1,11.93,200,2,12.23,100,1,12.34,200,2,12.36,200,2,13.69,15,1,13.72,15,1,13.73,100,1,13.87,200,2,14,100,1,14.03,2,1,14.28,100,1,14.45,100,1,14.52,100,1,14.56,800,2,ARL,326835877
2025-07-17T16:03:16.348468824Z,2025-07-17T16:03:16.348302787Z,160,2,1108,C,A,14.700000000,100,0,326551829,0,166037,272557230,ARL,0,14.7,100,0,166037,272557230,9.55,1700,17,9.68,100,1,10.61,200,2,11.27,100,1,11.4,100,1,11.76,100,1,11.93,200,2,12.23,100,1,12.34,200,2,12.36,200,2,13.69,15,1,13.72,15,1,13.73,100,1,13.87,200,2,14,100,1,14.03,2,1,14.28,100,1,14.45,100,1,14.52,100,1,14.56,800,2,ARL,326551829
2025-07-17T16:03:16.348468824Z,2025-07-17T16:03:16.348302787Z,160,2,1108,A,A,14.580000000,100,0,326835885,130,166037,272557230,ARL,0,14.58,100,130,166037,272557230,9.55,1700,17,9.68,100,1,10.61,200,2,11.27,100,1,11.4,100,1,11.76,100,1,11.93,200,2,12.23,100,1,12.34,200,2,12.36,200,2,13.69,15,1,13.72,15,1,13.73,100,1,13.87,200,2,14,100,1,14.03,2,1,14.28,100,1,14.45,100,1,14.52,100,1,14.56,800,2,ARL,326835885
2025-07-17T16:03:16.349679949Z,2025-07-17T16:03:16.349513354Z,160,2,1108,C,A,14.700000000,100,0,326551237,0,166595,272557430,ARL,0,14.7,100,0,166595,272557430,9.55,1700,17,9.68,100,1,10.61,200,2,11.27,100,1,11.4,100,1,11.76,100,1,11.93,200,2,12.23,100,1,12.34,200,2,12.36,200,2,13.69,15,1,13.72,15,1,13.73,100,1,13.87,200,2,14,100,1,14.03,2,1,14.28,100,1,14.45,100,1,14.52,100,1,14.56,800,2,ARL,326551237
2025-07-17T16:03:16.349679949Z,2025-07-17T16:03:16.349513354Z,160,2,1108,A,A,14.580000000,100,0,326836085,130,166595,272557430,ARL,0,14.58,100,130,166595,272557430,9.55,1700,17,9.68,100,1,10.61,200,2,11.27,100,1,11.4,100,1,11.76,100,1,11.93,200,2,12.23,100,1,12.34,200,2,12.36,200,2,13.69,15,1,13.72,15,1,13.73,100,1,13.87,200,2,14,100,1,14.03,2,1,14.28,100,1,14.45,100,1,14.52,100,1,14.56,800,2,ARL,326836085
2025-07-17T16:03:16.352011831Z,2025-07-17T16:03:16.351845457Z,160,2,1108,C,A,13.730000000,100,0,326729685,0,166374,272557789,ARL,0,13.73,100,0,166374,272557789,9.55,1700,17,9.68,100,1,10.61,200,2,11.27,100,1,11.4,100,1,11.76,100,1,11.93,200,2,12.23,100,1,12.34,200,2,12.36,200,2,13.69,15,1,13.72,15,1,13.87,200,2,14,100,1,14.03,2,1,14.28,100,1,14.45,100,1,14.52,100,1,14.56,800,2,14.58,200,2,ARL,326729685
2025-07-17T16:03:16.352011831Z,2025-07-17T16:03:16.351845457Z,160,2,1108,A,A,13.700000000,100,0,326836533,130,166374,272557789,ARL,0,13.7,100,130,166374,272557789,9.55,1700,17,9.68,100,1,10.61,200,2,11.27,100,1,11.4,100,1,11.76,100,1,11.93,200,2,12.23,100,1,12.34,200,2,12.36,200,2,13.69,15,1,13.7,100,1,13.72,15,1,13.87,200,2,14,100,1,14.03,2,1,14.28,100,1,14.45,100,1,14.52,100,1,14.56,800,2,ARL,326836533
2025-07-17T16:03:16.365985162Z,2025-07-17T16:03:16.365819243Z,160,2,1108,C,A,15.380000000,100,0,325714965,0,165919,272559024,ARL,0,15.38,100,0,165919,272559024,9.55,1700,17,9.68,100,1,10.61,200,2,11.27,100,1,11.4,100,1,11.76,100,1,11.93,200,2,12.23,100,1,12.34,200,2,12.36,200,2,13.69,15,1,13.7,100,1,13.72,15,1,13.87,200,2,14,100,1,14.03,2,1,14.28,100,1,14.45,100,1,14.52,100,1,14.56,800,2,ARL,325714965
2025-07-17T16:03:16.365985162Z,2025-07-17T16:03:16.365819243Z,160,2,1108,A,A,15.070000000,100,0,326837501,130,165919,272559024,ARL,0,15.07,100,130,165919,272559024,9.55,1700,17,9.68,100,1,10.61,200,2,11.27,100,1,11.4,100,1,11.76,100,1,11.93,200,2,12.23,100,1,12.34,200,2,12.36,200,2,13.69,15,1,13.7,100,1,13.72,15,1,13.87,200,2,14,100,1,14.03,2,1,14.28,100,1,14.45,100,1,14.52,100,1,14.56,800,2,ARL,326837501
2025-07-17T16:03:18.804325078Z,2025-07-17T16:03:18.804159952Z,160,2,1108,C,A,13.690000000,15,0,326835877,130,165126,272609485,ARL,0,13.69,15,130,165126,272609485,9.55,1700,17,9.68,100,1,10.61,200,2,11.27,100,1,11.4,100,1,11.76,100,1,11.93,200,2,12.23,100,1,12.34,200,2,12.36,200,2,13.7,100,1,13.72,15,1,13.87,200,2,14,100,1,14.03,2,1,14.28,100,1,14.45,100,1,14.52,100,1,14.56,800,2,14.58,200,2,ARL,326835877
2025-07-17T16:03:18.804367560Z,2025-07-17T16:03:18.804202246Z,160,2,1108,C,A,13.700000000,100,0,326836533,130,165314,272609486,ARL,0,13.7,100,130,165314,272609486,9.55,1700,17,9.68,100,1,10.61,200,2,11.27,100,1,11.4,100,1,11.76,100,1,11.93,200,2,12.23,100,1,12.34,200,2,12.36,200,2,13.72,15,1,13.87,200,2,14,100,1,14.03,2,1,14.28,100,1,14.45,100,1,14.52,100,1,14.56,800,2,14.58,200,2,14.6,700,1,ARL,326836533
2025-07-17T16:03:18.805099118Z,2025-07-17T16:03:18.804933488Z,160,2,1108,C,A,14.790000000,100,0,326729705,0,165630,272609510,ARL,0,14.79,100,0,165630,272609510,9.55,1700,17,9.68,100,1,10.61,200,2,11.27,100,1,11.4,100,1,11.76,100,1,11.93,200,2,12.23,100,1,12.34,200,2,12.36,200,2,13.72,15,1,13.87,200,2,14,100,1,14.03,2,1,14.28,100,1,14.45,100,1,14.52,100,1,14.56,800,2,14.58,200,2,14.6,700,1,ARL,326729705
2025-07-17T16:03:18.805099118Z,2025-07-17T16:03:18.804933488Z,160,2,1108,A,A,14.950000000,100,0,326892717,130,165630,272609510,ARL,0,14.95,100,130,165630,272609510,9.55,1700,17,9.68,100,1,10.61,200,2,11.27,100,1,11.4,100,1,11.76,100,1,11.93,200,2,12.23,100,1,12.34,200,2,12.36,200,2,13.72,15,1,13.87,200,2,14,100,1,14.03,2,1,14.28,100,1,14.45,100,1,14.52,100,1,14.56,800,2,14.58,200,2,14.6,700,1,ARL,326892717
2025-07-17T16:03:18.805291629Z,2025-07-17T16:03:18.805126035Z,160,2,1108,C,A,14.700000000,100,0,326729721,0,165594,272609526,ARL,0,14.7,100,0,165594,272609526,9.55,1700,17,9.68,100,1,10.61,200,2,11.27,100,1,11.4,100,1,11.76,100,1,11.93,200,2,12.23,100,1,12.34,200,2,12.36,200,2,13.72,15,1,13.87,200,2,14,100,1,14.03,2,1,14.28,100,1,14.45,100,1,14.52,100,1,14.56,800,2,14.58,200,2,14.6,700,1,ARL,326729721
2025-07-17T16:03:18.805291629Z,2025-07-17T16:03:18.805126035Z,160,2,1108,A,A,14.850000000,100,0,326892721,130,165594,272609526,ARL,0,14.85,100,130,165594,272609526,9.55,1700,17,9.68,100,1,10.61,200,2,11.27,100,1,11.4,100,1,11.76,100,1,11.93,200,2,12.23,100,1,12.34,200,2,12.36,200,2,13.72,15,1,13.87,200,2,14,100,1,14.03,2,1,14.28,100,1,14.45,100,1,14.52,100,1,14.56,800,2,14.58,200,2,14.6,700,1,ARL,326892721
2025-07-17T16:03:18.805449089Z,2025-07-17T16:03:18.805283236Z,160,2,1108,C,A,13.720000000,15,0,326729677,130,165853,272609541,ARL,0,13.72,15,130,165853,272609541,9.55,1700,17,9.68,100,1,10.61,200,2,11.27,100,1,11.4,100,1,11.76,100,1,11.93,200,2,12.23,100,1,12.34,200,2,12.36,200,2,13.87,200,2,14,100,1,14.03,2,1,14.28,100,1,14.45,100,1,14.52,100,1,14.56,800,2,14.58,200,2,14.6,700,1,14.68,1400,2,ARL,326729677
2025-07-17T16:03:18.806535903Z,2025-07-17T16:03:18.806370373Z,160,2,1108,C,A,14.580000000,100,0,326835885,0,165530,272609577,ARL,0,14.58,100,0,165530,272609577,9.55,1700,17,9.68,100,1,10.61,200,2,11.27,100,1,11.4,100,1,11.76,100,1,11.93,200,2,12.23,100,1,12.34,200,2,12.36,200,2,13.87,200,2,14,100,1,14.03,2,1,14.28,100,1,14.45,100,1,14.52,100,1,14.56,800,2,14.58,100,1,14.6,700,1,14.68,1400,2,ARL,326835885
2025-07-17T16:03:18.806535903Z,2025-07-17T16:03:18.806370373Z,160,2,1108,A,A,14.760000000,100,0,326892817,130,165530,272609577,ARL,0,14.76,100,130,165530,272609577,9.55,1700,17,9.68,100,1,10.61,200,2,11.27,100,1,11.4,100,1,11.76,100,1,11.93,200,2,12.23,100,1,12.34,200,2,12.36,200,2,13.87,200,2,14,100,1,14.03,2,1,14.28,100,1,14.45,100,1,14.52,100,1,14.56,800,2,14.58,100,1,14.6,700,1,14.68,1400,2,ARL,326892817
2025-07-17T16:03:18.806802589Z,2025-07-17T16:03:18.806637004Z,160,2,1108,C,A,14.580000000,100,0,326836085,0,165585,272609583,ARL,0,14.58,100,0,165585,272609583,9.55,1700,17,9.68,100,1,10.61,200,2,11.27,100,1,11.4,100,1,11.76,100,1,11.93,200,2,12.23,100,1,12.34,200,2,12.36,200,2,13.87,200,2,14,100,1,14.03,2,1,14.28,100,1,14.45,100,1,14.52,100,1,14.56,800,2,14.6,700,1,14.68,1400,2,14.7,100,1,ARL,326836085
2025-07-17T16:03:18.806802589Z,2025-07-17T16:03:18.806637004Z,160,2,1108,A,A,14.760000000,100,0,326892825,130,165585,272609583,ARL,0,14.76,100,130,165585,272609583,9.55,1700,17,9.68,100,1,10.61,200,2,11.27,100,1,11.4,100,1,11.76,100,1,11.93,200,2,12.23,100,1,12.34,200,2,12.36,200,2,13.87,200,2,14,100,1,14.03,2,1,14.28,100,1,14.45,100,1,14.52,100,1,14.56,800,2,14.6,700,1,14.68,1400,2,14.7,100,1,ARL,326892825
2025-07-17T16:03:18.809706334Z,2025-07-17T16:03:18.809540733Z,160,2,1108,C,A,14.520000000,100,0,326729729,0,165601,272609656,ARL,0,14.52,100,0,165601,272609656,9.55,1700,17,9.68,100,1,10.61,200,2,11.27,100,1,11.4,100,1,11.76,100,1,11.93,200,2,12.23,100,1,12.34,200,2,12.36,200,2,13.87,200,2,14,100,1,14.03,2,1,14.28,100,1,14.45,100,1,14.56,800,2,14.6,700,1,14.68,1400,2,14.7,100,1,14.76,200,2,ARL,326729729
2025-07-17T16:03:18.809706334Z,2025-07-17T16:03:18.809540733Z,160,2,1108,A,A,14.660000000,100,0,326892885,130,165601,272609656,ARL,0,14.66,100,130,165601,272609656,9.55,1700,17,9.68,100,1,10.61,200,2,11.27,100,1,11.4,100,1,11.76,100,1,11.93,200,2,12.23,100,1,12.34,200,2,12.36,200,2,13.87,200,2,14,100,1,14.03,2,1,14.28,100,1,14.45,100,1,14.56,800,2,14.6,700,1,14.66,100,1,14.68,1400,2,14.7,100,1,ARL,326892885
2025-07-17T16:03:18.809848665Z,2025-07-17T16:03:18.809683187Z,160,2,1108,C,A,15.790000000,100,0,326729733,0,165478,272609658,ARL,0,15.79,100,0,165478,272609658,9.55,1700,17,9.68,100,1,10.61,200,2,11.27,100,1,11.4,100,1,11.76,100,1,11.93,200,2,12.23,100,1,12.34,200,2,12.36,200,2,13.87,200,2,14,100,1,14.03,2,1,14.28,100,1,14.45,100,1,14.56,800,2,14.6,700,1,14.66,100,1,14.68,1400,2,14.7,100,1,ARL,326729733
2025-07-17T16:03:18.809848665Z,2025-07-17T16:03:18.809683187Z,160,2,1108,A,A,15.960000000,100,0,326892889,130,165478,272609658,ARL,0,15.96,100,130,165478,272609658,9.55,1700,17,9.68,100,1,10.61,200,2,11.27,100,1,11.4,100,1,11.76,100,1,11.93,200,2,12.23,100,1,12.34,200,2,12.36,200,2,13.87,200,2,14,100,1,14.03,2,1,14.28,100,1,14.45,100,1,14.56,800,2,14.6,700,1,14.66,100,1,14.68,1400,2,14.7,100,1,ARL,326892889
2025-07-17T16:03:18.812107206Z,2025-07-17T16:03:18.811941680Z,160,2,1108,C,A,17.440000000,100,0,326729725,0,165526,272609679,ARL,0,17.44,100,0,165526,272609679,9.55,1700,17,9.68,100,1,10.61,200,2,11.27,100,1,11.4,100,1,11.76,100,1,11.93,200,2,12.23,100,1,12.34,200,2,12.36,200,2,13.87,200,2,14,100,1,14.03,2,1,14.28,100,1,14.45,100,1,14.56,800,2,14.6,700,1,14.66,100,1,14.68,1400,2,14.7,100,1,ARL,326729725
2025-07-17T16:03:18.812107206Z,2025-07-17T16:03:18.811941680Z,160,2,1108,A,A,17.620000000,100,0,326892921,130,165526,272609679,ARL,0,17.62,100,130,165526,272609679,9.55,1700,17,9.68,100,1,10.61,200,2,11.27,100,1,11.4,100,1,11.76,100,1,11.93,200,2,12.23,100,1,12.34,200,2,12.36,200,2,13.87,200,2,14,100,1,14.03,2,1,14.28,100,1,14.45,100,1,14.56,800,2,14.6,700,1,14.66,100,1,14.68,1400,2,14.7,100,1,ARL,326892921
2025-07-17T16:03:18.818245629Z,2025-07-17T16:03:18.818080239Z,160,2,1108,C,A,14.000000000,100,0,326729929,130,165390,272609768,ARL,0,14,100,130,165390,272609768,9.55,1700,17,9.68,100,1,10.61,200,2,11.27,100,1,11.4,100,1,11.76,100,1,11.93,200,2,12.23,100,1,12.34,200,2,12.36,200,2,13.87,200,2,14.03,2,1,14.28,100,1,14.45,100,1,14.56,800,2,14.6,700,1,14.66,100,1,14.68,1400,2,14.7,100,1,14.76,200,2,ARL,326729929
2025-07-17T16:03:18.818301143Z,2025-07-17T16:03:18.818135688Z,160,2,1108,A,A,14.150000000,100,0,326893213,130,165455,272609769,ARL,0,14.15,100,130,165455,272609769,9.55,1700,17,9.68,100,1,10.61,200,2,11.27,100,1,11.4,100,1,11.76,100,1,11.93,200,2,12.23,100,1,12.34,200,2,12.36,200,2,13.87,200,2,14.03,2,1,14.15,100,1,14.28,100,1,14.45,100,1,14.56,800,2,14.6,700,1,14.66,100,1,14.68,1400,2,14.7,100,1,ARL,326893213
2025-07-17T16:03:18.868420503Z,2025-07-17T16:03:18.868254768Z,160,2,1108,C,A,14.700000000,100,0,326729821,0,165735,272610397,ARL,0,14.7,100,0,165735,272610397,9.55,1700,17,9.68,100,1,10.61,200,2,11.27,100,1,11.4,100,1,11.76,100,1,11.93,200,2,12.23,100,1,12.34,200,2,12.36,200,2,13.87,200,2,14.03,2,1,14.15,100,1,14.28,100,1,14.45,100,1,14.56,800,2,14.6,700,1,14.66,100,1,14.68,1400,2,14.76,200,2,ARL,326729821
2025-07-17T16:03:18.868420503Z,2025-07-17T16:03:18.868254768Z,160,2,1108,A,A,14.850000000,100,0,326893961,130,165735,272610397,ARL,0,14.85,100,130,165735,272610397,9.55,1700,17,9.68,100,1,10.61,200,2,11.27,100,1,11.4,100,1,11.76,100,1,11.93,200,2,12.23,100,1,12.34,200,2,12.36,200,2,13.87,200,2,14.03,2,1,14.15,100,1,14.28,100,1,14.45,100,1,14.56,800,2,14.6,700,1,14.66,100,1,14.68,1400,2,14.76,200,2,ARL,326893961
2025-07-17T16:03:19.191219507Z,2025-07-17T16:03:19.191054306Z,160,2,1108,A,A,13.880000000,100,0,326899125,130,165201,272614303,ARL,0,13.88,100,130,165201,272614303,9.55,1700,17,9.68,100,1,10.61,200,2,11.27,100,1,11.4,100,1,11.76,100,1,11.93,200,2,12.23,100,1,12.34,200,2,12.36,200,2,13.87,200,2,13.88,100,1,14.03,2,1,14.15,100,1,14.28,100,1,14.45,100,1,14.56,800,2,14.6,700,1,14.66,100,1,14.68,1400,2,ARL,326899125
2025-07-17T16:03:27.433957932Z,2025-07-17T16:03:27.433791643Z,160,2,1108,T,N,13.280000000,40,0,0,130,166289,272788756,ARL,0,13.28,40,130,166289,272788756,9.55,1700,17,9.68,100,1,10.61,200,2,11.27,100,1,11.4,100,1,11.76,100,1,11.93,200,2,12.23,100,1,12.34,200,2,12.36,200,2,13.87,200,2,13.88,100,1,14.03,2,1,14.15,100,1,14.28,100,1,14.45,100,1,14.56,800,2,14.6,700,1,14.66,100,1,14.68,1400,2,ARL,0
2025-07-17T16:03:27.436323951Z,2025-07-17T16:03:27.436158395Z,160,2,1108,A,A,14.250000000,53,0,327112281,130,165556,272788767,ARL,0,14.25,53,130,165556,272788767,9.55,1700,17,9.68,100,1,10.61,200,2,11.27,100,1,11.4,100,1,11.76,100,1,11.93,200,2,12.23,100,1,12.34,200,2,12.36,200,2,13.87,200,2,13.88,100,1,14.03,2,1,14.15,100,1,14.25,53,1,14.28,100,1,14.45,100,1,14.56,800,2,14.6,700,1,14.66,100,1,ARL,327112281
2025-07-17T16:03:27.436880768Z,2025-07-17T16:03:27.436715001Z,160,2,1108,C,B,12.230000000,100,0,291964745,0,165767,272788774,ARL,0,12.23,100,0,165767,272788774,9.55,1700,17,9.68,100,1,10.61,200,2,11.27,100,1,11.4,100,1,11.76,100,1,11.93,200,2,12.34,200,2,12.36,200,2,12.37,700,1,13.87,200,2,13.88,100,1,14.03,2,1,14.15,100,1,14.25,53,1,14.28,100,1,14.45,100,1,14.56,800,2,14.6,700,1,14.66,100,1,ARL,291964745
2025-07-17T16:03:27.436880768Z,2025-07-17T16:03:27.436715001Z,160,2,1108,A,B,12.100000000,100,0,327112289,130,165767,272788774,ARL,0,12.1,100,130,165767,272788774,9.55,1700,17,9.68,100,1,10.61,200,2,11.27,100,1,11.4,100,1,11.76,100,1,11.93,200,2,12.1,100,1,12.34,200,2,12.36,200,2,13.87,200,2,13.88,100,1,14.03,2,1,14.15,100,1,14.25,53,1,14.28,100,1,14.45,100,1,14.56,800,2,14.6,700,1,14.66,100,1,ARL,327112289
2025-07-17T16:03:27.438566971Z,2025-07-17T16:03:27.438400828Z,160,2,1108,C,B,12.340000000,100,0,285586113,0,166143,272788792,ARL,0,12.34,100,0,166143,272788792,9.55,1700,17,9.68,100,1,10.61,200,2,11.27,100,1,11.4,100,1,11.76,100,1,11.93,200,2,12.1,100,1,12.34,100,1,12.36,200,2,13.87,200,2,13.88,100,1,14.03,2,1,14.15,100,1,14.25,53,1,14.28,100,1,14.45,100,1,14.56,800,2,14.6,700,1,14.66,100,1,ARL,285586113
2025-07-17T16:03:27.438566971Z,2025-07-17T16:03:27.438400828Z,160,2,1108,A,B,12.200000000,100,0,327112385,130,166143,272788792,ARL,0,12.2,100,130,166143,272788792,9.55,1700,17,9.68,100,1,10.61,200,2,11.27,100,1,11.4,100,1,11.76,100,1,11.93,200,2,12.1,100,1,12.2,100,1,12.34,100,1,13.87,200,2,13.88,100,1,14.03,2,1,14.15,100,1,14.25,53,1,14.28,100,1,14.45,100,1,14.56,800,2,14.6,700,1,14.66,100,1,ARL,327112385
2025-07-17T16:03:27.438603564Z,2025-07-17T16:03:27.438437969Z,160,2,1108,C,B,12.340000000,100,0,285586189,0,165595,272788793,ARL,0,12.34,100,0,165595,272788793,9.55,1700,17,9.68,100,1,10.61,200,2,11.27,100,1,11.4,100,1,11.76,100,1,11.93,200,2,12.1,100,1,12.2,100,1,12.36,200,2,13.87,200,2,13.88,100,1,14.03,2,1,14.15,100,1,14.25,53,1,14.28,100,1,14.45,100,1,14.56,800,2,14.6,700,1,14.66,100,1,ARL,285586189
2025-07-17T16:03:27.438603564Z,2025-07-17T16:03:27.438437969Z,160,2,1108,A,B,12.200000000,100,0,327112393,130,165595,272788793,ARL,0,12.2,100,130,165595,272788793,9.55,1700,17,9.68,100,1,10.61,200,2,11.27,100,1,11.4,100,1,11.76,100,1,11.93,200,2,12.1,100,1,12.2,200,2,12.36,200,2,13.87,200,2,13.88,100,1,14.03,2,1,14.15,100,1,14.25,53,1,14.28,100,1,14.45,100,1,14.56,800,2,14.6,700,1,14.66,100,1,ARL,327112393
2025-07-17T16:03:27.454010355Z,2025-07-17T16:03:27.453845141Z,160,2,1108,C,B,13.030000000,100,0,285586293,130,165214,272788897,ARL,0,13.03,100,130,165214,272788897,9.55,1700,17,9.68,100,1,10.61,200,2,11.27,100,1,11.4,100,1,11.76,100,1,11.93,200,2,12.1,100,1,12.2,200,2,12.36,200,2,13.87,200,2,13.88,100,1,14.03,2,1,14.15,100,1,14.25,53,1,14.28,100,1,14.45,100,1,14.56,800,2,14.6,700,1,14.66,100,1,ARL,285586293
2025-07-17T16:03:27.454059719Z,2025-07-17T16:03:27.453894425Z,160,2,1108,A,B,12.950000000,100,0,327112565,130,165294,272788898,ARL,0,12.95,100,130,165294,272788898,9.55,1700,17,9.68,100,1,10.61,200,2,11.27,100,1,11.4,100,1,11.76,100,1,11.93,200,2,12.1,100,1,12.2,200,2,12.36,200,2,13.87,200,2,13.88,100,1,14.03,2,1,14.15,100,1,14.25,53,1,14.28,100,1,14.45,100,1,14.56,800,2,14.6,700,1,14.66,100,1,ARL,327112565
2025-07-17T16:03:27.454892321Z,2025-07-17T16:03:27.454726901Z,160,2,1108,C,B,12.950000000,100,0,327112565,130,165420,272788942,ARL,0,12.95,100,130,165420,272788942,9.55,1700,17,9.68,100,1,10.61,200,2,11.27,100,1,11.4,100,1,11.76,100,1,11.93,200,2,12.1,100,1,12.2,200,2,12.36,200,2,13.87,200,2,13.88,100,1,14.03,2,1,14.15,100,1,14.25,53,1,14.28,100,1,14.45,100,1,14.56,800,2,14.6,700,1,14.66,100,1,ARL,327112565
2025-07-17T16:03:27.454939600Z,2025-07-17T16:03:27.454773691Z,160,2,1108,A,B,12.860000000,100,0,327112577,130,165909,272788943,ARL,0,12.86,100,130,165909,272788943,9.55,1700,17,9.68,100,1,10.61,200,2,11.27,100,1,11.4,100,1,11.76,100,1,11.93,200,2,12.1,100,1,12.2,200,2,12.36,200,2,13.87,200,2,13.88,100,1,14.03,2,1,14.15,100,1,14.25,53,1,14.28,100,1,14.45,100,1,14.56,800,2,14.6,700,1,14.66,100,1,ARL,327112577
2025-07-17T16:03:27.517751270Z,2025-07-17T16:03:27.517585374Z,160,2,1108,C,B,12.460000000,100,0,285587281,130,165896,272790695,ARL,0,12.46,100,130,165896,272790695,9.55,1700,17,9.68,100,1,10.61,200,2,11.27,100,1,11.4,100,1,11.76,100,1,11.93,200,2,12.1,100,1,12.2,200,2,12.36,200,2,13.87,200,2,13.88,100,1,14.03,2,1,14.15,100,1,14.25,53,1,14.28,100,1,14.45,100,1,14.56,800,2,14.6,700,1,14.66,100,1,ARL,285587281
2025-07-17T16:03:27.517864675Z,2025-07-17T16:03:27.517699408Z,160,2,1108,A,B,12.330000000,100,0,327114465,130,165267,272790696,ARL,0,12.33,100,130,165267,272790696,9.55,1700,17,9.68,100,1,10.61,200,2,11.27,100,1,11.4,100,1,11.76,100,1,11.93,200,2,12.1,100,1,12.2,200,2,12.33,100,1,13.87,200,2,13.88,100,1,14.03,2,1,14.15,100,1,14.25,53,1,14.28,100,1,14.45,100,1,14.56,800,2,14.6,700,1,14.66,100,1,ARL,327114465
2025-07-17T16:03:27.536343943Z,2025-07-17T16:03:27.536178718Z,160,2,1108,C,A,14.250000000,53,0,327112281,130,165225,272791410,ARL,0,14.25,53,130,165225,272791410,9.55,1700,17,9.68,100,1,10.61,200,2,11.27,100,1,11.4,100,1,11.76,100,1,11.93,200,2,12.1,100,1,12.2,200,2,12.33,100,1,13.87,200,2,13.88,100,1,14.03,2,1,14.15,100,1,14.28,100,1,14.45,100,1,14.56,800,2,14.6,700,1,14.66,100,1,14.68,1400,2,ARL,327112281
2025-07-17T16:03:56.548348047Z,2025-07-17T16:03:56.548182793Z,160,2,1108,A,A,13.800000000,15,0,327675057,130,165254,273208310,ARL,0,13.8,15,130,165254,273208310,9.55,1700,17,9.68,100,1,10.61,200,2,11.27,100,1,11.4,100,1,11.76,100,1,11.93,200,2,12.1,100,1,12.2,200,2,12.33,100,1,13.8,15,1,13.87,200,2,13.88,100,1,14.03,2,1,14.15,100,1,14.28,100,1,14.45,100,1,14.56,800,2,14.6,700,1,14.66,100,1,ARL,327675057
2025-07-17T16:03:56.548611716Z,2025-07-17T16:03:56.548446336Z,160,2,1108,C,A,13.880000000,100,0,326899125,0,165380,273208316,ARL,0,13.88,100,0,165380,273208316,9.55,1700,17,9.68,100,1,10.61,200,2,11.27,100,1,11.4,100,1,11.76,100,1,11.93,200,2,12.1,100,1,12.2,200,2,12.33,100,1,13.8,15,1,13.87,200,2,14.03,2,1,14.15,100,1,14.28,100,1,14.45,100,1,14.56,800,2,14.6,700,1,14.66,100,1,14.68,1400,2,ARL,326899125
2025-07-17T16:03:56.548611716Z,2025-07-17T16:03:56.548446336Z,160,2,1108,A,A,13.810000000,100,0,327675065,130,165380,273208316,ARL,0,13.81,100,130,165380,273208316,9.55,1700,17,9.68,100,1,10.61,200,2,11.27,100,1,11.4,100,1,11.76,100,1,11.93,200,2,12.1,100,1,12.2,200,2,12.33,100,1,13.8,15,1,13.81,100,1,13.87,200,2,14.03,2,1,14.15,100,1,14.28,100,1,14.45,100,1,14.56,800,2,14.6,700,1,14.66,100,1,ARL,327675065
2025-07-17T16:03:56.549354405Z,2025-07-17T16:03:56.549188993Z,160,2,1108,C,A,14.950000000,100,0,326892717,0,165412,273208325,ARL,0,14.95,100,0,165412,273208325,9.55,1700,17,9.68,100,1,10.61,200,2,11.27,100,1,11.4,100,1,11.76,100,1,11.93,200,2,12.1,100,1,12.2,200,2,12.33,100,1,13.8,15,1,13.81,100,1,13.87,200,2,14.03,2,1,14.15,100,1,14.28,100,1,14.45,100,1,14.56,800,2,14.6,700,1,14.66,100,1,ARL,326892717
2025-07-17T16:03:56.549354405Z,2025-07-17T16:03:56.549188993Z,160,2,1108,A,A,14.880000000,100,0,327675093,130,165412,273208325,ARL,0,14.88,100,130,165412,273208325,9.55,1700,17,9.68,100,1,10.61,200,2,11.27,100,1,11.4,100,1,11.76,100,1,11.93,200,2,12.1,100,1,12.2,200,2,12.33,100,1,13.8,15,1,13.81,100,1,13.87,200,2,14.03,2,1,14.15,100,1,14.28,100,1,14.45,100,1,14.56,800,2,14.6,700,1,14.66,100,1,ARL,327675093
2025-07-17T16:04:06.233858611Z,2025-07-17T16:04:06.233692491Z,160,2,1108,C,A,14.760000000,100,0,326892825,0,166120,273345719,ARL,0,14.76,100,0,166120,273345719,9.55,1700,17,9.68,100,1,10.61,200,2,11.27,100,1,11.4,100,1,11.76,100,1,11.93,200,2,12.1,100,1,12.2,200,2,12.33,100,1,13.8,15,1,13.81,100,1,13.87,200,2,14.03,2,1,14.15,100,1,14.28,100,1,14.45,100,1,14.56,800,2,14.6,700,1,14.66,100,1,ARL,326892825
2025-07-17T16:04:06.233858611Z,2025-07-17T16:04:06.233692491Z,160,2,1108,A,A,14.640000000,100,0,327856297,130,166120,273345719,ARL,0,14.64,100,130,166120,273345719,9.55,1700,17,9.68,100,1,10.61,200,2,11.27,100,1,11.4,100,1,11.76,100,1,11.93,200,2,12.1,100,1,12.2,200,2,12.33,100,1,13.8,15,1,13.81,100,1,13.87,200,2,14.03,2,1,14.15,100,1,14.28,100,1,14.45,100,1,14.56,800,2,14.6,700,1,14.64,100,1,ARL,327856297
2025-07-17T16:04:06.234600198Z,2025-07-17T16:04:06.234433294Z,160,2,1108,C,A,14.760000000,100,0,326892817,0,166904,273345721,ARL,0,14.76,100,0,166904,273345721,9.55,1700,17,9.68,100,1,10.61,200,2,11.27,100,1,11.4,100,1,11.76,100,1,11.93,200,2,12.1,100,1,12.2,200,2,12.33,100,1,13.8,15,1,13.81,100,1,13.87,200,2,14.03,2,1,14.15,100,1,14.28,100,1,14.45,100,1,14.56,800,2,14.6,700,1,14.64,100,1,ARL,326892817
2025-07-17T16:04:06.234600198Z,2025-07-17T16:04:06.234433294Z,160,2,1108,A,A,14.640000000,100,0,327856309,130,166904,273345721,ARL,0,14.64,100,130,166904,273345721,9.55,1700,17,9.68,100,1,10.61,200,2,11.27,100,1,11.4,100,1,11.76,100,1,11.93,200,2,12.1,100,1,12.2,200,2,12.33,100,1,13.8,15,1,13.81,100,1,13.87,200,2,14.03,2,1,14.15,100,1,14.28,100,1,14.45,100,1,14.56,800,2,14.6,700,1,14.64,200,2,ARL,327856309
2025-07-17T16:04:06.510914101Z,2025-07-17T16:04:06.510748731Z,160,2,1108,A,A,13.720000000,15,0,327863853,130,165370,273352664,ARL,0,13.72,15,130,165370,273352664,9.55,1700,17,9.68,100,1,10.61,200,2,11.27,100,1,11.4,100,1,11.76,100,1,11.93,200,2,12.1,100,1,12.2,200,2,12.33,100,1,13.72,15,1,13.8,15,1,13.81,100,1,13.87,200,2,14.03,2,1,14.15,100,1,14.28,100,1,14.45,100,1,14.56,800,2,14.6,700,1,ARL,327863853
2025-07-17T16:04:06.512413102Z,2025-07-17T16:04:06.512244746Z,160,2,1108,C,A,13.810000000,100,0,327675065,0,168356,273352888,ARL,0,13.81,100,0,168356,273352888,9.55,1700,17,9.68,100,1,10.61,200,2,11.27,100,1,11.4,100,1,11.76,100,1,11.93,200,2,12.1,100,1,12.2,200,2,12.33,100,1,13.72,15,1,13.8,15,1,13.87,200,2,14.03,2,1,14.15,100,1,14.28,100,1,14.45,100,1,14.56,800,2,14.6,700,1,14.64,200,2,ARL,327675065
2025-07-17T16:04:06.512413102Z,2025-07-17T16:04:06.512244746Z,160,2,1108,A,A,13.730000000,100,0,327864137,128,168356,273352888,ARL,0,13.73,100,128,168356,273352888,9.55,1700,17,9.68,100,1,10.61,200,2,11.27,100,1,11.4,100,1,11.76,100,1,11.93,200,2,12.1,100,1,12.2,200,2,12.33,100,1,13.72,15,1,13.73,100,1,13.8,15,1,13.87,200,2,14.03,2,1,14.15,100,1,14.28,100,1,14.45,100,1,14.56,800,2,14.6,700,1,ARL,327864137
2025-07-17T16:04:06.513675299Z,2025-07-17T16:04:06.513497276Z,160,2,1108,C,A,14.880000000,100,0,327675093,0,178023,273353923,ARL,0,14.88,100,0,178023,273353923,9.55,1700,17,9.68,100,1,10.61,200,2,11.27,100,1,11.4,100,1,11.76,100,1,11.93,200,2,12.1,100,1,12.2,200,2,12.33,100,1,13.72,15,1,13.73,100,1,13.8,15,1,13.87,200,2,14.03,2,1,14.15,100,1,14.28,100,1,14.45,100,1,14.56,800,2,14.6,700,1,ARL,327675093
2025-07-17T16:04:06.513675299Z,2025-07-17T16:04:06.513497276Z,160,2,1108,A,A,14.790000000,100,0,327864893,128,178023,273353923,ARL,0,14.79,100,128,178023,273353923,9.55,1700,17,9.68,100,1,10.61,200,2,11.27,100,1,11.4,100,1,11.76,100,1,11.93,200,2,12.1,100,1,12.2,200,2,12.33,100,1,13.72,15,1,13.73,100,1,13.8,15,1,13.87,200,2,14.03,2,1,14.15,100,1,14.28,100,1,14.45,100,1,14.56,800,2,14.6,700,1,ARL,327864893
2025-07-17T16:04:06.522853161Z,2025-07-17T16:04:06.522687474Z,160,2,1108,C,A,14.850000000,100,0,326892721,0,165687,273357758,ARL,0,14.85,100,0,165687,273357758,9.55,1700,17,9.68,100,1,10.61,200,2,11.27,100,1,11.4,100,1,11.76,100,1,11.93,200,2,12.1,100,1,12.2,200,2,12.33,100,1,13.72,15,1,13.73,100,1,13.8,15,1,13.87,200,2,14.03,2,1,14.15,100,1,14.28,100,1,14.45,100,1,14.56,800,2,14.6,700,1,ARL,326892721
2025-07-17T16:04:06.522853161Z,2025-07-17T16:04:06.522687474Z,160,2,1108,A,A,14.700000000,100,0,327868421,130,165687,273357758,ARL,0,14.7,100,130,165687,273357758,9.55,1700,17,9.68,100,1,10.61,200,2,11.27,100,1,11.4,100,1,11.76,100,1,11.93,200,2,12.1,100,1,12.2,200,2,12.33,100,1,13.72,15,1,13.73,100,1,13.8,15,1,13.87,200,2,14.03,2,1,14.15,100,1,14.28,100,1,14.45,100,1,14.56,800,2,14.6,700,1,ARL,327868421
2025-07-17T16:04:06.525550815Z,2025-07-17T16:04:06.525385108Z,160,2,1108,C,A,14.150000000,100,0,326893213,130,165707,273358260,ARL,0,14.15,100,130,165707,273358260,9.55,1700,17,9.68,100,1,10.61,200,2,11.27,100,1,11.4,100,1,11.76,100,1,11.93,200,2,12.1,100,1,12.2,200,2,12.33,100,1,13.72,15,1,13.73,100,1,13.8,15,1,13.87,200,2,14.03,2,1,14.28,100,1,14.45,100,1,14.56,800,2,14.6,700,1,14.64,200,2,ARL,326893213
2025-07-17T16:04:06.525608746Z,2025-07-17T16:04:06.525442486Z,160,2,1108,A,A,14.000000000,100,0,327869193,128,166260,273358273,ARL,0,14,100,128,166260,273358273,9.55,1700,17,9.68,100,1,10.61,200,2,11.27,100,1,11.4,100,1,11.76,100,1,11.93,200,2,12.1,100,1,12.2,200,2,12.33,100,1,13.72,15,1,13.73,100,1,13.8,15,1,13.87,200,2,14,100,1,14.03,2,1,14.28,100,1,14.45,100,1,14.56,800,2,14.6,700,1,ARL,327869193
2025-07-17T16:04:06.528210755Z,2025-07-17T16:04:06.528043934Z,160,2,1108,C,A,14.660000000,100,0,326892885,130,166821,273358598,ARL,0,14.66,100,130,166821,273358598,9.55,1700,17,9.68,100,1,10.61,200,2,11.27,100,1,11.4,100,1,11.76,100,1,11.93,200,2,12.1,100,1,12.2,200,2,12.33,100,1,13.72,15,1,13.73,100,1,13.8,15,1,13.87,200,2,14,100,1,14.03,2,1,14.28,100,1,14.45,100,1,14.56,800,2,14.6,700,1,ARL,326892885
2025-07-17T16:04:06.528329048Z,2025-07-17T16:04:06.528161631Z,160,2,1108,A,A,14.520000000,100,0,327869529,128,167417,273358642,ARL,0,14.52,100,128,167417,273358642,9.55,1700,17,9.68,100,1,10.61,200,2,11.27,100,1,11.4,100,1,11.76,100,1,11.93,200,2,12.1,100,1,12.2,200,2,12.33,100,1,13.72,15,1,13.73,100,1,13.8,15,1,13.87,200,2,14,100,1,14.03,2,1,14.28,100,1,14.45,100,1,14.52,100,1,14.56,800,2,ARL,327869529
2025-07-17T16:04:06.543480312Z,2025-07-17T16:04:06.543314706Z,160,2,1108,C,A,17.620000000,100,0,326892921,0,165606,273359491,ARL,0,17.62,100,0,165606,273359491,9.55,1700,17,9.68,100,1,10.61,200,2,11.27,100,1,11.4,100,1,11.76,100,1,11.93,200,2,12.1,100,1,12.2,200,2,12.33,100,1,13.72,15,1,13.73,100,1,13.8,15,1,13.87,200,2,14,100,1,14.03,2,1,14.28,100,1,14.45,100,1,14.52,100,1,14.56,800,2,ARL,326892921
2025-07-17T16:04:06.543480312Z,2025-07-17T16:04:06.543314706Z,160,2,1108,A,A,17.440000000,100,0,327870217,130,165606,273359491,ARL,0,17.44,100,130,165606,273359491,9.55,1700,17,9.68,100,1,10.61,200,2,11.27,100,1,11.4,100,1,11.76,100,1,11.93,200,2,12.1,100,1,12.2,200,2,12.33,100,1,13.72,15,1,13.73,100,1,13.8,15,1,13.87,200,2,14,100,1,14.03,2,1,14.28,100,1,14.45,100,1,14.52,100,1,14.56,800,2,ARL,327870217
2025-07-17T16:04:06.548945239Z,2025-07-17T16:04:06.548778200Z,160,2,1108,C,A,15.960000000,100,0,326892889,0,167039,273359672,ARL,0,15.96,100,0,167039,273359672,9.55,1700,17,9.68,100,1,10.61,200,2,11.27,100,1,11.4,100,1,11.76,100,1,11.93,200,2,12.1,100,1,12.2,200,2,12.33,100,1,13.72,15,1,13.73,100,1,13.8,15,1,13.87,200,2,14,100,1,14.03,2,1,14.28,100,1,14.45,100,1,14.52,100,1,14.56,800,2,ARL,326892889
2025-07-17T16:04:06.548945239Z,2025-07-17T16:04:06.548778200Z,160,2,1108,A,A,15.790000000,100,0,327870361,130,167039,273359672,ARL,0,15.79,100,130,167039,273359672,9.55,1700,17,9.68,100,1,10.61,200,2,11.27,100,1,11.4,100,1,11.76,100,1,11.93,200,2,12.1,100,1,12.2,200,2,12.33,100,1,13.72,15,1,13.73,100,1,13.8,15,1,13.87,200,2,14,100,1,14.03,2,1,14.28,100,1,14.45,100,1,14.52,100,1,14.56,800,2,ARL,327870361
2025-07-17T16:04:06.648109829Z,2025-07-17T16:04:06.647944313Z,160,2,1108,C,A,14.850000000,100,0,326893961,0,165516,273361957,ARL,0,14.85,100,0,165516,273361957,9.55,1700,17,9.68,100,1,10.61,200,2,11.27,100,1,11.4,100,1,11.76,100,1,11.93,200,2,12.1,100,1,12.2,200,2,12.33,100,1,13.72,15,1,13.73,100,1,13.8,15,1,13.87,200,2,14,100,1,14.03,2,1,14.28,100,1,14.45,100,1,14.52,100,1,14.56,800,2,ARL,326893961
2025-07-17T16:04:06.648109829Z,2025-07-17T16:04:06.647944313Z,160,2,1108,A,A,14.700000000,100,0,327873009,130,165516,273361957,ARL,0,14.7,100,130,165516,273361957,9.55,1700,17,9.68,100,1,10.61,200,2,11.27,100,1,11.4,100,1,11.76,100,1,11.93,200,2,12.1,100,1,12.2,200,2,12.33,100,1,13.72,15,1,13.73,100,1,13.8,15,1,13.87,200,2,14,100,1,14.03,2,1,14.28,100,1,14.45,100,1,14.52,100,1,14.56,800,2,ARL,327873009
2025-07-17T16:04:06.805500523Z,2025-07-17T16:04:06.805335354Z,160,2,1108,C,A,13.720000000,15,0,327863853,130,165169,273364089,ARL,0,13.72,15,130,165169,273364089,9.55,1700,17,9.68,100,1,10.61,200,2,11.27,100,1,11.4,100,1,11.76,100,1,11.93,200,2,12.1,100,1,12.2,200,2,12.33,100,1,13.73,100,1,13.8,15,1,13.87,200,2,14,100,1,14.03,2,1,14.28,100,1,14.45,100,1,14.52,100,1,14.56,800,2,14.6,700,1,ARL,327863853
2025-07-17T16:04:06.806217584Z,2025-07-17T16:04:06.806052396Z,160,2,1108,C,A,13.800000000,15,0,327675057,130,165188,273364090,ARL,0,13.8,15,130,165188,273364090,9.55,1700,17,9.68,100,1,10.61,200,2,11.27,100,1,11.4,100,1,11.76,100,1,11.93,200,2,12.1,100,1,12.2,200,2,12.33,100,1,13.73,100,1,13.87,200,2,14,100,1,14.03,2,1,14.28,100,1,14.45,100,1,14.52,100,1,14.56,800,2,14.6,700,1,14.64,200,2,ARL,327675057
2025-07-17T16:04:21.277142662Z,2025-07-17T16:04:21.276976977Z,160,2,1108,A,A,13.770000000,100,0,328239293,130,165685,273687857,ARL,0,13.77,100,130,165685,273687857,9.55,1700,17,9.68,100,1,10.61,200,2,11.27,100,1,11.4,100,1,11.76,100,1,11.93,200,2,12.1,100,1,12.2,200,2,12.33,100,1,13.73,100,1,13.77,100,1,13.87,200,2,14,100,1,14.03,2,1,14.28,100,1,14.45,100,1,14.52,100,1,14.56,800,2,14.6,700,1,ARL,328239293
2025-07-17T16:04:27.791055146Z,2025-07-17T16:04:27.790889618Z,160,2,1108,C,A,14.030000000,2,0,326159041,0,165528,273775264,ARL,0,14.03,2,0,165528,273775264,9.55,1700,17,9.68,100,1,10.61,200,2,11.27,100,1,11.4,100,1,11.76,100,1,11.93,200,2,12.1,100,1,12.2,200,2,12.33,100,1,13.73,100,1,13.77,100,1,13.87,200,2,14,100,1,14.28,100,1,14.45,100,1,14.52,100,1,14.56,800,2,14.6,700,1,14.64,200,2,ARL,326159041
2025-07-17T16:04:27.791055146Z,2025-07-17T16:04:27.790889618Z,160,2,1108,A,A,13.940000000,2,0,328351217,130,165528,273775264,ARL,0,13.94,2,130,165528,273775264,9.55,1700,17,9.68,100,1,10.61,200,2,11.27,100,1,11.4,100,1,11.76,100,1,11.93,200,2,12.1,100,1,12.2,200,2,12.33,100,1,13.73,100,1,13.77,100,1,13.87,200,2,13.94,2,1,14,100,1,14.28,100,1,14.45,100,1,14.52,100,1,14.56,800,2,14.6,700,1,ARL,328351217
2025-07-17T16:04:31.232053154Z,2025-07-17T16:04:31.231887784Z,160,2,1108,A,A,13.680000000,15,0,328437797,130,165370,273846737,ARL,0,13.68,15,130,165370,273846737,9.55,1700,17,9.68,100,1,10.61,200,2,11.27,100,1,11.4,100,1,11.76,100,1,11.93,200,2,12.1,100,1,12.2,200,2,12.33,100,1,13.68,15,1,13.73,100,1,13.77,100,1,13.87,200,2,13.94,2,1,14,100,1,14.28,100,1,14.45,100,1,14.52,100,1,14.56,800,2,ARL,328437797
2025-07-17T16:04:31.232606440Z,2025-07-17T16:04:31.232440773Z,160,2,1108,A,A,13.720000000,100,0,328437805,130,165667,273846745,ARL,0,13.72,100,130,165667,273846745,9.55,1700,17,9.68,100,1,10.61,200,2,11.27,100,1,11.4,100,1,11.76,100,1,11.93,200,2,12.1,100,1,12.2,200,2,12.33,100,1,13.68,15,1,13.72,100,1,13.73,100,1,13.77,100,1,13.87,200,2,13.94,2,1,14,100,1,14.28,100,1,14.45,100,1,14.52,100,1,ARL,328437805
2025-07-17T16:04:31.246681162Z,2025-07-17T16:04:31.246515467Z,160,2,1108,C,A,13.770000000,100,0,328239293,130,165695,273847000,ARL,0,13.77,100,130,165695,273847000,9.55,1700,17,9.68,100,1,10.61,200,2,11.27,100,1,11.4,100,1,11.76,100,1,11.93,200,2,12.1,100,1,12.2,200,2,12.33,100,1,13.68,15,1,13.72,100,1,13.73,100,1,13.87,200,2,13.94,2,1,14,100,1,14.28,100,1,14.45,100,1,14.52,100,1,14.56,800,2,ARL,328239293
2025-07-17T16:04:32.836802111Z,2025-07-17T16:04:32.836635838Z,160,2,1108,C,A,13.730000000,100,0,327864137,0,166273,273882084,ARL,0,13.73,100,0,166273,273882084,9.55,1700,17,9.68,100,1,10.61,200,2,11.27,100,1,11.4,100,1,11.76,100,1,11.93,200,2,12.1,100,1,12.2,200,2,12.33,100,1,13.68,15,1,13.72,100,1,13.87,200,2,13.94,2,1,14,100,1,14.28,100,1,14.45,100,1,14.52,100,1,14.56,800,2,14.6,700,1,ARL,327864137
2025-07-17T16:04:32.836802111Z,2025-07-17T16:04:32.836635838Z,160,2,1108,A,A,13.690000000,100,0,328489153,130,166273,273882084,ARL,0,13.69,100,130,166273,273882084,9.55,1700,17,9.68,100,1,10.61,200,2,11.27,100,1,11.4,100,1,11.76,100,1,11.93,200,2,12.1,100,1,12.2,200,2,12.33,100,1,13.68,15,1,13.69,100,1,13.72,100,1,13.87,200,2,13.94,2,1,14,100,1,14.28,100,1,14.45,100,1,14.52,100,1,14.56,800,2,ARL,328489153
2025-07-17T16:04:32.837165431Z,2025-07-17T16:04:32.837000154Z,160,2,1108,C,B,13.120000000,100,0,325718833,130,165277,273882201,ARL,0,13.12,100,130,165277,273882201,9.55,1700,17,9.68,100,1,10.61,200,2,11.27,100,1,11.4,100,1,11.76,100,1,11.93,200,2,12.1,100,1,12.2,200,2,12.33,100,1,13.68,15,1,13.69,100,1,13.72,100,1,13.87,200,2,13.94,2,1,14,100,1,14.28,100,1,14.45,100,1,14.52,100,1,14.56,800,2,ARL,325718833
2025-07-17T16:04:32.837169083Z,2025-07-17T16:04:32.837002825Z,160,2,1108,C,B,13.120000000,100,0,325718837,128,166258,273882202,ARL,0,13.12,100,128,166258,273882202,9.55,1700,17,9.68,100,1,10.61,200,2,11.27,100,1,11.4,100,1,11.76,100,1,11.93,200,2,12.1,100,1,12.2,200,2,12.33,100,1,13.68,15,1,13.69,100,1,13.72,100,1,13.87,200,2,13.94,2,1,14,100,1,14.28,100,1,14.45,100,1,14.52,100,1,14.56,800,2,ARL,325718837
2025-07-17T16:04:32.837179568Z,2025-07-17T16:04:32.837013456Z,160,2,1108,A,B,12.980000000,100,0,328489377,130,166112,273882207,ARL,0,12.98,100,130,166112,273882207,9.55,1700,17,9.68,100,1,10.61,200,2,11.27,100,1,11.4,100,1,11.76,100,1,11.93,200,2,12.1,100,1,12.2,200,2,12.33,100,1,13.68,15,1,13.69,100,1,13.72,100,1,13.87,200,2,13.94,2,1,14,100,1,14.28,100,1,14.45,100,1,14.52,100,1,14.56,800,2,ARL,328489377
2025-07-17T16:04:32.837181582Z,2025-07-17T16:04:32.837016087Z,160,2,1108,A,B,12.980000000,100,0,328489385,130,165495,273882208,ARL,0,12.98,100,130,165495,273882208,9.55,1700,17,9.68,100,1,10.61,200,2,11.27,100,1,11.4,100,1,11.76,100,1,11.93,200,2,12.1,100,1,12.2,200,2,12.33,100,1,13.68,15,1,13.69,100,1,13.72,100,1,13.87,200,2,13.94,2,1,14,100,1,14.28,100,1,14.45,100,1,14.52,100,1,14.56,800,2,ARL,328489385
2025-07-17T16:04:32.837536434Z,2025-07-17T16:04:32.837369811Z,160,2,1108,C,A,14.790000000,100,0,327864893,0,166623,273882286,ARL,0,14.79,100,0,166623,273882286,9.55,1700,17,9.68,100,1,10.61,200,2,11.27,100,1,11.4,100,1,11.76,100,1,11.93,200,2,12.1,100,1,12.2,200,2,12.33,100,1,13.68,15,1,13.69,100,1,13.72,100,1,13.87,200,2,13.94,2,1,14,100,1,14.28,100,1,14.45,100,1,14.52,100,1,14.56,800,2,ARL,327864893
2025-07-17T16:04:32.837536434Z,2025-07-17T16:04:32.837369811Z,160,2,1108,A,A,14.750000000,100,0,328489481,128,166623,273882286,ARL,0,14.75,100,128,166623,273882286,9.55,1700,17,9.68,100,1,10.61,200,2,11.27,100,1,11.4,100,1,11.76,100,1,11.93,200,2,12.1,100,1,12.2,200,2,12.33,100,1,13.68,15,1,13.69,100,1,13.72,100,1,13.87,200,2,13.94,2,1,14,100,1,14.28,100,1,14.45,100,1,14.52,100,1,14.56,800,2,ARL,328489481
2025-07-17T16:04:36.810717146Z,2025-07-17T16:04:36.810551890Z,160,2,1108,A,A,13.650000000,15,0,328603377,130,165256,273963456,ARL,0,13.65,15,130,165256,273963456,9.55,1700,17,9.68,100,1,10.61,200,2,11.27,100,1,11.4,100,1,11.76,100,1,11.93,200,2,12.1,100,1,12.2,200,2,12.33,100,1,13.65,15,1,13.68,15,1,13.69,100,1,13.72,100,1,13.87,200,2,13.94,2,1,14,100,1,14.28,100,1,14.45,100,1,14.52,100,1,ARL,328603377
2025-07-17T16:04:37.026937493Z,2025-07-17T16:04:37.026771973Z,160,2,1108,A,A,13.690000000,100,0,328606289,130,165520,273965417,ARL,0,13.69,100,130,165520,273965417,9.55,1700,17,9.68,100,1,10.61,200,2,11.27,100,1,11.4,100,1,11.76,100,1,11.93,200,2,12.1,100,1,12.2,200,2,12.33,100,1,13.65,15,1,13.68,15,1,13.69,200,2,13.72,100,1,13.87,200,2,13.94,2,1,14,100,1,14.28,100,1,14.45,100,1,14.52,100,1,ARL,328606289
2025-07-17T16:04:37.033554557Z,2025-07-17T16:04:37.033389265Z,160,2,1108,C,A,13.720000000,100,0,328437805,130,165292,273965562,ARL,0,13.72,100,130,165292,273965562,9.55,1700,17,9.68,100,1,10.61,200,2,11.27,100,1,11.4,100,1,11.76,100,1,11.93,200,2,12.1,100,1,12.2,200,2,12.33,100,1,13.65,15,1,13.68,15,1,13.69,200,2,13.87,200,2,13.94,2,1,14,100,1,14.28,100,1,14.45,100,1,14.52,100,1,14.56,800,2,ARL,328437805
2025-07-17T16:04:37.542961161Z,2025-07-17T16:04:37.542795711Z,160,2,1108,C,A,13.690000000,100,0,328489153,0,165450,273971021,ARL,0,13.69,100,0,165450,273971021,9.55,1700,17,9.68,100,1,10.61,200,2,11.27,100,1,11.4,100,1,11.76,100,1,11.93,200,2,12.1,100,1,12.2,200,2,12.33,100,1,13.65,15,1,13.68,15,1,13.69,100,1,13.87,200,2,13.94,2,1,14,100,1,14.28,100,1,14.45,100,1,14.52,100,1,14.56,800,2,ARL,328489153
2025-07-17T16:04:37.542961161Z,2025-07-17T16:04:37.542795711Z,160,2,1108,A,A,13.660000000,100,0,328614509,130,165450,273971021,ARL,0,13.66,100,130,165450,273971021,9.55,1700,17,9.68,100,1,10.61,200,2,11.27,100,1,11.4,100,1,11.76,100,1,11.93,200,2,12.1,100,1,12.2,200,2,12.33,100,1,13.65,15,1,13.66,100,1,13.68,15,1,13.69,100,1,13.87,200,2,13.94,2,1,14,100,1,14.28,100,1,14.45,100,1,14.52,100,1,ARL,328614509
2025-07-17T16:04:37.543230680Z,2025-07-17T16:04:37.543063240Z,160,2,1108,C,A,13.870000000,100,0,326730517,0,167440,273971035,ARL,0,13.87,100,0,167440,273971035,9.55,1700,17,9.68,100,1,10.61,200,2,11.27,100,1,11.4,100,1,11.76,100,1,11.93,200,2,12.1,100,1,12.2,200,2,12.33,100,1,13.65,15,1,13.66,100,1,13.68,15,1,13.69,100,1,13.87,100,1,13.94,2,1,14,100,1,14.28,100,1,14.45,100,1,14.52,100,1,ARL,326730517
2025-07-17T16:04:37.543230680Z,2025-07-17T16:04:37.543064690Z,160,2,1108,C,A,13.870000000,100,0,326730521,130,165990,273971037,ARL,0,13.87,100,130,165990,273971037,9.55,1700,17,9.68,100,1,10.61,200,2,11.27,100,1,11.4,100,1,11.76,100,1,11.93,200,2,12.1,100,1,12.2,200,2,12.33,100,1,13.65,15,1,13.66,100,1,13.68,15,1,13.69,100,1,13.94,2,1,14,100,1,14.28,100,1,14.45,100,1,14.52,100,1,14.56,800,2,ARL,326730521
2025-07-17T16:04:37.543242390Z,2025-07-17T16:04:37.543077174Z,160,2,1108,A,A,13.800000000,100,0,328614525,130,165216,273971040,ARL,0,13.8,100,130,165216,273971040,9.55,1700,17,9.68,100,1,10.61,200,2,11.27,100,1,11.4,100,1,11.76,100,1,11.93,200,2,12.1,100,1,12.2,200,2,12.33,100,1,13.65,15,1,13.66,100,1,13.68,15,1,13.69,100,1,13.8,100,1,13.94,2,1,14,100,1,14.28,100,1,14.45,100,1,14.52,100,1,ARL,328614525
2025-07-17T16:04:37.543244193Z,2025-07-17T16:04:37.543078532Z,160,2,1108,A,A,13.800000000,100,0,328614529,130,165661,273971041,ARL,0,13.8,100,130,165661,273971041,9.55,1700,17,9.68,100,1,10.61,200,2,11.27,100,1,11.4,100,1,11.76,100,1,11.93,200,2,12.1,100,1,12.2,200,2,12.33,100,1,13.65,15,1,13.66,100,1,13.68,15,1,13.69,100,1,13.8,200,2,13.94,2,1,14,100,1,14.28,100,1,14.45,100,1,14.52,100,1,ARL,328614529
2025-07-17T16:04:37.549684713Z,2025-07-17T16:04:37.549519006Z,160,2,1108,C,A,14.000000000,100,0,327869193,130,165707,273973481,ARL,0,14,100,130,165707,273973481,9.55,1700,17,9.68,100,1,10.61,200,2,11.27,100,1,11.4,100,1,11.76,100,1,11.93,200,2,12.1,100,1,12.2,200,2,12.33,100,1,13.65,15,1,13.66,100,1,13.68,15,1,13.69,100,1,13.8,200,2,13.94,2,1,14.28,100,1,14.45,100,1,14.52,100,1,14.56,800,2,ARL,327869193
2025-07-17T16:04:37.549735824Z,2025-07-17T16:04:37.549570649Z,160,2,1108,A,A,13.930000000,100,0,328616925,130,165175,273973485,ARL,0,13.93,100,130,165175,273973485,9.55,1700,17,9.68,100,1,10.61,200,2,11.27,100,1,11.4,100,1,11.76,100,1,11.93,200,2,12.1,100,1,12.2,200,2,12.33,100,1,13.65,15,1,13.66,100,1,13.68,15,1,13.69,100,1,13.8,200,2,13.93,100,1,13.94,2,1,14.28,100,1,14.45,100,1,14.52,100,1,ARL,328616925
2025-07-17T16:04:44.524526545Z,2025-07-17T16:04:44.524360626Z,160,2,1108,C,A,13.680000000,15,0,328437797,130,165919,274066152,ARL,0,13.68,15,130,165919,274066152,9.55,1700,17,9.68,100,1,10.61,200,2,11.27,100,1,11.4,100,1,11.76,100,1,11.93,200,2,12.1,100,1,12.2,200,2,12.33,100,1,13.65,15,1,13.66,100,1,13.69,100,1,13.8,200,2,13.93,100,1,13.94,2,1,14.28,100,1,14.45,100,1,14.52,100,1,14.56,800,2,ARL,328437797
2025-07-17T16:04:45.528000143Z,2025-07-17T16:04:45.527835033Z,160,2,1108,A,A,13.630000000,15,0,328780565,130,165110,274088918,ARL,0,13.63,15,130,165110,274088918,9.55,1700,17,9.68,100,1,10.61,200,2,11.27,100,1,11.4,100,1,11.76,100,1,11.93,200,2,12.1,100,1,12.2,200,2,12.33,100,1,13.63,15,1,13.65,15,1,13.66,100,1,13.69,100,1,13.8,200,2,13.93,100,1,13.94,2,1,14.28,100,1,14.45,100,1,14.52,100,1,ARL,328780565
2025-07-17T16:04:45.528629613Z,2025-07-17T16:04:45.528464092Z,160,2,1108,C,A,14.640000000,100,0,327856309,0,165521,274088922,ARL,0,14.64,100,0,165521,274088922,9.55,1700,17,9.68,100,1,10.61,200,2,11.27,100,1,11.4,100,1,11.76,100,1,11.93,200,2,12.1,100,1,12.2,200,2,12.33,100,1,13.63,15,1,13.65,15,1,13.66,100,1,13.69,100,1,13.8,200,2,13.93,100,1,13.94,2,1,14.28,100,1,14.45,100,1,14.52,100,1,ARL,327856309
2025-07-17T16:04:45.528629613Z,2025-07-17T16:04:45.528464092Z,160,2,1108,A,A,14.520000000,100,0,328780577,130,165521,274088922,ARL,0,14.52,100,130,165521,274088922,9.55,1700,17,9.68,100,1,10.61,200,2,11.27,100,1,11.4,100,1,11.76,100,1,11.93,200,2,12.1,100,1,12.2,200,2,12.33,100,1,13.63,15,1,13.65,15,1,13.66,100,1,13.69,100,1,13.8,200,2,13.93,100,1,13.94,2,1,14.28,100,1,14.45,100,1,14.52,200,2,ARL,328780577
2025-07-17T16:04:45.530418278Z,2025-07-17T16:04:45.530252804Z,160,2,1108,C,A,14.640000000,100,0,327856297,0,165474,274088937,ARL,0,14.64,100,0,165474,274088937,9.55,1700,17,9.68,100,1,10.61,200,2,11.27,100,1,11.4,100,1,11.76,100,1,11.93,200,2,12.1,100,1,12.2,200,2,12.33,100,1,13.63,15,1,13.65,15,1,13.66,100,1,13.69,100,1,13.8,200,2,13.93,100,1,13.94,2,1,14.28,100,1,14.45,100,1,14.52,200,2,ARL,327856297
2025-07-17T16:04:45.530418278Z,2025-07-17T16:04:45.530252804Z,160,2,1108,A,A,14.520000000,100,0,328780597,130,165474,274088937,ARL,0,14.52,100,130,165474,274088937,9.55,1700,17,9.68,100,1,10.61,200,2,11.27,100,1,11.4,100,1,11.76,100,1,11.93,200,2,12.1,100,1,12.2,200,2,12.33,100,1,13.63,15,1,13.65,15,1,13.66,100,1,13.69,100,1,13.8,200,2,13.93,100,1,13.94,2,1,14.28,100,1,14.45,100,1,14.52,300,3,ARL,328780597
2025-07-17T16:04:45.533067029Z,2025-07-17T16:04:45.532901874Z,160,2,1108,C,A,13.660000000,100,0,328614509,0,165155,274088955,ARL,0,13.66,100,0,165155,274088955,9.55,1700,17,9.68,100,1,10.61,200,2,11.27,100,1,11.4,100,1,11.76,100,1,11.93,200,2,12.1,100,1,12.2,200,2,12.33,100,1,13.63,15,1,13.65,15,1,13.69,100,1,13.8,200,2,13.93,100,1,13.94,2,1,14.28,100,1,14.45,100,1,14.52,300,3,14.56,800,2,ARL,328614509
2025-07-17T16:04:45.533067029Z,2025-07-17T16:04:45.532901874Z,160,2,1108,A,A,13.640000000,100,0,328780669,130,165155,274088955,ARL,0,13.64,100,130,165155,274088955,9.55,1700,17,9.68,100,1,10.61,200,2,11.27,100,1,11.4,100,1,11.76,100,1,11.93,200,2,12.1,100,1,12.2,200,2,12.33,100,1,13.63,15,1,13.64,100,1,13.65,15,1,13.69,100,1,13.8,200,2,13.93,100,1,13.94,2,1,14.28,100,1,14.45,100,1,14.52,300,3,ARL,328780669
2025-07-17T16:04:45.533804768Z,2025-07-17T16:04:45.533639142Z,160,2,1108,C,A,14.750000000,100,0,328489481,0,165626,274088957,ARL,0,14.75,100,0,165626,274088957,9.55,1700,17,9.68,100,1,10.61,200,2,11.27,100,1,11.4,100,1,11.76,100,1,11.93,200,2,12.1,100,1,12.2,200,2,12.33,100,1,13.63,15,1,13.64,100,1,13.65,15,1,13.69,100,1,13.8,200,2,13.93,100,1,13.94,2,1,14.28,100,1,14.45,100,1,14.52,300,3,ARL,328489481
2025-07-17T16:04:45.533804768Z,2025-07-17T16:04:45.533639142Z,160,2,1108,A,A,14.700000000,100,0,328780685,130,165626,274088957,ARL,0,14.7,100,130,165626,274088957,9.55,1700,17,9.68,100,1,10.61,200,2,11.27,100,1,11.4,100,1,11.76,100,1,11.93,200,2,12.1,100,1,12.2,200,2,12.33,100,1,13.63,15,1,13.64,100,1,13.65,15,1,13.69,100,1,13.8,200,2,13.93,100,1,13.94,2,1,14.28,100,1,14.45,100,1,14.52,300,3,ARL,328780685
2025-07-17T16:04:45.533870711Z,2025-07-17T16:04:45.533705428Z,160,2,1108,A,A,13.670000000,100,0,328780689,130,165283,274088959,ARL,0,13.67,100,130,165283,274088959,9.55,1700,17,9.68,100,1,10.61,200,2,11.27,100,1,11.4,100,1,11.76,100,1,11.93,200,2,12.1,100,1,12.2,200,2,12.33,100,1,13.63,15,1,13.64,100,1,13.65,15,1,13.67,100,1,13.69,100,1,13.8,200,2,13.93,100,1,13.94,2,1,14.28,100,1,14.45,100,1,ARL,328780689
2025-07-17T16:04:45.563137443Z,2025-07-17T16:04:45.562972204Z,160,2,1108,C,A,13.690000000,100,0,328606289,130,165239,274089319,ARL,0,13.69,100,130,165239,274089319,9.55,1700,17,9.68,100,1,10.61,200,2,11.27,100,1,11.4,100,1,11.76,100,1,11.93,200,2,12.1,100,1,12.2,200,2,12.33,100,1,13.63,15,1,13.64,100,1,13.65,15,1,13.67,100,1,13.8,200,2,13.93,100,1,13.94,2,1,14.28,100,1,14.45,100,1,14.52,300,3,ARL,328606289
2025-07-17T16:04:56.809749973Z,2025-07-17T16:04:56.809584701Z,160,2,1108,C,A,13.650000000,15,0,328603377,130,165272,274293432,ARL,0,13.65,15,130,165272,274293432,9.55,1700,17,9.68,100,1,10.61,200,2,11.27,100,1,11.4,100,1,11.76,100,1,11.93,200,2,12.1,100,1,12.2,200,2,12.33,100,1,13.63,15,1,13.64,100,1,13.67,100,1,13.8,200,2,13.93,100,1,13.94,2,1,14.28,100,1,14.45,100,1,14.52,300,3,14.56,800,2,ARL,328603377
2025-07-17T16:04:57.827079009Z,2025-07-17T16:04:57.826913717Z,160,2,1108,A,A,13.610000000,15,0,329068341,130,165292,274310244,ARL,0,13.61,15,130,165292,274310244,9.55,1700,17,9.68,100,1,10.61,200,2,11.27,100,1,11.4,100,1,11.76,100,1,11.93,200,2,12.1,100,1,12.2,200,2,12.33,100,1,13.61,15,1,13.63,15,1,13.64,100,1,13.67,100,1,13.8,200,2,13.93,100,1,13.94,2,1,14.28,100,1,14.45,100,1,14.52,300,3,ARL,329068341
2025-07-17T16:04:57.970616610Z,2025-07-17T16:04:57.970451236Z,160,2,1108,C,A,13.640000000,100,0,328780669,0,165374,274316281,ARL,0,13.64,100,0,165374,274316281,9.55,1700,17,9.68,100,1,10.61,200,2,11.27,100,1,11.4,100,1,11.76,100,1,11.93,200,2,12.1,100,1,12.2,200,2,12.33,100,1,13.61,15,1,13.63,15,1,13.67,100,1,13.8,200,2,13.93,100,1,13.94,2,1,14.28,100,1,14.45,100,1,14.52,300,3,14.56,800,2,ARL,328780669
2025-07-17T16:04:57.970616610Z,2025-07-17T16:04:57.970451236Z,160,2,1108,A,A,13.620000000,100,0,329074609,130,165374,274316281,ARL,0,13.62,100,130,165374,274316281,9.55,1700,17,9.68,100,1,10.61,200,2,11.27,100,1,11.4,100,1,11.76,100,1,11.93,200,2,12.1,100,1,12.2,200,2,12.33,100,1,13.61,15,1,13.62,100,1,13.63,15,1,13.67,100,1,13.8,200,2,13.93,100,1,13.94,2,1,14.28,100,1,14.45,100,1,14.52,300,3,ARL,329074609
2025-07-17T16:04:57.971360344Z,2025-07-17T16:04:57.971193734Z,160,2,1108,C,A,14.450000000,100,0,325714601,128,166610,274316507,ARL,0,14.45,100,128,166610,274316507,9.55,1700,17,9.68,100,1,10.61,200,2,11.27,100,1,11.4,100,1,11.76,100,1,11.93,200,2,12.1,100,1,12.2,200,2,12.33,100,1,13.61,15,1,13.62,100,1,13.63,15,1,13.67,100,1,13.8,200,2,13.93,100,1,13.94,2,1,14.28,100,1,14.52,300,3,14.56,800,2,ARL,325714601
2025-07-17T16:04:57.971717511Z,2025-07-17T16:04:57.971552262Z,160,2,1108,A,A,14.230000000,100,0,329074833,130,165249,274316527,ARL,0,14.23,100,130,165249,274316527,9.55,1700,17,9.68,100,1,10.61,200,2,11.27,100,1,11.4,100,1,11.76,100,1,11.93,200,2,12.1,100,1,12.2,200,2,12.33,100,1,13.61,15,1,13.62,100,1,13.63,15,1,13.67,100,1,13.8,200,2,13.93,100,1,13.94,2,1,14.23,100,1,14.28,100,1,14.52,300,3,ARL,329074833
2025-07-17T16:04:57.992131878Z,2025-07-17T16:04:57.991966904Z,160,2,1108,C,A,13.610000000,15,0,329068341,130,164974,274318490,ARL,0,13.61,15,130,164974,274318490,9.55,1700,17,9.68,100,1,10.61,200,2,11.27,100,1,11.4,100,1,11.76,100,1,11.93,200,2,12.1,100,1,12.2,200,2,12.33,100,1,13.62,100,1,13.63,15,1,13.67,100,1,13.8,200,2,13.93,100,1,13.94,2,1,14.23,100,1,14.28,100,1,14.52,300,3,14.56,800,2,ARL,329068341
2025-07-17T16:04:57.993141438Z,2025-07-17T16:04:57.992976406Z,160,2,1108,C,A,13.620000000,100,0,329074609,130,165032,274318579,ARL,0,13.62,100,130,165032,274318579,9.55,1700,17,9.68,100,1,10.61,200,2,11.27,100,1,11.4,100,1,11.76,100,1,11.93,200,2,12.1,100,1,12.2,200,2,12.33,100,1,13.63,15,1,13.67,100,1,13.8,200,2,13.93,100,1,13.94,2,1,14.23,100,1,14.28,100,1,14.52,300,3,14.56,800,2,14.6,700,1,ARL,329074609
2025-07-17T16:04:57.993309561Z,2025-07-17T16:04:57.993143873Z,160,2,1108,C,A,13.630000000,15,0,328780565,130,165688,274318603,ARL,0,13.63,15,130,165688,274318603,9.55,1700,17,9.68,100,1,10.61,200,2,11.27,100,1,11.4,100,1,11.76,100,1,11.93,200,2,12.1,100,1,12.2,200,2,12.33,100,1,13.67,100,1,13.8,200,2,13.93,100,1,13.94,2,1,14.23,100,1,14.28,100,1,14.52,300,3,14.56,800,2,14.6,700,1,14.68,1400,2,ARL,328780565
2025-07-17T16:04:58.002259715Z,2025-07-17T16:04:58.002094377Z,160,2,1108,C,A,13.670000000,100,0,328780689,130,165338,274319058,ARL,0,13.67,100,130,165338,274319058,9.55,1700,17,9.68,100,1,10.61,200,2,11.27,100,1,11.4,100,1,11.76,100,1,11.93,200,2,12.1,100,1,12.2,200,2,12.33,100,1,13.8,200,2,13.93,100,1,13.94,2,1,14.23,100,1,14.28,100,1,14.52,300,3,14.56,800,2,14.6,700,1,14.68,1400,2,14.7,300,3,ARL,328780689
2025-07-17T16:04:58.002989430Z,2025-07-17T16:04:58.002823841Z,160,2,1108,C,A,14.700000000,100,0,328780685,0,165589,274319069,ARL,0,14.7,100,0,165589,274319069,9.55,1700,17,9.68,100,1,10.61,200,2,11.27,100,1,11.4,100,1,11.76,100,1,11.93,200,2,12.1,100,1,12.2,200,2,12.33,100,1,13.8,200,2,13.93,100,1,13.94,2,1,14.23,100,1,14.28,100,1,14.52,300,3,14.56,800,2,14.6,700,1,14.68,1400,2,14.7,200,2,ARL,328780685
2025-07-17T16:04:58.002989430Z,2025-07-17T16:04:58.002823841Z,160,2,1108,A,A,14.870000000,100,0,329078553,130,165589,274319069,ARL,0,14.87,100,130,165589,274319069,9.55,1700,17,9.68,100,1,10.61,200,2,11.27,100,1,11.4,100,1,11.76,100,1,11.93,200,2,12.1,100,1,12.2,200,2,12.33,100,1,13.8,200,2,13.93,100,1,13.94,2,1,14.23,100,1,14.28,100,1,14.52,300,3,14.56,800,2,14.6,700,1,14.68,1400,2,14.7,200,2,ARL,329078553
2025-07-17T16:04:58.013904697Z,2025-07-17T16:04:58.013739242Z,160,2,1108,C,A,13.930000000,100,0,328616925,130,165455,274319298,ARL,0,13.93,100,130,165455,274319298,9.55,1700,17,9.68,100,1,10.61,200,2,11.27,100,1,11.4,100,1,11.76,100,1,11.93,200,2,12.1,100,1,12.2,200,2,12.33,100,1,13.8,200,2,13.94,2,1,14.23,100,1,14.28,100,1,14.52,300,3,14.56,800,2,14.6,700,1,14.68,1400,2,14.7,200,2,14.87,100,1,ARL,328616925
2025-07-17T16:04:58.013959233Z,2025-07-17T16:04:58.013793974Z,160,2,1108,A,A,14.080000000,100,0,329078953,130,165259,274319304,ARL,0,14.08,100,130,165259,274319304,9.55,1700,17,9.68,100,1,10.61,200,2,11.27,100,1,11.4,100,1,11.76,100,1,11.93,200,2,12.1,100,1,12.2,200,2,12.33,100,1,13.8,200,2,13.94,2,1,14.08,100,1,14.23,100,1,14.28,100,1,14.52,300,3,14.56,800,2,14.6,700,1,14.68,1400,2,14.7,200,2,ARL,329078953
2025-07-17T16:04:58.536617917Z,2025-07-17T16:04:58.536452621Z,160,2,1108,A,A,13.810000000,100,0,329088265,130,165296,274326535,ARL,0,13.81,100,130,165296,274326535,9.55,1700,17,9.68,100,1,10.61,200,2,11.27,100,1,11.4,100,1,11.76,100,1,11.93,200,2,12.1,100,1,12.2,200,2,12.33,100,1,13.8,200,2,13.81,100,1,13.94,2,1,14.08,100,1,14.23,100,1,14.28,100,1,14.52,300,3,14.56,800,2,14.6,700,1,14.68,1400,2,ARL,329088265
2025-07-17T16:05:46.594131664Z,2025-07-17T16:05:46.593966383Z,160,2,1108,A,A,13.760000000,100,0,330066537,130,165281,275083968,ARL,0,13.76,100,130,165281,275083968,9.55,1700,17,9.68,100,1,10.61,200,2,11.27,100,1,11.4,100,1,11.76,100,1,11.93,200,2,12.1,100,1,12.2,200,2,12.33,100,1,13.76,100,1,13.8,200,2,13.81,100,1,13.94,2,1,14.08,100,1,14.23,100,1,14.28,100,1,14.52,300,3,14.56,800,2,14.6,700,1,ARL,330066537
2025-07-17T16:05:46.594871336Z,2025-07-17T16:05:46.594705962Z,160,2,1108,C,A,14.870000000,100,0,329078553,0,165374,275083970,ARL,0,14.87,100,0,165374,275083970,9.55,1700,17,9.68,100,1,10.61,200,2,11.27,100,1,11.4,100,1,11.76,100,1,11.93,200,2,12.1,100,1,12.2,200,2,12.33,100,1,13.76,100,1,13.8,200,2,13.81,100,1,13.94,2,1,14.08,100,1,14.23,100,1,14.28,100,1,14.52,300,3,14.56,800,2,14.6,700,1,ARL,329078553
2025-07-17T16:05:46.594871336Z,2025-07-17T16:05:46.594705962Z,160,2,1108,A,A,14.830000000,100,0,330066553,130,165374,275083970,ARL,0,14.83,100,130,165374,275083970,9.55,1700,17,9.68,100,1,10.61,200,2,11.27,100,1,11.4,100,1,11.76,100,1,11.93,200,2,12.1,100,1,12.2,200,2,12.33,100,1,13.76,100,1,13.8,200,2,13.81,100,1,13.94,2,1,14.08,100,1,14.23,100,1,14.28,100,1,14.52,300,3,14.56,800,2,14.6,700,1,ARL,330066553
2025-07-17T16:05:46.996003552Z,2025-07-17T16:05:46.995837526Z,160,2,1108,C,A,13.810000000,100,0,329088265,0,166026,275092978,ARL,0,13.81,100,0,166026,275092978,9.55,1700,17,9.68,100,1,10.61,200,2,11.27,100,1,11.4,100,1,11.76,100,1,11.93,200,2,12.1,100,1,12.2,200,2,12.33,100,1,13.76,100,1,13.8,200,2,13.94,2,1,14.08,100,1,14.23,100,1,14.28,100,1,14.52,300,3,14.56,800,2,14.6,700,1,14.68,1400,2,ARL,329088265
2025-07-17T16:05:46.996003552Z,2025-07-17T16:05:46.995837526Z,160,2,1108,A,A,13.770000000,100,0,330075425,130,166026,275092978,ARL,0,13.77,100,130,166026,275092978,9.55,1700,17,9.68,100,1,10.61,200,2,11.27,100,1,11.4,100,1,11.76,100,1,11.93,200,2,12.1,100,1,12.2,200,2,12.33,100,1,13.76,100,1,13.77,100,1,13.8,200,2,13.94,2,1,14.08,100,1,14.23,100,1,14.28,100,1,14.52,300,3,14.56,800,2,14.6,700,1,ARL,330075425
2025-07-17T16:05:50.680333151Z,2025-07-17T16:05:50.680167632Z,160,2,1108,A,A,13.680000000,15,0,330143813,130,165519,275152014,ARL,0,13.68,15,130,165519,275152014,9.55,1700,17,9.68,100,1,10.61,200,2,11.27,100,1,11.4,100,1,11.76,100,1,11.93,200,2,12.1,100,1,12.2,200,2,12.33,100,1,13.68,15,1,13.76,100,1,13.77,100,1,13.8,200,2,13.94,2,1,14.08,100,1,14.23,100,1,14.28,100,1,14.52,300,3,14.56,800,2,ARL,330143813
2025-07-17T16:05:50.697170320Z,2025-07-17T16:05:50.697005084Z,160,2,1108,A,A,13.720000000,100,0,330144301,130,165236,275152383,ARL,0,13.72,100,130,165236,275152383,9.55,1700,17,9.68,100,1,10.61,200,2,11.27,100,1,11.4,100,1,11.76,100,1,11.93,200,2,12.1,100,1,12.2,200,2,12.33,100,1,13.68,15,1,13.72,100,1,13.76,100,1,13.77,100,1,13.8,200,2,13.94,2,1,14.08,100,1,14.23,100,1,14.28,100,1,14.52,300,3,ARL,330144301
2025-07-17T16:05:50.697905372Z,2025-07-17T16:05:50.697739933Z,160,2,1108,C,A,14.830000000,100,0,330066553,0,165439,275152385,ARL,0,14.83,100,0,165439,275152385,9.55,1700,17,9.68,100,1,10.61,200,2,11.27,100,1,11.4,100,1,11.76,100,1,11.93,200,2,12.1,100,1,12.2,200,2,12.33,100,1,13.68,15,1,13.72,100,1,13.76,100,1,13.77,100,1,13.8,200,2,13.94,2,1,14.08,100,1,14.23,100,1,14.28,100,1,14.52,300,3,ARL,330066553
2025-07-17T16:05:50.697905372Z,2025-07-17T16:05:50.697739933Z,160,2,1108,A,A,14.780000000,100,0,330144321,130,165439,275152385,ARL,0,14.78,100,130,165439,275152385,9.55,1700,17,9.68,100,1,10.61,200,2,11.27,100,1,11.4,100,1,11.76,100,1,11.93,200,2,12.1,100,1,12.2,200,2,12.33,100,1,13.68,15,1,13.72,100,1,13.76,100,1,13.77,100,1,13.8,200,2,13.94,2,1,14.08,100,1,14.23,100,1,14.28,100,1,14.52,300,3,ARL,330144321
2025-07-17T16:05:50.704531748Z,2025-07-17T16:05:50.704366332Z,160,2,1108,C,A,13.760000000,100,0,330066537,130,165416,275152443,ARL,0,13.76,100,130,165416,275152443,9.55,1700,17,9.68,100,1,10.61,200,2,11.27,100,1,11.4,100,1,11.76,100,1,11.93,200,2,12.1,100,1,12.2,200,2,12.33,100,1,13.68,15,1,13.72,100,1,13.77,100,1,13.8,200,2,13.94,2,1,14.08,100,1,14.23,100,1,14.28,100,1,14.52,300,3,14.56,800,2,ARL,330066537
2025-07-17T16:05:50.708879311Z,2025-07-17T16:05:50.708714027Z,160,2,1108,C,A,14.080000000,100,0,329078953,130,165284,275152465,ARL,0,14.08,100,130,165284,275152465,9.55,1700,17,9.68,100,1,10.61,200,2,11.27,100,1,11.4,100,1,11.76,100,1,11.93,200,2,12.1,100,1,12.2,200,2,12.33,100,1,13.68,15,1,13.72,100,1,13.77,100,1,13.8,200,2,13.94,2,1,14.23,100,1,14.28,100,1,14.52,300,3,14.56,800,2,14.6,700,1,ARL,329078953
2025-07-17T16:05:50.708931189Z,2025-07-17T16:05:50.708766050Z,160,2,1108,A,A,13.990000000,100,0,330144513,130,165139,275152466,ARL,0,13.99,100,130,165139,275152466,9.55,1700,17,9.68,100,1,10.61,200,2,11.27,100,1,11.4,100,1,11.76,100,1,11.93,200,2,12.1,100,1,12.2,200,2,12.33,100,1,13.68,15,1,13.72,100,1,13.77,100,1,13.8,200,2,13.94,2,1,13.99,100,1,14.23,100,1,14.28,100,1,14.52,300,3,14.56,800,2,ARL,330144513
2025-07-17T16:05:50.913476268Z,2025-07-17T16:05:50.913310799Z,160,2,1108,C,A,13.770000000,100,0,330075425,0,165469,275159685,ARL,0,13.77,100,0,165469,275159685,9.55,1700,17,9.68,100,1,10.61,200,2,11.27,100,1,11.4,100,1,11.76,100,1,11.93,200,2,12.1,100,1,12.2,200,2,12.33,100,1,13.68,15,1,13.72,100,1,13.8,200,2,13.94,2,1,13.99,100,1,14.23,100,1,14.28,100,1,14.52,300,3,14.56,800,2,14.6,700,1,ARL,330075425
2025-07-17T16:05:50.913476268Z,2025-07-17T16:05:50.913310799Z,160,2,1108,A,A,13.690000000,100,0,330151389,130,165469,275159685,ARL,0,13.69,100,130,165469,275159685,9.55,1700,17,9.68,100,1,10.61,200,2,11.27,100,1,11.4,100,1,11.76,100,1,11.93,200,2,12.1,100,1,12.2,200,2,12.33,100,1,13.68,15,1,13.69,100,1,13.72,100,1,13.8,200,2,13.94,2,1,13.99,100,1,14.23,100,1,14.28,100,1,14.52,300,3,14.56,800,2,ARL,330151389
2025-07-17T16:05:59.704955970Z,2025-07-17T16:05:59.704790753Z,160,2,1108,A,A,13.640000000,15,0,330357473,130,165217,275325555,ARL,0,13.64,15,130,165217,275325555,9.55,1700,17,9.68,100,1,10.61,200,2,11.27,100,1,11.4,100,1,11.76,100,1,11.93,200,2,12.1,100,1,12.2,200,2,12.33,100,1,13.64,15,1,13.68,15,1,13.69,100,1,13.72,100,1,13.8,200,2,13.94,2,1,13.99,100,1,14.23,100,1,14.28,100,1,14.52,300,3,ARL,330357473
2025-07-17T16:05:59.715090662Z,2025-07-17T16:05:59.714925412Z,160,2,1108,A,A,13.680000000,100,0,330357633,130,165250,275325807,ARL,0,13.68,100,130,165250,275325807,9.55,1700,17,9.68,100,1,10.61,200,2,11.27,100,1,11.4,100,1,11.76,100,1,11.93,200,2,12.1,100,1,12.2,200,2,12.33,100,1,13.64,15,1,13.68,115,2,13.69,100,1,13.72,100,1,13.8,200,2,13.94,2,1,13.99,100,1,14.23,100,1,14.28,100,1,14.52,300,3,ARL,330357633
2025-07-17T16:05:59.722895750Z,2025-07-17T16:05:59.722730507Z,160,2,1108,C,A,13.720000000,100,0,330144301,130,165243,275325854,ARL,0,13.72,100,130,165243,275325854,9.55,1700,17,9.68,100,1,10.61,200,2,11.27,100,1,11.4,100,1,11.76,100,1,11.93,200,2,12.1,100,1,12.2,200,2,12.33,100,1,13.64,15,1,13.68,115,2,13.69,100,1,13.8,200,2,13.94,2,1,13.99,100,1,14.23,100,1,14.28,100,1,14.52,300,3,14.56,800,2,ARL,330144301
2025-07-17T16:05:59.802762087Z,2025-07-17T16:05:59.802596747Z,160,2,1108,C,A,13.690000000,100,0,330151389,0,165340,275327082,ARL,0,13.69,100,0,165340,275327082,9.55,1700,17,9.68,100,1,10.61,200,2,11.27,100,1,11.4,100,1,11.76,100,1,11.93,200,2,12.1,100,1,12.2,200,2,12.33,100,1,13.64,15,1,13.68,115,2,13.8,200,2,13.94,2,1,13.99,100,1,14.23,100,1,14.28,100,1,14.52,300,3,14.56,800,2,14.6,700,1,ARL,330151389
2025-07-17T16:05:59.802762087Z,2025-07-17T16:05:59.802596747Z,160,2,1108,A,A,13.650000000,100,0,330359197,130,165340,275327082,ARL,0,13.65,100,130,165340,275327082,9.55,1700,17,9.68,100,1,10.61,200,2,11.27,100,1,11.4,100,1,11.76,100,1,11.93,200,2,12.1,100,1,12.2,200,2,12.33,100,1,13.64,15,1,13.65,100,1,13.68,115,2,13.8,200,2,13.94,2,1,13.99,100,1,14.23,100,1,14.28,100,1,14.52,300,3,14.56,800,2,ARL,330359197
2025-07-17T16:05:59.803504658Z,2025-07-17T16:05:59.803338996Z,160,2,1108,C,A,14.780000000,100,0,330144321,0,165662,275327093,ARL,0,14.78,100,0,165662,275327093,9.55,1700,17,9.68,100,1,10.61,200,2,11.27,100,1,11.4,100,1,11.76,100,1,11.93,200,2,12.1,100,1,12.2,200,2,12.33,100,1,13.64,15,1,13.65,100,1,13.68,115,2,13.8,200,2,13.94,2,1,13.99,100,1,14.23,100,1,14.28,100,1,14.52,300,3,14.56,800,2,ARL,330144321
2025-07-17T16:05:59.803504658Z,2025-07-17T16:05:59.803338996Z,160,2,1108,A,A,14.710000000,100,0,330359225,130,165662,275327093,ARL,0,14.71,100,130,165662,275327093,9.55,1700,17,9.68,100,1,10.61,200,2,11.27,100,1,11.4,100,1,11.76,100,1,11.93,200,2,12.1,100,1,12.2,200,2,12.33,100,1,13.64,15,1,13.65,100,1,13.68,115,2,13.8,200,2,13.94,2,1,13.99,100,1,14.23,100,1,14.28,100,1,14.52,300,3,14.56,800,2,ARL,330359225
2025-07-17T16:05:59.827787837Z,2025-07-17T16:05:59.827622529Z,160,2,1108,C,A,13.990000000,100,0,330144513,130,165308,275327416,ARL,0,13.99,100,130,165308,275327416,9.55,1700,17,9.68,100,1,10.61,200,2,11.27,100,1,11.4,100,1,11.76,100,1,11.93,200,2,12.1,100,1,12.2,200,2,12.33,100,1,13.64,15,1,13.65,100,1,13.68,115,2,13.8,200,2,13.94,2,1,14.23,100,1,14.28,100,1,14.52,300,3,14.56,800,2,14.6,700,1,ARL,330144513
2025-07-17T16:05:59.827839802Z,2025-07-17T16:05:59.827674437Z,160,2,1108,A,A,13.920000000,100,0,330359625,130,165365,275327417,ARL,0,13.92,100,130,165365,275327417,9.55,1700,17,9.68,100,1,10.61,200,2,11.27,100,1,11.4,100,1,11.76,100,1,11.93,200,2,12.1,100,1,12.2,200,2,12.33,100,1,13.64,15,1,13.65,100,1,13.68,115,2,13.8,200,2,13.92,100,1,13.94,2,1,14.23,100,1,14.28,100,1,14.52,300,3,14.56,800,2,ARL,330359625
2025-07-17T16:06:02.724446337Z,2025-07-17T16:06:02.724280161Z,160,2,1108,C,A,13.680000000,15,0,330143813,128,166176,275430576,ARL,0,13.68,15,128,166176,275430576,9.55,1700,17,9.68,100,1,10.61,200,2,11.27,100,1,11.4,100,1,11.76,100,1,11.93,200,2,12.1,100,1,12.2,200,2,12.33,100,1,13.64,15,1,13.65,100,1,13.68,100,1,13.8,200,2,13.92,100,1,13.94,2,1,14.23,100,1,14.28,100,1,14.52,300,3,14.56,800,2,ARL,330143813
2025-07-17T16:06:03.729377770Z,2025-07-17T16:06:03.729212428Z,160,2,1108,A,A,13.620000000,15,0,330577045,130,165342,275517342,ARL,0,13.62,15,130,165342,275517342,9.55,1700,17,9.68,100,1,10.61,200,2,11.27,100,1,11.4,100,1,11.76,100,1,11.93,200,2,12.1,100,1,12.2,200,2,12.33,100,1,13.62,15,1,13.64,15,1,13.65,100,1,13.68,100,1,13.8,200,2,13.92,100,1,13.94,2,1,14.23,100,1,14.28,100,1,14.52,300,3,ARL,330577045
2025-07-17T16:06:03.738497645Z,2025-07-17T16:06:03.738332427Z,160,2,1108,A,A,13.650000000,100,0,330577773,130,165218,275517997,ARL,0,13.65,100,130,165218,275517997,9.55,1700,17,9.68,100,1,10.61,200,2,11.27,100,1,11.4,100,1,11.76,100,1,11.93,200,2,12.1,100,1,12.2,200,2,12.33,100,1,13.62,15,1,13.64,15,1,13.65,200,2,13.68,100,1,13.8,200,2,13.92,100,1,13.94,2,1,14.23,100,1,14.28,100,1,14.52,300,3,ARL,330577773
2025-07-17T16:06:03.747495669Z,2025-07-17T16:06:03.747330178Z,160,2,1108,C,A,13.680000000,100,0,330357633,130,165491,275518621,ARL,0,13.68,100,130,165491,275518621,9.55,1700,17,9.68,100,1,10.61,200,2,11.27,100,1,11.4,100,1,11.76,100,1,11.93,200,2,12.1,100,1,12.2,200,2,12.33,100,1,13.62,15,1,13.64,15,1,13.65,200,2,13.8,200,2,13.92,100,1,13.94,2,1,14.23,100,1,14.28,100,1,14.52,300,3,14.56,800,2,ARL,330357633
2025-07-17T16:06:03.887274670Z,2025-07-17T16:06:03.887107153Z,160,2,1108,C,A,13.650000000,100,0,330359197,0,167517,275532429,ARL,0,13.65,100,0,167517,275532429,9.55,1700,17,9.68,100,1,10.61,200,2,11.27,100,1,11.4,100,1,11.76,100,1,11.93,200,2,12.1,100,1,12.2,200,2,12.33,100,1,13.62,15,1,13.64,15,1,13.65,100,1,13.8,200,2,13.92,100,1,13.94,2,1,14.23,100,1,14.28,100,1,14.52,300,3,14.56,800,2,ARL,330359197
2025-07-17T16:06:03.887274670Z,2025-07-17T16:06:03.887107153Z,160,2,1108,A,A,13.630000000,100,0,330592465,130,167517,275532429,ARL,0,13.63,100,130,167517,275532429,9.55,1700,17,9.68,100,1,10.61,200,2,11.27,100,1,11.4,100,1,11.76,100,1,11.93,200,2,12.1,100,1,12.2,200,2,12.33,100,1,13.62,15,1,13.63,100,1,13.64,15,1,13.65,100,1,13.8,200,2,13.92,100,1,13.94,2,1,14.23,100,1,14.28,100,1,14.52,300,3,ARL,330592465
2025-07-17T16:06:07.510050758Z,2025-07-17T16:06:07.509885114Z,160,2,1108,C,A,13.640000000,15,0,330357473,130,165644,275647392,ARL,0,13.64,15,130,165644,275647392,9.55,1700,17,9.68,100,1,10.61,200,2,11.27,100,1,11.4,100,1,11.76,100,1,11.93,200,2,12.1,100,1,12.2,200,2,12.33,100,1,13.62,15,1,13.63,100,1,13.65,100,1,13.8,200,2,13.92,100,1,13.94,2,1,14.23,100,1,14.28,100,1,14.52,300,3,14.56,800,2,ARL,330357473
2025-07-17T16:06:09.885143909Z,2025-07-17T16:06:09.884978592Z,160,2,1108,A,A,13.600000000,15,0,330788421,130,165317,275699092,ARL,0,13.6,15,130,165317,275699092,9.55,1700,17,9.68,100,1,10.61,200,2,11.27,100,1,11.4,100,1,11.76,100,1,11.93,200,2,12.1,100,1,12.2,200,2,12.33,100,1,13.6,15,1,13.62,15,1,13.63,100,1,13.65,100,1,13.8,200,2,13.92,100,1,13.94,2,1,14.23,100,1,14.28,100,1,14.52,300,3,ARL,330788421
2025-07-17T16:06:09.967608061Z,2025-07-17T16:06:09.967442600Z,160,2,1108,C,A,13.630000000,100,0,330592465,0,165461,275700261,ARL,0,13.63,100,0,165461,275700261,9.55,1700,17,9.68,100,1,10.61,200,2,11.27,100,1,11.4,100,1,11.76,100,1,11.93,200,2,12.1,100,1,12.2,200,2,12.33,100,1,13.6,15,1,13.62,15,1,13.65,100,1,13.8,200,2,13.92,100,1,13.94,2,1,14.23,100,1,14.28,100,1,14.52,300,3,14.56,800,2,ARL,330592465
2025-07-17T16:06:09.967608061Z,2025-07-17T16:06:09.967442600Z,160,2,1108,A,A,13.610000000,100,0,330789481,130,165461,275700261,ARL,0,13.61,100,130,165461,275700261,9.55,1700,17,9.68,100,1,10.61,200,2,11.27,100,1,11.4,100,1,11.76,100,1,11.93,200,2,12.1,100,1,12.2,200,2,12.33,100,1,13.6,15,1,13.61,100,1,13.62,15,1,13.65,100,1,13.8,200,2,13.92,100,1,13.94,2,1,14.23,100,1,14.28,100,1,14.52,300,3,ARL,330789481
2025-07-17T16:06:09.968352066Z,2025-07-17T16:06:09.968186617Z,160,2,1108,C,A,14.710000000,100,0,330359225,0,165449,275700270,ARL,0,14.71,100,0,165449,275700270,9.55,1700,17,9.68,100,1,10.61,200,2,11.27,100,1,11.4,100,1,11.76,100,1,11.93,200,2,12.1,100,1,12.2,200,2,12.33,100,1,13.6,15,1,13.61,100,1,13.62,15,1,13.65,100,1,13.8,200,2,13.92,100,1,13.94,2,1,14.23,100,1,14.28,100,1,14.52,300,3,ARL,330359225
2025-07-17T16:06:09.968352066Z,2025-07-17T16:06:09.968186617Z,160,2,1108,A,A,14.670000000,100,0,330789501,130,165449,275700270,ARL,0,14.67,100,130,165449,275700270,9.55,1700,17,9.68,100,1,10.61,200,2,11.27,100,1,11.4,100,1,11.76,100,1,11.93,200,2,12.1,100,1,12.2,200,2,12.33,100,1,13.6,15,1,13.61,100,1,13.62,15,1,13.65,100,1,13.8,200,2,13.92,100,1,13.94,2,1,14.23,100,1,14.28,100,1,14.52,300,3,ARL,330789501
2025-07-17T16:06:09.970040686Z,2025-07-17T16:06:09.969875190Z,160,2,1108,C,A,17.440000000,100,0,327870217,0,165496,275700282,ARL,0,17.44,100,0,165496,275700282,9.55,1700,17,9.68,100,1,10.61,200,2,11.27,100,1,11.4,100,1,11.76,100,1,11.93,200,2,12.1,100,1,12.2,200,2,12.33,100,1,13.6,15,1,13.61,100,1,13.62,15,1,13.65,100,1,13.8,200,2,13.92,100,1,13.94,2,1,14.23,100,1,14.28,100,1,14.52,300,3,ARL,327870217
2025-07-17T16:06:09.970040686Z,2025-07-17T16:06:09.969875190Z,160,2,1108,A,A,17.290000000,100,0,330789509,130,165496,275700282,ARL,0,17.29,100,130,165496,275700282,9.55,1700,17,9.68,100,1,10.61,200,2,11.27,100,1,11.4,100,1,11.76,100,1,11.93,200,2,12.1,100,1,12.2,200,2,12.33,100,1,13.6,15,1,13.61,100,1,13.62,15,1,13.65,100,1,13.8,200,2,13.92,100,1,13.94,2,1,14.23,100,1,14.28,100,1,14.52,300,3,ARL,330789509
2025-07-17T16:06:20.470889851Z,2025-07-17T16:06:20.470724464Z,160,2,1108,A,A,13.630000000,100,0,331018065,130,165387,275896138,ARL,0,13.63,100,130,165387,275896138,9.55,1700,17,9.68,100,1,10.61,200,2,11.27,100,1,11.4,100,1,11.76,100,1,11.93,200,2,12.1,100,1,12.2,200,2,12.33,100,1,13.6,15,1,13.61,100,1,13.62,15,1,13.63,100,1,13.65,100,1,13.8,200,2,13.92,100,1,13.94,2,1,14.23,100,1,14.28,100,1,ARL,331018065
2025-07-17T16:06:20.477598578Z,2025-07-17T16:06:20.477432988Z,160,2,1108,C,A,13.650000000,100,0,330577773,130,165590,275896242,ARL,0,13.65,100,130,165590,275896242,9.55,1700,17,9.68,100,1,10.61,200,2,11.27,100,1,11.4,100,1,11.76,100,1,11.93,200,2,12.1,100,1,12.2,200,2,12.33,100,1,13.6,15,1,13.61,100,1,13.62,15,1,13.63,100,1,13.8,200,2,13.92,100,1,13.94,2,1,14.23,100,1,14.28,100,1,14.52,300,3,ARL,330577773
2025-07-17T16:06:20.811164178Z,2025-07-17T16:06:20.810998706Z,160,2,1108,C,A,13.620000000,15,0,330577045,130,165472,275900161,ARL,0,13.62,15,130,165472,275900161,9.55,1700,17,9.68,100,1,10.61,200,2,11.27,100,1,11.4,100,1,11.76,100,1,11.93,200,2,12.1,100,1,12.2,200,2,12.33,100,1,13.6,15,1,13.61,100,1,13.63,100,1,13.8,200,2,13.92,100,1,13.94,2,1,14.23,100,1,14.28,100,1,14.52,300,3,14.56,800,2,ARL,330577045
2025-07-17T16:06:22.151222819Z,2025-07-17T16:06:22.151057292Z,160,2,1108,A,A,13.580000000,15,0,331050981,130,165527,275926927,ARL,0,13.58,15,130,165527,275926927,9.55,1700,17,9.68,100,1,10.61,200,2,11.27,100,1,11.4,100,1,11.76,100,1,11.93,200,2,12.1,100,1,12.2,200,2,12.33,100,1,13.58,15,1,13.6,15,1,13.61,100,1,13.63,100,1,13.8,200,2,13.92,100,1,13.94,2,1,14.23,100,1,14.28,100,1,14.52,300,3,ARL,331050981
2025-07-17T16:06:22.151491832Z,2025-07-17T16:06:22.151326300Z,160,2,1108,C,A,13.610000000,100,0,330789481,0,165532,275926940,ARL,0,13.61,100,0,165532,275926940,9.55,1700,17,9.68,100,1,10.61,200,2,11.27,100,1,11.4,100,1,11.76,100,1,11.93,200,2,12.1,100,1,12.2,200,2,12.33,100,1,13.58,15,1,13.6,15,1,13.63,100,1,13.8,200,2,13.92,100,1,13.94,2,1,14.23,100,1,14.28,100,1,14.52,300,3,14.56,800,2,ARL,330789481
2025-07-17T16:06:22.151491832Z,2025-07-17T16:06:22.151326300Z,160,2,1108,A,A,13.590000000,100,0,331050989,130,165532,275926940,ARL,0,13.59,100,130,165532,275926940,9.55,1700,17,9.68,100,1,10.61,200,2,11.27,100,1,11.4,100,1,11.76,100,1,11.93,200,2,12.1,100,1,12.2,200,2,12.33,100,1,13.58,15,1,13.59,100,1,13.6,15,1,13.63,100,1,13.8,200,2,13.92,100,1,13.94,2,1,14.23,100,1,14.28,100,1,14.52,300,3,ARL,331050989
2025-07-17T16:06:22.151761329Z,2025-07-17T16:06:22.151595415Z,160,2,1108,C,A,13.800000000,100,0,328614525,0,165914,275926966,ARL,0,13.8,100,0,165914,275926966,9.55,1700,17,9.68,100,1,10.61,200,2,11.27,100,1,11.4,100,1,11.76,100,1,11.93,200,2,12.1,100,1,12.2,200,2,12.33,100,1,13.58,15,1,13.59,100,1,13.6,15,1,13.63,100,1,13.8,100,1,13.92,100,1,13.94,2,1,14.23,100,1,14.28,100,1,14.52,300,3,ARL,328614525
2025-07-17T16:06:22.151761329Z,2025-07-17T16:06:22.151595781Z,160,2,1108,C,A,13.800000000,100,0,328614529,130,165548,275926967,ARL,0,13.8,100,130,165548,275926967,9.55,1700,17,9.68,100,1,10.61,200,2,11.27,100,1,11.4,100,1,11.76,100,1,11.93,200,2,12.1,100,1,12.2,200,2,12.33,100,1,13.58,15,1,13.59,100,1,13.6,15,1,13.63,100,1,13.92,100,1,13.94,2,1,14.23,100,1,14.28,100,1,14.52,300,3,14.56,800,2,ARL,328614529
2025-07-17T16:06:22.153148893Z,2025-07-17T16:06:22.152983326Z,160,2,1108,C,A,15.790000000,100,0,327870361,0,165567,275927034,ARL,0,15.79,100,0,165567,275927034,9.55,1700,17,9.68,100,1,10.61,200,2,11.27,100,1,11.4,100,1,11.76,100,1,11.93,200,2,12.1,100,1,12.2,200,2,12.33,100,1,13.58,15,1,13.59,100,1,13.6,15,1,13.63,100,1,13.92,100,1,13.94,2,1,14.23,100,1,14.28,100,1,14.52,300,3,14.56,800,2,ARL,327870361
2025-07-17T16:06:22.153148893Z,2025-07-17T16:06:22.152983326Z,160,2,1108,A,A,15.630000000,100,0,331051145,130,165567,275927034,ARL,0,15.63,100,130,165567,275927034,9.55,1700,17,9.68,100,1,10.61,200,2,11.27,100,1,11.4,100,1,11.76,100,1,11.93,200,2,12.1,100,1,12.2,200,2,12.33,100,1,13.58,15,1,13.59,100,1,13.6,15,1,13.63,100,1,13.92,100,1,13.94,2,1,14.23,100,1,14.28,100,1,14.52,300,3,14.56,800,2,ARL,331051145
2025-07-17T16:06:22.153916169Z,2025-07-17T16:06:22.153749481Z,160,2,1108,C,A,14.700000000,100,0,327868421,0,166688,275927046,ARL,0,14.7,100,0,166688,275927046,9.55,1700,17,9.68,100,1,10.61,200,2,11.27,100,1,11.4,100,1,11.76,100,1,11.93,200,2,12.1,100,1,12.2,200,2,12.33,100,1,13.58,15,1,13.59,100,1,13.6,15,1,13.63,100,1,13.92,100,1,13.94,2,1,14.23,100,1,14.28,100,1,14.52,300,3,14.56,800,2,ARL,327868421
2025-07-17T16:06:22.153916169Z,2025-07-17T16:06:22.153749481Z,160,2,1108,A,A,14.550000000,100,0,331051173,130,166688,275927046,ARL,0,14.55,100,130,166688,275927046,9.55,1700,17,9.68,100,1,10.61,200,2,11.27,100,1,11.4,100,1,11.76,100,1,11.93,200,2,12.1,100,1,12.2,200,2,12.33,100,1,13.58,15,1,13.59,100,1,13.6,15,1,13.63,100,1,13.92,100,1,13.94,2,1,14.23,100,1,14.28,100,1,14.52,300,3,14.55,100,1,ARL,331051173
2025-07-17T16:06:22.156070698Z,2025-07-17T16:06:22.155905240Z,160,2,1108,C,A,14.520000000,100,0,327869529,0,165458,275927117,ARL,0,14.52,100,0,165458,275927117,9.55,1700,17,9.68,100,1,10.61,200,2,11.27,100,1,11.4,100,1,11.76,100,1,11.93,200,2,12.1,100,1,12.2,200,2,12.33,100,1,13.58,15,1,13.59,100,1,13.6,15,1,13.63,100,1,13.92,100,1,13.94,2,1,14.23,100,1,14.28,100,1,14.52,200,2,14.55,100,1,ARL,327869529
2025-07-17T16:06:22.156070698Z,2025-07-17T16:06:22.155905240Z,160,2,1108,A,A,14.380000000,100,0,331051369,130,165458,275927117,ARL,0,14.38,100,130,165458,275927117,9.55,1700,17,9.68,100,1,10.61,200,2,11.27,100,1,11.4,100,1,11.76,100,1,11.93,200,2,12.1,100,1,12.2,200,2,12.33,100,1,13.58,15,1,13.59,100,1,13.6,15,1,13.63,100,1,13.92,100,1,13.94,2,1,14.23,100,1,14.28,100,1,14.38,100,1,14.52,200,2,ARL,331051369
2025-07-17T16:06:22.178044675Z,2025-07-17T16:06:22.177879233Z,160,2,1108,C,A,14.700000000,100,0,327873009,0,165442,275927444,ARL,0,14.7,100,0,165442,275927444,9.55,1700,17,9.68,100,1,10.61,200,2,11.27,100,1,11.4,100,1,11.76,100,1,11.93,200,2,12.1,100,1,12.2,200,2,12.33,100,1,13.58,15,1,13.59,100,1,13.6,15,1,13.63,100,1,13.92,100,1,13.94,2,1,14.23,100,1,14.28,100,1,14.38,100,1,14.52,200,2,ARL,327873009
2025-07-17T16:06:22.178044675Z,2025-07-17T16:06:22.177879233Z,160,2,1108,A,A,14.550000000,100,0,331052197,130,165442,275927444,ARL,0,14.55,100,130,165442,275927444,9.55,1700,17,9.68,100,1,10.61,200,2,11.27,100,1,11.4,100,1,11.76,100,1,11.93,200,2,12.1,100,1,12.2,200,2,12.33,100,1,13.58,15,1,13.59,100,1,13.6,15,1,13.63,100,1,13.92,100,1,13.94,2,1,14.23,100,1,14.28,100,1,14.38,100,1,14.52,200,2,ARL,331052197
2025-07-17T16:06:24.519511128Z,2025-07-17T16:06:24.519345743Z,160,2,1108,A,A,13.600000000,100,0,331104725,130,165385,275968354,ARL,0,13.6,100,130,165385,275968354,9.55,1700,17,9.68,100,1,10.61,200,2,11.27,100,1,11.4,100,1,11.76,100,1,11.93,200,2,12.1,100,1,12.2,200,2,12.33,100,1,13.58,15,1,13.59,100,1,13.6,115,2,13.63,100,1,13.92,100,1,13.94,2,1,14.23,100,1,14.28,100,1,14.38,100,1,14.52,200,2,ARL,331104725
2025-07-17T16:06:24.526359716Z,2025-07-17T16:06:24.526194457Z,160,2,1108,C,A,13.630000000,100,0,331018065,130,165259,275968393,ARL,0,13.63,100,130,165259,275968393,9.55,1700,17,9.68,100,1,10.61,200,2,11.27,100,1,11.4,100,1,11.76,100,1,11.93,200,2,12.1,100,1,12.2,200,2,12.33,100,1,13.58,15,1,13.59,100,1,13.6,115,2,13.92,100,1,13.94,2,1,14.23,100,1,14.28,100,1,14.38,100,1,14.52,200,2,14.55,200,2,ARL,331018065
2025-07-17T16:06:26.610345800Z,2025-07-17T16:06:26.610180184Z,160,2,1108,C,A,13.940000000,2,0,328351217,0,165616,276013080,ARL,0,13.94,2,0,165616,276013080,9.55,1700,17,9.68,100,1,10.61,200,2,11.27,100,1,11.4,100,1,11.76,100,1,11.93,200,2,12.1,100,1,12.2,200,2,12.33,100,1,13.58,15,1,13.59,100,1,13.6,115,2,13.92,100,1,14.23,100,1,14.28,100,1,14.38,100,1,14.52,200,2,14.55,200,2,14.56,800,2,ARL,328351217
2025-07-17T16:06:26.610345800Z,2025-07-17T16:06:26.610180184Z,160,2,1108,A,A,13.850000000,2,0,331155889,130,165616,276013080,ARL,0,13.85,2,130,165616,276013080,9.55,1700,17,9.68,100,1,10.61,200,2,11.27,100,1,11.4,100,1,11.76,100,1,11.93,200,2,12.1,100,1,12.2,200,2,12.33,100,1,13.58,15,1,13.59,100,1,13.6,115,2,13.85,2,1,13.92,100,1,14.23,100,1,14.28,100,1,14.38,100,1,14.52,200,2,14.55,200,2,ARL,331155889
2025-07-17T16:06:30.625877214Z,2025-07-17T16:06:30.625711923Z,160,2,1108,A,A,14.270000000,700,0,331257169,130,165291,276103282,ARL,0,14.27,700,130,165291,276103282,9.55,1700,17,9.68,100,1,10.61,200,2,11.27,100,1,11.4,100,1,11.76,100,1,11.93,200,2,12.1,100,1,12.2,200,2,12.33,100,1,13.58,15,1,13.59,100,1,13.6,115,2,13.85,2,1,13.92,100,1,14.23,100,1,14.27,700,1,14.28,100,1,14.38,100,1,14.52,200,2,ARL,331257169
2025-07-17T16:06:30.625956307Z,2025-07-17T16:06:30.625790910Z,160,2,1108,C,A,14.680000000,700,0,325716945,130,165397,276103283,ARL,0,14.68,700,130,165397,276103283,9.55,1700,17,9.68,100,1,10.61,200,2,11.27,100,1,11.4,100,1,11.76,100,1,11.93,200,2,12.1,100,1,12.2,200,2,12.33,100,1,13.58,15,1,13.59,100,1,13.6,115,2,13.85,2,1,13.92,100,1,14.23,100,1,14.27,700,1,14.28,100,1,14.38,100,1,14.52,200,2,ARL,325716945
2025-07-17T16:06:31.127827805Z,2025-07-17T16:06:31.127662311Z,160,2,1108,A,A,14.480000000,700,0,331272997,130,165494,276118990,ARL,0,14.48,700,130,165494,276118990,9.55,1700,17,9.68,100,1,10.61,200,2,11.27,100,1,11.4,100,1,11.76,100,1,11.93,200,2,12.1,100,1,12.2,200,2,12.33,100,1,13.58,15,1,13.59,100,1,13.6,115,2,13.85,2,1,13.92,100,1,14.23,100,1,14.27,700,1,14.28,100,1,14.38,100,1,14.48,700,1,ARL,331272997
2025-07-17T16:06:31.128581831Z,2025-07-17T16:06:31.128416336Z,160,2,1108,C,A,14.680000000,700,0,289932801,130,165495,276119017,ARL,0,14.68,700,130,165495,276119017,9.55,1700,17,9.68,100,1,10.61,200,2,11.27,100,1,11.4,100,1,11.76,100,1,11.93,200,2,12.1,100,1,12.2,200,2,12.33,100,1,13.58,15,1,13.59,100,1,13.6,115,2,13.85,2,1,13.92,100,1,14.23,100,1,14.27,700,1,14.28,100,1,14.38,100,1,14.48,700,1,ARL,289932801
2025-07-17T16:06:31.990649229Z,2025-07-17T16:06:31.990483799Z,160,2,1108,C,A,13.600000000,15,0,330788421,130,165430,276135226,ARL,0,13.6,15,130,165430,276135226,9.55,1700,17,9.68,100,1,10.61,200,2,11.27,100,1,11.4,100,1,11.76,100,1,11.93,200,2,12.1,100,1,12.2,200,2,12.33,100,1,13.58,15,1,13.59,100,1,13.6,100,1,13.85,2,1,13.92,100,1,14.23,100,1,14.27,700,1,14.28,100,1,14.38,100,1,14.48,700,1,ARL,330788421
2025-07-17T16:06:42.812807096Z,2025-07-17T16:06:42.812641697Z,160,2,1108,A,A,13.560000000,15,0,331488089,130,165399,276276783,ARL,0,13.56,15,130,165399,276276783,9.55,1700,17,9.68,100,1,10.61,200,2,11.27,100,1,11.4,100,1,11.76,100,1,11.93,200,2,12.1,100,1,12.2,200,2,12.33,100,1,13.56,15,1,13.58,15,1,13.59,100,1,13.6,100,1,13.85,2,1,13.92,100,1,14.23,100,1,14.27,700,1,14.28,100,1,14.38,100,1,ARL,331488089
2025-07-17T16:06:43.012965957Z,2025-07-17T16:06:43.012799164Z,160,2,1108,C,A,13.590000000,100,0,331050989,0,166793,276279311,ARL,0,13.59,100,0,166793,276279311,9.55,1700,17,9.68,100,1,10.61,200,2,11.27,100,1,11.4,100,1,11.76,100,1,11.93,200,2,12.1,100,1,12.2,200,2,12.33,100,1,13.56,15,1,13.58,15,1,13.6,100,1,13.85,2,1,13.92,100,1,14.23,100,1,14.27,700,1,14.28,100,1,14.38,100,1,14.48,700,1,ARL,331050989
2025-07-17T16:06:43.012965957Z,2025-07-17T16:06:43.012799164Z,160,2,1108,A,A,13.570000000,100,0,331491049,128,166793,276279311,ARL,0,13.57,100,128,166793,276279311,9.55,1700,17,9.68,100,1,10.61,200,2,11.27,100,1,11.4,100,1,11.76,100,1,11.93,200,2,12.1,100,1,12.2,200,2,12.33,100,1,13.56,15,1,13.57,100,1,13.58,15,1,13.6,100,1,13.85,2,1,13.92,100,1,14.23,100,1,14.27,700,1,14.28,100,1,14.38,100,1,ARL,331491049
2025-07-17T16:06:43.013716205Z,2025-07-17T16:06:43.013550575Z,160,2,1108,C,A,14.670000000,100,0,330789501,0,165630,276279331,ARL,0,14.67,100,0,165630,276279331,9.55,1700,17,9.68,100,1,10.61,200,2,11.27,100,1,11.4,100,1,11.76,100,1,11.93,200,2,12.1,100,1,12.2,200,2,12.33,100,1,13.56,15,1,13.57,100,1,13.58,15,1,13.6,100,1,13.85,2,1,13.92,100,1,14.23,100,1,14.27,700,1,14.28,100,1,14.38,100,1,ARL,330789501
2025-07-17T16:06:43.013716205Z,2025-07-17T16:06:43.013550575Z,160,2,1108,A,A,14.620000000,100,0,331491077,130,165630,276279331,ARL,0,14.62,100,130,165630,276279331,9.55,1700,17,9.68,100,1,10.61,200,2,11.27,100,1,11.4,100,1,11.76,100,1,11.93,200,2,12.1,100,1,12.2,200,2,12.33,100,1,13.56,15,1,13.57,100,1,13.58,15,1,13.6,100,1,13.85,2,1,13.92,100,1,14.23,100,1,14.27,700,1,14.28,100,1,14.38,100,1,ARL,331491077
2025-07-17T16:06:43.024656023Z,2025-07-17T16:06:43.024490355Z,160,2,1108,C,A,13.920000000,100,0,330359625,130,165668,276279620,ARL,0,13.92,100,130,165668,276279620,9.55,1700,17,9.68,100,1,10.61,200,2,11.27,100,1,11.4,100,1,11.76,100,1,11.93,200,2,12.1,100,1,12.2,200,2,12.33,100,1,13.56,15,1,13.57,100,1,13.58,15,1,13.6,100,1,13.85,2,1,14.23,100,1,14.27,700,1,14.28,100,1,14.38,100,1,14.48,700,1,ARL,330359625
2025-07-17T16:06:43.024708304Z,2025-07-17T16:06:43.024543099Z,160,2,1108,A,A,13.840000000,100,0,331491269,130,165205,276279621,ARL,0,13.84,100,130,165205,276279621,9.55,1700,17,9.68,100,1,10.61,200,2,11.27,100,1,11.4,100,1,11.76,100,1,11.93,200,2,12.1,100,1,12.2,200,2,12.33,100,1,13.56,15,1,13.57,100,1,13.58,15,1,13.6,100,1,13.84,100,1,13.85,2,1,14.23,100,1,14.27,700,1,14.28,100,1,14.38,100,1,ARL,331491269
2025-07-17T16:06:49.613941821Z,2025-07-17T16:06:49.613776144Z,160,2,1108,C,A,13.580000000,15,0,331050981,130,165677,276382302,ARL,0,13.58,15,130,165677,276382302,9.55,1700,17,9.68,100,1,10.61,200,2,11.27,100,1,11.4,100,1,11.76,100,1,11.93,200,2,12.1,100,1,12.2,200,2,12.33,100,1,13.56,15,1,13.57,100,1,13.6,100,1,13.84,100,1,13.85,2,1,14.23,100,1,14.27,700,1,14.28,100,1,14.38,100,1,14.48,700,1,ARL,331050981
2025-07-17T16:06:50.618669843Z,2025-07-17T16:06:50.618504506Z,160,2,1108,A,A,13.540000000,15,0,331666961,130,165337,276408477,ARL,0,13.54,15,130,165337,276408477,9.55,1700,17,9.68,100,1,10.61,200,2,11.27,100,1,11.4,100,1,11.76,100,1,11.93,200,2,12.1,100,1,12.2,200,2,12.33,100,1,13.54,15,1,13.56,15,1,13.57,100,1,13.6,100,1,13.84,100,1,13.85,2,1,14.23,100,1,14.27,700,1,14.28,100,1,14.38,100,1,ARL,331666961
2025-07-17T16:06:50.626438205Z,2025-07-17T16:06:50.626272828Z,160,2,1108,A,A,13.580000000,100,0,331667121,130,165377,276408566,ARL,0,13.58,100,130,165377,276408566,9.55,1700,17,9.68,100,1,10.61,200,2,11.27,100,1,11.4,100,1,11.76,100,1,11.93,200,2,12.1,100,1,12.2,200,2,12.33,100,1,13.54,15,1,13.56,15,1,13.57,100,1,13.58,100,1,13.6,100,1,13.84,100,1,13.85,2,1,14.23,100,1,14.27,700,1,14.28,100,1,ARL,331667121
2025-07-17T16:06:50.633113557Z,2025-07-17T16:06:50.632947998Z,160,2,1108,C,A,13.600000000,100,0,331104725,130,165559,276408644,ARL,0,13.6,100,130,165559,276408644,9.55,1700,17,9.68,100,1,10.61,200,2,11.27,100,1,11.4,100,1,11.76,100,1,11.93,200,2,12.1,100,1,12.2,200,2,12.33,100,1,13.54,15,1,13.56,15,1,13.57,100,1,13.58,100,1,13.84,100,1,13.85,2,1,14.23,100,1,14.27,700,1,14.28,100,1,14.38,100,1,ARL,331104725
