ts_recv,ts_event,rtype,publisher_id,instrument_id,action,side,price,size,channel_id,order_id,flags,ts_in_delta,sequence,symbol,depth,price,size,flags,ts_in_delta,sequence,bid_px_00,bid_sz_00,bid_ct_00,ask_px_00,ask_sz_00,ask_ct_00,bid_px_01,bid_sz_01,bid_ct_01,ask_px_01,ask_sz_01,ask_ct_01,bid_px_02,bid_sz_02,bid_ct_02,ask_px_02,ask_sz_02,ask_ct_02,bid_px_03,bid_sz_03,bid_ct_03,ask_px_03,ask_sz_03,ask_ct_03,bid_px_04,bid_sz_04,bid_ct_04,ask_px_04,ask_sz_04,ask_ct_04,bid_px_05,bid_sz_05,bid_ct_05,ask_px_05,ask_sz_05,ask_ct_05,bid_px_06,bid_sz_06,bid_ct_06,ask_px_06,ask_sz_06,ask_ct_06,bid_px_07,bid_sz_07,bid_ct_07,ask_px_07,ask_sz_07,ask_ct_07,bid_px_08,bid_sz_08,bid_ct_08,ask_px_08,ask_sz_08,ask_ct_08,bid_px_09,bid_sz_09,bid_ct_09,ask_px_09,ask_sz_09,ask_ct_09,symbol,order_id
2025-07-17T15:39:44.859886562Z,2025-07-17T15:39:44.859720946Z,160,2,1108,C,A,14.610000000,100,0,296455041,0,165616,248760319,ARL,0,14.61,100,0,165616,248760319,9.55,1700,17,9.68,100,1,10.61,200,2,11.27,100,1,11.4,100,1,11.76,100,1,11.93,200,2,12.23,100,1,12.34,200,2,12.36,200,2,14.07,2,1,14.26,100,1,14.4,100,1,14.56,900,3,14.6,700,1,14.61,100,1,14.68,1400,2,14.78,100,1,14.96,200,2,15.06,100,1,ARL,296455041
2025-07-17T15:39:44.859886562Z,2025-07-17T15:39:44.859720946Z,160,2,1108,A,A,15.100000000,100,0,296485621,130,165616,248760319,ARL,0,15.1,100,130,165616,248760319,9.55,1700,17,9.68,100,1,10.61,200,2,11.27,100,1,11.4,100,1,11.76,100,1,11.93,200,2,12.23,100,1,12.34,200,2,12.36,200,2,14.07,2,1,14.26,100,1,14.4,100,1,14.56,900,3,14.6,700,1,14.61,100,1,14.68,1400,2,14.78,100,1,14.96,200,2,15.06,100,1,ARL,296485621
2025-07-17T15:39:44.860160096Z,2025-07-17T15:39:44.859994671Z,160,2,1108,A,A,14.080000000,100,0,296485629,130,165425,248760324,ARL,0,14.08,100,130,165425,248760324,9.55,1700,17,9.68,100,1,10.61,200,2,11.27,100,1,11.4,100,1,11.76,100,1,11.93,200,2,12.23,100,1,12.34,200,2,12.36,200,2,14.07,2,1,14.08,100,1,14.26,100,1,14.4,100,1,14.56,900,3,14.6,700,1,14.61,100,1,14.68,1400,2,14.78,100,1,14.96,200,2,ARL,296485629
2025-07-17T15:39:44.863678795Z,2025-07-17T15:39:44.863513587Z,160,2,1108,C,A,14.610000000,100,0,296455037,0,165208,248760417,ARL,0,14.61,100,0,165208,248760417,9.55,1700,17,9.68,100,1,10.61,200,2,11.27,100,1,11.4,100,1,11.76,100,1,11.93,200,2,12.23,100,1,12.34,200,2,12.36,200,2,14.07,2,1,14.08,100,1,14.26,100,1,14.4,100,1,14.56,900,3,14.6,700,1,14.68,1400,2,14.78,100,1,14.96,200,2,15.06,100,1,ARL,296455037
2025-07-17T15:39:44.863678795Z,2025-07-17T15:39:44.863513587Z,160,2,1108,A,A,15.100000000,100,0,296485649,130,165208,248760417,ARL,0,15.1,100,130,165208,248760417,9.55,1700,17,9.68,100,1,10.61,200,2,11.27,100,1,11.4,100,1,11.76,100,1,11.93,200,2,12.23,100,1,12.34,200,2,12.36,200,2,14.07,2,1,14.08,100,1,14.26,100,1,14.4,100,1,14.56,900,3,14.6,700,1,14.68,1400,2,14.78,100,1,14.96,200,2,15.06,100,1,ARL,296485649
2025-07-17T15:39:54.187008224Z,2025-07-17T15:39:54.186842327Z,160,2,1108,C,A,15.100000000,100,0,296485649,0,165897,248915116,ARL,0,15.1,100,0,165897,248915116,9.55,1700,17,9.68,100,1,10.61,200,2,11.27,100,1,11.4,100,1,11.76,100,1,11.93,200,2,12.23,100,1,12.34,200,2,12.36,200,2,14.07,2,1,14.08,100,1,14.26,100,1,14.4,100,1,14.56,900,3,14.6,700,1,14.68,1400,2,14.78,100,1,14.96,200,2,15.06,100,1,ARL,296485649
2025-07-17T15:39:54.187008224Z,2025-07-17T15:39:54.186842327Z,160,2,1108,A,A,14.880000000,100,0,296679277,130,165897,248915116,ARL,0,14.88,100,130,165897,248915116,9.55,1700,17,9.68,100,1,10.61,200,2,11.27,100,1,11.4,100,1,11.76,100,1,11.93,200,2,12.23,100,1,12.34,200,2,12.36,200,2,14.07,2,1,14.08,100,1,14.26,100,1,14.4,100,1,14.56,900,3,14.6,700,1,14.68,1400,2,14.78,100,1,14.88,100,1,14.96,200,2,ARL,296679277
2025-07-17T15:39:54.187557412Z,2025-07-17T15:39:54.187391707Z,160,2,1108,C,A,15.100000000,100,0,296485621,0,165705,248915126,ARL,0,15.1,100,0,165705,248915126,9.55,1700,17,9.68,100,1,10.61,200,2,11.27,100,1,11.4,100,1,11.76,100,1,11.93,200,2,12.23,100,1,12.34,200,2,12.36,200,2,14.07,2,1,14.08,100,1,14.26,100,1,14.4,100,1,14.56,900,3,14.6,700,1,14.68,1400,2,14.78,100,1,14.88,100,1,14.96,200,2,ARL,296485621
2025-07-17T15:39:54.187557412Z,2025-07-17T15:39:54.187391707Z,160,2,1108,A,A,14.880000000,100,0,296679285,130,165705,248915126,ARL,0,14.88,100,130,165705,248915126,9.55,1700,17,9.68,100,1,10.61,200,2,11.27,100,1,11.4,100,1,11.76,100,1,11.93,200,2,12.23,100,1,12.34,200,2,12.36,200,2,14.07,2,1,14.08,100,1,14.26,100,1,14.4,100,1,14.56,900,3,14.6,700,1,14.68,1400,2,14.78,100,1,14.88,200,2,14.96,200,2,ARL,296679285
2025-07-17T15:42:06.780503054Z,2025-07-17T15:42:06.780337543Z,160,2,1108,A,A,13.900000000,15,0,299689753,130,165511,251407709,ARL,0,13.9,15,130,165511,251407709,9.55,1700,17,9.68,100,1,10.61,200,2,11.27,100,1,11.4,100,1,11.76,100,1,11.93,200,2,12.23,100,1,12.34,200,2,12.36,200,2,13.9,15,1,14.07,2,1,14.08,100,1,14.26,100,1,14.4,100,1,14.56,900,3,14.6,700,1,14.68,1400,2,14.78,100,1,14.88,200,2,ARL,299689753
2025-07-17T15:42:06.780767761Z,2025-07-17T15:42:06.780602350Z,160,2,1108,C,A,14.080000000,100,0,296485629,0,165411,251407713,ARL,0,14.08,100,0,165411,251407713,9.55,1700,17,9.68,100,1,10.61,200,2,11.27,100,1,11.4,100,1,11.76,100,1,11.93,200,2,12.23,100,1,12.34,200,2,12.36,200,2,13.9,15,1,14.07,2,1,14.26,100,1,14.4,100,1,14.56,900,3,14.6,700,1,14.68,1400,2,14.78,100,1,14.88,200,2,14.96,200,2,ARL,296485629
2025-07-17T15:42:06.780767761Z,2025-07-17T15:42:06.780602350Z,160,2,1108,A,A,13.910000000,100,0,299689769,130,165411,251407713,ARL,0,13.91,100,130,165411,251407713,9.55,1700,17,9.68,100,1,10.61,200,2,11.27,100,1,11.4,100,1,11.76,100,1,11.93,200,2,12.23,100,1,12.34,200,2,12.36,200,2,13.9,15,1,13.91,100,1,14.07,2,1,14.26,100,1,14.4,100,1,14.56,900,3,14.6,700,1,14.68,1400,2,14.78,100,1,14.88,200,2,ARL,299689769
2025-07-17T15:42:06.781502831Z,2025-07-17T15:42:06.781336642Z,160,2,1108,C,A,15.060000000,100,0,296478965,0,166189,251407747,ARL,0,15.06,100,0,166189,251407747,9.55,1700,17,9.68,100,1,10.61,200,2,11.27,100,1,11.4,100,1,11.76,100,1,11.93,200,2,12.23,100,1,12.34,200,2,12.36,200,2,13.9,15,1,13.91,100,1,14.07,2,1,14.26,100,1,14.4,100,1,14.56,900,3,14.6,700,1,14.68,1400,2,14.78,100,1,14.88,200,2,ARL,296478965
2025-07-17T15:42:06.781502831Z,2025-07-17T15:42:06.781336642Z,160,2,1108,A,A,14.990000000,100,0,299689857,130,166189,251407747,ARL,0,14.99,100,130,166189,251407747,9.55,1700,17,9.68,100,1,10.61,200,2,11.27,100,1,11.4,100,1,11.76,100,1,11.93,200,2,12.23,100,1,12.34,200,2,12.36,200,2,13.9,15,1,13.91,100,1,14.07,2,1,14.26,100,1,14.4,100,1,14.56,900,3,14.6,700,1,14.68,1400,2,14.78,100,1,14.88,200,2,ARL,299689857
2025-07-17T15:42:06.795521307Z,2025-07-17T15:42:06.795355762Z,160,2,1108,C,A,14.260000000,100,0,296479425,130,165545,251408268,ARL,0,14.26,100,130,165545,251408268,9.55,1700,17,9.68,100,1,10.61,200,2,11.27,100,1,11.4,100,1,11.76,100,1,11.93,200,2,12.23,100,1,12.34,200,2,12.36,200,2,13.9,15,1,13.91,100,1,14.07,2,1,14.4,100,1,14.56,900,3,14.6,700,1,14.68,1400,2,14.78,100,1,14.88,200,2,14.96,200,2,ARL,296479425
2025-07-17T15:42:06.795573392Z,2025-07-17T15:42:06.795408057Z,160,2,1108,A,A,14.190000000,100,0,299690593,130,165335,251408269,ARL,0,14.19,100,130,165335,251408269,9.55,1700,17,9.68,100,1,10.61,200,2,11.27,100,1,11.4,100,1,11.76,100,1,11.93,200,2,12.23,100,1,12.34,200,2,12.36,200,2,13.9,15,1,13.91,100,1,14.07,2,1,14.19,100,1,14.4,100,1,14.56,900,3,14.6,700,1,14.68,1400,2,14.78,100,1,14.88,200,2,ARL,299690593
2025-07-17T15:42:16.264132159Z,2025-07-17T15:42:16.263966448Z,160,2,1108,C,A,14.880000000,100,0,296679285,0,165711,251574391,ARL,0,14.88,100,0,165711,251574391,9.55,1700,17,9.68,100,1,10.61,200,2,11.27,100,1,11.4,100,1,11.76,100,1,11.93,200,2,12.23,100,1,12.34,200,2,12.36,200,2,13.9,15,1,13.91,100,1,14.07,2,1,14.19,100,1,14.4,100,1,14.56,900,3,14.6,700,1,14.68,1400,2,14.78,100,1,14.88,100,1,ARL,296679285
2025-07-17T15:42:16.264132159Z,2025-07-17T15:42:16.263966448Z,160,2,1108,A,A,14.760000000,100,0,299903169,130,165711,251574391,ARL,0,14.76,100,130,165711,251574391,9.55,1700,17,9.68,100,1,10.61,200,2,11.27,100,1,11.4,100,1,11.76,100,1,11.93,200,2,12.23,100,1,12.34,200,2,12.36,200,2,13.9,15,1,13.91,100,1,14.07,2,1,14.19,100,1,14.4,100,1,14.56,900,3,14.6,700,1,14.68,1400,2,14.76,100,1,14.78,100,1,ARL,299903169
2025-07-17T15:42:17.356766715Z,2025-07-17T15:42:17.356601231Z,160,2,1108,A,A,13.830000000,15,0,299923773,130,165484,251593608,ARL,0,13.83,15,130,165484,251593608,9.55,1700,17,9.68,100,1,10.61,200,2,11.27,100,1,11.4,100,1,11.76,100,1,11.93,200,2,12.23,100,1,12.34,200,2,12.36,200,2,13.83,15,1,13.9,15,1,13.91,100,1,14.07,2,1,14.19,100,1,14.4,100,1,14.56,900,3,14.6,700,1,14.68,1400,2,14.76,100,1,ARL,299923773
2025-07-17T15:42:17.577474246Z,2025-07-17T15:42:17.577308779Z,160,2,1108,C,A,13.910000000,100,0,299689769,0,165467,251595553,ARL,0,13.91,100,0,165467,251595553,9.55,1700,17,9.68,100,1,10.61,200,2,11.27,100,1,11.4,100,1,11.76,100,1,11.93,200,2,12.23,100,1,12.34,200,2,12.36,200,2,13.83,15,1,13.9,15,1,14.07,2,1,14.19,100,1,14.4,100,1,14.56,900,3,14.6,700,1,14.68,1400,2,14.76,100,1,14.78,100,1,ARL,299689769
2025-07-17T15:42:17.577474246Z,2025-07-17T15:42:17.577308779Z,160,2,1108,A,A,13.840000000,100,0,299926781,130,165467,251595553,ARL,0,13.84,100,130,165467,251595553,9.55,1700,17,9.68,100,1,10.61,200,2,11.27,100,1,11.4,100,1,11.76,100,1,11.93,200,2,12.23,100,1,12.34,200,2,12.36,200,2,13.83,15,1,13.84,100,1,13.9,15,1,14.07,2,1,14.19,100,1,14.4,100,1,14.56,900,3,14.6,700,1,14.68,1400,2,14.76,100,1,ARL,299926781
2025-07-17T15:42:17.578219175Z,2025-07-17T15:42:17.578053644Z,160,2,1108,C,A,14.990000000,100,0,299689857,0,165531,251595563,ARL,0,14.99,100,0,165531,251595563,9.55,1700,17,9.68,100,1,10.61,200,2,11.27,100,1,11.4,100,1,11.76,100,1,11.93,200,2,12.23,100,1,12.34,200,2,12.36,200,2,13.83,15,1,13.84,100,1,13.9,15,1,14.07,2,1,14.19,100,1,14.4,100,1,14.56,900,3,14.6,700,1,14.68,1400,2,14.76,100,1,ARL,299689857
2025-07-17T15:42:17.578219175Z,2025-07-17T15:42:17.578053644Z,160,2,1108,A,A,14.910000000,100,0,299926801,130,165531,251595563,ARL,0,14.91,100,130,165531,251595563,9.55,1700,17,9.68,100,1,10.61,200,2,11.27,100,1,11.4,100,1,11.76,100,1,11.93,200,2,12.23,100,1,12.34,200,2,12.36,200,2,13.83,15,1,13.84,100,1,13.9,15,1,14.07,2,1,14.19,100,1,14.4,100,1,14.56,900,3,14.6,700,1,14.68,1400,2,14.76,100,1,ARL,299926801
2025-07-17T15:42:17.579343189Z,2025-07-17T15:42:17.579177582Z,160,2,1108,C,A,14.780000000,100,0,296479285,0,165607,251595571,ARL,0,14.78,100,0,165607,251595571,9.55,1700,17,9.68,100,1,10.61,200,2,11.27,100,1,11.4,100,1,11.76,100,1,11.93,200,2,12.23,100,1,12.34,200,2,12.36,200,2,13.83,15,1,13.84,100,1,13.9,15,1,14.07,2,1,14.19,100,1,14.4,100,1,14.56,900,3,14.6,700,1,14.68,1400,2,14.76,100,1,ARL,296479285
2025-07-17T15:42:17.579343189Z,2025-07-17T15:42:17.579177582Z,160,2,1108,A,A,14.640000000,100,0,299926813,130,165607,251595571,ARL,0,14.64,100,130,165607,251595571,9.55,1700,17,9.68,100,1,10.61,200,2,11.27,100,1,11.4,100,1,11.76,100,1,11.93,200,2,12.23,100,1,12.34,200,2,12.36,200,2,13.83,15,1,13.84,100,1,13.9,15,1,14.07,2,1,14.19,100,1,14.4,100,1,14.56,900,3,14.6,700,1,14.64,100,1,14.68,1400,2,ARL,299926813
2025-07-17T15:42:17.580008869Z,2025-07-17T15:42:17.579843331Z,160,2,1108,C,A,14.960000000,100,0,296479053,0,165538,251595576,ARL,0,14.96,100,0,165538,251595576,9.55,1700,17,9.68,100,1,10.61,200,2,11.27,100,1,11.4,100,1,11.76,100,1,11.93,200,2,12.23,100,1,12.34,200,2,12.36,200,2,13.83,15,1,13.84,100,1,13.9,15,1,14.07,2,1,14.19,100,1,14.4,100,1,14.56,900,3,14.6,700,1,14.64,100,1,14.68,1400,2,ARL,296479053
2025-07-17T15:42:17.580008869Z,2025-07-17T15:42:17.579843331Z,160,2,1108,A,A,14.810000000,100,0,299926849,130,165538,251595576,ARL,0,14.81,100,130,165538,251595576,9.55,1700,17,9.68,100,1,10.61,200,2,11.27,100,1,11.4,100,1,11.76,100,1,11.93,200,2,12.23,100,1,12.34,200,2,12.36,200,2,13.83,15,1,13.84,100,1,13.9,15,1,14.07,2,1,14.19,100,1,14.4,100,1,14.56,900,3,14.6,700,1,14.64,100,1,14.68,1400,2,ARL,299926849
2025-07-17T15:42:17.580035793Z,2025-07-17T15:42:17.579870309Z,160,2,1108,C,A,16.080000000,100,0,296480097,0,165484,251595577,ARL,0,16.08,100,0,165484,251595577,9.55,1700,17,9.68,100,1,10.61,200,2,11.27,100,1,11.4,100,1,11.76,100,1,11.93,200,2,12.23,100,1,12.34,200,2,12.36,200,2,13.83,15,1,13.84,100,1,13.9,15,1,14.07,2,1,14.19,100,1,14.4,100,1,14.56,900,3,14.6,700,1,14.64,100,1,14.68,1400,2,ARL,296480097
2025-07-17T15:42:17.580035793Z,2025-07-17T15:42:17.579870309Z,160,2,1108,A,A,15.920000000,100,0,299926853,130,165484,251595577,ARL,0,15.92,100,130,165484,251595577,9.55,1700,17,9.68,100,1,10.61,200,2,11.27,100,1,11.4,100,1,11.76,100,1,11.93,200,2,12.23,100,1,12.34,200,2,12.36,200,2,13.83,15,1,13.84,100,1,13.9,15,1,14.07,2,1,14.19,100,1,14.4,100,1,14.56,900,3,14.6,700,1,14.64,100,1,14.68,1400,2,ARL,299926853
2025-07-17T15:42:17.580061097Z,2025-07-17T15:42:17.579895610Z,160,2,1108,C,A,14.960000000,100,0,296482509,0,165487,251595578,ARL,0,14.96,100,0,165487,251595578,9.55,1700,17,9.68,100,1,10.61,200,2,11.27,100,1,11.4,100,1,11.76,100,1,11.93,200,2,12.23,100,1,12.34,200,2,12.36,200,2,13.83,15,1,13.84,100,1,13.9,15,1,14.07,2,1,14.19,100,1,14.4,100,1,14.56,900,3,14.6,700,1,14.64,100,1,14.68,1400,2,ARL,296482509
2025-07-17T15:42:17.580061097Z,2025-07-17T15:42:17.579895610Z,160,2,1108,A,A,14.810000000,100,0,299926857,130,165487,251595578,ARL,0,14.81,100,130,165487,251595578,9.55,1700,17,9.68,100,1,10.61,200,2,11.27,100,1,11.4,100,1,11.76,100,1,11.93,200,2,12.23,100,1,12.34,200,2,12.36,200,2,13.83,15,1,13.84,100,1,13.9,15,1,14.07,2,1,14.19,100,1,14.4,100,1,14.56,900,3,14.6,700,1,14.64,100,1,14.68,1400,2,ARL,299926857
2025-07-17T15:42:17.580093535Z,2025-07-17T15:42:17.579928136Z,160,2,1108,C,A,17.760000000,100,0,296479893,0,165399,251595580,ARL,0,17.76,100,0,165399,251595580,9.55,1700,17,9.68,100,1,10.61,200,2,11.27,100,1,11.4,100,1,11.76,100,1,11.93,200,2,12.23,100,1,12.34,200,2,12.36,200,2,13.83,15,1,13.84,100,1,13.9,15,1,14.07,2,1,14.19,100,1,14.4,100,1,14.56,900,3,14.6,700,1,14.64,100,1,14.68,1400,2,ARL,296479893
2025-07-17T15:42:17.580093535Z,2025-07-17T15:42:17.579928136Z,160,2,1108,A,A,17.580000000,100,0,299926861,130,165399,251595580,ARL,0,17.58,100,130,165399,251595580,9.55,1700,17,9.68,100,1,10.61,200,2,11.27,100,1,11.4,100,1,11.76,100,1,11.93,200,2,12.23,100,1,12.34,200,2,12.36,200,2,13.83,15,1,13.84,100,1,13.9,15,1,14.07,2,1,14.19,100,1,14.4,100,1,14.56,900,3,14.6,700,1,14.64,100,1,14.68,1400,2,ARL,299926861
2025-07-17T15:42:17.589263550Z,2025-07-17T15:42:17.589098227Z,160,2,1108,C,A,14.190000000,100,0,299690593,130,165323,251595691,ARL,0,14.19,100,130,165323,251595691,9.55,1700,17,9.68,100,1,10.61,200,2,11.27,100,1,11.4,100,1,11.76,100,1,11.93,200,2,12.23,100,1,12.34,200,2,12.36,200,2,13.83,15,1,13.84,100,1,13.9,15,1,14.07,2,1,14.4,100,1,14.56,900,3,14.6,700,1,14.64,100,1,14.68,1400,2,14.76,100,1,ARL,299690593
2025-07-17T15:42:17.589316911Z,2025-07-17T15:42:17.589151325Z,160,2,1108,A,A,14.120000000,100,0,299926965,130,165586,251595692,ARL,0,14.12,100,130,165586,251595692,9.55,1700,17,9.68,100,1,10.61,200,2,11.27,100,1,11.4,100,1,11.76,100,1,11.93,200,2,12.23,100,1,12.34,200,2,12.36,200,2,13.83,15,1,13.84,100,1,13.9,15,1,14.07,2,1,14.12,100,1,14.4,100,1,14.56,900,3,14.6,700,1,14.64,100,1,14.68,1400,2,ARL,299926965
2025-07-17T15:42:18.398220000Z,2025-07-17T15:42:18.398054465Z,160,2,1108,C,A,14.880000000,100,0,296679277,0,165535,251612478,ARL,0,14.88,100,0,165535,251612478,9.55,1700,17,9.68,100,1,10.61,200,2,11.27,100,1,11.4,100,1,11.76,100,1,11.93,200,2,12.23,100,1,12.34,200,2,12.36,200,2,13.83,15,1,13.84,100,1,13.9,15,1,14.07,2,1,14.12,100,1,14.4,100,1,14.56,900,3,14.6,700,1,14.64,100,1,14.68,1400,2,ARL,296679277
2025-07-17T15:42:18.398220000Z,2025-07-17T15:42:18.398054465Z,160,2,1108,A,A,14.730000000,100,0,299945073,130,165535,251612478,ARL,0,14.73,100,130,165535,251612478,9.55,1700,17,9.68,100,1,10.61,200,2,11.27,100,1,11.4,100,1,11.76,100,1,11.93,200,2,12.23,100,1,12.34,200,2,12.36,200,2,13.83,15,1,13.84,100,1,13.9,15,1,14.07,2,1,14.12,100,1,14.4,100,1,14.56,900,3,14.6,700,1,14.64,100,1,14.68,1400,2,ARL,299945073
2025-07-17T15:42:21.517871714Z,2025-07-17T15:42:21.517706139Z,160,2,1108,C,A,13.900000000,15,0,299689753,130,165575,251668179,ARL,0,13.9,15,130,165575,251668179,9.55,1700,17,9.68,100,1,10.61,200,2,11.27,100,1,11.4,100,1,11.76,100,1,11.93,200,2,12.23,100,1,12.34,200,2,12.36,200,2,13.83,15,1,13.84,100,1,14.07,2,1,14.12,100,1,14.4,100,1,14.56,900,3,14.6,700,1,14.64,100,1,14.68,1400,2,14.73,100,1,ARL,299689753
2025-07-17T15:42:22.522744242Z,2025-07-17T15:42:22.522578675Z,160,2,1108,A,A,13.790000000,15,0,300042293,130,165567,251690950,ARL,0,13.79,15,130,165567,251690950,9.55,1700,17,9.68,100,1,10.61,200,2,11.27,100,1,11.4,100,1,11.76,100,1,11.93,200,2,12.23,100,1,12.34,200,2,12.36,200,2,13.79,15,1,13.83,15,1,13.84,100,1,14.07,2,1,14.12,100,1,14.4,100,1,14.56,900,3,14.6,700,1,14.64,100,1,14.68,1400,2,ARL,300042293
2025-07-17T15:42:22.533681479Z,2025-07-17T15:42:22.533515955Z,160,2,1108,A,A,13.820000000,100,0,300042385,130,165524,251691033,ARL,0,13.82,100,130,165524,251691033,9.55,1700,17,9.68,100,1,10.61,200,2,11.27,100,1,11.4,100,1,11.76,100,1,11.93,200,2,12.23,100,1,12.34,200,2,12.36,200,2,13.79,15,1,13.82,100,1,13.83,15,1,13.84,100,1,14.07,2,1,14.12,100,1,14.4,100,1,14.56,900,3,14.6,700,1,14.64,100,1,ARL,300042385
2025-07-17T15:42:23.490247121Z,2025-07-17T15:42:23.490079821Z,160,2,1108,C,A,13.840000000,100,0,299926781,0,167300,251710173,ARL,0,13.84,100,0,167300,251710173,9.55,1700,17,9.68,100,1,10.61,200,2,11.27,100,1,11.4,100,1,11.76,100,1,11.93,200,2,12.23,100,1,12.34,200,2,12.36,200,2,13.79,15,1,13.82,100,1,13.83,15,1,14.07,2,1,14.12,100,1,14.4,100,1,14.56,900,3,14.6,700,1,14.64,100,1,14.68,1400,2,ARL,299926781
2025-07-17T15:42:23.490247121Z,2025-07-17T15:42:23.490079821Z,160,2,1108,A,A,13.800000000,100,0,300061581,128,167300,251710173,ARL,0,13.8,100,128,167300,251710173,9.55,1700,17,9.68,100,1,10.61,200,2,11.27,100,1,11.4,100,1,11.76,100,1,11.93,200,2,12.23,100,1,12.34,200,2,12.36,200,2,13.79,15,1,13.8,100,1,13.82,100,1,13.83,15,1,14.07,2,1,14.12,100,1,14.4,100,1,14.56,900,3,14.6,700,1,14.64,100,1,ARL,300061581
2025-07-17T15:42:23.491451368Z,2025-07-17T15:42:23.491285065Z,160,2,1108,C,A,14.910000000,100,0,299926801,0,166303,251710647,ARL,0,14.91,100,0,166303,251710647,9.55,1700,17,9.68,100,1,10.61,200,2,11.27,100,1,11.4,100,1,11.76,100,1,11.93,200,2,12.23,100,1,12.34,200,2,12.36,200,2,13.79,15,1,13.8,100,1,13.82,100,1,13.83,15,1,14.07,2,1,14.12,100,1,14.4,100,1,14.56,900,3,14.6,700,1,14.64,100,1,ARL,299926801
2025-07-17T15:42:23.491451368Z,2025-07-17T15:42:23.491285065Z,160,2,1108,A,A,14.870000000,100,0,300061989,128,166303,251710647,ARL,0,14.87,100,128,166303,251710647,9.55,1700,17,9.68,100,1,10.61,200,2,11.27,100,1,11.4,100,1,11.76,100,1,11.93,200,2,12.23,100,1,12.34,200,2,12.36,200,2,13.79,15,1,13.8,100,1,13.82,100,1,13.83,15,1,14.07,2,1,14.12,100,1,14.4,100,1,14.56,900,3,14.6,700,1,14.64,100,1,ARL,300061989
2025-07-17T15:42:23.589065154Z,2025-07-17T15:42:23.588899941Z,160,2,1108,C,A,13.790000000,15,0,300042293,130,165213,251718746,ARL,0,13.79,15,130,165213,251718746,9.55,1700,17,9.68,100,1,10.61,200,2,11.27,100,1,11.4,100,1,11.76,100,1,11.93,200,2,12.23,100,1,12.34,200,2,12.36,200,2,13.8,100,1,13.82,100,1,13.83,15,1,14.07,2,1,14.12,100,1,14.4,100,1,14.56,900,3,14.6,700,1,14.64,100,1,14.68,1400,2,ARL,300042293
2025-07-17T15:42:23.589220778Z,2025-07-17T15:42:23.589055082Z,160,2,1108,C,A,13.830000000,15,0,299923773,130,165696,251718767,ARL,0,13.83,15,130,165696,251718767,9.55,1700,17,9.68,100,1,10.61,200,2,11.27,100,1,11.4,100,1,11.76,100,1,11.93,200,2,12.23,100,1,12.34,200,2,12.36,200,2,13.8,100,1,13.82,100,1,14.07,2,1,14.12,100,1,14.4,100,1,14.56,900,3,14.6,700,1,14.64,100,1,14.68,1400,2,14.73,100,1,ARL,299923773
2025-07-17T15:42:34.003710081Z,2025-07-17T15:42:34.003544527Z,160,2,1108,C,A,13.800000000,100,0,300061581,130,165554,251901273,ARL,0,13.8,100,130,165554,251901273,9.55,1700,17,9.68,100,1,10.61,200,2,11.27,100,1,11.4,100,1,11.76,100,1,11.93,200,2,12.23,100,1,12.34,200,2,12.36,200,2,13.82,100,1,14.07,2,1,14.12,100,1,14.4,100,1,14.56,900,3,14.6,700,1,14.64,100,1,14.68,1400,2,14.73,100,1,14.76,100,1,ARL,300061581
2025-07-17T15:42:34.003949340Z,2025-07-17T15:42:34.003783950Z,160,2,1108,C,A,13.820000000,100,0,300042385,130,165390,251901275,ARL,0,13.82,100,130,165390,251901275,9.55,1700,17,9.68,100,1,10.61,200,2,11.27,100,1,11.4,100,1,11.76,100,1,11.93,200,2,12.23,100,1,12.34,200,2,12.36,200,2,14.07,2,1,14.12,100,1,14.4,100,1,14.56,900,3,14.6,700,1,14.64,100,1,14.68,1400,2,14.73,100,1,14.76,100,1,14.81,200,2,ARL,300042385
2025-07-17T15:42:34.004225180Z,2025-07-17T15:42:34.004059450Z,160,2,1108,C,A,14.730000000,100,0,299945073,0,165730,251901280,ARL,0,14.73,100,0,165730,251901280,9.55,1700,17,9.68,100,1,10.61,200,2,11.27,100,1,11.4,100,1,11.76,100,1,11.93,200,2,12.23,100,1,12.34,200,2,12.36,200,2,14.07,2,1,14.12,100,1,14.4,100,1,14.56,900,3,14.6,700,1,14.64,100,1,14.68,1400,2,14.76,100,1,14.81,200,2,14.87,100,1,ARL,299945073
2025-07-17T15:42:34.004225180Z,2025-07-17T15:42:34.004059450Z,160,2,1108,A,A,14.880000000,100,0,300280745,130,165730,251901280,ARL,0,14.88,100,130,165730,251901280,9.55,1700,17,9.68,100,1,10.61,200,2,11.27,100,1,11.4,100,1,11.76,100,1,11.93,200,2,12.23,100,1,12.34,200,2,12.36,200,2,14.07,2,1,14.12,100,1,14.4,100,1,14.56,900,3,14.6,700,1,14.64,100,1,14.68,1400,2,14.76,100,1,14.81,200,2,14.87,100,1,ARL,300280745
2025-07-17T15:42:34.004671652Z,2025-07-17T15:42:34.004506043Z,160,2,1108,C,A,14.870000000,100,0,300061989,0,165609,251901285,ARL,0,14.87,100,0,165609,251901285,9.55,1700,17,9.68,100,1,10.61,200,2,11.27,100,1,11.4,100,1,11.76,100,1,11.93,200,2,12.23,100,1,12.34,200,2,12.36,200,2,14.07,2,1,14.12,100,1,14.4,100,1,14.56,900,3,14.6,700,1,14.64,100,1,14.68,1400,2,14.76,100,1,14.81,200,2,14.88,100,1,ARL,300061989
2025-07-17T15:42:34.004671652Z,2025-07-17T15:42:34.004506043Z,160,2,1108,A,A,15.060000000,100,0,300280757,130,165609,251901285,ARL,0,15.06,100,130,165609,251901285,9.55,1700,17,9.68,100,1,10.61,200,2,11.27,100,1,11.4,100,1,11.76,100,1,11.93,200,2,12.23,100,1,12.34,200,2,12.36,200,2,14.07,2,1,14.12,100,1,14.4,100,1,14.56,900,3,14.6,700,1,14.64,100,1,14.68,1400,2,14.76,100,1,14.81,200,2,14.88,100,1,ARL,300280757
2025-07-17T15:42:34.004677786Z,2025-07-17T15:42:34.004512153Z,160,2,1108,C,A,14.760000000,100,0,299903169,0,165633,251901286,ARL,0,14.76,100,0,165633,251901286,9.55,1700,17,9.68,100,1,10.61,200,2,11.27,100,1,11.4,100,1,11.76,100,1,11.93,200,2,12.23,100,1,12.34,200,2,12.36,200,2,14.07,2,1,14.12,100,1,14.4,100,1,14.56,900,3,14.6,700,1,14.64,100,1,14.68,1400,2,14.81,200,2,14.88,100,1,15.06,100,1,ARL,299903169
2025-07-17T15:42:34.004677786Z,2025-07-17T15:42:34.004512153Z,160,2,1108,A,A,14.880000000,100,0,300280761,130,165633,251901286,ARL,0,14.88,100,130,165633,251901286,9.55,1700,17,9.68,100,1,10.61,200,2,11.27,100,1,11.4,100,1,11.76,100,1,11.93,200,2,12.23,100,1,12.34,200,2,12.36,200,2,14.07,2,1,14.12,100,1,14.4,100,1,14.56,900,3,14.6,700,1,14.64,100,1,14.68,1400,2,14.81,200,2,14.88,200,2,15.06,100,1,ARL,300280761
2025-07-17T15:42:34.005574760Z,2025-07-17T15:42:34.005409139Z,160,2,1108,C,A,15.920000000,100,0,299926853,0,165621,251901302,ARL,0,15.92,100,0,165621,251901302,9.55,1700,17,9.68,100,1,10.61,200,2,11.27,100,1,11.4,100,1,11.76,100,1,11.93,200,2,12.23,100,1,12.34,200,2,12.36,200,2,14.07,2,1,14.12,100,1,14.4,100,1,14.56,900,3,14.6,700,1,14.64,100,1,14.68,1400,2,14.81,200,2,14.88,200,2,15.06,100,1,ARL,299926853
2025-07-17T15:42:34.005574760Z,2025-07-17T15:42:34.005409139Z,160,2,1108,A,A,16.080000000,100,0,300280773,130,165621,251901302,ARL,0,16.08,100,130,165621,251901302,9.55,1700,17,9.68,100,1,10.61,200,2,11.27,100,1,11.4,100,1,11.76,100,1,11.93,200,2,12.23,100,1,12.34,200,2,12.36,200,2,14.07,2,1,14.12,100,1,14.4,100,1,14.56,900,3,14.6,700,1,14.64,100,1,14.68,1400,2,14.81,200,2,14.88,200,2,15.06,100,1,ARL,300280773
2025-07-17T15:42:34.005832926Z,2025-07-17T15:42:34.005667449Z,160,2,1108,C,A,14.810000000,100,0,299926849,0,165477,251901305,ARL,0,14.81,100,0,165477,251901305,9.55,1700,17,9.68,100,1,10.61,200,2,11.27,100,1,11.4,100,1,11.76,100,1,11.93,200,2,12.23,100,1,12.34,200,2,12.36,200,2,14.07,2,1,14.12,100,1,14.4,100,1,14.56,900,3,14.6,700,1,14.64,100,1,14.68,1400,2,14.81,100,1,14.88,200,2,15.06,100,1,ARL,299926849
2025-07-17T15:42:34.005832926Z,2025-07-17T15:42:34.005667449Z,160,2,1108,A,A,14.960000000,100,0,300280777,130,165477,251901305,ARL,0,14.96,100,130,165477,251901305,9.55,1700,17,9.68,100,1,10.61,200,2,11.27,100,1,11.4,100,1,11.76,100,1,11.93,200,2,12.23,100,1,12.34,200,2,12.36,200,2,14.07,2,1,14.12,100,1,14.4,100,1,14.56,900,3,14.6,700,1,14.64,100,1,14.68,1400,2,14.81,100,1,14.88,200,2,14.96,100,1,ARL,300280777
2025-07-17T15:42:34.006831024Z,2025-07-17T15:42:34.006665512Z,160,2,1108,C,A,17.580000000,100,0,299926861,0,165512,251901319,ARL,0,17.58,100,0,165512,251901319,9.55,1700,17,9.68,100,1,10.61,200,2,11.27,100,1,11.4,100,1,11.76,100,1,11.93,200,2,12.23,100,1,12.34,200,2,12.36,200,2,14.07,2,1,14.12,100,1,14.4,100,1,14.56,900,3,14.6,700,1,14.64,100,1,14.68,1400,2,14.81,100,1,14.88,200,2,14.96,100,1,ARL,299926861
2025-07-17T15:42:34.006831024Z,2025-07-17T15:42:34.006665512Z,160,2,1108,A,A,17.760000000,100,0,300280797,130,165512,251901319,ARL,0,17.76,100,130,165512,251901319,9.55,1700,17,9.68,100,1,10.61,200,2,11.27,100,1,11.4,100,1,11.76,100,1,11.93,200,2,12.23,100,1,12.34,200,2,12.36,200,2,14.07,2,1,14.12,100,1,14.4,100,1,14.56,900,3,14.6,700,1,14.64,100,1,14.68,1400,2,14.81,100,1,14.88,200,2,14.96,100,1,ARL,300280797
2025-07-17T15:42:34.007908678Z,2025-07-17T15:42:34.007743383Z,160,2,1108,C,A,14.640000000,100,0,299926813,130,165295,251901330,ARL,0,14.64,100,130,165295,251901330,9.55,1700,17,9.68,100,1,10.61,200,2,11.27,100,1,11.4,100,1,11.76,100,1,11.93,200,2,12.23,100,1,12.34,200,2,12.36,200,2,14.07,2,1,14.12,100,1,14.4,100,1,14.56,900,3,14.6,700,1,14.68,1400,2,14.81,100,1,14.88,200,2,14.96,100,1,15.06,100,1,ARL,299926813
2025-07-17T15:42:34.008072663Z,2025-07-17T15:42:34.007907269Z,160,2,1108,A,A,14.780000000,100,0,300280825,130,165394,251901331,ARL,0,14.78,100,130,165394,251901331,9.55,1700,17,9.68,100,1,10.61,200,2,11.27,100,1,11.4,100,1,11.76,100,1,11.93,200,2,12.23,100,1,12.34,200,2,12.36,200,2,14.07,2,1,14.12,100,1,14.4,100,1,14.56,900,3,14.6,700,1,14.68,1400,2,14.78,100,1,14.81,100,1,14.88,200,2,14.96,100,1,ARL,300280825
2025-07-17T15:42:34.010196831Z,2025-07-17T15:42:34.010031518Z,160,2,1108,C,A,14.120000000,100,0,299926965,130,165313,251901352,ARL,0,14.12,100,130,165313,251901352,9.55,1700,17,9.68,100,1,10.61,200,2,11.27,100,1,11.4,100,1,11.76,100,1,11.93,200,2,12.23,100,1,12.34,200,2,12.36,200,2,14.07,2,1,14.4,100,1,14.56,900,3,14.6,700,1,14.68,1400,2,14.78,100,1,14.81,100,1,14.88,200,2,14.96,100,1,15.06,100,1,ARL,299926965
2025-07-17T15:42:34.010248842Z,2025-07-17T15:42:34.010083409Z,160,2,1108,A,A,14.260000000,100,0,300280857,130,165433,251901353,ARL,0,14.26,100,130,165433,251901353,9.55,1700,17,9.68,100,1,10.61,200,2,11.27,100,1,11.4,100,1,11.76,100,1,11.93,200,2,12.23,100,1,12.34,200,2,12.36,200,2,14.07,2,1,14.26,100,1,14.4,100,1,14.56,900,3,14.6,700,1,14.68,1400,2,14.78,100,1,14.81,100,1,14.88,200,2,14.96,100,1,ARL,300280857
2025-07-17T15:42:34.010572370Z,2025-07-17T15:42:34.010406771Z,160,2,1108,C,A,14.810000000,100,0,299926857,0,165599,251901355,ARL,0,14.81,100,0,165599,251901355,9.55,1700,17,9.68,100,1,10.61,200,2,11.27,100,1,11.4,100,1,11.76,100,1,11.93,200,2,12.23,100,1,12.34,200,2,12.36,200,2,14.07,2,1,14.26,100,1,14.4,100,1,14.56,900,3,14.6,700,1,14.68,1400,2,14.78,100,1,14.88,200,2,14.96,100,1,15.06,100,1,ARL,299926857
2025-07-17T15:42:34.010572370Z,2025-07-17T15:42:34.010406771Z,160,2,1108,A,A,14.960000000,100,0,300280873,130,165599,251901355,ARL,0,14.96,100,130,165599,251901355,9.55,1700,17,9.68,100,1,10.61,200,2,11.27,100,1,11.4,100,1,11.76,100,1,11.93,200,2,12.23,100,1,12.34,200,2,12.36,200,2,14.07,2,1,14.26,100,1,14.4,100,1,14.56,900,3,14.6,700,1,14.68,1400,2,14.78,100,1,14.88,200,2,14.96,200,2,15.06,100,1,ARL,300280873
2025-07-17T15:42:34.952098027Z,2025-07-17T15:42:34.951932909Z,160,2,1108,A,A,14.080000000,100,0,300294885,130,165118,251912292,ARL,0,14.08,100,130,165118,251912292,9.55,1700,17,9.68,100,1,10.61,200,2,11.27,100,1,11.4,100,1,11.76,100,1,11.93,200,2,12.23,100,1,12.34,200,2,12.36,200,2,14.07,2,1,14.08,100,1,14.26,100,1,14.4,100,1,14.56,900,3,14.6,700,1,14.68,1400,2,14.78,100,1,14.88,200,2,14.96,200,2,ARL,300294885
2025-07-17T15:43:21.513838949Z,2025-07-17T15:43:21.513673603Z,160,2,1108,A,A,13.920000000,15,0,301218889,130,165346,252622568,ARL,0,13.92,15,130,165346,252622568,9.55,1700,17,9.68,100,1,10.61,200,2,11.27,100,1,11.4,100,1,11.76,100,1,11.93,200,2,12.23,100,1,12.34,200,2,12.36,200,2,13.92,15,1,14.07,2,1,14.08,100,1,14.26,100,1,14.4,100,1,14.56,900,3,14.6,700,1,14.68,1400,2,14.78,100,1,14.88,200,2,ARL,301218889
2025-07-17T15:43:24.878236760Z,2025-07-17T15:43:24.878071152Z,160,2,1108,C,A,14.080000000,100,0,300294885,0,165608,252681819,ARL,0,14.08,100,0,165608,252681819,9.55,1700,17,9.68,100,1,10.61,200,2,11.27,100,1,11.4,100,1,11.76,100,1,11.93,200,2,12.23,100,1,12.34,200,2,12.36,200,2,13.92,15,1,14.07,2,1,14.26,100,1,14.4,100,1,14.56,900,3,14.6,700,1,14.68,1400,2,14.78,100,1,14.88,200,2,14.96,200,2,ARL,300294885
2025-07-17T15:43:24.878236760Z,2025-07-17T15:43:24.878071152Z,160,2,1108,A,A,13.930000000,100,0,301295841,130,165608,252681819,ARL,0,13.93,100,130,165608,252681819,9.55,1700,17,9.68,100,1,10.61,200,2,11.27,100,1,11.4,100,1,11.76,100,1,11.93,200,2,12.23,100,1,12.34,200,2,12.36,200,2,13.92,15,1,13.93,100,1,14.07,2,1,14.26,100,1,14.4,100,1,14.56,900,3,14.6,700,1,14.68,1400,2,14.78,100,1,14.88,200,2,ARL,301295841
2025-07-17T15:43:24.879003443Z,2025-07-17T15:43:24.878837670Z,160,2,1108,C,A,15.060000000,100,0,300280757,0,165773,252681832,ARL,0,15.06,100,0,165773,252681832,9.55,1700,17,9.68,100,1,10.61,200,2,11.27,100,1,11.4,100,1,11.76,100,1,11.93,200,2,12.23,100,1,12.34,200,2,12.36,200,2,13.92,15,1,13.93,100,1,14.07,2,1,14.26,100,1,14.4,100,1,14.56,900,3,14.6,700,1,14.68,1400,2,14.78,100,1,14.88,200,2,ARL,300280757
2025-07-17T15:43:24.879003443Z,2025-07-17T15:43:24.878837670Z,160,2,1108,A,A,15.010000000,100,0,301295873,130,165773,252681832,ARL,0,15.01,100,130,165773,252681832,9.55,1700,17,9.68,100,1,10.61,200,2,11.27,100,1,11.4,100,1,11.76,100,1,11.93,200,2,12.23,100,1,12.34,200,2,12.36,200,2,13.92,15,1,13.93,100,1,14.07,2,1,14.26,100,1,14.4,100,1,14.56,900,3,14.6,700,1,14.68,1400,2,14.78,100,1,14.88,200,2,ARL,301295873
2025-07-17T15:43:32.780372412Z,2025-07-17T15:43:32.780206927Z,160,2,1108,A,A,13.880000000,15,0,301451057,130,165485,252800884,ARL,0,13.88,15,130,165485,252800884,9.55,1700,17,9.68,100,1,10.61,200,2,11.27,100,1,11.4,100,1,11.76,100,1,11.93,200,2,12.23,100,1,12.34,200,2,12.36,200,2,13.88,15,1,13.92,15,1,13.93,100,1,14.07,2,1,14.26,100,1,14.4,100,1,14.56,900,3,14.6,700,1,14.68,1400,2,14.78,100,1,ARL,301451057
2025-07-17T15:43:32.780639619Z,2025-07-17T15:43:32.780474141Z,160,2,1108,C,A,13.930000000,100,0,301295841,0,165478,252800887,ARL,0,13.93,100,0,165478,252800887,9.55,1700,17,9.68,100,1,10.61,200,2,11.27,100,1,11.4,100,1,11.76,100,1,11.93,200,2,12.23,100,1,12.34,200,2,12.36,200,2,13.88,15,1,13.92,15,1,14.07,2,1,14.26,100,1,14.4,100,1,14.56,900,3,14.6,700,1,14.68,1400,2,14.78,100,1,14.88,200,2,ARL,301295841
2025-07-17T15:43:32.780639619Z,2025-07-17T15:43:32.780474141Z,160,2,1108,A,A,13.890000000,100,0,301451061,130,165478,252800887,ARL,0,13.89,100,130,165478,252800887,9.55,1700,17,9.68,100,1,10.61,200,2,11.27,100,1,11.4,100,1,11.76,100,1,11.93,200,2,12.23,100,1,12.34,200,2,12.36,200,2,13.88,15,1,13.89,100,1,13.92,15,1,14.07,2,1,14.26,100,1,14.4,100,1,14.56,900,3,14.6,700,1,14.68,1400,2,14.78,100,1,ARL,301451061
2025-07-17T15:43:32.781382162Z,2025-07-17T15:43:32.781216589Z,160,2,1108,C,A,15.010000000,100,0,301295873,0,165573,252800892,ARL,0,15.01,100,0,165573,252800892,9.55,1700,17,9.68,100,1,10.61,200,2,11.27,100,1,11.4,100,1,11.76,100,1,11.93,200,2,12.23,100,1,12.34,200,2,12.36,200,2,13.88,15,1,13.89,100,1,13.92,15,1,14.07,2,1,14.26,100,1,14.4,100,1,14.56,900,3,14.6,700,1,14.68,1400,2,14.78,100,1,ARL,301295873
2025-07-17T15:43:32.781382162Z,2025-07-17T15:43:32.781216589Z,160,2,1108,A,A,14.970000000,100,0,301451077,130,165573,252800892,ARL,0,14.97,100,130,165573,252800892,9.55,1700,17,9.68,100,1,10.61,200,2,11.27,100,1,11.4,100,1,11.76,100,1,11.93,200,2,12.23,100,1,12.34,200,2,12.36,200,2,13.88,15,1,13.89,100,1,13.92,15,1,14.07,2,1,14.26,100,1,14.4,100,1,14.56,900,3,14.6,700,1,14.68,1400,2,14.78,100,1,ARL,301451077
2025-07-17T15:43:32.792119698Z,2025-07-17T15:43:32.791954053Z,160,2,1108,C,A,14.260000000,100,0,300280857,130,165645,252801681,ARL,0,14.26,100,130,165645,252801681,9.55,1700,17,9.68,100,1,10.61,200,2,11.27,100,1,11.4,100,1,11.76,100,1,11.93,200,2,12.23,100,1,12.34,200,2,12.36,200,2,13.88,15,1,13.89,100,1,13.92,15,1,14.07,2,1,14.4,100,1,14.56,900,3,14.6,700,1,14.68,1400,2,14.78,100,1,14.88,200,2,ARL,300280857
2025-07-17T15:43:32.792174617Z,2025-07-17T15:43:32.792008881Z,160,2,1108,A,A,14.170000000,100,0,301452785,130,165736,252801689,ARL,0,14.17,100,130,165736,252801689,9.55,1700,17,9.68,100,1,10.61,200,2,11.27,100,1,11.4,100,1,11.76,100,1,11.93,200,2,12.23,100,1,12.34,200,2,12.36,200,2,13.88,15,1,13.89,100,1,13.92,15,1,14.07,2,1,14.17,100,1,14.4,100,1,14.56,900,3,14.6,700,1,14.68,1400,2,14.78,100,1,ARL,301452785
2025-07-17T15:43:44.004832641Z,2025-07-17T15:43:44.004667259Z,160,2,1108,C,A,13.920000000,15,0,301218889,130,165382,252977583,ARL,0,13.92,15,130,165382,252977583,9.55,1700,17,9.68,100,1,10.61,200,2,11.27,100,1,11.4,100,1,11.76,100,1,11.93,200,2,12.23,100,1,12.34,200,2,12.36,200,2,13.88,15,1,13.89,100,1,14.07,2,1,14.17,100,1,14.4,100,1,14.56,900,3,14.6,700,1,14.68,1400,2,14.78,100,1,14.88,200,2,ARL,301218889
2025-07-17T15:43:44.005191111Z,2025-07-17T15:43:44.005025587Z,160,2,1108,C,A,14.880000000,100,0,300280761,0,165524,252977592,ARL,0,14.88,100,0,165524,252977592,9.55,1700,17,9.68,100,1,10.61,200,2,11.27,100,1,11.4,100,1,11.76,100,1,11.93,200,2,12.23,100,1,12.34,200,2,12.36,200,2,13.88,15,1,13.89,100,1,14.07,2,1,14.17,100,1,14.4,100,1,14.56,900,3,14.6,700,1,14.68,1400,2,14.78,100,1,14.88,100,1,ARL,300280761
2025-07-17T15:43:44.005191111Z,2025-07-17T15:43:44.005025587Z,160,2,1108,A,A,14.770000000,100,0,301671709,130,165524,252977592,ARL,0,14.77,100,130,165524,252977592,9.55,1700,17,9.68,100,1,10.61,200,2,11.27,100,1,11.4,100,1,11.76,100,1,11.93,200,2,12.23,100,1,12.34,200,2,12.36,200,2,13.88,15,1,13.89,100,1,14.07,2,1,14.17,100,1,14.4,100,1,14.56,900,3,14.6,700,1,14.68,1400,2,14.77,100,1,14.78,100,1,ARL,301671709
2025-07-17T15:43:44.005313071Z,2025-07-17T15:43:44.005147707Z,160,2,1108,C,A,14.880000000,100,0,300280745,0,165364,252977595,ARL,0,14.88,100,0,165364,252977595,9.55,1700,17,9.68,100,1,10.61,200,2,11.27,100,1,11.4,100,1,11.76,100,1,11.93,200,2,12.23,100,1,12.34,200,2,12.36,200,2,13.88,15,1,13.89,100,1,14.07,2,1,14.17,100,1,14.4,100,1,14.56,900,3,14.6,700,1,14.68,1400,2,14.77,100,1,14.78,100,1,ARL,300280745
2025-07-17T15:43:44.005313071Z,2025-07-17T15:43:44.005147707Z,160,2,1108,A,A,14.770000000,100,0,301671713,130,165364,252977595,ARL,0,14.77,100,130,165364,252977595,9.55,1700,17,9.68,100,1,10.61,200,2,11.27,100,1,11.4,100,1,11.76,100,1,11.93,200,2,12.23,100,1,12.34,200,2,12.36,200,2,13.88,15,1,13.89,100,1,14.07,2,1,14.17,100,1,14.4,100,1,14.56,900,3,14.6,700,1,14.68,1400,2,14.77,200,2,14.78,100,1,ARL,301671713
2025-07-17T15:43:48.787497664Z,2025-07-17T15:43:48.787332399Z,160,2,1108,A,A,13.830000000,15,0,301746941,130,165265,253027890,ARL,0,13.83,15,130,165265,253027890,9.55,1700,17,9.68,100,1,10.61,200,2,11.27,100,1,11.4,100,1,11.76,100,1,11.93,200,2,12.23,100,1,12.34,200,2,12.36,200,2,13.83,15,1,13.88,15,1,13.89,100,1,14.07,2,1,14.17,100,1,14.4,100,1,14.56,900,3,14.6,700,1,14.68,1400,2,14.77,200,2,ARL,301746941
2025-07-17T15:43:48.787766907Z,2025-07-17T15:43:48.787601640Z,160,2,1108,C,A,13.890000000,100,0,301451061,0,165267,253027924,ARL,0,13.89,100,0,165267,253027924,9.55,1700,17,9.68,100,1,10.61,200,2,11.27,100,1,11.4,100,1,11.76,100,1,11.93,200,2,12.23,100,1,12.34,200,2,12.36,200,2,13.83,15,1,13.88,15,1,14.07,2,1,14.17,100,1,14.4,100,1,14.56,900,3,14.6,700,1,14.68,1400,2,14.77,200,2,14.78,100,1,ARL,301451061
2025-07-17T15:43:48.787766907Z,2025-07-17T15:43:48.787601640Z,160,2,1108,A,A,13.840000000,100,0,301746949,130,165267,253027924,ARL,0,13.84,100,130,165267,253027924,9.55,1700,17,9.68,100,1,10.61,200,2,11.27,100,1,11.4,100,1,11.76,100,1,11.93,200,2,12.23,100,1,12.34,200,2,12.36,200,2,13.83,15,1,13.84,100,1,13.88,15,1,14.07,2,1,14.17,100,1,14.4,100,1,14.56,900,3,14.6,700,1,14.68,1400,2,14.77,200,2,ARL,301746949
2025-07-17T15:43:48.788512022Z,2025-07-17T15:43:48.788345787Z,160,2,1108,C,A,14.970000000,100,0,301451077,0,166235,253027959,ARL,0,14.97,100,0,166235,253027959,9.55,1700,17,9.68,100,1,10.61,200,2,11.27,100,1,11.4,100,1,11.76,100,1,11.93,200,2,12.23,100,1,12.34,200,2,12.36,200,2,13.83,15,1,13.84,100,1,13.88,15,1,14.07,2,1,14.17,100,1,14.4,100,1,14.56,900,3,14.6,700,1,14.68,1400,2,14.77,200,2,ARL,301451077
2025-07-17T15:43:48.788512022Z,2025-07-17T15:43:48.788345787Z,160,2,1108,A,A,14.910000000,100,0,301746969,128,166235,253027959,ARL,0,14.91,100,128,166235,253027959,9.55,1700,17,9.68,100,1,10.61,200,2,11.27,100,1,11.4,100,1,11.76,100,1,11.93,200,2,12.23,100,1,12.34,200,2,12.36,200,2,13.83,15,1,13.84,100,1,13.88,15,1,14.07,2,1,14.17,100,1,14.4,100,1,14.56,900,3,14.6,700,1,14.68,1400,2,14.77,200,2,ARL,301746969
2025-07-17T15:43:48.790573820Z,2025-07-17T15:43:48.790408191Z,160,2,1108,C,A,14.960000000,100,0,300280777,0,165629,253028026,ARL,0,14.96,100,0,165629,253028026,9.55,1700,17,9.68,100,1,10.61,200,2,11.27,100,1,11.4,100,1,11.76,100,1,11.93,200,2,12.23,100,1,12.34,200,2,12.36,200,2,13.83,15,1,13.84,100,1,13.88,15,1,14.07,2,1,14.17,100,1,14.4,100,1,14.56,900,3,14.6,700,1,14.68,1400,2,14.77,200,2,ARL,300280777
2025-07-17T15:43:48.790573820Z,2025-07-17T15:43:48.790408191Z,160,2,1108,A,A,14.810000000,100,0,301747001,130,165629,253028026,ARL,0,14.81,100,130,165629,253028026,9.55,1700,17,9.68,100,1,10.61,200,2,11.27,100,1,11.4,100,1,11.76,100,1,11.93,200,2,12.23,100,1,12.34,200,2,12.36,200,2,13.83,15,1,13.84,100,1,13.88,15,1,14.07,2,1,14.17,100,1,14.4,100,1,14.56,900,3,14.6,700,1,14.68,1400,2,14.77,200,2,ARL,301747001
2025-07-17T15:43:48.790600546Z,2025-07-17T15:43:48.790434947Z,160,2,1108,C,A,14.780000000,100,0,300280825,0,165599,253028027,ARL,0,14.78,100,0,165599,253028027,9.55,1700,17,9.68,100,1,10.61,200,2,11.27,100,1,11.4,100,1,11.76,100,1,11.93,200,2,12.23,100,1,12.34,200,2,12.36,200,2,13.83,15,1,13.84,100,1,13.88,15,1,14.07,2,1,14.17,100,1,14.4,100,1,14.56,900,3,14.6,700,1,14.68,1400,2,14.77,200,2,ARL,300280825
2025-07-17T15:43:48.790600546Z,2025-07-17T15:43:48.790434947Z,160,2,1108,A,A,14.640000000,100,0,301747005,130,165599,253028027,ARL,0,14.64,100,130,165599,253028027,9.55,1700,17,9.68,100,1,10.61,200,2,11.27,100,1,11.4,100,1,11.76,100,1,11.93,200,2,12.23,100,1,12.34,200,2,12.36,200,2,13.83,15,1,13.84,100,1,13.88,15,1,14.07,2,1,14.17,100,1,14.4,100,1,14.56,900,3,14.6,700,1,14.64,100,1,14.68,1400,2,ARL,301747005
2025-07-17T15:43:48.800959598Z,2025-07-17T15:43:48.800794196Z,160,2,1108,C,A,17.760000000,100,0,300280797,0,165402,253028707,ARL,0,17.76,100,0,165402,253028707,9.55,1700,17,9.68,100,1,10.61,200,2,11.27,100,1,11.4,100,1,11.76,100,1,11.93,200,2,12.23,100,1,12.34,200,2,12.36,200,2,13.83,15,1,13.84,100,1,13.88,15,1,14.07,2,1,14.17,100,1,14.4,100,1,14.56,900,3,14.6,700,1,14.64,100,1,14.68,1400,2,ARL,300280797
2025-07-17T15:43:48.800959598Z,2025-07-17T15:43:48.800794196Z,160,2,1108,A,A,17.580000000,100,0,301747261,130,165402,253028707,ARL,0,17.58,100,130,165402,253028707,9.55,1700,17,9.68,100,1,10.61,200,2,11.27,100,1,11.4,100,1,11.76,100,1,11.93,200,2,12.23,100,1,12.34,200,2,12.36,200,2,13.83,15,1,13.84,100,1,13.88,15,1,14.07,2,1,14.17,100,1,14.4,100,1,14.56,900,3,14.6,700,1,14.64,100,1,14.68,1400,2,ARL,301747261
2025-07-17T15:43:48.806845249Z,2025-07-17T15:43:48.806679708Z,160,2,1108,C,A,16.080000000,100,0,300280773,0,165541,253028803,ARL,0,16.08,100,0,165541,253028803,9.55,1700,17,9.68,100,1,10.61,200,2,11.27,100,1,11.4,100,1,11.76,100,1,11.93,200,2,12.23,100,1,12.34,200,2,12.36,200,2,13.83,15,1,13.84,100,1,13.88,15,1,14.07,2,1,14.17,100,1,14.4,100,1,14.56,900,3,14.6,700,1,14.64,100,1,14.68,1400,2,ARL,300280773
2025-07-17T15:43:48.806845249Z,2025-07-17T15:43:48.806679708Z,160,2,1108,A,A,15.920000000,100,0,301747301,130,165541,253028803,ARL,0,15.92,100,130,165541,253028803,9.55,1700,17,9.68,100,1,10.61,200,2,11.27,100,1,11.4,100,1,11.76,100,1,11.93,200,2,12.23,100,1,12.34,200,2,12.36,200,2,13.83,15,1,13.84,100,1,13.88,15,1,14.07,2,1,14.17,100,1,14.4,100,1,14.56,900,3,14.6,700,1,14.64,100,1,14.68,1400,2,ARL,301747301
2025-07-17T15:43:48.852570853Z,2025-07-17T15:43:48.852405047Z,160,2,1108,C,A,14.960000000,100,0,300280873,0,165806,253029437,ARL,0,14.96,100,0,165806,253029437,9.55,1700,17,9.68,100,1,10.61,200,2,11.27,100,1,11.4,100,1,11.76,100,1,11.93,200,2,12.23,100,1,12.34,200,2,12.36,200,2,13.83,15,1,13.84,100,1,13.88,15,1,14.07,2,1,14.17,100,1,14.4,100,1,14.56,900,3,14.6,700,1,14.64,100,1,14.68,1400,2,ARL,300280873
2025-07-17T15:43:48.852570853Z,2025-07-17T15:43:48.852405047Z,160,2,1108,A,A,14.810000000,100,0,301747957,130,165806,253029437,ARL,0,14.81,100,130,165806,253029437,9.55,1700,17,9.68,100,1,10.61,200,2,11.27,100,1,11.4,100,1,11.76,100,1,11.93,200,2,12.23,100,1,12.34,200,2,12.36,200,2,13.83,15,1,13.84,100,1,13.88,15,1,14.07,2,1,14.17,100,1,14.4,100,1,14.56,900,3,14.6,700,1,14.64,100,1,14.68,1400,2,ARL,301747957
2025-07-17T15:43:53.123817759Z,2025-07-17T15:43:53.123652480Z,160,2,1108,C,A,13.880000000,15,0,301451057,130,165279,253100941,ARL,0,13.88,15,130,165279,253100941,9.55,1700,17,9.68,100,1,10.61,200,2,11.27,100,1,11.4,100,1,11.76,100,1,11.93,200,2,12.23,100,1,12.34,200,2,12.36,200,2,13.83,15,1,13.84,100,1,14.07,2,1,14.17,100,1,14.4,100,1,14.56,900,3,14.6,700,1,14.64,100,1,14.68,1400,2,14.77,200,2,ARL,301451057
2025-07-17T15:43:54.126276976Z,2025-07-17T15:43:54.126111293Z,160,2,1108,A,A,13.810000000,15,0,301867541,130,165683,253121467,ARL,0,13.81,15,130,165683,253121467,9.55,1700,17,9.68,100,1,10.61,200,2,11.27,100,1,11.4,100,1,11.76,100,1,11.93,200,2,12.23,100,1,12.34,200,2,12.36,200,2,13.81,15,1,13.83,15,1,13.84,100,1,14.07,2,1,14.17,100,1,14.4,100,1,14.56,900,3,14.6,700,1,14.64,100,1,14.68,1400,2,ARL,301867541
2025-07-17T15:43:54.998238933Z,2025-07-17T15:43:54.998073317Z,160,2,1108,C,A,13.840000000,100,0,301746949,0,165616,253137948,ARL,0,13.84,100,0,165616,253137948,9.55,1700,17,9.68,100,1,10.61,200,2,11.27,100,1,11.4,100,1,11.76,100,1,11.93,200,2,12.23,100,1,12.34,200,2,12.36,200,2,13.81,15,1,13.83,15,1,14.07,2,1,14.17,100,1,14.4,100,1,14.56,900,3,14.6,700,1,14.64,100,1,14.68,1400,2,14.77,200,2,ARL,301746949
2025-07-17T15:43:54.998238933Z,2025-07-17T15:43:54.998073317Z,160,2,1108,A,A,13.820000000,100,0,301885353,130,165616,253137948,ARL,0,13.82,100,130,165616,253137948,9.55,1700,17,9.68,100,1,10.61,200,2,11.27,100,1,11.4,100,1,11.76,100,1,11.93,200,2,12.23,100,1,12.34,200,2,12.36,200,2,13.81,15,1,13.82,100,1,13.83,15,1,14.07,2,1,14.17,100,1,14.4,100,1,14.56,900,3,14.6,700,1,14.64,100,1,14.68,1400,2,ARL,301885353
2025-07-17T15:43:55.019172741Z,2025-07-17T15:43:55.019007300Z,160,2,1108,C,A,14.170000000,100,0,301452785,130,165441,253138492,ARL,0,14.17,100,130,165441,253138492,9.55,1700,17,9.68,100,1,10.61,200,2,11.27,100,1,11.4,100,1,11.76,100,1,11.93,200,2,12.23,100,1,12.34,200,2,12.36,200,2,13.81,15,1,13.82,100,1,13.83,15,1,14.07,2,1,14.4,100,1,14.56,900,3,14.6,700,1,14.64,100,1,14.68,1400,2,14.77,200,2,ARL,301452785
2025-07-17T15:43:55.019225935Z,2025-07-17T15:43:55.019060515Z,160,2,1108,A,A,14.100000000,100,0,301886057,130,165420,253138493,ARL,0,14.1,100,130,165420,253138493,9.55,1700,17,9.68,100,1,10.61,200,2,11.27,100,1,11.4,100,1,11.76,100,1,11.93,200,2,12.23,100,1,12.34,200,2,12.36,200,2,13.81,15,1,13.82,100,1,13.83,15,1,14.07,2,1,14.1,100,1,14.4,100,1,14.56,900,3,14.6,700,1,14.64,100,1,14.68,1400,2,ARL,301886057
2025-07-17T15:44:01.698791467Z,2025-07-17T15:44:01.698626200Z,160,2,1108,C,A,13.830000000,15,0,301746941,130,165267,253246317,ARL,0,13.83,15,130,165267,253246317,9.55,1700,17,9.68,100,1,10.61,200,2,11.27,100,1,11.4,100,1,11.76,100,1,11.93,200,2,12.23,100,1,12.34,200,2,12.36,200,2,13.81,15,1,13.82,100,1,14.07,2,1,14.1,100,1,14.4,100,1,14.56,900,3,14.6,700,1,14.64,100,1,14.68,1400,2,14.77,200,2,ARL,301746941
2025-07-17T15:44:04.014878156Z,2025-07-17T15:44:04.014712730Z,160,2,1108,A,A,13.830000000,100,0,302078553,130,165426,253292355,ARL,0,13.83,100,130,165426,253292355,9.55,1700,17,9.68,100,1,10.61,200,2,11.27,100,1,11.4,100,1,11.76,100,1,11.93,200,2,12.23,100,1,12.34,200,2,12.36,200,2,13.81,15,1,13.82,100,1,13.83,100,1,14.07,2,1,14.1,100,1,14.4,100,1,14.56,900,3,14.6,700,1,14.64,100,1,14.68,1400,2,ARL,302078553
2025-07-17T15:44:05.055626948Z,2025-07-17T15:44:05.055461574Z,160,2,1108,A,A,13.810000000,100,0,302100649,130,165374,253307083,ARL,0,13.81,100,130,165374,253307083,9.55,1700,17,9.68,100,1,10.61,200,2,11.27,100,1,11.4,100,1,11.76,100,1,11.93,200,2,12.23,100,1,12.34,200,2,12.36,200,2,13.81,115,2,13.82,100,1,13.83,100,1,14.07,2,1,14.1,100,1,14.4,100,1,14.56,900,3,14.6,700,1,14.64,100,1,14.68,1400,2,ARL,302100649
2025-07-17T15:44:05.062431949Z,2025-07-17T15:44:05.062266845Z,160,2,1108,C,A,13.830000000,100,0,302078553,130,165104,253307147,ARL,0,13.83,100,130,165104,253307147,9.55,1700,17,9.68,100,1,10.61,200,2,11.27,100,1,11.4,100,1,11.76,100,1,11.93,200,2,12.23,100,1,12.34,200,2,12.36,200,2,13.81,115,2,13.82,100,1,14.07,2,1,14.1,100,1,14.4,100,1,14.56,900,3,14.6,700,1,14.64,100,1,14.68,1400,2,14.77,200,2,ARL,302078553
2025-07-17T15:44:09.389713730Z,2025-07-17T15:44:09.389548394Z,160,2,1108,A,A,13.760000000,15,0,302205249,130,165336,253384422,ARL,0,13.76,15,130,165336,253384422,9.55,1700,17,9.68,100,1,10.61,200,2,11.27,100,1,11.4,100,1,11.76,100,1,11.93,200,2,12.23,100,1,12.34,200,2,12.36,200,2,13.76,15,1,13.81,115,2,13.82,100,1,14.07,2,1,14.1,100,1,14.4,100,1,14.56,900,3,14.6,700,1,14.64,100,1,14.68,1400,2,ARL,302205249
2025-07-17T15:44:09.390496140Z,2025-07-17T15:44:09.390329935Z,160,2,1108,C,A,14.770000000,100,0,301671709,0,166205,253384438,ARL,0,14.77,100,0,166205,253384438,9.55,1700,17,9.68,100,1,10.61,200,2,11.27,100,1,11.4,100,1,11.76,100,1,11.93,200,2,12.23,100,1,12.34,200,2,12.36,200,2,13.76,15,1,13.81,115,2,13.82,100,1,14.07,2,1,14.1,100,1,14.4,100,1,14.56,900,3,14.6,700,1,14.64,100,1,14.68,1400,2,ARL,301671709
2025-07-17T15:44:09.390496140Z,2025-07-17T15:44:09.390329935Z,160,2,1108,A,A,14.660000000,100,0,302205289,128,166205,253384438,ARL,0,14.66,100,128,166205,253384438,9.55,1700,17,9.68,100,1,10.61,200,2,11.27,100,1,11.4,100,1,11.76,100,1,11.93,200,2,12.23,100,1,12.34,200,2,12.36,200,2,13.76,15,1,13.81,115,2,13.82,100,1,14.07,2,1,14.1,100,1,14.4,100,1,14.56,900,3,14.6,700,1,14.64,100,1,14.66,100,1,ARL,302205289
2025-07-17T15:44:09.391058486Z,2025-07-17T15:44:09.390893172Z,160,2,1108,C,A,14.770000000,100,0,301671713,0,165314,253384456,ARL,0,14.77,100,0,165314,253384456,9.55,1700,17,9.68,100,1,10.61,200,2,11.27,100,1,11.4,100,1,11.76,100,1,11.93,200,2,12.23,100,1,12.34,200,2,12.36,200,2,13.76,15,1,13.81,115,2,13.82,100,1,14.07,2,1,14.1,100,1,14.4,100,1,14.56,900,3,14.6,700,1,14.64,100,1,14.66,100,1,ARL,301671713
2025-07-17T15:44:09.391058486Z,2025-07-17T15:44:09.390893172Z,160,2,1108,A,A,14.660000000,100,0,302205309,130,165314,253384456,ARL,0,14.66,100,130,165314,253384456,9.55,1700,17,9.68,100,1,10.61,200,2,11.27,100,1,11.4,100,1,11.76,100,1,11.93,200,2,12.23,100,1,12.34,200,2,12.36,200,2,13.76,15,1,13.81,115,2,13.82,100,1,14.07,2,1,14.1,100,1,14.4,100,1,14.56,900,3,14.6,700,1,14.64,100,1,14.66,200,2,ARL,302205309
2025-07-17T15:44:09.395447612Z,2025-07-17T15:44:09.395281780Z,160,2,1108,C,A,13.820000000,100,0,301885353,0,165832,253384698,ARL,0,13.82,100,0,165832,253384698,9.55,1700,17,9.68,100,1,10.61,200,2,11.27,100,1,11.4,100,1,11.76,100,1,11.93,200,2,12.23,100,1,12.34,200,2,12.36,200,2,13.76,15,1,13.81,115,2,14.07,2,1,14.1,100,1,14.4,100,1,14.56,900,3,14.6,700,1,14.64,100,1,14.66,200,2,14.68,1400,2,ARL,301885353
2025-07-17T15:44:09.395447612Z,2025-07-17T15:44:09.395281780Z,160,2,1108,A,A,13.770000000,100,0,302205493,130,165832,253384698,ARL,0,13.77,100,130,165832,253384698,9.55,1700,17,9.68,100,1,10.61,200,2,11.27,100,1,11.4,100,1,11.76,100,1,11.93,200,2,12.23,100,1,12.34,200,2,12.36,200,2,13.76,15,1,13.77,100,1,13.81,115,2,14.07,2,1,14.1,100,1,14.4,100,1,14.56,900,3,14.6,700,1,14.64,100,1,14.66,200,2,ARL,302205493
2025-07-17T15:44:09.396195647Z,2025-07-17T15:44:09.396030225Z,160,2,1108,C,A,14.910000000,100,0,301746969,0,165422,253384731,ARL,0,14.91,100,0,165422,253384731,9.55,1700,17,9.68,100,1,10.61,200,2,11.27,100,1,11.4,100,1,11.76,100,1,11.93,200,2,12.23,100,1,12.34,200,2,12.36,200,2,13.76,15,1,13.77,100,1,13.81,115,2,14.07,2,1,14.1,100,1,14.4,100,1,14.56,900,3,14.6,700,1,14.64,100,1,14.66,200,2,ARL,301746969
2025-07-17T15:44:09.396195647Z,2025-07-17T15:44:09.396030225Z,160,2,1108,A,A,14.840000000,100,0,302205537,130,165422,253384731,ARL,0,14.84,100,130,165422,253384731,9.55,1700,17,9.68,100,1,10.61,200,2,11.27,100,1,11.4,100,1,11.76,100,1,11.93,200,2,12.23,100,1,12.34,200,2,12.36,200,2,13.76,15,1,13.77,100,1,13.81,115,2,14.07,2,1,14.1,100,1,14.4,100,1,14.56,900,3,14.6,700,1,14.64,100,1,14.66,200,2,ARL,302205537
2025-07-17T15:44:09.398011186Z,2025-07-17T15:44:09.397845986Z,160,2,1108,A,A,13.790000000,100,0,302205561,130,165200,253384788,ARL,0,13.79,100,130,165200,253384788,9.55,1700,17,9.68,100,1,10.61,200,2,11.27,100,1,11.4,100,1,11.76,100,1,11.93,200,2,12.23,100,1,12.34,200,2,12.36,200,2,13.76,15,1,13.77,100,1,13.79,100,1,13.81,115,2,14.07,2,1,14.1,100,1,14.4,100,1,14.56,900,3,14.6,700,1,14.64,100,1,ARL,302205561
2025-07-17T15:44:09.404828956Z,2025-07-17T15:44:09.404663816Z,160,2,1108,C,A,13.810000000,100,0,302100649,130,165140,253385013,ARL,0,13.81,100,130,165140,253385013,9.55,1700,17,9.68,100,1,10.61,200,2,11.27,100,1,11.4,100,1,11.76,100,1,11.93,200,2,12.23,100,1,12.34,200,2,12.36,200,2,13.76,15,1,13.77,100,1,13.79,100,1,13.81,15,1,14.07,2,1,14.1,100,1,14.4,100,1,14.56,900,3,14.6,700,1,14.64,100,1,ARL,302100649
2025-07-17T15:44:20.402535831Z,2025-07-17T15:44:20.402370565Z,160,2,1108,C,A,13.810000000,15,0,301867541,130,165266,253562230,ARL,0,13.81,15,130,165266,253562230,9.55,1700,17,9.68,100,1,10.61,200,2,11.27,100,1,11.4,100,1,11.76,100,1,11.93,200,2,12.23,100,1,12.34,200,2,12.36,200,2,13.76,15,1,13.77,100,1,13.79,100,1,14.07,2,1,14.1,100,1,14.4,100,1,14.56,900,3,14.6,700,1,14.64,100,1,14.66,200,2,ARL,301867541
2025-07-17T15:44:21.405486122Z,2025-07-17T15:44:21.405320730Z,160,2,1108,A,A,13.740000000,15,0,302458113,130,165392,253582427,ARL,0,13.74,15,130,165392,253582427,9.55,1700,17,9.68,100,1,10.61,200,2,11.27,100,1,11.4,100,1,11.76,100,1,11.93,200,2,12.23,100,1,12.34,200,2,12.36,200,2,13.74,15,1,13.76,15,1,13.77,100,1,13.79,100,1,14.07,2,1,14.1,100,1,14.4,100,1,14.56,900,3,14.6,700,1,14.64,100,1,ARL,302458113
2025-07-17T15:44:21.843235911Z,2025-07-17T15:44:21.843070079Z,160,2,1108,C,A,13.770000000,100,0,302205493,0,165832,253590641,ARL,0,13.77,100,0,165832,253590641,9.55,1700,17,9.68,100,1,10.61,200,2,11.27,100,1,11.4,100,1,11.76,100,1,11.93,200,2,12.23,100,1,12.34,200,2,12.36,200,2,13.74,15,1,13.76,15,1,13.79,100,1,14.07,2,1,14.1,100,1,14.4,100,1,14.56,900,3,14.6,700,1,14.64,100,1,14.66,200,2,ARL,302205493
2025-07-17T15:44:21.843235911Z,2025-07-17T15:44:21.843070079Z,160,2,1108,A,A,13.750000000,100,0,302466045,130,165832,253590641,ARL,0,13.75,100,130,165832,253590641,9.55,1700,17,9.68,100,1,10.61,200,2,11.27,100,1,11.4,100,1,11.76,100,1,11.93,200,2,12.23,100,1,12.34,200,2,12.36,200,2,13.74,15,1,13.75,100,1,13.76,15,1,13.79,100,1,14.07,2,1,14.1,100,1,14.4,100,1,14.56,900,3,14.6,700,1,14.64,100,1,ARL,302466045
2025-07-17T15:44:21.855416093Z,2025-07-17T15:44:21.855250804Z,160,2,1108,C,A,14.100000000,100,0,301886057,130,165289,253590837,ARL,0,14.1,100,130,165289,253590837,9.55,1700,17,9.68,100,1,10.61,200,2,11.27,100,1,11.4,100,1,11.76,100,1,11.93,200,2,12.23,100,1,12.34,200,2,12.36,200,2,13.74,15,1,13.75,100,1,13.76,15,1,13.79,100,1,14.07,2,1,14.4,100,1,14.56,900,3,14.6,700,1,14.64,100,1,14.66,200,2,ARL,301886057
2025-07-17T15:44:21.855471158Z,2025-07-17T15:44:21.855305995Z,160,2,1108,A,A,14.030000000,100,0,302466157,130,165163,253590838,ARL,0,14.03,100,130,165163,253590838,9.55,1700,17,9.68,100,1,10.61,200,2,11.27,100,1,11.4,100,1,11.76,100,1,11.93,200,2,12.23,100,1,12.34,200,2,12.36,200,2,13.74,15,1,13.75,100,1,13.76,15,1,13.79,100,1,14.03,100,1,14.07,2,1,14.4,100,1,14.56,900,3,14.6,700,1,14.64,100,1,ARL,302466157
2025-07-17T15:44:24.447075532Z,2025-07-17T15:44:24.446910206Z,160,2,1108,A,A,13.770000000,100,0,302500469,130,165326,253614407,ARL,0,13.77,100,130,165326,253614407,9.55,1700,17,9.68,100,1,10.61,200,2,11.27,100,1,11.4,100,1,11.76,100,1,11.93,200,2,12.23,100,1,12.34,200,2,12.36,200,2,13.74,15,1,13.75,100,1,13.76,15,1,13.77,100,1,13.79,100,1,14.03,100,1,14.07,2,1,14.4,100,1,14.56,900,3,14.6,700,1,ARL,302500469
2025-07-17T15:44:24.465555818Z,2025-07-17T15:44:24.465390625Z,160,2,1108,C,A,13.790000000,100,0,302205561,130,165193,253614591,ARL,0,13.79,100,130,165193,253614591,9.55,1700,17,9.68,100,1,10.61,200,2,11.27,100,1,11.4,100,1,11.76,100,1,11.93,200,2,12.23,100,1,12.34,200,2,12.36,200,2,13.74,15,1,13.75,100,1,13.76,15,1,13.77,100,1,14.03,100,1,14.07,2,1,14.4,100,1,14.56,900,3,14.6,700,1,14.64,100,1,ARL,302205561
2025-07-17T15:44:30.846822983Z,2025-07-17T15:44:30.846657613Z,160,2,1108,C,A,13.760000000,15,0,302205249,130,165370,253704439,ARL,0,13.76,15,130,165370,253704439,9.55,1700,17,9.68,100,1,10.61,200,2,11.27,100,1,11.4,100,1,11.76,100,1,11.93,200,2,12.23,100,1,12.34,200,2,12.36,200,2,13.74,15,1,13.75,100,1,13.77,100,1,14.03,100,1,14.07,2,1,14.4,100,1,14.56,900,3,14.6,700,1,14.64,100,1,14.66,200,2,ARL,302205249
2025-07-17T15:44:31.849784693Z,2025-07-17T15:44:31.849618640Z,160,2,1108,A,A,13.720000000,15,0,302649021,130,166053,253721156,ARL,0,13.72,15,130,166053,253721156,9.55,1700,17,9.68,100,1,10.61,200,2,11.27,100,1,11.4,100,1,11.76,100,1,11.93,200,2,12.23,100,1,12.34,200,2,12.36,200,2,13.72,15,1,13.74,15,1,13.75,100,1,13.77,100,1,14.03,100,1,14.07,2,1,14.4,100,1,14.56,900,3,14.6,700,1,14.64,100,1,ARL,302649021
2025-07-17T15:44:31.849921857Z,2025-07-17T15:44:31.849756452Z,160,2,1108,A,A,13.750000000,100,0,302649029,130,165405,253721157,ARL,0,13.75,100,130,165405,253721157,9.55,1700,17,9.68,100,1,10.61,200,2,11.27,100,1,11.4,100,1,11.76,100,1,11.93,200,2,12.23,100,1,12.34,200,2,12.36,200,2,13.72,15,1,13.74,15,1,13.75,200,2,13.77,100,1,14.03,100,1,14.07,2,1,14.4,100,1,14.56,900,3,14.6,700,1,14.64,100,1,ARL,302649029
2025-07-17T15:44:31.910124978Z,2025-07-17T15:44:31.909959614Z,160,2,1108,C,A,13.770000000,100,0,302500469,130,165364,253722140,ARL,0,13.77,100,130,165364,253722140,9.55,1700,17,9.68,100,1,10.61,200,2,11.27,100,1,11.4,100,1,11.76,100,1,11.93,200,2,12.23,100,1,12.34,200,2,12.36,200,2,13.72,15,1,13.74,15,1,13.75,200,2,14.03,100,1,14.07,2,1,14.4,100,1,14.56,900,3,14.6,700,1,14.64,100,1,14.66,200,2,ARL,302500469
2025-07-17T15:44:32.484497230Z,2025-07-17T15:44:32.484331764Z,160,2,1108,C,A,13.750000000,100,0,302466045,0,165466,253730877,ARL,0,13.75,100,0,165466,253730877,9.55,1700,17,9.68,100,1,10.61,200,2,11.27,100,1,11.4,100,1,11.76,100,1,11.93,200,2,12.23,100,1,12.34,200,2,12.36,200,2,13.72,15,1,13.74,15,1,13.75,100,1,14.03,100,1,14.07,2,1,14.4,100,1,14.56,900,3,14.6,700,1,14.64,100,1,14.66,200,2,ARL,302466045
2025-07-17T15:44:32.484497230Z,2025-07-17T15:44:32.484331764Z,160,2,1108,A,A,13.730000000,100,0,302662769,130,165466,253730877,ARL,0,13.73,100,130,165466,253730877,9.55,1700,17,9.68,100,1,10.61,200,2,11.27,100,1,11.4,100,1,11.76,100,1,11.93,200,2,12.23,100,1,12.34,200,2,12.36,200,2,13.72,15,1,13.73,100,1,13.74,15,1,13.75,100,1,14.03,100,1,14.07,2,1,14.4,100,1,14.56,900,3,14.6,700,1,14.64,100,1,ARL,302662769
2025-07-17T15:44:32.485238209Z,2025-07-17T15:44:32.485072552Z,160,2,1108,C,A,14.840000000,100,0,302205537,0,165657,253730907,ARL,0,14.84,100,0,165657,253730907,9.55,1700,17,9.68,100,1,10.61,200,2,11.27,100,1,11.4,100,1,11.76,100,1,11.93,200,2,12.23,100,1,12.34,200,2,12.36,200,2,13.72,15,1,13.73,100,1,13.74,15,1,13.75,100,1,14.03,100,1,14.07,2,1,14.4,100,1,14.56,900,3,14.6,700,1,14.64,100,1,ARL,302205537
2025-07-17T15:44:32.485238209Z,2025-07-17T15:44:32.485072552Z,160,2,1108,A,A,14.790000000,100,0,302662821,130,165657,253730907,ARL,0,14.79,100,130,165657,253730907,9.55,1700,17,9.68,100,1,10.61,200,2,11.27,100,1,11.4,100,1,11.76,100,1,11.93,200,2,12.23,100,1,12.34,200,2,12.36,200,2,13.72,15,1,13.73,100,1,13.74,15,1,13.75,100,1,14.03,100,1,14.07,2,1,14.4,100,1,14.56,900,3,14.6,700,1,14.64,100,1,ARL,302662821
2025-07-17T15:44:33.389387814Z,2025-07-17T15:44:33.389222513Z,160,2,1108,A,A,14.280000000,100,0,302681357,130,165301,253745665,ARL,0,14.28,100,130,165301,253745665,9.55,1700,17,9.68,100,1,10.61,200,2,11.27,100,1,11.4,100,1,11.76,100,1,11.93,200,2,12.23,100,1,12.34,200,2,12.36,200,2,13.72,15,1,13.73,100,1,13.74,15,1,13.75,100,1,14.03,100,1,14.07,2,1,14.28,100,1,14.4,100,1,14.56,900,3,14.6,700,1,ARL,302681357
2025-07-17T15:44:33.389389030Z,2025-07-17T15:44:33.389223581Z,160,2,1108,C,A,14.560000000,100,0,146960005,130,165449,253745666,ARL,0,14.56,100,130,165449,253745666,9.55,1700,17,9.68,100,1,10.61,200,2,11.27,100,1,11.4,100,1,11.76,100,1,11.93,200,2,12.23,100,1,12.34,200,2,12.36,200,2,13.72,15,1,13.73,100,1,13.74,15,1,13.75,100,1,14.03,100,1,14.07,2,1,14.28,100,1,14.4,100,1,14.56,800,2,14.6,700,1,ARL,146960005
2025-07-17T15:44:36.362187673Z,2025-07-17T15:44:36.362022168Z,160,2,1108,C,A,13.740000000,15,0,302458113,130,165505,253783635,ARL,0,13.74,15,130,165505,253783635,9.55,1700,17,9.68,100,1,10.61,200,2,11.27,100,1,11.4,100,1,11.76,100,1,11.93,200,2,12.23,100,1,12.34,200,2,12.36,200,2,13.72,15,1,13.73,100,1,13.75,100,1,14.03,100,1,14.07,2,1,14.28,100,1,14.4,100,1,14.56,800,2,14.6,700,1,14.64,100,1,ARL,302458113
2025-07-17T15:44:37.364377419Z,2025-07-17T15:44:37.364212109Z,160,2,1108,A,A,13.700000000,15,0,302750929,130,165310,253797506,ARL,0,13.7,15,130,165310,253797506,9.55,1700,17,9.68,100,1,10.61,200,2,11.27,100,1,11.4,100,1,11.76,100,1,11.93,200,2,12.23,100,1,12.34,200,2,12.36,200,2,13.7,15,1,13.72,15,1,13.73,100,1,13.75,100,1,14.03,100,1,14.07,2,1,14.28,100,1,14.4,100,1,14.56,800,2,14.6,700,1,ARL,302750929
2025-07-17T15:44:37.364519067Z,2025-07-17T15:44:37.364353897Z,160,2,1108,A,A,13.730000000,100,0,302750937,130,165170,253797510,ARL,0,13.73,100,130,165170,253797510,9.55,1700,17,9.68,100,1,10.61,200,2,11.27,100,1,11.4,100,1,11.76,100,1,11.93,200,2,12.23,100,1,12.34,200,2,12.36,200,2,13.7,15,1,13.72,15,1,13.73,200,2,13.75,100,1,14.03,100,1,14.07,2,1,14.28,100,1,14.4,100,1,14.56,800,2,14.6,700,1,ARL,302750937
2025-07-17T15:44:37.458119494Z,2025-07-17T15:44:37.457954350Z,160,2,1108,C,A,13.750000000,100,0,302649029,130,165144,253798432,ARL,0,13.75,100,130,165144,253798432,9.55,1700,17,9.68,100,1,10.61,200,2,11.27,100,1,11.4,100,1,11.76,100,1,11.93,200,2,12.23,100,1,12.34,200,2,12.36,200,2,13.7,15,1,13.72,15,1,13.73,200,2,14.03,100,1,14.07,2,1,14.28,100,1,14.4,100,1,14.56,800,2,14.6,700,1,14.64,100,1,ARL,302649029
2025-07-17T15:44:38.432460509Z,2025-07-17T15:44:38.432294362Z,160,2,1108,C,A,13.730000000,100,0,302662769,0,166147,253807786,ARL,0,13.73,100,0,166147,253807786,9.55,1700,17,9.68,100,1,10.61,200,2,11.27,100,1,11.4,100,1,11.76,100,1,11.93,200,2,12.23,100,1,12.34,200,2,12.36,200,2,13.7,15,1,13.72,15,1,13.73,100,1,14.03,100,1,14.07,2,1,14.28,100,1,14.4,100,1,14.56,800,2,14.6,700,1,14.64,100,1,ARL,302662769
2025-07-17T15:44:38.432460509Z,2025-07-17T15:44:38.432294362Z,160,2,1108,A,A,13.710000000,100,0,302763889,130,166147,253807786,ARL,0,13.71,100,130,166147,253807786,9.55,1700,17,9.68,100,1,10.61,200,2,11.27,100,1,11.4,100,1,11.76,100,1,11.93,200,2,12.23,100,1,12.34,200,2,12.36,200,2,13.7,15,1,13.71,100,1,13.72,15,1,13.73,100,1,14.03,100,1,14.07,2,1,14.28,100,1,14.4,100,1,14.56,800,2,14.6,700,1,ARL,302763889
2025-07-17T15:44:38.439253975Z,2025-07-17T15:44:38.439088042Z,160,2,1108,C,A,15.920000000,100,0,301747301,0,165933,253808105,ARL,0,15.92,100,0,165933,253808105,9.55,1700,17,9.68,100,1,10.61,200,2,11.27,100,1,11.4,100,1,11.76,100,1,11.93,200,2,12.23,100,1,12.34,200,2,12.36,200,2,13.7,15,1,13.71,100,1,13.72,15,1,13.73,100,1,14.03,100,1,14.07,2,1,14.28,100,1,14.4,100,1,14.56,800,2,14.6,700,1,ARL,301747301
2025-07-17T15:44:38.439253975Z,2025-07-17T15:44:38.439088042Z,160,2,1108,A,A,15.770000000,100,0,302764121,130,165933,253808105,ARL,0,15.77,100,130,165933,253808105,9.55,1700,17,9.68,100,1,10.61,200,2,11.27,100,1,11.4,100,1,11.76,100,1,11.93,200,2,12.23,100,1,12.34,200,2,12.36,200,2,13.7,15,1,13.71,100,1,13.72,15,1,13.73,100,1,14.03,100,1,14.07,2,1,14.28,100,1,14.4,100,1,14.56,800,2,14.6,700,1,ARL,302764121
2025-07-17T15:44:38.440321697Z,2025-07-17T15:44:38.440156077Z,160,2,1108,C,A,17.580000000,100,0,301747261,0,165620,253808122,ARL,0,17.58,100,0,165620,253808122,9.55,1700,17,9.68,100,1,10.61,200,2,11.27,100,1,11.4,100,1,11.76,100,1,11.93,200,2,12.23,100,1,12.34,200,2,12.36,200,2,13.7,15,1,13.71,100,1,13.72,15,1,13.73,100,1,14.03,100,1,14.07,2,1,14.28,100,1,14.4,100,1,14.56,800,2,14.6,700,1,ARL,301747261
2025-07-17T15:44:38.440321697Z,2025-07-17T15:44:38.440156077Z,160,2,1108,A,A,17.420000000,100,0,302764137,130,165620,253808122,ARL,0,17.42,100,130,165620,253808122,9.55,1700,17,9.68,100,1,10.61,200,2,11.27,100,1,11.4,100,1,11.76,100,1,11.93,200,2,12.23,100,1,12.34,200,2,12.36,200,2,13.7,15,1,13.71,100,1,13.72,15,1,13.73,100,1,14.03,100,1,14.07,2,1,14.28,100,1,14.4,100,1,14.56,800,2,14.6,700,1,ARL,302764137
2025-07-17T15:44:43.019262217Z,2025-07-17T15:44:43.019083502Z,160,2,1108,C,A,13.700000000,15,0,302750929,128,178715,253875920,ARL,0,13.7,15,128,178715,253875920,9.55,1700,17,9.68,100,1,10.61,200,2,11.27,100,1,11.4,100,1,11.76,100,1,11.93,200,2,12.23,100,1,12.34,200,2,12.36,200,2,13.71,100,1,13.72,15,1,13.73,100,1,14.03,100,1,14.07,2,1,14.28,100,1,14.4,100,1,14.56,800,2,14.6,700,1,14.64,100,1,ARL,302750929
2025-07-17T15:44:43.019352658Z,2025-07-17T15:44:43.019184132Z,160,2,1108,C,A,13.720000000,15,0,302649021,128,168526,253876010,ARL,0,13.72,15,128,168526,253876010,9.55,1700,17,9.68,100,1,10.61,200,2,11.27,100,1,11.4,100,1,11.76,100,1,11.93,200,2,12.23,100,1,12.34,200,2,12.36,200,2,13.71,100,1,13.73,100,1,14.03,100,1,14.07,2,1,14.28,100,1,14.4,100,1,14.56,800,2,14.6,700,1,14.64,100,1,14.66,200,2,ARL,302649021
2025-07-17T15:44:44.076009999Z,2025-07-17T15:44:44.075843113Z,160,2,1108,A,A,13.700000000,15,0,302867209,128,166886,253892869,ARL,0,13.7,15,128,166886,253892869,9.55,1700,17,9.68,100,1,10.61,200,2,11.27,100,1,11.4,100,1,11.76,100,1,11.93,200,2,12.23,100,1,12.34,200,2,12.36,200,2,13.7,15,1,13.71,100,1,13.73,100,1,14.03,100,1,14.07,2,1,14.28,100,1,14.4,100,1,14.56,800,2,14.6,700,1,14.64,100,1,ARL,302867209
2025-07-17T15:44:44.781630732Z,2025-07-17T15:44:44.781464821Z,160,2,1108,C,A,13.700000000,15,0,302867209,130,165911,253901222,ARL,0,13.7,15,130,165911,253901222,9.55,1700,17,9.68,100,1,10.61,200,2,11.27,100,1,11.4,100,1,11.76,100,1,11.93,200,2,12.23,100,1,12.34,200,2,12.36,200,2,13.71,100,1,13.73,100,1,14.03,100,1,14.07,2,1,14.28,100,1,14.4,100,1,14.56,800,2,14.6,700,1,14.64,100,1,14.66,200,2,ARL,302867209
2025-07-17T15:44:53.143249270Z,2025-07-17T15:44:53.143083969Z,160,2,1108,C,A,13.730000000,100,0,302750937,130,165301,254011871,ARL,0,13.73,100,130,165301,254011871,9.55,1700,17,9.68,100,1,10.61,200,2,11.27,100,1,11.4,100,1,11.76,100,1,11.93,200,2,12.23,100,1,12.34,200,2,12.36,200,2,13.71,100,1,14.03,100,1,14.07,2,1,14.28,100,1,14.4,100,1,14.56,800,2,14.6,700,1,14.64,100,1,14.66,200,2,14.68,1400,2,ARL,302750937
2025-07-17T15:44:57.191188470Z,2025-07-17T15:44:57.191023026Z,160,2,1108,A,A,13.750000000,100,0,303118785,130,165444,254079162,ARL,0,13.75,100,130,165444,254079162,9.55,1700,17,9.68,100,1,10.61,200,2,11.27,100,1,11.4,100,1,11.76,100,1,11.93,200,2,12.23,100,1,12.34,200,2,12.36,200,2,13.71,100,1,13.75,100,1,14.03,100,1,14.07,2,1,14.28,100,1,14.4,100,1,14.56,800,2,14.6,700,1,14.64,100,1,14.66,200,2,ARL,303118785
2025-07-17T15:45:07.065756574Z,2025-07-17T15:45:07.065587919Z,160,2,1108,C,A,13.710000000,100,0,302763889,128,168655,254244597,ARL,0,13.71,100,128,168655,254244597,9.55,1700,17,9.68,100,1,10.61,200,2,11.27,100,1,11.4,100,1,11.76,100,1,11.93,200,2,12.23,100,1,12.34,200,2,12.36,200,2,13.75,100,1,14.03,100,1,14.07,2,1,14.28,100,1,14.4,100,1,14.56,800,2,14.6,700,1,14.64,100,1,14.66,200,2,14.68,1400,2,ARL,302763889
2025-07-17T15:45:07.080131505Z,2025-07-17T15:45:07.079966224Z,160,2,1108,C,A,13.750000000,100,0,303118785,130,165281,254245492,ARL,0,13.75,100,130,165281,254245492,9.55,1700,17,9.68,100,1,10.61,200,2,11.27,100,1,11.4,100,1,11.76,100,1,11.93,200,2,12.23,100,1,12.34,200,2,12.36,200,2,14.03,100,1,14.07,2,1,14.28,100,1,14.4,100,1,14.56,800,2,14.6,700,1,14.64,100,1,14.66,200,2,14.68,1400,2,14.79,100,1,ARL,303118785
2025-07-17T15:45:07.080687215Z,2025-07-17T15:45:07.080521807Z,160,2,1108,C,A,14.660000000,100,0,302205289,0,165408,254245505,ARL,0,14.66,100,0,165408,254245505,9.55,1700,17,9.68,100,1,10.61,200,2,11.27,100,1,11.4,100,1,11.76,100,1,11.93,200,2,12.23,100,1,12.34,200,2,12.36,200,2,14.03,100,1,14.07,2,1,14.28,100,1,14.4,100,1,14.56,800,2,14.6,700,1,14.64,100,1,14.66,100,1,14.68,1400,2,14.79,100,1,ARL,302205289
2025-07-17T15:45:07.080687215Z,2025-07-17T15:45:07.080521807Z,160,2,1108,A,A,14.890000000,100,0,303330477,130,165408,254245505,ARL,0,14.89,100,130,165408,254245505,9.55,1700,17,9.68,100,1,10.61,200,2,11.27,100,1,11.4,100,1,11.76,100,1,11.93,200,2,12.23,100,1,12.34,200,2,12.36,200,2,14.03,100,1,14.07,2,1,14.28,100,1,14.4,100,1,14.56,800,2,14.6,700,1,14.64,100,1,14.66,100,1,14.68,1400,2,14.79,100,1,ARL,303330477
2025-07-17T15:45:07.080872245Z,2025-07-17T15:45:07.080706110Z,160,2,1108,C,A,14.790000000,100,0,302662821,0,166135,254245511,ARL,0,14.79,100,0,166135,254245511,9.55,1700,17,9.68,100,1,10.61,200,2,11.27,100,1,11.4,100,1,11.76,100,1,11.93,200,2,12.23,100,1,12.34,200,2,12.36,200,2,14.03,100,1,14.07,2,1,14.28,100,1,14.4,100,1,14.56,800,2,14.6,700,1,14.64,100,1,14.66,100,1,14.68,1400,2,14.81,200,2,ARL,302662821
2025-07-17T15:45:07.080872245Z,2025-07-17T15:45:07.080706110Z,160,2,1108,A,A,15.060000000,100,0,303330485,130,166135,254245511,ARL,0,15.06,100,130,166135,254245511,9.55,1700,17,9.68,100,1,10.61,200,2,11.27,100,1,11.4,100,1,11.76,100,1,11.93,200,2,12.23,100,1,12.34,200,2,12.36,200,2,14.03,100,1,14.07,2,1,14.28,100,1,14.4,100,1,14.56,800,2,14.6,700,1,14.64,100,1,14.66,100,1,14.68,1400,2,14.81,200,2,ARL,303330485
2025-07-17T15:45:07.081578064Z,2025-07-17T15:45:07.081407507Z,160,2,1108,C,A,14.810000000,100,0,301747001,0,170557,254245568,ARL,0,14.81,100,0,170557,254245568,9.55,1700,17,9.68,100,1,10.61,200,2,11.27,100,1,11.4,100,1,11.76,100,1,11.93,200,2,12.23,100,1,12.34,200,2,12.36,200,2,14.03,100,1,14.07,2,1,14.28,100,1,14.4,100,1,14.56,800,2,14.6,700,1,14.64,100,1,14.66,100,1,14.68,1400,2,14.81,100,1,ARL,301747001
2025-07-17T15:45:07.081578064Z,2025-07-17T15:45:07.081407507Z,160,2,1108,A,A,14.960000000,100,0,303330509,128,170557,254245568,ARL,0,14.96,100,128,170557,254245568,9.55,1700,17,9.68,100,1,10.61,200,2,11.27,100,1,11.4,100,1,11.76,100,1,11.93,200,2,12.23,100,1,12.34,200,2,12.36,200,2,14.03,100,1,14.07,2,1,14.28,100,1,14.4,100,1,14.56,800,2,14.6,700,1,14.64,100,1,14.66,100,1,14.68,1400,2,14.81,100,1,ARL,303330509
2025-07-17T15:45:07.081607970Z,2025-07-17T15:45:07.081441134Z,160,2,1108,C,A,14.660000000,100,0,302205309,0,166836,254245576,ARL,0,14.66,100,0,166836,254245576,9.55,1700,17,9.68,100,1,10.61,200,2,11.27,100,1,11.4,100,1,11.76,100,1,11.93,200,2,12.23,100,1,12.34,200,2,12.36,200,2,14.03,100,1,14.07,2,1,14.28,100,1,14.4,100,1,14.56,800,2,14.6,700,1,14.64,100,1,14.68,1400,2,14.81,100,1,14.89,100,1,ARL,302205309
2025-07-17T15:45:07.081607970Z,2025-07-17T15:45:07.081441134Z,160,2,1108,A,A,14.890000000,100,0,303330521,130,166836,254245576,ARL,0,14.89,100,130,166836,254245576,9.55,1700,17,9.68,100,1,10.61,200,2,11.27,100,1,11.4,100,1,11.76,100,1,11.93,200,2,12.23,100,1,12.34,200,2,12.36,200,2,14.03,100,1,14.07,2,1,14.28,100,1,14.4,100,1,14.56,800,2,14.6,700,1,14.64,100,1,14.68,1400,2,14.81,100,1,14.89,200,2,ARL,303330521
2025-07-17T15:45:07.083898999Z,2025-07-17T15:45:07.083732443Z,160,2,1108,C,A,17.420000000,100,0,302764137,0,166556,254246327,ARL,0,17.42,100,0,166556,254246327,9.55,1700,17,9.68,100,1,10.61,200,2,11.27,100,1,11.4,100,1,11.76,100,1,11.93,200,2,12.23,100,1,12.34,200,2,12.36,200,2,14.03,100,1,14.07,2,1,14.28,100,1,14.4,100,1,14.56,800,2,14.6,700,1,14.64,100,1,14.68,1400,2,14.81,100,1,14.89,200,2,ARL,302764137
2025-07-17T15:45:07.083898999Z,2025-07-17T15:45:07.083732443Z,160,2,1108,A,A,17.760000000,100,0,303331309,130,166556,254246327,ARL,0,17.76,100,130,166556,254246327,9.55,1700,17,9.68,100,1,10.61,200,2,11.27,100,1,11.4,100,1,11.76,100,1,11.93,200,2,12.23,100,1,12.34,200,2,12.36,200,2,14.03,100,1,14.07,2,1,14.28,100,1,14.4,100,1,14.56,800,2,14.6,700,1,14.64,100,1,14.68,1400,2,14.81,100,1,14.89,200,2,ARL,303331309
2025-07-17T15:45:07.085222525Z,2025-07-17T15:45:07.085057258Z,160,2,1108,C,A,14.030000000,100,0,302466157,130,165267,254246434,ARL,0,14.03,100,130,165267,254246434,9.55,1700,17,9.68,100,1,10.61,200,2,11.27,100,1,11.4,100,1,11.76,100,1,11.93,200,2,12.23,100,1,12.34,200,2,12.36,200,2,14.07,2,1,14.28,100,1,14.4,100,1,14.56,800,2,14.6,700,1,14.64,100,1,14.68,1400,2,14.81,100,1,14.89,200,2,14.96,100,1,ARL,302466157
2025-07-17T15:45:07.085274852Z,2025-07-17T15:45:07.085109545Z,160,2,1108,A,A,14.260000000,100,0,303331401,130,165307,254246437,ARL,0,14.26,100,130,165307,254246437,9.55,1700,17,9.68,100,1,10.61,200,2,11.27,100,1,11.4,100,1,11.76,100,1,11.93,200,2,12.23,100,1,12.34,200,2,12.36,200,2,14.07,2,1,14.26,100,1,14.28,100,1,14.4,100,1,14.56,800,2,14.6,700,1,14.64,100,1,14.68,1400,2,14.81,100,1,14.89,200,2,ARL,303331401
2025-07-17T15:45:07.086534700Z,2025-07-17T15:45:07.086368957Z,160,2,1108,C,A,14.640000000,100,0,301747005,130,165743,254246501,ARL,0,14.64,100,130,165743,254246501,9.55,1700,17,9.68,100,1,10.61,200,2,11.27,100,1,11.4,100,1,11.76,100,1,11.93,200,2,12.23,100,1,12.34,200,2,12.36,200,2,14.07,2,1,14.26,100,1,14.28,100,1,14.4,100,1,14.56,800,2,14.6,700,1,14.68,1400,2,14.81,100,1,14.89,200,2,14.96,100,1,ARL,301747005
2025-07-17T15:45:07.086660325Z,2025-07-17T15:45:07.086494745Z,160,2,1108,A,A,14.780000000,100,0,303331425,130,165580,254246502,ARL,0,14.78,100,130,165580,254246502,9.55,1700,17,9.68,100,1,10.61,200,2,11.27,100,1,11.4,100,1,11.76,100,1,11.93,200,2,12.23,100,1,12.34,200,2,12.36,200,2,14.07,2,1,14.26,100,1,14.28,100,1,14.4,100,1,14.56,800,2,14.6,700,1,14.68,1400,2,14.78,100,1,14.81,100,1,14.89,200,2,ARL,303331425
2025-07-17T15:45:07.087389466Z,2025-07-17T15:45:07.087223859Z,160,2,1108,C,A,15.770000000,100,0,302764121,0,165607,254246529,ARL,0,15.77,100,0,165607,254246529,9.55,1700,17,9.68,100,1,10.61,200,2,11.27,100,1,11.4,100,1,11.76,100,1,11.93,200,2,12.23,100,1,12.34,200,2,12.36,200,2,14.07,2,1,14.26,100,1,14.28,100,1,14.4,100,1,14.56,800,2,14.6,700,1,14.68,1400,2,14.78,100,1,14.81,100,1,14.89,200,2,ARL,302764121
2025-07-17T15:45:07.087389466Z,2025-07-17T15:45:07.087223859Z,160,2,1108,A,A,16.080000000,100,0,303331429,130,165607,254246529,ARL,0,16.08,100,130,165607,254246529,9.55,1700,17,9.68,100,1,10.61,200,2,11.27,100,1,11.4,100,1,11.76,100,1,11.93,200,2,12.23,100,1,12.34,200,2,12.36,200,2,14.07,2,1,14.26,100,1,14.28,100,1,14.4,100,1,14.56,800,2,14.6,700,1,14.68,1400,2,14.78,100,1,14.81,100,1,14.89,200,2,ARL,303331429
2025-07-17T15:45:07.133978488Z,2025-07-17T15:45:07.133812895Z,160,2,1108,C,A,14.810000000,100,0,301747957,0,165593,254250625,ARL,0,14.81,100,0,165593,254250625,9.55,1700,17,9.68,100,1,10.61,200,2,11.27,100,1,11.4,100,1,11.76,100,1,11.93,200,2,12.23,100,1,12.34,200,2,12.36,200,2,14.07,2,1,14.26,100,1,14.28,100,1,14.4,100,1,14.56,800,2,14.6,700,1,14.68,1400,2,14.78,100,1,14.89,200,2,14.96,100,1,ARL,301747957
2025-07-17T15:45:07.133978488Z,2025-07-17T15:45:07.133812895Z,160,2,1108,A,A,14.960000000,100,0,303334253,130,165593,254250625,ARL,0,14.96,100,130,165593,254250625,9.55,1700,17,9.68,100,1,10.61,200,2,11.27,100,1,11.4,100,1,11.76,100,1,11.93,200,2,12.23,100,1,12.34,200,2,12.36,200,2,14.07,2,1,14.26,100,1,14.28,100,1,14.4,100,1,14.56,800,2,14.6,700,1,14.68,1400,2,14.78,100,1,14.89,200,2,14.96,200,2,ARL,303334253
2025-07-17T15:45:07.469961302Z,2025-07-17T15:45:07.469796155Z,160,2,1108,A,A,14.080000000,100,0,303340405,130,165147,254258029,ARL,0,14.08,100,130,165147,254258029,9.55,1700,17,9.68,100,1,10.61,200,2,11.27,100,1,11.4,100,1,11.76,100,1,11.93,200,2,12.23,100,1,12.34,200,2,12.36,200,2,14.07,2,1,14.08,100,1,14.26,100,1,14.28,100,1,14.4,100,1,14.56,800,2,14.6,700,1,14.68,1400,2,14.78,100,1,14.89,200,2,ARL,303340405
2025-07-17T15:45:08.094768552Z,2025-07-17T15:45:08.094603115Z,160,2,1108,C,A,14.890000000,100,0,303330521,0,165437,254266885,ARL,0,14.89,100,0,165437,254266885,9.55,1700,17,9.68,100,1,10.61,200,2,11.27,100,1,11.4,100,1,11.76,100,1,11.93,200,2,12.23,100,1,12.34,200,2,12.36,200,2,14.07,2,1,14.08,100,1,14.26,100,1,14.28,100,1,14.4,100,1,14.56,800,2,14.6,700,1,14.68,1400,2,14.78,100,1,14.89,100,1,ARL,303330521
2025-07-17T15:45:08.094768552Z,2025-07-17T15:45:08.094603115Z,160,2,1108,A,A,15.100000000,100,0,303349309,130,165437,254266885,ARL,0,15.1,100,130,165437,254266885,9.55,1700,17,9.68,100,1,10.61,200,2,11.27,100,1,11.4,100,1,11.76,100,1,11.93,200,2,12.23,100,1,12.34,200,2,12.36,200,2,14.07,2,1,14.08,100,1,14.26,100,1,14.28,100,1,14.4,100,1,14.56,800,2,14.6,700,1,14.68,1400,2,14.78,100,1,14.89,100,1,ARL,303349309
2025-07-17T15:45:08.103306644Z,2025-07-17T15:45:08.103141155Z,160,2,1108,C,A,14.890000000,100,0,303330477,0,165489,254266971,ARL,0,14.89,100,0,165489,254266971,9.55,1700,17,9.68,100,1,10.61,200,2,11.27,100,1,11.4,100,1,11.76,100,1,11.93,200,2,12.23,100,1,12.34,200,2,12.36,200,2,14.07,2,1,14.08,100,1,14.26,100,1,14.28,100,1,14.4,100,1,14.56,800,2,14.6,700,1,14.68,1400,2,14.78,100,1,14.96,200,2,ARL,303330477
2025-07-17T15:45:08.103306644Z,2025-07-17T15:45:08.103141155Z,160,2,1108,A,A,15.100000000,100,0,303349377,130,165489,254266971,ARL,0,15.1,100,130,165489,254266971,9.55,1700,17,9.68,100,1,10.61,200,2,11.27,100,1,11.4,100,1,11.76,100,1,11.93,200,2,12.23,100,1,12.34,200,2,12.36,200,2,14.07,2,1,14.08,100,1,14.26,100,1,14.28,100,1,14.4,100,1,14.56,800,2,14.6,700,1,14.68,1400,2,14.78,100,1,14.96,200,2,ARL,303349377
2025-07-17T15:45:24.187008278Z,2025-07-17T15:45:24.186842413Z,160,2,1108,C,A,15.100000000,100,0,303349309,0,165865,254547413,ARL,0,15.1,100,0,165865,254547413,9.55,1700,17,9.68,100,1,10.61,200,2,11.27,100,1,11.4,100,1,11.76,100,1,11.93,200,2,12.23,100,1,12.34,200,2,12.36,200,2,14.07,2,1,14.08,100,1,14.26,100,1,14.28,100,1,14.4,100,1,14.56,800,2,14.6,700,1,14.68,1400,2,14.78,100,1,14.96,200,2,ARL,303349309
2025-07-17T15:45:24.187008278Z,2025-07-17T15:45:24.186842413Z,160,2,1108,A,A,14.880000000,100,0,303682385,130,165865,254547413,ARL,0,14.88,100,130,165865,254547413,9.55,1700,17,9.68,100,1,10.61,200,2,11.27,100,1,11.4,100,1,11.76,100,1,11.93,200,2,12.23,100,1,12.34,200,2,12.36,200,2,14.07,2,1,14.08,100,1,14.26,100,1,14.28,100,1,14.4,100,1,14.56,800,2,14.6,700,1,14.68,1400,2,14.78,100,1,14.88,100,1,ARL,303682385
2025-07-17T15:45:24.187441892Z,2025-07-17T15:45:24.187276389Z,160,2,1108,C,A,15.100000000,100,0,303349377,0,165503,254547415,ARL,0,15.1,100,0,165503,254547415,9.55,1700,17,9.68,100,1,10.61,200,2,11.27,100,1,11.4,100,1,11.76,100,1,11.93,200,2,12.23,100,1,12.34,200,2,12.36,200,2,14.07,2,1,14.08,100,1,14.26,100,1,14.28,100,1,14.4,100,1,14.56,800,2,14.6,700,1,14.68,1400,2,14.78,100,1,14.88,100,1,ARL,303349377
2025-07-17T15:45:24.187441892Z,2025-07-17T15:45:24.187276389Z,160,2,1108,A,A,14.880000000,100,0,303682389,130,165503,254547415,ARL,0,14.88,100,130,165503,254547415,9.55,1700,17,9.68,100,1,10.61,200,2,11.27,100,1,11.4,100,1,11.76,100,1,11.93,200,2,12.23,100,1,12.34,200,2,12.36,200,2,14.07,2,1,14.08,100,1,14.26,100,1,14.28,100,1,14.4,100,1,14.56,800,2,14.6,700,1,14.68,1400,2,14.78,100,1,14.88,200,2,ARL,303682389
2025-07-17T15:45:37.509454888Z,2025-07-17T15:45:37.509289536Z,160,2,1108,A,A,13.940000000,15,0,304056997,130,165352,254851462,ARL,0,13.94,15,130,165352,254851462,9.55,1700,17,9.68,100,1,10.61,200,2,11.27,100,1,11.4,100,1,11.76,100,1,11.93,200,2,12.23,100,1,12.34,200,2,12.36,200,2,13.94,15,1,14.07,2,1,14.08,100,1,14.26,100,1,14.28,100,1,14.4,100,1,14.56,800,2,14.6,700,1,14.68,1400,2,14.78,100,1,ARL,304056997
2025-07-17T15:45:37.998133497Z,2025-07-17T15:45:37.997967775Z,160,2,1108,C,A,14.080000000,100,0,303340405,0,165722,254864588,ARL,0,14.08,100,0,165722,254864588,9.55,1700,17,9.68,100,1,10.61,200,2,11.27,100,1,11.4,100,1,11.76,100,1,11.93,200,2,12.23,100,1,12.34,200,2,12.36,200,2,13.94,15,1,14.07,2,1,14.26,100,1,14.28,100,1,14.4,100,1,14.56,800,2,14.6,700,1,14.68,1400,2,14.78,100,1,14.88,200,2,ARL,303340405
2025-07-17T15:45:37.998133497Z,2025-07-17T15:45:37.997967775Z,160,2,1108,A,A,13.950000000,100,0,304072245,130,165722,254864588,ARL,0,13.95,100,130,165722,254864588,9.55,1700,17,9.68,100,1,10.61,200,2,11.27,100,1,11.4,100,1,11.76,100,1,11.93,200,2,12.23,100,1,12.34,200,2,12.36,200,2,13.94,15,1,13.95,100,1,14.07,2,1,14.26,100,1,14.28,100,1,14.4,100,1,14.56,800,2,14.6,700,1,14.68,1400,2,14.78,100,1,ARL,304072245
2025-07-17T15:45:44.700593408Z,2025-07-17T15:45:44.700428155Z,160,2,1108,A,A,13.890000000,15,0,304238913,130,165253,254999429,ARL,0,13.89,15,130,165253,254999429,9.55,1700,17,9.68,100,1,10.61,200,2,11.27,100,1,11.4,100,1,11.76,100,1,11.93,200,2,12.23,100,1,12.34,200,2,12.36,200,2,13.89,15,1,13.94,15,1,13.95,100,1,14.07,2,1,14.26,100,1,14.28,100,1,14.4,100,1,14.56,800,2,14.6,700,1,14.68,1400,2,ARL,304238913
2025-07-17T15:45:45.262537122Z,2025-07-17T15:45:45.262371701Z,160,2,1108,C,A,13.950000000,100,0,304072245,0,165421,255010979,ARL,0,13.95,100,0,165421,255010979,9.55,1700,17,9.68,100,1,10.61,200,2,11.27,100,1,11.4,100,1,11.76,100,1,11.93,200,2,12.23,100,1,12.34,200,2,12.36,200,2,13.89,15,1,13.94,15,1,14.07,2,1,14.26,100,1,14.28,100,1,14.4,100,1,14.56,800,2,14.6,700,1,14.68,1400,2,14.78,100,1,ARL,304072245
2025-07-17T15:45:45.262537122Z,2025-07-17T15:45:45.262371701Z,160,2,1108,A,A,13.900000000,100,0,304252313,130,165421,255010979,ARL,0,13.9,100,130,165421,255010979,9.55,1700,17,9.68,100,1,10.61,200,2,11.27,100,1,11.4,100,1,11.76,100,1,11.93,200,2,12.23,100,1,12.34,200,2,12.36,200,2,13.89,15,1,13.9,100,1,13.94,15,1,14.07,2,1,14.26,100,1,14.28,100,1,14.4,100,1,14.56,800,2,14.6,700,1,14.68,1400,2,ARL,304252313
2025-07-17T15:45:45.263289023Z,2025-07-17T15:45:45.263123432Z,160,2,1108,C,A,15.060000000,100,0,303330485,0,165591,255010987,ARL,0,15.06,100,0,165591,255010987,9.55,1700,17,9.68,100,1,10.61,200,2,11.27,100,1,11.4,100,1,11.76,100,1,11.93,200,2,12.23,100,1,12.34,200,2,12.36,200,2,13.89,15,1,13.9,100,1,13.94,15,1,14.07,2,1,14.26,100,1,14.28,100,1,14.4,100,1,14.56,800,2,14.6,700,1,14.68,1400,2,ARL,303330485
2025-07-17T15:45:45.263289023Z,2025-07-17T15:45:45.263123432Z,160,2,1108,A,A,14.980000000,100,0,304252333,130,165591,255010987,ARL,0,14.98,100,130,165591,255010987,9.55,1700,17,9.68,100,1,10.61,200,2,11.27,100,1,11.4,100,1,11.76,100,1,11.93,200,2,12.23,100,1,12.34,200,2,12.36,200,2,13.89,15,1,13.9,100,1,13.94,15,1,14.07,2,1,14.26,100,1,14.28,100,1,14.4,100,1,14.56,800,2,14.6,700,1,14.68,1400,2,ARL,304252333
2025-07-17T15:45:45.274360382Z,2025-07-17T15:45:45.274194870Z,160,2,1108,C,A,14.260000000,100,0,303331401,130,165512,255011158,ARL,0,14.26,100,130,165512,255011158,9.55,1700,17,9.68,100,1,10.61,200,2,11.27,100,1,11.4,100,1,11.76,100,1,11.93,200,2,12.23,100,1,12.34,200,2,12.36,200,2,13.89,15,1,13.9,100,1,13.94,15,1,14.07,2,1,14.28,100,1,14.4,100,1,14.56,800,2,14.6,700,1,14.68,1400,2,14.78,100,1,ARL,303331401
2025-07-17T15:45:45.274410721Z,2025-07-17T15:45:45.274245387Z,160,2,1108,A,A,14.180000000,100,0,304252469,130,165334,255011161,ARL,0,14.18,100,130,165334,255011161,9.55,1700,17,9.68,100,1,10.61,200,2,11.27,100,1,11.4,100,1,11.76,100,1,11.93,200,2,12.23,100,1,12.34,200,2,12.36,200,2,13.89,15,1,13.9,100,1,13.94,15,1,14.07,2,1,14.18,100,1,14.28,100,1,14.4,100,1,14.56,800,2,14.6,700,1,14.68,1400,2,ARL,304252469
2025-07-17T15:45:58.419783333Z,2025-07-17T15:45:58.419617935Z,160,2,1108,C,A,13.940000000,15,0,304056997,130,165398,255183198,ARL,0,13.94,15,130,165398,255183198,9.55,1700,17,9.68,100,1,10.61,200,2,11.27,100,1,11.4,100,1,11.76,100,1,11.93,200,2,12.23,100,1,12.34,200,2,12.36,200,2,13.89,15,1,13.9,100,1,14.07,2,1,14.18,100,1,14.28,100,1,14.4,100,1,14.56,800,2,14.6,700,1,14.68,1400,2,14.78,100,1,ARL,304056997
2025-07-17T15:45:58.420278691Z,2025-07-17T15:45:58.420113307Z,160,2,1108,C,A,14.880000000,100,0,303682389,0,165384,255183203,ARL,0,14.88,100,0,165384,255183203,9.55,1700,17,9.68,100,1,10.61,200,2,11.27,100,1,11.4,100,1,11.76,100,1,11.93,200,2,12.23,100,1,12.34,200,2,12.36,200,2,13.89,15,1,13.9,100,1,14.07,2,1,14.18,100,1,14.28,100,1,14.4,100,1,14.56,800,2,14.6,700,1,14.68,1400,2,14.78,100,1,ARL,303682389
2025-07-17T15:45:58.420278691Z,2025-07-17T15:45:58.420113307Z,160,2,1108,A,A,14.770000000,100,0,304503585,130,165384,255183203,ARL,0,14.77,100,130,165384,255183203,9.55,1700,17,9.68,100,1,10.61,200,2,11.27,100,1,11.4,100,1,11.76,100,1,11.93,200,2,12.23,100,1,12.34,200,2,12.36,200,2,13.89,15,1,13.9,100,1,14.07,2,1,14.18,100,1,14.28,100,1,14.4,100,1,14.56,800,2,14.6,700,1,14.68,1400,2,14.77,100,1,ARL,304503585
2025-07-17T15:45:58.420755889Z,2025-07-17T15:45:58.420590199Z,160,2,1108,C,A,14.880000000,100,0,303682385,0,165690,255183204,ARL,0,14.88,100,0,165690,255183204,9.55,1700,17,9.68,100,1,10.61,200,2,11.27,100,1,11.4,100,1,11.76,100,1,11.93,200,2,12.23,100,1,12.34,200,2,12.36,200,2,13.89,15,1,13.9,100,1,14.07,2,1,14.18,100,1,14.28,100,1,14.4,100,1,14.56,800,2,14.6,700,1,14.68,1400,2,14.77,100,1,ARL,303682385
2025-07-17T15:45:58.420755889Z,2025-07-17T15:45:58.420590199Z,160,2,1108,A,A,14.770000000,100,0,304503593,130,165690,255183204,ARL,0,14.77,100,130,165690,255183204,9.55,1700,17,9.68,100,1,10.61,200,2,11.27,100,1,11.4,100,1,11.76,100,1,11.93,200,2,12.23,100,1,12.34,200,2,12.36,200,2,13.89,15,1,13.9,100,1,14.07,2,1,14.18,100,1,14.28,100,1,14.4,100,1,14.56,800,2,14.6,700,1,14.68,1400,2,14.77,200,2,ARL,304503593
2025-07-17T15:45:58.782892109Z,2025-07-17T15:45:58.782726994Z,160,2,1108,C,A,13.890000000,15,0,304238913,130,165115,255189425,ARL,0,13.89,15,130,165115,255189425,9.55,1700,17,9.68,100,1,10.61,200,2,11.27,100,1,11.4,100,1,11.76,100,1,11.93,200,2,12.23,100,1,12.34,200,2,12.36,200,2,13.9,100,1,14.07,2,1,14.18,100,1,14.28,100,1,14.4,100,1,14.56,800,2,14.6,700,1,14.68,1400,2,14.77,200,2,14.78,100,1,ARL,304238913
2025-07-17T15:46:16.783057616Z,2025-07-17T15:46:16.782892334Z,160,2,1108,A,A,13.880000000,15,0,304949689,130,165282,255552962,ARL,0,13.88,15,130,165282,255552962,9.55,1700,17,9.68,100,1,10.61,200,2,11.27,100,1,11.4,100,1,11.76,100,1,11.93,200,2,12.23,100,1,12.34,200,2,12.36,200,2,13.88,15,1,13.9,100,1,14.07,2,1,14.18,100,1,14.28,100,1,14.4,100,1,14.56,800,2,14.6,700,1,14.68,1400,2,14.77,200,2,ARL,304949689
2025-07-17T15:46:16.783326241Z,2025-07-17T15:46:16.783160795Z,160,2,1108,C,A,13.900000000,100,0,304252313,0,165446,255552970,ARL,0,13.9,100,0,165446,255552970,9.55,1700,17,9.68,100,1,10.61,200,2,11.27,100,1,11.4,100,1,11.76,100,1,11.93,200,2,12.23,100,1,12.34,200,2,12.36,200,2,13.88,15,1,14.07,2,1,14.18,100,1,14.28,100,1,14.4,100,1,14.56,800,2,14.6,700,1,14.68,1400,2,14.77,200,2,14.78,100,1,ARL,304252313
2025-07-17T15:46:16.783326241Z,2025-07-17T15:46:16.783160795Z,160,2,1108,A,A,13.890000000,100,0,304949697,130,165446,255552970,ARL,0,13.89,100,130,165446,255552970,9.55,1700,17,9.68,100,1,10.61,200,2,11.27,100,1,11.4,100,1,11.76,100,1,11.93,200,2,12.23,100,1,12.34,200,2,12.36,200,2,13.88,15,1,13.89,100,1,14.07,2,1,14.18,100,1,14.28,100,1,14.4,100,1,14.56,800,2,14.6,700,1,14.68,1400,2,14.77,200,2,ARL,304949697
2025-07-17T15:46:18.782897570Z,2025-07-17T15:46:18.782732218Z,160,2,1108,C,A,13.880000000,15,0,304949689,130,165352,255587336,ARL,0,13.88,15,130,165352,255587336,9.55,1700,17,9.68,100,1,10.61,200,2,11.27,100,1,11.4,100,1,11.76,100,1,11.93,200,2,12.23,100,1,12.34,200,2,12.36,200,2,13.89,100,1,14.07,2,1,14.18,100,1,14.28,100,1,14.4,100,1,14.56,800,2,14.6,700,1,14.68,1400,2,14.77,200,2,14.78,100,1,ARL,304949689
2025-07-17T15:46:28.474166897Z,2025-07-17T15:46:28.474001551Z,160,2,1108,C,A,13.890000000,100,0,304949697,130,165346,255746167,ARL,0,13.89,100,130,165346,255746167,9.55,1700,17,9.68,100,1,10.61,200,2,11.27,100,1,11.4,100,1,11.76,100,1,11.93,200,2,12.23,100,1,12.34,200,2,12.36,200,2,14.07,2,1,14.18,100,1,14.28,100,1,14.4,100,1,14.56,800,2,14.6,700,1,14.68,1400,2,14.77,200,2,14.78,100,1,14.96,200,2,ARL,304949697
2025-07-17T15:46:28.474726594Z,2025-07-17T15:46:28.474561156Z,160,2,1108,C,A,14.770000000,100,0,304503593,0,165438,255746173,ARL,0,14.77,100,0,165438,255746173,9.55,1700,17,9.68,100,1,10.61,200,2,11.27,100,1,11.4,100,1,11.76,100,1,11.93,200,2,12.23,100,1,12.34,200,2,12.36,200,2,14.07,2,1,14.18,100,1,14.28,100,1,14.4,100,1,14.56,800,2,14.6,700,1,14.68,1400,2,14.77,100,1,14.78,100,1,14.96,200,2,ARL,304503593
2025-07-17T15:46:28.474726594Z,2025-07-17T15:46:28.474561156Z,160,2,1108,A,A,14.880000000,100,0,305184937,130,165438,255746173,ARL,0,14.88,100,130,165438,255746173,9.55,1700,17,9.68,100,1,10.61,200,2,11.27,100,1,11.4,100,1,11.76,100,1,11.93,200,2,12.23,100,1,12.34,200,2,12.36,200,2,14.07,2,1,14.18,100,1,14.28,100,1,14.4,100,1,14.56,800,2,14.6,700,1,14.68,1400,2,14.77,100,1,14.78,100,1,14.88,100,1,ARL,305184937
2025-07-17T15:46:28.474896460Z,2025-07-17T15:46:28.474730225Z,160,2,1108,C,A,14.770000000,100,0,304503585,0,166235,255746176,ARL,0,14.77,100,0,166235,255746176,9.55,1700,17,9.68,100,1,10.61,200,2,11.27,100,1,11.4,100,1,11.76,100,1,11.93,200,2,12.23,100,1,12.34,200,2,12.36,200,2,14.07,2,1,14.18,100,1,14.28,100,1,14.4,100,1,14.56,800,2,14.6,700,1,14.68,1400,2,14.78,100,1,14.88,100,1,14.96,200,2,ARL,304503585
2025-07-17T15:46:28.474896460Z,2025-07-17T15:46:28.474730225Z,160,2,1108,A,A,14.880000000,100,0,305184953,130,166235,255746176,ARL,0,14.88,100,130,166235,255746176,9.55,1700,17,9.68,100,1,10.61,200,2,11.27,100,1,11.4,100,1,11.76,100,1,11.93,200,2,12.23,100,1,12.34,200,2,12.36,200,2,14.07,2,1,14.18,100,1,14.28,100,1,14.4,100,1,14.56,800,2,14.6,700,1,14.68,1400,2,14.78,100,1,14.88,200,2,14.96,200,2,ARL,305184953
2025-07-17T15:46:28.474902154Z,2025-07-17T15:46:28.474736101Z,160,2,1108,C,A,14.980000000,100,0,304252333,0,166053,255746178,ARL,0,14.98,100,0,166053,255746178,9.55,1700,17,9.68,100,1,10.61,200,2,11.27,100,1,11.4,100,1,11.76,100,1,11.93,200,2,12.23,100,1,12.34,200,2,12.36,200,2,14.07,2,1,14.18,100,1,14.28,100,1,14.4,100,1,14.56,800,2,14.6,700,1,14.68,1400,2,14.78,100,1,14.88,200,2,14.96,200,2,ARL,304252333
2025-07-17T15:46:28.474902154Z,2025-07-17T15:46:28.474736101Z,160,2,1108,A,A,15.030000000,100,0,305184957,128,166053,255746178,ARL,0,15.03,100,128,166053,255746178,9.55,1700,17,9.68,100,1,10.61,200,2,11.27,100,1,11.4,100,1,11.76,100,1,11.93,200,2,12.23,100,1,12.34,200,2,12.36,200,2,14.07,2,1,14.18,100,1,14.28,100,1,14.4,100,1,14.56,800,2,14.6,700,1,14.68,1400,2,14.78,100,1,14.88,200,2,14.96,200,2,ARL,305184957
2025-07-17T15:46:28.492881980Z,2025-07-17T15:46:28.492716775Z,160,2,1108,C,A,14.180000000,100,0,304252469,130,165205,255746619,ARL,0,14.18,100,130,165205,255746619,9.55,1700,17,9.68,100,1,10.61,200,2,11.27,100,1,11.4,100,1,11.76,100,1,11.93,200,2,12.23,100,1,12.34,200,2,12.36,200,2,14.07,2,1,14.28,100,1,14.4,100,1,14.56,800,2,14.6,700,1,14.68,1400,2,14.78,100,1,14.88,200,2,14.96,200,2,15.03,100,1,ARL,304252469
2025-07-17T15:46:28.492931279Z,2025-07-17T15:46:28.492765859Z,160,2,1108,A,A,14.260000000,100,0,305185529,130,165420,255746621,ARL,0,14.26,100,130,165420,255746621,9.55,1700,17,9.68,100,1,10.61,200,2,11.27,100,1,11.4,100,1,11.76,100,1,11.93,200,2,12.23,100,1,12.34,200,2,12.36,200,2,14.07,2,1,14.26,100,1,14.28,100,1,14.4,100,1,14.56,800,2,14.6,700,1,14.68,1400,2,14.78,100,1,14.88,200,2,14.96,200,2,ARL,305185529
2025-07-17T15:46:28.646273467Z,2025-07-17T15:46:28.646108242Z,160,2,1108,A,A,14.080000000,100,0,305187077,130,165225,255748568,ARL,0,14.08,100,130,165225,255748568,9.55,1700,17,9.68,100,1,10.61,200,2,11.27,100,1,11.4,100,1,11.76,100,1,11.93,200,2,12.23,100,1,12.34,200,2,12.36,200,2,14.07,2,1,14.08,100,1,14.26,100,1,14.28,100,1,14.4,100,1,14.56,800,2,14.6,700,1,14.68,1400,2,14.78,100,1,14.88,200,2,ARL,305187077
2025-07-17T15:46:57.524024658Z,2025-07-17T15:46:57.523859388Z,160,2,1108,A,A,13.920000000,15,0,305862145,130,165270,256268482,ARL,0,13.92,15,130,165270,256268482,9.55,1700,17,9.68,100,1,10.61,200,2,11.27,100,1,11.4,100,1,11.76,100,1,11.93,200,2,12.23,100,1,12.34,200,2,12.36,200,2,13.92,15,1,14.07,2,1,14.08,100,1,14.26,100,1,14.28,100,1,14.4,100,1,14.56,800,2,14.6,700,1,14.68,1400,2,14.78,100,1,ARL,305862145
2025-07-17T15:46:57.932842994Z,2025-07-17T15:46:57.932677299Z,160,2,1108,C,A,14.080000000,100,0,305187077,0,165695,256280751,ARL,0,14.08,100,0,165695,256280751,9.55,1700,17,9.68,100,1,10.61,200,2,11.27,100,1,11.4,100,1,11.76,100,1,11.93,200,2,12.23,100,1,12.34,200,2,12.36,200,2,13.92,15,1,14.07,2,1,14.26,100,1,14.28,100,1,14.4,100,1,14.56,800,2,14.6,700,1,14.68,1400,2,14.78,100,1,14.88,200,2,ARL,305187077
2025-07-17T15:46:57.932842994Z,2025-07-17T15:46:57.932677299Z,160,2,1108,A,A,13.930000000,100,0,305878881,130,165695,256280751,ARL,0,13.93,100,130,165695,256280751,9.55,1700,17,9.68,100,1,10.61,200,2,11.27,100,1,11.4,100,1,11.76,100,1,11.93,200,2,12.23,100,1,12.34,200,2,12.36,200,2,13.92,15,1,13.93,100,1,14.07,2,1,14.26,100,1,14.28,100,1,14.4,100,1,14.56,800,2,14.6,700,1,14.68,1400,2,14.78,100,1,ARL,305878881
2025-07-17T15:47:06.609456251Z,2025-07-17T15:47:06.609290857Z,160,2,1108,A,A,13.880000000,15,0,306121113,130,165394,256488374,ARL,0,13.88,15,130,165394,256488374,9.55,1700,17,9.68,100,1,10.61,200,2,11.27,100,1,11.4,100,1,11.76,100,1,11.93,200,2,12.23,100,1,12.34,200,2,12.36,200,2,13.88,15,1,13.92,15,1,13.93,100,1,14.07,2,1,14.26,100,1,14.28,100,1,14.4,100,1,14.56,800,2,14.6,700,1,14.68,1400,2,ARL,306121113
2025-07-17T15:47:08.787695144Z,2025-07-17T15:47:08.787529505Z,160,2,1108,C,A,13.930000000,100,0,305878881,0,165639,256532991,ARL,0,13.93,100,0,165639,256532991,9.55,1700,17,9.68,100,1,10.61,200,2,11.27,100,1,11.4,100,1,11.76,100,1,11.93,200,2,12.23,100,1,12.34,200,2,12.36,200,2,13.88,15,1,13.92,15,1,14.07,2,1,14.26,100,1,14.28,100,1,14.4,100,1,14.56,800,2,14.6,700,1,14.68,1400,2,14.78,100,1,ARL,305878881
2025-07-17T15:47:08.787695144Z,2025-07-17T15:47:08.787529505Z,160,2,1108,A,A,13.890000000,100,0,306170837,130,165639,256532991,ARL,0,13.89,100,130,165639,256532991,9.55,1700,17,9.68,100,1,10.61,200,2,11.27,100,1,11.4,100,1,11.76,100,1,11.93,200,2,12.23,100,1,12.34,200,2,12.36,200,2,13.88,15,1,13.89,100,1,13.92,15,1,14.07,2,1,14.26,100,1,14.28,100,1,14.4,100,1,14.56,800,2,14.6,700,1,14.68,1400,2,ARL,306170837
2025-07-17T15:47:08.788440762Z,2025-07-17T15:47:08.788275184Z,160,2,1108,C,A,15.030000000,100,0,305184957,0,165578,256533005,ARL,0,15.03,100,0,165578,256533005,9.55,1700,17,9.68,100,1,10.61,200,2,11.27,100,1,11.4,100,1,11.76,100,1,11.93,200,2,12.23,100,1,12.34,200,2,12.36,200,2,13.88,15,1,13.89,100,1,13.92,15,1,14.07,2,1,14.26,100,1,14.28,100,1,14.4,100,1,14.56,800,2,14.6,700,1,14.68,1400,2,ARL,305184957
2025-07-17T15:47:08.788440762Z,2025-07-17T15:47:08.788275184Z,160,2,1108,A,A,14.970000000,100,0,306170869,130,165578,256533005,ARL,0,14.97,100,130,165578,256533005,9.55,1700,17,9.68,100,1,10.61,200,2,11.27,100,1,11.4,100,1,11.76,100,1,11.93,200,2,12.23,100,1,12.34,200,2,12.36,200,2,13.88,15,1,13.89,100,1,13.92,15,1,14.07,2,1,14.26,100,1,14.28,100,1,14.4,100,1,14.56,800,2,14.6,700,1,14.68,1400,2,ARL,306170869
2025-07-17T15:47:08.805983406Z,2025-07-17T15:47:08.805818249Z,160,2,1108,C,A,14.260000000,100,0,305185529,130,165157,256533442,ARL,0,14.26,100,130,165157,256533442,9.55,1700,17,9.68,100,1,10.61,200,2,11.27,100,1,11.4,100,1,11.76,100,1,11.93,200,2,12.23,100,1,12.34,200,2,12.36,200,2,13.88,15,1,13.89,100,1,13.92,15,1,14.07,2,1,14.28,100,1,14.4,100,1,14.56,800,2,14.6,700,1,14.68,1400,2,14.78,100,1,ARL,305185529
2025-07-17T15:47:08.806033773Z,2025-07-17T15:47:08.805868059Z,160,2,1108,A,A,14.170000000,100,0,306171457,130,165714,256533443,ARL,0,14.17,100,130,165714,256533443,9.55,1700,17,9.68,100,1,10.61,200,2,11.27,100,1,11.4,100,1,11.76,100,1,11.93,200,2,12.23,100,1,12.34,200,2,12.36,200,2,13.88,15,1,13.89,100,1,13.92,15,1,14.07,2,1,14.17,100,1,14.28,100,1,14.4,100,1,14.56,800,2,14.6,700,1,14.68,1400,2,ARL,306171457
2025-07-17T15:47:13.121454355Z,2025-07-17T15:47:13.121288953Z,160,2,1108,C,A,13.880000000,15,0,306121113,130,165402,256612694,ARL,0,13.88,15,130,165402,256612694,9.55,1700,17,9.68,100,1,10.61,200,2,11.27,100,1,11.4,100,1,11.76,100,1,11.93,200,2,12.23,100,1,12.34,200,2,12.36,200,2,13.89,100,1,13.92,15,1,14.07,2,1,14.17,100,1,14.28,100,1,14.4,100,1,14.56,800,2,14.6,700,1,14.68,1400,2,14.78,100,1,ARL,306121113
2025-07-17T15:47:13.122562533Z,2025-07-17T15:47:13.122396816Z,160,2,1108,C,A,13.920000000,15,0,305862145,130,165717,256612757,ARL,0,13.92,15,130,165717,256612757,9.55,1700,17,9.68,100,1,10.61,200,2,11.27,100,1,11.4,100,1,11.76,100,1,11.93,200,2,12.23,100,1,12.34,200,2,12.36,200,2,13.89,100,1,14.07,2,1,14.17,100,1,14.28,100,1,14.4,100,1,14.56,800,2,14.6,700,1,14.68,1400,2,14.78,100,1,14.88,200,2,ARL,305862145
2025-07-17T15:47:24.786476266Z,2025-07-17T15:47:24.786310694Z,160,2,1108,A,A,13.870000000,15,0,306519385,130,165572,256812416,ARL,0,13.87,15,130,165572,256812416,9.55,1700,17,9.68,100,1,10.61,200,2,11.27,100,1,11.4,100,1,11.76,100,1,11.93,200,2,12.23,100,1,12.34,200,2,12.36,200,2,13.87,15,1,13.89,100,1,14.07,2,1,14.17,100,1,14.28,100,1,14.4,100,1,14.56,800,2,14.6,700,1,14.68,1400,2,14.78,100,1,ARL,306519385
2025-07-17T15:47:24.786745657Z,2025-07-17T15:47:24.786580061Z,160,2,1108,C,A,13.890000000,100,0,306170837,0,165596,256812420,ARL,0,13.89,100,0,165596,256812420,9.55,1700,17,9.68,100,1,10.61,200,2,11.27,100,1,11.4,100,1,11.76,100,1,11.93,200,2,12.23,100,1,12.34,200,2,12.36,200,2,13.87,15,1,14.07,2,1,14.17,100,1,14.28,100,1,14.4,100,1,14.56,800,2,14.6,700,1,14.68,1400,2,14.78,100,1,14.88,200,2,ARL,306170837
2025-07-17T15:47:24.786745657Z,2025-07-17T15:47:24.786580061Z,160,2,1108,A,A,13.880000000,100,0,306519397,130,165596,256812420,ARL,0,13.88,100,130,165596,256812420,9.55,1700,17,9.68,100,1,10.61,200,2,11.27,100,1,11.4,100,1,11.76,100,1,11.93,200,2,12.23,100,1,12.34,200,2,12.36,200,2,13.87,15,1,13.88,100,1,14.07,2,1,14.17,100,1,14.28,100,1,14.4,100,1,14.56,800,2,14.6,700,1,14.68,1400,2,14.78,100,1,ARL,306519397
2025-07-17T15:47:24.786925729Z,2025-07-17T15:47:24.786759805Z,160,2,1108,C,A,14.880000000,100,0,305184937,0,165924,256812422,ARL,0,14.88,100,0,165924,256812422,9.55,1700,17,9.68,100,1,10.61,200,2,11.27,100,1,11.4,100,1,11.76,100,1,11.93,200,2,12.23,100,1,12.34,200,2,12.36,200,2,13.87,15,1,13.88,100,1,14.07,2,1,14.17,100,1,14.28,100,1,14.4,100,1,14.56,800,2,14.6,700,1,14.68,1400,2,14.78,100,1,ARL,305184937
2025-07-17T15:47:24.786925729Z,2025-07-17T15:47:24.786759805Z,160,2,1108,A,A,14.770000000,100,0,306519409,130,165924,256812422,ARL,0,14.77,100,130,165924,256812422,9.55,1700,17,9.68,100,1,10.61,200,2,11.27,100,1,11.4,100,1,11.76,100,1,11.93,200,2,12.23,100,1,12.34,200,2,12.36,200,2,13.87,15,1,13.88,100,1,14.07,2,1,14.17,100,1,14.28,100,1,14.4,100,1,14.56,800,2,14.6,700,1,14.68,1400,2,14.77,100,1,ARL,306519409
2025-07-17T15:47:24.800616004Z,2025-07-17T15:47:24.800449950Z,160,2,1108,C,A,14.880000000,100,0,305184953,0,166054,256812578,ARL,0,14.88,100,0,166054,256812578,9.55,1700,17,9.68,100,1,10.61,200,2,11.27,100,1,11.4,100,1,11.76,100,1,11.93,200,2,12.23,100,1,12.34,200,2,12.36,200,2,13.87,15,1,13.88,100,1,14.07,2,1,14.17,100,1,14.28,100,1,14.4,100,1,14.56,800,2,14.6,700,1,14.68,1400,2,14.77,100,1,ARL,305184953
2025-07-17T15:47:24.800616004Z,2025-07-17T15:47:24.800449950Z,160,2,1108,A,A,14.750000000,100,0,306519741,130,166054,256812578,ARL,0,14.75,100,130,166054,256812578,9.55,1700,17,9.68,100,1,10.61,200,2,11.27,100,1,11.4,100,1,11.76,100,1,11.93,200,2,12.23,100,1,12.34,200,2,12.36,200,2,13.87,15,1,13.88,100,1,14.07,2,1,14.17,100,1,14.28,100,1,14.4,100,1,14.56,800,2,14.6,700,1,14.68,1400,2,14.75,100,1,ARL,306519741
2025-07-17T15:47:27.860272892Z,2025-07-17T15:47:27.860107552Z,160,2,1108,A,A,13.830000000,15,0,306587393,130,165340,256866835,ARL,0,13.83,15,130,165340,256866835,9.55,1700,17,9.68,100,1,10.61,200,2,11.27,100,1,11.4,100,1,11.76,100,1,11.93,200,2,12.23,100,1,12.34,200,2,12.36,200,2,13.83,15,1,13.87,15,1,13.88,100,1,14.07,2,1,14.17,100,1,14.28,100,1,14.4,100,1,14.56,800,2,14.6,700,1,14.68,1400,2,ARL,306587393
2025-07-17T15:47:31.407029312Z,2025-07-17T15:47:31.406863918Z,160,2,1108,C,A,13.880000000,100,0,306519397,0,165394,256910124,ARL,0,13.88,100,0,165394,256910124,9.55,1700,17,9.68,100,1,10.61,200,2,11.27,100,1,11.4,100,1,11.76,100,1,11.93,200,2,12.23,100,1,12.34,200,2,12.36,200,2,13.83,15,1,13.87,15,1,14.07,2,1,14.17,100,1,14.28,100,1,14.4,100,1,14.56,800,2,14.6,700,1,14.68,1400,2,14.75,100,1,ARL,306519397
2025-07-17T15:47:31.407029312Z,2025-07-17T15:47:31.406863918Z,160,2,1108,A,A,13.840000000,100,0,306647425,130,165394,256910124,ARL,0,13.84,100,130,165394,256910124,9.55,1700,17,9.68,100,1,10.61,200,2,11.27,100,1,11.4,100,1,11.76,100,1,11.93,200,2,12.23,100,1,12.34,200,2,12.36,200,2,13.83,15,1,13.84,100,1,13.87,15,1,14.07,2,1,14.17,100,1,14.28,100,1,14.4,100,1,14.56,800,2,14.6,700,1,14.68,1400,2,ARL,306647425
2025-07-17T15:47:31.407771110Z,2025-07-17T15:47:31.407605685Z,160,2,1108,C,A,14.970000000,100,0,306170869,0,165425,256910129,ARL,0,14.97,100,0,165425,256910129,9.55,1700,17,9.68,100,1,10.61,200,2,11.27,100,1,11.4,100,1,11.76,100,1,11.93,200,2,12.23,100,1,12.34,200,2,12.36,200,2,13.83,15,1,13.84,100,1,13.87,15,1,14.07,2,1,14.17,100,1,14.28,100,1,14.4,100,1,14.56,800,2,14.6,700,1,14.68,1400,2,ARL,306170869
2025-07-17T15:47:31.407771110Z,2025-07-17T15:47:31.407605685Z,160,2,1108,A,A,14.910000000,100,0,306647445,130,165425,256910129,ARL,0,14.91,100,130,165425,256910129,9.55,1700,17,9.68,100,1,10.61,200,2,11.27,100,1,11.4,100,1,11.76,100,1,11.93,200,2,12.23,100,1,12.34,200,2,12.36,200,2,13.83,15,1,13.84,100,1,13.87,15,1,14.07,2,1,14.17,100,1,14.28,100,1,14.4,100,1,14.56,800,2,14.6,700,1,14.68,1400,2,ARL,306647445
2025-07-17T15:47:31.413491477Z,2025-07-17T15:47:31.413325908Z,160,2,1108,C,A,14.780000000,100,0,303331425,0,165569,256910184,ARL,0,14.78,100,0,165569,256910184,9.55,1700,17,9.68,100,1,10.61,200,2,11.27,100,1,11.4,100,1,11.76,100,1,11.93,200,2,12.23,100,1,12.34,200,2,12.36,200,2,13.83,15,1,13.84,100,1,13.87,15,1,14.07,2,1,14.17,100,1,14.28,100,1,14.4,100,1,14.56,800,2,14.6,700,1,14.68,1400,2,ARL,303331425
2025-07-17T15:47:31.413491477Z,2025-07-17T15:47:31.413325908Z,160,2,1108,A,A,14.640000000,100,0,306647521,130,165569,256910184,ARL,0,14.64,100,130,165569,256910184,9.55,1700,17,9.68,100,1,10.61,200,2,11.27,100,1,11.4,100,1,11.76,100,1,11.93,200,2,12.23,100,1,12.34,200,2,12.36,200,2,13.83,15,1,13.84,100,1,13.87,15,1,14.07,2,1,14.17,100,1,14.28,100,1,14.4,100,1,14.56,800,2,14.6,700,1,14.64,100,1,ARL,306647521
2025-07-17T15:47:31.433486283Z,2025-07-17T15:47:31.433320466Z,160,2,1108,C,A,14.960000000,100,0,303330509,0,165817,256910721,ARL,0,14.96,100,0,165817,256910721,9.55,1700,17,9.68,100,1,10.61,200,2,11.27,100,1,11.4,100,1,11.76,100,1,11.93,200,2,12.23,100,1,12.34,200,2,12.36,200,2,13.83,15,1,13.84,100,1,13.87,15,1,14.07,2,1,14.17,100,1,14.28,100,1,14.4,100,1,14.56,800,2,14.6,700,1,14.64,100,1,ARL,303330509
2025-07-17T15:47:31.433486283Z,2025-07-17T15:47:31.433320466Z,160,2,1108,A,A,14.810000000,100,0,306649913,130,165817,256910721,ARL,0,14.81,100,130,165817,256910721,9.55,1700,17,9.68,100,1,10.61,200,2,11.27,100,1,11.4,100,1,11.76,100,1,11.93,200,2,12.23,100,1,12.34,200,2,12.36,200,2,13.83,15,1,13.84,100,1,13.87,15,1,14.07,2,1,14.17,100,1,14.28,100,1,14.4,100,1,14.56,800,2,14.6,700,1,14.64,100,1,ARL,306649913
2025-07-17T15:47:31.574128504Z,2025-07-17T15:47:31.573963059Z,160,2,1108,C,A,16.080000000,100,0,303331429,0,165445,256912087,ARL,0,16.08,100,0,165445,256912087,9.55,1700,17,9.68,100,1,10.61,200,2,11.27,100,1,11.4,100,1,11.76,100,1,11.93,200,2,12.23,100,1,12.34,200,2,12.36,200,2,13.83,15,1,13.84,100,1,13.87,15,1,14.07,2,1,14.17,100,1,14.28,100,1,14.4,100,1,14.56,800,2,14.6,700,1,14.64,100,1,ARL,303331429
2025-07-17T15:47:31.574128504Z,2025-07-17T15:47:31.573963059Z,160,2,1108,A,A,15.920000000,100,0,306652001,130,165445,256912087,ARL,0,15.92,100,130,165445,256912087,9.55,1700,17,9.68,100,1,10.61,200,2,11.27,100,1,11.4,100,1,11.76,100,1,11.93,200,2,12.23,100,1,12.34,200,2,12.36,200,2,13.83,15,1,13.84,100,1,13.87,15,1,14.07,2,1,14.17,100,1,14.28,100,1,14.4,100,1,14.56,800,2,14.6,700,1,14.64,100,1,ARL,306652001
2025-07-17T15:47:31.575374481Z,2025-07-17T15:47:31.575209032Z,160,2,1108,C,A,17.760000000,100,0,303331309,0,165449,256912094,ARL,0,17.76,100,0,165449,256912094,9.55,1700,17,9.68,100,1,10.61,200,2,11.27,100,1,11.4,100,1,11.76,100,1,11.93,200,2,12.23,100,1,12.34,200,2,12.36,200,2,13.83,15,1,13.84,100,1,13.87,15,1,14.07,2,1,14.17,100,1,14.28,100,1,14.4,100,1,14.56,800,2,14.6,700,1,14.64,100,1,ARL,303331309
2025-07-17T15:47:31.575374481Z,2025-07-17T15:47:31.575209032Z,160,2,1108,A,A,17.580000000,100,0,306652017,130,165449,256912094,ARL,0,17.58,100,130,165449,256912094,9.55,1700,17,9.68,100,1,10.61,200,2,11.27,100,1,11.4,100,1,11.76,100,1,11.93,200,2,12.23,100,1,12.34,200,2,12.36,200,2,13.83,15,1,13.84,100,1,13.87,15,1,14.07,2,1,14.17,100,1,14.28,100,1,14.4,100,1,14.56,800,2,14.6,700,1,14.64,100,1,ARL,306652017
2025-07-17T15:47:31.740095714Z,2025-07-17T15:47:31.739930142Z,160,2,1108,C,A,14.960000000,100,0,303334253,0,165572,256914067,ARL,0,14.96,100,0,165572,256914067,9.55,1700,17,9.68,100,1,10.61,200,2,11.27,100,1,11.4,100,1,11.76,100,1,11.93,200,2,12.23,100,1,12.34,200,2,12.36,200,2,13.83,15,1,13.84,100,1,13.87,15,1,14.07,2,1,14.17,100,1,14.28,100,1,14.4,100,1,14.56,800,2,14.6,700,1,14.64,100,1,ARL,303334253
2025-07-17T15:47:31.740095714Z,2025-07-17T15:47:31.739930142Z,160,2,1108,A,A,14.810000000,100,0,306653713,130,165572,256914067,ARL,0,14.81,100,130,165572,256914067,9.55,1700,17,9.68,100,1,10.61,200,2,11.27,100,1,11.4,100,1,11.76,100,1,11.93,200,2,12.23,100,1,12.34,200,2,12.36,200,2,13.83,15,1,13.84,100,1,13.87,15,1,14.07,2,1,14.17,100,1,14.28,100,1,14.4,100,1,14.56,800,2,14.6,700,1,14.64,100,1,ARL,306653713
2025-07-17T15:47:37.159589804Z,2025-07-17T15:47:37.159424166Z,160,2,1108,C,A,13.870000000,15,0,306519385,130,165638,256983942,ARL,0,13.87,15,130,165638,256983942,9.55,1700,17,9.68,100,1,10.61,200,2,11.27,100,1,11.4,100,1,11.76,100,1,11.93,200,2,12.23,100,1,12.34,200,2,12.36,200,2,13.83,15,1,13.84,100,1,14.07,2,1,14.17,100,1,14.28,100,1,14.4,100,1,14.56,800,2,14.6,700,1,14.64,100,1,14.68,1400,2,ARL,306519385
2025-07-17T15:47:37.172000440Z,2025-07-17T15:47:37.171834941Z,160,2,1108,A,A,13.850000000,100,0,306749753,130,165499,256984053,ARL,0,13.85,100,130,165499,256984053,9.55,1700,17,9.68,100,1,10.61,200,2,11.27,100,1,11.4,100,1,11.76,100,1,11.93,200,2,12.23,100,1,12.34,200,2,12.36,200,2,13.83,15,1,13.84,100,1,13.85,100,1,14.07,2,1,14.17,100,1,14.28,100,1,14.4,100,1,14.56,800,2,14.6,700,1,14.64,100,1,ARL,306749753
2025-07-17T15:47:38.161181283Z,2025-07-17T15:47:38.161015969Z,160,2,1108,A,A,13.790000000,15,0,306770041,130,165314,256998606,ARL,0,13.79,15,130,165314,256998606,9.55,1700,17,9.68,100,1,10.61,200,2,11.27,100,1,11.4,100,1,11.76,100,1,11.93,200,2,12.23,100,1,12.34,200,2,12.36,200,2,13.79,15,1,13.83,15,1,13.84,100,1,13.85,100,1,14.07,2,1,14.17,100,1,14.28,100,1,14.4,100,1,14.56,800,2,14.6,700,1,ARL,306770041
2025-07-17T15:47:38.794962245Z,2025-07-17T15:47:38.794795887Z,160,2,1108,C,A,13.840000000,100,0,306647425,0,166358,257010989,ARL,0,13.84,100,0,166358,257010989,9.55,1700,17,9.68,100,1,10.61,200,2,11.27,100,1,11.4,100,1,11.76,100,1,11.93,200,2,12.23,100,1,12.34,200,2,12.36,200,2,13.79,15,1,13.83,15,1,13.85,100,1,14.07,2,1,14.17,100,1,14.28,100,1,14.4,100,1,14.56,800,2,14.6,700,1,14.64,100,1,ARL,306647425
2025-07-17T15:47:38.794962245Z,2025-07-17T15:47:38.794795887Z,160,2,1108,A,A,13.800000000,100,0,306784133,128,166358,257010989,ARL,0,13.8,100,128,166358,257010989,9.55,1700,17,9.68,100,1,10.61,200,2,11.27,100,1,11.4,100,1,11.76,100,1,11.93,200,2,12.23,100,1,12.34,200,2,12.36,200,2,13.79,15,1,13.8,100,1,13.83,15,1,13.85,100,1,14.07,2,1,14.17,100,1,14.28,100,1,14.4,100,1,14.56,800,2,14.6,700,1,ARL,306784133
2025-07-17T15:47:38.795723570Z,2025-07-17T15:47:38.795557785Z,160,2,1108,C,A,14.910000000,100,0,306647445,0,165785,257011058,ARL,0,14.91,100,0,165785,257011058,9.55,1700,17,9.68,100,1,10.61,200,2,11.27,100,1,11.4,100,1,11.76,100,1,11.93,200,2,12.23,100,1,12.34,200,2,12.36,200,2,13.79,15,1,13.8,100,1,13.83,15,1,13.85,100,1,14.07,2,1,14.17,100,1,14.28,100,1,14.4,100,1,14.56,800,2,14.6,700,1,ARL,306647445
2025-07-17T15:47:38.795723570Z,2025-07-17T15:47:38.795557785Z,160,2,1108,A,A,14.870000000,100,0,306784201,130,165785,257011058,ARL,0,14.87,100,130,165785,257011058,9.55,1700,17,9.68,100,1,10.61,200,2,11.27,100,1,11.4,100,1,11.76,100,1,11.93,200,2,12.23,100,1,12.34,200,2,12.36,200,2,13.79,15,1,13.8,100,1,13.83,15,1,13.85,100,1,14.07,2,1,14.17,100,1,14.28,100,1,14.4,100,1,14.56,800,2,14.6,700,1,ARL,306784201
2025-07-17T15:47:38.804624258Z,2025-07-17T15:47:38.804458744Z,160,2,1108,C,A,14.170000000,100,0,306171457,130,165514,257011716,ARL,0,14.17,100,130,165514,257011716,9.55,1700,17,9.68,100,1,10.61,200,2,11.27,100,1,11.4,100,1,11.76,100,1,11.93,200,2,12.23,100,1,12.34,200,2,12.36,200,2,13.79,15,1,13.8,100,1,13.83,15,1,13.85,100,1,14.07,2,1,14.28,100,1,14.4,100,1,14.56,800,2,14.6,700,1,14.64,100,1,ARL,306171457
2025-07-17T15:47:38.804679592Z,2025-07-17T15:47:38.804513793Z,160,2,1108,A,A,14.080000000,100,0,306784853,130,165799,257011717,ARL,0,14.08,100,130,165799,257011717,9.55,1700,17,9.68,100,1,10.61,200,2,11.27,100,1,11.4,100,1,11.76,100,1,11.93,200,2,12.23,100,1,12.34,200,2,12.36,200,2,13.79,15,1,13.8,100,1,13.83,15,1,13.85,100,1,14.07,2,1,14.08,100,1,14.28,100,1,14.4,100,1,14.56,800,2,14.6,700,1,ARL,306784853
2025-07-17T15:47:39.092472059Z,2025-07-17T15:47:39.092305947Z,160,2,1108,C,A,13.790000000,15,0,306770041,130,166112,257018687,ARL,0,13.79,15,130,166112,257018687,9.55,1700,17,9.68,100,1,10.61,200,2,11.27,100,1,11.4,100,1,11.76,100,1,11.93,200,2,12.23,100,1,12.34,200,2,12.36,200,2,13.8,100,1,13.83,15,1,13.85,100,1,14.07,2,1,14.08,100,1,14.28,100,1,14.4,100,1,14.56,800,2,14.6,700,1,14.64,100,1,ARL,306770041
2025-07-17T15:47:39.095920859Z,2025-07-17T15:47:39.095755335Z,160,2,1108,C,A,13.830000000,15,0,306587393,130,165524,257018796,ARL,0,13.83,15,130,165524,257018796,9.55,1700,17,9.68,100,1,10.61,200,2,11.27,100,1,11.4,100,1,11.76,100,1,11.93,200,2,12.23,100,1,12.34,200,2,12.36,200,2,13.8,100,1,13.85,100,1,14.07,2,1,14.08,100,1,14.28,100,1,14.4,100,1,14.56,800,2,14.6,700,1,14.64,100,1,14.68,1400,2,ARL,306587393
2025-07-17T15:48:08.909366905Z,2025-07-17T15:48:08.909201576Z,160,2,1108,A,A,13.830000000,100,0,307567929,130,165329,257603755,ARL,0,13.83,100,130,165329,257603755,9.55,1700,17,9.68,100,1,10.61,200,2,11.27,100,1,11.4,100,1,11.76,100,1,11.93,200,2,12.23,100,1,12.34,200,2,12.36,200,2,13.8,100,1,13.83,100,1,13.85,100,1,14.07,2,1,14.08,100,1,14.28,100,1,14.4,100,1,14.56,800,2,14.6,700,1,14.64,100,1,ARL,307567929
2025-07-17T15:48:08.916721098Z,2025-07-17T15:48:08.916555821Z,160,2,1108,C,A,13.850000000,100,0,306749753,130,165277,257604057,ARL,0,13.85,100,130,165277,257604057,9.55,1700,17,9.68,100,1,10.61,200,2,11.27,100,1,11.4,100,1,11.76,100,1,11.93,200,2,12.23,100,1,12.34,200,2,12.36,200,2,13.8,100,1,13.83,100,1,14.07,2,1,14.08,100,1,14.28,100,1,14.4,100,1,14.56,800,2,14.6,700,1,14.64,100,1,14.68,1400,2,ARL,306749753
2025-07-17T15:48:09.653473465Z,2025-07-17T15:48:09.653308042Z,160,2,1108,A,A,13.780000000,15,0,307587873,130,165423,257621095,ARL,0,13.78,15,130,165423,257621095,9.55,1700,17,9.68,100,1,10.61,200,2,11.27,100,1,11.4,100,1,11.76,100,1,11.93,200,2,12.23,100,1,12.34,200,2,12.36,200,2,13.78,15,1,13.8,100,1,13.83,100,1,14.07,2,1,14.08,100,1,14.28,100,1,14.4,100,1,14.56,800,2,14.6,700,1,14.64,100,1,ARL,307587873
2025-07-17T15:48:11.166689254Z,2025-07-17T15:48:11.166517494Z,160,2,1108,C,A,13.780000000,15,0,307587873,128,171760,257644020,ARL,0,13.78,15,128,171760,257644020,9.55,1700,17,9.68,100,1,10.61,200,2,11.27,100,1,11.4,100,1,11.76,100,1,11.93,200,2,12.23,100,1,12.34,200,2,12.36,200,2,13.8,100,1,13.83,100,1,14.07,2,1,14.08,100,1,14.28,100,1,14.4,100,1,14.56,800,2,14.6,700,1,14.64,100,1,14.68,1400,2,ARL,307587873
2025-07-17T15:48:13.509078553Z,2025-07-17T15:48:13.508913083Z,160,2,1108,A,A,13.780000000,15,0,307714769,130,165470,257727039,ARL,0,13.78,15,130,165470,257727039,9.55,1700,17,9.68,100,1,10.61,200,2,11.27,100,1,11.4,100,1,11.76,100,1,11.93,200,2,12.23,100,1,12.34,200,2,12.36,200,2,13.78,15,1,13.8,100,1,13.83,100,1,14.07,2,1,14.08,100,1,14.28,100,1,14.4,100,1,14.56,800,2,14.6,700,1,14.64,100,1,ARL,307714769
2025-07-17T15:48:13.525953545Z,2025-07-17T15:48:13.525788139Z,160,2,1108,A,A,13.810000000,100,0,307715101,130,165406,257727301,ARL,0,13.81,100,130,165406,257727301,9.55,1700,17,9.68,100,1,10.61,200,2,11.27,100,1,11.4,100,1,11.76,100,1,11.93,200,2,12.23,100,1,12.34,200,2,12.36,200,2,13.78,15,1,13.8,100,1,13.81,100,1,13.83,100,1,14.07,2,1,14.08,100,1,14.28,100,1,14.4,100,1,14.56,800,2,14.6,700,1,ARL,307715101
2025-07-17T15:48:13.532608874Z,2025-07-17T15:48:13.532443045Z,160,2,1108,C,A,13.830000000,100,0,307567929,130,165829,257727457,ARL,0,13.83,100,130,165829,257727457,9.55,1700,17,9.68,100,1,10.61,200,2,11.27,100,1,11.4,100,1,11.76,100,1,11.93,200,2,12.23,100,1,12.34,200,2,12.36,200,2,13.78,15,1,13.8,100,1,13.81,100,1,14.07,2,1,14.08,100,1,14.28,100,1,14.4,100,1,14.56,800,2,14.6,700,1,14.64,100,1,ARL,307567929
2025-07-17T15:48:15.568544154Z,2025-07-17T15:48:15.568378275Z,160,2,1108,C,A,13.800000000,100,0,306784133,0,165879,257757458,ARL,0,13.8,100,0,165879,257757458,9.55,1700,17,9.68,100,1,10.61,200,2,11.27,100,1,11.4,100,1,11.76,100,1,11.93,200,2,12.23,100,1,12.34,200,2,12.36,200,2,13.78,15,1,13.81,100,1,14.07,2,1,14.08,100,1,14.28,100,1,14.4,100,1,14.56,800,2,14.6,700,1,14.64,100,1,14.68,1400,2,ARL,306784133
2025-07-17T15:48:15.568544154Z,2025-07-17T15:48:15.568378275Z,160,2,1108,A,A,13.790000000,100,0,307753241,130,165879,257757458,ARL,0,13.79,100,130,165879,257757458,9.55,1700,17,9.68,100,1,10.61,200,2,11.27,100,1,11.4,100,1,11.76,100,1,11.93,200,2,12.23,100,1,12.34,200,2,12.36,200,2,13.78,15,1,13.79,100,1,13.81,100,1,14.07,2,1,14.08,100,1,14.28,100,1,14.4,100,1,14.56,800,2,14.6,700,1,14.64,100,1,ARL,307753241
2025-07-17T15:48:24.009355346Z,2025-07-17T15:48:24.009190157Z,160,2,1108,A,A,13.750000000,15,0,307964605,130,165189,257928318,ARL,0,13.75,15,130,165189,257928318,9.55,1700,17,9.68,100,1,10.61,200,2,11.27,100,1,11.4,100,1,11.76,100,1,11.93,200,2,12.23,100,1,12.34,200,2,12.36,200,2,13.75,15,1,13.78,15,1,13.79,100,1,13.81,100,1,14.07,2,1,14.08,100,1,14.28,100,1,14.4,100,1,14.56,800,2,14.6,700,1,ARL,307964605
2025-07-17T15:48:24.009522633Z,2025-07-17T15:48:24.009357442Z,160,2,1108,A,A,13.790000000,100,0,307964609,130,165191,257928319,ARL,0,13.79,100,130,165191,257928319,9.55,1700,17,9.68,100,1,10.61,200,2,11.27,100,1,11.4,100,1,11.76,100,1,11.93,200,2,12.23,100,1,12.34,200,2,12.36,200,2,13.75,15,1,13.78,15,1,13.79,200,2,13.81,100,1,14.07,2,1,14.08,100,1,14.28,100,1,14.4,100,1,14.56,800,2,14.6,700,1,ARL,307964609
2025-07-17T15:48:24.009944381Z,2025-07-17T15:48:24.009778967Z,160,2,1108,C,A,13.790000000,100,0,307753241,0,165414,257928325,ARL,0,13.79,100,0,165414,257928325,9.55,1700,17,9.68,100,1,10.61,200,2,11.27,100,1,11.4,100,1,11.76,100,1,11.93,200,2,12.23,100,1,12.34,200,2,12.36,200,2,13.75,15,1,13.78,15,1,13.79,100,1,13.81,100,1,14.07,2,1,14.08,100,1,14.28,100,1,14.4,100,1,14.56,800,2,14.6,700,1,ARL,307753241
2025-07-17T15:48:24.009944381Z,2025-07-17T15:48:24.009778967Z,160,2,1108,A,A,13.760000000,100,0,307964621,130,165414,257928325,ARL,0,13.76,100,130,165414,257928325,9.55,1700,17,9.68,100,1,10.61,200,2,11.27,100,1,11.4,100,1,11.76,100,1,11.93,200,2,12.23,100,1,12.34,200,2,12.36,200,2,13.75,15,1,13.76,100,1,13.78,15,1,13.79,100,1,13.81,100,1,14.07,2,1,14.08,100,1,14.28,100,1,14.4,100,1,14.56,800,2,ARL,307964621
2025-07-17T15:48:24.009974166Z,2025-07-17T15:48:24.009808793Z,160,2,1108,C,A,13.810000000,100,0,307715101,130,165373,257928326,ARL,0,13.81,100,130,165373,257928326,9.55,1700,17,9.68,100,1,10.61,200,2,11.27,100,1,11.4,100,1,11.76,100,1,11.93,200,2,12.23,100,1,12.34,200,2,12.36,200,2,13.75,15,1,13.76,100,1,13.78,15,1,13.79,100,1,14.07,2,1,14.08,100,1,14.28,100,1,14.4,100,1,14.56,800,2,14.6,700,1,ARL,307715101
2025-07-17T15:48:24.010555416Z,2025-07-17T15:48:24.010390029Z,160,2,1108,C,A,14.770000000,100,0,306519409,0,165387,257928333,ARL,0,14.77,100,0,165387,257928333,9.55,1700,17,9.68,100,1,10.61,200,2,11.27,100,1,11.4,100,1,11.76,100,1,11.93,200,2,12.23,100,1,12.34,200,2,12.36,200,2,13.75,15,1,13.76,100,1,13.78,15,1,13.79,100,1,14.07,2,1,14.08,100,1,14.28,100,1,14.4,100,1,14.56,800,2,14.6,700,1,ARL,306519409
2025-07-17T15:48:24.010555416Z,2025-07-17T15:48:24.010390029Z,160,2,1108,A,A,14.650000000,100,0,307964661,130,165387,257928333,ARL,0,14.65,100,130,165387,257928333,9.55,1700,17,9.68,100,1,10.61,200,2,11.27,100,1,11.4,100,1,11.76,100,1,11.93,200,2,12.23,100,1,12.34,200,2,12.36,200,2,13.75,15,1,13.76,100,1,13.78,15,1,13.79,100,1,14.07,2,1,14.08,100,1,14.28,100,1,14.4,100,1,14.56,800,2,14.6,700,1,ARL,307964661
2025-07-17T15:48:24.010677522Z,2025-07-17T15:48:24.010512050Z,160,2,1108,C,A,14.870000000,100,0,306784201,0,165472,257928340,ARL,0,14.87,100,0,165472,257928340,9.55,1700,17,9.68,100,1,10.61,200,2,11.27,100,1,11.4,100,1,11.76,100,1,11.93,200,2,12.23,100,1,12.34,200,2,12.36,200,2,13.75,15,1,13.76,100,1,13.78,15,1,13.79,100,1,14.07,2,1,14.08,100,1,14.28,100,1,14.4,100,1,14.56,800,2,14.6,700,1,ARL,306784201
2025-07-17T15:48:24.010677522Z,2025-07-17T15:48:24.010512050Z,160,2,1108,A,A,14.830000000,100,0,307964665,130,165472,257928340,ARL,0,14.83,100,130,165472,257928340,9.55,1700,17,9.68,100,1,10.61,200,2,11.27,100,1,11.4,100,1,11.76,100,1,11.93,200,2,12.23,100,1,12.34,200,2,12.36,200,2,13.75,15,1,13.76,100,1,13.78,15,1,13.79,100,1,14.07,2,1,14.08,100,1,14.28,100,1,14.4,100,1,14.56,800,2,14.6,700,1,ARL,307964665
2025-07-17T15:48:42.009954046Z,2025-07-17T15:48:42.009788565Z,160,2,1108,C,A,13.780000000,15,0,307714769,130,165481,258199397,ARL,0,13.78,15,130,165481,258199397,9.55,1700,17,9.68,100,1,10.61,200,2,11.27,100,1,11.4,100,1,11.76,100,1,11.93,200,2,12.23,100,1,12.34,200,2,12.36,200,2,13.75,15,1,13.76,100,1,13.79,100,1,14.07,2,1,14.08,100,1,14.28,100,1,14.4,100,1,14.56,800,2,14.6,700,1,14.64,100,1,ARL,307714769
2025-07-17T15:48:42.011846392Z,2025-07-17T15:48:42.011680742Z,160,2,1108,C,A,14.750000000,100,0,306519741,0,165650,258199535,ARL,0,14.75,100,0,165650,258199535,9.55,1700,17,9.68,100,1,10.61,200,2,11.27,100,1,11.4,100,1,11.76,100,1,11.93,200,2,12.23,100,1,12.34,200,2,12.36,200,2,13.75,15,1,13.76,100,1,13.79,100,1,14.07,2,1,14.08,100,1,14.28,100,1,14.4,100,1,14.56,800,2,14.6,700,1,14.64,100,1,ARL,306519741
2025-07-17T15:48:42.011846392Z,2025-07-17T15:48:42.011680742Z,160,2,1108,A,A,14.640000000,100,0,308296381,130,165650,258199535,ARL,0,14.64,100,130,165650,258199535,9.55,1700,17,9.68,100,1,10.61,200,2,11.27,100,1,11.4,100,1,11.76,100,1,11.93,200,2,12.23,100,1,12.34,200,2,12.36,200,2,13.75,15,1,13.76,100,1,13.79,100,1,14.07,2,1,14.08,100,1,14.28,100,1,14.4,100,1,14.56,800,2,14.6,700,1,14.64,200,2,ARL,308296381
2025-07-17T15:48:42.016761374Z,2025-07-17T15:48:42.016595806Z,160,2,1108,A,A,13.770000000,100,0,308296741,130,165568,258199787,ARL,0,13.77,100,130,165568,258199787,9.55,1700,17,9.68,100,1,10.61,200,2,11.27,100,1,11.4,100,1,11.76,100,1,11.93,200,2,12.23,100,1,12.34,200,2,12.36,200,2,13.75,15,1,13.76,100,1,13.77,100,1,13.79,100,1,14.07,2,1,14.08,100,1,14.28,100,1,14.4,100,1,14.56,800,2,14.6,700,1,ARL,308296741
2025-07-17T15:48:42.023432407Z,2025-07-17T15:48:42.023266760Z,160,2,1108,C,A,13.790000000,100,0,307964609,130,165647,258199990,ARL,0,13.79,100,130,165647,258199990,9.55,1700,17,9.68,100,1,10.61,200,2,11.27,100,1,11.4,100,1,11.76,100,1,11.93,200,2,12.23,100,1,12.34,200,2,12.36,200,2,13.75,15,1,13.76,100,1,13.77,100,1,14.07,2,1,14.08,100,1,14.28,100,1,14.4,100,1,14.56,800,2,14.6,700,1,14.64,200,2,ARL,307964609
2025-07-17T15:48:46.750088490Z,2025-07-17T15:48:46.749922127Z,160,2,1108,A,A,13.730000000,15,0,308374537,128,166363,258260871,ARL,0,13.73,15,128,166363,258260871,9.55,1700,17,9.68,100,1,10.61,200,2,11.27,100,1,11.4,100,1,11.76,100,1,11.93,200,2,12.23,100,1,12.34,200,2,12.36,200,2,13.73,15,1,13.75,15,1,13.76,100,1,13.77,100,1,14.07,2,1,14.08,100,1,14.28,100,1,14.4,100,1,14.56,800,2,14.6,700,1,ARL,308374537
2025-07-17T15:48:46.758551033Z,2025-07-17T15:48:46.758385367Z,160,2,1108,C,A,13.760000000,100,0,307964621,0,165666,258261154,ARL,0,13.76,100,0,165666,258261154,9.55,1700,17,9.68,100,1,10.61,200,2,11.27,100,1,11.4,100,1,11.76,100,1,11.93,200,2,12.23,100,1,12.34,200,2,12.36,200,2,13.73,15,1,13.75,15,1,13.77,100,1,14.07,2,1,14.08,100,1,14.28,100,1,14.4,100,1,14.56,800,2,14.6,700,1,14.64,200,2,ARL,307964621
2025-07-17T15:48:46.758551033Z,2025-07-17T15:48:46.758385367Z,160,2,1108,A,A,13.740000000,100,0,308374881,130,165666,258261154,ARL,0,13.74,100,130,165666,258261154,9.55,1700,17,9.68,100,1,10.61,200,2,11.27,100,1,11.4,100,1,11.76,100,1,11.93,200,2,12.23,100,1,12.34,200,2,12.36,200,2,13.73,15,1,13.74,100,1,13.75,15,1,13.77,100,1,14.07,2,1,14.08,100,1,14.28,100,1,14.4,100,1,14.56,800,2,14.6,700,1,ARL,308374881
2025-07-17T15:48:46.773668988Z,2025-07-17T15:48:46.773503306Z,160,2,1108,C,A,14.080000000,100,0,306784853,130,165682,258261538,ARL,0,14.08,100,130,165682,258261538,9.55,1700,17,9.68,100,1,10.61,200,2,11.27,100,1,11.4,100,1,11.76,100,1,11.93,200,2,12.23,100,1,12.34,200,2,12.36,200,2,13.73,15,1,13.74,100,1,13.75,15,1,13.77,100,1,14.07,2,1,14.28,100,1,14.4,100,1,14.56,800,2,14.6,700,1,14.64,200,2,ARL,306784853
2025-07-17T15:48:46.773720726Z,2025-07-17T15:48:46.773555566Z,160,2,1108,A,A,14.010000000,100,0,308375185,130,165160,258261539,ARL,0,14.01,100,130,165160,258261539,9.55,1700,17,9.68,100,1,10.61,200,2,11.27,100,1,11.4,100,1,11.76,100,1,11.93,200,2,12.23,100,1,12.34,200,2,12.36,200,2,13.73,15,1,13.74,100,1,13.75,15,1,13.77,100,1,14.01,100,1,14.07,2,1,14.28,100,1,14.4,100,1,14.56,800,2,14.6,700,1,ARL,308375185
2025-07-17T15:49:02.010494480Z,2025-07-17T15:49:02.010329052Z,160,2,1108,A,A,13.750000000,100,0,308705489,130,165428,258502869,ARL,0,13.75,100,130,165428,258502869,9.55,1700,17,9.68,100,1,10.61,200,2,11.27,100,1,11.4,100,1,11.76,100,1,11.93,200,2,12.23,100,1,12.34,200,2,12.36,200,2,13.73,15,1,13.74,100,1,13.75,115,2,13.77,100,1,14.01,100,1,14.07,2,1,14.28,100,1,14.4,100,1,14.56,800,2,14.6,700,1,ARL,308705489
2025-07-17T15:49:02.019989567Z,2025-07-17T15:49:02.019824230Z,160,2,1108,C,A,13.770000000,100,0,308296741,130,165337,258502929,ARL,0,13.77,100,130,165337,258502929,9.55,1700,17,9.68,100,1,10.61,200,2,11.27,100,1,11.4,100,1,11.76,100,1,11.93,200,2,12.23,100,1,12.34,200,2,12.36,200,2,13.73,15,1,13.74,100,1,13.75,115,2,14.01,100,1,14.07,2,1,14.28,100,1,14.4,100,1,14.56,800,2,14.6,700,1,14.64,200,2,ARL,308296741
2025-07-17T15:49:03.406005590Z,2025-07-17T15:49:03.405840358Z,160,2,1108,C,A,13.750000000,15,0,307964605,130,165232,258527308,ARL,0,13.75,15,130,165232,258527308,9.55,1700,17,9.68,100,1,10.61,200,2,11.27,100,1,11.4,100,1,11.76,100,1,11.93,200,2,12.23,100,1,12.34,200,2,12.36,200,2,13.73,15,1,13.74,100,1,13.75,100,1,14.01,100,1,14.07,2,1,14.28,100,1,14.4,100,1,14.56,800,2,14.6,700,1,14.64,200,2,ARL,307964605
2025-07-17T15:49:04.713997925Z,2025-07-17T15:49:04.713831675Z,160,2,1108,A,A,13.710000000,15,0,308763065,128,166250,258547335,ARL,0,13.71,15,128,166250,258547335,9.55,1700,17,9.68,100,1,10.61,200,2,11.27,100,1,11.4,100,1,11.76,100,1,11.93,200,2,12.23,100,1,12.34,200,2,12.36,200,2,13.71,15,1,13.73,15,1,13.74,100,1,13.75,100,1,14.01,100,1,14.07,2,1,14.28,100,1,14.4,100,1,14.56,800,2,14.6,700,1,ARL,308763065
2025-07-17T15:49:06.013111941Z,2025-07-17T15:49:06.012946379Z,160,2,1108,A,A,13.730000000,100,0,308786185,130,165562,258567259,ARL,0,13.73,100,130,165562,258567259,9.55,1700,17,9.68,100,1,10.61,200,2,11.27,100,1,11.4,100,1,11.76,100,1,11.93,200,2,12.23,100,1,12.34,200,2,12.36,200,2,13.71,15,1,13.73,115,2,13.74,100,1,13.75,100,1,14.01,100,1,14.07,2,1,14.28,100,1,14.4,100,1,14.56,800,2,14.6,700,1,ARL,308786185
2025-07-17T15:49:06.023292147Z,2025-07-17T15:49:06.023126600Z,160,2,1108,C,A,13.750000000,100,0,308705489,130,165547,258567405,ARL,0,13.75,100,130,165547,258567405,9.55,1700,17,9.68,100,1,10.61,200,2,11.27,100,1,11.4,100,1,11.76,100,1,11.93,200,2,12.23,100,1,12.34,200,2,12.36,200,2,13.71,15,1,13.73,115,2,13.74,100,1,14.01,100,1,14.07,2,1,14.28,100,1,14.4,100,1,14.56,800,2,14.6,700,1,14.64,200,2,ARL,308705489
2025-07-17T15:49:06.344356890Z,2025-07-17T15:49:06.344191321Z,160,2,1108,C,A,13.740000000,100,0,308374881,0,165569,258574949,ARL,0,13.74,100,0,165569,258574949,9.55,1700,17,9.68,100,1,10.61,200,2,11.27,100,1,11.4,100,1,11.76,100,1,11.93,200,2,12.23,100,1,12.34,200,2,12.36,200,2,13.71,15,1,13.73,115,2,14.01,100,1,14.07,2,1,14.28,100,1,14.4,100,1,14.56,800,2,14.6,700,1,14.64,200,2,14.65,100,1,ARL,308374881
2025-07-17T15:49:06.344356890Z,2025-07-17T15:49:06.344191321Z,160,2,1108,A,A,13.720000000,100,0,308797069,130,165569,258574949,ARL,0,13.72,100,130,165569,258574949,9.55,1700,17,9.68,100,1,10.61,200,2,11.27,100,1,11.4,100,1,11.76,100,1,11.93,200,2,12.23,100,1,12.34,200,2,12.36,200,2,13.71,15,1,13.72,100,1,13.73,115,2,14.01,100,1,14.07,2,1,14.28,100,1,14.4,100,1,14.56,800,2,14.6,700,1,14.64,200,2,ARL,308797069
2025-07-17T15:49:06.345104491Z,2025-07-17T15:49:06.344938975Z,160,2,1108,C,A,14.830000000,100,0,307964665,0,165516,258575013,ARL,0,14.83,100,0,165516,258575013,9.55,1700,17,9.68,100,1,10.61,200,2,11.27,100,1,11.4,100,1,11.76,100,1,11.93,200,2,12.23,100,1,12.34,200,2,12.36,200,2,13.71,15,1,13.72,100,1,13.73,115,2,14.01,100,1,14.07,2,1,14.28,100,1,14.4,100,1,14.56,800,2,14.6,700,1,14.64,200,2,ARL,307964665
2025-07-17T15:49:06.345104491Z,2025-07-17T15:49:06.344938975Z,160,2,1108,A,A,14.780000000,100,0,308797245,130,165516,258575013,ARL,0,14.78,100,130,165516,258575013,9.55,1700,17,9.68,100,1,10.61,200,2,11.27,100,1,11.4,100,1,11.76,100,1,11.93,200,2,12.23,100,1,12.34,200,2,12.36,200,2,13.71,15,1,13.72,100,1,13.73,115,2,14.01,100,1,14.07,2,1,14.28,100,1,14.4,100,1,14.56,800,2,14.6,700,1,14.64,200,2,ARL,308797245
2025-07-17T15:49:06.362945410Z,2025-07-17T15:49:06.362779870Z,160,2,1108,C,A,17.580000000,100,0,306652017,0,165540,258575963,ARL,0,17.58,100,0,165540,258575963,9.55,1700,17,9.68,100,1,10.61,200,2,11.27,100,1,11.4,100,1,11.76,100,1,11.93,200,2,12.23,100,1,12.34,200,2,12.36,200,2,13.71,15,1,13.72,100,1,13.73,115,2,14.01,100,1,14.07,2,1,14.28,100,1,14.4,100,1,14.56,800,2,14.6,700,1,14.64,200,2,ARL,306652017
2025-07-17T15:49:06.362945410Z,2025-07-17T15:49:06.362779870Z,160,2,1108,A,A,17.430000000,100,0,308799373,130,165540,258575963,ARL,0,17.43,100,130,165540,258575963,9.55,1700,17,9.68,100,1,10.61,200,2,11.27,100,1,11.4,100,1,11.76,100,1,11.93,200,2,12.23,100,1,12.34,200,2,12.36,200,2,13.71,15,1,13.72,100,1,13.73,115,2,14.01,100,1,14.07,2,1,14.28,100,1,14.4,100,1,14.56,800,2,14.6,700,1,14.64,200,2,ARL,308799373
2025-07-17T15:49:10.459317885Z,2025-07-17T15:49:10.459152457Z,160,2,1108,C,A,13.730000000,15,0,308374537,130,165428,258636400,ARL,0,13.73,15,130,165428,258636400,9.55,1700,17,9.68,100,1,10.61,200,2,11.27,100,1,11.4,100,1,11.76,100,1,11.93,200,2,12.23,100,1,12.34,200,2,12.36,200,2,13.71,15,1,13.72,100,1,13.73,100,1,14.01,100,1,14.07,2,1,14.28,100,1,14.4,100,1,14.56,800,2,14.6,700,1,14.64,200,2,ARL,308374537
2025-07-17T15:49:11.460597600Z,2025-07-17T15:49:11.460432218Z,160,2,1108,A,A,13.690000000,15,0,308893737,130,165382,258650544,ARL,0,13.69,15,130,165382,258650544,9.55,1700,17,9.68,100,1,10.61,200,2,11.27,100,1,11.4,100,1,11.76,100,1,11.93,200,2,12.23,100,1,12.34,200,2,12.36,200,2,13.69,15,1,13.71,15,1,13.72,100,1,13.73,100,1,14.01,100,1,14.07,2,1,14.28,100,1,14.4,100,1,14.56,800,2,14.6,700,1,ARL,308893737
2025-07-17T15:49:11.891643099Z,2025-07-17T15:49:11.891477604Z,160,2,1108,C,A,13.720000000,100,0,308797069,0,165495,258658721,ARL,0,13.72,100,0,165495,258658721,9.55,1700,17,9.68,100,1,10.61,200,2,11.27,100,1,11.4,100,1,11.76,100,1,11.93,200,2,12.23,100,1,12.34,200,2,12.36,200,2,13.69,15,1,13.71,15,1,13.73,100,1,14.01,100,1,14.07,2,1,14.28,100,1,14.4,100,1,14.56,800,2,14.6,700,1,14.64,200,2,ARL,308797069
2025-07-17T15:49:11.891643099Z,2025-07-17T15:49:11.891477604Z,160,2,1108,A,A,13.700000000,100,0,308901793,130,165495,258658721,ARL,0,13.7,100,130,165495,258658721,9.55,1700,17,9.68,100,1,10.61,200,2,11.27,100,1,11.4,100,1,11.76,100,1,11.93,200,2,12.23,100,1,12.34,200,2,12.36,200,2,13.69,15,1,13.7,100,1,13.71,15,1,13.73,100,1,14.01,100,1,14.07,2,1,14.28,100,1,14.4,100,1,14.56,800,2,14.6,700,1,ARL,308901793
2025-07-17T15:49:11.893989071Z,2025-07-17T15:49:11.893823458Z,160,2,1108,C,A,14.810000000,100,0,306649913,0,165613,258658835,ARL,0,14.81,100,0,165613,258658835,9.55,1700,17,9.68,100,1,10.61,200,2,11.27,100,1,11.4,100,1,11.76,100,1,11.93,200,2,12.23,100,1,12.34,200,2,12.36,200,2,13.69,15,1,13.7,100,1,13.71,15,1,13.73,100,1,14.01,100,1,14.07,2,1,14.28,100,1,14.4,100,1,14.56,800,2,14.6,700,1,ARL,306649913
2025-07-17T15:49:11.893989071Z,2025-07-17T15:49:11.893823458Z,160,2,1108,A,A,14.660000000,100,0,308901981,130,165613,258658835,ARL,0,14.66,100,130,165613,258658835,9.55,1700,17,9.68,100,1,10.61,200,2,11.27,100,1,11.4,100,1,11.76,100,1,11.93,200,2,12.23,100,1,12.34,200,2,12.36,200,2,13.69,15,1,13.7,100,1,13.71,15,1,13.73,100,1,14.01,100,1,14.07,2,1,14.28,100,1,14.4,100,1,14.56,800,2,14.6,700,1,ARL,308901981
2025-07-17T15:49:11.904231149Z,2025-07-17T15:49:11.904065674Z,160,2,1108,C,A,15.920000000,100,0,306652001,0,165475,258659039,ARL,0,15.92,100,0,165475,258659039,9.55,1700,17,9.68,100,1,10.61,200,2,11.27,100,1,11.4,100,1,11.76,100,1,11.93,200,2,12.23,100,1,12.34,200,2,12.36,200,2,13.69,15,1,13.7,100,1,13.71,15,1,13.73,100,1,14.01,100,1,14.07,2,1,14.28,100,1,14.4,100,1,14.56,800,2,14.6,700,1,ARL,306652001
2025-07-17T15:49:11.904231149Z,2025-07-17T15:49:11.904065674Z,160,2,1108,A,A,15.760000000,100,0,308902229,130,165475,258659039,ARL,0,15.76,100,130,165475,258659039,9.55,1700,17,9.68,100,1,10.61,200,2,11.27,100,1,11.4,100,1,11.76,100,1,11.93,200,2,12.23,100,1,12.34,200,2,12.36,200,2,13.69,15,1,13.7,100,1,13.71,15,1,13.73,100,1,14.01,100,1,14.07,2,1,14.28,100,1,14.4,100,1,14.56,800,2,14.6,700,1,ARL,308902229
2025-07-17T15:49:11.935521687Z,2025-07-17T15:49:11.935356090Z,160,2,1108,C,A,14.810000000,100,0,306653713,0,165597,258659320,ARL,0,14.81,100,0,165597,258659320,9.55,1700,17,9.68,100,1,10.61,200,2,11.27,100,1,11.4,100,1,11.76,100,1,11.93,200,2,12.23,100,1,12.34,200,2,12.36,200,2,13.69,15,1,13.7,100,1,13.71,15,1,13.73,100,1,14.01,100,1,14.07,2,1,14.28,100,1,14.4,100,1,14.56,800,2,14.6,700,1,ARL,306653713
2025-07-17T15:49:11.935521687Z,2025-07-17T15:49:11.935356090Z,160,2,1108,A,A,14.660000000,100,0,308903001,130,165597,258659320,ARL,0,14.66,100,130,165597,258659320,9.55,1700,17,9.68,100,1,10.61,200,2,11.27,100,1,11.4,100,1,11.76,100,1,11.93,200,2,12.23,100,1,12.34,200,2,12.36,200,2,13.69,15,1,13.7,100,1,13.71,15,1,13.73,100,1,14.01,100,1,14.07,2,1,14.28,100,1,14.4,100,1,14.56,800,2,14.6,700,1,ARL,308903001
2025-07-17T15:49:11.948701049Z,2025-07-17T15:49:11.948535655Z,160,2,1108,C,A,14.640000000,100,0,306647521,130,165394,258659496,ARL,0,14.64,100,130,165394,258659496,9.55,1700,17,9.68,100,1,10.61,200,2,11.27,100,1,11.4,100,1,11.76,100,1,11.93,200,2,12.23,100,1,12.34,200,2,12.36,200,2,13.69,15,1,13.7,100,1,13.71,15,1,13.73,100,1,14.01,100,1,14.07,2,1,14.28,100,1,14.4,100,1,14.56,800,2,14.6,700,1,ARL,306647521
2025-07-17T15:49:11.948829112Z,2025-07-17T15:49:11.948663655Z,160,2,1108,A,A,14.500000000,100,0,308903349,130,165457,258659499,ARL,0,14.5,100,130,165457,258659499,9.55,1700,17,9.68,100,1,10.61,200,2,11.27,100,1,11.4,100,1,11.76,100,1,11.93,200,2,12.23,100,1,12.34,200,2,12.36,200,2,13.69,15,1,13.7,100,1,13.71,15,1,13.73,100,1,14.01,100,1,14.07,2,1,14.28,100,1,14.4,100,1,14.5,100,1,14.56,800,2,ARL,308903349
2025-07-17T15:49:12.221221367Z,2025-07-17T15:49:12.221056085Z,160,2,1108,A,A,13.710000000,100,0,308909249,130,165282,258663292,ARL,0,13.71,100,130,165282,258663292,9.55,1700,17,9.68,100,1,10.61,200,2,11.27,100,1,11.4,100,1,11.76,100,1,11.93,200,2,12.23,100,1,12.34,200,2,12.36,200,2,13.69,15,1,13.7,100,1,13.71,115,2,13.73,100,1,14.01,100,1,14.07,2,1,14.28,100,1,14.4,100,1,14.5,100,1,14.56,800,2,ARL,308909249
2025-07-17T15:49:12.227986905Z,2025-07-17T15:49:12.227821500Z,160,2,1108,C,A,13.730000000,100,0,308786185,130,165405,258663378,ARL,0,13.73,100,130,165405,258663378,9.55,1700,17,9.68,100,1,10.61,200,2,11.27,100,1,11.4,100,1,11.76,100,1,11.93,200,2,12.23,100,1,12.34,200,2,12.36,200,2,13.69,15,1,13.7,100,1,13.71,115,2,14.01,100,1,14.07,2,1,14.28,100,1,14.4,100,1,14.5,100,1,14.56,800,2,14.6,700,1,ARL,308786185
2025-07-17T15:49:14.463229121Z,2025-07-17T15:49:14.463063539Z,160,2,1108,C,A,13.710000000,15,0,308763065,130,165582,258702625,ARL,0,13.71,15,130,165582,258702625,9.55,1700,17,9.68,100,1,10.61,200,2,11.27,100,1,11.4,100,1,11.76,100,1,11.93,200,2,12.23,100,1,12.34,200,2,12.36,200,2,13.69,15,1,13.7,100,1,13.71,100,1,14.01,100,1,14.07,2,1,14.28,100,1,14.4,100,1,14.5,100,1,14.56,800,2,14.6,700,1,ARL,308763065
2025-07-17T15:49:15.466365122Z,2025-07-17T15:49:15.466199239Z,160,2,1108,A,A,13.670000000,15,0,308980305,130,165883,258716863,ARL,0,13.67,15,130,165883,258716863,9.55,1700,17,9.68,100,1,10.61,200,2,11.27,100,1,11.4,100,1,11.76,100,1,11.93,200,2,12.23,100,1,12.34,200,2,12.36,200,2,13.67,15,1,13.69,15,1,13.7,100,1,13.71,100,1,14.01,100,1,14.07,2,1,14.28,100,1,14.4,100,1,14.5,100,1,14.56,800,2,ARL,308980305
2025-07-17T15:49:16.351024588Z,2025-07-17T15:49:16.350859152Z,160,2,1108,C,A,13.700000000,100,0,308901793,0,165436,258727929,ARL,0,13.7,100,0,165436,258727929,9.55,1700,17,9.68,100,1,10.61,200,2,11.27,100,1,11.4,100,1,11.76,100,1,11.93,200,2,12.23,100,1,12.34,200,2,12.36,200,2,13.67,15,1,13.69,15,1,13.71,100,1,14.01,100,1,14.07,2,1,14.28,100,1,14.4,100,1,14.5,100,1,14.56,800,2,14.6,700,1,ARL,308901793
2025-07-17T15:49:16.351024588Z,2025-07-17T15:49:16.350859152Z,160,2,1108,A,A,13.680000000,100,0,308998225,130,165436,258727929,ARL,0,13.68,100,130,165436,258727929,9.55,1700,17,9.68,100,1,10.61,200,2,11.27,100,1,11.4,100,1,11.76,100,1,11.93,200,2,12.23,100,1,12.34,200,2,12.36,200,2,13.67,15,1,13.68,100,1,13.69,15,1,13.71,100,1,14.01,100,1,14.07,2,1,14.28,100,1,14.4,100,1,14.5,100,1,14.56,800,2,ARL,308998225
2025-07-17T15:49:16.351759618Z,2025-07-17T15:49:16.351594042Z,160,2,1108,C,A,14.780000000,100,0,308797245,0,165576,258727956,ARL,0,14.78,100,0,165576,258727956,9.55,1700,17,9.68,100,1,10.61,200,2,11.27,100,1,11.4,100,1,11.76,100,1,11.93,200,2,12.23,100,1,12.34,200,2,12.36,200,2,13.67,15,1,13.68,100,1,13.69,15,1,13.71,100,1,14.01,100,1,14.07,2,1,14.28,100,1,14.4,100,1,14.5,100,1,14.56,800,2,ARL,308797245
2025-07-17T15:49:16.351759618Z,2025-07-17T15:49:16.351594042Z,160,2,1108,A,A,14.740000000,100,0,308998341,130,165576,258727956,ARL,0,14.74,100,130,165576,258727956,9.55,1700,17,9.68,100,1,10.61,200,2,11.27,100,1,11.4,100,1,11.76,100,1,11.93,200,2,12.23,100,1,12.34,200,2,12.36,200,2,13.67,15,1,13.68,100,1,13.69,15,1,13.71,100,1,14.01,100,1,14.07,2,1,14.28,100,1,14.4,100,1,14.5,100,1,14.56,800,2,ARL,308998341
2025-07-17T15:49:16.494111490Z,2025-07-17T15:49:16.493946243Z,160,2,1108,A,A,13.690000000,100,0,309001525,130,165247,258729266,ARL,0,13.69,100,130,165247,258729266,9.55,1700,17,9.68,100,1,10.61,200,2,11.27,100,1,11.4,100,1,11.76,100,1,11.93,200,2,12.23,100,1,12.34,200,2,12.36,200,2,13.67,15,1,13.68,100,1,13.69,115,2,13.71,100,1,14.01,100,1,14.07,2,1,14.28,100,1,14.4,100,1,14.5,100,1,14.56,800,2,ARL,309001525
2025-07-17T15:49:16.557924863Z,2025-07-17T15:49:16.557759633Z,160,2,1108,C,A,13.710000000,100,0,308909249,130,165230,258730034,ARL,0,13.71,100,130,165230,258730034,9.55,1700,17,9.68,100,1,10.61,200,2,11.27,100,1,11.4,100,1,11.76,100,1,11.93,200,2,12.23,100,1,12.34,200,2,12.36,200,2,13.67,15,1,13.68,100,1,13.69,115,2,14.01,100,1,14.07,2,1,14.28,100,1,14.4,100,1,14.5,100,1,14.56,800,2,14.6,700,1,ARL,308909249
2025-07-17T15:49:21.186150487Z,2025-07-17T15:49:21.185984774Z,160,2,1108,C,A,14.070000000,2,0,296478973,0,165713,258786552,ARL,0,14.07,2,0,165713,258786552,9.55,1700,17,9.68,100,1,10.61,200,2,11.27,100,1,11.4,100,1,11.76,100,1,11.93,200,2,12.23,100,1,12.34,200,2,12.36,200,2,13.67,15,1,13.68,100,1,13.69,115,2,14.01,100,1,14.28,100,1,14.4,100,1,14.5,100,1,14.56,800,2,14.6,700,1,14.64,100,1,ARL,296478973
2025-07-17T15:49:21.186150487Z,2025-07-17T15:49:21.185984774Z,160,2,1108,A,A,13.980000000,2,0,309091513,130,165713,258786552,ARL,0,13.98,2,130,165713,258786552,9.55,1700,17,9.68,100,1,10.61,200,2,11.27,100,1,11.4,100,1,11.76,100,1,11.93,200,2,12.23,100,1,12.34,200,2,12.36,200,2,13.67,15,1,13.68,100,1,13.69,115,2,13.98,2,1,14.01,100,1,14.28,100,1,14.4,100,1,14.5,100,1,14.56,800,2,14.6,700,1,ARL,309091513
2025-07-17T15:49:24.283152112Z,2025-07-17T15:49:24.282985894Z,160,2,1108,C,A,13.690000000,15,0,308893737,130,166218,258838460,ARL,0,13.69,15,130,166218,258838460,9.55,1700,17,9.68,100,1,10.61,200,2,11.27,100,1,11.4,100,1,11.76,100,1,11.93,200,2,12.23,100,1,12.34,200,2,12.36,200,2,13.67,15,1,13.68,100,1,13.69,100,1,13.98,2,1,14.01,100,1,14.28,100,1,14.4,100,1,14.5,100,1,14.56,800,2,14.6,700,1,ARL,308893737
2025-07-17T15:49:34.570197134Z,2025-07-17T15:49:34.570031718Z,160,2,1108,C,A,13.670000000,15,0,308980305,130,165416,258980876,ARL,0,13.67,15,130,165416,258980876,9.55,1700,17,9.68,100,1,10.61,200,2,11.27,100,1,11.4,100,1,11.76,100,1,11.93,200,2,12.23,100,1,12.34,200,2,12.36,200,2,13.68,100,1,13.69,100,1,13.98,2,1,14.01,100,1,14.28,100,1,14.4,100,1,14.5,100,1,14.56,800,2,14.6,700,1,14.64,100,1,ARL,308980305
2025-07-17T15:49:34.591512915Z,2025-07-17T15:49:34.591347169Z,160,2,1108,C,A,13.690000000,100,0,309001525,130,165746,258983321,ARL,0,13.69,100,130,165746,258983321,9.55,1700,17,9.68,100,1,10.61,200,2,11.27,100,1,11.4,100,1,11.76,100,1,11.93,200,2,12.23,100,1,12.34,200,2,12.36,200,2,13.68,100,1,13.98,2,1,14.01,100,1,14.28,100,1,14.4,100,1,14.5,100,1,14.56,800,2,14.6,700,1,14.64,100,1,14.65,100,1,ARL,309001525
2025-07-17T15:49:38.610017394Z,2025-07-17T15:49:38.609851985Z,160,2,1108,A,A,13.720000000,100,0,309410565,130,165409,259031220,ARL,0,13.72,100,130,165409,259031220,9.55,1700,17,9.68,100,1,10.61,200,2,11.27,100,1,11.4,100,1,11.76,100,1,11.93,200,2,12.23,100,1,12.34,200,2,12.36,200,2,13.68,100,1,13.72,100,1,13.98,2,1,14.01,100,1,14.28,100,1,14.4,100,1,14.5,100,1,14.56,800,2,14.6,700,1,14.64,100,1,ARL,309410565
2025-07-17T15:49:38.610073334Z,2025-07-17T15:49:38.609907720Z,160,2,1108,C,B,13.260000000,100,0,291975017,130,165614,259031221,ARL,0,13.26,100,130,165614,259031221,9.55,1700,17,9.68,100,1,10.61,200,2,11.27,100,1,11.4,100,1,11.76,100,1,11.93,200,2,12.23,100,1,12.34,200,2,12.36,200,2,13.68,100,1,13.72,100,1,13.98,2,1,14.01,100,1,14.28,100,1,14.4,100,1,14.5,100,1,14.56,800,2,14.6,700,1,14.64,100,1,ARL,291975017
2025-07-17T15:49:39.068515005Z,2025-07-17T15:49:39.068349660Z,160,2,1108,A,B,13.020000000,100,0,309415429,130,165345,259035032,ARL,0,13.02,100,130,165345,259035032,9.55,1700,17,9.68,100,1,10.61,200,2,11.27,100,1,11.4,100,1,11.76,100,1,11.93,200,2,12.23,100,1,12.34,200,2,12.36,200,2,13.68,100,1,13.72,100,1,13.98,2,1,14.01,100,1,14.28,100,1,14.4,100,1,14.5,100,1,14.56,800,2,14.6,700,1,14.64,100,1,ARL,309415429
2025-07-17T15:49:44.788414401Z,2025-07-17T15:49:44.788249210Z,160,2,1108,A,A,13.670000000,15,0,309524921,130,165191,259105347,ARL,0,13.67,15,130,165191,259105347,9.55,1700,17,9.68,100,1,10.61,200,2,11.27,100,1,11.4,100,1,11.76,100,1,11.93,200,2,12.23,100,1,12.34,200,2,12.36,200,2,13.67,15,1,13.68,100,1,13.72,100,1,13.98,2,1,14.01,100,1,14.28,100,1,14.4,100,1,14.5,100,1,14.56,800,2,14.6,700,1,ARL,309524921
2025-07-17T15:49:44.789020757Z,2025-07-17T15:49:44.788855587Z,160,2,1108,A,A,13.700000000,100,0,309524933,130,165170,259105361,ARL,0,13.7,100,130,165170,259105361,9.55,1700,17,9.68,100,1,10.61,200,2,11.27,100,1,11.4,100,1,11.76,100,1,11.93,200,2,12.23,100,1,12.34,200,2,12.36,200,2,13.67,15,1,13.68,100,1,13.7,100,1,13.72,100,1,13.98,2,1,14.01,100,1,14.28,100,1,14.4,100,1,14.5,100,1,14.56,800,2,ARL,309524933
2025-07-17T15:49:44.789702916Z,2025-07-17T15:49:44.789537536Z,160,2,1108,C,A,13.720000000,100,0,309410565,130,165380,259105380,ARL,0,13.72,100,130,165380,259105380,9.55,1700,17,9.68,100,1,10.61,200,2,11.27,100,1,11.4,100,1,11.76,100,1,11.93,200,2,12.23,100,1,12.34,200,2,12.36,200,2,13.67,15,1,13.68,100,1,13.7,100,1,13.98,2,1,14.01,100,1,14.28,100,1,14.4,100,1,14.5,100,1,14.56,800,2,14.6,700,1,ARL,309410565
2025-07-17T15:49:54.788658841Z,2025-07-17T15:49:54.788493605Z,160,2,1108,A,A,13.650000000,15,0,309707269,130,165236,259253294,ARL,0,13.65,15,130,165236,259253294,9.55,1700,17,9.68,100,1,10.61,200,2,11.27,100,1,11.4,100,1,11.76,100,1,11.93,200,2,12.23,100,1,12.34,200,2,12.36,200,2,13.65,15,1,13.67,15,1,13.68,100,1,13.7,100,1,13.98,2,1,14.01,100,1,14.28,100,1,14.4,100,1,14.5,100,1,14.56,800,2,ARL,309707269
2025-07-17T15:49:54.799535744Z,2025-07-17T15:49:54.799370442Z,160,2,1108,A,A,13.680000000,100,0,309707413,130,165302,259253527,ARL,0,13.68,100,130,165302,259253527,9.55,1700,17,9.68,100,1,10.61,200,2,11.27,100,1,11.4,100,1,11.76,100,1,11.93,200,2,12.23,100,1,12.34,200,2,12.36,200,2,13.65,15,1,13.67,15,1,13.68,200,2,13.7,100,1,13.98,2,1,14.01,100,1,14.28,100,1,14.4,100,1,14.5,100,1,14.56,800,2,ARL,309707413
2025-07-17T15:49:54.820634917Z,2025-07-17T15:49:54.820469390Z,160,2,1108,C,A,13.700000000,100,0,309524933,130,165527,259253732,ARL,0,13.7,100,130,165527,259253732,9.55,1700,17,9.68,100,1,10.61,200,2,11.27,100,1,11.4,100,1,11.76,100,1,11.93,200,2,12.23,100,1,12.34,200,2,12.36,200,2,13.65,15,1,13.67,15,1,13.68,200,2,13.98,2,1,14.01,100,1,14.28,100,1,14.4,100,1,14.5,100,1,14.56,800,2,14.6,700,1,ARL,309524933
2025-07-17T15:49:59.512104064Z,2025-07-17T15:49:59.511938438Z,160,2,1108,C,A,13.680000000,100,0,308998225,0,165626,259313537,ARL,0,13.68,100,0,165626,259313537,9.55,1700,17,9.68,100,1,10.61,200,2,11.27,100,1,11.4,100,1,11.76,100,1,11.93,200,2,12.23,100,1,12.34,200,2,12.36,200,2,13.65,15,1,13.67,15,1,13.68,100,1,13.98,2,1,14.01,100,1,14.28,100,1,14.4,100,1,14.5,100,1,14.56,800,2,14.6,700,1,ARL,308998225
2025-07-17T15:49:59.512104064Z,2025-07-17T15:49:59.511938438Z,160,2,1108,A,A,13.660000000,100,0,309782481,130,165626,259313537,ARL,0,13.66,100,130,165626,259313537,9.55,1700,17,9.68,100,1,10.61,200,2,11.27,100,1,11.4,100,1,11.76,100,1,11.93,200,2,12.23,100,1,12.34,200,2,12.36,200,2,13.65,15,1,13.66,100,1,13.67,15,1,13.68,100,1,13.98,2,1,14.01,100,1,14.28,100,1,14.4,100,1,14.5,100,1,14.56,800,2,ARL,309782481
2025-07-17T15:49:59.534062634Z,2025-07-17T15:49:59.533897369Z,160,2,1108,C,A,14.010000000,100,0,308375185,130,165265,259314032,ARL,0,14.01,100,130,165265,259314032,9.55,1700,17,9.68,100,1,10.61,200,2,11.27,100,1,11.4,100,1,11.76,100,1,11.93,200,2,12.23,100,1,12.34,200,2,12.36,200,2,13.65,15,1,13.66,100,1,13.67,15,1,13.68,100,1,13.98,2,1,14.28,100,1,14.4,100,1,14.5,100,1,14.56,800,2,14.6,700,1,ARL,308375185
2025-07-17T15:49:59.534115275Z,2025-07-17T15:49:59.533948952Z,160,2,1108,A,A,13.930000000,100,0,309782973,130,166323,259314033,ARL,0,13.93,100,130,166323,259314033,9.55,1700,17,9.68,100,1,10.61,200,2,11.27,100,1,11.4,100,1,11.76,100,1,11.93,200,2,12.23,100,1,12.34,200,2,12.36,200,2,13.65,15,1,13.66,100,1,13.67,15,1,13.68,100,1,13.93,100,1,13.98,2,1,14.28,100,1,14.4,100,1,14.5,100,1,14.56,800,2,ARL,309782973
2025-07-17T15:50:00.547404972Z,2025-07-17T15:50:00.547239401Z,160,2,1108,C,A,13.670000000,15,0,309524921,130,165571,259349868,ARL,0,13.67,15,130,165571,259349868,9.55,1700,17,9.68,100,1,10.61,200,2,11.27,100,1,11.4,100,1,11.76,100,1,11.93,200,2,12.23,100,1,12.34,200,2,12.36,200,2,13.65,15,1,13.66,100,1,13.68,100,1,13.93,100,1,13.98,2,1,14.28,100,1,14.4,100,1,14.5,100,1,14.56,800,2,14.6,700,1,ARL,309524921
2025-07-17T15:50:00.555536688Z,2025-07-17T15:50:00.555363249Z,160,2,1108,C,A,14.650000000,100,0,307964661,0,173439,259353226,ARL,0,14.65,100,0,173439,259353226,9.55,1700,17,9.68,100,1,10.61,200,2,11.27,100,1,11.4,100,1,11.76,100,1,11.93,200,2,12.23,100,1,12.34,200,2,12.36,200,2,13.65,15,1,13.66,100,1,13.68,100,1,13.93,100,1,13.98,2,1,14.28,100,1,14.4,100,1,14.5,100,1,14.56,800,2,14.6,700,1,ARL,307964661
2025-07-17T15:50:00.555536688Z,2025-07-17T15:50:00.555363249Z,160,2,1108,A,A,14.540000000,100,0,309823025,128,173439,259353226,ARL,0,14.54,100,128,173439,259353226,9.55,1700,17,9.68,100,1,10.61,200,2,11.27,100,1,11.4,100,1,11.76,100,1,11.93,200,2,12.23,100,1,12.34,200,2,12.36,200,2,13.65,15,1,13.66,100,1,13.68,100,1,13.93,100,1,13.98,2,1,14.28,100,1,14.4,100,1,14.5,100,1,14.54,100,1,14.56,800,2,ARL,309823025
2025-07-17T15:50:03.412422880Z,2025-07-17T15:50:03.412257475Z,160,2,1108,A,A,13.630000000,15,0,309899025,130,165405,259413272,ARL,0,13.63,15,130,165405,259413272,9.55,1700,17,9.68,100,1,10.61,200,2,11.27,100,1,11.4,100,1,11.76,100,1,11.93,200,2,12.23,100,1,12.34,200,2,12.36,200,2,13.63,15,1,13.65,15,1,13.66,100,1,13.68,100,1,13.93,100,1,13.98,2,1,14.28,100,1,14.4,100,1,14.5,100,1,14.54,100,1,ARL,309899025
2025-07-17T15:50:03.415527372Z,2025-07-17T15:50:03.415361851Z,160,2,1108,C,A,14.640000000,100,0,308296381,0,165521,259413427,ARL,0,14.64,100,0,165521,259413427,9.55,1700,17,9.68,100,1,10.61,200,2,11.27,100,1,11.4,100,1,11.76,100,1,11.93,200,2,12.23,100,1,12.34,200,2,12.36,200,2,13.63,15,1,13.65,15,1,13.66,100,1,13.68,100,1,13.93,100,1,13.98,2,1,14.28,100,1,14.4,100,1,14.5,100,1,14.54,100,1,ARL,308296381
2025-07-17T15:50:03.415527372Z,2025-07-17T15:50:03.415361851Z,160,2,1108,A,A,14.530000000,100,0,309899141,130,165521,259413427,ARL,0,14.53,100,130,165521,259413427,9.55,1700,17,9.68,100,1,10.61,200,2,11.27,100,1,11.4,100,1,11.76,100,1,11.93,200,2,12.23,100,1,12.34,200,2,12.36,200,2,13.63,15,1,13.65,15,1,13.66,100,1,13.68,100,1,13.93,100,1,13.98,2,1,14.28,100,1,14.4,100,1,14.5,100,1,14.53,100,1,ARL,309899141
2025-07-17T15:50:03.824292152Z,2025-07-17T15:50:03.824126753Z,160,2,1108,C,A,13.660000000,100,0,309782481,0,165399,259418661,ARL,0,13.66,100,0,165399,259418661,9.55,1700,17,9.68,100,1,10.61,200,2,11.27,100,1,11.4,100,1,11.76,100,1,11.93,200,2,12.23,100,1,12.34,200,2,12.36,200,2,13.63,15,1,13.65,15,1,13.68,100,1,13.93,100,1,13.98,2,1,14.28,100,1,14.4,100,1,14.5,100,1,14.53,100,1,14.54,100,1,ARL,309782481
2025-07-17T15:50:03.824292152Z,2025-07-17T15:50:03.824126753Z,160,2,1108,A,A,13.640000000,100,0,309903973,130,165399,259418661,ARL,0,13.64,100,130,165399,259418661,9.55,1700,17,9.68,100,1,10.61,200,2,11.27,100,1,11.4,100,1,11.76,100,1,11.93,200,2,12.23,100,1,12.34,200,2,12.36,200,2,13.63,15,1,13.64,100,1,13.65,15,1,13.68,100,1,13.93,100,1,13.98,2,1,14.28,100,1,14.4,100,1,14.5,100,1,14.53,100,1,ARL,309903973
2025-07-17T15:50:03.825028460Z,2025-07-17T15:50:03.824863026Z,160,2,1108,C,A,14.740000000,100,0,308998341,0,165434,259418664,ARL,0,14.74,100,0,165434,259418664,9.55,1700,17,9.68,100,1,10.61,200,2,11.27,100,1,11.4,100,1,11.76,100,1,11.93,200,2,12.23,100,1,12.34,200,2,12.36,200,2,13.63,15,1,13.64,100,1,13.65,15,1,13.68,100,1,13.93,100,1,13.98,2,1,14.28,100,1,14.4,100,1,14.5,100,1,14.53,100,1,ARL,308998341
2025-07-17T15:50:03.825028460Z,2025-07-17T15:50:03.824863026Z,160,2,1108,A,A,14.700000000,100,0,309903993,130,165434,259418664,ARL,0,14.7,100,130,165434,259418664,9.55,1700,17,9.68,100,1,10.61,200,2,11.27,100,1,11.4,100,1,11.76,100,1,11.93,200,2,12.23,100,1,12.34,200,2,12.36,200,2,13.63,15,1,13.64,100,1,13.65,15,1,13.68,100,1,13.93,100,1,13.98,2,1,14.28,100,1,14.4,100,1,14.5,100,1,14.53,100,1,ARL,309903993
2025-07-17T15:50:04.484898759Z,2025-07-17T15:50:04.484733438Z,160,2,1108,A,A,13.660000000,100,0,309922345,130,165321,259433904,ARL,0,13.66,100,130,165321,259433904,9.55,1700,17,9.68,100,1,10.61,200,2,11.27,100,1,11.4,100,1,11.76,100,1,11.93,200,2,12.23,100,1,12.34,200,2,12.36,200,2,13.63,15,1,13.64,100,1,13.65,15,1,13.66,100,1,13.68,100,1,13.93,100,1,13.98,2,1,14.28,100,1,14.4,100,1,14.5,100,1,ARL,309922345
2025-07-17T15:50:04.524729039Z,2025-07-17T15:50:04.524563568Z,160,2,1108,C,A,13.680000000,100,0,309707413,130,165471,259434652,ARL,0,13.68,100,130,165471,259434652,9.55,1700,17,9.68,100,1,10.61,200,2,11.27,100,1,11.4,100,1,11.76,100,1,11.93,200,2,12.23,100,1,12.34,200,2,12.36,200,2,13.63,15,1,13.64,100,1,13.65,15,1,13.66,100,1,13.93,100,1,13.98,2,1,14.28,100,1,14.4,100,1,14.5,100,1,14.53,100,1,ARL,309707413
2025-07-17T15:50:06.787826975Z,2025-07-17T15:50:06.787661846Z,160,2,1108,C,A,13.630000000,15,0,309899025,130,165129,259472951,ARL,0,13.63,15,130,165129,259472951,9.55,1700,17,9.68,100,1,10.61,200,2,11.27,100,1,11.4,100,1,11.76,100,1,11.93,200,2,12.23,100,1,12.34,200,2,12.36,200,2,13.64,100,1,13.65,15,1,13.66,100,1,13.93,100,1,13.98,2,1,14.28,100,1,14.4,100,1,14.5,100,1,14.53,100,1,14.54,100,1,ARL,309899025
2025-07-17T15:50:09.185499367Z,2025-07-17T15:50:09.185334126Z,160,2,1108,A,A,13.610000000,15,0,310030465,130,165241,259516855,ARL,0,13.61,15,130,165241,259516855,9.55,1700,17,9.68,100,1,10.61,200,2,11.27,100,1,11.4,100,1,11.76,100,1,11.93,200,2,12.23,100,1,12.34,200,2,12.36,200,2,13.61,15,1,13.64,100,1,13.65,15,1,13.66,100,1,13.93,100,1,13.98,2,1,14.28,100,1,14.4,100,1,14.5,100,1,14.53,100,1,ARL,310030465
2025-07-17T15:50:09.198476437Z,2025-07-17T15:50:09.198311198Z,160,2,1108,A,A,13.640000000,100,0,310031625,130,165239,259517754,ARL,0,13.64,100,130,165239,259517754,9.55,1700,17,9.68,100,1,10.61,200,2,11.27,100,1,11.4,100,1,11.76,100,1,11.93,200,2,12.23,100,1,12.34,200,2,12.36,200,2,13.61,15,1,13.64,200,2,13.65,15,1,13.66,100,1,13.93,100,1,13.98,2,1,14.28,100,1,14.4,100,1,14.5,100,1,14.53,100,1,ARL,310031625
2025-07-17T15:50:09.205487416Z,2025-07-17T15:50:09.205322092Z,160,2,1108,C,A,13.660000000,100,0,309922345,130,165324,259517973,ARL,0,13.66,100,130,165324,259517973,9.55,1700,17,9.68,100,1,10.61,200,2,11.27,100,1,11.4,100,1,11.76,100,1,11.93,200,2,12.23,100,1,12.34,200,2,12.36,200,2,13.61,15,1,13.64,200,2,13.65,15,1,13.93,100,1,13.98,2,1,14.28,100,1,14.4,100,1,14.5,100,1,14.53,100,1,14.54,100,1,ARL,309922345
2025-07-17T15:50:09.330738153Z,2025-07-17T15:50:09.330572653Z,160,2,1108,C,A,13.640000000,100,0,309903973,0,165500,259522708,ARL,0,13.64,100,0,165500,259522708,9.55,1700,17,9.68,100,1,10.61,200,2,11.27,100,1,11.4,100,1,11.76,100,1,11.93,200,2,12.23,100,1,12.34,200,2,12.36,200,2,13.61,15,1,13.64,100,1,13.65,15,1,13.93,100,1,13.98,2,1,14.28,100,1,14.4,100,1,14.5,100,1,14.53,100,1,14.54,100,1,ARL,309903973
2025-07-17T15:50:09.330738153Z,2025-07-17T15:50:09.330572653Z,160,2,1108,A,A,13.620000000,100,0,310037965,130,165500,259522708,ARL,0,13.62,100,130,165500,259522708,9.55,1700,17,9.68,100,1,10.61,200,2,11.27,100,1,11.4,100,1,11.76,100,1,11.93,200,2,12.23,100,1,12.34,200,2,12.36,200,2,13.61,15,1,13.62,100,1,13.64,100,1,13.65,15,1,13.93,100,1,13.98,2,1,14.28,100,1,14.4,100,1,14.5,100,1,14.53,100,1,ARL,310037965
2025-07-17T15:50:20.204539185Z,2025-07-17T15:50:20.204373858Z,160,2,1108,C,A,13.650000000,15,0,309707269,130,165327,259737768,ARL,0,13.65,15,130,165327,259737768,9.55,1700,17,9.68,100,1,10.61,200,2,11.27,100,1,11.4,100,1,11.76,100,1,11.93,200,2,12.23,100,1,12.34,200,2,12.36,200,2,13.61,15,1,13.62,100,1,13.64,100,1,13.93,100,1,13.98,2,1,14.28,100,1,14.4,100,1,14.5,100,1,14.53,100,1,14.54,100,1,ARL,309707269
2025-07-17T15:50:25.935579034Z,2025-07-17T15:50:25.935412900Z,160,2,1108,A,A,13.590000000,15,0,310424077,128,166134,259828644,ARL,0,13.59,15,128,166134,259828644,9.55,1700,17,9.68,100,1,10.61,200,2,11.27,100,1,11.4,100,1,11.76,100,1,11.93,200,2,12.23,100,1,12.34,200,2,12.36,200,2,13.59,15,1,13.61,15,1,13.62,100,1,13.64,100,1,13.93,100,1,13.98,2,1,14.28,100,1,14.4,100,1,14.5,100,1,14.53,100,1,ARL,310424077
2025-07-17T15:50:26.954828150Z,2025-07-17T15:50:26.954662143Z,160,2,1108,C,A,13.620000000,100,0,310037965,0,166007,259847181,ARL,0,13.62,100,0,166007,259847181,9.55,1700,17,9.68,100,1,10.61,200,2,11.27,100,1,11.4,100,1,11.76,100,1,11.93,200,2,12.23,100,1,12.34,200,2,12.36,200,2,13.59,15,1,13.61,15,1,13.64,100,1,13.93,100,1,13.98,2,1,14.28,100,1,14.4,100,1,14.5,100,1,14.53,100,1,14.54,100,1,ARL,310037965
2025-07-17T15:50:26.954828150Z,2025-07-17T15:50:26.954662143Z,160,2,1108,A,A,13.600000000,100,0,310446249,130,166007,259847181,ARL,0,13.6,100,130,166007,259847181,9.55,1700,17,9.68,100,1,10.61,200,2,11.27,100,1,11.4,100,1,11.76,100,1,11.93,200,2,12.23,100,1,12.34,200,2,12.36,200,2,13.59,15,1,13.6,100,1,13.61,15,1,13.64,100,1,13.93,100,1,13.98,2,1,14.28,100,1,14.4,100,1,14.5,100,1,14.53,100,1,ARL,310446249
2025-07-17T15:50:26.955565904Z,2025-07-17T15:50:26.955400327Z,160,2,1108,C,A,14.700000000,100,0,309903993,0,165577,259847190,ARL,0,14.7,100,0,165577,259847190,9.55,1700,17,9.68,100,1,10.61,200,2,11.27,100,1,11.4,100,1,11.76,100,1,11.93,200,2,12.23,100,1,12.34,200,2,12.36,200,2,13.59,15,1,13.6,100,1,13.61,15,1,13.64,100,1,13.93,100,1,13.98,2,1,14.28,100,1,14.4,100,1,14.5,100,1,14.53,100,1,ARL,309903993
2025-07-17T15:50:26.955565904Z,2025-07-17T15:50:26.955400327Z,160,2,1108,A,A,14.650000000,100,0,310446269,130,165577,259847190,ARL,0,14.65,100,130,165577,259847190,9.55,1700,17,9.68,100,1,10.61,200,2,11.27,100,1,11.4,100,1,11.76,100,1,11.93,200,2,12.23,100,1,12.34,200,2,12.36,200,2,13.59,15,1,13.6,100,1,13.61,15,1,13.64,100,1,13.93,100,1,13.98,2,1,14.28,100,1,14.4,100,1,14.5,100,1,14.53,100,1,ARL,310446269
2025-07-17T15:50:26.956259508Z,2025-07-17T15:50:26.956094101Z,160,2,1108,C,A,17.430000000,100,0,308799373,0,165407,259847199,ARL,0,17.43,100,0,165407,259847199,9.55,1700,17,9.68,100,1,10.61,200,2,11.27,100,1,11.4,100,1,11.76,100,1,11.93,200,2,12.23,100,1,12.34,200,2,12.36,200,2,13.59,15,1,13.6,100,1,13.61,15,1,13.64,100,1,13.93,100,1,13.98,2,1,14.28,100,1,14.4,100,1,14.5,100,1,14.53,100,1,ARL,308799373
2025-07-17T15:50:26.956259508Z,2025-07-17T15:50:26.956094101Z,160,2,1108,A,A,17.280000000,100,0,310446293,130,165407,259847199,ARL,0,17.28,100,130,165407,259847199,9.55,1700,17,9.68,100,1,10.61,200,2,11.27,100,1,11.4,100,1,11.76,100,1,11.93,200,2,12.23,100,1,12.34,200,2,12.36,200,2,13.59,15,1,13.6,100,1,13.61,15,1,13.64,100,1,13.93,100,1,13.98,2,1,14.28,100,1,14.4,100,1,14.5,100,1,14.53,100,1,ARL,310446293
2025-07-17T15:50:26.983044736Z,2025-07-17T15:50:26.982879448Z,160,2,1108,A,A,15.510000000,100,0,310447441,130,165288,259847556,ARL,0,15.51,100,130,165288,259847556,9.55,1700,17,9.68,100,1,10.61,200,2,11.27,100,1,11.4,100,1,11.76,100,1,11.93,200,2,12.23,100,1,12.34,200,2,12.36,200,2,13.59,15,1,13.6,100,1,13.61,15,1,13.64,100,1,13.93,100,1,13.98,2,1,14.28,100,1,14.4,100,1,14.5,100,1,14.53,100,1,ARL,310447441
2025-07-17T15:50:26.983057675Z,2025-07-17T15:50:26.982892468Z,160,2,1108,C,A,15.780000000,100,0,282776733,130,165207,259847557,ARL,0,15.78,100,130,165207,259847557,9.55,1700,17,9.68,100,1,10.61,200,2,11.27,100,1,11.4,100,1,11.76,100,1,11.93,200,2,12.23,100,1,12.34,200,2,12.36,200,2,13.59,15,1,13.6,100,1,13.61,15,1,13.64,100,1,13.93,100,1,13.98,2,1,14.28,100,1,14.4,100,1,14.5,100,1,14.53,100,1,ARL,282776733
2025-07-17T15:50:30.046879569Z,2025-07-17T15:50:30.046714265Z,160,2,1108,C,A,13.590000000,15,0,310424077,130,165304,259916670,ARL,0,13.59,15,130,165304,259916670,9.55,1700,17,9.68,100,1,10.61,200,2,11.27,100,1,11.4,100,1,11.76,100,1,11.93,200,2,12.23,100,1,12.34,200,2,12.36,200,2,13.6,100,1,13.61,15,1,13.64,100,1,13.93,100,1,13.98,2,1,14.28,100,1,14.4,100,1,14.5,100,1,14.53,100,1,14.54,100,1,ARL,310424077
2025-07-17T15:50:30.047015114Z,2025-07-17T15:50:30.046849726Z,160,2,1108,C,A,13.610000000,15,0,310030465,130,165388,259916674,ARL,0,13.61,15,130,165388,259916674,9.55,1700,17,9.68,100,1,10.61,200,2,11.27,100,1,11.4,100,1,11.76,100,1,11.93,200,2,12.23,100,1,12.34,200,2,12.36,200,2,13.6,100,1,13.64,100,1,13.93,100,1,13.98,2,1,14.28,100,1,14.4,100,1,14.5,100,1,14.53,100,1,14.54,100,1,14.56,800,2,ARL,310030465
2025-07-17T15:51:37.986158330Z,2025-07-17T15:51:37.985992174Z,160,2,1108,C,A,13.980000000,2,0,309091513,0,166156,261130345,ARL,0,13.98,2,0,166156,261130345,9.55,1700,17,9.68,100,1,10.61,200,2,11.27,100,1,11.4,100,1,11.76,100,1,11.93,200,2,12.23,100,1,12.34,200,2,12.36,200,2,13.6,100,1,13.64,100,1,13.93,100,1,14.28,100,1,14.4,100,1,14.5,100,1,14.53,100,1,14.54,100,1,14.56,800,2,14.6,700,1,ARL,309091513
2025-07-17T15:51:37.986158330Z,2025-07-17T15:51:37.985992174Z,160,2,1108,A,A,13.890000000,2,0,311979125,130,166156,261130345,ARL,0,13.89,2,130,166156,261130345,9.55,1700,17,9.68,100,1,10.61,200,2,11.27,100,1,11.4,100,1,11.76,100,1,11.93,200,2,12.23,100,1,12.34,200,2,12.36,200,2,13.6,100,1,13.64,100,1,13.89,2,1,13.93,100,1,14.28,100,1,14.4,100,1,14.5,100,1,14.53,100,1,14.54,100,1,14.56,800,2,ARL,311979125
2025-07-17T15:52:16.371517839Z,2025-07-17T15:52:16.371351021Z,160,2,1108,T,N,13.410000000,58,0,0,0,166818,261713745,ARL,0,13.41,58,0,166818,261713745,9.55,1700,17,9.68,100,1,10.61,200,2,11.27,100,1,11.4,100,1,11.76,100,1,11.93,200,2,12.23,100,1,12.34,200,2,12.36,200,2,13.6,100,1,13.64,100,1,13.89,2,1,13.93,100,1,14.28,100,1,14.4,100,1,14.5,100,1,14.53,100,1,14.54,100,1,14.56,800,2,ARL,0
2025-07-17T15:52:16.371517839Z,2025-07-17T15:52:16.371351021Z,160,2,1108,T,N,13.280000000,12,0,0,130,166818,261713746,ARL,0,13.28,12,130,166818,261713746,9.55,1700,17,9.68,100,1,10.61,200,2,11.27,100,1,11.4,100,1,11.76,100,1,11.93,200,2,12.23,100,1,12.34,200,2,12.36,200,2,13.6,100,1,13.64,100,1,13.89,2,1,13.93,100,1,14.28,100,1,14.4,100,1,14.5,100,1,14.53,100,1,14.54,100,1,14.56,800,2,ARL,0
2025-07-17T15:52:16.372434625Z,2025-07-17T15:52:16.372269170Z,160,2,1108,C,A,13.600000000,100,0,310446249,130,165455,261713790,ARL,0,13.6,100,130,165455,261713790,9.55,1700,17,9.68,100,1,10.61,200,2,11.27,100,1,11.4,100,1,11.76,100,1,11.93,200,2,12.23,100,1,12.34,200,2,12.36,200,2,13.64,100,1,13.89,2,1,13.93,100,1,14.28,100,1,14.4,100,1,14.5,100,1,14.53,100,1,14.54,100,1,14.56,800,2,14.6,700,1,ARL,310446249
2025-07-17T15:52:16.373188791Z,2025-07-17T15:52:16.373023186Z,160,2,1108,C,A,14.650000000,100,0,310446269,0,165605,261713830,ARL,0,14.65,100,0,165605,261713830,9.55,1700,17,9.68,100,1,10.61,200,2,11.27,100,1,11.4,100,1,11.76,100,1,11.93,200,2,12.23,100,1,12.34,200,2,12.36,200,2,13.64,100,1,13.89,2,1,13.93,100,1,14.28,100,1,14.4,100,1,14.5,100,1,14.53,100,1,14.54,100,1,14.56,800,2,14.6,700,1,ARL,310446269
2025-07-17T15:52:16.373188791Z,2025-07-17T15:52:16.373023186Z,160,2,1108,A,A,14.700000000,100,0,312771573,130,165605,261713830,ARL,0,14.7,100,130,165605,261713830,9.55,1700,17,9.68,100,1,10.61,200,2,11.27,100,1,11.4,100,1,11.76,100,1,11.93,200,2,12.23,100,1,12.34,200,2,12.36,200,2,13.64,100,1,13.89,2,1,13.93,100,1,14.28,100,1,14.4,100,1,14.5,100,1,14.53,100,1,14.54,100,1,14.56,800,2,14.6,700,1,ARL,312771573
2025-07-17T15:52:16.374353159Z,2025-07-17T15:52:16.374186508Z,160,2,1108,C,A,13.640000000,100,0,310031625,130,166651,261713870,ARL,0,13.64,100,130,166651,261713870,9.55,1700,17,9.68,100,1,10.61,200,2,11.27,100,1,11.4,100,1,11.76,100,1,11.93,200,2,12.23,100,1,12.34,200,2,12.36,200,2,13.89,2,1,13.93,100,1,14.28,100,1,14.4,100,1,14.5,100,1,14.53,100,1,14.54,100,1,14.56,800,2,14.6,700,1,14.66,200,2,ARL,310031625
2025-07-17T15:52:16.374480183Z,2025-07-17T15:52:16.374312976Z,160,2,1108,A,A,15.860000000,100,0,312771645,128,167207,261713880,ARL,0,15.86,100,128,167207,261713880,9.55,1700,17,9.68,100,1,10.61,200,2,11.27,100,1,11.4,100,1,11.76,100,1,11.93,200,2,12.23,100,1,12.34,200,2,12.36,200,2,13.89,2,1,13.93,100,1,14.28,100,1,14.4,100,1,14.5,100,1,14.53,100,1,14.54,100,1,14.56,800,2,14.6,700,1,14.66,200,2,ARL,312771645
2025-07-17T15:52:16.374493650Z,2025-07-17T15:52:16.374327668Z,160,2,1108,C,A,15.510000000,100,0,310447441,130,165982,261713884,ARL,0,15.51,100,130,165982,261713884,9.55,1700,17,9.68,100,1,10.61,200,2,11.27,100,1,11.4,100,1,11.76,100,1,11.93,200,2,12.23,100,1,12.34,200,2,12.36,200,2,13.89,2,1,13.93,100,1,14.28,100,1,14.4,100,1,14.5,100,1,14.53,100,1,14.54,100,1,14.56,800,2,14.6,700,1,14.66,200,2,ARL,310447441
2025-07-17T15:52:16.375388285Z,2025-07-17T15:52:16.375222836Z,160,2,1108,C,A,14.540000000,100,0,309823025,0,165449,261713944,ARL,0,14.54,100,0,165449,261713944,9.55,1700,17,9.68,100,1,10.61,200,2,11.27,100,1,11.4,100,1,11.76,100,1,11.93,200,2,12.23,100,1,12.34,200,2,12.36,200,2,13.89,2,1,13.93,100,1,14.28,100,1,14.4,100,1,14.5,100,1,14.53,100,1,14.56,800,2,14.6,700,1,14.66,200,2,14.68,1400,2,ARL,309823025
2025-07-17T15:52:16.375388285Z,2025-07-17T15:52:16.375222836Z,160,2,1108,A,A,14.810000000,100,0,312771781,130,165449,261713944,ARL,0,14.81,100,130,165449,261713944,9.55,1700,17,9.68,100,1,10.61,200,2,11.27,100,1,11.4,100,1,11.76,100,1,11.93,200,2,12.23,100,1,12.34,200,2,12.36,200,2,13.89,2,1,13.93,100,1,14.28,100,1,14.4,100,1,14.5,100,1,14.53,100,1,14.56,800,2,14.6,700,1,14.66,200,2,14.68,1400,2,ARL,312771781
2025-07-17T15:52:16.375414247Z,2025-07-17T15:52:16.375248654Z,160,2,1108,C,A,14.660000000,100,0,308901981,0,165593,261713945,ARL,0,14.66,100,0,165593,261713945,9.55,1700,17,9.68,100,1,10.61,200,2,11.27,100,1,11.4,100,1,11.76,100,1,11.93,200,2,12.23,100,1,12.34,200,2,12.36,200,2,13.89,2,1,13.93,100,1,14.28,100,1,14.4,100,1,14.5,100,1,14.53,100,1,14.56,800,2,14.6,700,1,14.66,100,1,14.68,1400,2,ARL,308901981
2025-07-17T15:52:16.375414247Z,2025-07-17T15:52:16.375248654Z,160,2,1108,A,A,14.890000000,100,0,312771785,130,165593,261713945,ARL,0,14.89,100,130,165593,261713945,9.55,1700,17,9.68,100,1,10.61,200,2,11.27,100,1,11.4,100,1,11.76,100,1,11.93,200,2,12.23,100,1,12.34,200,2,12.36,200,2,13.89,2,1,13.93,100,1,14.28,100,1,14.4,100,1,14.5,100,1,14.53,100,1,14.56,800,2,14.6,700,1,14.66,100,1,14.68,1400,2,ARL,312771785
2025-07-17T15:52:16.375828154Z,2025-07-17T15:52:16.375662552Z,160,2,1108,C,A,14.530000000,100,0,309899141,0,165602,261713959,ARL,0,14.53,100,0,165602,261713959,9.55,1700,17,9.68,100,1,10.61,200,2,11.27,100,1,11.4,100,1,11.76,100,1,11.93,200,2,12.23,100,1,12.34,200,2,12.36,200,2,13.89,2,1,13.93,100,1,14.28,100,1,14.4,100,1,14.5,100,1,14.56,800,2,14.6,700,1,14.66,100,1,14.68,1400,2,14.7,100,1,ARL,309899141
2025-07-17T15:52:16.375828154Z,2025-07-17T15:52:16.375662552Z,160,2,1108,A,A,14.760000000,100,0,312771829,130,165602,261713959,ARL,0,14.76,100,130,165602,261713959,9.55,1700,17,9.68,100,1,10.61,200,2,11.27,100,1,11.4,100,1,11.76,100,1,11.93,200,2,12.23,100,1,12.34,200,2,12.36,200,2,13.89,2,1,13.93,100,1,14.28,100,1,14.4,100,1,14.5,100,1,14.56,800,2,14.6,700,1,14.66,100,1,14.68,1400,2,14.7,100,1,ARL,312771829
2025-07-17T15:52:16.377345053Z,2025-07-17T15:52:16.377179230Z,160,2,1108,C,A,17.280000000,100,0,310446293,0,165823,261714104,ARL,0,17.28,100,0,165823,261714104,9.55,1700,17,9.68,100,1,10.61,200,2,11.27,100,1,11.4,100,1,11.76,100,1,11.93,200,2,12.23,100,1,12.34,200,2,12.36,200,2,13.89,2,1,13.93,100,1,14.28,100,1,14.4,100,1,14.5,100,1,14.56,800,2,14.6,700,1,14.66,100,1,14.68,1400,2,14.7,100,1,ARL,310446293
2025-07-17T15:52:16.377345053Z,2025-07-17T15:52:16.377179230Z,160,2,1108,A,A,17.700000000,100,0,312772009,130,165823,261714104,ARL,0,17.7,100,130,165823,261714104,9.55,1700,17,9.68,100,1,10.61,200,2,11.27,100,1,11.4,100,1,11.76,100,1,11.93,200,2,12.23,100,1,12.34,200,2,12.36,200,2,13.89,2,1,13.93,100,1,14.28,100,1,14.4,100,1,14.5,100,1,14.56,800,2,14.6,700,1,14.66,100,1,14.68,1400,2,14.7,100,1,ARL,312772009
2025-07-17T15:52:16.378239114Z,2025-07-17T15:52:16.378073674Z,160,2,1108,C,A,15.760000000,100,0,308902229,0,165440,261714140,ARL,0,15.76,100,0,165440,261714140,9.55,1700,17,9.68,100,1,10.61,200,2,11.27,100,1,11.4,100,1,11.76,100,1,11.93,200,2,12.23,100,1,12.34,200,2,12.36,200,2,13.89,2,1,13.93,100,1,14.28,100,1,14.4,100,1,14.5,100,1,14.56,800,2,14.6,700,1,14.66,100,1,14.68,1400,2,14.7,100,1,ARL,308902229
2025-07-17T15:52:16.378239114Z,2025-07-17T15:52:16.378073674Z,160,2,1108,A,A,16.020000000,100,0,312772057,130,165440,261714140,ARL,0,16.02,100,130,165440,261714140,9.55,1700,17,9.68,100,1,10.61,200,2,11.27,100,1,11.4,100,1,11.76,100,1,11.93,200,2,12.23,100,1,12.34,200,2,12.36,200,2,13.89,2,1,13.93,100,1,14.28,100,1,14.4,100,1,14.5,100,1,14.56,800,2,14.6,700,1,14.66,100,1,14.68,1400,2,14.7,100,1,ARL,312772057
2025-07-17T15:52:16.378385943Z,2025-07-17T15:52:16.378220434Z,160,2,1108,C,A,14.500000000,100,0,308903349,0,165509,261714145,ARL,0,14.5,100,0,165509,261714145,9.55,1700,17,9.68,100,1,10.61,200,2,11.27,100,1,11.4,100,1,11.76,100,1,11.93,200,2,12.23,100,1,12.34,200,2,12.36,200,2,13.89,2,1,13.93,100,1,14.28,100,1,14.4,100,1,14.56,800,2,14.6,700,1,14.66,100,1,14.68,1400,2,14.7,100,1,14.76,100,1,ARL,308903349
2025-07-17T15:52:16.378385943Z,2025-07-17T15:52:16.378220434Z,160,2,1108,A,A,14.720000000,100,0,312772061,130,165509,261714145,ARL,0,14.72,100,130,165509,261714145,9.55,1700,17,9.68,100,1,10.61,200,2,11.27,100,1,11.4,100,1,11.76,100,1,11.93,200,2,12.23,100,1,12.34,200,2,12.36,200,2,13.89,2,1,13.93,100,1,14.28,100,1,14.4,100,1,14.56,800,2,14.6,700,1,14.66,100,1,14.68,1400,2,14.7,100,1,14.72,100,1,ARL,312772061
2025-07-17T15:52:16.378870638Z,2025-07-17T15:52:16.378705201Z,160,2,1108,A,B,13.270000000,10,0,312772069,130,165437,261714171,ARL,0,13.27,10,130,165437,261714171,9.55,1700,17,9.68,100,1,10.61,200,2,11.27,100,1,11.4,100,1,11.76,100,1,11.93,200,2,12.23,100,1,12.34,200,2,12.36,200,2,13.89,2,1,13.93,100,1,14.28,100,1,14.4,100,1,14.56,800,2,14.6,700,1,14.66,100,1,14.68,1400,2,14.7,100,1,14.72,100,1,ARL,312772069
2025-07-17T15:52:16.378872385Z,2025-07-17T15:52:16.378707041Z,160,2,1108,A,A,13.860000000,15,0,312772073,130,165344,261714172,ARL,0,13.86,15,130,165344,261714172,9.55,1700,17,9.68,100,1,10.61,200,2,11.27,100,1,11.4,100,1,11.76,100,1,11.93,200,2,12.23,100,1,12.34,200,2,12.36,200,2,13.86,15,1,13.89,2,1,13.93,100,1,14.28,100,1,14.4,100,1,14.56,800,2,14.6,700,1,14.66,100,1,14.68,1400,2,14.7,100,1,ARL,312772073
2025-07-17T15:52:16.379127782Z,2025-07-17T15:52:16.378962330Z,160,2,1108,C,B,13.020000000,100,0,309415429,0,165452,261714185,ARL,0,13.02,100,0,165452,261714185,9.55,1700,17,9.68,100,1,10.61,200,2,11.27,100,1,11.4,100,1,11.76,100,1,11.93,200,2,12.23,100,1,12.34,200,2,12.36,200,2,13.86,15,1,13.89,2,1,13.93,100,1,14.28,100,1,14.4,100,1,14.56,800,2,14.6,700,1,14.66,100,1,14.68,1400,2,14.7,100,1,ARL,309415429
2025-07-17T15:52:16.379127782Z,2025-07-17T15:52:16.378962330Z,160,2,1108,A,B,13.260000000,100,0,312772077,130,165452,261714185,ARL,0,13.26,100,130,165452,261714185,9.55,1700,17,9.68,100,1,10.61,200,2,11.27,100,1,11.4,100,1,11.76,100,1,11.93,200,2,12.23,100,1,12.34,200,2,12.36,200,2,13.86,15,1,13.89,2,1,13.93,100,1,14.28,100,1,14.4,100,1,14.56,800,2,14.6,700,1,14.66,100,1,14.68,1400,2,14.7,100,1,ARL,312772077
2025-07-17T15:52:16.389025469Z,2025-07-17T15:52:16.388859982Z,160,2,1108,C,A,13.930000000,100,0,309782973,130,165487,261714477,ARL,0,13.93,100,130,165487,261714477,9.55,1700,17,9.68,100,1,10.61,200,2,11.27,100,1,11.4,100,1,11.76,100,1,11.93,200,2,12.23,100,1,12.34,200,2,12.36,200,2,13.86,15,1,13.89,2,1,14.28,100,1,14.4,100,1,14.56,800,2,14.6,700,1,14.66,100,1,14.68,1400,2,14.7,100,1,14.72,100,1,ARL,309782973
2025-07-17T15:52:16.389082451Z,2025-07-17T15:52:16.388917108Z,160,2,1108,A,A,14.190000000,100,0,312772501,130,165343,261714481,ARL,0,14.19,100,130,165343,261714481,9.55,1700,17,9.68,100,1,10.61,200,2,11.27,100,1,11.4,100,1,11.76,100,1,11.93,200,2,12.23,100,1,12.34,200,2,12.36,200,2,13.86,15,1,13.89,2,1,14.19,100,1,14.28,100,1,14.4,100,1,14.56,800,2,14.6,700,1,14.66,100,1,14.68,1400,2,14.7,100,1,ARL,312772501
2025-07-17T15:52:16.396174502Z,2025-07-17T15:52:16.396008715Z,160,2,1108,C,A,14.660000000,100,0,308903001,0,165787,261714603,ARL,0,14.66,100,0,165787,261714603,9.55,1700,17,9.68,100,1,10.61,200,2,11.27,100,1,11.4,100,1,11.76,100,1,11.93,200,2,12.23,100,1,12.34,200,2,12.36,200,2,13.86,15,1,13.89,2,1,14.19,100,1,14.28,100,1,14.4,100,1,14.56,800,2,14.6,700,1,14.68,1400,2,14.7,100,1,14.72,100,1,ARL,308903001
2025-07-17T15:52:16.396174502Z,2025-07-17T15:52:16.396008715Z,160,2,1108,A,A,14.960000000,100,0,312772869,130,165787,261714603,ARL,0,14.96,100,130,165787,261714603,9.55,1700,17,9.68,100,1,10.61,200,2,11.27,100,1,11.4,100,1,11.76,100,1,11.93,200,2,12.23,100,1,12.34,200,2,12.36,200,2,13.86,15,1,13.89,2,1,14.19,100,1,14.28,100,1,14.4,100,1,14.56,800,2,14.6,700,1,14.68,1400,2,14.7,100,1,14.72,100,1,ARL,312772869
2025-07-17T15:52:16.397677681Z,2025-07-17T15:52:16.397512710Z,160,2,1108,C,A,14.190000000,100,0,312772501,130,164971,261714619,ARL,0,14.19,100,130,164971,261714619,9.55,1700,17,9.68,100,1,10.61,200,2,11.27,100,1,11.4,100,1,11.76,100,1,11.93,200,2,12.23,100,1,12.34,200,2,12.36,200,2,13.86,15,1,13.89,2,1,14.28,100,1,14.4,100,1,14.56,800,2,14.6,700,1,14.68,1400,2,14.7,100,1,14.72,100,1,14.76,100,1,ARL,312772501
2025-07-17T15:52:16.397727042Z,2025-07-17T15:52:16.397561691Z,160,2,1108,A,A,14.260000000,100,0,312772901,130,165351,261714620,ARL,0,14.26,100,130,165351,261714620,9.55,1700,17,9.68,100,1,10.61,200,2,11.27,100,1,11.4,100,1,11.76,100,1,11.93,200,2,12.23,100,1,12.34,200,2,12.36,200,2,13.86,15,1,13.89,2,1,14.26,100,1,14.28,100,1,14.4,100,1,14.56,800,2,14.6,700,1,14.68,1400,2,14.7,100,1,14.72,100,1,ARL,312772901
2025-07-17T15:52:16.424137423Z,2025-07-17T15:52:16.423972000Z,160,2,1108,C,A,14.700000000,100,0,312771573,0,165423,261714976,ARL,0,14.7,100,0,165423,261714976,9.55,1700,17,9.68,100,1,10.61,200,2,11.27,100,1,11.4,100,1,11.76,100,1,11.93,200,2,12.23,100,1,12.34,200,2,12.36,200,2,13.86,15,1,13.89,2,1,14.26,100,1,14.28,100,1,14.4,100,1,14.56,800,2,14.6,700,1,14.68,1400,2,14.72,100,1,14.76,100,1,ARL,312771573
2025-07-17T15:52:16.424137423Z,2025-07-17T15:52:16.423972000Z,160,2,1108,A,A,15.060000000,100,0,312773353,130,165423,261714976,ARL,0,15.06,100,130,165423,261714976,9.55,1700,17,9.68,100,1,10.61,200,2,11.27,100,1,11.4,100,1,11.76,100,1,11.93,200,2,12.23,100,1,12.34,200,2,12.36,200,2,13.86,15,1,13.89,2,1,14.26,100,1,14.28,100,1,14.4,100,1,14.56,800,2,14.6,700,1,14.68,1400,2,14.72,100,1,14.76,100,1,ARL,312773353
2025-07-17T15:52:16.464781343Z,2025-07-17T15:52:16.464616142Z,160,2,1108,A,A,13.870000000,100,0,312773881,130,165201,261715303,ARL,0,13.87,100,130,165201,261715303,9.55,1700,17,9.68,100,1,10.61,200,2,11.27,100,1,11.4,100,1,11.76,100,1,11.93,200,2,12.23,100,1,12.34,200,2,12.36,200,2,13.86,15,1,13.87,100,1,13.89,2,1,14.26,100,1,14.28,100,1,14.4,100,1,14.56,800,2,14.6,700,1,14.68,1400,2,14.72,100,1,ARL,312773881
2025-07-17T15:52:16.473556948Z,2025-07-17T15:52:16.473391480Z,160,2,1108,C,A,15.060000000,100,0,312773353,0,165468,261715409,ARL,0,15.06,100,0,165468,261715409,9.55,1700,17,9.68,100,1,10.61,200,2,11.27,100,1,11.4,100,1,11.76,100,1,11.93,200,2,12.23,100,1,12.34,200,2,12.36,200,2,13.86,15,1,13.87,100,1,13.89,2,1,14.26,100,1,14.28,100,1,14.4,100,1,14.56,800,2,14.6,700,1,14.68,1400,2,14.72,100,1,ARL,312773353
2025-07-17T15:52:16.473556948Z,2025-07-17T15:52:16.473391480Z,160,2,1108,A,A,14.950000000,100,0,312774001,130,165468,261715409,ARL,0,14.95,100,130,165468,261715409,9.55,1700,17,9.68,100,1,10.61,200,2,11.27,100,1,11.4,100,1,11.76,100,1,11.93,200,2,12.23,100,1,12.34,200,2,12.36,200,2,13.86,15,1,13.87,100,1,13.89,2,1,14.26,100,1,14.28,100,1,14.4,100,1,14.56,800,2,14.6,700,1,14.68,1400,2,14.72,100,1,ARL,312774001
2025-07-17T15:52:16.480090894Z,2025-07-17T15:52:16.479925781Z,160,2,1108,C,A,14.260000000,100,0,312772901,130,165113,261715467,ARL,0,14.26,100,130,165113,261715467,9.55,1700,17,9.68,100,1,10.61,200,2,11.27,100,1,11.4,100,1,11.76,100,1,11.93,200,2,12.23,100,1,12.34,200,2,12.36,200,2,13.86,15,1,13.87,100,1,13.89,2,1,14.28,100,1,14.4,100,1,14.56,800,2,14.6,700,1,14.68,1400,2,14.72,100,1,14.76,100,1,ARL,312772901
2025-07-17T15:52:16.480140131Z,2025-07-17T15:52:16.479974840Z,160,2,1108,A,A,14.150000000,100,0,312774033,130,165291,261715468,ARL,0,14.15,100,130,165291,261715468,9.55,1700,17,9.68,100,1,10.61,200,2,11.27,100,1,11.4,100,1,11.76,100,1,11.93,200,2,12.23,100,1,12.34,200,2,12.36,200,2,13.86,15,1,13.87,100,1,13.89,2,1,14.15,100,1,14.28,100,1,14.4,100,1,14.56,800,2,14.6,700,1,14.68,1400,2,14.72,100,1,ARL,312774033
2025-07-17T15:52:28.787316865Z,2025-07-17T15:52:28.787151494Z,160,2,1108,C,B,13.270000000,10,0,312772069,130,165371,261883294,ARL,0,13.27,10,130,165371,261883294,9.55,1700,17,9.68,100,1,10.61,200,2,11.27,100,1,11.4,100,1,11.76,100,1,11.93,200,2,12.23,100,1,12.34,200,2,12.36,200,2,13.86,15,1,13.87,100,1,13.89,2,1,14.15,100,1,14.28,100,1,14.4,100,1,14.56,800,2,14.6,700,1,14.68,1400,2,14.72,100,1,ARL,312772069
2025-07-17T15:52:28.787317827Z,2025-07-17T15:52:28.787152437Z,160,2,1108,C,A,13.860000000,15,0,312772073,130,165390,261883295,ARL,0,13.86,15,130,165390,261883295,9.55,1700,17,9.68,100,1,10.61,200,2,11.27,100,1,11.4,100,1,11.76,100,1,11.93,200,2,12.23,100,1,12.34,200,2,12.36,200,2,13.87,100,1,13.89,2,1,14.15,100,1,14.28,100,1,14.4,100,1,14.56,800,2,14.6,700,1,14.68,1400,2,14.72,100,1,14.76,100,1,ARL,312772073
2025-07-17T15:52:43.128371033Z,2025-07-17T15:52:43.128203357Z,160,2,1108,C,A,13.890000000,2,0,311979125,0,167676,262115170,ARL,0,13.89,2,0,167676,262115170,9.55,1700,17,9.68,100,1,10.61,200,2,11.27,100,1,11.4,100,1,11.76,100,1,11.93,200,2,12.23,100,1,12.34,200,2,12.36,200,2,13.87,100,1,14.15,100,1,14.28,100,1,14.4,100,1,14.56,800,2,14.6,700,1,14.68,1400,2,14.72,100,1,14.76,100,1,14.81,100,1,ARL,311979125
2025-07-17T15:52:43.128371033Z,2025-07-17T15:52:43.128203357Z,160,2,1108,A,A,13.990000000,2,0,313336713,128,167676,262115170,ARL,0,13.99,2,128,167676,262115170,9.55,1700,17,9.68,100,1,10.61,200,2,11.27,100,1,11.4,100,1,11.76,100,1,11.93,200,2,12.23,100,1,12.34,200,2,12.36,200,2,13.87,100,1,13.99,2,1,14.15,100,1,14.28,100,1,14.4,100,1,14.56,800,2,14.6,700,1,14.68,1400,2,14.72,100,1,14.76,100,1,ARL,313336713
2025-07-17T15:54:24.908483782Z,2025-07-17T15:54:24.908318259Z,160,2,1108,A,B,13.290000000,10,0,315581981,130,165523,263863872,ARL,0,13.29,10,130,165523,263863872,9.55,1700,17,9.68,100,1,10.61,200,2,11.27,100,1,11.4,100,1,11.76,100,1,11.93,200,2,12.23,100,1,12.34,200,2,12.36,200,2,13.87,100,1,13.99,2,1,14.15,100,1,14.28,100,1,14.4,100,1,14.56,800,2,14.6,700,1,14.68,1400,2,14.72,100,1,14.76,100,1,ARL,315581981
2025-07-17T15:54:26.792478456Z,2025-07-17T15:54:26.792313320Z,160,2,1108,C,B,13.290000000,10,0,315581981,130,165136,263895481,ARL,0,13.29,10,130,165136,263895481,9.55,1700,17,9.68,100,1,10.61,200,2,11.27,100,1,11.4,100,1,11.76,100,1,11.93,200,2,12.23,100,1,12.34,200,2,12.36,200,2,13.87,100,1,13.99,2,1,14.15,100,1,14.28,100,1,14.4,100,1,14.56,800,2,14.6,700,1,14.68,1400,2,14.72,100,1,14.76,100,1,ARL,315581981
2025-07-17T15:54:52.986116083Z,2025-07-17T15:54:52.985950259Z,160,2,1108,C,A,13.990000000,2,0,313336713,0,165824,264262615,ARL,0,13.99,2,0,165824,264262615,9.55,1700,17,9.68,100,1,10.61,200,2,11.27,100,1,11.4,100,1,11.76,100,1,11.93,200,2,12.23,100,1,12.34,200,2,12.36,200,2,13.87,100,1,14.15,100,1,14.28,100,1,14.4,100,1,14.56,800,2,14.6,700,1,14.68,1400,2,14.72,100,1,14.76,100,1,14.81,100,1,ARL,313336713
2025-07-17T15:54:52.986116083Z,2025-07-17T15:54:52.985950259Z,160,2,1108,A,A,14.100000000,2,0,316098525,130,165824,264262615,ARL,0,14.1,2,130,165824,264262615,9.55,1700,17,9.68,100,1,10.61,200,2,11.27,100,1,11.4,100,1,11.76,100,1,11.93,200,2,12.23,100,1,12.34,200,2,12.36,200,2,13.87,100,1,14.1,2,1,14.15,100,1,14.28,100,1,14.4,100,1,14.56,800,2,14.6,700,1,14.68,1400,2,14.72,100,1,14.76,100,1,ARL,316098525
2025-07-17T15:55:33.673598252Z,2025-07-17T15:55:33.673432762Z,160,2,1108,A,B,13.290000000,10,0,316911465,130,165490,264905534,ARL,0,13.29,10,130,165490,264905534,9.55,1700,17,9.68,100,1,10.61,200,2,11.27,100,1,11.4,100,1,11.76,100,1,11.93,200,2,12.23,100,1,12.34,200,2,12.36,200,2,13.87,100,1,14.1,2,1,14.15,100,1,14.28,100,1,14.4,100,1,14.56,800,2,14.6,700,1,14.68,1400,2,14.72,100,1,14.76,100,1,ARL,316911465
2025-07-17T15:55:34.257417204Z,2025-07-17T15:55:34.257251787Z,160,2,1108,C,B,13.260000000,100,0,312772077,0,165417,264919835,ARL,0,13.26,100,0,165417,264919835,9.55,1700,17,9.68,100,1,10.61,200,2,11.27,100,1,11.4,100,1,11.76,100,1,11.93,200,2,12.23,100,1,12.34,200,2,12.36,200,2,13.87,100,1,14.1,2,1,14.15,100,1,14.28,100,1,14.4,100,1,14.56,800,2,14.6,700,1,14.68,1400,2,14.72,100,1,14.76,100,1,ARL,312772077
2025-07-17T15:55:34.257417204Z,2025-07-17T15:55:34.257251787Z,160,2,1108,A,B,13.280000000,100,0,316924721,130,165417,264919835,ARL,0,13.28,100,130,165417,264919835,9.55,1700,17,9.68,100,1,10.61,200,2,11.27,100,1,11.4,100,1,11.76,100,1,11.93,200,2,12.23,100,1,12.34,200,2,12.36,200,2,13.87,100,1,14.1,2,1,14.15,100,1,14.28,100,1,14.4,100,1,14.56,800,2,14.6,700,1,14.68,1400,2,14.72,100,1,14.76,100,1,ARL,316924721
2025-07-17T15:55:40.197750400Z,2025-07-17T15:55:40.197584524Z,160,2,1108,C,B,13.290000000,10,0,316911465,130,165876,265015966,ARL,0,13.29,10,130,165876,265015966,9.55,1700,17,9.68,100,1,10.61,200,2,11.27,100,1,11.4,100,1,11.76,100,1,11.93,200,2,12.23,100,1,12.34,200,2,12.36,200,2,13.87,100,1,14.1,2,1,14.15,100,1,14.28,100,1,14.4,100,1,14.56,800,2,14.6,700,1,14.68,1400,2,14.72,100,1,14.76,100,1,ARL,316911465
2025-07-17T15:57:51.111288955Z,2025-07-17T15:57:51.111121910Z,160,2,1108,T,N,13.600000000,1,0,0,0,167045,267268162,ARL,0,13.6,1,0,167045,267268162,9.55,1700,17,9.68,100,1,10.61,200,2,11.27,100,1,11.4,100,1,11.76,100,1,11.93,200,2,12.23,100,1,12.34,200,2,12.36,200,2,13.87,100,1,14.1,2,1,14.15,100,1,14.28,100,1,14.4,100,1,14.56,800,2,14.6,700,1,14.68,1400,2,14.72,100,1,14.76,100,1,ARL,0
2025-07-17T15:57:51.111288955Z,2025-07-17T15:57:51.111121910Z,160,2,1108,T,N,13.575000000,99,0,0,130,167045,267268163,ARL,0,13.575,99,130,167045,267268163,9.55,1700,17,9.68,100,1,10.61,200,2,11.27,100,1,11.4,100,1,11.76,100,1,11.93,200,2,12.23,100,1,12.34,200,2,12.36,200,2,13.87,100,1,14.1,2,1,14.15,100,1,14.28,100,1,14.4,100,1,14.56,800,2,14.6,700,1,14.68,1400,2,14.72,100,1,14.76,100,1,ARL,0
2025-07-17T15:57:51.111693755Z,2025-07-17T15:57:51.111527963Z,160,2,1108,T,N,13.575000000,100,0,0,130,165792,267268168,ARL,0,13.575,100,130,165792,267268168,9.55,1700,17,9.68,100,1,10.61,200,2,11.27,100,1,11.4,100,1,11.76,100,1,11.93,200,2,12.23,100,1,12.34,200,2,12.36,200,2,13.87,100,1,14.1,2,1,14.15,100,1,14.28,100,1,14.4,100,1,14.56,800,2,14.6,700,1,14.68,1400,2,14.72,100,1,14.76,100,1,ARL,0
2025-07-17T15:57:51.112077532Z,2025-07-17T15:57:51.111911476Z,160,2,1108,T,N,13.575000000,1,0,0,130,166056,267268183,ARL,0,13.575,1,130,166056,267268183,9.55,1700,17,9.68,100,1,10.61,200,2,11.27,100,1,11.4,100,1,11.76,100,1,11.93,200,2,12.23,100,1,12.34,200,2,12.36,200,2,13.87,100,1,14.1,2,1,14.15,100,1,14.28,100,1,14.4,100,1,14.56,800,2,14.6,700,1,14.68,1400,2,14.72,100,1,14.76,100,1,ARL,0
2025-07-17T15:57:51.328863560Z,2025-07-17T15:57:51.328698198Z,160,2,1108,C,A,13.870000000,100,0,312773881,130,165362,267272430,ARL,0,13.87,100,130,165362,267272430,9.55,1700,17,9.68,100,1,10.61,200,2,11.27,100,1,11.4,100,1,11.76,100,1,11.93,200,2,12.23,100,1,12.34,200,2,12.36,200,2,14.1,2,1,14.15,100,1,14.28,100,1,14.4,100,1,14.56,800,2,14.6,700,1,14.68,1400,2,14.72,100,1,14.76,100,1,14.81,100,1,ARL,312773881
2025-07-17T15:57:51.329613584Z,2025-07-17T15:57:51.329447325Z,160,2,1108,C,A,14.950000000,100,0,312774001,0,166259,267272438,ARL,0,14.95,100,0,166259,267272438,9.55,1700,17,9.68,100,1,10.61,200,2,11.27,100,1,11.4,100,1,11.76,100,1,11.93,200,2,12.23,100,1,12.34,200,2,12.36,200,2,14.1,2,1,14.15,100,1,14.28,100,1,14.4,100,1,14.56,800,2,14.6,700,1,14.68,1400,2,14.72,100,1,14.76,100,1,14.81,100,1,ARL,312774001
2025-07-17T15:57:51.329613584Z,2025-07-17T15:57:51.329447325Z,160,2,1108,A,A,15.000000000,100,0,319985021,130,166259,267272438,ARL,0,15,100,130,166259,267272438,9.55,1700,17,9.68,100,1,10.61,200,2,11.27,100,1,11.4,100,1,11.76,100,1,11.93,200,2,12.23,100,1,12.34,200,2,12.36,200,2,14.1,2,1,14.15,100,1,14.28,100,1,14.4,100,1,14.56,800,2,14.6,700,1,14.68,1400,2,14.72,100,1,14.76,100,1,14.81,100,1,ARL,319985021
2025-07-17T15:57:51.329857672Z,2025-07-17T15:57:51.329692071Z,160,2,1108,C,A,14.760000000,100,0,312771829,0,165601,267272442,ARL,0,14.76,100,0,165601,267272442,9.55,1700,17,9.68,100,1,10.61,200,2,11.27,100,1,11.4,100,1,11.76,100,1,11.93,200,2,12.23,100,1,12.34,200,2,12.36,200,2,14.1,2,1,14.15,100,1,14.28,100,1,14.4,100,1,14.56,800,2,14.6,700,1,14.68,1400,2,14.72,100,1,14.81,100,1,14.89,100,1,ARL,312771829
2025-07-17T15:57:51.329857672Z,2025-07-17T15:57:51.329692071Z,160,2,1108,A,A,14.890000000,100,0,319985025,130,165601,267272442,ARL,0,14.89,100,130,165601,267272442,9.55,1700,17,9.68,100,1,10.61,200,2,11.27,100,1,11.4,100,1,11.76,100,1,11.93,200,2,12.23,100,1,12.34,200,2,12.36,200,2,14.1,2,1,14.15,100,1,14.28,100,1,14.4,100,1,14.56,800,2,14.6,700,1,14.68,1400,2,14.72,100,1,14.81,100,1,14.89,200,2,ARL,319985025
2025-07-17T15:57:51.339328219Z,2025-07-17T15:57:51.339162512Z,160,2,1108,C,A,14.150000000,100,0,312774033,130,165707,267272660,ARL,0,14.15,100,130,165707,267272660,9.55,1700,17,9.68,100,1,10.61,200,2,11.27,100,1,11.4,100,1,11.76,100,1,11.93,200,2,12.23,100,1,12.34,200,2,12.36,200,2,14.1,2,1,14.28,100,1,14.4,100,1,14.56,800,2,14.6,700,1,14.68,1400,2,14.72,100,1,14.81,100,1,14.89,200,2,14.96,100,1,ARL,312774033
2025-07-17T15:57:51.339382098Z,2025-07-17T15:57:51.339216923Z,160,2,1108,A,A,14.260000000,100,0,319985165,130,165175,267272665,ARL,0,14.26,100,130,165175,267272665,9.55,1700,17,9.68,100,1,10.61,200,2,11.27,100,1,11.4,100,1,11.76,100,1,11.93,200,2,12.23,100,1,12.34,200,2,12.36,200,2,14.1,2,1,14.26,100,1,14.28,100,1,14.4,100,1,14.56,800,2,14.6,700,1,14.68,1400,2,14.72,100,1,14.81,100,1,14.89,200,2,ARL,319985165
2025-07-17T15:57:51.379736852Z,2025-07-17T15:57:51.379570470Z,160,2,1108,C,A,15.000000000,100,0,319985021,0,166382,267273071,ARL,0,15,100,0,166382,267273071,9.55,1700,17,9.68,100,1,10.61,200,2,11.27,100,1,11.4,100,1,11.76,100,1,11.93,200,2,12.23,100,1,12.34,200,2,12.36,200,2,14.1,2,1,14.26,100,1,14.28,100,1,14.4,100,1,14.56,800,2,14.6,700,1,14.68,1400,2,14.72,100,1,14.81,100,1,14.89,200,2,ARL,319985021
2025-07-17T15:57:51.379736852Z,2025-07-17T15:57:51.379570470Z,160,2,1108,A,A,15.060000000,100,0,319985497,128,166382,267273071,ARL,0,15.06,100,128,166382,267273071,9.55,1700,17,9.68,100,1,10.61,200,2,11.27,100,1,11.4,100,1,11.76,100,1,11.93,200,2,12.23,100,1,12.34,200,2,12.36,200,2,14.1,2,1,14.26,100,1,14.28,100,1,14.4,100,1,14.56,800,2,14.6,700,1,14.68,1400,2,14.72,100,1,14.81,100,1,14.89,200,2,ARL,319985497
2025-07-17T15:57:52.378369524Z,2025-07-17T15:57:52.378204338Z,160,2,1108,A,A,14.110000000,100,0,320000233,130,165186,267283873,ARL,0,14.11,100,130,165186,267283873,9.55,1700,17,9.68,100,1,10.61,200,2,11.27,100,1,11.4,100,1,11.76,100,1,11.93,200,2,12.23,100,1,12.34,200,2,12.36,200,2,14.1,2,1,14.11,100,1,14.26,100,1,14.28,100,1,14.4,100,1,14.56,800,2,14.6,700,1,14.68,1400,2,14.72,100,1,14.81,100,1,ARL,320000233
2025-07-17T15:58:14.483879079Z,2025-07-17T15:58:14.483712278Z,160,2,1108,T,N,13.410000000,44,0,0,130,166801,267657010,ARL,0,13.41,44,130,166801,267657010,9.55,1700,17,9.68,100,1,10.61,200,2,11.27,100,1,11.4,100,1,11.76,100,1,11.93,200,2,12.23,100,1,12.34,200,2,12.36,200,2,14.1,2,1,14.11,100,1,14.26,100,1,14.28,100,1,14.4,100,1,14.56,800,2,14.6,700,1,14.68,1400,2,14.72,100,1,14.81,100,1,ARL,0
2025-07-17T15:58:14.483909354Z,2025-07-17T15:58:14.483743947Z,160,2,1108,A,A,13.760000000,4,0,320484625,130,165407,267657011,ARL,0,13.76,4,130,165407,267657011,9.55,1700,17,9.68,100,1,10.61,200,2,11.27,100,1,11.4,100,1,11.76,100,1,11.93,200,2,12.23,100,1,12.34,200,2,12.36,200,2,13.76,4,1,14.1,2,1,14.11,100,1,14.26,100,1,14.28,100,1,14.4,100,1,14.56,800,2,14.6,700,1,14.68,1400,2,14.72,100,1,ARL,320484625
2025-07-17T15:58:14.484164551Z,2025-07-17T15:58:14.483999049Z,160,2,1108,C,A,14.110000000,100,0,320000233,0,165502,267657013,ARL,0,14.11,100,0,165502,267657013,9.55,1700,17,9.68,100,1,10.61,200,2,11.27,100,1,11.4,100,1,11.76,100,1,11.93,200,2,12.23,100,1,12.34,200,2,12.36,200,2,13.76,4,1,14.1,2,1,14.26,100,1,14.28,100,1,14.4,100,1,14.56,800,2,14.6,700,1,14.68,1400,2,14.72,100,1,14.81,100,1,ARL,320000233
2025-07-17T15:58:14.484164551Z,2025-07-17T15:58:14.483999049Z,160,2,1108,A,A,13.770000000,100,0,320484637,130,165502,267657013,ARL,0,13.77,100,130,165502,267657013,9.55,1700,17,9.68,100,1,10.61,200,2,11.27,100,1,11.4,100,1,11.76,100,1,11.93,200,2,12.23,100,1,12.34,200,2,12.36,200,2,13.76,4,1,13.77,100,1,14.1,2,1,14.26,100,1,14.28,100,1,14.4,100,1,14.56,800,2,14.6,700,1,14.68,1400,2,14.72,100,1,ARL,320484637
2025-07-17T15:58:14.484183413Z,2025-07-17T15:58:14.484017806Z,160,2,1108,C,B,13.280000000,100,0,316924721,130,165607,267657014,ARL,0,13.28,100,130,165607,267657014,9.55,1700,17,9.68,100,1,10.61,200,2,11.27,100,1,11.4,100,1,11.76,100,1,11.93,200,2,12.23,100,1,12.34,200,2,12.36,200,2,13.76,4,1,13.77,100,1,14.1,2,1,14.26,100,1,14.28,100,1,14.4,100,1,14.56,800,2,14.6,700,1,14.68,1400,2,14.72,100,1,ARL,316924721
2025-07-17T15:58:14.484299450Z,2025-07-17T15:58:14.484133730Z,160,2,1108,T,N,13.410000000,8,0,0,130,165720,267657017,ARL,0,13.41,8,130,165720,267657017,9.55,1700,17,9.68,100,1,10.61,200,2,11.27,100,1,11.4,100,1,11.76,100,1,11.93,200,2,12.23,100,1,12.34,200,2,12.36,200,2,13.76,4,1,13.77,100,1,14.1,2,1,14.26,100,1,14.28,100,1,14.4,100,1,14.56,800,2,14.6,700,1,14.68,1400,2,14.72,100,1,ARL,0
2025-07-17T15:58:14.484312532Z,2025-07-17T15:58:14.484147359Z,160,2,1108,A,A,13.790000000,100,0,320484661,130,165173,267657020,ARL,0,13.79,100,130,165173,267657020,9.55,1700,17,9.68,100,1,10.61,200,2,11.27,100,1,11.4,100,1,11.76,100,1,11.93,200,2,12.23,100,1,12.34,200,2,12.36,200,2,13.76,4,1,13.77,100,1,13.79,100,1,14.1,2,1,14.26,100,1,14.28,100,1,14.4,100,1,14.56,800,2,14.6,700,1,14.68,1400,2,ARL,320484661
2025-07-17T15:58:14.484902175Z,2025-07-17T15:58:14.484736787Z,160,2,1108,C,A,15.060000000,100,0,319985497,0,165388,267657063,ARL,0,15.06,100,0,165388,267657063,9.55,1700,17,9.68,100,1,10.61,200,2,11.27,100,1,11.4,100,1,11.76,100,1,11.93,200,2,12.23,100,1,12.34,200,2,12.36,200,2,13.76,4,1,13.77,100,1,13.79,100,1,14.1,2,1,14.26,100,1,14.28,100,1,14.4,100,1,14.56,800,2,14.6,700,1,14.68,1400,2,ARL,319985497
2025-07-17T15:58:14.484902175Z,2025-07-17T15:58:14.484736787Z,160,2,1108,A,A,14.840000000,100,0,320484709,130,165388,267657063,ARL,0,14.84,100,130,165388,267657063,9.55,1700,17,9.68,100,1,10.61,200,2,11.27,100,1,11.4,100,1,11.76,100,1,11.93,200,2,12.23,100,1,12.34,200,2,12.36,200,2,13.76,4,1,13.77,100,1,13.79,100,1,14.1,2,1,14.26,100,1,14.28,100,1,14.4,100,1,14.56,800,2,14.6,700,1,14.68,1400,2,ARL,320484709
2025-07-17T15:58:14.484927848Z,2025-07-17T15:58:14.484761664Z,160,2,1108,C,A,13.760000000,4,0,320484625,128,166184,267657070,ARL,0,13.76,4,128,166184,267657070,9.55,1700,17,9.68,100,1,10.61,200,2,11.27,100,1,11.4,100,1,11.76,100,1,11.93,200,2,12.23,100,1,12.34,200,2,12.36,200,2,13.77,100,1,13.79,100,1,14.1,2,1,14.26,100,1,14.28,100,1,14.4,100,1,14.56,800,2,14.6,700,1,14.68,1400,2,14.72,100,1,ARL,320484625
2025-07-17T15:58:14.484963870Z,2025-07-17T15:58:14.484798779Z,160,2,1108,C,A,13.770000000,100,0,320484637,130,165091,267657073,ARL,0,13.77,100,130,165091,267657073,9.55,1700,17,9.68,100,1,10.61,200,2,11.27,100,1,11.4,100,1,11.76,100,1,11.93,200,2,12.23,100,1,12.34,200,2,12.36,200,2,13.79,100,1,14.1,2,1,14.26,100,1,14.28,100,1,14.4,100,1,14.56,800,2,14.6,700,1,14.68,1400,2,14.72,100,1,14.81,100,1,ARL,320484637
2025-07-17T15:58:14.485392903Z,2025-07-17T15:58:14.485227487Z,160,2,1108,C,A,14.810000000,100,0,312771781,0,165416,267657092,ARL,0,14.81,100,0,165416,267657092,9.55,1700,17,9.68,100,1,10.61,200,2,11.27,100,1,11.4,100,1,11.76,100,1,11.93,200,2,12.23,100,1,12.34,200,2,12.36,200,2,13.79,100,1,14.1,2,1,14.26,100,1,14.28,100,1,14.4,100,1,14.56,800,2,14.6,700,1,14.68,1400,2,14.72,100,1,14.84,100,1,ARL,312771781
2025-07-17T15:58:14.485392903Z,2025-07-17T15:58:14.485227487Z,160,2,1108,A,A,14.680000000,100,0,320484781,130,165416,267657092,ARL,0,14.68,100,130,165416,267657092,9.55,1700,17,9.68,100,1,10.61,200,2,11.27,100,1,11.4,100,1,11.76,100,1,11.93,200,2,12.23,100,1,12.34,200,2,12.36,200,2,13.79,100,1,14.1,2,1,14.26,100,1,14.28,100,1,14.4,100,1,14.56,800,2,14.6,700,1,14.68,1500,3,14.72,100,1,14.84,100,1,ARL,320484781
2025-07-17T15:58:14.485831602Z,2025-07-17T15:58:14.485666254Z,160,2,1108,C,A,16.020000000,100,0,312772057,0,165348,267657097,ARL,0,16.02,100,0,165348,267657097,9.55,1700,17,9.68,100,1,10.61,200,2,11.27,100,1,11.4,100,1,11.76,100,1,11.93,200,2,12.23,100,1,12.34,200,2,12.36,200,2,13.79,100,1,14.1,2,1,14.26,100,1,14.28,100,1,14.4,100,1,14.56,800,2,14.6,700,1,14.68,1500,3,14.72,100,1,14.84,100,1,ARL,312772057
2025-07-17T15:58:14.485831602Z,2025-07-17T15:58:14.485666254Z,160,2,1108,A,A,15.860000000,100,0,320484817,130,165348,267657097,ARL,0,15.86,100,130,165348,267657097,9.55,1700,17,9.68,100,1,10.61,200,2,11.27,100,1,11.4,100,1,11.76,100,1,11.93,200,2,12.23,100,1,12.34,200,2,12.36,200,2,13.79,100,1,14.1,2,1,14.26,100,1,14.28,100,1,14.4,100,1,14.56,800,2,14.6,700,1,14.68,1500,3,14.72,100,1,14.84,100,1,ARL,320484817
2025-07-17T15:58:14.485850874Z,2025-07-17T15:58:14.485685308Z,160,2,1108,C,A,14.960000000,100,0,312772869,0,165566,267657098,ARL,0,14.96,100,0,165566,267657098,9.55,1700,17,9.68,100,1,10.61,200,2,11.27,100,1,11.4,100,1,11.76,100,1,11.93,200,2,12.23,100,1,12.34,200,2,12.36,200,2,13.79,100,1,14.1,2,1,14.26,100,1,14.28,100,1,14.4,100,1,14.56,800,2,14.6,700,1,14.68,1500,3,14.72,100,1,14.84,100,1,ARL,312772869
2025-07-17T15:58:14.485850874Z,2025-07-17T15:58:14.485685308Z,160,2,1108,A,A,14.760000000,100,0,320484821,130,165566,267657098,ARL,0,14.76,100,130,165566,267657098,9.55,1700,17,9.68,100,1,10.61,200,2,11.27,100,1,11.4,100,1,11.76,100,1,11.93,200,2,12.23,100,1,12.34,200,2,12.36,200,2,13.79,100,1,14.1,2,1,14.26,100,1,14.28,100,1,14.4,100,1,14.56,800,2,14.6,700,1,14.68,1500,3,14.72,100,1,14.76,100,1,ARL,320484821
2025-07-17T15:58:14.485989643Z,2025-07-17T15:58:14.485824228Z,160,2,1108,C,A,14.890000000,100,0,319985025,0,165415,267657101,ARL,0,14.89,100,0,165415,267657101,9.55,1700,17,9.68,100,1,10.61,200,2,11.27,100,1,11.4,100,1,11.76,100,1,11.93,200,2,12.23,100,1,12.34,200,2,12.36,200,2,13.79,100,1,14.1,2,1,14.26,100,1,14.28,100,1,14.4,100,1,14.56,800,2,14.6,700,1,14.68,1500,3,14.72,100,1,14.76,100,1,ARL,319985025
2025-07-17T15:58:14.485989643Z,2025-07-17T15:58:14.485824228Z,160,2,1108,A,A,14.690000000,100,0,320484825,130,165415,267657101,ARL,0,14.69,100,130,165415,267657101,9.55,1700,17,9.68,100,1,10.61,200,2,11.27,100,1,11.4,100,1,11.76,100,1,11.93,200,2,12.23,100,1,12.34,200,2,12.36,200,2,13.79,100,1,14.1,2,1,14.26,100,1,14.28,100,1,14.4,100,1,14.56,800,2,14.6,700,1,14.68,1500,3,14.69,100,1,14.72,100,1,ARL,320484825
2025-07-17T15:58:14.486406355Z,2025-07-17T15:58:14.486240860Z,160,2,1108,C,A,17.700000000,100,0,312772009,0,165495,267657116,ARL,0,17.7,100,0,165495,267657116,9.55,1700,17,9.68,100,1,10.61,200,2,11.27,100,1,11.4,100,1,11.76,100,1,11.93,200,2,12.23,100,1,12.34,200,2,12.36,200,2,13.79,100,1,14.1,2,1,14.26,100,1,14.28,100,1,14.4,100,1,14.56,800,2,14.6,700,1,14.68,1500,3,14.69,100,1,14.72,100,1,ARL,312772009
2025-07-17T15:58:14.486406355Z,2025-07-17T15:58:14.486240860Z,160,2,1108,A,A,17.520000000,100,0,320484837,130,165495,267657116,ARL,0,17.52,100,130,165495,267657116,9.55,1700,17,9.68,100,1,10.61,200,2,11.27,100,1,11.4,100,1,11.76,100,1,11.93,200,2,12.23,100,1,12.34,200,2,12.36,200,2,13.79,100,1,14.1,2,1,14.26,100,1,14.28,100,1,14.4,100,1,14.56,800,2,14.6,700,1,14.68,1500,3,14.69,100,1,14.72,100,1,ARL,320484837
2025-07-17T15:58:14.508177256Z,2025-07-17T15:58:14.508012098Z,160,2,1108,C,A,14.260000000,100,0,319985165,130,165158,267657330,ARL,0,14.26,100,130,165158,267657330,9.55,1700,17,9.68,100,1,10.61,200,2,11.27,100,1,11.4,100,1,11.76,100,1,11.93,200,2,12.23,100,1,12.34,200,2,12.36,200,2,13.79,100,1,14.1,2,1,14.28,100,1,14.4,100,1,14.56,800,2,14.6,700,1,14.68,1500,3,14.69,100,1,14.72,100,1,14.76,100,1,ARL,319985165
2025-07-17T15:58:14.508227890Z,2025-07-17T15:58:14.508062605Z,160,2,1108,A,A,14.050000000,100,0,320484985,130,165285,267657333,ARL,0,14.05,100,130,165285,267657333,9.55,1700,17,9.68,100,1,10.61,200,2,11.27,100,1,11.4,100,1,11.76,100,1,11.93,200,2,12.23,100,1,12.34,200,2,12.36,200,2,13.79,100,1,14.05,100,1,14.1,2,1,14.28,100,1,14.4,100,1,14.56,800,2,14.6,700,1,14.68,1500,3,14.69,100,1,14.72,100,1,ARL,320484985
2025-07-17T15:58:14.529557108Z,2025-07-17T15:58:14.529391743Z,160,2,1108,A,B,13.020000000,100,0,320485385,130,165365,267657561,ARL,0,13.02,100,130,165365,267657561,9.55,1700,17,9.68,100,1,10.61,200,2,11.27,100,1,11.4,100,1,11.76,100,1,11.93,200,2,12.23,100,1,12.34,200,2,12.36,200,2,13.79,100,1,14.05,100,1,14.1,2,1,14.28,100,1,14.4,100,1,14.56,800,2,14.6,700,1,14.68,1500,3,14.69,100,1,14.72,100,1,ARL,320485385
2025-07-17T15:58:14.529578291Z,2025-07-17T15:58:14.529413184Z,160,2,1108,A,A,13.800000000,100,0,320485389,130,165107,267657562,ARL,0,13.8,100,130,165107,267657562,9.55,1700,17,9.68,100,1,10.61,200,2,11.27,100,1,11.4,100,1,11.76,100,1,11.93,200,2,12.23,100,1,12.34,200,2,12.36,200,2,13.79,100,1,13.8,100,1,14.05,100,1,14.1,2,1,14.28,100,1,14.4,100,1,14.56,800,2,14.6,700,1,14.68,1500,3,14.69,100,1,ARL,320485389
2025-07-17T15:58:14.659899426Z,2025-07-17T15:58:14.659734381Z,160,2,1108,C,A,13.790000000,100,0,320484661,130,165045,267658873,ARL,0,13.79,100,130,165045,267658873,9.55,1700,17,9.68,100,1,10.61,200,2,11.27,100,1,11.4,100,1,11.76,100,1,11.93,200,2,12.23,100,1,12.34,200,2,12.36,200,2,13.8,100,1,14.05,100,1,14.1,2,1,14.28,100,1,14.4,100,1,14.56,800,2,14.6,700,1,14.68,1500,3,14.69,100,1,14.72,100,1,ARL,320484661
2025-07-17T15:58:14.659939230Z,2025-07-17T15:58:14.659773896Z,160,2,1108,C,A,13.800000000,100,0,320485389,130,165334,267658879,ARL,0,13.8,100,130,165334,267658879,9.55,1700,17,9.68,100,1,10.61,200,2,11.27,100,1,11.4,100,1,11.76,100,1,11.93,200,2,12.23,100,1,12.34,200,2,12.36,200,2,14.05,100,1,14.1,2,1,14.28,100,1,14.4,100,1,14.56,800,2,14.6,700,1,14.68,1500,3,14.69,100,1,14.72,100,1,14.76,100,1,ARL,320485389
2025-07-17T15:58:14.660667636Z,2025-07-17T15:58:14.660502341Z,160,2,1108,C,A,14.840000000,100,0,320484709,0,165295,267658892,ARL,0,14.84,100,0,165295,267658892,9.55,1700,17,9.68,100,1,10.61,200,2,11.27,100,1,11.4,100,1,11.76,100,1,11.93,200,2,12.23,100,1,12.34,200,2,12.36,200,2,14.05,100,1,14.1,2,1,14.28,100,1,14.4,100,1,14.56,800,2,14.6,700,1,14.68,1500,3,14.69,100,1,14.72,100,1,14.76,100,1,ARL,320484709
2025-07-17T15:58:14.660667636Z,2025-07-17T15:58:14.660502341Z,160,2,1108,A,A,14.910000000,100,0,320486925,130,165295,267658892,ARL,0,14.91,100,130,165295,267658892,9.55,1700,17,9.68,100,1,10.61,200,2,11.27,100,1,11.4,100,1,11.76,100,1,11.93,200,2,12.23,100,1,12.34,200,2,12.36,200,2,14.05,100,1,14.1,2,1,14.28,100,1,14.4,100,1,14.56,800,2,14.6,700,1,14.68,1500,3,14.69,100,1,14.72,100,1,14.76,100,1,ARL,320486925
2025-07-17T15:58:14.664378962Z,2025-07-17T15:58:14.664213722Z,160,2,1108,C,A,17.520000000,100,0,320484837,0,165240,267658928,ARL,0,17.52,100,0,165240,267658928,9.55,1700,17,9.68,100,1,10.61,200,2,11.27,100,1,11.4,100,1,11.76,100,1,11.93,200,2,12.23,100,1,12.34,200,2,12.36,200,2,14.05,100,1,14.1,2,1,14.28,100,1,14.4,100,1,14.56,800,2,14.6,700,1,14.68,1500,3,14.69,100,1,14.72,100,1,14.76,100,1,ARL,320484837
2025-07-17T15:58:14.664378962Z,2025-07-17T15:58:14.664213722Z,160,2,1108,A,A,17.760000000,100,0,320486937,130,165240,267658928,ARL,0,17.76,100,130,165240,267658928,9.55,1700,17,9.68,100,1,10.61,200,2,11.27,100,1,11.4,100,1,11.76,100,1,11.93,200,2,12.23,100,1,12.34,200,2,12.36,200,2,14.05,100,1,14.1,2,1,14.28,100,1,14.4,100,1,14.56,800,2,14.6,700,1,14.68,1500,3,14.69,100,1,14.72,100,1,14.76,100,1,ARL,320486937
2025-07-17T15:58:14.664939310Z,2025-07-17T15:58:14.664774078Z,160,2,1108,C,A,15.860000000,100,0,320484817,0,165232,267658931,ARL,0,15.86,100,0,165232,267658931,9.55,1700,17,9.68,100,1,10.61,200,2,11.27,100,1,11.4,100,1,11.76,100,1,11.93,200,2,12.23,100,1,12.34,200,2,12.36,200,2,14.05,100,1,14.1,2,1,14.28,100,1,14.4,100,1,14.56,800,2,14.6,700,1,14.68,1500,3,14.69,100,1,14.72,100,1,14.76,100,1,ARL,320484817
2025-07-17T15:58:14.664939310Z,2025-07-17T15:58:14.664774078Z,160,2,1108,A,A,16.080000000,100,0,320486945,130,165232,267658931,ARL,0,16.08,100,130,165232,267658931,9.55,1700,17,9.68,100,1,10.61,200,2,11.27,100,1,11.4,100,1,11.76,100,1,11.93,200,2,12.23,100,1,12.34,200,2,12.36,200,2,14.05,100,1,14.1,2,1,14.28,100,1,14.4,100,1,14.56,800,2,14.6,700,1,14.68,1500,3,14.69,100,1,14.72,100,1,14.76,100,1,ARL,320486945
2025-07-17T15:58:14.672315806Z,2025-07-17T15:58:14.672150755Z,160,2,1108,C,A,14.050000000,100,0,320484985,130,165051,267658982,ARL,0,14.05,100,130,165051,267658982,9.55,1700,17,9.68,100,1,10.61,200,2,11.27,100,1,11.4,100,1,11.76,100,1,11.93,200,2,12.23,100,1,12.34,200,2,12.36,200,2,14.1,2,1,14.28,100,1,14.4,100,1,14.56,800,2,14.6,700,1,14.68,1500,3,14.69,100,1,14.72,100,1,14.76,100,1,14.89,100,1,ARL,320484985
2025-07-17T15:58:14.672365974Z,2025-07-17T15:58:14.672200872Z,160,2,1108,A,A,14.120000000,100,0,320487017,130,165102,267658983,ARL,0,14.12,100,130,165102,267658983,9.55,1700,17,9.68,100,1,10.61,200,2,11.27,100,1,11.4,100,1,11.76,100,1,11.93,200,2,12.23,100,1,12.34,200,2,12.36,200,2,14.1,2,1,14.12,100,1,14.28,100,1,14.4,100,1,14.56,800,2,14.6,700,1,14.68,1500,3,14.69,100,1,14.72,100,1,14.76,100,1,ARL,320487017
2025-07-17T15:58:14.673184116Z,2025-07-17T15:58:14.673019194Z,160,2,1108,C,A,14.120000000,100,0,320487017,130,164922,267658989,ARL,0,14.12,100,130,164922,267658989,9.55,1700,17,9.68,100,1,10.61,200,2,11.27,100,1,11.4,100,1,11.76,100,1,11.93,200,2,12.23,100,1,12.34,200,2,12.36,200,2,14.1,2,1,14.28,100,1,14.4,100,1,14.56,800,2,14.6,700,1,14.68,1500,3,14.69,100,1,14.72,100,1,14.76,100,1,14.89,100,1,ARL,320487017
2025-07-17T15:58:14.673230480Z,2025-07-17T15:58:14.673065320Z,160,2,1108,A,A,14.260000000,100,0,320487025,130,165160,267658990,ARL,0,14.26,100,130,165160,267658990,9.55,1700,17,9.68,100,1,10.61,200,2,11.27,100,1,11.4,100,1,11.76,100,1,11.93,200,2,12.23,100,1,12.34,200,2,12.36,200,2,14.1,2,1,14.26,100,1,14.28,100,1,14.4,100,1,14.56,800,2,14.6,700,1,14.68,1500,3,14.69,100,1,14.72,100,1,14.76,100,1,ARL,320487025
2025-07-17T15:58:14.682945541Z,2025-07-17T15:58:14.682780396Z,160,2,1108,C,A,14.760000000,100,0,320484821,0,165145,267659018,ARL,0,14.76,100,0,165145,267659018,9.55,1700,17,9.68,100,1,10.61,200,2,11.27,100,1,11.4,100,1,11.76,100,1,11.93,200,2,12.23,100,1,12.34,200,2,12.36,200,2,14.1,2,1,14.26,100,1,14.28,100,1,14.4,100,1,14.56,800,2,14.6,700,1,14.68,1500,3,14.69,100,1,14.72,100,1,14.89,100,1,ARL,320484821
2025-07-17T15:58:14.682945541Z,2025-07-17T15:58:14.682780396Z,160,2,1108,A,A,14.960000000,100,0,320487105,130,165145,267659018,ARL,0,14.96,100,130,165145,267659018,9.55,1700,17,9.68,100,1,10.61,200,2,11.27,100,1,11.4,100,1,11.76,100,1,11.93,200,2,12.23,100,1,12.34,200,2,12.36,200,2,14.1,2,1,14.26,100,1,14.28,100,1,14.4,100,1,14.56,800,2,14.6,700,1,14.68,1500,3,14.69,100,1,14.72,100,1,14.89,100,1,ARL,320487105
2025-07-17T15:58:14.710787891Z,2025-07-17T15:58:14.710622495Z,160,2,1108,C,A,14.910000000,100,0,320486925,0,165396,267659178,ARL,0,14.91,100,0,165396,267659178,9.55,1700,17,9.68,100,1,10.61,200,2,11.27,100,1,11.4,100,1,11.76,100,1,11.93,200,2,12.23,100,1,12.34,200,2,12.36,200,2,14.1,2,1,14.26,100,1,14.28,100,1,14.4,100,1,14.56,800,2,14.6,700,1,14.68,1500,3,14.69,100,1,14.72,100,1,14.89,100,1,ARL,320486925
2025-07-17T15:58:14.710787891Z,2025-07-17T15:58:14.710622495Z,160,2,1108,A,A,15.060000000,100,0,320487357,130,165396,267659178,ARL,0,15.06,100,130,165396,267659178,9.55,1700,17,9.68,100,1,10.61,200,2,11.27,100,1,11.4,100,1,11.76,100,1,11.93,200,2,12.23,100,1,12.34,200,2,12.36,200,2,14.1,2,1,14.26,100,1,14.28,100,1,14.4,100,1,14.56,800,2,14.6,700,1,14.68,1500,3,14.69,100,1,14.72,100,1,14.89,100,1,ARL,320487357
2025-07-17T15:58:15.564070256Z,2025-07-17T15:58:15.563904700Z,160,2,1108,C,A,14.680000000,100,0,320484781,0,165556,267672469,ARL,0,14.68,100,0,165556,267672469,9.55,1700,17,9.68,100,1,10.61,200,2,11.27,100,1,11.4,100,1,11.76,100,1,11.93,200,2,12.23,100,1,12.34,200,2,12.36,200,2,14.1,2,1,14.26,100,1,14.28,100,1,14.4,100,1,14.56,800,2,14.6,700,1,14.68,1400,2,14.69,100,1,14.72,100,1,14.89,100,1,ARL,320484781
2025-07-17T15:58:15.564070256Z,2025-07-17T15:58:15.563904700Z,160,2,1108,A,A,14.870000000,100,0,320504473,130,165556,267672469,ARL,0,14.87,100,130,165556,267672469,9.55,1700,17,9.68,100,1,10.61,200,2,11.27,100,1,11.4,100,1,11.76,100,1,11.93,200,2,12.23,100,1,12.34,200,2,12.36,200,2,14.1,2,1,14.26,100,1,14.28,100,1,14.4,100,1,14.56,800,2,14.6,700,1,14.68,1400,2,14.69,100,1,14.72,100,1,14.87,100,1,ARL,320504473
2025-07-17T15:58:15.577719796Z,2025-07-17T15:58:15.577554368Z,160,2,1108,C,A,14.690000000,100,0,320484825,0,165428,267672549,ARL,0,14.69,100,0,165428,267672549,9.55,1700,17,9.68,100,1,10.61,200,2,11.27,100,1,11.4,100,1,11.76,100,1,11.93,200,2,12.23,100,1,12.34,200,2,12.36,200,2,14.1,2,1,14.26,100,1,14.28,100,1,14.4,100,1,14.56,800,2,14.6,700,1,14.68,1400,2,14.72,100,1,14.87,100,1,14.89,100,1,ARL,320484825
2025-07-17T15:58:15.577719796Z,2025-07-17T15:58:15.577554368Z,160,2,1108,A,A,14.880000000,100,0,320504609,130,165428,267672549,ARL,0,14.88,100,130,165428,267672549,9.55,1700,17,9.68,100,1,10.61,200,2,11.27,100,1,11.4,100,1,11.76,100,1,11.93,200,2,12.23,100,1,12.34,200,2,12.36,200,2,14.1,2,1,14.26,100,1,14.28,100,1,14.4,100,1,14.56,800,2,14.6,700,1,14.68,1400,2,14.72,100,1,14.87,100,1,14.88,100,1,ARL,320504609
2025-07-17T15:58:16.502080515Z,2025-07-17T15:58:16.501915292Z,160,2,1108,A,A,14.110000000,100,0,320519893,130,165223,267685252,ARL,0,14.11,100,130,165223,267685252,9.55,1700,17,9.68,100,1,10.61,200,2,11.27,100,1,11.4,100,1,11.76,100,1,11.93,200,2,12.23,100,1,12.34,200,2,12.36,200,2,14.1,2,1,14.11,100,1,14.26,100,1,14.28,100,1,14.4,100,1,14.56,800,2,14.6,700,1,14.68,1400,2,14.72,100,1,14.87,100,1,ARL,320519893
2025-07-17T15:58:19.965200980Z,2025-07-17T15:58:19.965034325Z,160,2,1108,A,A,13.940000000,15,0,320588689,130,166655,267738403,ARL,0,13.94,15,130,166655,267738403,9.55,1700,17,9.68,100,1,10.61,200,2,11.27,100,1,11.4,100,1,11.76,100,1,11.93,200,2,12.23,100,1,12.34,200,2,12.36,200,2,13.94,15,1,14.1,2,1,14.11,100,1,14.26,100,1,14.28,100,1,14.4,100,1,14.56,800,2,14.6,700,1,14.68,1400,2,14.72,100,1,ARL,320588689
2025-07-17T15:58:20.237833402Z,2025-07-17T15:58:20.237668047Z,160,2,1108,C,A,14.110000000,100,0,320519893,0,165355,267745213,ARL,0,14.11,100,0,165355,267745213,9.55,1700,17,9.68,100,1,10.61,200,2,11.27,100,1,11.4,100,1,11.76,100,1,11.93,200,2,12.23,100,1,12.34,200,2,12.36,200,2,13.94,15,1,14.1,2,1,14.26,100,1,14.28,100,1,14.4,100,1,14.56,800,2,14.6,700,1,14.68,1400,2,14.72,100,1,14.87,100,1,ARL,320519893
2025-07-17T15:58:20.237833402Z,2025-07-17T15:58:20.237668047Z,160,2,1108,A,A,13.950000000,100,0,320595817,130,165355,267745213,ARL,0,13.95,100,130,165355,267745213,9.55,1700,17,9.68,100,1,10.61,200,2,11.27,100,1,11.4,100,1,11.76,100,1,11.93,200,2,12.23,100,1,12.34,200,2,12.36,200,2,13.94,15,1,13.95,100,1,14.1,2,1,14.26,100,1,14.28,100,1,14.4,100,1,14.56,800,2,14.6,700,1,14.68,1400,2,14.72,100,1,ARL,320595817
2025-07-17T15:58:20.705512171Z,2025-07-17T15:58:20.705344578Z,160,2,1108,C,A,13.940000000,15,0,320588689,128,167593,267754327,ARL,0,13.94,15,128,167593,267754327,9.55,1700,17,9.68,100,1,10.61,200,2,11.27,100,1,11.4,100,1,11.76,100,1,11.93,200,2,12.23,100,1,12.34,200,2,12.36,200,2,13.95,100,1,14.1,2,1,14.26,100,1,14.28,100,1,14.4,100,1,14.56,800,2,14.6,700,1,14.68,1400,2,14.72,100,1,14.87,100,1,ARL,320588689
2025-07-17T15:58:30.800053062Z,2025-07-17T15:58:30.799887713Z,160,2,1108,A,A,13.890000000,15,0,320833897,130,165349,267913947,ARL,0,13.89,15,130,165349,267913947,9.55,1700,17,9.68,100,1,10.61,200,2,11.27,100,1,11.4,100,1,11.76,100,1,11.93,200,2,12.23,100,1,12.34,200,2,12.36,200,2,13.89,15,1,13.95,100,1,14.1,2,1,14.26,100,1,14.28,100,1,14.4,100,1,14.56,800,2,14.6,700,1,14.68,1400,2,14.72,100,1,ARL,320833897
2025-07-17T15:58:30.905657319Z,2025-07-17T15:58:30.905491759Z,160,2,1108,C,A,13.950000000,100,0,320595817,0,165560,267919515,ARL,0,13.95,100,0,165560,267919515,9.55,1700,17,9.68,100,1,10.61,200,2,11.27,100,1,11.4,100,1,11.76,100,1,11.93,200,2,12.23,100,1,12.34,200,2,12.36,200,2,13.89,15,1,14.1,2,1,14.26,100,1,14.28,100,1,14.4,100,1,14.56,800,2,14.6,700,1,14.68,1400,2,14.72,100,1,14.87,100,1,ARL,320595817
2025-07-17T15:58:30.905657319Z,2025-07-17T15:58:30.905491759Z,160,2,1108,A,A,13.900000000,100,0,320839125,130,165560,267919515,ARL,0,13.9,100,130,165560,267919515,9.55,1700,17,9.68,100,1,10.61,200,2,11.27,100,1,11.4,100,1,11.76,100,1,11.93,200,2,12.23,100,1,12.34,200,2,12.36,200,2,13.89,15,1,13.9,100,1,14.1,2,1,14.26,100,1,14.28,100,1,14.4,100,1,14.56,800,2,14.6,700,1,14.68,1400,2,14.72,100,1,ARL,320839125
2025-07-17T15:58:30.906412286Z,2025-07-17T15:58:30.906246950Z,160,2,1108,C,A,15.060000000,100,0,320487357,0,165336,267919540,ARL,0,15.06,100,0,165336,267919540,9.55,1700,17,9.68,100,1,10.61,200,2,11.27,100,1,11.4,100,1,11.76,100,1,11.93,200,2,12.23,100,1,12.34,200,2,12.36,200,2,13.89,15,1,13.9,100,1,14.1,2,1,14.26,100,1,14.28,100,1,14.4,100,1,14.56,800,2,14.6,700,1,14.68,1400,2,14.72,100,1,ARL,320487357
