ts_recv,ts_event,rtype,publisher_id,instrument_id,action,side,price,size,channel_id,order_id,flags,ts_in_delta,sequence,symbol,depth,price,size,flags,ts_in_delta,sequence,bid_px_00,bid_sz_00,bid_ct_00,ask_px_00,ask_sz_00,ask_ct_00,bid_px_01,bid_sz_01,bid_ct_01,ask_px_01,ask_sz_01,ask_ct_01,bid_px_02,bid_sz_02,bid_ct_02,ask_px_02,ask_sz_02,ask_ct_02,bid_px_03,bid_sz_03,bid_ct_03,ask_px_03,ask_sz_03,ask_ct_03,bid_px_04,bid_sz_04,bid_ct_04,ask_px_04,ask_sz_04,ask_ct_04,bid_px_05,bid_sz_05,bid_ct_05,ask_px_05,ask_sz_05,ask_ct_05,bid_px_06,bid_sz_06,bid_ct_06,ask_px_06,ask_sz_06,ask_ct_06,bid_px_07,bid_sz_07,bid_ct_07,ask_px_07,ask_sz_07,ask_ct_07,bid_px_08,bid_sz_08,bid_ct_08,ask_px_08,ask_sz_08,ask_ct_08,bid_px_09,bid_sz_09,bid_ct_09,ask_px_09,ask_sz_09,ask_ct_09,symbol,order_id
2025-07-17T13:46:09.563782397Z,2025-07-17T13:46:09.563617017Z,160,2,1108,A,A,17.700000000,100,0,84609557,130,165380,69579787,ARL,0,17.7,100,130,165380,69579787,9.55,1700,17,9.67,100,1,10.61,200,2,11.27,100,1,11.4,100,1,11.76,100,1,11.93,200,2,12.23,100,1,12.26,700,1,12.33,200,2,13.78,2,1,13.93,100,1,13.94,100,1,14.2,100,1,14.28,100,1,14.3,200,2,14.34,100,1,14.46,700,1,14.47,100,1,14.49,100,1,ARL,84609557
2025-07-17T13:46:09.565379544Z,2025-07-17T13:46:09.565213822Z,160,2,1108,C,A,13.780000000,2,0,58709197,0,165722,69579892,ARL,0,13.78,2,0,165722,69579892,9.55,1700,17,9.67,100,1,10.61,200,2,11.27,100,1,11.4,100,1,11.76,100,1,11.93,200,2,12.23,100,1,12.26,700,1,12.33,200,2,13.93,100,1,13.94,100,1,14.2,100,1,14.28,100,1,14.3,200,2,14.34,100,1,14.46,700,1,14.47,100,1,14.49,100,1,14.67,700,1,ARL,58709197
2025-07-17T13:46:09.565379544Z,2025-07-17T13:46:09.565213822Z,160,2,1108,A,A,13.930000000,2,0,84609637,130,165722,69579892,ARL,0,13.93,2,130,165722,69579892,9.55,1700,17,9.67,100,1,10.61,200,2,11.27,100,1,11.4,100,1,11.76,100,1,11.93,200,2,12.23,100,1,12.26,700,1,12.33,200,2,13.93,102,2,13.94,100,1,14.2,100,1,14.28,100,1,14.3,200,2,14.34,100,1,14.46,700,1,14.47,100,1,14.49,100,1,14.67,700,1,ARL,84609637
2025-07-17T13:46:09.565403598Z,2025-07-17T13:46:09.565237899Z,160,2,1108,C,A,15.730000000,100,0,84607837,0,165699,69579893,ARL,0,15.73,100,0,165699,69579893,9.55,1700,17,9.67,100,1,10.61,200,2,11.27,100,1,11.4,100,1,11.76,100,1,11.93,200,2,12.23,100,1,12.26,700,1,12.33,200,2,13.93,102,2,13.94,100,1,14.2,100,1,14.28,100,1,14.3,200,2,14.34,100,1,14.46,700,1,14.47,100,1,14.49,100,1,14.67,700,1,ARL,84607837
2025-07-17T13:46:09.565403598Z,2025-07-17T13:46:09.565237899Z,160,2,1108,A,A,16.020000000,100,0,84609645,130,165699,69579893,ARL,0,16.02,100,130,165699,69579893,9.55,1700,17,9.67,100,1,10.61,200,2,11.27,100,1,11.4,100,1,11.76,100,1,11.93,200,2,12.23,100,1,12.26,700,1,12.33,200,2,13.93,102,2,13.94,100,1,14.2,100,1,14.28,100,1,14.3,200,2,14.34,100,1,14.46,700,1,14.47,100,1,14.49,100,1,14.67,700,1,ARL,84609645
2025-07-17T13:46:09.566687064Z,2025-07-17T13:46:09.566522227Z,160,2,1108,C,A,13.940000000,100,0,84609305,130,164837,69579922,ARL,0,13.94,100,130,164837,69579922,9.55,1700,17,9.67,100,1,10.61,200,2,11.27,100,1,11.4,100,1,11.76,100,1,11.93,200,2,12.23,100,1,12.26,700,1,12.33,200,2,13.93,102,2,14.2,100,1,14.28,100,1,14.3,200,2,14.34,100,1,14.46,700,1,14.47,100,1,14.49,100,1,14.67,700,1,14.7,700,1,ARL,84609305
2025-07-17T13:46:09.566736503Z,2025-07-17T13:46:09.566571131Z,160,2,1108,A,A,14.210000000,100,0,84609733,130,165372,69579923,ARL,0,14.21,100,130,165372,69579923,9.55,1700,17,9.67,100,1,10.61,200,2,11.27,100,1,11.4,100,1,11.76,100,1,11.93,200,2,12.23,100,1,12.26,700,1,12.33,200,2,13.93,102,2,14.2,100,1,14.21,100,1,14.28,100,1,14.3,200,2,14.34,100,1,14.46,700,1,14.47,100,1,14.49,100,1,14.67,700,1,ARL,84609733
2025-07-17T13:46:09.583735074Z,2025-07-17T13:46:09.583569619Z,160,2,1108,C,A,14.740000000,100,0,43852129,0,165455,69580598,ARL,0,14.74,100,0,165455,69580598,9.55,1700,17,9.67,100,1,10.61,200,2,11.27,100,1,11.4,100,1,11.76,100,1,11.93,200,2,12.23,100,1,12.26,700,1,12.33,200,2,13.93,102,2,14.2,100,1,14.21,100,1,14.28,100,1,14.3,200,2,14.34,100,1,14.46,700,1,14.47,100,1,14.49,100,1,14.67,700,1,ARL,43852129
2025-07-17T13:46:09.583735074Z,2025-07-17T13:46:09.583569619Z,160,2,1108,A,A,15.330000000,100,0,84611025,130,165455,69580598,ARL,0,15.33,100,130,165455,69580598,9.55,1700,17,9.67,100,1,10.61,200,2,11.27,100,1,11.4,100,1,11.76,100,1,11.93,200,2,12.23,100,1,12.26,700,1,12.33,200,2,13.93,102,2,14.2,100,1,14.21,100,1,14.28,100,1,14.3,200,2,14.34,100,1,14.46,700,1,14.47,100,1,14.49,100,1,14.67,700,1,ARL,84611025
2025-07-17T13:46:09.591552337Z,2025-07-17T13:46:09.591386919Z,160,2,1108,C,A,14.490000000,100,0,84607785,0,165418,69581249,ARL,0,14.49,100,0,165418,69581249,9.55,1700,17,9.67,100,1,10.61,200,2,11.27,100,1,11.4,100,1,11.76,100,1,11.93,200,2,12.23,100,1,12.26,700,1,12.33,200,2,13.93,102,2,14.2,100,1,14.21,100,1,14.28,100,1,14.3,200,2,14.34,100,1,14.46,700,1,14.47,100,1,14.67,700,1,14.7,700,1,ARL,84607785
2025-07-17T13:46:09.591552337Z,2025-07-17T13:46:09.591386919Z,160,2,1108,A,A,15.010000000,100,0,84611613,130,165418,69581249,ARL,0,15.01,100,130,165418,69581249,9.55,1700,17,9.67,100,1,10.61,200,2,11.27,100,1,11.4,100,1,11.76,100,1,11.93,200,2,12.23,100,1,12.26,700,1,12.33,200,2,13.93,102,2,14.2,100,1,14.21,100,1,14.28,100,1,14.3,200,2,14.34,100,1,14.46,700,1,14.47,100,1,14.67,700,1,14.7,700,1,ARL,84611613
2025-07-17T13:46:09.595667047Z,2025-07-17T13:46:09.595500037Z,160,2,1108,A,A,14.630000000,700,0,84612081,128,167010,69582059,ARL,0,14.63,700,128,167010,69582059,9.55,1700,17,9.67,100,1,10.61,200,2,11.27,100,1,11.4,100,1,11.76,100,1,11.93,200,2,12.23,100,1,12.26,700,1,12.33,200,2,13.93,102,2,14.2,100,1,14.21,100,1,14.28,100,1,14.3,200,2,14.34,100,1,14.46,700,1,14.47,100,1,14.63,700,1,14.67,700,1,ARL,84612081
2025-07-17T13:46:09.610291566Z,2025-07-17T13:46:09.610126066Z,160,2,1108,C,A,14.340000000,100,0,44088637,0,165500,69582709,ARL,0,14.34,100,0,165500,69582709,9.55,1700,17,9.67,100,1,10.61,200,2,11.27,100,1,11.4,100,1,11.76,100,1,11.93,200,2,12.23,100,1,12.26,700,1,12.33,200,2,13.93,102,2,14.2,100,1,14.21,100,1,14.28,100,1,14.3,200,2,14.46,700,1,14.47,100,1,14.63,700,1,14.67,700,1,14.7,700,1,ARL,44088637
2025-07-17T13:46:09.610291566Z,2025-07-17T13:46:09.610126066Z,160,2,1108,A,A,14.910000000,100,0,84612773,130,165500,69582709,ARL,0,14.91,100,130,165500,69582709,9.55,1700,17,9.67,100,1,10.61,200,2,11.27,100,1,11.4,100,1,11.76,100,1,11.93,200,2,12.23,100,1,12.26,700,1,12.33,200,2,13.93,102,2,14.2,100,1,14.21,100,1,14.28,100,1,14.3,200,2,14.46,700,1,14.47,100,1,14.63,700,1,14.67,700,1,14.7,700,1,ARL,84612773
2025-07-17T13:46:09.812938843Z,2025-07-17T13:46:09.812773551Z,160,2,1108,A,A,14.760000000,100,0,84618189,130,165292,69586965,ARL,0,14.76,100,130,165292,69586965,9.55,1700,17,9.67,100,1,10.61,200,2,11.27,100,1,11.4,100,1,11.76,100,1,11.93,200,2,12.23,100,1,12.26,700,1,12.33,200,2,13.93,102,2,14.2,100,1,14.21,100,1,14.28,100,1,14.3,200,2,14.46,700,1,14.47,100,1,14.63,700,1,14.67,700,1,14.7,700,1,ARL,84618189
2025-07-17T13:46:09.812950020Z,2025-07-17T13:46:09.812784722Z,160,2,1108,C,A,14.200000000,100,0,43804081,130,165298,69586966,ARL,0,14.2,100,130,165298,69586966,9.55,1700,17,9.67,100,1,10.61,200,2,11.27,100,1,11.4,100,1,11.76,100,1,11.93,200,2,12.23,100,1,12.26,700,1,12.33,200,2,13.93,102,2,14.21,100,1,14.28,100,1,14.3,200,2,14.46,700,1,14.47,100,1,14.63,700,1,14.67,700,1,14.7,700,1,14.76,100,1,ARL,43804081
2025-07-17T13:46:09.936895839Z,2025-07-17T13:46:09.936730596Z,160,2,1108,C,A,13.930000000,100,0,44066417,130,165243,69592193,ARL,0,13.93,100,130,165243,69592193,9.55,1700,17,9.67,100,1,10.61,200,2,11.27,100,1,11.4,100,1,11.76,100,1,11.93,200,2,12.23,100,1,12.26,700,1,12.33,200,2,13.93,2,1,14.21,100,1,14.28,100,1,14.3,200,2,14.46,700,1,14.47,100,1,14.63,700,1,14.67,700,1,14.7,700,1,14.76,100,1,ARL,44066417
2025-07-17T13:46:09.936896832Z,2025-07-17T13:46:09.936731544Z,160,2,1108,A,A,14.480000000,100,0,84624129,130,165288,69592194,ARL,0,14.48,100,130,165288,69592194,9.55,1700,17,9.67,100,1,10.61,200,2,11.27,100,1,11.4,100,1,11.76,100,1,11.93,200,2,12.23,100,1,12.26,700,1,12.33,200,2,13.93,2,1,14.21,100,1,14.28,100,1,14.3,200,2,14.46,700,1,14.47,100,1,14.48,100,1,14.63,700,1,14.67,700,1,14.7,700,1,ARL,84624129
2025-07-17T13:46:09.937622396Z,2025-07-17T13:46:09.937457145Z,160,2,1108,C,A,15.010000000,100,0,84611613,0,165251,69592231,ARL,0,15.01,100,0,165251,69592231,9.55,1700,17,9.67,100,1,10.61,200,2,11.27,100,1,11.4,100,1,11.76,100,1,11.93,200,2,12.23,100,1,12.26,700,1,12.33,200,2,13.93,2,1,14.21,100,1,14.28,100,1,14.3,200,2,14.46,700,1,14.47,100,1,14.48,100,1,14.63,700,1,14.67,700,1,14.7,700,1,ARL,84611613
2025-07-17T13:46:09.937622396Z,2025-07-17T13:46:09.937457145Z,160,2,1108,A,A,15.060000000,100,0,84624201,130,165251,69592231,ARL,0,15.06,100,130,165251,69592231,9.55,1700,17,9.67,100,1,10.61,200,2,11.27,100,1,11.4,100,1,11.76,100,1,11.93,200,2,12.23,100,1,12.26,700,1,12.33,200,2,13.93,2,1,14.21,100,1,14.28,100,1,14.3,200,2,14.46,700,1,14.47,100,1,14.48,100,1,14.63,700,1,14.67,700,1,14.7,700,1,ARL,84624201
2025-07-17T13:46:10.046960966Z,2025-07-17T13:46:10.046795728Z,160,2,1108,C,A,14.700000000,700,0,84609321,130,165238,69596523,ARL,0,14.7,700,130,165238,69596523,9.55,1700,17,9.67,100,1,10.61,200,2,11.27,100,1,11.4,100,1,11.76,100,1,11.93,200,2,12.23,100,1,12.26,700,1,12.33,200,2,13.93,2,1,14.21,100,1,14.28,100,1,14.3,200,2,14.46,700,1,14.47,100,1,14.48,100,1,14.63,700,1,14.67,700,1,14.76,100,1,ARL,84609321
2025-07-17T13:46:10.046962793Z,2025-07-17T13:46:10.046796743Z,160,2,1108,C,A,14.630000000,700,0,84612081,130,166050,69596524,ARL,0,14.63,700,130,166050,69596524,9.55,1700,17,9.67,100,1,10.61,200,2,11.27,100,1,11.4,100,1,11.76,100,1,11.93,200,2,12.23,100,1,12.26,700,1,12.33,200,2,13.93,2,1,14.21,100,1,14.28,100,1,14.3,200,2,14.46,700,1,14.47,100,1,14.48,100,1,14.67,700,1,14.76,100,1,14.91,200,2,ARL,84612081
2025-07-17T13:46:10.047001176Z,2025-07-17T13:46:10.046834863Z,160,2,1108,A,A,14.990000000,700,0,84628757,0,166313,69596525,ARL,0,14.99,700,0,166313,69596525,9.55,1700,17,9.67,100,1,10.61,200,2,11.27,100,1,11.4,100,1,11.76,100,1,11.93,200,2,12.23,100,1,12.26,700,1,12.33,200,2,13.93,2,1,14.21,100,1,14.28,100,1,14.3,200,2,14.46,700,1,14.47,100,1,14.48,100,1,14.67,700,1,14.76,100,1,14.91,200,2,ARL,84628757
2025-07-17T13:46:10.047001176Z,2025-07-17T13:46:10.046835277Z,160,2,1108,A,A,14.910000000,700,0,84628761,130,165899,69596526,ARL,0,14.91,700,130,165899,69596526,9.55,1700,17,9.67,100,1,10.61,200,2,11.27,100,1,11.4,100,1,11.76,100,1,11.93,200,2,12.23,100,1,12.26,700,1,12.33,200,2,13.93,2,1,14.21,100,1,14.28,100,1,14.3,200,2,14.46,700,1,14.47,100,1,14.48,100,1,14.67,700,1,14.76,100,1,14.91,900,3,ARL,84628761
2025-07-17T13:46:10.047030471Z,2025-07-17T13:46:10.046864551Z,160,2,1108,A,A,16.200000000,100,0,84628765,130,165920,69596527,ARL,0,16.2,100,130,165920,69596527,9.55,1700,17,9.67,100,1,10.61,200,2,11.27,100,1,11.4,100,1,11.76,100,1,11.93,200,2,12.23,100,1,12.26,700,1,12.33,200,2,13.93,2,1,14.21,100,1,14.28,100,1,14.3,200,2,14.46,700,1,14.47,100,1,14.48,100,1,14.67,700,1,14.76,100,1,14.91,900,3,ARL,84628765
2025-07-17T13:46:10.047042954Z,2025-07-17T13:46:10.046877789Z,160,2,1108,C,A,15.890000000,100,0,84609309,130,165165,69596529,ARL,0,15.89,100,130,165165,69596529,9.55,1700,17,9.67,100,1,10.61,200,2,11.27,100,1,11.4,100,1,11.76,100,1,11.93,200,2,12.23,100,1,12.26,700,1,12.33,200,2,13.93,2,1,14.21,100,1,14.28,100,1,14.3,200,2,14.46,700,1,14.47,100,1,14.48,100,1,14.67,700,1,14.76,100,1,14.91,900,3,ARL,84609309
2025-07-17T13:46:10.047089640Z,2025-07-17T13:46:10.046924268Z,160,2,1108,C,A,13.930000000,2,0,84609637,0,165372,69596531,ARL,0,13.93,2,0,165372,69596531,9.55,1700,17,9.67,100,1,10.61,200,2,11.27,100,1,11.4,100,1,11.76,100,1,11.93,200,2,12.23,100,1,12.26,700,1,12.33,200,2,14.21,100,1,14.28,100,1,14.3,200,2,14.46,700,1,14.47,100,1,14.48,100,1,14.67,700,1,14.76,100,1,14.91,900,3,14.99,700,1,ARL,84609637
2025-07-17T13:46:10.047089640Z,2025-07-17T13:46:10.046924268Z,160,2,1108,A,A,14.200000000,2,0,84628773,130,165372,69596531,ARL,0,14.2,2,130,165372,69596531,9.55,1700,17,9.67,100,1,10.61,200,2,11.27,100,1,11.4,100,1,11.76,100,1,11.93,200,2,12.23,100,1,12.26,700,1,12.33,200,2,14.2,2,1,14.21,100,1,14.28,100,1,14.3,200,2,14.46,700,1,14.47,100,1,14.48,100,1,14.67,700,1,14.76,100,1,14.91,900,3,ARL,84628773
2025-07-17T13:46:10.047429477Z,2025-07-17T13:46:10.047264301Z,160,2,1108,C,A,14.280000000,100,0,84607809,130,165176,69596542,ARL,0,14.28,100,130,165176,69596542,9.55,1700,17,9.67,100,1,10.61,200,2,11.27,100,1,11.4,100,1,11.76,100,1,11.93,200,2,12.23,100,1,12.26,700,1,12.33,200,2,14.2,2,1,14.21,100,1,14.3,200,2,14.46,700,1,14.47,100,1,14.48,100,1,14.67,700,1,14.76,100,1,14.91,900,3,14.99,700,1,ARL,84607809
2025-07-17T13:46:10.047479201Z,2025-07-17T13:46:10.047313929Z,160,2,1108,C,A,14.670000000,700,0,84609409,130,165272,69596543,ARL,0,14.67,700,130,165272,69596543,9.55,1700,17,9.67,100,1,10.61,200,2,11.27,100,1,11.4,100,1,11.76,100,1,11.93,200,2,12.23,100,1,12.26,700,1,12.33,200,2,14.2,2,1,14.21,100,1,14.3,200,2,14.46,700,1,14.47,100,1,14.48,100,1,14.76,100,1,14.91,900,3,14.99,700,1,15.06,100,1,ARL,84609409
2025-07-17T13:46:10.047784342Z,2025-07-17T13:46:10.047618250Z,160,2,1108,A,A,14.830000000,100,0,84628793,128,166092,69596548,ARL,0,14.83,100,128,166092,69596548,9.55,1700,17,9.67,100,1,10.61,200,2,11.27,100,1,11.4,100,1,11.76,100,1,11.93,200,2,12.23,100,1,12.26,700,1,12.33,200,2,14.2,2,1,14.21,100,1,14.3,200,2,14.46,700,1,14.47,100,1,14.48,100,1,14.76,100,1,14.83,100,1,14.91,900,3,14.99,700,1,ARL,84628793
2025-07-17T13:46:10.047806230Z,2025-07-17T13:46:10.047640842Z,160,2,1108,C,A,14.460000000,700,0,44548325,130,165388,69596550,ARL,0,14.46,700,130,165388,69596550,9.55,1700,17,9.67,100,1,10.61,200,2,11.27,100,1,11.4,100,1,11.76,100,1,11.93,200,2,12.23,100,1,12.26,700,1,12.33,200,2,14.2,2,1,14.21,100,1,14.3,200,2,14.47,100,1,14.48,100,1,14.76,100,1,14.83,100,1,14.91,900,3,14.99,700,1,15.06,100,1,ARL,44548325
2025-07-17T13:46:10.047885265Z,2025-07-17T13:46:10.047719954Z,160,2,1108,A,A,14.950000000,700,0,84628797,130,165311,69596551,ARL,0,14.95,700,130,165311,69596551,9.55,1700,17,9.67,100,1,10.61,200,2,11.27,100,1,11.4,100,1,11.76,100,1,11.93,200,2,12.23,100,1,12.26,700,1,12.33,200,2,14.2,2,1,14.21,100,1,14.3,200,2,14.47,100,1,14.48,100,1,14.76,100,1,14.83,100,1,14.91,900,3,14.95,700,1,14.99,700,1,ARL,84628797
2025-07-17T13:46:10.047929072Z,2025-07-17T13:46:10.047763743Z,160,2,1108,C,A,14.910000000,100,0,84609389,0,165329,69596552,ARL,0,14.91,100,0,165329,69596552,9.55,1700,17,9.67,100,1,10.61,200,2,11.27,100,1,11.4,100,1,11.76,100,1,11.93,200,2,12.23,100,1,12.26,700,1,12.33,200,2,14.2,2,1,14.21,100,1,14.3,200,2,14.47,100,1,14.48,100,1,14.76,100,1,14.83,100,1,14.91,800,2,14.95,700,1,14.99,700,1,ARL,84609389
2025-07-17T13:46:10.047929072Z,2025-07-17T13:46:10.047763743Z,160,2,1108,A,A,15.200000000,100,0,84628801,130,165329,69596552,ARL,0,15.2,100,130,165329,69596552,9.55,1700,17,9.67,100,1,10.61,200,2,11.27,100,1,11.4,100,1,11.76,100,1,11.93,200,2,12.23,100,1,12.26,700,1,12.33,200,2,14.2,2,1,14.21,100,1,14.3,200,2,14.47,100,1,14.48,100,1,14.76,100,1,14.83,100,1,14.91,800,2,14.95,700,1,14.99,700,1,ARL,84628801
2025-07-17T13:46:10.047983286Z,2025-07-17T13:46:10.047817649Z,160,2,1108,C,A,15.060000000,100,0,84624201,0,165637,69596553,ARL,0,15.06,100,0,165637,69596553,9.55,1700,17,9.67,100,1,10.61,200,2,11.27,100,1,11.4,100,1,11.76,100,1,11.93,200,2,12.23,100,1,12.26,700,1,12.33,200,2,14.2,2,1,14.21,100,1,14.3,200,2,14.47,100,1,14.48,100,1,14.76,100,1,14.83,100,1,14.91,800,2,14.95,700,1,14.99,700,1,ARL,84624201
2025-07-17T13:46:10.047983286Z,2025-07-17T13:46:10.047817649Z,160,2,1108,A,A,15.300000000,100,0,84628813,130,165637,69596553,ARL,0,15.3,100,130,165637,69596553,9.55,1700,17,9.67,100,1,10.61,200,2,11.27,100,1,11.4,100,1,11.76,100,1,11.93,200,2,12.23,100,1,12.26,700,1,12.33,200,2,14.2,2,1,14.21,100,1,14.3,200,2,14.47,100,1,14.48,100,1,14.76,100,1,14.83,100,1,14.91,800,2,14.95,700,1,14.99,700,1,ARL,84628813
2025-07-17T13:46:10.048529147Z,2025-07-17T13:46:10.048363798Z,160,2,1108,A,A,15.140000000,700,0,84628829,130,165349,69596568,ARL,0,15.14,700,130,165349,69596568,9.55,1700,17,9.67,100,1,10.61,200,2,11.27,100,1,11.4,100,1,11.76,100,1,11.93,200,2,12.23,100,1,12.26,700,1,12.33,200,2,14.2,2,1,14.21,100,1,14.3,200,2,14.47,100,1,14.48,100,1,14.76,100,1,14.83,100,1,14.91,800,2,14.95,700,1,14.99,700,1,ARL,84628829
2025-07-17T13:46:10.048840949Z,2025-07-17T13:46:10.048674815Z,160,2,1108,C,A,15.330000000,100,0,84609385,0,166134,69596577,ARL,0,15.33,100,0,166134,69596577,9.55,1700,17,9.67,100,1,10.61,200,2,11.27,100,1,11.4,100,1,11.76,100,1,11.93,200,2,12.23,100,1,12.26,700,1,12.33,200,2,14.2,2,1,14.21,100,1,14.3,200,2,14.47,100,1,14.48,100,1,14.76,100,1,14.83,100,1,14.91,800,2,14.95,700,1,14.99,700,1,ARL,84609385
2025-07-17T13:46:10.048840949Z,2025-07-17T13:46:10.048674815Z,160,2,1108,A,A,15.640000000,100,0,84628833,130,166134,69596577,ARL,0,15.64,100,130,166134,69596577,9.55,1700,17,9.67,100,1,10.61,200,2,11.27,100,1,11.4,100,1,11.76,100,1,11.93,200,2,12.23,100,1,12.26,700,1,12.33,200,2,14.2,2,1,14.21,100,1,14.3,200,2,14.47,100,1,14.48,100,1,14.76,100,1,14.83,100,1,14.91,800,2,14.95,700,1,14.99,700,1,ARL,84628833
2025-07-17T13:46:10.051935025Z,2025-07-17T13:46:10.051769303Z,160,2,1108,C,A,17.700000000,100,0,84609557,0,165722,69596649,ARL,0,17.7,100,0,165722,69596649,9.55,1700,17,9.67,100,1,10.61,200,2,11.27,100,1,11.4,100,1,11.76,100,1,11.93,200,2,12.23,100,1,12.26,700,1,12.33,200,2,14.2,2,1,14.21,100,1,14.3,200,2,14.47,100,1,14.48,100,1,14.76,100,1,14.83,100,1,14.91,800,2,14.95,700,1,14.99,700,1,ARL,84609557
2025-07-17T13:46:10.051935025Z,2025-07-17T13:46:10.051769303Z,160,2,1108,A,A,18.050000000,100,0,84628913,130,165722,69596649,ARL,0,18.05,100,130,165722,69596649,9.55,1700,17,9.67,100,1,10.61,200,2,11.27,100,1,11.4,100,1,11.76,100,1,11.93,200,2,12.23,100,1,12.26,700,1,12.33,200,2,14.2,2,1,14.21,100,1,14.3,200,2,14.47,100,1,14.48,100,1,14.76,100,1,14.83,100,1,14.91,800,2,14.95,700,1,14.99,700,1,ARL,84628913
2025-07-17T13:46:10.054332558Z,2025-07-17T13:46:10.054167322Z,160,2,1108,C,A,16.020000000,100,0,84609645,0,165236,69596777,ARL,0,16.02,100,0,165236,69596777,9.55,1700,17,9.67,100,1,10.61,200,2,11.27,100,1,11.4,100,1,11.76,100,1,11.93,200,2,12.23,100,1,12.26,700,1,12.33,200,2,14.2,2,1,14.21,100,1,14.3,200,2,14.47,100,1,14.48,100,1,14.76,100,1,14.83,100,1,14.91,800,2,14.95,700,1,14.99,700,1,ARL,84609645
2025-07-17T13:46:10.054332558Z,2025-07-17T13:46:10.054167322Z,160,2,1108,A,A,16.350000000,100,0,84629065,130,165236,69596777,ARL,0,16.35,100,130,165236,69596777,9.55,1700,17,9.67,100,1,10.61,200,2,11.27,100,1,11.4,100,1,11.76,100,1,11.93,200,2,12.23,100,1,12.26,700,1,12.33,200,2,14.2,2,1,14.21,100,1,14.3,200,2,14.47,100,1,14.48,100,1,14.76,100,1,14.83,100,1,14.91,800,2,14.95,700,1,14.99,700,1,ARL,84629065
2025-07-17T13:46:10.055434148Z,2025-07-17T13:46:10.055269067Z,160,2,1108,C,A,14.210000000,100,0,84609733,130,165081,69596798,ARL,0,14.21,100,130,165081,69596798,9.55,1700,17,9.67,100,1,10.61,200,2,11.27,100,1,11.4,100,1,11.76,100,1,11.93,200,2,12.23,100,1,12.26,700,1,12.33,200,2,14.2,2,1,14.3,200,2,14.47,100,1,14.48,100,1,14.76,100,1,14.83,100,1,14.91,800,2,14.95,700,1,14.99,700,1,15.14,700,1,ARL,84609733
2025-07-17T13:46:10.055483249Z,2025-07-17T13:46:10.055317945Z,160,2,1108,A,A,14.480000000,100,0,84629093,130,165304,69596799,ARL,0,14.48,100,130,165304,69596799,9.55,1700,17,9.67,100,1,10.61,200,2,11.27,100,1,11.4,100,1,11.76,100,1,11.93,200,2,12.23,100,1,12.26,700,1,12.33,200,2,14.2,2,1,14.3,200,2,14.47,100,1,14.48,200,2,14.76,100,1,14.83,100,1,14.91,800,2,14.95,700,1,14.99,700,1,15.14,700,1,ARL,84629093
2025-07-17T13:46:10.061411059Z,2025-07-17T13:46:10.061246123Z,160,2,1108,C,A,14.480000000,100,0,84629093,130,164936,69596987,ARL,0,14.48,100,130,164936,69596987,9.55,1700,17,9.67,100,1,10.61,200,2,11.27,100,1,11.4,100,1,11.76,100,1,11.93,200,2,12.23,100,1,12.26,700,1,12.33,200,2,14.2,2,1,14.3,200,2,14.47,100,1,14.48,100,1,14.76,100,1,14.83,100,1,14.91,800,2,14.95,700,1,14.99,700,1,15.14,700,1,ARL,84629093
2025-07-17T13:46:10.061459915Z,2025-07-17T13:46:10.061294728Z,160,2,1108,A,A,14.590000000,100,0,84629329,130,165187,69596990,ARL,0,14.59,100,130,165187,69596990,9.55,1700,17,9.67,100,1,10.61,200,2,11.27,100,1,11.4,100,1,11.76,100,1,11.93,200,2,12.23,100,1,12.26,700,1,12.33,200,2,14.2,2,1,14.3,200,2,14.47,100,1,14.48,100,1,14.59,100,1,14.76,100,1,14.83,100,1,14.91,800,2,14.95,700,1,14.99,700,1,ARL,84629329
2025-07-17T13:46:10.087891846Z,2025-07-17T13:46:10.087725560Z,160,2,1108,C,A,15.330000000,100,0,84611025,0,166286,69597697,ARL,0,15.33,100,0,166286,69597697,9.55,1700,17,9.67,100,1,10.61,200,2,11.27,100,1,11.4,100,1,11.76,100,1,11.93,200,2,12.23,100,1,12.26,700,1,12.33,200,2,14.2,2,1,14.3,200,2,14.47,100,1,14.48,100,1,14.59,100,1,14.76,100,1,14.83,100,1,14.91,800,2,14.95,700,1,14.99,700,1,ARL,84611025
2025-07-17T13:46:10.087891846Z,2025-07-17T13:46:10.087725560Z,160,2,1108,A,A,15.730000000,100,0,84629953,128,166286,69597697,ARL,0,15.73,100,128,166286,69597697,9.55,1700,17,9.67,100,1,10.61,200,2,11.27,100,1,11.4,100,1,11.76,100,1,11.93,200,2,12.23,100,1,12.26,700,1,12.33,200,2,14.2,2,1,14.3,200,2,14.47,100,1,14.48,100,1,14.59,100,1,14.76,100,1,14.83,100,1,14.91,800,2,14.95,700,1,14.99,700,1,ARL,84629953
2025-07-17T13:46:10.098194757Z,2025-07-17T13:46:10.098029439Z,160,2,1108,C,A,15.300000000,100,0,84628813,0,165318,69597813,ARL,0,15.3,100,0,165318,69597813,9.55,1700,17,9.67,100,1,10.61,200,2,11.27,100,1,11.4,100,1,11.76,100,1,11.93,200,2,12.23,100,1,12.26,700,1,12.33,200,2,14.2,2,1,14.3,200,2,14.47,100,1,14.48,100,1,14.59,100,1,14.76,100,1,14.83,100,1,14.91,800,2,14.95,700,1,14.99,700,1,ARL,84628813
2025-07-17T13:46:10.098194757Z,2025-07-17T13:46:10.098029439Z,160,2,1108,A,A,15.410000000,100,0,84630217,130,165318,69597813,ARL,0,15.41,100,130,165318,69597813,9.55,1700,17,9.67,100,1,10.61,200,2,11.27,100,1,11.4,100,1,11.76,100,1,11.93,200,2,12.23,100,1,12.26,700,1,12.33,200,2,14.2,2,1,14.3,200,2,14.47,100,1,14.48,100,1,14.59,100,1,14.76,100,1,14.83,100,1,14.91,800,2,14.95,700,1,14.99,700,1,ARL,84630217
2025-07-17T13:46:10.109235050Z,2025-07-17T13:46:10.109069598Z,160,2,1108,C,A,14.910000000,100,0,84612773,0,165452,69598154,ARL,0,14.91,100,0,165452,69598154,9.55,1700,17,9.67,100,1,10.61,200,2,11.27,100,1,11.4,100,1,11.76,100,1,11.93,200,2,12.23,100,1,12.26,700,1,12.33,200,2,14.2,2,1,14.3,200,2,14.47,100,1,14.48,100,1,14.59,100,1,14.76,100,1,14.83,100,1,14.91,700,1,14.95,700,1,14.99,700,1,ARL,84612773
2025-07-17T13:46:10.109235050Z,2025-07-17T13:46:10.109069598Z,160,2,1108,A,A,15.310000000,100,0,84630849,130,165452,69598154,ARL,0,15.31,100,130,165452,69598154,9.55,1700,17,9.67,100,1,10.61,200,2,11.27,100,1,11.4,100,1,11.76,100,1,11.93,200,2,12.23,100,1,12.26,700,1,12.33,200,2,14.2,2,1,14.3,200,2,14.47,100,1,14.48,100,1,14.59,100,1,14.76,100,1,14.83,100,1,14.91,700,1,14.95,700,1,14.99,700,1,ARL,84630849
2025-07-17T13:46:10.551481906Z,2025-07-17T13:46:10.551316402Z,160,2,1108,C,A,14.470000000,100,0,84608321,0,165504,69614455,ARL,0,14.47,100,0,165504,69614455,9.55,1700,17,9.67,100,1,10.61,200,2,11.27,100,1,11.4,100,1,11.76,100,1,11.93,200,2,12.23,100,1,12.26,700,1,12.33,200,2,14.2,2,1,14.3,200,2,14.48,100,1,14.59,100,1,14.76,100,1,14.83,100,1,14.91,700,1,14.95,700,1,14.99,700,1,15.14,700,1,ARL,84608321
2025-07-17T13:46:10.551481906Z,2025-07-17T13:46:10.551316402Z,160,2,1108,A,A,15.090000000,100,0,84650629,130,165504,69614455,ARL,0,15.09,100,130,165504,69614455,9.55,1700,17,9.67,100,1,10.61,200,2,11.27,100,1,11.4,100,1,11.76,100,1,11.93,200,2,12.23,100,1,12.26,700,1,12.33,200,2,14.2,2,1,14.3,200,2,14.48,100,1,14.59,100,1,14.76,100,1,14.83,100,1,14.91,700,1,14.95,700,1,14.99,700,1,15.09,100,1,ARL,84650629
2025-07-17T13:46:10.904838107Z,2025-07-17T13:46:10.904672934Z,160,2,1108,A,A,15.160000000,100,0,84668677,130,165173,69628781,ARL,0,15.16,100,130,165173,69628781,9.55,1700,17,9.67,100,1,10.61,200,2,11.27,100,1,11.4,100,1,11.76,100,1,11.93,200,2,12.23,100,1,12.26,700,1,12.33,200,2,14.2,2,1,14.3,200,2,14.48,100,1,14.59,100,1,14.76,100,1,14.83,100,1,14.91,700,1,14.95,700,1,14.99,700,1,15.09,100,1,ARL,84668677
2025-07-17T13:46:10.904858553Z,2025-07-17T13:46:10.904693578Z,160,2,1108,C,A,14.760000000,100,0,84618189,130,164975,69628783,ARL,0,14.76,100,130,164975,69628783,9.55,1700,17,9.67,100,1,10.61,200,2,11.27,100,1,11.4,100,1,11.76,100,1,11.93,200,2,12.23,100,1,12.26,700,1,12.33,200,2,14.2,2,1,14.3,200,2,14.48,100,1,14.59,100,1,14.83,100,1,14.91,700,1,14.95,700,1,14.99,700,1,15.09,100,1,15.14,700,1,ARL,84618189
2025-07-17T13:46:11.840882444Z,2025-07-17T13:46:11.840717150Z,160,2,1108,A,A,14.870000000,100,0,84708037,130,165294,69663346,ARL,0,14.87,100,130,165294,69663346,9.55,1700,17,9.67,100,1,10.61,200,2,11.27,100,1,11.4,100,1,11.76,100,1,11.93,200,2,12.23,100,1,12.26,700,1,12.33,200,2,14.2,2,1,14.3,200,2,14.48,100,1,14.59,100,1,14.83,100,1,14.87,100,1,14.91,700,1,14.95,700,1,14.99,700,1,15.09,100,1,ARL,84708037
2025-07-17T13:46:11.840894787Z,2025-07-17T13:46:11.840729407Z,160,2,1108,C,A,14.480000000,100,0,84624129,130,165380,69663347,ARL,0,14.48,100,130,165380,69663347,9.55,1700,17,9.67,100,1,10.61,200,2,11.27,100,1,11.4,100,1,11.76,100,1,11.93,200,2,12.23,100,1,12.26,700,1,12.33,200,2,14.2,2,1,14.3,200,2,14.59,100,1,14.83,100,1,14.87,100,1,14.91,700,1,14.95,700,1,14.99,700,1,15.09,100,1,15.14,700,1,ARL,84624129
2025-07-17T13:46:23.920813185Z,2025-07-17T13:46:23.920647302Z,160,2,1108,C,B,12.880000000,2,0,58709193,0,165883,70104076,ARL,0,12.88,2,0,165883,70104076,9.55,1700,17,9.67,100,1,10.61,200,2,11.27,100,1,11.4,100,1,11.76,100,1,11.93,200,2,12.23,100,1,12.26,700,1,12.33,200,2,14.2,2,1,14.3,200,2,14.59,100,1,14.83,100,1,14.87,100,1,14.91,700,1,14.95,700,1,14.99,700,1,15.09,100,1,15.14,700,1,ARL,58709193
2025-07-17T13:46:23.920813185Z,2025-07-17T13:46:23.920647302Z,160,2,1108,A,B,13.120000000,2,0,85194077,130,165883,70104076,ARL,0,13.12,2,130,165883,70104076,9.55,1700,17,9.67,100,1,10.61,200,2,11.27,100,1,11.4,100,1,11.76,100,1,11.93,200,2,12.23,100,1,12.26,700,1,12.33,200,2,14.2,2,1,14.3,200,2,14.59,100,1,14.83,100,1,14.87,100,1,14.91,700,1,14.95,700,1,14.99,700,1,15.09,100,1,15.14,700,1,ARL,85194077
2025-07-17T13:46:45.786579604Z,2025-07-17T13:46:45.786413307Z,160,2,1108,C,B,13.120000000,2,0,85194077,0,166297,70834235,ARL,0,13.12,2,0,166297,70834235,9.55,1700,17,9.67,100,1,10.61,200,2,11.27,100,1,11.4,100,1,11.76,100,1,11.93,200,2,12.23,100,1,12.26,700,1,12.33,200,2,14.2,2,1,14.3,200,2,14.59,100,1,14.83,100,1,14.87,100,1,14.91,700,1,14.95,700,1,14.99,700,1,15.09,100,1,15.14,700,1,ARL,85194077
2025-07-17T13:46:45.786579604Z,2025-07-17T13:46:45.786413307Z,160,2,1108,A,B,13.200000000,2,0,86056033,130,166297,70834235,ARL,0,13.2,2,130,166297,70834235,9.55,1700,17,9.67,100,1,10.61,200,2,11.27,100,1,11.4,100,1,11.76,100,1,11.93,200,2,12.23,100,1,12.26,700,1,12.33,200,2,14.2,2,1,14.3,200,2,14.59,100,1,14.83,100,1,14.87,100,1,14.91,700,1,14.95,700,1,14.99,700,1,15.09,100,1,15.14,700,1,ARL,86056033
2025-07-17T13:47:34.987167177Z,2025-07-17T13:47:34.987001473Z,160,2,1108,C,B,13.200000000,2,0,86056033,0,165704,72269967,ARL,0,13.2,2,0,165704,72269967,9.55,1700,17,9.67,100,1,10.61,200,2,11.27,100,1,11.4,100,1,11.76,100,1,11.93,200,2,12.23,100,1,12.26,700,1,12.33,200,2,14.2,2,1,14.3,200,2,14.59,100,1,14.83,100,1,14.87,100,1,14.91,700,1,14.95,700,1,14.99,700,1,15.09,100,1,15.14,700,1,ARL,86056033
2025-07-17T13:47:34.987167177Z,2025-07-17T13:47:34.987001473Z,160,2,1108,A,B,13.260000000,2,0,87750309,130,165704,72269967,ARL,0,13.26,2,130,165704,72269967,9.55,1700,17,9.67,100,1,10.61,200,2,11.27,100,1,11.4,100,1,11.76,100,1,11.93,200,2,12.23,100,1,12.26,700,1,12.33,200,2,14.2,2,1,14.3,200,2,14.59,100,1,14.83,100,1,14.87,100,1,14.91,700,1,14.95,700,1,14.99,700,1,15.09,100,1,15.14,700,1,ARL,87750309
2025-07-17T13:49:46.533586484Z,2025-07-17T13:49:46.533420775Z,160,2,1108,C,A,14.300000000,100,0,77910357,0,165709,76393090,ARL,0,14.3,100,0,165709,76393090,9.55,1700,17,9.67,100,1,10.61,200,2,11.27,100,1,11.4,100,1,11.76,100,1,11.93,200,2,12.23,100,1,12.26,700,1,12.33,200,2,14.2,2,1,14.3,100,1,14.59,100,1,14.83,100,1,14.87,100,1,14.91,700,1,14.95,700,1,14.99,700,1,15.09,100,1,15.14,700,1,ARL,77910357
2025-07-17T13:49:46.533586484Z,2025-07-17T13:49:46.533420775Z,160,2,1108,A,A,15.260000000,100,0,92510725,130,165709,76393090,ARL,0,15.26,100,130,165709,76393090,9.55,1700,17,9.67,100,1,10.61,200,2,11.27,100,1,11.4,100,1,11.76,100,1,11.93,200,2,12.23,100,1,12.26,700,1,12.33,200,2,14.2,2,1,14.3,100,1,14.59,100,1,14.83,100,1,14.87,100,1,14.91,700,1,14.95,700,1,14.99,700,1,15.09,100,1,15.14,700,1,ARL,92510725
2025-07-17T13:49:46.533732414Z,2025-07-17T13:49:46.533566805Z,160,2,1108,C,A,14.300000000,100,0,74589605,0,165609,76393092,ARL,0,14.3,100,0,165609,76393092,9.55,1700,17,9.67,100,1,10.61,200,2,11.27,100,1,11.4,100,1,11.76,100,1,11.93,200,2,12.23,100,1,12.26,700,1,12.33,200,2,14.2,2,1,14.59,100,1,14.83,100,1,14.87,100,1,14.91,700,1,14.95,700,1,14.99,700,1,15.09,100,1,15.14,700,1,15.16,100,1,ARL,74589605
2025-07-17T13:49:46.533732414Z,2025-07-17T13:49:46.533566805Z,160,2,1108,A,A,15.260000000,100,0,92510729,130,165609,76393092,ARL,0,15.26,100,130,165609,76393092,9.55,1700,17,9.67,100,1,10.61,200,2,11.27,100,1,11.4,100,1,11.76,100,1,11.93,200,2,12.23,100,1,12.26,700,1,12.33,200,2,14.2,2,1,14.59,100,1,14.83,100,1,14.87,100,1,14.91,700,1,14.95,700,1,14.99,700,1,15.09,100,1,15.14,700,1,15.16,100,1,ARL,92510729
2025-07-17T13:49:46.533768662Z,2025-07-17T13:49:46.533603070Z,160,2,1108,C,A,14.910000000,700,0,84628761,130,165592,76393093,ARL,0,14.91,700,130,165592,76393093,9.55,1700,17,9.67,100,1,10.61,200,2,11.27,100,1,11.4,100,1,11.76,100,1,11.93,200,2,12.23,100,1,12.26,700,1,12.33,200,2,14.2,2,1,14.59,100,1,14.83,100,1,14.87,100,1,14.95,700,1,14.99,700,1,15.09,100,1,15.14,700,1,15.16,100,1,15.2,100,1,ARL,84628761
2025-07-17T13:49:46.533810238Z,2025-07-17T13:49:46.533644528Z,160,2,1108,A,A,15.070000000,700,0,92510741,130,165710,76393094,ARL,0,15.07,700,130,165710,76393094,9.55,1700,17,9.67,100,1,10.61,200,2,11.27,100,1,11.4,100,1,11.76,100,1,11.93,200,2,12.23,100,1,12.26,700,1,12.33,200,2,14.2,2,1,14.59,100,1,14.83,100,1,14.87,100,1,14.95,700,1,14.99,700,1,15.07,700,1,15.09,100,1,15.14,700,1,15.16,100,1,ARL,92510741
2025-07-17T13:49:46.534488891Z,2025-07-17T13:49:46.534323177Z,160,2,1108,C,A,15.410000000,100,0,84630217,0,165714,76393099,ARL,0,15.41,100,0,165714,76393099,9.55,1700,17,9.67,100,1,10.61,200,2,11.27,100,1,11.4,100,1,11.76,100,1,11.93,200,2,12.23,100,1,12.26,700,1,12.33,200,2,14.2,2,1,14.59,100,1,14.83,100,1,14.87,100,1,14.95,700,1,14.99,700,1,15.07,700,1,15.09,100,1,15.14,700,1,15.16,100,1,ARL,84630217
2025-07-17T13:49:46.534488891Z,2025-07-17T13:49:46.534323177Z,160,2,1108,A,A,15.460000000,100,0,92510753,130,165714,76393099,ARL,0,15.46,100,130,165714,76393099,9.55,1700,17,9.67,100,1,10.61,200,2,11.27,100,1,11.4,100,1,11.76,100,1,11.93,200,2,12.23,100,1,12.26,700,1,12.33,200,2,14.2,2,1,14.59,100,1,14.83,100,1,14.87,100,1,14.95,700,1,14.99,700,1,15.07,700,1,15.09,100,1,15.14,700,1,15.16,100,1,ARL,92510753
2025-07-17T13:49:46.534555834Z,2025-07-17T13:49:46.534390219Z,160,2,1108,C,A,15.200000000,100,0,84628801,0,165615,76393100,ARL,0,15.2,100,0,165615,76393100,9.55,1700,17,9.67,100,1,10.61,200,2,11.27,100,1,11.4,100,1,11.76,100,1,11.93,200,2,12.23,100,1,12.26,700,1,12.33,200,2,14.2,2,1,14.59,100,1,14.83,100,1,14.87,100,1,14.95,700,1,14.99,700,1,15.07,700,1,15.09,100,1,15.14,700,1,15.16,100,1,ARL,84628801
2025-07-17T13:49:46.534555834Z,2025-07-17T13:49:46.534390219Z,160,2,1108,A,A,15.360000000,100,0,92510761,130,165615,76393100,ARL,0,15.36,100,130,165615,76393100,9.55,1700,17,9.67,100,1,10.61,200,2,11.27,100,1,11.4,100,1,11.76,100,1,11.93,200,2,12.23,100,1,12.26,700,1,12.33,200,2,14.2,2,1,14.59,100,1,14.83,100,1,14.87,100,1,14.95,700,1,14.99,700,1,15.07,700,1,15.09,100,1,15.14,700,1,15.16,100,1,ARL,92510761
2025-07-17T13:49:46.535182699Z,2025-07-17T13:49:46.535017084Z,160,2,1108,C,A,16.350000000,100,0,84629065,0,165615,76393115,ARL,0,16.35,100,0,165615,76393115,9.55,1700,17,9.67,100,1,10.61,200,2,11.27,100,1,11.4,100,1,11.76,100,1,11.93,200,2,12.23,100,1,12.26,700,1,12.33,200,2,14.2,2,1,14.59,100,1,14.83,100,1,14.87,100,1,14.95,700,1,14.99,700,1,15.07,700,1,15.09,100,1,15.14,700,1,15.16,100,1,ARL,84629065
2025-07-17T13:49:46.535182699Z,2025-07-17T13:49:46.535017084Z,160,2,1108,A,A,16.510000000,100,0,92510813,130,165615,76393115,ARL,0,16.51,100,130,165615,76393115,9.55,1700,17,9.67,100,1,10.61,200,2,11.27,100,1,11.4,100,1,11.76,100,1,11.93,200,2,12.23,100,1,12.26,700,1,12.33,200,2,14.2,2,1,14.59,100,1,14.83,100,1,14.87,100,1,14.95,700,1,14.99,700,1,15.07,700,1,15.09,100,1,15.14,700,1,15.16,100,1,ARL,92510813
2025-07-17T13:49:46.535737854Z,2025-07-17T13:49:46.535572067Z,160,2,1108,C,A,18.050000000,100,0,84628913,0,165787,76393138,ARL,0,18.05,100,0,165787,76393138,9.55,1700,17,9.67,100,1,10.61,200,2,11.27,100,1,11.4,100,1,11.76,100,1,11.93,200,2,12.23,100,1,12.26,700,1,12.33,200,2,14.2,2,1,14.59,100,1,14.83,100,1,14.87,100,1,14.95,700,1,14.99,700,1,15.07,700,1,15.09,100,1,15.14,700,1,15.16,100,1,ARL,84628913
2025-07-17T13:49:46.535737854Z,2025-07-17T13:49:46.535572067Z,160,2,1108,A,A,18.230000000,100,0,92510841,130,165787,76393138,ARL,0,18.23,100,130,165787,76393138,9.55,1700,17,9.67,100,1,10.61,200,2,11.27,100,1,11.4,100,1,11.76,100,1,11.93,200,2,12.23,100,1,12.26,700,1,12.33,200,2,14.2,2,1,14.59,100,1,14.83,100,1,14.87,100,1,14.95,700,1,14.99,700,1,15.07,700,1,15.09,100,1,15.14,700,1,15.16,100,1,ARL,92510841
2025-07-17T13:56:11.001810226Z,2025-07-17T13:56:11.001642441Z,160,2,1108,A,B,13.280000000,1,0,107702381,128,167785,89819278,ARL,0,13.28,1,128,167785,89819278,9.55,1700,17,9.67,100,1,10.61,200,2,11.27,100,1,11.4,100,1,11.76,100,1,11.93,200,2,12.23,100,1,12.26,700,1,12.33,200,2,14.2,2,1,14.59,100,1,14.83,100,1,14.87,100,1,14.95,700,1,14.99,700,1,15.07,700,1,15.09,100,1,15.14,700,1,15.16,100,1,ARL,107702381
2025-07-17T13:56:11.005550129Z,2025-07-17T13:56:11.005384065Z,160,2,1108,A,B,13.280000000,10,0,107702861,130,166064,89819705,ARL,0,13.28,10,130,166064,89819705,9.55,1700,17,9.67,100,1,10.61,200,2,11.27,100,1,11.4,100,1,11.76,100,1,11.93,200,2,12.23,100,1,12.26,700,1,12.33,200,2,14.2,2,1,14.59,100,1,14.83,100,1,14.87,100,1,14.95,700,1,14.99,700,1,15.07,700,1,15.09,100,1,15.14,700,1,15.16,100,1,ARL,107702861
2025-07-17T13:56:11.005550669Z,2025-07-17T13:56:11.005385425Z,160,2,1108,A,A,13.940000000,10,0,107702865,130,165244,89819706,ARL,0,13.94,10,130,165244,89819706,9.55,1700,17,9.67,100,1,10.61,200,2,11.27,100,1,11.4,100,1,11.76,100,1,11.93,200,2,12.23,100,1,12.26,700,1,12.33,200,2,13.94,10,1,14.2,2,1,14.59,100,1,14.83,100,1,14.87,100,1,14.95,700,1,14.99,700,1,15.07,700,1,15.09,100,1,15.14,700,1,ARL,107702865
2025-07-17T13:56:11.013819857Z,2025-07-17T13:56:11.013654317Z,160,2,1108,C,A,15.260000000,100,0,92510729,0,165540,89820163,ARL,0,15.26,100,0,165540,89820163,9.55,1700,17,9.67,100,1,10.61,200,2,11.27,100,1,11.4,100,1,11.76,100,1,11.93,200,2,12.23,100,1,12.26,700,1,12.33,200,2,13.94,10,1,14.2,2,1,14.59,100,1,14.83,100,1,14.87,100,1,14.95,700,1,14.99,700,1,15.07,700,1,15.09,100,1,15.14,700,1,ARL,92510729
2025-07-17T13:56:11.013819857Z,2025-07-17T13:56:11.013654317Z,160,2,1108,A,A,14.840000000,100,0,107703205,130,165540,89820163,ARL,0,14.84,100,130,165540,89820163,9.55,1700,17,9.67,100,1,10.61,200,2,11.27,100,1,11.4,100,1,11.76,100,1,11.93,200,2,12.23,100,1,12.26,700,1,12.33,200,2,13.94,10,1,14.2,2,1,14.59,100,1,14.83,100,1,14.84,100,1,14.87,100,1,14.95,700,1,14.99,700,1,15.07,700,1,15.09,100,1,ARL,107703205
2025-07-17T13:56:11.026680779Z,2025-07-17T13:56:11.026515306Z,160,2,1108,C,A,15.260000000,100,0,92510725,0,165473,89820408,ARL,0,15.26,100,0,165473,89820408,9.55,1700,17,9.67,100,1,10.61,200,2,11.27,100,1,11.4,100,1,11.76,100,1,11.93,200,2,12.23,100,1,12.26,700,1,12.33,200,2,13.94,10,1,14.2,2,1,14.59,100,1,14.83,100,1,14.84,100,1,14.87,100,1,14.95,700,1,14.99,700,1,15.07,700,1,15.09,100,1,ARL,92510725
2025-07-17T13:56:11.026680779Z,2025-07-17T13:56:11.026515306Z,160,2,1108,A,A,14.840000000,100,0,107703433,130,165473,89820408,ARL,0,14.84,100,130,165473,89820408,9.55,1700,17,9.67,100,1,10.61,200,2,11.27,100,1,11.4,100,1,11.76,100,1,11.93,200,2,12.23,100,1,12.26,700,1,12.33,200,2,13.94,10,1,14.2,2,1,14.59,100,1,14.83,100,1,14.84,200,2,14.87,100,1,14.95,700,1,14.99,700,1,15.07,700,1,15.09,100,1,ARL,107703433
2025-07-17T13:56:11.101916770Z,2025-07-17T13:56:11.101751649Z,160,2,1108,C,B,13.280000000,1,0,107702381,130,165121,89823845,ARL,0,13.28,1,130,165121,89823845,9.55,1700,17,9.67,100,1,10.61,200,2,11.27,100,1,11.4,100,1,11.76,100,1,11.93,200,2,12.23,100,1,12.26,700,1,12.33,200,2,13.94,10,1,14.2,2,1,14.59,100,1,14.83,100,1,14.84,200,2,14.87,100,1,14.95,700,1,14.99,700,1,15.07,700,1,15.09,100,1,ARL,107702381
2025-07-17T13:56:19.511755342Z,2025-07-17T13:56:19.511590204Z,160,2,1108,C,B,13.280000000,10,0,107702861,130,165138,90148349,ARL,0,13.28,10,130,165138,90148349,9.55,1700,17,9.67,100,1,10.61,200,2,11.27,100,1,11.4,100,1,11.76,100,1,11.93,200,2,12.23,100,1,12.26,700,1,12.33,200,2,13.94,10,1,14.2,2,1,14.59,100,1,14.83,100,1,14.84,200,2,14.87,100,1,14.95,700,1,14.99,700,1,15.07,700,1,15.09,100,1,ARL,107702861
2025-07-17T13:56:22.512134723Z,2025-07-17T13:56:22.511968820Z,160,2,1108,C,A,13.940000000,10,0,107702865,130,165903,90281309,ARL,0,13.94,10,130,165903,90281309,9.55,1700,17,9.67,100,1,10.61,200,2,11.27,100,1,11.4,100,1,11.76,100,1,11.93,200,2,12.23,100,1,12.26,700,1,12.33,200,2,14.2,2,1,14.59,100,1,14.83,100,1,14.84,200,2,14.87,100,1,14.95,700,1,14.99,700,1,15.07,700,1,15.09,100,1,15.14,700,1,ARL,107702865
2025-07-17T13:56:22.517155918Z,2025-07-17T13:56:22.516990420Z,160,2,1108,C,A,14.840000000,100,0,107703205,0,165498,90281853,ARL,0,14.84,100,0,165498,90281853,9.55,1700,17,9.67,100,1,10.61,200,2,11.27,100,1,11.4,100,1,11.76,100,1,11.93,200,2,12.23,100,1,12.26,700,1,12.33,200,2,14.2,2,1,14.59,100,1,14.83,100,1,14.84,100,1,14.87,100,1,14.95,700,1,14.99,700,1,15.07,700,1,15.09,100,1,15.14,700,1,ARL,107703205
2025-07-17T13:56:22.517155918Z,2025-07-17T13:56:22.516990420Z,160,2,1108,A,A,15.260000000,100,0,108217045,130,165498,90281853,ARL,0,15.26,100,130,165498,90281853,9.55,1700,17,9.67,100,1,10.61,200,2,11.27,100,1,11.4,100,1,11.76,100,1,11.93,200,2,12.23,100,1,12.26,700,1,12.33,200,2,14.2,2,1,14.59,100,1,14.83,100,1,14.84,100,1,14.87,100,1,14.95,700,1,14.99,700,1,15.07,700,1,15.09,100,1,15.14,700,1,ARL,108217045
2025-07-17T13:56:22.517527654Z,2025-07-17T13:56:22.517362170Z,160,2,1108,C,A,14.840000000,100,0,107703433,0,165484,90281893,ARL,0,14.84,100,0,165484,90281893,9.55,1700,17,9.67,100,1,10.61,200,2,11.27,100,1,11.4,100,1,11.76,100,1,11.93,200,2,12.23,100,1,12.26,700,1,12.33,200,2,14.2,2,1,14.59,100,1,14.83,100,1,14.87,100,1,14.95,700,1,14.99,700,1,15.07,700,1,15.09,100,1,15.14,700,1,15.16,100,1,ARL,107703433
2025-07-17T13:56:22.517527654Z,2025-07-17T13:56:22.517362170Z,160,2,1108,A,A,15.260000000,100,0,108217173,130,165484,90281893,ARL,0,15.26,100,130,165484,90281893,9.55,1700,17,9.67,100,1,10.61,200,2,11.27,100,1,11.4,100,1,11.76,100,1,11.93,200,2,12.23,100,1,12.26,700,1,12.33,200,2,14.2,2,1,14.59,100,1,14.83,100,1,14.87,100,1,14.95,700,1,14.99,700,1,15.07,700,1,15.09,100,1,15.14,700,1,15.16,100,1,ARL,108217173
2025-07-17T13:56:40.757800894Z,2025-07-17T13:56:40.757635216Z,160,2,1108,C,A,14.200000000,2,0,84628773,0,165678,90866180,ARL,0,14.2,2,0,165678,90866180,9.55,1700,17,9.67,100,1,10.61,200,2,11.27,100,1,11.4,100,1,11.76,100,1,11.93,200,2,12.23,100,1,12.26,700,1,12.33,200,2,14.59,100,1,14.83,100,1,14.87,100,1,14.95,700,1,14.99,700,1,15.07,700,1,15.09,100,1,15.14,700,1,15.16,100,1,15.26,200,2,ARL,84628773
2025-07-17T13:56:40.757800894Z,2025-07-17T13:56:40.757635216Z,160,2,1108,A,A,14.360000000,2,0,108872153,130,165678,90866180,ARL,0,14.36,2,130,165678,90866180,9.55,1700,17,9.67,100,1,10.61,200,2,11.27,100,1,11.4,100,1,11.76,100,1,11.93,200,2,12.23,100,1,12.26,700,1,12.33,200,2,14.36,2,1,14.59,100,1,14.83,100,1,14.87,100,1,14.95,700,1,14.99,700,1,15.07,700,1,15.09,100,1,15.14,700,1,15.16,100,1,ARL,108872153
2025-07-17T13:57:40.142022323Z,2025-07-17T13:57:40.141855674Z,160,2,1108,C,B,13.260000000,2,0,87750309,0,166649,92821039,ARL,0,13.26,2,0,166649,92821039,9.55,1700,17,9.67,100,1,10.61,200,2,11.27,100,1,11.4,100,1,11.76,100,1,11.93,200,2,12.23,100,1,12.26,700,1,12.33,200,2,14.36,2,1,14.59,100,1,14.83,100,1,14.87,100,1,14.95,700,1,14.99,700,1,15.07,700,1,15.09,100,1,15.14,700,1,15.16,100,1,ARL,87750309
2025-07-17T13:57:40.142022323Z,2025-07-17T13:57:40.141855674Z,160,2,1108,A,B,13.120000000,2,0,111169049,128,166649,92821039,ARL,0,13.12,2,128,166649,92821039,9.55,1700,17,9.67,100,1,10.61,200,2,11.27,100,1,11.4,100,1,11.76,100,1,11.93,200,2,12.23,100,1,12.26,700,1,12.33,200,2,14.36,2,1,14.59,100,1,14.83,100,1,14.87,100,1,14.95,700,1,14.99,700,1,15.07,700,1,15.09,100,1,15.14,700,1,15.16,100,1,ARL,111169049
2025-07-17T13:57:44.947757237Z,2025-07-17T13:57:44.947591620Z,160,2,1108,C,A,14.360000000,2,0,108872153,0,165617,92961696,ARL,0,14.36,2,0,165617,92961696,9.55,1700,17,9.67,100,1,10.61,200,2,11.27,100,1,11.4,100,1,11.76,100,1,11.93,200,2,12.23,100,1,12.26,700,1,12.33,200,2,14.59,100,1,14.83,100,1,14.87,100,1,14.95,700,1,14.99,700,1,15.07,700,1,15.09,100,1,15.14,700,1,15.16,100,1,15.26,200,2,ARL,108872153
2025-07-17T13:57:44.947757237Z,2025-07-17T13:57:44.947591620Z,160,2,1108,A,A,14.500000000,2,0,111347121,130,165617,92961696,ARL,0,14.5,2,130,165617,92961696,9.55,1700,17,9.67,100,1,10.61,200,2,11.27,100,1,11.4,100,1,11.76,100,1,11.93,200,2,12.23,100,1,12.26,700,1,12.33,200,2,14.5,2,1,14.59,100,1,14.83,100,1,14.87,100,1,14.95,700,1,14.99,700,1,15.07,700,1,15.09,100,1,15.14,700,1,15.16,100,1,ARL,111347121
2025-07-17T13:59:50.477911158Z,2025-07-17T13:59:50.477745739Z,160,2,1108,C,B,13.250000000,11,0,44586753,130,165419,96389796,ARL,0,13.25,11,130,165419,96389796,9.55,1700,17,9.67,100,1,10.61,200,2,11.27,100,1,11.4,100,1,11.76,100,1,11.93,200,2,12.23,100,1,12.26,700,1,12.33,200,2,14.5,2,1,14.59,100,1,14.83,100,1,14.87,100,1,14.95,700,1,14.99,700,1,15.07,700,1,15.09,100,1,15.14,700,1,15.16,100,1,ARL,44586753
2025-07-17T13:59:50.479576984Z,2025-07-17T13:59:50.479411482Z,160,2,1108,C,B,12.360000000,100,0,43787977,0,165502,96389821,ARL,0,12.36,100,0,165502,96389821,9.55,1700,17,9.67,100,1,10.61,200,2,11.27,100,1,11.4,100,1,11.76,100,1,11.93,200,2,12.23,100,1,12.26,700,1,12.33,200,2,14.5,2,1,14.59,100,1,14.83,100,1,14.87,100,1,14.95,700,1,14.99,700,1,15.07,700,1,15.09,100,1,15.14,700,1,15.16,100,1,ARL,43787977
2025-07-17T13:59:50.479576984Z,2025-07-17T13:59:50.479411482Z,160,2,1108,A,B,12.510000000,100,0,115474337,130,165502,96389821,ARL,0,12.51,100,130,165502,96389821,9.55,1700,17,9.67,100,1,10.61,200,2,11.27,100,1,11.4,100,1,11.76,100,1,11.93,200,2,12.23,100,1,12.26,700,1,12.33,200,2,14.5,2,1,14.59,100,1,14.83,100,1,14.87,100,1,14.95,700,1,14.99,700,1,15.07,700,1,15.09,100,1,15.14,700,1,15.16,100,1,ARL,115474337
2025-07-17T13:59:50.480863637Z,2025-07-17T13:59:50.480698233Z,160,2,1108,C,B,12.360000000,100,0,43781537,0,165404,96389845,ARL,0,12.36,100,0,165404,96389845,9.55,1700,17,9.67,100,1,10.61,200,2,11.27,100,1,11.4,100,1,11.76,100,1,11.93,200,2,12.23,100,1,12.26,700,1,12.33,200,2,14.5,2,1,14.59,100,1,14.83,100,1,14.87,100,1,14.95,700,1,14.99,700,1,15.07,700,1,15.09,100,1,15.14,700,1,15.16,100,1,ARL,43781537
2025-07-17T13:59:50.480863637Z,2025-07-17T13:59:50.480698233Z,160,2,1108,A,B,12.510000000,100,0,115474357,130,165404,96389845,ARL,0,12.51,100,130,165404,96389845,9.55,1700,17,9.67,100,1,10.61,200,2,11.27,100,1,11.4,100,1,11.76,100,1,11.93,200,2,12.23,100,1,12.26,700,1,12.33,200,2,14.5,2,1,14.59,100,1,14.83,100,1,14.87,100,1,14.95,700,1,14.99,700,1,15.07,700,1,15.09,100,1,15.14,700,1,15.16,100,1,ARL,115474357
2025-07-17T14:00:00.063037446Z,2025-07-17T14:00:00.062872132Z,160,2,1108,A,B,13.110000000,100,0,115813253,130,165314,96673952,ARL,0,13.11,100,130,165314,96673952,9.55,1700,17,9.67,100,1,10.61,200,2,11.27,100,1,11.4,100,1,11.76,100,1,11.93,200,2,12.23,100,1,12.26,700,1,12.33,200,2,14.5,2,1,14.59,100,1,14.83,100,1,14.87,100,1,14.95,700,1,14.99,700,1,15.07,700,1,15.09,100,1,15.14,700,1,15.16,100,1,ARL,115813253
2025-07-17T14:00:00.063056200Z,2025-07-17T14:00:00.062890891Z,160,2,1108,A,A,14.510000000,100,0,115813261,130,165309,96673954,ARL,0,14.51,100,130,165309,96673954,9.55,1700,17,9.67,100,1,10.61,200,2,11.27,100,1,11.4,100,1,11.76,100,1,11.93,200,2,12.23,100,1,12.26,700,1,12.33,200,2,14.5,2,1,14.51,100,1,14.59,100,1,14.83,100,1,14.87,100,1,14.95,700,1,14.99,700,1,15.07,700,1,15.09,100,1,15.14,700,1,ARL,115813261
2025-07-17T14:02:01.157985602Z,2025-07-17T14:02:01.157819863Z,160,2,1108,C,B,13.120000000,2,0,111169049,0,165739,101310413,ARL,0,13.12,2,0,165739,101310413,9.55,1700,17,9.67,100,1,10.61,200,2,11.27,100,1,11.4,100,1,11.76,100,1,11.93,200,2,12.23,100,1,12.26,700,1,12.33,200,2,14.5,2,1,14.51,100,1,14.59,100,1,14.83,100,1,14.87,100,1,14.95,700,1,14.99,700,1,15.07,700,1,15.09,100,1,15.14,700,1,ARL,111169049
2025-07-17T14:02:01.157985602Z,2025-07-17T14:02:01.157819863Z,160,2,1108,A,B,13.260000000,2,0,121098337,130,165739,101310413,ARL,0,13.26,2,130,165739,101310413,9.55,1700,17,9.67,100,1,10.61,200,2,11.27,100,1,11.4,100,1,11.76,100,1,11.93,200,2,12.23,100,1,12.26,700,1,12.33,200,2,14.5,2,1,14.51,100,1,14.59,100,1,14.83,100,1,14.87,100,1,14.95,700,1,14.99,700,1,15.07,700,1,15.09,100,1,15.14,700,1,ARL,121098337
2025-07-17T14:02:01.157986499Z,2025-07-17T14:02:01.157820985Z,160,2,1108,C,A,14.500000000,2,0,111347121,0,165514,101310414,ARL,0,14.5,2,0,165514,101310414,9.55,1700,17,9.67,100,1,10.61,200,2,11.27,100,1,11.4,100,1,11.76,100,1,11.93,200,2,12.23,100,1,12.26,700,1,12.33,200,2,14.51,100,1,14.59,100,1,14.83,100,1,14.87,100,1,14.95,700,1,14.99,700,1,15.07,700,1,15.09,100,1,15.14,700,1,15.16,100,1,ARL,111347121
2025-07-17T14:02:01.157986499Z,2025-07-17T14:02:01.157820985Z,160,2,1108,A,A,14.360000000,2,0,121098341,130,165514,101310414,ARL,0,14.36,2,130,165514,101310414,9.55,1700,17,9.67,100,1,10.61,200,2,11.27,100,1,11.4,100,1,11.76,100,1,11.93,200,2,12.23,100,1,12.26,700,1,12.33,200,2,14.36,2,1,14.51,100,1,14.59,100,1,14.83,100,1,14.87,100,1,14.95,700,1,14.99,700,1,15.07,700,1,15.09,100,1,15.14,700,1,ARL,121098341
2025-07-17T14:02:01.283528838Z,2025-07-17T14:02:01.283363185Z,160,2,1108,C,B,13.110000000,100,0,115813253,0,165653,101317376,ARL,0,13.11,100,0,165653,101317376,9.55,1700,17,9.67,100,1,10.61,200,2,11.27,100,1,11.4,100,1,11.76,100,1,11.93,200,2,12.23,100,1,12.26,700,1,12.33,200,2,14.36,2,1,14.51,100,1,14.59,100,1,14.83,100,1,14.87,100,1,14.95,700,1,14.99,700,1,15.07,700,1,15.09,100,1,15.14,700,1,ARL,115813253
2025-07-17T14:02:01.283528838Z,2025-07-17T14:02:01.283363185Z,160,2,1108,A,B,13.250000000,100,0,121107957,130,165653,101317376,ARL,0,13.25,100,130,165653,101317376,9.55,1700,17,9.67,100,1,10.61,200,2,11.27,100,1,11.4,100,1,11.76,100,1,11.93,200,2,12.23,100,1,12.26,700,1,12.33,200,2,14.36,2,1,14.51,100,1,14.59,100,1,14.83,100,1,14.87,100,1,14.95,700,1,14.99,700,1,15.07,700,1,15.09,100,1,15.14,700,1,ARL,121107957
2025-07-17T14:02:01.283544588Z,2025-07-17T14:02:01.283378637Z,160,2,1108,C,A,14.510000000,100,0,115813261,0,165951,101317377,ARL,0,14.51,100,0,165951,101317377,9.55,1700,17,9.67,100,1,10.61,200,2,11.27,100,1,11.4,100,1,11.76,100,1,11.93,200,2,12.23,100,1,12.26,700,1,12.33,200,2,14.36,2,1,14.59,100,1,14.83,100,1,14.87,100,1,14.95,700,1,14.99,700,1,15.07,700,1,15.09,100,1,15.14,700,1,15.16,100,1,ARL,115813261
2025-07-17T14:02:01.283544588Z,2025-07-17T14:02:01.283378637Z,160,2,1108,A,A,14.370000000,100,0,121107961,130,165951,101317377,ARL,0,14.37,100,130,165951,101317377,9.55,1700,17,9.67,100,1,10.61,200,2,11.27,100,1,11.4,100,1,11.76,100,1,11.93,200,2,12.23,100,1,12.26,700,1,12.33,200,2,14.36,2,1,14.37,100,1,14.59,100,1,14.83,100,1,14.87,100,1,14.95,700,1,14.99,700,1,15.07,700,1,15.09,100,1,15.14,700,1,ARL,121107961
2025-07-17T14:04:21.248906318Z,2025-07-17T14:04:21.248740930Z,160,2,1108,A,A,14.350000000,1,0,126872197,130,165388,106336852,ARL,0,14.35,1,130,165388,106336852,9.55,1700,17,9.67,100,1,10.61,200,2,11.27,100,1,11.4,100,1,11.76,100,1,11.93,200,2,12.23,100,1,12.26,700,1,12.33,200,2,14.35,1,1,14.36,2,1,14.37,100,1,14.59,100,1,14.83,100,1,14.87,100,1,14.95,700,1,14.99,700,1,15.07,700,1,15.09,100,1,ARL,126872197
2025-07-17T14:04:21.250325900Z,2025-07-17T14:04:21.250160548Z,160,2,1108,C,B,12.510000000,100,0,115474357,0,165352,106336976,ARL,0,12.51,100,0,165352,106336976,9.55,1700,17,9.67,100,1,10.61,200,2,11.27,100,1,11.4,100,1,11.76,100,1,11.93,200,2,12.23,100,1,12.26,700,1,12.33,200,2,14.35,1,1,14.36,2,1,14.37,100,1,14.59,100,1,14.83,100,1,14.87,100,1,14.95,700,1,14.99,700,1,15.07,700,1,15.09,100,1,ARL,115474357
2025-07-17T14:04:21.250325900Z,2025-07-17T14:04:21.250160548Z,160,2,1108,A,B,12.360000000,100,0,126872345,130,165352,106336976,ARL,0,12.36,100,130,165352,106336976,9.55,1700,17,9.67,100,1,10.61,200,2,11.27,100,1,11.4,100,1,11.76,100,1,11.93,200,2,12.23,100,1,12.26,700,1,12.33,200,2,14.35,1,1,14.36,2,1,14.37,100,1,14.59,100,1,14.83,100,1,14.87,100,1,14.95,700,1,14.99,700,1,15.07,700,1,15.09,100,1,ARL,126872345
2025-07-17T14:04:21.250797741Z,2025-07-17T14:04:21.250632048Z,160,2,1108,C,B,12.510000000,100,0,115474337,0,165693,106337002,ARL,0,12.51,100,0,165693,106337002,9.55,1700,17,9.67,100,1,10.61,200,2,11.27,100,1,11.4,100,1,11.76,100,1,11.93,200,2,12.23,100,1,12.26,700,1,12.33,200,2,14.35,1,1,14.36,2,1,14.37,100,1,14.59,100,1,14.83,100,1,14.87,100,1,14.95,700,1,14.99,700,1,15.07,700,1,15.09,100,1,ARL,115474337
2025-07-17T14:04:21.250797741Z,2025-07-17T14:04:21.250632048Z,160,2,1108,A,B,12.360000000,100,0,126872361,130,165693,106337002,ARL,0,12.36,100,130,165693,106337002,9.55,1700,17,9.67,100,1,10.61,200,2,11.27,100,1,11.4,100,1,11.76,100,1,11.93,200,2,12.23,100,1,12.26,700,1,12.33,200,2,14.35,1,1,14.36,2,1,14.37,100,1,14.59,100,1,14.83,100,1,14.87,100,1,14.95,700,1,14.99,700,1,15.07,700,1,15.09,100,1,ARL,126872361
2025-07-17T14:04:21.350207939Z,2025-07-17T14:04:21.350041949Z,160,2,1108,C,A,14.350000000,1,0,126872197,128,165990,106339204,ARL,0,14.35,1,128,165990,106339204,9.55,1700,17,9.67,100,1,10.61,200,2,11.27,100,1,11.4,100,1,11.76,100,1,11.93,200,2,12.23,100,1,12.26,700,1,12.33,200,2,14.36,2,1,14.37,100,1,14.59,100,1,14.83,100,1,14.87,100,1,14.95,700,1,14.99,700,1,15.07,700,1,15.09,100,1,15.14,700,1,ARL,126872197
2025-07-17T14:04:54.699926747Z,2025-07-17T14:04:54.699761263Z,160,2,1108,C,A,15.460000000,100,0,92510753,0,165484,107313441,ARL,0,15.46,100,0,165484,107313441,9.55,1700,17,9.67,100,1,10.61,200,2,11.27,100,1,11.4,100,1,11.76,100,1,11.93,200,2,12.23,100,1,12.26,700,1,12.33,200,2,14.36,2,1,14.37,100,1,14.59,100,1,14.83,100,1,14.87,100,1,14.95,700,1,14.99,700,1,15.07,700,1,15.09,100,1,15.14,700,1,ARL,92510753
2025-07-17T14:04:54.699926747Z,2025-07-17T14:04:54.699761263Z,160,2,1108,A,A,15.340000000,100,0,127999501,130,165484,107313441,ARL,0,15.34,100,130,165484,107313441,9.55,1700,17,9.67,100,1,10.61,200,2,11.27,100,1,11.4,100,1,11.76,100,1,11.93,200,2,12.23,100,1,12.26,700,1,12.33,200,2,14.36,2,1,14.37,100,1,14.59,100,1,14.83,100,1,14.87,100,1,14.95,700,1,14.99,700,1,15.07,700,1,15.09,100,1,15.14,700,1,ARL,127999501
2025-07-17T14:05:10.258855609Z,2025-07-17T14:05:10.258689253Z,160,2,1108,A,A,14.080000000,1,0,128570149,130,166356,107833096,ARL,0,14.08,1,130,166356,107833096,9.55,1700,17,9.67,100,1,10.61,200,2,11.27,100,1,11.4,100,1,11.76,100,1,11.93,200,2,12.23,100,1,12.26,700,1,12.33,200,2,14.08,1,1,14.36,2,1,14.37,100,1,14.59,100,1,14.83,100,1,14.87,100,1,14.95,700,1,14.99,700,1,15.07,700,1,15.09,100,1,ARL,128570149
2025-07-17T14:05:10.259513876Z,2025-07-17T14:05:10.259348471Z,160,2,1108,C,A,15.260000000,100,0,108217173,0,165405,107833168,ARL,0,15.26,100,0,165405,107833168,9.55,1700,17,9.67,100,1,10.61,200,2,11.27,100,1,11.4,100,1,11.76,100,1,11.93,200,2,12.23,100,1,12.26,700,1,12.33,200,2,14.08,1,1,14.36,2,1,14.37,100,1,14.59,100,1,14.83,100,1,14.87,100,1,14.95,700,1,14.99,700,1,15.07,700,1,15.09,100,1,ARL,108217173
2025-07-17T14:05:10.259513876Z,2025-07-17T14:05:10.259348471Z,160,2,1108,A,A,14.980000000,100,0,128570229,130,165405,107833168,ARL,0,14.98,100,130,165405,107833168,9.55,1700,17,9.67,100,1,10.61,200,2,11.27,100,1,11.4,100,1,11.76,100,1,11.93,200,2,12.23,100,1,12.26,700,1,12.33,200,2,14.08,1,1,14.36,2,1,14.37,100,1,14.59,100,1,14.83,100,1,14.87,100,1,14.95,700,1,14.98,100,1,14.99,700,1,15.07,700,1,ARL,128570229
2025-07-17T14:05:10.259895236Z,2025-07-17T14:05:10.259729446Z,160,2,1108,C,A,15.260000000,100,0,108217045,0,165790,107833188,ARL,0,15.26,100,0,165790,107833188,9.55,1700,17,9.67,100,1,10.61,200,2,11.27,100,1,11.4,100,1,11.76,100,1,11.93,200,2,12.23,100,1,12.26,700,1,12.33,200,2,14.08,1,1,14.36,2,1,14.37,100,1,14.59,100,1,14.83,100,1,14.87,100,1,14.95,700,1,14.98,100,1,14.99,700,1,15.07,700,1,ARL,108217045
2025-07-17T14:05:10.259895236Z,2025-07-17T14:05:10.259729446Z,160,2,1108,A,A,14.980000000,100,0,128570237,130,165790,107833188,ARL,0,14.98,100,130,165790,107833188,9.55,1700,17,9.67,100,1,10.61,200,2,11.27,100,1,11.4,100,1,11.76,100,1,11.93,200,2,12.23,100,1,12.26,700,1,12.33,200,2,14.08,1,1,14.36,2,1,14.37,100,1,14.59,100,1,14.83,100,1,14.87,100,1,14.95,700,1,14.98,200,2,14.99,700,1,15.07,700,1,ARL,128570237
2025-07-17T14:05:10.262461863Z,2025-07-17T14:05:10.262295631Z,160,2,1108,C,A,14.370000000,100,0,121107961,0,166232,107833310,ARL,0,14.37,100,0,166232,107833310,9.55,1700,17,9.67,100,1,10.61,200,2,11.27,100,1,11.4,100,1,11.76,100,1,11.93,200,2,12.23,100,1,12.26,700,1,12.33,200,2,14.08,1,1,14.36,2,1,14.59,100,1,14.83,100,1,14.87,100,1,14.95,700,1,14.98,200,2,14.99,700,1,15.07,700,1,15.09,100,1,ARL,121107961
2025-07-17T14:05:10.262461863Z,2025-07-17T14:05:10.262295631Z,160,2,1108,A,A,14.090000000,100,0,128570317,130,166232,107833310,ARL,0,14.09,100,130,166232,107833310,9.55,1700,17,9.67,100,1,10.61,200,2,11.27,100,1,11.4,100,1,11.76,100,1,11.93,200,2,12.23,100,1,12.26,700,1,12.33,200,2,14.08,1,1,14.09,100,1,14.36,2,1,14.59,100,1,14.83,100,1,14.87,100,1,14.95,700,1,14.98,200,2,14.99,700,1,15.07,700,1,ARL,128570317
2025-07-17T14:05:10.262866527Z,2025-07-17T14:05:10.262701351Z,160,2,1108,C,A,14.080000000,1,0,128570149,130,165176,107833359,ARL,0,14.08,1,130,165176,107833359,9.55,1700,17,9.67,100,1,10.61,200,2,11.27,100,1,11.4,100,1,11.76,100,1,11.93,200,2,12.23,100,1,12.26,700,1,12.33,200,2,14.09,100,1,14.36,2,1,14.59,100,1,14.83,100,1,14.87,100,1,14.95,700,1,14.98,200,2,14.99,700,1,15.07,700,1,15.09,100,1,ARL,128570149
2025-07-17T14:05:10.263188035Z,2025-07-17T14:05:10.263022539Z,160,2,1108,C,A,15.340000000,100,0,127999501,0,165496,107833371,ARL,0,15.34,100,0,165496,107833371,9.55,1700,17,9.67,100,1,10.61,200,2,11.27,100,1,11.4,100,1,11.76,100,1,11.93,200,2,12.23,100,1,12.26,700,1,12.33,200,2,14.09,100,1,14.36,2,1,14.59,100,1,14.83,100,1,14.87,100,1,14.95,700,1,14.98,200,2,14.99,700,1,15.07,700,1,15.09,100,1,ARL,127999501
2025-07-17T14:05:10.263188035Z,2025-07-17T14:05:10.263022539Z,160,2,1108,A,A,15.180000000,100,0,128570417,130,165496,107833371,ARL,0,15.18,100,130,165496,107833371,9.55,1700,17,9.67,100,1,10.61,200,2,11.27,100,1,11.4,100,1,11.76,100,1,11.93,200,2,12.23,100,1,12.26,700,1,12.33,200,2,14.09,100,1,14.36,2,1,14.59,100,1,14.83,100,1,14.87,100,1,14.95,700,1,14.98,200,2,14.99,700,1,15.07,700,1,15.09,100,1,ARL,128570417
2025-07-17T14:05:10.264495078Z,2025-07-17T14:05:10.264329670Z,160,2,1108,C,A,15.360000000,100,0,92510761,0,165408,107833404,ARL,0,15.36,100,0,165408,107833404,9.55,1700,17,9.67,100,1,10.61,200,2,11.27,100,1,11.4,100,1,11.76,100,1,11.93,200,2,12.23,100,1,12.26,700,1,12.33,200,2,14.09,100,1,14.36,2,1,14.59,100,1,14.83,100,1,14.87,100,1,14.95,700,1,14.98,200,2,14.99,700,1,15.07,700,1,15.09,100,1,ARL,92510761
2025-07-17T14:05:10.264495078Z,2025-07-17T14:05:10.264329670Z,160,2,1108,A,A,15.080000000,100,0,128570449,130,165408,107833404,ARL,0,15.08,100,130,165408,107833404,9.55,1700,17,9.67,100,1,10.61,200,2,11.27,100,1,11.4,100,1,11.76,100,1,11.93,200,2,12.23,100,1,12.26,700,1,12.33,200,2,14.09,100,1,14.36,2,1,14.59,100,1,14.83,100,1,14.87,100,1,14.95,700,1,14.98,200,2,14.99,700,1,15.07,700,1,15.08,100,1,ARL,128570449
2025-07-17T14:05:10.264590318Z,2025-07-17T14:05:10.264425026Z,160,2,1108,C,A,15.090000000,100,0,84650629,130,165292,107833406,ARL,0,15.09,100,130,165292,107833406,9.55,1700,17,9.67,100,1,10.61,200,2,11.27,100,1,11.4,100,1,11.76,100,1,11.93,200,2,12.23,100,1,12.26,700,1,12.33,200,2,14.09,100,1,14.36,2,1,14.59,100,1,14.83,100,1,14.87,100,1,14.95,700,1,14.98,200,2,14.99,700,1,15.07,700,1,15.08,100,1,ARL,84650629
2025-07-17T14:05:10.264715723Z,2025-07-17T14:05:10.264550510Z,160,2,1108,A,A,14.890000000,100,0,128570453,130,165213,107833407,ARL,0,14.89,100,130,165213,107833407,9.55,1700,17,9.67,100,1,10.61,200,2,11.27,100,1,11.4,100,1,11.76,100,1,11.93,200,2,12.23,100,1,12.26,700,1,12.33,200,2,14.09,100,1,14.36,2,1,14.59,100,1,14.83,100,1,14.87,100,1,14.89,100,1,14.95,700,1,14.98,200,2,14.99,700,1,15.07,700,1,ARL,128570453
2025-07-17T14:05:10.269943051Z,2025-07-17T14:05:10.269777131Z,160,2,1108,C,A,14.590000000,100,0,84629329,128,165920,107833716,ARL,0,14.59,100,128,165920,107833716,9.55,1700,17,9.67,100,1,10.61,200,2,11.27,100,1,11.4,100,1,11.76,100,1,11.93,200,2,12.23,100,1,12.26,700,1,12.33,200,2,14.09,100,1,14.36,2,1,14.83,100,1,14.87,100,1,14.89,100,1,14.95,700,1,14.98,200,2,14.99,700,1,15.07,700,1,15.08,100,1,ARL,84629329
2025-07-17T14:05:10.269997960Z,2025-07-17T14:05:10.269832842Z,160,2,1108,A,A,14.370000000,100,0,128570621,130,165118,107833720,ARL,0,14.37,100,130,165118,107833720,9.55,1700,17,9.67,100,1,10.61,200,2,11.27,100,1,11.4,100,1,11.76,100,1,11.93,200,2,12.23,100,1,12.26,700,1,12.33,200,2,14.09,100,1,14.36,2,1,14.37,100,1,14.83,100,1,14.87,100,1,14.89,100,1,14.95,700,1,14.98,200,2,14.99,700,1,15.07,700,1,ARL,128570621
2025-07-17T14:05:10.271865423Z,2025-07-17T14:05:10.271699633Z,160,2,1108,C,A,18.230000000,100,0,92510841,0,165790,107833881,ARL,0,18.23,100,0,165790,107833881,9.55,1700,17,9.67,100,1,10.61,200,2,11.27,100,1,11.4,100,1,11.76,100,1,11.93,200,2,12.23,100,1,12.26,700,1,12.33,200,2,14.09,100,1,14.36,2,1,14.37,100,1,14.83,100,1,14.87,100,1,14.89,100,1,14.95,700,1,14.98,200,2,14.99,700,1,15.07,700,1,ARL,92510841
2025-07-17T14:05:10.271865423Z,2025-07-17T14:05:10.271699633Z,160,2,1108,A,A,17.900000000,100,0,128570685,130,165790,107833881,ARL,0,17.9,100,130,165790,107833881,9.55,1700,17,9.67,100,1,10.61,200,2,11.27,100,1,11.4,100,1,11.76,100,1,11.93,200,2,12.23,100,1,12.26,700,1,12.33,200,2,14.09,100,1,14.36,2,1,14.37,100,1,14.83,100,1,14.87,100,1,14.89,100,1,14.95,700,1,14.98,200,2,14.99,700,1,15.07,700,1,ARL,128570685
2025-07-17T14:05:10.276320920Z,2025-07-17T14:05:10.276155439Z,160,2,1108,C,A,16.510000000,100,0,92510813,0,165481,107834635,ARL,0,16.51,100,0,165481,107834635,9.55,1700,17,9.67,100,1,10.61,200,2,11.27,100,1,11.4,100,1,11.76,100,1,11.93,200,2,12.23,100,1,12.26,700,1,12.33,200,2,14.09,100,1,14.36,2,1,14.37,100,1,14.83,100,1,14.87,100,1,14.89,100,1,14.95,700,1,14.98,200,2,14.99,700,1,15.07,700,1,ARL,92510813
2025-07-17T14:05:10.276320920Z,2025-07-17T14:05:10.276155439Z,160,2,1108,A,A,16.210000000,100,0,128570977,130,165481,107834635,ARL,0,16.21,100,130,165481,107834635,9.55,1700,17,9.67,100,1,10.61,200,2,11.27,100,1,11.4,100,1,11.76,100,1,11.93,200,2,12.23,100,1,12.26,700,1,12.33,200,2,14.09,100,1,14.36,2,1,14.37,100,1,14.83,100,1,14.87,100,1,14.89,100,1,14.95,700,1,14.98,200,2,14.99,700,1,15.07,700,1,ARL,128570977
2025-07-17T14:05:10.342982797Z,2025-07-17T14:05:10.342817229Z,160,2,1108,C,A,15.310000000,100,0,84630849,0,165568,107837761,ARL,0,15.31,100,0,165568,107837761,9.55,1700,17,9.67,100,1,10.61,200,2,11.27,100,1,11.4,100,1,11.76,100,1,11.93,200,2,12.23,100,1,12.26,700,1,12.33,200,2,14.09,100,1,14.36,2,1,14.37,100,1,14.83,100,1,14.87,100,1,14.89,100,1,14.95,700,1,14.98,200,2,14.99,700,1,15.07,700,1,ARL,84630849
2025-07-17T14:05:10.342982797Z,2025-07-17T14:05:10.342817229Z,160,2,1108,A,A,15.080000000,100,0,128573957,130,165568,107837761,ARL,0,15.08,100,130,165568,107837761,9.55,1700,17,9.67,100,1,10.61,200,2,11.27,100,1,11.4,100,1,11.76,100,1,11.93,200,2,12.23,100,1,12.26,700,1,12.33,200,2,14.09,100,1,14.36,2,1,14.37,100,1,14.83,100,1,14.87,100,1,14.89,100,1,14.95,700,1,14.98,200,2,14.99,700,1,15.07,700,1,ARL,128573957
2025-07-17T14:05:31.418741362Z,2025-07-17T14:05:31.418575692Z,160,2,1108,C,A,14.360000000,2,0,121098341,0,165670,108664911,ARL,0,14.36,2,0,165670,108664911,9.55,1700,17,9.67,100,1,10.61,200,2,11.27,100,1,11.4,100,1,11.76,100,1,11.93,200,2,12.23,100,1,12.26,700,1,12.33,200,2,14.09,100,1,14.37,100,1,14.83,100,1,14.87,100,1,14.89,100,1,14.95,700,1,14.98,200,2,14.99,700,1,15.07,700,1,15.08,200,2,ARL,121098341
2025-07-17T14:05:31.418741362Z,2025-07-17T14:05:31.418575692Z,160,2,1108,A,A,14.260000000,2,0,129518753,130,165670,108664911,ARL,0,14.26,2,130,165670,108664911,9.55,1700,17,9.67,100,1,10.61,200,2,11.27,100,1,11.4,100,1,11.76,100,1,11.93,200,2,12.23,100,1,12.26,700,1,12.33,200,2,14.09,100,1,14.26,2,1,14.37,100,1,14.83,100,1,14.87,100,1,14.89,100,1,14.95,700,1,14.98,200,2,14.99,700,1,15.07,700,1,ARL,129518753
2025-07-17T14:06:01.386006059Z,2025-07-17T14:06:01.385840471Z,160,2,1108,C,B,13.260000000,2,0,121098337,0,165588,109685525,ARL,0,13.26,2,0,165588,109685525,9.55,1700,17,9.67,100,1,10.61,200,2,11.27,100,1,11.4,100,1,11.76,100,1,11.93,200,2,12.23,100,1,12.26,700,1,12.33,200,2,14.09,100,1,14.26,2,1,14.37,100,1,14.83,100,1,14.87,100,1,14.89,100,1,14.95,700,1,14.98,200,2,14.99,700,1,15.07,700,1,ARL,121098337
2025-07-17T14:06:01.386006059Z,2025-07-17T14:06:01.385840471Z,160,2,1108,A,B,13.150000000,2,0,130693973,130,165588,109685525,ARL,0,13.15,2,130,165588,109685525,9.55,1700,17,9.67,100,1,10.61,200,2,11.27,100,1,11.4,100,1,11.76,100,1,11.93,200,2,12.23,100,1,12.26,700,1,12.33,200,2,14.09,100,1,14.26,2,1,14.37,100,1,14.83,100,1,14.87,100,1,14.89,100,1,14.95,700,1,14.98,200,2,14.99,700,1,15.07,700,1,ARL,130693973
2025-07-17T14:13:11.346377890Z,2025-07-17T14:13:11.346212166Z,160,2,1108,C,A,15.180000000,100,0,128570417,0,165724,123937587,ARL,0,15.18,100,0,165724,123937587,9.55,1700,17,9.67,100,1,10.61,200,2,11.27,100,1,11.4,100,1,11.76,100,1,11.93,200,2,12.23,100,1,12.26,700,1,12.33,200,2,14.09,100,1,14.26,2,1,14.37,100,1,14.83,100,1,14.87,100,1,14.89,100,1,14.95,700,1,14.98,200,2,14.99,700,1,15.07,700,1,ARL,128570417
2025-07-17T14:13:11.346377890Z,2025-07-17T14:13:11.346212166Z,160,2,1108,A,A,15.090000000,100,0,146955361,130,165724,123937587,ARL,0,15.09,100,130,165724,123937587,9.55,1700,17,9.67,100,1,10.61,200,2,11.27,100,1,11.4,100,1,11.76,100,1,11.93,200,2,12.23,100,1,12.26,700,1,12.33,200,2,14.09,100,1,14.26,2,1,14.37,100,1,14.83,100,1,14.87,100,1,14.89,100,1,14.95,700,1,14.98,200,2,14.99,700,1,15.07,700,1,ARL,146955361
2025-07-17T14:13:11.358916626Z,2025-07-17T14:13:11.358751092Z,160,2,1108,C,A,14.370000000,100,0,128570621,130,165534,123938202,ARL,0,14.37,100,130,165534,123938202,9.55,1700,17,9.67,100,1,10.61,200,2,11.27,100,1,11.4,100,1,11.76,100,1,11.93,200,2,12.23,100,1,12.26,700,1,12.33,200,2,14.09,100,1,14.26,2,1,14.83,100,1,14.87,100,1,14.89,100,1,14.95,700,1,14.98,200,2,14.99,700,1,15.07,700,1,15.08,200,2,ARL,128570621
2025-07-17T14:13:11.358968656Z,2025-07-17T14:13:11.358802966Z,160,2,1108,A,A,14.280000000,100,0,146956357,130,165690,123938203,ARL,0,14.28,100,130,165690,123938203,9.55,1700,17,9.67,100,1,10.61,200,2,11.27,100,1,11.4,100,1,11.76,100,1,11.93,200,2,12.23,100,1,12.26,700,1,12.33,200,2,14.09,100,1,14.26,2,1,14.28,100,1,14.83,100,1,14.87,100,1,14.89,100,1,14.95,700,1,14.98,200,2,14.99,700,1,15.07,700,1,ARL,146956357
2025-07-17T14:13:11.393088913Z,2025-07-17T14:13:11.392923396Z,160,2,1108,C,A,15.730000000,100,0,84629953,0,165517,123939815,ARL,0,15.73,100,0,165517,123939815,9.55,1700,17,9.67,100,1,10.61,200,2,11.27,100,1,11.4,100,1,11.76,100,1,11.93,200,2,12.23,100,1,12.26,700,1,12.33,200,2,14.09,100,1,14.26,2,1,14.28,100,1,14.83,100,1,14.87,100,1,14.89,100,1,14.95,700,1,14.98,200,2,14.99,700,1,15.07,700,1,ARL,84629953
2025-07-17T14:13:11.393088913Z,2025-07-17T14:13:11.392923396Z,160,2,1108,A,A,15.400000000,100,0,146959177,130,165517,123939815,ARL,0,15.4,100,130,165517,123939815,9.55,1700,17,9.67,100,1,10.61,200,2,11.27,100,1,11.4,100,1,11.76,100,1,11.93,200,2,12.23,100,1,12.26,700,1,12.33,200,2,14.09,100,1,14.26,2,1,14.28,100,1,14.83,100,1,14.87,100,1,14.89,100,1,14.95,700,1,14.98,200,2,14.99,700,1,15.07,700,1,ARL,146959177
2025-07-17T14:13:11.423482323Z,2025-07-17T14:13:11.423316840Z,160,2,1108,A,A,14.560000000,100,0,146960005,130,165483,123940437,ARL,0,14.56,100,130,165483,123940437,9.55,1700,17,9.67,100,1,10.61,200,2,11.27,100,1,11.4,100,1,11.76,100,1,11.93,200,2,12.23,100,1,12.26,700,1,12.33,200,2,14.09,100,1,14.26,2,1,14.28,100,1,14.56,100,1,14.83,100,1,14.87,100,1,14.89,100,1,14.95,700,1,14.98,200,2,14.99,700,1,ARL,146960005
2025-07-17T14:13:11.423483431Z,2025-07-17T14:13:11.423317922Z,160,2,1108,C,A,14.870000000,100,0,84708037,130,165509,123940438,ARL,0,14.87,100,130,165509,123940438,9.55,1700,17,9.67,100,1,10.61,200,2,11.27,100,1,11.4,100,1,11.76,100,1,11.93,200,2,12.23,100,1,12.26,700,1,12.33,200,2,14.09,100,1,14.26,2,1,14.28,100,1,14.56,100,1,14.83,100,1,14.89,100,1,14.95,700,1,14.98,200,2,14.99,700,1,15.07,700,1,ARL,84708037
2025-07-17T14:13:11.555808541Z,2025-07-17T14:13:11.555642984Z,160,2,1108,A,A,14.840000000,100,0,146962993,130,165557,123942727,ARL,0,14.84,100,130,165557,123942727,9.55,1700,17,9.67,100,1,10.61,200,2,11.27,100,1,11.4,100,1,11.76,100,1,11.93,200,2,12.23,100,1,12.26,700,1,12.33,200,2,14.09,100,1,14.26,2,1,14.28,100,1,14.56,100,1,14.83,100,1,14.84,100,1,14.89,100,1,14.95,700,1,14.98,200,2,14.99,700,1,ARL,146962993
2025-07-17T14:13:11.555828856Z,2025-07-17T14:13:11.555663413Z,160,2,1108,C,A,15.160000000,100,0,84668677,130,165443,123942728,ARL,0,15.16,100,130,165443,123942728,9.55,1700,17,9.67,100,1,10.61,200,2,11.27,100,1,11.4,100,1,11.76,100,1,11.93,200,2,12.23,100,1,12.26,700,1,12.33,200,2,14.09,100,1,14.26,2,1,14.28,100,1,14.56,100,1,14.83,100,1,14.84,100,1,14.89,100,1,14.95,700,1,14.98,200,2,14.99,700,1,ARL,84668677
2025-07-17T14:13:19.230983072Z,2025-07-17T14:13:19.230817808Z,160,2,1108,A,A,14.910000000,700,0,147217629,130,165264,124169794,ARL,0,14.91,700,130,165264,124169794,9.55,1700,17,9.67,100,1,10.61,200,2,11.27,100,1,11.4,100,1,11.76,100,1,11.93,200,2,12.23,100,1,12.26,700,1,12.33,200,2,14.09,100,1,14.26,2,1,14.28,100,1,14.56,100,1,14.83,100,1,14.84,100,1,14.89,100,1,14.91,700,1,14.95,700,1,14.98,200,2,ARL,147217629
2025-07-17T14:13:19.231778755Z,2025-07-17T14:13:19.231613044Z,160,2,1108,C,A,15.140000000,700,0,84628829,130,165711,124169802,ARL,0,15.14,700,130,165711,124169802,9.55,1700,17,9.67,100,1,10.61,200,2,11.27,100,1,11.4,100,1,11.76,100,1,11.93,200,2,12.23,100,1,12.26,700,1,12.33,200,2,14.09,100,1,14.26,2,1,14.28,100,1,14.56,100,1,14.83,100,1,14.84,100,1,14.89,100,1,14.91,700,1,14.95,700,1,14.98,200,2,ARL,84628829
2025-07-17T14:22:28.338174848Z,2025-07-17T14:22:28.338009329Z,160,2,1108,A,A,14.000000000,1,0,168073025,130,165519,142657338,ARL,0,14,1,130,165519,142657338,9.55,1700,17,9.67,100,1,10.61,200,2,11.27,100,1,11.4,100,1,11.76,100,1,11.93,200,2,12.23,100,1,12.26,700,1,12.33,200,2,14,1,1,14.09,100,1,14.26,2,1,14.28,100,1,14.56,100,1,14.83,100,1,14.84,100,1,14.89,100,1,14.91,700,1,14.95,700,1,ARL,168073025
2025-07-17T14:22:29.994011311Z,2025-07-17T14:22:29.993845812Z,160,2,1108,C,A,14.090000000,100,0,128570317,0,165499,142715813,ARL,0,14.09,100,0,165499,142715813,9.55,1700,17,9.67,100,1,10.61,200,2,11.27,100,1,11.4,100,1,11.76,100,1,11.93,200,2,12.23,100,1,12.26,700,1,12.33,200,2,14,1,1,14.26,2,1,14.28,100,1,14.56,100,1,14.83,100,1,14.84,100,1,14.89,100,1,14.91,700,1,14.95,700,1,14.98,200,2,ARL,128570317
2025-07-17T14:22:29.994011311Z,2025-07-17T14:22:29.993845812Z,160,2,1108,A,A,14.010000000,100,0,168141389,130,165499,142715813,ARL,0,14.01,100,130,165499,142715813,9.55,1700,17,9.67,100,1,10.61,200,2,11.27,100,1,11.4,100,1,11.76,100,1,11.93,200,2,12.23,100,1,12.26,700,1,12.33,200,2,14,1,1,14.01,100,1,14.26,2,1,14.28,100,1,14.56,100,1,14.83,100,1,14.84,100,1,14.89,100,1,14.91,700,1,14.95,700,1,ARL,168141389
2025-07-17T14:32:58.233129156Z,2025-07-17T14:32:58.232963791Z,160,2,1108,C,B,13.250000000,100,0,121107957,130,165365,162140358,ARL,0,13.25,100,130,165365,162140358,9.55,1700,17,9.67,100,1,10.61,200,2,11.27,100,1,11.4,100,1,11.76,100,1,11.93,200,2,12.23,100,1,12.26,700,1,12.33,200,2,14,1,1,14.01,100,1,14.26,2,1,14.28,100,1,14.56,100,1,14.83,100,1,14.84,100,1,14.89,100,1,14.91,700,1,14.95,700,1,ARL,121107957
2025-07-17T14:32:58.714015555Z,2025-07-17T14:32:58.713850212Z,160,2,1108,A,B,13.140000000,100,0,190326921,130,165343,162149922,ARL,0,13.14,100,130,165343,162149922,9.55,1700,17,9.67,100,1,10.61,200,2,11.27,100,1,11.4,100,1,11.76,100,1,11.93,200,2,12.23,100,1,12.26,700,1,12.33,200,2,14,1,1,14.01,100,1,14.26,2,1,14.28,100,1,14.56,100,1,14.83,100,1,14.84,100,1,14.89,100,1,14.91,700,1,14.95,700,1,ARL,190326921
2025-07-17T14:34:48.346344959Z,2025-07-17T14:34:48.346179643Z,160,2,1108,C,A,14.000000000,1,0,168073025,130,165316,164925706,ARL,0,14,1,130,165316,164925706,9.55,1700,17,9.67,100,1,10.61,200,2,11.27,100,1,11.4,100,1,11.76,100,1,11.93,200,2,12.23,100,1,12.26,700,1,12.33,200,2,14.01,100,1,14.26,2,1,14.28,100,1,14.56,100,1,14.83,100,1,14.84,100,1,14.89,100,1,14.91,700,1,14.95,700,1,14.98,200,2,ARL,168073025
2025-07-17T14:47:30.548081358Z,2025-07-17T14:47:30.547915870Z,160,2,1108,A,B,13.380000000,33,0,215999733,130,165488,183466992,ARL,0,13.38,33,130,165488,183466992,9.55,1700,17,9.67,100,1,10.61,200,2,11.27,100,1,11.4,100,1,11.76,100,1,11.93,200,2,12.23,100,1,12.26,700,1,12.33,200,2,14.01,100,1,14.26,2,1,14.28,100,1,14.56,100,1,14.83,100,1,14.84,100,1,14.89,100,1,14.91,700,1,14.95,700,1,14.98,200,2,ARL,215999733
2025-07-17T14:47:30.548346701Z,2025-07-17T14:47:30.548180936Z,160,2,1108,C,B,13.140000000,100,0,190326921,0,165765,183466994,ARL,0,13.14,100,0,165765,183466994,9.55,1700,17,9.67,100,1,10.61,200,2,11.27,100,1,11.4,100,1,11.76,100,1,11.93,200,2,12.23,100,1,12.26,700,1,12.33,200,2,14.01,100,1,14.26,2,1,14.28,100,1,14.56,100,1,14.83,100,1,14.84,100,1,14.89,100,1,14.91,700,1,14.95,700,1,14.98,200,2,ARL,190326921
2025-07-17T14:47:30.548346701Z,2025-07-17T14:47:30.548180936Z,160,2,1108,A,B,13.370000000,100,0,215999737,130,165765,183466994,ARL,0,13.37,100,130,165765,183466994,9.55,1700,17,9.67,100,1,10.61,200,2,11.27,100,1,11.4,100,1,11.76,100,1,11.93,200,2,12.23,100,1,12.26,700,1,12.33,200,2,14.01,100,1,14.26,2,1,14.28,100,1,14.56,100,1,14.83,100,1,14.84,100,1,14.89,100,1,14.91,700,1,14.95,700,1,14.98,200,2,ARL,215999737
2025-07-17T14:47:30.548831608Z,2025-07-17T14:47:30.548666035Z,160,2,1108,C,B,12.360000000,100,0,126872345,0,165573,183467001,ARL,0,12.36,100,0,165573,183467001,9.55,1700,17,9.67,100,1,10.61,200,2,11.27,100,1,11.4,100,1,11.76,100,1,11.93,200,2,12.23,100,1,12.26,700,1,12.33,200,2,14.01,100,1,14.26,2,1,14.28,100,1,14.56,100,1,14.83,100,1,14.84,100,1,14.89,100,1,14.91,700,1,14.95,700,1,14.98,200,2,ARL,126872345
2025-07-17T14:47:30.548831608Z,2025-07-17T14:47:30.548666035Z,160,2,1108,A,B,12.480000000,100,0,215999741,130,165573,183467001,ARL,0,12.48,100,130,165573,183467001,9.55,1700,17,9.67,100,1,10.61,200,2,11.27,100,1,11.4,100,1,11.76,100,1,11.93,200,2,12.23,100,1,12.26,700,1,12.33,200,2,14.01,100,1,14.26,2,1,14.28,100,1,14.56,100,1,14.83,100,1,14.84,100,1,14.89,100,1,14.91,700,1,14.95,700,1,14.98,200,2,ARL,215999741
2025-07-17T14:47:30.549090785Z,2025-07-17T14:47:30.548925394Z,160,2,1108,C,B,12.230000000,100,0,43317473,0,165391,183467002,ARL,0,12.23,100,0,165391,183467002,9.55,1700,17,9.67,100,1,10.61,200,2,11.27,100,1,11.4,100,1,11.76,100,1,11.93,200,2,12.26,700,1,12.33,200,2,12.36,100,1,14.01,100,1,14.26,2,1,14.28,100,1,14.56,100,1,14.83,100,1,14.84,100,1,14.89,100,1,14.91,700,1,14.95,700,1,14.98,200,2,ARL,43317473
2025-07-17T14:47:30.549090785Z,2025-07-17T14:47:30.548925394Z,160,2,1108,A,B,12.330000000,100,0,215999753,130,165391,183467002,ARL,0,12.33,100,130,165391,183467002,9.55,1700,17,9.67,100,1,10.61,200,2,11.27,100,1,11.4,100,1,11.76,100,1,11.93,200,2,12.26,700,1,12.33,300,3,12.36,100,1,14.01,100,1,14.26,2,1,14.28,100,1,14.56,100,1,14.83,100,1,14.84,100,1,14.89,100,1,14.91,700,1,14.95,700,1,14.98,200,2,ARL,215999753
2025-07-17T14:47:30.549341156Z,2025-07-17T14:47:30.549175659Z,160,2,1108,C,B,12.360000000,100,0,126872361,0,165497,183467004,ARL,0,12.36,100,0,165497,183467004,9.55,1700,17,9.67,100,1,10.61,200,2,11.27,100,1,11.4,100,1,11.76,100,1,11.93,200,2,12.26,700,1,12.33,300,3,12.37,700,1,14.01,100,1,14.26,2,1,14.28,100,1,14.56,100,1,14.83,100,1,14.84,100,1,14.89,100,1,14.91,700,1,14.95,700,1,14.98,200,2,ARL,126872361
2025-07-17T14:47:30.549341156Z,2025-07-17T14:47:30.549175659Z,160,2,1108,A,B,12.480000000,100,0,215999761,130,165497,183467004,ARL,0,12.48,100,130,165497,183467004,9.55,1700,17,9.67,100,1,10.61,200,2,11.27,100,1,11.4,100,1,11.76,100,1,11.93,200,2,12.26,700,1,12.33,300,3,12.37,700,1,14.01,100,1,14.26,2,1,14.28,100,1,14.56,100,1,14.83,100,1,14.84,100,1,14.89,100,1,14.91,700,1,14.95,700,1,14.98,200,2,ARL,215999761
2025-07-17T14:47:30.571385383Z,2025-07-17T14:47:30.571220121Z,160,2,1108,C,B,12.990000000,100,0,43805737,130,165262,183468111,ARL,0,12.99,100,130,165262,183468111,9.55,1700,17,9.67,100,1,10.61,200,2,11.27,100,1,11.4,100,1,11.76,100,1,11.93,200,2,12.26,700,1,12.33,300,3,12.37,700,1,14.01,100,1,14.26,2,1,14.28,100,1,14.56,100,1,14.83,100,1,14.84,100,1,14.89,100,1,14.91,700,1,14.95,700,1,14.98,200,2,ARL,43805737
2025-07-17T14:47:30.571436944Z,2025-07-17T14:47:30.571271737Z,160,2,1108,A,B,13.100000000,100,0,216001413,130,165207,183468112,ARL,0,13.1,100,130,165207,183468112,9.55,1700,17,9.67,100,1,10.61,200,2,11.27,100,1,11.4,100,1,11.76,100,1,11.93,200,2,12.26,700,1,12.33,300,3,12.37,700,1,14.01,100,1,14.26,2,1,14.28,100,1,14.56,100,1,14.83,100,1,14.84,100,1,14.89,100,1,14.91,700,1,14.95,700,1,14.98,200,2,ARL,216001413
2025-07-17T14:47:37.384610677Z,2025-07-17T14:47:37.384441232Z,160,2,1108,A,B,12.500000000,700,0,216223005,130,169445,183649796,ARL,0,12.5,700,130,169445,183649796,9.55,1700,17,9.67,100,1,10.61,200,2,11.27,100,1,11.4,100,1,11.76,100,1,11.93,200,2,12.26,700,1,12.33,300,3,12.37,700,1,14.01,100,1,14.26,2,1,14.28,100,1,14.56,100,1,14.83,100,1,14.84,100,1,14.89,100,1,14.91,700,1,14.95,700,1,14.98,200,2,ARL,216223005
2025-07-17T14:47:37.385400265Z,2025-07-17T14:47:37.385234288Z,160,2,1108,C,B,12.260000000,700,0,44570585,130,165977,183649801,ARL,0,12.26,700,130,165977,183649801,9.55,1700,17,9.67,100,1,10.61,200,2,11.27,100,1,11.4,100,1,11.76,100,1,11.93,200,2,12.33,300,3,12.37,700,1,12.42,700,1,14.01,100,1,14.26,2,1,14.28,100,1,14.56,100,1,14.83,100,1,14.84,100,1,14.89,100,1,14.91,700,1,14.95,700,1,14.98,200,2,ARL,44570585
2025-07-17T14:52:02.610481877Z,2025-07-17T14:52:02.610315566Z,160,2,1108,T,N,13.410000000,1,0,0,130,166311,189559140,ARL,0,13.41,1,130,166311,189559140,9.55,1700,17,9.67,100,1,10.61,200,2,11.27,100,1,11.4,100,1,11.76,100,1,11.93,200,2,12.33,300,3,12.37,700,1,12.42,700,1,14.01,100,1,14.26,2,1,14.28,100,1,14.56,100,1,14.83,100,1,14.84,100,1,14.89,100,1,14.91,700,1,14.95,700,1,14.98,200,2,ARL,0
2025-07-17T14:52:02.610509102Z,2025-07-17T14:52:02.610343819Z,160,2,1108,A,A,13.710000000,1,0,223347833,130,165283,189559141,ARL,0,13.71,1,130,165283,189559141,9.55,1700,17,9.67,100,1,10.61,200,2,11.27,100,1,11.4,100,1,11.76,100,1,11.93,200,2,12.33,300,3,12.37,700,1,12.42,700,1,13.71,1,1,14.01,100,1,14.26,2,1,14.28,100,1,14.56,100,1,14.83,100,1,14.84,100,1,14.89,100,1,14.91,700,1,14.95,700,1,ARL,223347833
2025-07-17T14:52:02.611701408Z,2025-07-17T14:52:02.611536221Z,160,2,1108,C,A,13.710000000,1,0,223347833,130,165187,189559156,ARL,0,13.71,1,130,165187,189559156,9.55,1700,17,9.67,100,1,10.61,200,2,11.27,100,1,11.4,100,1,11.76,100,1,11.93,200,2,12.33,300,3,12.37,700,1,12.42,700,1,14.01,100,1,14.26,2,1,14.28,100,1,14.56,100,1,14.83,100,1,14.84,100,1,14.89,100,1,14.91,700,1,14.95,700,1,14.98,200,2,ARL,223347833
2025-07-17T15:00:11.560678862Z,2025-07-17T15:00:11.560513555Z,160,2,1108,C,B,13.380000000,33,0,215999733,130,165307,200140364,ARL,0,13.38,33,130,165307,200140364,9.55,1700,17,9.67,100,1,10.61,200,2,11.27,100,1,11.4,100,1,11.76,100,1,11.93,200,2,12.33,300,3,12.37,700,1,12.42,700,1,14.01,100,1,14.26,2,1,14.28,100,1,14.56,100,1,14.83,100,1,14.84,100,1,14.89,100,1,14.91,700,1,14.95,700,1,14.98,200,2,ARL,215999733
2025-07-17T15:00:11.563053782Z,2025-07-17T15:00:11.562887948Z,160,2,1108,C,B,12.480000000,100,0,215999761,0,165834,200140389,ARL,0,12.48,100,0,165834,200140389,9.55,1700,17,9.67,100,1,10.61,200,2,11.27,100,1,11.4,100,1,11.76,100,1,11.93,200,2,12.33,300,3,12.37,700,1,12.42,700,1,14.01,100,1,14.26,2,1,14.28,100,1,14.56,100,1,14.83,100,1,14.84,100,1,14.89,100,1,14.91,700,1,14.95,700,1,14.98,200,2,ARL,215999761
2025-07-17T15:00:11.563053782Z,2025-07-17T15:00:11.562887948Z,160,2,1108,A,B,12.650000000,100,0,236179089,130,165834,200140389,ARL,0,12.65,100,130,165834,200140389,9.55,1700,17,9.67,100,1,10.61,200,2,11.27,100,1,11.4,100,1,11.76,100,1,11.93,200,2,12.33,300,3,12.37,700,1,12.42,700,1,14.01,100,1,14.26,2,1,14.28,100,1,14.56,100,1,14.83,100,1,14.84,100,1,14.89,100,1,14.91,700,1,14.95,700,1,14.98,200,2,ARL,236179089
2025-07-17T15:00:12.536218524Z,2025-07-17T15:00:12.536052536Z,160,2,1108,C,B,12.480000000,100,0,215999741,0,165988,200161810,ARL,0,12.48,100,0,165988,200161810,9.55,1700,17,9.67,100,1,10.61,200,2,11.27,100,1,11.4,100,1,11.76,100,1,11.93,200,2,12.33,300,3,12.37,700,1,12.42,700,1,14.01,100,1,14.26,2,1,14.28,100,1,14.56,100,1,14.83,100,1,14.84,100,1,14.89,100,1,14.91,700,1,14.95,700,1,14.98,200,2,ARL,215999741
2025-07-17T15:00:12.536218524Z,2025-07-17T15:00:12.536052536Z,160,2,1108,A,B,12.650000000,100,0,236206261,130,165988,200161810,ARL,0,12.65,100,130,165988,200161810,9.55,1700,17,9.67,100,1,10.61,200,2,11.27,100,1,11.4,100,1,11.76,100,1,11.93,200,2,12.33,300,3,12.37,700,1,12.42,700,1,14.01,100,1,14.26,2,1,14.28,100,1,14.56,100,1,14.83,100,1,14.84,100,1,14.89,100,1,14.91,700,1,14.95,700,1,14.98,200,2,ARL,236206261
2025-07-17T15:01:11.658789910Z,2025-07-17T15:01:11.658624662Z,160,2,1108,A,A,13.980000000,10,0,237940713,130,165248,201616674,ARL,0,13.98,10,130,165248,201616674,9.55,1700,17,9.67,100,1,10.61,200,2,11.27,100,1,11.4,100,1,11.76,100,1,11.93,200,2,12.33,300,3,12.37,700,1,12.42,700,1,13.98,10,1,14.01,100,1,14.26,2,1,14.28,100,1,14.56,100,1,14.83,100,1,14.84,100,1,14.89,100,1,14.91,700,1,14.95,700,1,ARL,237940713
2025-07-17T15:01:12.948386121Z,2025-07-17T15:01:12.948220412Z,160,2,1108,C,A,14.010000000,100,0,168141389,0,165709,201642675,ARL,0,14.01,100,0,165709,201642675,9.55,1700,17,9.67,100,1,10.61,200,2,11.27,100,1,11.4,100,1,11.76,100,1,11.93,200,2,12.33,300,3,12.37,700,1,12.42,700,1,13.98,10,1,14.26,2,1,14.28,100,1,14.56,100,1,14.83,100,1,14.84,100,1,14.89,100,1,14.91,700,1,14.95,700,1,14.98,200,2,ARL,168141389
2025-07-17T15:01:12.948386121Z,2025-07-17T15:01:12.948220412Z,160,2,1108,A,A,13.990000000,100,0,237978541,130,165709,201642675,ARL,0,13.99,100,130,165709,201642675,9.55,1700,17,9.67,100,1,10.61,200,2,11.27,100,1,11.4,100,1,11.76,100,1,11.93,200,2,12.33,300,3,12.37,700,1,12.42,700,1,13.98,10,1,13.99,100,1,14.26,2,1,14.28,100,1,14.56,100,1,14.83,100,1,14.84,100,1,14.89,100,1,14.91,700,1,14.95,700,1,ARL,237978541
2025-07-17T15:01:12.949124493Z,2025-07-17T15:01:12.948959226Z,160,2,1108,C,A,14.830000000,100,0,84628793,130,165267,201642712,ARL,0,14.83,100,130,165267,201642712,9.55,1700,17,9.67,100,1,10.61,200,2,11.27,100,1,11.4,100,1,11.76,100,1,11.93,200,2,12.33,300,3,12.37,700,1,12.42,700,1,13.98,10,1,13.99,100,1,14.26,2,1,14.28,100,1,14.56,100,1,14.84,100,1,14.89,100,1,14.91,700,1,14.95,700,1,14.98,200,2,ARL,84628793
2025-07-17T15:01:12.949484115Z,2025-07-17T15:01:12.949317198Z,160,2,1108,A,A,14.610000000,100,0,237978629,130,166917,201642747,ARL,0,14.61,100,130,166917,201642747,9.55,1700,17,9.67,100,1,10.61,200,2,11.27,100,1,11.4,100,1,11.76,100,1,11.93,200,2,12.33,300,3,12.37,700,1,12.42,700,1,13.98,10,1,13.99,100,1,14.26,2,1,14.28,100,1,14.56,100,1,14.61,100,1,14.84,100,1,14.89,100,1,14.91,700,1,14.95,700,1,ARL,237978629
2025-07-17T15:01:26.963916368Z,2025-07-17T15:01:26.963746832Z,160,2,1108,C,A,13.980000000,10,0,237940713,128,169536,201984003,ARL,0,13.98,10,128,169536,201984003,9.55,1700,17,9.67,100,1,10.61,200,2,11.27,100,1,11.4,100,1,11.76,100,1,11.93,200,2,12.33,300,3,12.37,700,1,12.42,700,1,13.99,100,1,14.26,2,1,14.28,100,1,14.56,100,1,14.61,100,1,14.84,100,1,14.89,100,1,14.91,700,1,14.95,700,1,14.98,200,2,ARL,237940713
2025-07-17T15:01:37.513312432Z,2025-07-17T15:01:37.513147090Z,160,2,1108,A,A,13.980000000,10,0,238668633,130,165342,202186180,ARL,0,13.98,10,130,165342,202186180,9.55,1700,17,9.67,100,1,10.61,200,2,11.27,100,1,11.4,100,1,11.76,100,1,11.93,200,2,12.33,300,3,12.37,700,1,12.42,700,1,13.98,10,1,13.99,100,1,14.26,2,1,14.28,100,1,14.56,100,1,14.61,100,1,14.84,100,1,14.89,100,1,14.91,700,1,14.95,700,1,ARL,238668633
2025-07-17T15:05:36.047202557Z,2025-07-17T15:05:36.047029298Z,160,2,1108,C,A,13.980000000,10,0,238668633,128,173259,207097179,ARL,0,13.98,10,128,173259,207097179,9.55,1700,17,9.67,100,1,10.61,200,2,11.27,100,1,11.4,100,1,11.76,100,1,11.93,200,2,12.33,300,3,12.37,700,1,12.42,700,1,13.99,100,1,14.26,2,1,14.28,100,1,14.56,100,1,14.61,100,1,14.84,100,1,14.89,100,1,14.91,700,1,14.95,700,1,14.98,200,2,ARL,238668633
2025-07-17T15:10:34.469866273Z,2025-07-17T15:10:34.469700487Z,160,2,1108,C,A,14.260000000,2,0,129518753,0,165786,213735006,ARL,0,14.26,2,0,165786,213735006,9.55,1700,17,9.67,100,1,10.61,200,2,11.27,100,1,11.4,100,1,11.76,100,1,11.93,200,2,12.33,300,3,12.37,700,1,12.42,700,1,13.99,100,1,14.28,100,1,14.56,100,1,14.61,100,1,14.84,100,1,14.89,100,1,14.91,700,1,14.95,700,1,14.98,200,2,14.99,700,1,ARL,129518753
2025-07-17T15:10:34.469866273Z,2025-07-17T15:10:34.469700487Z,160,2,1108,A,A,14.170000000,2,0,252720897,130,165786,213735006,ARL,0,14.17,2,130,165786,213735006,9.55,1700,17,9.67,100,1,10.61,200,2,11.27,100,1,11.4,100,1,11.76,100,1,11.93,200,2,12.33,300,3,12.37,700,1,12.42,700,1,13.99,100,1,14.17,2,1,14.28,100,1,14.56,100,1,14.61,100,1,14.84,100,1,14.89,100,1,14.91,700,1,14.95,700,1,14.98,200,2,ARL,252720897
2025-07-17T15:12:52.735414592Z,2025-07-17T15:12:52.735249178Z,160,2,1108,A,A,14.030000000,100,0,256325129,130,165414,216651092,ARL,0,14.03,100,130,165414,216651092,9.55,1700,17,9.67,100,1,10.61,200,2,11.27,100,1,11.4,100,1,11.76,100,1,11.93,200,2,12.33,300,3,12.37,700,1,12.42,700,1,13.99,100,1,14.03,100,1,14.17,2,1,14.28,100,1,14.56,100,1,14.61,100,1,14.84,100,1,14.89,100,1,14.91,700,1,14.95,700,1,ARL,256325129
2025-07-17T15:13:06.511853457Z,2025-07-17T15:13:06.511687613Z,160,2,1108,A,A,13.980000000,10,0,256739841,130,165844,216995105,ARL,0,13.98,10,130,165844,216995105,9.55,1700,17,9.67,100,1,10.61,200,2,11.27,100,1,11.4,100,1,11.76,100,1,11.93,200,2,12.33,300,3,12.37,700,1,12.42,700,1,13.98,10,1,13.99,100,1,14.03,100,1,14.17,2,1,14.28,100,1,14.56,100,1,14.61,100,1,14.84,100,1,14.89,100,1,14.91,700,1,ARL,256739841
2025-07-17T15:13:08.654089411Z,2025-07-17T15:13:08.653923821Z,160,2,1108,A,A,14.010000000,100,0,256818881,130,165590,217058300,ARL,0,14.01,100,130,165590,217058300,9.55,1700,17,9.67,100,1,10.61,200,2,11.27,100,1,11.4,100,1,11.76,100,1,11.93,200,2,12.33,300,3,12.37,700,1,12.42,700,1,13.98,10,1,13.99,100,1,14.01,100,1,14.03,100,1,14.17,2,1,14.28,100,1,14.56,100,1,14.61,100,1,14.84,100,1,14.89,100,1,ARL,256818881
2025-07-17T15:13:08.661686458Z,2025-07-17T15:13:08.661521116Z,160,2,1108,C,A,14.030000000,100,0,256325129,130,165342,217058550,ARL,0,14.03,100,130,165342,217058550,9.55,1700,17,9.67,100,1,10.61,200,2,11.27,100,1,11.4,100,1,11.76,100,1,11.93,200,2,12.33,300,3,12.37,700,1,12.42,700,1,13.98,10,1,13.99,100,1,14.01,100,1,14.17,2,1,14.28,100,1,14.56,100,1,14.61,100,1,14.84,100,1,14.89,100,1,14.91,700,1,ARL,256325129
2025-07-17T15:14:00.440728359Z,2025-07-17T15:14:00.440563034Z,160,2,1108,C,A,13.980000000,10,0,256739841,130,165325,218096891,ARL,0,13.98,10,130,165325,218096891,9.55,1700,17,9.67,100,1,10.61,200,2,11.27,100,1,11.4,100,1,11.76,100,1,11.93,200,2,12.33,300,3,12.37,700,1,12.42,700,1,13.99,100,1,14.01,100,1,14.17,2,1,14.28,100,1,14.56,100,1,14.61,100,1,14.84,100,1,14.89,100,1,14.91,700,1,14.95,700,1,ARL,256739841
2025-07-17T15:14:52.382139830Z,2025-07-17T15:14:52.381974473Z,160,2,1108,A,A,13.980000000,10,0,259546169,130,165357,219204095,ARL,0,13.98,10,130,165357,219204095,9.55,1700,17,9.67,100,1,10.61,200,2,11.27,100,1,11.4,100,1,11.76,100,1,11.93,200,2,12.33,300,3,12.37,700,1,12.42,700,1,13.98,10,1,13.99,100,1,14.01,100,1,14.17,2,1,14.28,100,1,14.56,100,1,14.61,100,1,14.84,100,1,14.89,100,1,14.91,700,1,ARL,259546169
2025-07-17T15:14:56.683309707Z,2025-07-17T15:14:56.683144163Z,160,2,1108,C,A,14.010000000,100,0,256818881,130,165544,219317677,ARL,0,14.01,100,130,165544,219317677,9.55,1700,17,9.67,100,1,10.61,200,2,11.27,100,1,11.4,100,1,11.76,100,1,11.93,200,2,12.33,300,3,12.37,700,1,12.42,700,1,13.98,10,1,13.99,100,1,14.17,2,1,14.28,100,1,14.56,100,1,14.61,100,1,14.84,100,1,14.89,100,1,14.91,700,1,14.95,700,1,ARL,256818881
2025-07-17T15:15:11.661118778Z,2025-07-17T15:15:11.660953613Z,160,2,1108,A,A,14.020000000,100,0,260184621,130,165165,219726276,ARL,0,14.02,100,130,165165,219726276,9.55,1700,17,9.67,100,1,10.61,200,2,11.27,100,1,11.4,100,1,11.76,100,1,11.93,200,2,12.33,300,3,12.37,700,1,12.42,700,1,13.98,10,1,13.99,100,1,14.02,100,1,14.17,2,1,14.28,100,1,14.56,100,1,14.61,100,1,14.84,100,1,14.89,100,1,14.91,700,1,ARL,260184621
2025-07-17T15:15:32.408863263Z,2025-07-17T15:15:32.408694312Z,160,2,1108,C,A,13.980000000,10,0,259546169,128,168951,220152194,ARL,0,13.98,10,128,168951,220152194,9.55,1700,17,9.67,100,1,10.61,200,2,11.27,100,1,11.4,100,1,11.76,100,1,11.93,200,2,12.33,300,3,12.37,700,1,12.42,700,1,13.99,100,1,14.02,100,1,14.17,2,1,14.28,100,1,14.56,100,1,14.61,100,1,14.84,100,1,14.89,100,1,14.91,700,1,14.95,700,1,ARL,259546169
2025-07-17T15:16:31.607242914Z,2025-07-17T15:16:31.607077080Z,160,2,1108,A,A,14.000000000,100,0,262279553,130,165834,221423516,ARL,0,14,100,130,165834,221423516,9.55,1700,17,9.67,100,1,10.61,200,2,11.27,100,1,11.4,100,1,11.76,100,1,11.93,200,2,12.33,300,3,12.37,700,1,12.42,700,1,13.99,100,1,14,100,1,14.02,100,1,14.17,2,1,14.28,100,1,14.56,100,1,14.61,100,1,14.84,100,1,14.89,100,1,14.91,700,1,ARL,262279553
2025-07-17T15:16:31.614370696Z,2025-07-17T15:16:31.614205345Z,160,2,1108,C,A,14.020000000,100,0,260184621,130,165351,221423706,ARL,0,14.02,100,130,165351,221423706,9.55,1700,17,9.67,100,1,10.61,200,2,11.27,100,1,11.4,100,1,11.76,100,1,11.93,200,2,12.33,300,3,12.37,700,1,12.42,700,1,13.99,100,1,14,100,1,14.17,2,1,14.28,100,1,14.56,100,1,14.61,100,1,14.84,100,1,14.89,100,1,14.91,700,1,14.95,700,1,ARL,260184621
2025-07-17T15:16:39.373467449Z,2025-07-17T15:16:39.373301585Z,160,2,1108,A,A,13.980000000,10,0,262432821,130,165864,221549244,ARL,0,13.98,10,130,165864,221549244,9.55,1700,17,9.67,100,1,10.61,200,2,11.27,100,1,11.4,100,1,11.76,100,1,11.93,200,2,12.33,300,3,12.37,700,1,12.42,700,1,13.98,10,1,13.99,100,1,14,100,1,14.17,2,1,14.28,100,1,14.56,100,1,14.61,100,1,14.84,100,1,14.89,100,1,14.91,700,1,ARL,262432821
2025-07-17T15:17:50.916325497Z,2025-07-17T15:17:50.916157330Z,160,2,1108,C,A,13.980000000,10,0,262432821,130,168167,223060323,ARL,0,13.98,10,130,168167,223060323,9.55,1700,17,9.67,100,1,10.61,200,2,11.27,100,1,11.4,100,1,11.76,100,1,11.93,200,2,12.33,300,3,12.37,700,1,12.42,700,1,13.99,100,1,14,100,1,14.17,2,1,14.28,100,1,14.56,100,1,14.61,100,1,14.84,100,1,14.89,100,1,14.91,700,1,14.95,700,1,ARL,262432821
2025-07-17T15:17:51.938467389Z,2025-07-17T15:17:51.938301087Z,160,2,1108,C,A,14.000000000,100,0,262279553,130,166302,223092013,ARL,0,14,100,130,166302,223092013,9.55,1700,17,9.67,100,1,10.61,200,2,11.27,100,1,11.4,100,1,11.76,100,1,11.93,200,2,12.33,300,3,12.37,700,1,12.42,700,1,13.99,100,1,14.17,2,1,14.28,100,1,14.56,100,1,14.61,100,1,14.84,100,1,14.89,100,1,14.91,700,1,14.95,700,1,14.98,200,2,ARL,262279553
2025-07-17T15:17:55.957423821Z,2025-07-17T15:17:55.957258362Z,160,2,1108,A,A,14.010000000,100,0,264420961,130,165459,223181022,ARL,0,14.01,100,130,165459,223181022,9.55,1700,17,9.67,100,1,10.61,200,2,11.27,100,1,11.4,100,1,11.76,100,1,11.93,200,2,12.33,300,3,12.37,700,1,12.42,700,1,13.99,100,1,14.01,100,1,14.17,2,1,14.28,100,1,14.56,100,1,14.61,100,1,14.84,100,1,14.89,100,1,14.91,700,1,14.95,700,1,ARL,264420961
2025-07-17T15:19:23.618380576Z,2025-07-17T15:19:23.618215364Z,160,2,1108,C,A,14.010000000,100,0,264420961,130,165212,224925658,ARL,0,14.01,100,130,165212,224925658,9.55,1700,17,9.67,100,1,10.61,200,2,11.27,100,1,11.4,100,1,11.76,100,1,11.93,200,2,12.33,300,3,12.37,700,1,12.42,700,1,13.99,100,1,14.17,2,1,14.28,100,1,14.56,100,1,14.61,100,1,14.84,100,1,14.89,100,1,14.91,700,1,14.95,700,1,14.98,200,2,ARL,264420961
2025-07-17T15:19:27.663790911Z,2025-07-17T15:19:27.663625107Z,160,2,1108,A,A,14.030000000,100,0,266714557,130,165804,224999109,ARL,0,14.03,100,130,165804,224999109,9.55,1700,17,9.67,100,1,10.61,200,2,11.27,100,1,11.4,100,1,11.76,100,1,11.93,200,2,12.33,300,3,12.37,700,1,12.42,700,1,13.99,100,1,14.03,100,1,14.17,2,1,14.28,100,1,14.56,100,1,14.61,100,1,14.84,100,1,14.89,100,1,14.91,700,1,14.95,700,1,ARL,266714557
2025-07-17T15:20:46.705145876Z,2025-07-17T15:20:46.704980311Z,160,2,1108,A,A,14.010000000,100,0,269075833,130,165565,226851430,ARL,0,14.01,100,130,165565,226851430,9.55,1700,17,9.67,100,1,10.61,200,2,11.27,100,1,11.4,100,1,11.76,100,1,11.93,200,2,12.33,300,3,12.37,700,1,12.42,700,1,13.99,100,1,14.01,100,1,14.03,100,1,14.17,2,1,14.28,100,1,14.56,100,1,14.61,100,1,14.84,100,1,14.89,100,1,14.91,700,1,ARL,269075833
2025-07-17T15:20:46.716698477Z,2025-07-17T15:20:46.716532886Z,160,2,1108,C,A,14.030000000,100,0,266714557,130,165591,226851533,ARL,0,14.03,100,130,165591,226851533,9.55,1700,17,9.67,100,1,10.61,200,2,11.27,100,1,11.4,100,1,11.76,100,1,11.93,200,2,12.33,300,3,12.37,700,1,12.42,700,1,13.99,100,1,14.01,100,1,14.17,2,1,14.28,100,1,14.56,100,1,14.61,100,1,14.84,100,1,14.89,100,1,14.91,700,1,14.95,700,1,ARL,266714557
2025-07-17T15:23:00.249962772Z,2025-07-17T15:23:00.249796874Z,160,2,1108,C,B,13.150000000,2,0,130693973,0,165898,229397485,ARL,0,13.15,2,0,165898,229397485,9.55,1700,17,9.67,100,1,10.61,200,2,11.27,100,1,11.4,100,1,11.76,100,1,11.93,200,2,12.33,300,3,12.37,700,1,12.42,700,1,13.99,100,1,14.01,100,1,14.17,2,1,14.28,100,1,14.56,100,1,14.61,100,1,14.84,100,1,14.89,100,1,14.91,700,1,14.95,700,1,ARL,130693973
2025-07-17T15:23:00.249962772Z,2025-07-17T15:23:00.249796874Z,160,2,1108,A,B,13.230000000,2,0,272263853,130,165898,229397485,ARL,0,13.23,2,130,165898,229397485,9.55,1700,17,9.67,100,1,10.61,200,2,11.27,100,1,11.4,100,1,11.76,100,1,11.93,200,2,12.33,300,3,12.37,700,1,12.42,700,1,13.99,100,1,14.01,100,1,14.17,2,1,14.28,100,1,14.56,100,1,14.61,100,1,14.84,100,1,14.89,100,1,14.91,700,1,14.95,700,1,ARL,272263853
2025-07-17T15:26:04.666158860Z,2025-07-17T15:26:04.665993515Z,160,2,1108,C,A,14.170000000,2,0,252720897,0,165345,232977340,ARL,0,14.17,2,0,165345,232977340,9.55,1700,17,9.67,100,1,10.61,200,2,11.27,100,1,11.4,100,1,11.76,100,1,11.93,200,2,12.33,300,3,12.37,700,1,12.42,700,1,13.99,100,1,14.01,100,1,14.28,100,1,14.56,100,1,14.61,100,1,14.84,100,1,14.89,100,1,14.91,700,1,14.95,700,1,14.98,200,2,ARL,252720897
2025-07-17T15:26:04.666158860Z,2025-07-17T15:26:04.665993515Z,160,2,1108,A,A,14.090000000,2,0,276751517,130,165345,232977340,ARL,0,14.09,2,130,165345,232977340,9.55,1700,17,9.67,100,1,10.61,200,2,11.27,100,1,11.4,100,1,11.76,100,1,11.93,200,2,12.33,300,3,12.37,700,1,12.42,700,1,13.99,100,1,14.01,100,1,14.09,2,1,14.28,100,1,14.56,100,1,14.61,100,1,14.84,100,1,14.89,100,1,14.91,700,1,14.95,700,1,ARL,276751517
2025-07-17T15:28:38.882985923Z,2025-07-17T15:28:38.882820591Z,160,2,1108,A,A,13.990000000,100,0,280387693,130,165332,235874491,ARL,0,13.99,100,130,165332,235874491,9.55,1700,17,9.67,100,1,10.61,200,2,11.27,100,1,11.4,100,1,11.76,100,1,11.93,200,2,12.33,300,3,12.37,700,1,12.42,700,1,13.99,200,2,14.01,100,1,14.09,2,1,14.28,100,1,14.56,100,1,14.61,100,1,14.84,100,1,14.89,100,1,14.91,700,1,14.95,700,1,ARL,280387693
2025-07-17T15:28:38.890789214Z,2025-07-17T15:28:38.890623989Z,160,2,1108,C,A,14.010000000,100,0,269075833,130,165225,235874556,ARL,0,14.01,100,130,165225,235874556,9.55,1700,17,9.67,100,1,10.61,200,2,11.27,100,1,11.4,100,1,11.76,100,1,11.93,200,2,12.33,300,3,12.37,700,1,12.42,700,1,13.99,200,2,14.09,2,1,14.28,100,1,14.56,100,1,14.61,100,1,14.84,100,1,14.89,100,1,14.91,700,1,14.95,700,1,14.98,200,2,ARL,269075833
2025-07-17T15:28:44.820934614Z,2025-07-17T15:28:44.820769301Z,160,2,1108,C,A,13.990000000,100,0,280387693,130,165313,235961324,ARL,0,13.99,100,130,165313,235961324,9.55,1700,17,9.67,100,1,10.61,200,2,11.27,100,1,11.4,100,1,11.76,100,1,11.93,200,2,12.33,300,3,12.37,700,1,12.42,700,1,13.99,100,1,14.09,2,1,14.28,100,1,14.56,100,1,14.61,100,1,14.84,100,1,14.89,100,1,14.91,700,1,14.95,700,1,14.98,200,2,ARL,280387693
2025-07-17T15:28:48.918811203Z,2025-07-17T15:28:48.918645728Z,160,2,1108,A,A,14.010000000,100,0,280580873,130,165475,236028551,ARL,0,14.01,100,130,165475,236028551,9.55,1700,17,9.67,100,1,10.61,200,2,11.27,100,1,11.4,100,1,11.76,100,1,11.93,200,2,12.33,300,3,12.37,700,1,12.42,700,1,13.99,100,1,14.01,100,1,14.09,2,1,14.28,100,1,14.56,100,1,14.61,100,1,14.84,100,1,14.89,100,1,14.91,700,1,14.95,700,1,ARL,280580873
2025-07-17T15:30:23.573233259Z,2025-07-17T15:30:23.573067851Z,160,2,1108,A,A,13.820000000,10,0,282775557,130,165408,237754758,ARL,0,13.82,10,130,165408,237754758,9.55,1700,17,9.67,100,1,10.61,200,2,11.27,100,1,11.4,100,1,11.76,100,1,11.93,200,2,12.33,300,3,12.37,700,1,12.42,700,1,13.82,10,1,13.99,100,1,14.01,100,1,14.09,2,1,14.28,100,1,14.56,100,1,14.61,100,1,14.84,100,1,14.89,100,1,14.91,700,1,ARL,282775557
2025-07-17T15:30:23.573528359Z,2025-07-17T15:30:23.573362522Z,160,2,1108,C,A,14.980000000,100,0,128570237,0,165837,237754762,ARL,0,14.98,100,0,165837,237754762,9.55,1700,17,9.67,100,1,10.61,200,2,11.27,100,1,11.4,100,1,11.76,100,1,11.93,200,2,12.33,300,3,12.37,700,1,12.42,700,1,13.82,10,1,13.99,100,1,14.01,100,1,14.09,2,1,14.28,100,1,14.56,100,1,14.61,100,1,14.84,100,1,14.89,100,1,14.91,700,1,ARL,128570237
2025-07-17T15:30:23.573528359Z,2025-07-17T15:30:23.573362522Z,160,2,1108,A,A,14.720000000,100,0,282775561,130,165837,237754762,ARL,0,14.72,100,130,165837,237754762,9.55,1700,17,9.67,100,1,10.61,200,2,11.27,100,1,11.4,100,1,11.76,100,1,11.93,200,2,12.33,300,3,12.37,700,1,12.42,700,1,13.82,10,1,13.99,100,1,14.01,100,1,14.09,2,1,14.28,100,1,14.56,100,1,14.61,100,1,14.72,100,1,14.84,100,1,14.89,100,1,ARL,282775561
2025-07-17T15:30:23.574854165Z,2025-07-17T15:30:23.574688647Z,160,2,1108,C,A,14.980000000,100,0,128570229,0,165518,237754776,ARL,0,14.98,100,0,165518,237754776,9.55,1700,17,9.67,100,1,10.61,200,2,11.27,100,1,11.4,100,1,11.76,100,1,11.93,200,2,12.33,300,3,12.37,700,1,12.42,700,1,13.82,10,1,13.99,100,1,14.01,100,1,14.09,2,1,14.28,100,1,14.56,100,1,14.61,100,1,14.72,100,1,14.84,100,1,14.89,100,1,ARL,128570229
2025-07-17T15:30:23.574854165Z,2025-07-17T15:30:23.574688647Z,160,2,1108,A,A,14.720000000,100,0,282775577,130,165518,237754776,ARL,0,14.72,100,130,165518,237754776,9.55,1700,17,9.67,100,1,10.61,200,2,11.27,100,1,11.4,100,1,11.76,100,1,11.93,200,2,12.33,300,3,12.37,700,1,12.42,700,1,13.82,10,1,13.99,100,1,14.01,100,1,14.09,2,1,14.28,100,1,14.56,100,1,14.61,100,1,14.72,200,2,14.84,100,1,14.89,100,1,ARL,282775577
2025-07-17T15:30:23.585191081Z,2025-07-17T15:30:23.585025490Z,160,2,1108,A,A,13.840000000,100,0,282775973,130,165591,237755075,ARL,0,13.84,100,130,165591,237755075,9.55,1700,17,9.67,100,1,10.61,200,2,11.27,100,1,11.4,100,1,11.76,100,1,11.93,200,2,12.33,300,3,12.37,700,1,12.42,700,1,13.82,10,1,13.84,100,1,13.99,100,1,14.01,100,1,14.09,2,1,14.28,100,1,14.56,100,1,14.61,100,1,14.72,200,2,14.84,100,1,ARL,282775973
2025-07-17T15:30:23.585960886Z,2025-07-17T15:30:23.585795327Z,160,2,1108,C,A,15.090000000,100,0,146955361,0,165559,237755081,ARL,0,15.09,100,0,165559,237755081,9.55,1700,17,9.67,100,1,10.61,200,2,11.27,100,1,11.4,100,1,11.76,100,1,11.93,200,2,12.33,300,3,12.37,700,1,12.42,700,1,13.82,10,1,13.84,100,1,13.99,100,1,14.01,100,1,14.09,2,1,14.28,100,1,14.56,100,1,14.61,100,1,14.72,200,2,14.84,100,1,ARL,146955361
2025-07-17T15:30:23.585960886Z,2025-07-17T15:30:23.585795327Z,160,2,1108,A,A,14.910000000,100,0,282776009,130,165559,237755081,ARL,0,14.91,100,130,165559,237755081,9.55,1700,17,9.67,100,1,10.61,200,2,11.27,100,1,11.4,100,1,11.76,100,1,11.93,200,2,12.33,300,3,12.37,700,1,12.42,700,1,13.82,10,1,13.84,100,1,13.99,100,1,14.01,100,1,14.09,2,1,14.28,100,1,14.56,100,1,14.61,100,1,14.72,200,2,14.84,100,1,ARL,282776009
2025-07-17T15:30:23.586719371Z,2025-07-17T15:30:23.586553674Z,160,2,1108,C,A,14.890000000,100,0,128570453,0,165697,237755086,ARL,0,14.89,100,0,165697,237755086,9.55,1700,17,9.67,100,1,10.61,200,2,11.27,100,1,11.4,100,1,11.76,100,1,11.93,200,2,12.33,300,3,12.37,700,1,12.42,700,1,13.82,10,1,13.84,100,1,13.99,100,1,14.01,100,1,14.09,2,1,14.28,100,1,14.56,100,1,14.61,100,1,14.72,200,2,14.84,100,1,ARL,128570453
2025-07-17T15:30:23.586719371Z,2025-07-17T15:30:23.586553674Z,160,2,1108,A,A,14.650000000,100,0,282776013,130,165697,237755086,ARL,0,14.65,100,130,165697,237755086,9.55,1700,17,9.67,100,1,10.61,200,2,11.27,100,1,11.4,100,1,11.76,100,1,11.93,200,2,12.33,300,3,12.37,700,1,12.42,700,1,13.82,10,1,13.84,100,1,13.99,100,1,14.01,100,1,14.09,2,1,14.28,100,1,14.56,100,1,14.61,100,1,14.65,100,1,14.72,200,2,ARL,282776013
2025-07-17T15:30:23.586762105Z,2025-07-17T15:30:23.586596452Z,160,2,1108,C,A,15.640000000,100,0,84628833,0,165653,237755087,ARL,0,15.64,100,0,165653,237755087,9.55,1700,17,9.67,100,1,10.61,200,2,11.27,100,1,11.4,100,1,11.76,100,1,11.93,200,2,12.33,300,3,12.37,700,1,12.42,700,1,13.82,10,1,13.84,100,1,13.99,100,1,14.01,100,1,14.09,2,1,14.28,100,1,14.56,100,1,14.61,100,1,14.65,100,1,14.72,200,2,ARL,84628833
2025-07-17T15:30:23.586762105Z,2025-07-17T15:30:23.586596452Z,160,2,1108,A,A,15.230000000,100,0,282776017,130,165653,237755087,ARL,0,15.23,100,130,165653,237755087,9.55,1700,17,9.67,100,1,10.61,200,2,11.27,100,1,11.4,100,1,11.76,100,1,11.93,200,2,12.33,300,3,12.37,700,1,12.42,700,1,13.82,10,1,13.84,100,1,13.99,100,1,14.01,100,1,14.09,2,1,14.28,100,1,14.56,100,1,14.61,100,1,14.65,100,1,14.72,200,2,ARL,282776017
2025-07-17T15:30:23.587432517Z,2025-07-17T15:30:23.587267064Z,160,2,1108,C,A,17.900000000,100,0,128570685,0,165453,237755097,ARL,0,17.9,100,0,165453,237755097,9.55,1700,17,9.67,100,1,10.61,200,2,11.27,100,1,11.4,100,1,11.76,100,1,11.93,200,2,12.33,300,3,12.37,700,1,12.42,700,1,13.82,10,1,13.84,100,1,13.99,100,1,14.01,100,1,14.09,2,1,14.28,100,1,14.56,100,1,14.61,100,1,14.65,100,1,14.72,200,2,ARL,128570685
2025-07-17T15:30:23.587432517Z,2025-07-17T15:30:23.587267064Z,160,2,1108,A,A,17.580000000,100,0,282776025,130,165453,237755097,ARL,0,17.58,100,130,165453,237755097,9.55,1700,17,9.67,100,1,10.61,200,2,11.27,100,1,11.4,100,1,11.76,100,1,11.93,200,2,12.33,300,3,12.37,700,1,12.42,700,1,13.82,10,1,13.84,100,1,13.99,100,1,14.01,100,1,14.09,2,1,14.28,100,1,14.56,100,1,14.61,100,1,14.65,100,1,14.72,200,2,ARL,282776025
2025-07-17T15:30:23.587581881Z,2025-07-17T15:30:23.587416236Z,160,2,1108,C,A,15.080000000,100,0,128570449,0,165645,237755098,ARL,0,15.08,100,0,165645,237755098,9.55,1700,17,9.67,100,1,10.61,200,2,11.27,100,1,11.4,100,1,11.76,100,1,11.93,200,2,12.33,300,3,12.37,700,1,12.42,700,1,13.82,10,1,13.84,100,1,13.99,100,1,14.01,100,1,14.09,2,1,14.28,100,1,14.56,100,1,14.61,100,1,14.65,100,1,14.72,200,2,ARL,128570449
2025-07-17T15:30:23.587581881Z,2025-07-17T15:30:23.587416236Z,160,2,1108,A,A,14.810000000,100,0,282776029,130,165645,237755098,ARL,0,14.81,100,130,165645,237755098,9.55,1700,17,9.67,100,1,10.61,200,2,11.27,100,1,11.4,100,1,11.76,100,1,11.93,200,2,12.33,300,3,12.37,700,1,12.42,700,1,13.82,10,1,13.84,100,1,13.99,100,1,14.01,100,1,14.09,2,1,14.28,100,1,14.56,100,1,14.61,100,1,14.65,100,1,14.72,200,2,ARL,282776029
2025-07-17T15:30:23.587611440Z,2025-07-17T15:30:23.587445922Z,160,2,1108,C,A,16.210000000,100,0,128570977,0,165518,237755099,ARL,0,16.21,100,0,165518,237755099,9.55,1700,17,9.67,100,1,10.61,200,2,11.27,100,1,11.4,100,1,11.76,100,1,11.93,200,2,12.33,300,3,12.37,700,1,12.42,700,1,13.82,10,1,13.84,100,1,13.99,100,1,14.01,100,1,14.09,2,1,14.28,100,1,14.56,100,1,14.61,100,1,14.65,100,1,14.72,200,2,ARL,128570977
2025-07-17T15:30:23.587611440Z,2025-07-17T15:30:23.587445922Z,160,2,1108,A,A,15.920000000,100,0,282776033,130,165518,237755099,ARL,0,15.92,100,130,165518,237755099,9.55,1700,17,9.67,100,1,10.61,200,2,11.27,100,1,11.4,100,1,11.76,100,1,11.93,200,2,12.33,300,3,12.37,700,1,12.42,700,1,13.82,10,1,13.84,100,1,13.99,100,1,14.01,100,1,14.09,2,1,14.28,100,1,14.56,100,1,14.61,100,1,14.65,100,1,14.72,200,2,ARL,282776033
2025-07-17T15:30:23.590261792Z,2025-07-17T15:30:23.590096343Z,160,2,1108,C,A,15.080000000,100,0,128573957,0,165449,237755128,ARL,0,15.08,100,0,165449,237755128,9.55,1700,17,9.67,100,1,10.61,200,2,11.27,100,1,11.4,100,1,11.76,100,1,11.93,200,2,12.33,300,3,12.37,700,1,12.42,700,1,13.82,10,1,13.84,100,1,13.99,100,1,14.01,100,1,14.09,2,1,14.28,100,1,14.56,100,1,14.61,100,1,14.65,100,1,14.72,200,2,ARL,128573957
2025-07-17T15:30:23.590261792Z,2025-07-17T15:30:23.590096343Z,160,2,1108,A,A,14.810000000,100,0,282776089,130,165449,237755128,ARL,0,14.81,100,130,165449,237755128,9.55,1700,17,9.67,100,1,10.61,200,2,11.27,100,1,11.4,100,1,11.76,100,1,11.93,200,2,12.33,300,3,12.37,700,1,12.42,700,1,13.82,10,1,13.84,100,1,13.99,100,1,14.01,100,1,14.09,2,1,14.28,100,1,14.56,100,1,14.61,100,1,14.65,100,1,14.72,200,2,ARL,282776089
2025-07-17T15:30:23.591959120Z,2025-07-17T15:30:23.591793735Z,160,2,1108,C,A,14.010000000,100,0,280580873,130,165385,237755138,ARL,0,14.01,100,130,165385,237755138,9.55,1700,17,9.67,100,1,10.61,200,2,11.27,100,1,11.4,100,1,11.76,100,1,11.93,200,2,12.33,300,3,12.37,700,1,12.42,700,1,13.82,10,1,13.84,100,1,13.99,100,1,14.09,2,1,14.28,100,1,14.56,100,1,14.61,100,1,14.65,100,1,14.72,200,2,14.81,200,2,ARL,280580873
2025-07-17T15:30:23.602992439Z,2025-07-17T15:30:23.602827102Z,160,2,1108,C,A,14.280000000,100,0,146956357,130,165337,237755229,ARL,0,14.28,100,130,165337,237755229,9.55,1700,17,9.67,100,1,10.61,200,2,11.27,100,1,11.4,100,1,11.76,100,1,11.93,200,2,12.33,300,3,12.37,700,1,12.42,700,1,13.82,10,1,13.84,100,1,13.99,100,1,14.09,2,1,14.56,100,1,14.61,100,1,14.65,100,1,14.72,200,2,14.81,200,2,14.84,100,1,ARL,146956357
2025-07-17T15:30:23.603046460Z,2025-07-17T15:30:23.602881129Z,160,2,1108,A,A,14.120000000,100,0,282776285,130,165331,237755230,ARL,0,14.12,100,130,165331,237755230,9.55,1700,17,9.67,100,1,10.61,200,2,11.27,100,1,11.4,100,1,11.76,100,1,11.93,200,2,12.33,300,3,12.37,700,1,12.42,700,1,13.82,10,1,13.84,100,1,13.99,100,1,14.09,2,1,14.12,100,1,14.56,100,1,14.61,100,1,14.65,100,1,14.72,200,2,14.81,200,2,ARL,282776285
2025-07-17T15:30:23.628720816Z,2025-07-17T15:30:23.628555135Z,160,2,1108,A,A,15.780000000,100,0,282776733,130,165681,237755415,ARL,0,15.78,100,130,165681,237755415,9.55,1700,17,9.67,100,1,10.61,200,2,11.27,100,1,11.4,100,1,11.76,100,1,11.93,200,2,12.33,300,3,12.37,700,1,12.42,700,1,13.82,10,1,13.84,100,1,13.99,100,1,14.09,2,1,14.12,100,1,14.56,100,1,14.61,100,1,14.65,100,1,14.72,200,2,14.81,200,2,ARL,282776733
2025-07-17T15:30:23.628732597Z,2025-07-17T15:30:23.628567293Z,160,2,1108,C,A,16.200000000,100,0,84628765,130,165304,237755416,ARL,0,16.2,100,130,165304,237755416,9.55,1700,17,9.67,100,1,10.61,200,2,11.27,100,1,11.4,100,1,11.76,100,1,11.93,200,2,12.33,300,3,12.37,700,1,12.42,700,1,13.82,10,1,13.84,100,1,13.99,100,1,14.09,2,1,14.12,100,1,14.56,100,1,14.61,100,1,14.65,100,1,14.72,200,2,14.81,200,2,ARL,84628765
2025-07-17T15:30:23.952122580Z,2025-07-17T15:30:23.951957017Z,160,2,1108,C,A,13.990000000,100,0,237978541,0,165563,237759683,ARL,0,13.99,100,0,165563,237759683,9.55,1700,17,9.67,100,1,10.61,200,2,11.27,100,1,11.4,100,1,11.76,100,1,11.93,200,2,12.33,300,3,12.37,700,1,12.42,700,1,13.82,10,1,13.84,100,1,14.09,2,1,14.12,100,1,14.56,100,1,14.61,100,1,14.65,100,1,14.72,200,2,14.81,200,2,14.84,100,1,ARL,237978541
2025-07-17T15:30:23.952122580Z,2025-07-17T15:30:23.951957017Z,160,2,1108,A,A,13.830000000,100,0,282781741,130,165563,237759683,ARL,0,13.83,100,130,165563,237759683,9.55,1700,17,9.67,100,1,10.61,200,2,11.27,100,1,11.4,100,1,11.76,100,1,11.93,200,2,12.33,300,3,12.37,700,1,12.42,700,1,13.82,10,1,13.83,100,1,13.84,100,1,14.09,2,1,14.12,100,1,14.56,100,1,14.61,100,1,14.65,100,1,14.72,200,2,14.81,200,2,ARL,282781741
2025-07-17T15:30:24.769074814Z,2025-07-17T15:30:24.768909757Z,160,2,1108,C,A,13.820000000,10,0,282775557,130,165057,237771822,ARL,0,13.82,10,130,165057,237771822,9.55,1700,17,9.67,100,1,10.61,200,2,11.27,100,1,11.4,100,1,11.76,100,1,11.93,200,2,12.33,300,3,12.37,700,1,12.42,700,1,13.83,100,1,13.84,100,1,14.09,2,1,14.12,100,1,14.56,100,1,14.61,100,1,14.65,100,1,14.72,200,2,14.81,200,2,14.84,100,1,ARL,282775557
2025-07-17T15:30:28.617337198Z,2025-07-17T15:30:28.617171810Z,160,2,1108,A,A,14.530000000,700,0,282881853,130,165388,237840336,ARL,0,14.53,700,130,165388,237840336,9.55,1700,17,9.67,100,1,10.61,200,2,11.27,100,1,11.4,100,1,11.76,100,1,11.93,200,2,12.33,300,3,12.37,700,1,12.42,700,1,13.83,100,1,13.84,100,1,14.09,2,1,14.12,100,1,14.53,700,1,14.56,100,1,14.61,100,1,14.65,100,1,14.72,200,2,14.81,200,2,ARL,282881853
2025-07-17T15:30:28.617387294Z,2025-07-17T15:30:28.617221981Z,160,2,1108,C,A,15.070000000,700,0,92510741,130,165313,237840337,ARL,0,15.07,700,130,165313,237840337,9.55,1700,17,9.67,100,1,10.61,200,2,11.27,100,1,11.4,100,1,11.76,100,1,11.93,200,2,12.33,300,3,12.37,700,1,12.42,700,1,13.83,100,1,13.84,100,1,14.09,2,1,14.12,100,1,14.53,700,1,14.56,100,1,14.61,100,1,14.65,100,1,14.72,200,2,14.81,200,2,ARL,92510741
2025-07-17T15:30:30.767213907Z,2025-07-17T15:30:30.767048606Z,160,2,1108,A,A,14.600000000,700,0,282920685,130,165301,237873135,ARL,0,14.6,700,130,165301,237873135,9.55,1700,17,9.67,100,1,10.61,200,2,11.27,100,1,11.4,100,1,11.76,100,1,11.93,200,2,12.33,300,3,12.37,700,1,12.42,700,1,13.83,100,1,13.84,100,1,14.09,2,1,14.12,100,1,14.53,700,1,14.56,100,1,14.6,700,1,14.61,100,1,14.65,100,1,14.72,200,2,ARL,282920685
2025-07-17T15:30:30.767267001Z,2025-07-17T15:30:30.767101317Z,160,2,1108,C,A,14.990000000,700,0,84628757,130,165684,237873136,ARL,0,14.99,700,130,165684,237873136,9.55,1700,17,9.67,100,1,10.61,200,2,11.27,100,1,11.4,100,1,11.76,100,1,11.93,200,2,12.33,300,3,12.37,700,1,12.42,700,1,13.83,100,1,13.84,100,1,14.09,2,1,14.12,100,1,14.53,700,1,14.56,100,1,14.6,700,1,14.61,100,1,14.65,100,1,14.72,200,2,ARL,84628757
2025-07-17T15:30:33.016987097Z,2025-07-17T15:30:33.016821395Z,160,2,1108,A,A,14.560000000,700,0,282969973,130,165702,237915946,ARL,0,14.56,700,130,165702,237915946,9.55,1700,17,9.67,100,1,10.61,200,2,11.27,100,1,11.4,100,1,11.76,100,1,11.93,200,2,12.33,300,3,12.37,700,1,12.42,700,1,13.83,100,1,13.84,100,1,14.09,2,1,14.12,100,1,14.53,700,1,14.56,800,2,14.6,700,1,14.61,100,1,14.65,100,1,14.72,200,2,ARL,282969973
2025-07-17T15:30:33.017384279Z,2025-07-17T15:30:33.017218657Z,160,2,1108,C,A,14.950000000,700,0,84628797,130,165622,237915951,ARL,0,14.95,700,130,165622,237915951,9.55,1700,17,9.67,100,1,10.61,200,2,11.27,100,1,11.4,100,1,11.76,100,1,11.93,200,2,12.33,300,3,12.37,700,1,12.42,700,1,13.83,100,1,13.84,100,1,14.09,2,1,14.12,100,1,14.53,700,1,14.56,800,2,14.6,700,1,14.61,100,1,14.65,100,1,14.72,200,2,ARL,84628797
2025-07-17T15:30:49.985906754Z,2025-07-17T15:30:49.985741094Z,160,2,1108,C,A,14.090000000,2,0,276751517,0,165660,238230724,ARL,0,14.09,2,0,165660,238230724,9.55,1700,17,9.67,100,1,10.61,200,2,11.27,100,1,11.4,100,1,11.76,100,1,11.93,200,2,12.33,300,3,12.37,700,1,12.42,700,1,13.83,100,1,13.84,100,1,14.12,100,1,14.53,700,1,14.56,800,2,14.6,700,1,14.61,100,1,14.65,100,1,14.72,200,2,14.81,200,2,ARL,276751517
2025-07-17T15:30:49.985906754Z,2025-07-17T15:30:49.985741094Z,160,2,1108,A,A,14.020000000,2,0,283348193,130,165660,238230724,ARL,0,14.02,2,130,165660,238230724,9.55,1700,17,9.67,100,1,10.61,200,2,11.27,100,1,11.4,100,1,11.76,100,1,11.93,200,2,12.33,300,3,12.37,700,1,12.42,700,1,13.83,100,1,13.84,100,1,14.02,2,1,14.12,100,1,14.53,700,1,14.56,800,2,14.6,700,1,14.61,100,1,14.65,100,1,14.72,200,2,ARL,283348193
2025-07-17T15:30:59.996516554Z,2025-07-17T15:30:59.996351383Z,160,2,1108,C,A,13.830000000,100,0,282781741,130,165171,238442318,ARL,0,13.83,100,130,165171,238442318,9.55,1700,17,9.67,100,1,10.61,200,2,11.27,100,1,11.4,100,1,11.76,100,1,11.93,200,2,12.33,300,3,12.37,700,1,12.42,700,1,13.84,100,1,14.02,2,1,14.12,100,1,14.53,700,1,14.56,800,2,14.6,700,1,14.61,100,1,14.65,100,1,14.72,200,2,14.81,200,2,ARL,282781741
2025-07-17T15:31:00.002203922Z,2025-07-17T15:31:00.002038446Z,160,2,1108,C,A,13.840000000,100,0,282775973,130,165476,238442443,ARL,0,13.84,100,130,165476,238442443,9.55,1700,17,9.67,100,1,10.61,200,2,11.27,100,1,11.4,100,1,11.76,100,1,11.93,200,2,12.33,300,3,12.37,700,1,12.42,700,1,14.02,2,1,14.12,100,1,14.53,700,1,14.56,800,2,14.6,700,1,14.61,100,1,14.65,100,1,14.72,200,2,14.81,200,2,14.84,100,1,ARL,282775973
2025-07-17T15:31:00.002478393Z,2025-07-17T15:31:00.002313250Z,160,2,1108,C,A,14.530000000,700,0,282881853,130,165143,238442461,ARL,0,14.53,700,130,165143,238442461,9.55,1700,17,9.67,100,1,10.61,200,2,11.27,100,1,11.4,100,1,11.76,100,1,11.93,200,2,12.33,300,3,12.37,700,1,12.42,700,1,14.02,2,1,14.12,100,1,14.56,800,2,14.6,700,1,14.61,100,1,14.65,100,1,14.72,200,2,14.81,200,2,14.84,100,1,14.91,800,2,ARL,282881853
2025-07-17T15:31:00.002525213Z,2025-07-17T15:31:00.002359969Z,160,2,1108,A,A,14.680000000,700,0,283592941,130,165244,238442467,ARL,0,14.68,700,130,165244,238442467,9.55,1700,17,9.67,100,1,10.61,200,2,11.27,100,1,11.4,100,1,11.76,100,1,11.93,200,2,12.33,300,3,12.37,700,1,12.42,700,1,14.02,2,1,14.12,100,1,14.56,800,2,14.6,700,1,14.61,100,1,14.65,100,1,14.68,700,1,14.72,200,2,14.81,200,2,14.84,100,1,ARL,283592941
2025-07-17T15:31:00.002938332Z,2025-07-17T15:31:00.002772683Z,160,2,1108,C,A,14.720000000,100,0,282775577,0,165649,238442486,ARL,0,14.72,100,0,165649,238442486,9.55,1700,17,9.67,100,1,10.61,200,2,11.27,100,1,11.4,100,1,11.76,100,1,11.93,200,2,12.33,300,3,12.37,700,1,12.42,700,1,14.02,2,1,14.12,100,1,14.56,800,2,14.6,700,1,14.61,100,1,14.65,100,1,14.68,700,1,14.72,100,1,14.81,200,2,14.84,100,1,ARL,282775577
2025-07-17T15:31:00.002938332Z,2025-07-17T15:31:00.002772683Z,160,2,1108,A,A,14.970000000,100,0,283592993,130,165649,238442486,ARL,0,14.97,100,130,165649,238442486,9.55,1700,17,9.67,100,1,10.61,200,2,11.27,100,1,11.4,100,1,11.76,100,1,11.93,200,2,12.33,300,3,12.37,700,1,12.42,700,1,14.02,2,1,14.12,100,1,14.56,800,2,14.6,700,1,14.61,100,1,14.65,100,1,14.68,700,1,14.72,100,1,14.81,200,2,14.84,100,1,ARL,283592993
2025-07-17T15:31:00.002953704Z,2025-07-17T15:31:00.002788190Z,160,2,1108,C,A,14.910000000,100,0,282776009,0,165514,238442490,ARL,0,14.91,100,0,165514,238442490,9.55,1700,17,9.67,100,1,10.61,200,2,11.27,100,1,11.4,100,1,11.76,100,1,11.93,200,2,12.33,300,3,12.37,700,1,12.42,700,1,14.02,2,1,14.12,100,1,14.56,800,2,14.6,700,1,14.61,100,1,14.65,100,1,14.68,700,1,14.72,100,1,14.81,200,2,14.84,100,1,ARL,282776009
2025-07-17T15:31:00.002953704Z,2025-07-17T15:31:00.002788190Z,160,2,1108,A,A,14.960000000,100,0,283592997,130,165514,238442490,ARL,0,14.96,100,130,165514,238442490,9.55,1700,17,9.67,100,1,10.61,200,2,11.27,100,1,11.4,100,1,11.76,100,1,11.93,200,2,12.33,300,3,12.37,700,1,12.42,700,1,14.02,2,1,14.12,100,1,14.56,800,2,14.6,700,1,14.61,100,1,14.65,100,1,14.68,700,1,14.72,100,1,14.81,200,2,14.84,100,1,ARL,283592997
2025-07-17T15:31:00.003368272Z,2025-07-17T15:31:00.003202003Z,160,2,1108,C,A,14.720000000,100,0,282775561,0,166269,238442510,ARL,0,14.72,100,0,166269,238442510,9.55,1700,17,9.67,100,1,10.61,200,2,11.27,100,1,11.4,100,1,11.76,100,1,11.93,200,2,12.33,300,3,12.37,700,1,12.42,700,1,14.02,2,1,14.12,100,1,14.56,800,2,14.6,700,1,14.61,100,1,14.65,100,1,14.68,700,1,14.81,200,2,14.84,100,1,14.91,700,1,ARL,282775561
2025-07-17T15:31:00.003368272Z,2025-07-17T15:31:00.003202003Z,160,2,1108,A,A,14.970000000,100,0,283593041,130,166269,238442510,ARL,0,14.97,100,130,166269,238442510,9.55,1700,17,9.67,100,1,10.61,200,2,11.27,100,1,11.4,100,1,11.76,100,1,11.93,200,2,12.33,300,3,12.37,700,1,12.42,700,1,14.02,2,1,14.12,100,1,14.56,800,2,14.6,700,1,14.61,100,1,14.65,100,1,14.68,700,1,14.81,200,2,14.84,100,1,14.91,700,1,ARL,283593041
2025-07-17T15:31:00.006784947Z,2025-07-17T15:31:00.006618398Z,160,2,1108,C,A,14.650000000,100,0,282776013,130,166549,238442608,ARL,0,14.65,100,130,166549,238442608,9.55,1700,17,9.67,100,1,10.61,200,2,11.27,100,1,11.4,100,1,11.76,100,1,11.93,200,2,12.33,300,3,12.37,700,1,12.42,700,1,14.02,2,1,14.12,100,1,14.56,800,2,14.6,700,1,14.61,100,1,14.68,700,1,14.81,200,2,14.84,100,1,14.91,700,1,14.96,100,1,ARL,282776013
2025-07-17T15:31:00.006950491Z,2025-07-17T15:31:00.006784814Z,160,2,1108,A,A,14.790000000,100,0,283593313,130,165677,238442616,ARL,0,14.79,100,130,165677,238442616,9.55,1700,17,9.67,100,1,10.61,200,2,11.27,100,1,11.4,100,1,11.76,100,1,11.93,200,2,12.33,300,3,12.37,700,1,12.42,700,1,14.02,2,1,14.12,100,1,14.56,800,2,14.6,700,1,14.61,100,1,14.68,700,1,14.79,100,1,14.81,200,2,14.84,100,1,14.91,700,1,ARL,283593313
2025-07-17T15:31:00.017759891Z,2025-07-17T15:31:00.017594312Z,160,2,1108,C,A,17.580000000,100,0,282776025,0,165579,238443214,ARL,0,17.58,100,0,165579,238443214,9.55,1700,17,9.67,100,1,10.61,200,2,11.27,100,1,11.4,100,1,11.76,100,1,11.93,200,2,12.33,300,3,12.37,700,1,12.42,700,1,14.02,2,1,14.12,100,1,14.56,800,2,14.6,700,1,14.61,100,1,14.68,700,1,14.79,100,1,14.81,200,2,14.84,100,1,14.91,700,1,ARL,282776025
2025-07-17T15:31:00.017759891Z,2025-07-17T15:31:00.017594312Z,160,2,1108,A,A,17.760000000,100,0,283594173,130,165579,238443214,ARL,0,17.76,100,130,165579,238443214,9.55,1700,17,9.67,100,1,10.61,200,2,11.27,100,1,11.4,100,1,11.76,100,1,11.93,200,2,12.33,300,3,12.37,700,1,12.42,700,1,14.02,2,1,14.12,100,1,14.56,800,2,14.6,700,1,14.61,100,1,14.68,700,1,14.79,100,1,14.81,200,2,14.84,100,1,14.91,700,1,ARL,283594173
2025-07-17T15:31:00.028894478Z,2025-07-17T15:31:00.028729168Z,160,2,1108,C,A,14.120000000,100,0,282776285,130,165310,238443996,ARL,0,14.12,100,130,165310,238443996,9.55,1700,17,9.67,100,1,10.61,200,2,11.27,100,1,11.4,100,1,11.76,100,1,11.93,200,2,12.33,300,3,12.37,700,1,12.42,700,1,14.02,2,1,14.56,800,2,14.6,700,1,14.61,100,1,14.68,700,1,14.79,100,1,14.81,200,2,14.84,100,1,14.91,700,1,14.96,100,1,ARL,282776285
2025-07-17T15:31:00.028947312Z,2025-07-17T15:31:00.028782030Z,160,2,1108,A,A,14.260000000,100,0,283595181,130,165282,238443998,ARL,0,14.26,100,130,165282,238443998,9.55,1700,17,9.67,100,1,10.61,200,2,11.27,100,1,11.4,100,1,11.76,100,1,11.93,200,2,12.33,300,3,12.37,700,1,12.42,700,1,14.02,2,1,14.26,100,1,14.56,800,2,14.6,700,1,14.61,100,1,14.68,700,1,14.79,100,1,14.81,200,2,14.84,100,1,14.91,700,1,ARL,283595181
2025-07-17T15:31:00.053107210Z,2025-07-17T15:31:00.052941898Z,160,2,1108,C,A,14.960000000,100,0,283592997,0,165312,238444735,ARL,0,14.96,100,0,165312,238444735,9.55,1700,17,9.67,100,1,10.61,200,2,11.27,100,1,11.4,100,1,11.76,100,1,11.93,200,2,12.33,300,3,12.37,700,1,12.42,700,1,14.02,2,1,14.26,100,1,14.56,800,2,14.6,700,1,14.61,100,1,14.68,700,1,14.79,100,1,14.81,200,2,14.84,100,1,14.91,700,1,ARL,283592997
2025-07-17T15:31:00.053107210Z,2025-07-17T15:31:00.052941898Z,160,2,1108,A,A,15.060000000,100,0,283596673,130,165312,238444735,ARL,0,15.06,100,130,165312,238444735,9.55,1700,17,9.67,100,1,10.61,200,2,11.27,100,1,11.4,100,1,11.76,100,1,11.93,200,2,12.33,300,3,12.37,700,1,12.42,700,1,14.02,2,1,14.26,100,1,14.56,800,2,14.6,700,1,14.61,100,1,14.68,700,1,14.79,100,1,14.81,200,2,14.84,100,1,14.91,700,1,ARL,283596673
2025-07-17T15:31:00.054830847Z,2025-07-17T15:31:00.054665340Z,160,2,1108,C,A,14.810000000,100,0,282776089,0,165507,238444759,ARL,0,14.81,100,0,165507,238444759,9.55,1700,17,9.67,100,1,10.61,200,2,11.27,100,1,11.4,100,1,11.76,100,1,11.93,200,2,12.33,300,3,12.37,700,1,12.42,700,1,14.02,2,1,14.26,100,1,14.56,800,2,14.6,700,1,14.61,100,1,14.68,700,1,14.79,100,1,14.81,100,1,14.84,100,1,14.91,700,1,ARL,282776089
2025-07-17T15:31:00.054830847Z,2025-07-17T15:31:00.054665340Z,160,2,1108,A,A,14.960000000,100,0,283596721,130,165507,238444759,ARL,0,14.96,100,130,165507,238444759,9.55,1700,17,9.67,100,1,10.61,200,2,11.27,100,1,11.4,100,1,11.76,100,1,11.93,200,2,12.33,300,3,12.37,700,1,12.42,700,1,14.02,2,1,14.26,100,1,14.56,800,2,14.6,700,1,14.61,100,1,14.68,700,1,14.79,100,1,14.81,100,1,14.84,100,1,14.91,700,1,ARL,283596721
2025-07-17T15:31:00.071409275Z,2025-07-17T15:31:00.071243665Z,160,2,1108,C,A,14.810000000,100,0,282776029,0,165610,238444961,ARL,0,14.81,100,0,165610,238444961,9.55,1700,17,9.67,100,1,10.61,200,2,11.27,100,1,11.4,100,1,11.76,100,1,11.93,200,2,12.33,300,3,12.37,700,1,12.42,700,1,14.02,2,1,14.26,100,1,14.56,800,2,14.6,700,1,14.61,100,1,14.68,700,1,14.79,100,1,14.84,100,1,14.91,700,1,14.96,100,1,ARL,282776029
2025-07-17T15:31:00.071409275Z,2025-07-17T15:31:00.071243665Z,160,2,1108,A,A,14.960000000,100,0,283596945,130,165610,238444961,ARL,0,14.96,100,130,165610,238444961,9.55,1700,17,9.67,100,1,10.61,200,2,11.27,100,1,11.4,100,1,11.76,100,1,11.93,200,2,12.33,300,3,12.37,700,1,12.42,700,1,14.02,2,1,14.26,100,1,14.56,800,2,14.6,700,1,14.61,100,1,14.68,700,1,14.79,100,1,14.84,100,1,14.91,700,1,14.96,200,2,ARL,283596945
2025-07-17T15:31:00.243369582Z,2025-07-17T15:31:00.243203860Z,160,2,1108,C,A,15.920000000,100,0,282776033,0,165722,238447595,ARL,0,15.92,100,0,165722,238447595,9.55,1700,17,9.67,100,1,10.61,200,2,11.27,100,1,11.4,100,1,11.76,100,1,11.93,200,2,12.33,300,3,12.37,700,1,12.42,700,1,14.02,2,1,14.26,100,1,14.56,800,2,14.6,700,1,14.61,100,1,14.68,700,1,14.79,100,1,14.84,100,1,14.91,700,1,14.96,200,2,ARL,282776033
2025-07-17T15:31:00.243369582Z,2025-07-17T15:31:00.243203860Z,160,2,1108,A,A,16.080000000,100,0,283599609,130,165722,238447595,ARL,0,16.08,100,130,165722,238447595,9.55,1700,17,9.67,100,1,10.61,200,2,11.27,100,1,11.4,100,1,11.76,100,1,11.93,200,2,12.33,300,3,12.37,700,1,12.42,700,1,14.02,2,1,14.26,100,1,14.56,800,2,14.6,700,1,14.61,100,1,14.68,700,1,14.79,100,1,14.84,100,1,14.91,700,1,14.96,200,2,ARL,283599609
2025-07-17T15:31:00.347828545Z,2025-07-17T15:31:00.347663441Z,160,2,1108,A,A,14.030000000,100,0,283604173,130,165104,238450791,ARL,0,14.03,100,130,165104,238450791,9.55,1700,17,9.67,100,1,10.61,200,2,11.27,100,1,11.4,100,1,11.76,100,1,11.93,200,2,12.33,300,3,12.37,700,1,12.42,700,1,14.02,2,1,14.03,100,1,14.26,100,1,14.56,800,2,14.6,700,1,14.61,100,1,14.68,700,1,14.79,100,1,14.84,100,1,14.91,700,1,ARL,283604173
2025-07-17T15:31:04.014590575Z,2025-07-17T15:31:04.014425425Z,160,2,1108,A,A,14.000000000,100,0,283694233,130,165150,238529875,ARL,0,14,100,130,165150,238529875,9.55,1700,17,9.67,100,1,10.61,200,2,11.27,100,1,11.4,100,1,11.76,100,1,11.93,200,2,12.33,300,3,12.37,700,1,12.42,700,1,14,100,1,14.02,2,1,14.03,100,1,14.26,100,1,14.56,800,2,14.6,700,1,14.61,100,1,14.68,700,1,14.79,100,1,14.84,100,1,ARL,283694233
2025-07-17T15:31:04.124577845Z,2025-07-17T15:31:04.124411850Z,160,2,1108,C,A,14.030000000,100,0,283604173,0,165995,238531822,ARL,0,14.03,100,0,165995,238531822,9.55,1700,17,9.67,100,1,10.61,200,2,11.27,100,1,11.4,100,1,11.76,100,1,11.93,200,2,12.33,300,3,12.37,700,1,12.42,700,1,14,100,1,14.02,2,1,14.26,100,1,14.56,800,2,14.6,700,1,14.61,100,1,14.68,700,1,14.79,100,1,14.84,100,1,14.91,700,1,ARL,283604173
2025-07-17T15:31:04.124577845Z,2025-07-17T15:31:04.124411850Z,160,2,1108,A,A,14.010000000,100,0,283695933,130,165995,238531822,ARL,0,14.01,100,130,165995,238531822,9.55,1700,17,9.67,100,1,10.61,200,2,11.27,100,1,11.4,100,1,11.76,100,1,11.93,200,2,12.33,300,3,12.37,700,1,12.42,700,1,14,100,1,14.01,100,1,14.02,2,1,14.26,100,1,14.56,800,2,14.6,700,1,14.61,100,1,14.68,700,1,14.79,100,1,14.84,100,1,ARL,283695933
2025-07-17T15:32:28.644506279Z,2025-07-17T15:32:28.644335983Z,160,2,1108,A,B,13.550000000,10,0,285545121,128,170296,239938946,ARL,0,13.55,10,128,170296,239938946,9.55,1700,17,9.67,100,1,10.61,200,2,11.27,100,1,11.4,100,1,11.76,100,1,11.93,200,2,12.33,300,3,12.37,700,1,12.42,700,1,14,100,1,14.01,100,1,14.02,2,1,14.26,100,1,14.56,800,2,14.6,700,1,14.61,100,1,14.68,700,1,14.79,100,1,14.84,100,1,ARL,285545121
2025-07-17T15:32:28.653238729Z,2025-07-17T15:32:28.653073176Z,160,2,1108,C,B,13.370000000,100,0,215999737,0,165553,239940048,ARL,0,13.37,100,0,165553,239940048,9.55,1700,17,9.67,100,1,10.61,200,2,11.27,100,1,11.4,100,1,11.76,100,1,11.93,200,2,12.33,300,3,12.37,700,1,12.42,700,1,14,100,1,14.01,100,1,14.02,2,1,14.26,100,1,14.56,800,2,14.6,700,1,14.61,100,1,14.68,700,1,14.79,100,1,14.84,100,1,ARL,215999737
2025-07-17T15:32:28.653238729Z,2025-07-17T15:32:28.653073176Z,160,2,1108,A,B,13.540000000,100,0,285545885,130,165553,239940048,ARL,0,13.54,100,130,165553,239940048,9.55,1700,17,9.67,100,1,10.61,200,2,11.27,100,1,11.4,100,1,11.76,100,1,11.93,200,2,12.33,300,3,12.37,700,1,12.42,700,1,14,100,1,14.01,100,1,14.02,2,1,14.26,100,1,14.56,800,2,14.6,700,1,14.61,100,1,14.68,700,1,14.79,100,1,14.84,100,1,ARL,285545885
2025-07-17T15:32:28.653978501Z,2025-07-17T15:32:28.653812889Z,160,2,1108,C,B,12.330000000,100,0,215999753,0,165612,239940096,ARL,0,12.33,100,0,165612,239940096,9.55,1700,17,9.67,100,1,10.61,200,2,11.27,100,1,11.4,100,1,11.76,100,1,11.93,200,2,12.33,200,2,12.37,700,1,12.42,700,1,14,100,1,14.01,100,1,14.02,2,1,14.26,100,1,14.56,800,2,14.6,700,1,14.61,100,1,14.68,700,1,14.79,100,1,14.84,100,1,ARL,215999753
2025-07-17T15:32:28.653978501Z,2025-07-17T15:32:28.653812889Z,160,2,1108,A,B,12.490000000,100,0,285545945,130,165612,239940096,ARL,0,12.49,100,130,165612,239940096,9.55,1700,17,9.67,100,1,10.61,200,2,11.27,100,1,11.4,100,1,11.76,100,1,11.93,200,2,12.33,200,2,12.37,700,1,12.42,700,1,14,100,1,14.01,100,1,14.02,2,1,14.26,100,1,14.56,800,2,14.6,700,1,14.61,100,1,14.68,700,1,14.79,100,1,14.84,100,1,ARL,285545945
2025-07-17T15:32:28.653980648Z,2025-07-17T15:32:28.653815154Z,160,2,1108,C,B,12.670000000,100,0,43663229,130,165494,239940097,ARL,0,12.67,100,130,165494,239940097,9.55,1700,17,9.67,100,1,10.61,200,2,11.27,100,1,11.4,100,1,11.76,100,1,11.93,200,2,12.33,200,2,12.37,700,1,12.42,700,1,14,100,1,14.01,100,1,14.02,2,1,14.26,100,1,14.56,800,2,14.6,700,1,14.61,100,1,14.68,700,1,14.79,100,1,14.84,100,1,ARL,43663229
2025-07-17T15:32:28.654336987Z,2025-07-17T15:32:28.654171723Z,160,2,1108,A,B,12.940000000,100,0,285545953,130,165264,239940109,ARL,0,12.94,100,130,165264,239940109,9.55,1700,17,9.67,100,1,10.61,200,2,11.27,100,1,11.4,100,1,11.76,100,1,11.93,200,2,12.33,200,2,12.37,700,1,12.42,700,1,14,100,1,14.01,100,1,14.02,2,1,14.26,100,1,14.56,800,2,14.6,700,1,14.61,100,1,14.68,700,1,14.79,100,1,14.84,100,1,ARL,285545953
2025-07-17T15:32:28.657073743Z,2025-07-17T15:32:28.656908386Z,160,2,1108,C,B,12.470000000,100,0,43554133,130,165357,239940358,ARL,0,12.47,100,130,165357,239940358,9.55,1700,17,9.67,100,1,10.61,200,2,11.27,100,1,11.4,100,1,11.76,100,1,11.93,200,2,12.33,200,2,12.37,700,1,12.42,700,1,14,100,1,14.01,100,1,14.02,2,1,14.26,100,1,14.56,800,2,14.6,700,1,14.61,100,1,14.68,700,1,14.79,100,1,14.84,100,1,ARL,43554133
2025-07-17T15:32:28.657173856Z,2025-07-17T15:32:28.657008222Z,160,2,1108,A,B,12.730000000,100,0,285546061,130,165634,239940359,ARL,0,12.73,100,130,165634,239940359,9.55,1700,17,9.67,100,1,10.61,200,2,11.27,100,1,11.4,100,1,11.76,100,1,11.93,200,2,12.33,200,2,12.37,700,1,12.42,700,1,14,100,1,14.01,100,1,14.02,2,1,14.26,100,1,14.56,800,2,14.6,700,1,14.61,100,1,14.68,700,1,14.79,100,1,14.84,100,1,ARL,285546061
2025-07-17T15:32:28.667074437Z,2025-07-17T15:32:28.666909194Z,160,2,1108,C,B,13.100000000,100,0,216001413,130,165243,239940810,ARL,0,13.1,100,130,165243,239940810,9.55,1700,17,9.67,100,1,10.61,200,2,11.27,100,1,11.4,100,1,11.76,100,1,11.93,200,2,12.33,200,2,12.37,700,1,12.42,700,1,14,100,1,14.01,100,1,14.02,2,1,14.26,100,1,14.56,800,2,14.6,700,1,14.61,100,1,14.68,700,1,14.79,100,1,14.84,100,1,ARL,216001413
2025-07-17T15:32:28.667126637Z,2025-07-17T15:32:28.666961018Z,160,2,1108,A,B,13.270000000,100,0,285546673,130,165619,239940813,ARL,0,13.27,100,130,165619,239940813,9.55,1700,17,9.67,100,1,10.61,200,2,11.27,100,1,11.4,100,1,11.76,100,1,11.93,200,2,12.33,200,2,12.37,700,1,12.42,700,1,14,100,1,14.01,100,1,14.02,2,1,14.26,100,1,14.56,800,2,14.6,700,1,14.61,100,1,14.68,700,1,14.79,100,1,14.84,100,1,ARL,285546673
2025-07-17T15:32:28.674444711Z,2025-07-17T15:32:28.674279259Z,160,2,1108,C,B,12.330000000,100,0,43755813,0,165452,239941057,ARL,0,12.33,100,0,165452,239941057,9.55,1700,17,9.67,100,1,10.61,200,2,11.27,100,1,11.4,100,1,11.76,100,1,11.93,200,2,12.33,100,1,12.37,700,1,12.42,700,1,14,100,1,14.01,100,1,14.02,2,1,14.26,100,1,14.56,800,2,14.6,700,1,14.61,100,1,14.68,700,1,14.79,100,1,14.84,100,1,ARL,43755813
2025-07-17T15:32:28.674444711Z,2025-07-17T15:32:28.674279259Z,160,2,1108,A,B,12.590000000,100,0,285546893,130,165452,239941057,ARL,0,12.59,100,130,165452,239941057,9.55,1700,17,9.67,100,1,10.61,200,2,11.27,100,1,11.4,100,1,11.76,100,1,11.93,200,2,12.33,100,1,12.37,700,1,12.42,700,1,14,100,1,14.01,100,1,14.02,2,1,14.26,100,1,14.56,800,2,14.6,700,1,14.61,100,1,14.68,700,1,14.79,100,1,14.84,100,1,ARL,285546893
2025-07-17T15:32:28.691264796Z,2025-07-17T15:32:28.691099298Z,160,2,1108,C,B,9.670000000,100,0,44082961,0,165498,239941825,ARL,0,9.67,100,0,165498,239941825,9.55,1700,17,10.61,200,2,11.27,100,1,11.4,100,1,11.76,100,1,11.93,200,2,12.33,100,1,12.37,700,1,12.42,700,1,12.43,700,1,14,100,1,14.01,100,1,14.02,2,1,14.26,100,1,14.56,800,2,14.6,700,1,14.61,100,1,14.68,700,1,14.79,100,1,14.84,100,1,ARL,44082961
2025-07-17T15:32:28.691264796Z,2025-07-17T15:32:28.691099298Z,160,2,1108,A,B,9.880000000,100,0,285548137,130,165498,239941825,ARL,0,9.88,100,130,165498,239941825,9.55,1700,17,9.88,100,1,10.61,200,2,11.27,100,1,11.4,100,1,11.76,100,1,11.93,200,2,12.33,100,1,12.37,700,1,12.42,700,1,14,100,1,14.01,100,1,14.02,2,1,14.26,100,1,14.56,800,2,14.6,700,1,14.61,100,1,14.68,700,1,14.79,100,1,14.84,100,1,ARL,285548137
2025-07-17T15:32:28.711494526Z,2025-07-17T15:32:28.711329066Z,160,2,1108,C,B,11.270000000,100,0,43826785,0,165460,239942732,ARL,0,11.27,100,0,165460,239942732,9.55,1700,17,9.88,100,1,10.61,200,2,11.4,100,1,11.76,100,1,11.93,200,2,12.33,100,1,12.37,700,1,12.42,700,1,12.43,700,1,14,100,1,14.01,100,1,14.02,2,1,14.26,100,1,14.56,800,2,14.6,700,1,14.61,100,1,14.68,700,1,14.79,100,1,14.84,100,1,ARL,43826785
2025-07-17T15:32:28.711494526Z,2025-07-17T15:32:28.711329066Z,160,2,1108,A,B,11.500000000,100,0,285549537,130,165460,239942732,ARL,0,11.5,100,130,165460,239942732,9.55,1700,17,9.88,100,1,10.61,200,2,11.4,100,1,11.5,100,1,11.76,100,1,11.93,200,2,12.33,100,1,12.37,700,1,12.42,700,1,14,100,1,14.01,100,1,14.02,2,1,14.26,100,1,14.56,800,2,14.6,700,1,14.61,100,1,14.68,700,1,14.79,100,1,14.84,100,1,ARL,285549537
2025-07-17T15:32:28.771995987Z,2025-07-17T15:32:28.771830554Z,160,2,1108,C,B,13.550000000,10,0,285545121,128,165433,239945992,ARL,0,13.55,10,128,165433,239945992,9.55,1700,17,9.88,100,1,10.61,200,2,11.4,100,1,11.5,100,1,11.76,100,1,11.93,200,2,12.33,100,1,12.37,700,1,12.42,700,1,14,100,1,14.01,100,1,14.02,2,1,14.26,100,1,14.56,800,2,14.6,700,1,14.61,100,1,14.68,700,1,14.79,100,1,14.84,100,1,ARL,285545121
2025-07-17T15:32:28.806930722Z,2025-07-17T15:32:28.806765209Z,160,2,1108,C,B,12.330000000,100,0,44088633,0,165513,239948319,ARL,0,12.33,100,0,165513,239948319,9.55,1700,17,9.88,100,1,10.61,200,2,11.4,100,1,11.5,100,1,11.76,100,1,11.93,200,2,12.37,700,1,12.42,700,1,12.43,700,1,14,100,1,14.01,100,1,14.02,2,1,14.26,100,1,14.56,800,2,14.6,700,1,14.61,100,1,14.68,700,1,14.79,100,1,14.84,100,1,ARL,44088633
2025-07-17T15:32:28.806930722Z,2025-07-17T15:32:28.806765209Z,160,2,1108,A,B,12.590000000,100,0,285553901,130,165513,239948319,ARL,0,12.59,100,130,165513,239948319,9.55,1700,17,9.88,100,1,10.61,200,2,11.4,100,1,11.5,100,1,11.76,100,1,11.93,200,2,12.37,700,1,12.42,700,1,12.43,700,1,14,100,1,14.01,100,1,14.02,2,1,14.26,100,1,14.56,800,2,14.6,700,1,14.61,100,1,14.68,700,1,14.79,100,1,14.84,100,1,ARL,285553901
2025-07-17T15:32:28.850288215Z,2025-07-17T15:32:28.850122877Z,160,2,1108,A,A,13.980000000,100,0,285556869,130,165338,239950805,ARL,0,13.98,100,130,165338,239950805,9.55,1700,17,9.88,100,1,10.61,200,2,11.4,100,1,11.5,100,1,11.76,100,1,11.93,200,2,12.37,700,1,12.42,700,1,12.43,700,1,13.98,100,1,14,100,1,14.01,100,1,14.02,2,1,14.26,100,1,14.56,800,2,14.6,700,1,14.61,100,1,14.68,700,1,14.79,100,1,ARL,285556869
2025-07-17T15:32:28.857140107Z,2025-07-17T15:32:28.856973845Z,160,2,1108,C,A,14.000000000,100,0,283694233,130,166262,239951361,ARL,0,14,100,130,166262,239951361,9.55,1700,17,9.88,100,1,10.61,200,2,11.4,100,1,11.5,100,1,11.76,100,1,11.93,200,2,12.37,700,1,12.42,700,1,12.43,700,1,13.98,100,1,14.01,100,1,14.02,2,1,14.26,100,1,14.56,800,2,14.6,700,1,14.61,100,1,14.68,700,1,14.79,100,1,14.84,100,1,ARL,283694233
2025-07-17T15:32:29.573634202Z,2025-07-17T15:32:29.573469021Z,160,2,1108,C,B,13.540000000,100,0,285545885,130,165181,239975997,ARL,0,13.54,100,130,165181,239975997,9.55,1700,17,9.88,100,1,10.61,200,2,11.4,100,1,11.5,100,1,11.76,100,1,11.93,200,2,12.37,700,1,12.42,700,1,12.43,700,1,13.98,100,1,14.01,100,1,14.02,2,1,14.26,100,1,14.56,800,2,14.6,700,1,14.61,100,1,14.68,700,1,14.79,100,1,14.84,100,1,ARL,285545885
2025-07-17T15:32:29.574368326Z,2025-07-17T15:32:29.574202467Z,160,2,1108,C,B,12.490000000,100,0,285545945,0,165859,239976004,ARL,0,12.49,100,0,165859,239976004,9.55,1700,17,9.88,100,1,10.61,200,2,11.4,100,1,11.5,100,1,11.76,100,1,11.93,200,2,12.37,700,1,12.42,700,1,12.43,700,1,13.98,100,1,14.01,100,1,14.02,2,1,14.26,100,1,14.56,800,2,14.6,700,1,14.61,100,1,14.68,700,1,14.79,100,1,14.84,100,1,ARL,285545945
2025-07-17T15:32:29.574368326Z,2025-07-17T15:32:29.574202467Z,160,2,1108,A,B,12.270000000,100,0,285586089,130,165859,239976004,ARL,0,12.27,100,130,165859,239976004,9.55,1700,17,9.88,100,1,10.61,200,2,11.4,100,1,11.5,100,1,11.76,100,1,11.93,200,2,12.27,100,1,12.37,700,1,12.42,700,1,13.98,100,1,14.01,100,1,14.02,2,1,14.26,100,1,14.56,800,2,14.6,700,1,14.61,100,1,14.68,700,1,14.79,100,1,14.84,100,1,ARL,285586089
2025-07-17T15:32:29.574371866Z,2025-07-17T15:32:29.574206685Z,160,2,1108,C,B,12.940000000,100,0,285545953,130,165181,239976005,ARL,0,12.94,100,130,165181,239976005,9.55,1700,17,9.88,100,1,10.61,200,2,11.4,100,1,11.5,100,1,11.76,100,1,11.93,200,2,12.27,100,1,12.37,700,1,12.42,700,1,13.98,100,1,14.01,100,1,14.02,2,1,14.26,100,1,14.56,800,2,14.6,700,1,14.61,100,1,14.68,700,1,14.79,100,1,14.84,100,1,ARL,285545953
2025-07-17T15:32:29.574722141Z,2025-07-17T15:32:29.574556760Z,160,2,1108,A,B,12.710000000,100,0,285586093,130,165381,239976069,ARL,0,12.71,100,130,165381,239976069,9.55,1700,17,9.88,100,1,10.61,200,2,11.4,100,1,11.5,100,1,11.76,100,1,11.93,200,2,12.27,100,1,12.37,700,1,12.42,700,1,13.98,100,1,14.01,100,1,14.02,2,1,14.26,100,1,14.56,800,2,14.6,700,1,14.61,100,1,14.68,700,1,14.79,100,1,14.84,100,1,ARL,285586093
2025-07-17T15:32:29.575134655Z,2025-07-17T15:32:29.574968914Z,160,2,1108,C,B,12.590000000,100,0,285546893,0,165741,239976143,ARL,0,12.59,100,0,165741,239976143,9.55,1700,17,9.88,100,1,10.61,200,2,11.4,100,1,11.5,100,1,11.76,100,1,11.93,200,2,12.27,100,1,12.37,700,1,12.42,700,1,13.98,100,1,14.01,100,1,14.02,2,1,14.26,100,1,14.56,800,2,14.6,700,1,14.61,100,1,14.68,700,1,14.79,100,1,14.84,100,1,ARL,285546893
2025-07-17T15:32:29.575134655Z,2025-07-17T15:32:29.574968914Z,160,2,1108,A,B,12.340000000,100,0,285586113,130,165741,239976143,ARL,0,12.34,100,130,165741,239976143,9.55,1700,17,9.88,100,1,10.61,200,2,11.4,100,1,11.5,100,1,11.76,100,1,11.93,200,2,12.27,100,1,12.34,100,1,12.37,700,1,13.98,100,1,14.01,100,1,14.02,2,1,14.26,100,1,14.56,800,2,14.6,700,1,14.61,100,1,14.68,700,1,14.79,100,1,14.84,100,1,ARL,285586113
2025-07-17T15:32:29.575550333Z,2025-07-17T15:32:29.575384940Z,160,2,1108,C,B,11.500000000,100,0,285549537,0,165393,239976173,ARL,0,11.5,100,0,165393,239976173,9.55,1700,17,9.88,100,1,10.61,200,2,11.4,100,1,11.76,100,1,11.93,200,2,12.27,100,1,12.34,100,1,12.37,700,1,12.42,700,1,13.98,100,1,14.01,100,1,14.02,2,1,14.26,100,1,14.56,800,2,14.6,700,1,14.61,100,1,14.68,700,1,14.79,100,1,14.84,100,1,ARL,285549537
2025-07-17T15:32:29.575550333Z,2025-07-17T15:32:29.575384940Z,160,2,1108,A,B,11.270000000,100,0,285586145,130,165393,239976173,ARL,0,11.27,100,130,165393,239976173,9.55,1700,17,9.88,100,1,10.61,200,2,11.27,100,1,11.4,100,1,11.76,100,1,11.93,200,2,12.27,100,1,12.34,100,1,12.37,700,1,13.98,100,1,14.01,100,1,14.02,2,1,14.26,100,1,14.56,800,2,14.6,700,1,14.61,100,1,14.68,700,1,14.79,100,1,14.84,100,1,ARL,285586145
2025-07-17T15:32:29.575821091Z,2025-07-17T15:32:29.575655631Z,160,2,1108,C,B,9.880000000,100,0,285548137,0,165460,239976183,ARL,0,9.88,100,0,165460,239976183,9.55,1700,17,10.61,200,2,11.27,100,1,11.4,100,1,11.76,100,1,11.93,200,2,12.27,100,1,12.34,100,1,12.37,700,1,12.42,700,1,13.98,100,1,14.01,100,1,14.02,2,1,14.26,100,1,14.56,800,2,14.6,700,1,14.61,100,1,14.68,700,1,14.79,100,1,14.84,100,1,ARL,285548137
2025-07-17T15:32:29.575821091Z,2025-07-17T15:32:29.575655631Z,160,2,1108,A,B,9.680000000,100,0,285586157,130,165460,239976183,ARL,0,9.68,100,130,165460,239976183,9.55,1700,17,9.68,100,1,10.61,200,2,11.27,100,1,11.4,100,1,11.76,100,1,11.93,200,2,12.27,100,1,12.34,100,1,12.37,700,1,13.98,100,1,14.01,100,1,14.02,2,1,14.26,100,1,14.56,800,2,14.6,700,1,14.61,100,1,14.68,700,1,14.79,100,1,14.84,100,1,ARL,285586157
2025-07-17T15:32:29.578317238Z,2025-07-17T15:32:29.578151593Z,160,2,1108,C,B,12.590000000,100,0,285553901,0,165645,239976225,ARL,0,12.59,100,0,165645,239976225,9.55,1700,17,9.68,100,1,10.61,200,2,11.27,100,1,11.4,100,1,11.76,100,1,11.93,200,2,12.27,100,1,12.34,100,1,12.37,700,1,13.98,100,1,14.01,100,1,14.02,2,1,14.26,100,1,14.56,800,2,14.6,700,1,14.61,100,1,14.68,700,1,14.79,100,1,14.84,100,1,ARL,285553901
2025-07-17T15:32:29.578317238Z,2025-07-17T15:32:29.578151593Z,160,2,1108,A,B,12.340000000,100,0,285586189,130,165645,239976225,ARL,0,12.34,100,130,165645,239976225,9.55,1700,17,9.68,100,1,10.61,200,2,11.27,100,1,11.4,100,1,11.76,100,1,11.93,200,2,12.27,100,1,12.34,200,2,12.37,700,1,13.98,100,1,14.01,100,1,14.02,2,1,14.26,100,1,14.56,800,2,14.6,700,1,14.61,100,1,14.68,700,1,14.79,100,1,14.84,100,1,ARL,285586189
2025-07-17T15:32:29.580933155Z,2025-07-17T15:32:29.580767960Z,160,2,1108,A,B,13.260000000,100,0,285586221,130,165195,239976262,ARL,0,13.26,100,130,165195,239976262,9.55,1700,17,9.68,100,1,10.61,200,2,11.27,100,1,11.4,100,1,11.76,100,1,11.93,200,2,12.27,100,1,12.34,200,2,12.37,700,1,13.98,100,1,14.01,100,1,14.02,2,1,14.26,100,1,14.56,800,2,14.6,700,1,14.61,100,1,14.68,700,1,14.79,100,1,14.84,100,1,ARL,285586221
2025-07-17T15:32:29.580952045Z,2025-07-17T15:32:29.580786478Z,160,2,1108,C,A,14.010000000,100,0,283695933,0,165567,239976263,ARL,0,14.01,100,0,165567,239976263,9.55,1700,17,9.68,100,1,10.61,200,2,11.27,100,1,11.4,100,1,11.76,100,1,11.93,200,2,12.27,100,1,12.34,200,2,12.37,700,1,13.98,100,1,14.02,2,1,14.26,100,1,14.56,800,2,14.6,700,1,14.61,100,1,14.68,700,1,14.79,100,1,14.84,100,1,14.91,700,1,ARL,283695933
2025-07-17T15:32:29.580952045Z,2025-07-17T15:32:29.580786478Z,160,2,1108,A,A,13.990000000,100,0,285586225,130,165567,239976263,ARL,0,13.99,100,130,165567,239976263,9.55,1700,17,9.68,100,1,10.61,200,2,11.27,100,1,11.4,100,1,11.76,100,1,11.93,200,2,12.27,100,1,12.34,200,2,12.37,700,1,13.98,100,1,13.99,100,1,14.02,2,1,14.26,100,1,14.56,800,2,14.6,700,1,14.61,100,1,14.68,700,1,14.79,100,1,14.84,100,1,ARL,285586225
2025-07-17T15:32:29.587192852Z,2025-07-17T15:32:29.587027681Z,160,2,1108,C,B,13.270000000,100,0,285546673,130,165171,239976327,ARL,0,13.27,100,130,165171,239976327,9.55,1700,17,9.68,100,1,10.61,200,2,11.27,100,1,11.4,100,1,11.76,100,1,11.93,200,2,12.27,100,1,12.34,200,2,12.37,700,1,13.98,100,1,13.99,100,1,14.02,2,1,14.26,100,1,14.56,800,2,14.6,700,1,14.61,100,1,14.68,700,1,14.79,100,1,14.84,100,1,ARL,285546673
2025-07-17T15:32:29.587246470Z,2025-07-17T15:32:29.587081086Z,160,2,1108,A,B,13.030000000,100,0,285586293,130,165384,239976336,ARL,0,13.03,100,130,165384,239976336,9.55,1700,17,9.68,100,1,10.61,200,2,11.27,100,1,11.4,100,1,11.76,100,1,11.93,200,2,12.27,100,1,12.34,200,2,12.37,700,1,13.98,100,1,13.99,100,1,14.02,2,1,14.26,100,1,14.56,800,2,14.6,700,1,14.61,100,1,14.68,700,1,14.79,100,1,14.84,100,1,ARL,285586293
2025-07-17T15:32:29.659679280Z,2025-07-17T15:32:29.659513918Z,160,2,1108,C,B,12.730000000,100,0,285546061,0,165362,239977574,ARL,0,12.73,100,0,165362,239977574,9.55,1700,17,9.68,100,1,10.61,200,2,11.27,100,1,11.4,100,1,11.76,100,1,11.93,200,2,12.27,100,1,12.34,200,2,12.37,700,1,13.98,100,1,13.99,100,1,14.02,2,1,14.26,100,1,14.56,800,2,14.6,700,1,14.61,100,1,14.68,700,1,14.79,100,1,14.84,100,1,ARL,285546061
2025-07-17T15:32:29.659679280Z,2025-07-17T15:32:29.659513918Z,160,2,1108,A,B,12.460000000,100,0,285587281,130,165362,239977574,ARL,0,12.46,100,130,165362,239977574,9.55,1700,17,9.68,100,1,10.61,200,2,11.27,100,1,11.4,100,1,11.76,100,1,11.93,200,2,12.27,100,1,12.34,200,2,12.37,700,1,13.98,100,1,13.99,100,1,14.02,2,1,14.26,100,1,14.56,800,2,14.6,700,1,14.61,100,1,14.68,700,1,14.79,100,1,14.84,100,1,ARL,285587281
2025-07-17T15:33:04.248156868Z,2025-07-17T15:33:04.247990788Z,160,2,1108,C,A,14.970000000,100,0,283592993,0,166080,240885845,ARL,0,14.97,100,0,166080,240885845,9.55,1700,17,9.68,100,1,10.61,200,2,11.27,100,1,11.4,100,1,11.76,100,1,11.93,200,2,12.27,100,1,12.34,200,2,12.37,700,1,13.98,100,1,13.99,100,1,14.02,2,1,14.26,100,1,14.56,800,2,14.6,700,1,14.61,100,1,14.68,700,1,14.79,100,1,14.84,100,1,ARL,283592993
2025-07-17T15:33:04.248156868Z,2025-07-17T15:33:04.247990788Z,160,2,1108,A,A,14.720000000,100,0,286680573,130,166080,240885845,ARL,0,14.72,100,130,166080,240885845,9.55,1700,17,9.68,100,1,10.61,200,2,11.27,100,1,11.4,100,1,11.76,100,1,11.93,200,2,12.27,100,1,12.34,200,2,12.37,700,1,13.98,100,1,13.99,100,1,14.02,2,1,14.26,100,1,14.56,800,2,14.6,700,1,14.61,100,1,14.68,700,1,14.72,100,1,14.79,100,1,ARL,286680573
2025-07-17T15:33:04.248189408Z,2025-07-17T15:33:04.248023883Z,160,2,1108,C,A,14.970000000,100,0,283593041,0,165525,240885847,ARL,0,14.97,100,0,165525,240885847,9.55,1700,17,9.68,100,1,10.61,200,2,11.27,100,1,11.4,100,1,11.76,100,1,11.93,200,2,12.27,100,1,12.34,200,2,12.37,700,1,13.98,100,1,13.99,100,1,14.02,2,1,14.26,100,1,14.56,800,2,14.6,700,1,14.61,100,1,14.68,700,1,14.72,100,1,14.79,100,1,ARL,283593041
2025-07-17T15:33:04.248189408Z,2025-07-17T15:33:04.248023883Z,160,2,1108,A,A,14.720000000,100,0,286680577,130,165525,240885847,ARL,0,14.72,100,130,165525,240885847,9.55,1700,17,9.68,100,1,10.61,200,2,11.27,100,1,11.4,100,1,11.76,100,1,11.93,200,2,12.27,100,1,12.34,200,2,12.37,700,1,13.98,100,1,13.99,100,1,14.02,2,1,14.26,100,1,14.56,800,2,14.6,700,1,14.61,100,1,14.68,700,1,14.72,200,2,14.79,100,1,ARL,286680577
2025-07-17T15:33:04.255712050Z,2025-07-17T15:33:04.255546094Z,160,2,1108,A,A,13.840000000,100,0,286680685,130,165956,240886132,ARL,0,13.84,100,130,165956,240886132,9.55,1700,17,9.68,100,1,10.61,200,2,11.27,100,1,11.4,100,1,11.76,100,1,11.93,200,2,12.27,100,1,12.34,200,2,12.37,700,1,13.84,100,1,13.98,100,1,13.99,100,1,14.02,2,1,14.26,100,1,14.56,800,2,14.6,700,1,14.61,100,1,14.68,700,1,14.72,200,2,ARL,286680685
2025-07-17T15:33:04.255777981Z,2025-07-17T15:33:04.255612126Z,160,2,1108,C,B,12.270000000,100,0,285586089,0,165855,240886133,ARL,0,12.27,100,0,165855,240886133,9.55,1700,17,9.68,100,1,10.61,200,2,11.27,100,1,11.4,100,1,11.76,100,1,11.93,200,2,12.34,200,2,12.37,700,1,12.42,700,1,13.84,100,1,13.98,100,1,13.99,100,1,14.02,2,1,14.26,100,1,14.56,800,2,14.6,700,1,14.61,100,1,14.68,700,1,14.72,200,2,ARL,285586089
2025-07-17T15:33:04.255777981Z,2025-07-17T15:33:04.255612126Z,160,2,1108,A,B,12.230000000,100,0,286680693,130,165855,240886133,ARL,0,12.23,100,130,165855,240886133,9.55,1700,17,9.68,100,1,10.61,200,2,11.27,100,1,11.4,100,1,11.76,100,1,11.93,200,2,12.23,100,1,12.34,200,2,12.37,700,1,13.84,100,1,13.98,100,1,13.99,100,1,14.02,2,1,14.26,100,1,14.56,800,2,14.6,700,1,14.61,100,1,14.68,700,1,14.72,200,2,ARL,286680693
2025-07-17T15:33:04.256438228Z,2025-07-17T15:33:04.256272676Z,160,2,1108,C,A,15.060000000,100,0,283596673,0,165552,240886147,ARL,0,15.06,100,0,165552,240886147,9.55,1700,17,9.68,100,1,10.61,200,2,11.27,100,1,11.4,100,1,11.76,100,1,11.93,200,2,12.23,100,1,12.34,200,2,12.37,700,1,13.84,100,1,13.98,100,1,13.99,100,1,14.02,2,1,14.26,100,1,14.56,800,2,14.6,700,1,14.61,100,1,14.68,700,1,14.72,200,2,ARL,283596673
2025-07-17T15:33:04.256438228Z,2025-07-17T15:33:04.256272676Z,160,2,1108,A,A,14.910000000,100,0,286680721,130,165552,240886147,ARL,0,14.91,100,130,165552,240886147,9.55,1700,17,9.68,100,1,10.61,200,2,11.27,100,1,11.4,100,1,11.76,100,1,11.93,200,2,12.23,100,1,12.34,200,2,12.37,700,1,13.84,100,1,13.98,100,1,13.99,100,1,14.02,2,1,14.26,100,1,14.56,800,2,14.6,700,1,14.61,100,1,14.68,700,1,14.72,200,2,ARL,286680721
2025-07-17T15:33:04.258080504Z,2025-07-17T15:33:04.257914956Z,160,2,1108,C,A,14.960000000,100,0,283596945,0,165548,240886188,ARL,0,14.96,100,0,165548,240886188,9.55,1700,17,9.68,100,1,10.61,200,2,11.27,100,1,11.4,100,1,11.76,100,1,11.93,200,2,12.23,100,1,12.34,200,2,12.37,700,1,13.84,100,1,13.98,100,1,13.99,100,1,14.02,2,1,14.26,100,1,14.56,800,2,14.6,700,1,14.61,100,1,14.68,700,1,14.72,200,2,ARL,283596945
2025-07-17T15:33:04.258080504Z,2025-07-17T15:33:04.257914956Z,160,2,1108,A,A,14.810000000,100,0,286680741,130,165548,240886188,ARL,0,14.81,100,130,165548,240886188,9.55,1700,17,9.68,100,1,10.61,200,2,11.27,100,1,11.4,100,1,11.76,100,1,11.93,200,2,12.23,100,1,12.34,200,2,12.37,700,1,13.84,100,1,13.98,100,1,13.99,100,1,14.02,2,1,14.26,100,1,14.56,800,2,14.6,700,1,14.61,100,1,14.68,700,1,14.72,200,2,ARL,286680741
2025-07-17T15:33:04.261684319Z,2025-07-17T15:33:04.261518776Z,160,2,1108,C,A,14.790000000,100,0,283593313,0,165543,240886271,ARL,0,14.79,100,0,165543,240886271,9.55,1700,17,9.68,100,1,10.61,200,2,11.27,100,1,11.4,100,1,11.76,100,1,11.93,200,2,12.23,100,1,12.34,200,2,12.37,700,1,13.84,100,1,13.98,100,1,13.99,100,1,14.02,2,1,14.26,100,1,14.56,800,2,14.6,700,1,14.61,100,1,14.68,700,1,14.72,200,2,ARL,283593313
2025-07-17T15:33:04.261684319Z,2025-07-17T15:33:04.261518776Z,160,2,1108,A,A,14.650000000,100,0,286680905,130,165543,240886271,ARL,0,14.65,100,130,165543,240886271,9.55,1700,17,9.68,100,1,10.61,200,2,11.27,100,1,11.4,100,1,11.76,100,1,11.93,200,2,12.23,100,1,12.34,200,2,12.37,700,1,13.84,100,1,13.98,100,1,13.99,100,1,14.02,2,1,14.26,100,1,14.56,800,2,14.6,700,1,14.61,100,1,14.65,100,1,14.68,700,1,ARL,286680905
2025-07-17T15:33:04.263011314Z,2025-07-17T15:33:04.262845834Z,160,2,1108,C,A,14.260000000,100,0,283595181,130,165480,240886294,ARL,0,14.26,100,130,165480,240886294,9.55,1700,17,9.68,100,1,10.61,200,2,11.27,100,1,11.4,100,1,11.76,100,1,11.93,200,2,12.23,100,1,12.34,200,2,12.37,700,1,13.84,100,1,13.98,100,1,13.99,100,1,14.02,2,1,14.56,800,2,14.6,700,1,14.61,100,1,14.65,100,1,14.68,700,1,14.72,200,2,ARL,283595181
2025-07-17T15:33:04.263052660Z,2025-07-17T15:33:04.262887184Z,160,2,1108,C,A,13.980000000,100,0,285556869,130,165476,240886296,ARL,0,13.98,100,130,165476,240886296,9.55,1700,17,9.68,100,1,10.61,200,2,11.27,100,1,11.4,100,1,11.76,100,1,11.93,200,2,12.23,100,1,12.34,200,2,12.37,700,1,13.84,100,1,13.99,100,1,14.02,2,1,14.56,800,2,14.6,700,1,14.61,100,1,14.65,100,1,14.68,700,1,14.72,200,2,14.81,100,1,ARL,285556869
2025-07-17T15:33:04.263065252Z,2025-07-17T15:33:04.262899981Z,160,2,1108,A,A,14.120000000,100,0,286680917,130,165271,240886297,ARL,0,14.12,100,130,165271,240886297,9.55,1700,17,9.68,100,1,10.61,200,2,11.27,100,1,11.4,100,1,11.76,100,1,11.93,200,2,12.23,100,1,12.34,200,2,12.37,700,1,13.84,100,1,13.99,100,1,14.02,2,1,14.12,100,1,14.56,800,2,14.6,700,1,14.61,100,1,14.65,100,1,14.68,700,1,14.72,200,2,ARL,286680917
2025-07-17T15:33:04.271212113Z,2025-07-17T15:33:04.271046430Z,160,2,1108,C,A,17.760000000,100,0,283594173,0,165683,240886583,ARL,0,17.76,100,0,165683,240886583,9.55,1700,17,9.68,100,1,10.61,200,2,11.27,100,1,11.4,100,1,11.76,100,1,11.93,200,2,12.23,100,1,12.34,200,2,12.37,700,1,13.84,100,1,13.99,100,1,14.02,2,1,14.12,100,1,14.56,800,2,14.6,700,1,14.61,100,1,14.65,100,1,14.68,700,1,14.72,200,2,ARL,283594173
2025-07-17T15:33:04.271212113Z,2025-07-17T15:33:04.271046430Z,160,2,1108,A,A,17.580000000,100,0,286681057,130,165683,240886583,ARL,0,17.58,100,130,165683,240886583,9.55,1700,17,9.68,100,1,10.61,200,2,11.27,100,1,11.4,100,1,11.76,100,1,11.93,200,2,12.23,100,1,12.34,200,2,12.37,700,1,13.84,100,1,13.99,100,1,14.02,2,1,14.12,100,1,14.56,800,2,14.6,700,1,14.61,100,1,14.65,100,1,14.68,700,1,14.72,200,2,ARL,286681057
2025-07-17T15:33:04.277880725Z,2025-07-17T15:33:04.277715123Z,160,2,1108,C,A,16.080000000,100,0,283599609,0,165602,240886720,ARL,0,16.08,100,0,165602,240886720,9.55,1700,17,9.68,100,1,10.61,200,2,11.27,100,1,11.4,100,1,11.76,100,1,11.93,200,2,12.23,100,1,12.34,200,2,12.37,700,1,13.84,100,1,13.99,100,1,14.02,2,1,14.12,100,1,14.56,800,2,14.6,700,1,14.61,100,1,14.65,100,1,14.68,700,1,14.72,200,2,ARL,283599609
2025-07-17T15:33:04.277880725Z,2025-07-17T15:33:04.277715123Z,160,2,1108,A,A,15.920000000,100,0,286681229,130,165602,240886720,ARL,0,15.92,100,130,165602,240886720,9.55,1700,17,9.68,100,1,10.61,200,2,11.27,100,1,11.4,100,1,11.76,100,1,11.93,200,2,12.23,100,1,12.34,200,2,12.37,700,1,13.84,100,1,13.99,100,1,14.02,2,1,14.12,100,1,14.56,800,2,14.6,700,1,14.61,100,1,14.65,100,1,14.68,700,1,14.72,200,2,ARL,286681229
2025-07-17T15:33:04.418840148Z,2025-07-17T15:33:04.418674487Z,160,2,1108,C,A,14.960000000,100,0,283596721,0,165661,240888774,ARL,0,14.96,100,0,165661,240888774,9.55,1700,17,9.68,100,1,10.61,200,2,11.27,100,1,11.4,100,1,11.76,100,1,11.93,200,2,12.23,100,1,12.34,200,2,12.37,700,1,13.84,100,1,13.99,100,1,14.02,2,1,14.12,100,1,14.56,800,2,14.6,700,1,14.61,100,1,14.65,100,1,14.68,700,1,14.72,200,2,ARL,283596721
2025-07-17T15:33:04.418840148Z,2025-07-17T15:33:04.418674487Z,160,2,1108,A,A,14.810000000,100,0,286684005,130,165661,240888774,ARL,0,14.81,100,130,165661,240888774,9.55,1700,17,9.68,100,1,10.61,200,2,11.27,100,1,11.4,100,1,11.76,100,1,11.93,200,2,12.23,100,1,12.34,200,2,12.37,700,1,13.84,100,1,13.99,100,1,14.02,2,1,14.12,100,1,14.56,800,2,14.6,700,1,14.61,100,1,14.65,100,1,14.68,700,1,14.72,200,2,ARL,286684005
2025-07-17T15:33:05.330854217Z,2025-07-17T15:33:05.330688486Z,160,2,1108,C,A,13.990000000,100,0,285586225,0,165731,240911093,ARL,0,13.99,100,0,165731,240911093,9.55,1700,17,9.68,100,1,10.61,200,2,11.27,100,1,11.4,100,1,11.76,100,1,11.93,200,2,12.23,100,1,12.34,200,2,12.37,700,1,13.84,100,1,14.02,2,1,14.12,100,1,14.56,800,2,14.6,700,1,14.61,100,1,14.65,100,1,14.68,700,1,14.72,200,2,14.81,200,2,ARL,285586225
2025-07-17T15:33:05.330854217Z,2025-07-17T15:33:05.330688486Z,160,2,1108,A,A,13.850000000,100,0,286704785,130,165731,240911093,ARL,0,13.85,100,130,165731,240911093,9.55,1700,17,9.68,100,1,10.61,200,2,11.27,100,1,11.4,100,1,11.76,100,1,11.93,200,2,12.23,100,1,12.34,200,2,12.37,700,1,13.84,100,1,13.85,100,1,14.02,2,1,14.12,100,1,14.56,800,2,14.6,700,1,14.61,100,1,14.65,100,1,14.68,700,1,14.72,200,2,ARL,286704785
2025-07-17T15:33:06.455979270Z,2025-07-17T15:33:06.455814002Z,160,2,1108,C,A,13.840000000,100,0,286680685,130,165268,240936407,ARL,0,13.84,100,130,165268,240936407,9.55,1700,17,9.68,100,1,10.61,200,2,11.27,100,1,11.4,100,1,11.76,100,1,11.93,200,2,12.23,100,1,12.34,200,2,12.37,700,1,13.85,100,1,14.02,2,1,14.12,100,1,14.56,800,2,14.6,700,1,14.61,100,1,14.65,100,1,14.68,700,1,14.72,200,2,14.81,200,2,ARL,286680685
2025-07-17T15:33:10.468005342Z,2025-07-17T15:33:10.467840054Z,160,2,1108,A,A,13.870000000,100,0,286828253,130,165288,241000095,ARL,0,13.87,100,130,165288,241000095,9.55,1700,17,9.68,100,1,10.61,200,2,11.27,100,1,11.4,100,1,11.76,100,1,11.93,200,2,12.23,100,1,12.34,200,2,12.37,700,1,13.85,100,1,13.87,100,1,14.02,2,1,14.12,100,1,14.56,800,2,14.6,700,1,14.61,100,1,14.65,100,1,14.68,700,1,14.72,200,2,ARL,286828253
2025-07-17T15:33:40.986585803Z,2025-07-17T15:33:40.986420127Z,160,2,1108,C,A,14.020000000,2,0,283348193,0,165676,241593788,ARL,0,14.02,2,0,165676,241593788,9.55,1700,17,9.68,100,1,10.61,200,2,11.27,100,1,11.4,100,1,11.76,100,1,11.93,200,2,12.23,100,1,12.34,200,2,12.37,700,1,13.85,100,1,13.87,100,1,14.12,100,1,14.56,800,2,14.6,700,1,14.61,100,1,14.65,100,1,14.68,700,1,14.72,200,2,14.81,200,2,ARL,283348193
2025-07-17T15:33:40.986585803Z,2025-07-17T15:33:40.986420127Z,160,2,1108,A,A,13.950000000,2,0,287540393,130,165676,241593788,ARL,0,13.95,2,130,165676,241593788,9.55,1700,17,9.68,100,1,10.61,200,2,11.27,100,1,11.4,100,1,11.76,100,1,11.93,200,2,12.23,100,1,12.34,200,2,12.37,700,1,13.85,100,1,13.87,100,1,13.95,2,1,14.12,100,1,14.56,800,2,14.6,700,1,14.61,100,1,14.65,100,1,14.68,700,1,14.72,200,2,ARL,287540393
2025-07-17T15:33:41.766184571Z,2025-07-17T15:33:41.766018916Z,160,2,1108,A,A,13.820000000,10,0,287560109,130,165655,241612289,ARL,0,13.82,10,130,165655,241612289,9.55,1700,17,9.68,100,1,10.61,200,2,11.27,100,1,11.4,100,1,11.76,100,1,11.93,200,2,12.23,100,1,12.34,200,2,12.37,700,1,13.82,10,1,13.85,100,1,13.87,100,1,13.95,2,1,14.12,100,1,14.56,800,2,14.6,700,1,14.61,100,1,14.65,100,1,14.68,700,1,ARL,287560109
2025-07-17T15:33:41.766265703Z,2025-07-17T15:33:41.766100204Z,160,2,1108,C,A,13.850000000,100,0,286704785,0,165499,241612294,ARL,0,13.85,100,0,165499,241612294,9.55,1700,17,9.68,100,1,10.61,200,2,11.27,100,1,11.4,100,1,11.76,100,1,11.93,200,2,12.23,100,1,12.34,200,2,12.37,700,1,13.82,10,1,13.87,100,1,13.95,2,1,14.12,100,1,14.56,800,2,14.6,700,1,14.61,100,1,14.65,100,1,14.68,700,1,14.72,200,2,ARL,286704785
2025-07-17T15:33:41.766265703Z,2025-07-17T15:33:41.766100204Z,160,2,1108,A,A,13.830000000,100,0,287560121,130,165499,241612294,ARL,0,13.83,100,130,165499,241612294,9.55,1700,17,9.68,100,1,10.61,200,2,11.27,100,1,11.4,100,1,11.76,100,1,11.93,200,2,12.23,100,1,12.34,200,2,12.37,700,1,13.82,10,1,13.83,100,1,13.87,100,1,13.95,2,1,14.12,100,1,14.56,800,2,14.6,700,1,14.61,100,1,14.65,100,1,14.68,700,1,ARL,287560121
2025-07-17T15:33:41.777404666Z,2025-07-17T15:33:41.777239400Z,160,2,1108,A,A,13.850000000,100,0,287560333,130,165266,241612426,ARL,0,13.85,100,130,165266,241612426,9.55,1700,17,9.68,100,1,10.61,200,2,11.27,100,1,11.4,100,1,11.76,100,1,11.93,200,2,12.23,100,1,12.34,200,2,12.37,700,1,13.82,10,1,13.83,100,1,13.85,100,1,13.87,100,1,13.95,2,1,14.12,100,1,14.56,800,2,14.6,700,1,14.61,100,1,14.65,100,1,ARL,287560333
2025-07-17T15:33:41.784121031Z,2025-07-17T15:33:41.783955668Z,160,2,1108,C,A,13.870000000,100,0,286828253,130,165363,241612450,ARL,0,13.87,100,130,165363,241612450,9.55,1700,17,9.68,100,1,10.61,200,2,11.27,100,1,11.4,100,1,11.76,100,1,11.93,200,2,12.23,100,1,12.34,200,2,12.37,700,1,13.82,10,1,13.83,100,1,13.85,100,1,13.95,2,1,14.12,100,1,14.56,800,2,14.6,700,1,14.61,100,1,14.65,100,1,14.68,700,1,ARL,286828253
2025-07-17T15:33:42.773141775Z,2025-07-17T15:33:42.772976862Z,160,2,1108,C,A,13.820000000,10,0,287560109,130,164913,241630390,ARL,0,13.82,10,130,164913,241630390,9.55,1700,17,9.68,100,1,10.61,200,2,11.27,100,1,11.4,100,1,11.76,100,1,11.93,200,2,12.23,100,1,12.34,200,2,12.37,700,1,13.83,100,1,13.85,100,1,13.95,2,1,14.12,100,1,14.56,800,2,14.6,700,1,14.61,100,1,14.65,100,1,14.68,700,1,14.72,200,2,ARL,287560109
2025-07-17T15:34:28.155773560Z,2025-07-17T15:34:28.155608087Z,160,2,1108,A,A,14.200000000,50,0,288723725,130,165473,242513312,ARL,0,14.2,50,130,165473,242513312,9.55,1700,17,9.68,100,1,10.61,200,2,11.27,100,1,11.4,100,1,11.76,100,1,11.93,200,2,12.23,100,1,12.34,200,2,12.37,700,1,13.83,100,1,13.85,100,1,13.95,2,1,14.12,100,1,14.2,50,1,14.56,800,2,14.6,700,1,14.61,100,1,14.65,100,1,14.68,700,1,ARL,288723725
2025-07-17T15:34:28.156815057Z,2025-07-17T15:34:28.156649544Z,160,2,1108,C,B,12.650000000,100,0,236206261,0,165513,242513329,ARL,0,12.65,100,0,165513,242513329,9.55,1700,17,9.68,100,1,10.61,200,2,11.27,100,1,11.4,100,1,11.76,100,1,11.93,200,2,12.23,100,1,12.34,200,2,12.37,700,1,13.83,100,1,13.85,100,1,13.95,2,1,14.12,100,1,14.2,50,1,14.56,800,2,14.6,700,1,14.61,100,1,14.65,100,1,14.68,700,1,ARL,236206261
2025-07-17T15:34:28.156815057Z,2025-07-17T15:34:28.156649544Z,160,2,1108,A,B,12.360000000,100,0,288723813,130,165513,242513329,ARL,0,12.36,100,130,165513,242513329,9.55,1700,17,9.68,100,1,10.61,200,2,11.27,100,1,11.4,100,1,11.76,100,1,11.93,200,2,12.23,100,1,12.34,200,2,12.36,100,1,13.83,100,1,13.85,100,1,13.95,2,1,14.12,100,1,14.2,50,1,14.56,800,2,14.6,700,1,14.61,100,1,14.65,100,1,14.68,700,1,ARL,288723813
2025-07-17T15:34:28.156884900Z,2025-07-17T15:34:28.156719339Z,160,2,1108,C,B,12.650000000,100,0,236179089,0,165561,242513330,ARL,0,12.65,100,0,165561,242513330,9.55,1700,17,9.68,100,1,10.61,200,2,11.27,100,1,11.4,100,1,11.76,100,1,11.93,200,2,12.23,100,1,12.34,200,2,12.36,100,1,13.83,100,1,13.85,100,1,13.95,2,1,14.12,100,1,14.2,50,1,14.56,800,2,14.6,700,1,14.61,100,1,14.65,100,1,14.68,700,1,ARL,236179089
2025-07-17T15:34:28.156884900Z,2025-07-17T15:34:28.156719339Z,160,2,1108,A,B,12.360000000,100,0,288723817,130,165561,242513330,ARL,0,12.36,100,130,165561,242513330,9.55,1700,17,9.68,100,1,10.61,200,2,11.27,100,1,11.4,100,1,11.76,100,1,11.93,200,2,12.23,100,1,12.34,200,2,12.36,200,2,13.83,100,1,13.85,100,1,13.95,2,1,14.12,100,1,14.2,50,1,14.56,800,2,14.6,700,1,14.61,100,1,14.65,100,1,14.68,700,1,ARL,288723817
2025-07-17T15:34:28.164796058Z,2025-07-17T15:34:28.164629965Z,160,2,1108,T,N,13.410000000,43,0,0,130,166093,242513452,ARL,0,13.41,43,130,166093,242513452,9.55,1700,17,9.68,100,1,10.61,200,2,11.27,100,1,11.4,100,1,11.76,100,1,11.93,200,2,12.23,100,1,12.34,200,2,12.36,200,2,13.83,100,1,13.85,100,1,13.95,2,1,14.12,100,1,14.2,50,1,14.56,800,2,14.6,700,1,14.61,100,1,14.65,100,1,14.68,700,1,ARL,0
2025-07-17T15:34:28.165386986Z,2025-07-17T15:34:28.165221345Z,160,2,1108,T,N,13.410000000,100,0,0,130,165641,242513454,ARL,0,13.41,100,130,165641,242513454,9.55,1700,17,9.68,100,1,10.61,200,2,11.27,100,1,11.4,100,1,11.76,100,1,11.93,200,2,12.23,100,1,12.34,200,2,12.36,200,2,13.83,100,1,13.85,100,1,13.95,2,1,14.12,100,1,14.2,50,1,14.56,800,2,14.6,700,1,14.61,100,1,14.65,100,1,14.68,700,1,ARL,0
2025-07-17T15:34:28.166683461Z,2025-07-17T15:34:28.166516235Z,160,2,1108,T,N,13.410000000,56,0,0,0,167226,242513557,ARL,0,13.41,56,0,167226,242513557,9.55,1700,17,9.68,100,1,10.61,200,2,11.27,100,1,11.4,100,1,11.76,100,1,11.93,200,2,12.23,100,1,12.34,200,2,12.36,200,2,13.83,100,1,13.85,100,1,13.95,2,1,14.12,100,1,14.2,50,1,14.56,800,2,14.6,700,1,14.61,100,1,14.65,100,1,14.68,700,1,ARL,0
2025-07-17T15:34:28.166683461Z,2025-07-17T15:34:28.166516235Z,160,2,1108,T,N,13.410000000,28,0,0,130,167226,242513558,ARL,0,13.41,28,130,167226,242513558,9.55,1700,17,9.68,100,1,10.61,200,2,11.27,100,1,11.4,100,1,11.76,100,1,11.93,200,2,12.23,100,1,12.34,200,2,12.36,200,2,13.83,100,1,13.85,100,1,13.95,2,1,14.12,100,1,14.2,50,1,14.56,800,2,14.6,700,1,14.61,100,1,14.65,100,1,14.68,700,1,ARL,0
2025-07-17T15:34:28.170740864Z,2025-07-17T15:34:28.170575785Z,160,2,1108,A,A,13.810000000,50,0,288724173,130,165079,242513651,ARL,0,13.81,50,130,165079,242513651,9.55,1700,17,9.68,100,1,10.61,200,2,11.27,100,1,11.4,100,1,11.76,100,1,11.93,200,2,12.23,100,1,12.34,200,2,12.36,200,2,13.81,50,1,13.83,100,1,13.85,100,1,13.95,2,1,14.12,100,1,14.2,50,1,14.56,800,2,14.6,700,1,14.61,100,1,14.65,100,1,ARL,288724173
2025-07-17T15:34:28.170792211Z,2025-07-17T15:34:28.170626756Z,160,2,1108,C,B,13.260000000,100,0,285586221,130,165455,242513653,ARL,0,13.26,100,130,165455,242513653,9.55,1700,17,9.68,100,1,10.61,200,2,11.27,100,1,11.4,100,1,11.76,100,1,11.93,200,2,12.23,100,1,12.34,200,2,12.36,200,2,13.81,50,1,13.83,100,1,13.85,100,1,13.95,2,1,14.12,100,1,14.2,50,1,14.56,800,2,14.6,700,1,14.61,100,1,14.65,100,1,ARL,285586221
2025-07-17T15:34:28.171437442Z,2025-07-17T15:34:28.171272157Z,160,2,1108,A,A,13.780000000,2,0,288724201,130,165285,242513665,ARL,0,13.78,2,130,165285,242513665,9.55,1700,17,9.68,100,1,10.61,200,2,11.27,100,1,11.4,100,1,11.76,100,1,11.93,200,2,12.23,100,1,12.34,200,2,12.36,200,2,13.78,2,1,13.81,50,1,13.83,100,1,13.85,100,1,13.95,2,1,14.12,100,1,14.2,50,1,14.56,800,2,14.6,700,1,14.61,100,1,ARL,288724201
2025-07-17T15:34:28.171604993Z,2025-07-17T15:34:28.171439252Z,160,2,1108,T,N,13.410000000,13,0,0,130,165741,242513674,ARL,0,13.41,13,130,165741,242513674,9.55,1700,17,9.68,100,1,10.61,200,2,11.27,100,1,11.4,100,1,11.76,100,1,11.93,200,2,12.23,100,1,12.34,200,2,12.36,200,2,13.78,2,1,13.81,50,1,13.83,100,1,13.85,100,1,13.95,2,1,14.12,100,1,14.2,50,1,14.56,800,2,14.6,700,1,14.61,100,1,ARL,0
2025-07-17T15:34:28.172057926Z,2025-07-17T15:34:28.171892519Z,160,2,1108,A,B,13.310000000,10,0,288724225,130,165407,242513691,ARL,0,13.31,10,130,165407,242513691,9.55,1700,17,9.68,100,1,10.61,200,2,11.27,100,1,11.4,100,1,11.76,100,1,11.93,200,2,12.23,100,1,12.34,200,2,12.36,200,2,13.78,2,1,13.81,50,1,13.83,100,1,13.85,100,1,13.95,2,1,14.12,100,1,14.2,50,1,14.56,800,2,14.6,700,1,14.61,100,1,ARL,288724225
2025-07-17T15:34:28.172058708Z,2025-07-17T15:34:28.171893498Z,160,2,1108,A,A,13.820000000,10,0,288724229,130,165210,242513692,ARL,0,13.82,10,130,165210,242513692,9.55,1700,17,9.68,100,1,10.61,200,2,11.27,100,1,11.4,100,1,11.76,100,1,11.93,200,2,12.23,100,1,12.34,200,2,12.36,200,2,13.78,2,1,13.81,50,1,13.82,10,1,13.83,100,1,13.85,100,1,13.95,2,1,14.12,100,1,14.2,50,1,14.56,800,2,14.6,700,1,ARL,288724229
2025-07-17T15:34:28.175011712Z,2025-07-17T15:34:28.174846475Z,160,2,1108,A,B,13.300000000,100,0,288724429,130,165237,242513742,ARL,0,13.3,100,130,165237,242513742,9.55,1700,17,9.68,100,1,10.61,200,2,11.27,100,1,11.4,100,1,11.76,100,1,11.93,200,2,12.23,100,1,12.34,200,2,12.36,200,2,13.78,2,1,13.81,50,1,13.82,10,1,13.83,100,1,13.85,100,1,13.95,2,1,14.12,100,1,14.2,50,1,14.56,800,2,14.6,700,1,ARL,288724429
2025-07-17T15:34:28.175030125Z,2025-07-17T15:34:28.174864618Z,160,2,1108,C,A,13.830000000,100,0,287560121,0,165507,242513743,ARL,0,13.83,100,0,165507,242513743,9.55,1700,17,9.68,100,1,10.61,200,2,11.27,100,1,11.4,100,1,11.76,100,1,11.93,200,2,12.23,100,1,12.34,200,2,12.36,200,2,13.78,2,1,13.81,50,1,13.82,10,1,13.85,100,1,13.95,2,1,14.12,100,1,14.2,50,1,14.56,800,2,14.6,700,1,14.61,100,1,ARL,287560121
2025-07-17T15:34:28.175030125Z,2025-07-17T15:34:28.174864618Z,160,2,1108,A,A,13.790000000,100,0,288724433,130,165507,242513743,ARL,0,13.79,100,130,165507,242513743,9.55,1700,17,9.68,100,1,10.61,200,2,11.27,100,1,11.4,100,1,11.76,100,1,11.93,200,2,12.23,100,1,12.34,200,2,12.36,200,2,13.78,2,1,13.79,100,1,13.81,50,1,13.82,10,1,13.85,100,1,13.95,2,1,14.12,100,1,14.2,50,1,14.56,800,2,14.6,700,1,ARL,288724433
2025-07-17T15:34:28.175329569Z,2025-07-17T15:34:28.175164464Z,160,2,1108,C,A,13.780000000,2,0,288724201,130,165105,242513747,ARL,0,13.78,2,130,165105,242513747,9.55,1700,17,9.68,100,1,10.61,200,2,11.27,100,1,11.4,100,1,11.76,100,1,11.93,200,2,12.23,100,1,12.34,200,2,12.36,200,2,13.79,100,1,13.81,50,1,13.82,10,1,13.85,100,1,13.95,2,1,14.12,100,1,14.2,50,1,14.56,800,2,14.6,700,1,14.61,100,1,ARL,288724201
2025-07-17T15:34:28.175752130Z,2025-07-17T15:34:28.175586497Z,160,2,1108,C,B,12.230000000,100,0,286680693,0,165633,242513748,ARL,0,12.23,100,0,165633,242513748,9.55,1700,17,9.68,100,1,10.61,200,2,11.27,100,1,11.4,100,1,11.76,100,1,11.93,200,2,12.34,200,2,12.36,200,2,12.37,700,1,13.79,100,1,13.81,50,1,13.82,10,1,13.85,100,1,13.95,2,1,14.12,100,1,14.2,50,1,14.56,800,2,14.6,700,1,14.61,100,1,ARL,286680693
2025-07-17T15:34:28.175752130Z,2025-07-17T15:34:28.175586497Z,160,2,1108,A,B,12.270000000,100,0,288724485,130,165633,242513748,ARL,0,12.27,100,130,165633,242513748,9.55,1700,17,9.68,100,1,10.61,200,2,11.27,100,1,11.4,100,1,11.76,100,1,11.93,200,2,12.27,100,1,12.34,200,2,12.36,200,2,13.79,100,1,13.81,50,1,13.82,10,1,13.85,100,1,13.95,2,1,14.12,100,1,14.2,50,1,14.56,800,2,14.6,700,1,14.61,100,1,ARL,288724485
2025-07-17T15:34:28.175767666Z,2025-07-17T15:34:28.175602100Z,160,2,1108,C,A,14.910000000,100,0,286680721,0,165566,242513749,ARL,0,14.91,100,0,165566,242513749,9.55,1700,17,9.68,100,1,10.61,200,2,11.27,100,1,11.4,100,1,11.76,100,1,11.93,200,2,12.27,100,1,12.34,200,2,12.36,200,2,13.79,100,1,13.81,50,1,13.82,10,1,13.85,100,1,13.95,2,1,14.12,100,1,14.2,50,1,14.56,800,2,14.6,700,1,14.61,100,1,ARL,286680721
2025-07-17T15:34:28.175767666Z,2025-07-17T15:34:28.175602100Z,160,2,1108,A,A,14.860000000,100,0,288724489,130,165566,242513749,ARL,0,14.86,100,130,165566,242513749,9.55,1700,17,9.68,100,1,10.61,200,2,11.27,100,1,11.4,100,1,11.76,100,1,11.93,200,2,12.27,100,1,12.34,200,2,12.36,200,2,13.79,100,1,13.81,50,1,13.82,10,1,13.85,100,1,13.95,2,1,14.12,100,1,14.2,50,1,14.56,800,2,14.6,700,1,14.61,100,1,ARL,288724489
2025-07-17T15:34:28.180356536Z,2025-07-17T15:34:28.180191067Z,160,2,1108,A,A,13.800000000,100,0,288724565,130,165469,242513781,ARL,0,13.8,100,130,165469,242513781,9.55,1700,17,9.68,100,1,10.61,200,2,11.27,100,1,11.4,100,1,11.76,100,1,11.93,200,2,12.27,100,1,12.34,200,2,12.36,200,2,13.79,100,1,13.8,100,1,13.81,50,1,13.82,10,1,13.85,100,1,13.95,2,1,14.12,100,1,14.2,50,1,14.56,800,2,14.6,700,1,ARL,288724565
2025-07-17T15:34:28.187237384Z,2025-07-17T15:34:28.187072050Z,160,2,1108,C,A,13.850000000,100,0,287560333,130,165334,242513907,ARL,0,13.85,100,130,165334,242513907,9.55,1700,17,9.68,100,1,10.61,200,2,11.27,100,1,11.4,100,1,11.76,100,1,11.93,200,2,12.27,100,1,12.34,200,2,12.36,200,2,13.79,100,1,13.8,100,1,13.81,50,1,13.82,10,1,13.95,2,1,14.12,100,1,14.2,50,1,14.56,800,2,14.6,700,1,14.61,100,1,ARL,287560333
2025-07-17T15:34:28.192269421Z,2025-07-17T15:34:28.192104387Z,160,2,1108,C,A,13.790000000,100,0,288724433,130,165034,242513974,ARL,0,13.79,100,130,165034,242513974,9.55,1700,17,9.68,100,1,10.61,200,2,11.27,100,1,11.4,100,1,11.76,100,1,11.93,200,2,12.27,100,1,12.34,200,2,12.36,200,2,13.8,100,1,13.81,50,1,13.82,10,1,13.95,2,1,14.12,100,1,14.2,50,1,14.56,800,2,14.6,700,1,14.61,100,1,14.65,100,1,ARL,288724433
2025-07-17T15:34:28.231601320Z,2025-07-17T15:34:28.231436134Z,160,2,1108,A,A,13.830000000,100,0,288725173,130,165186,242514372,ARL,0,13.83,100,130,165186,242514372,9.55,1700,17,9.68,100,1,10.61,200,2,11.27,100,1,11.4,100,1,11.76,100,1,11.93,200,2,12.27,100,1,12.34,200,2,12.36,200,2,13.8,100,1,13.81,50,1,13.82,10,1,13.83,100,1,13.95,2,1,14.12,100,1,14.2,50,1,14.56,800,2,14.6,700,1,14.61,100,1,ARL,288725173
2025-07-17T15:34:28.256123809Z,2025-07-17T15:34:28.255958718Z,160,2,1108,C,A,14.200000000,50,0,288723725,130,165091,242514761,ARL,0,14.2,50,130,165091,242514761,9.55,1700,17,9.68,100,1,10.61,200,2,11.27,100,1,11.4,100,1,11.76,100,1,11.93,200,2,12.27,100,1,12.34,200,2,12.36,200,2,13.8,100,1,13.81,50,1,13.82,10,1,13.83,100,1,13.95,2,1,14.12,100,1,14.56,800,2,14.6,700,1,14.61,100,1,14.65,100,1,ARL,288723725
2025-07-17T15:34:28.271275449Z,2025-07-17T15:34:28.271110273Z,160,2,1108,C,A,13.810000000,50,0,288724173,130,165176,242515164,ARL,0,13.81,50,130,165176,242515164,9.55,1700,17,9.68,100,1,10.61,200,2,11.27,100,1,11.4,100,1,11.76,100,1,11.93,200,2,12.27,100,1,12.34,200,2,12.36,200,2,13.8,100,1,13.82,10,1,13.83,100,1,13.95,2,1,14.12,100,1,14.56,800,2,14.6,700,1,14.61,100,1,14.65,100,1,14.68,700,1,ARL,288724173
2025-07-17T15:34:28.281217370Z,2025-07-17T15:34:28.281052249Z,160,2,1108,C,A,13.800000000,100,0,288724565,130,165121,242515254,ARL,0,13.8,100,130,165121,242515254,9.55,1700,17,9.68,100,1,10.61,200,2,11.27,100,1,11.4,100,1,11.76,100,1,11.93,200,2,12.27,100,1,12.34,200,2,12.36,200,2,13.82,10,1,13.83,100,1,13.95,2,1,14.12,100,1,14.56,800,2,14.6,700,1,14.61,100,1,14.65,100,1,14.68,700,1,14.72,200,2,ARL,288724565
2025-07-17T15:34:28.281945481Z,2025-07-17T15:34:28.281780230Z,160,2,1108,C,A,14.860000000,100,0,288724489,0,165251,242515263,ARL,0,14.86,100,0,165251,242515263,9.55,1700,17,9.68,100,1,10.61,200,2,11.27,100,1,11.4,100,1,11.76,100,1,11.93,200,2,12.27,100,1,12.34,200,2,12.36,200,2,13.82,10,1,13.83,100,1,13.95,2,1,14.12,100,1,14.56,800,2,14.6,700,1,14.61,100,1,14.65,100,1,14.68,700,1,14.72,200,2,ARL,288724489
2025-07-17T15:34:28.281945481Z,2025-07-17T15:34:28.281780230Z,160,2,1108,A,A,14.900000000,100,0,288726085,130,165251,242515263,ARL,0,14.9,100,130,165251,242515263,9.55,1700,17,9.68,100,1,10.61,200,2,11.27,100,1,11.4,100,1,11.76,100,1,11.93,200,2,12.27,100,1,12.34,200,2,12.36,200,2,13.82,10,1,13.83,100,1,13.95,2,1,14.12,100,1,14.56,800,2,14.6,700,1,14.61,100,1,14.65,100,1,14.68,700,1,14.72,200,2,ARL,288726085
2025-07-17T15:34:32.289409612Z,2025-07-17T15:34:32.289244370Z,160,2,1108,A,A,13.840000000,100,0,288845417,130,165242,242598225,ARL,0,13.84,100,130,165242,242598225,9.55,1700,17,9.68,100,1,10.61,200,2,11.27,100,1,11.4,100,1,11.76,100,1,11.93,200,2,12.27,100,1,12.34,200,2,12.36,200,2,13.82,10,1,13.83,100,1,13.84,100,1,13.95,2,1,14.12,100,1,14.56,800,2,14.6,700,1,14.61,100,1,14.65,100,1,14.68,700,1,ARL,288845417
2025-07-17T15:34:39.864692027Z,2025-07-17T15:34:39.864526516Z,160,2,1108,A,A,13.800000000,15,0,289055901,130,165511,242774235,ARL,0,13.8,15,130,165511,242774235,9.55,1700,17,9.68,100,1,10.61,200,2,11.27,100,1,11.4,100,1,11.76,100,1,11.93,200,2,12.27,100,1,12.34,200,2,12.36,200,2,13.8,15,1,13.82,10,1,13.83,100,1,13.84,100,1,13.95,2,1,14.12,100,1,14.56,800,2,14.6,700,1,14.61,100,1,14.65,100,1,ARL,289055901
2025-07-17T15:34:39.865337932Z,2025-07-17T15:34:39.865171719Z,160,2,1108,C,A,13.830000000,100,0,288725173,0,166213,242774299,ARL,0,13.83,100,0,166213,242774299,9.55,1700,17,9.68,100,1,10.61,200,2,11.27,100,1,11.4,100,1,11.76,100,1,11.93,200,2,12.27,100,1,12.34,200,2,12.36,200,2,13.8,15,1,13.82,10,1,13.84,100,1,13.95,2,1,14.12,100,1,14.56,800,2,14.6,700,1,14.61,100,1,14.65,100,1,14.68,700,1,ARL,288725173
2025-07-17T15:34:39.865337932Z,2025-07-17T15:34:39.865171719Z,160,2,1108,A,A,13.810000000,100,0,289056097,130,166213,242774299,ARL,0,13.81,100,130,166213,242774299,9.55,1700,17,9.68,100,1,10.61,200,2,11.27,100,1,11.4,100,1,11.76,100,1,11.93,200,2,12.27,100,1,12.34,200,2,12.36,200,2,13.8,15,1,13.81,100,1,13.82,10,1,13.84,100,1,13.95,2,1,14.12,100,1,14.56,800,2,14.6,700,1,14.61,100,1,14.65,100,1,ARL,289056097
2025-07-17T15:34:39.869175972Z,2025-07-17T15:34:39.869009668Z,160,2,1108,T,N,13.410000000,1,0,0,130,166304,242774413,ARL,0,13.41,1,130,166304,242774413,9.55,1700,17,9.68,100,1,10.61,200,2,11.27,100,1,11.4,100,1,11.76,100,1,11.93,200,2,12.27,100,1,12.34,200,2,12.36,200,2,13.8,15,1,13.81,100,1,13.82,10,1,13.84,100,1,13.95,2,1,14.12,100,1,14.56,800,2,14.6,700,1,14.61,100,1,14.65,100,1,ARL,0
2025-07-17T15:34:39.871606986Z,2025-07-17T15:34:39.871441822Z,160,2,1108,A,A,13.810000000,100,0,289056353,130,165164,242774468,ARL,0,13.81,100,130,165164,242774468,9.55,1700,17,9.68,100,1,10.61,200,2,11.27,100,1,11.4,100,1,11.76,100,1,11.93,200,2,12.27,100,1,12.34,200,2,12.36,200,2,13.8,15,1,13.81,200,2,13.82,10,1,13.84,100,1,13.95,2,1,14.12,100,1,14.56,800,2,14.6,700,1,14.61,100,1,14.65,100,1,ARL,289056353
2025-07-17T15:34:39.878645012Z,2025-07-17T15:34:39.878479562Z,160,2,1108,C,A,13.840000000,100,0,288845417,130,165450,242774619,ARL,0,13.84,100,130,165450,242774619,9.55,1700,17,9.68,100,1,10.61,200,2,11.27,100,1,11.4,100,1,11.76,100,1,11.93,200,2,12.27,100,1,12.34,200,2,12.36,200,2,13.8,15,1,13.81,200,2,13.82,10,1,13.95,2,1,14.12,100,1,14.56,800,2,14.6,700,1,14.61,100,1,14.65,100,1,14.68,700,1,ARL,288845417
2025-07-17T15:34:42.774190041Z,2025-07-17T15:34:42.774024574Z,160,2,1108,C,B,13.310000000,10,0,288724225,130,165467,242816556,ARL,0,13.31,10,130,165467,242816556,9.55,1700,17,9.68,100,1,10.61,200,2,11.27,100,1,11.4,100,1,11.76,100,1,11.93,200,2,12.27,100,1,12.34,200,2,12.36,200,2,13.8,15,1,13.81,200,2,13.82,10,1,13.95,2,1,14.12,100,1,14.56,800,2,14.6,700,1,14.61,100,1,14.65,100,1,14.68,700,1,ARL,288724225
2025-07-17T15:34:42.775304741Z,2025-07-17T15:34:42.775139521Z,160,2,1108,C,A,13.810000000,100,0,289056353,130,165220,242816563,ARL,0,13.81,100,130,165220,242816563,9.55,1700,17,9.68,100,1,10.61,200,2,11.27,100,1,11.4,100,1,11.76,100,1,11.93,200,2,12.27,100,1,12.34,200,2,12.36,200,2,13.8,15,1,13.81,100,1,13.82,10,1,13.95,2,1,14.12,100,1,14.56,800,2,14.6,700,1,14.61,100,1,14.65,100,1,14.68,700,1,ARL,289056353
2025-07-17T15:34:46.774087945Z,2025-07-17T15:34:46.773922586Z,160,2,1108,C,A,13.800000000,15,0,289055901,130,165359,242893860,ARL,0,13.8,15,130,165359,242893860,9.55,1700,17,9.68,100,1,10.61,200,2,11.27,100,1,11.4,100,1,11.76,100,1,11.93,200,2,12.27,100,1,12.34,200,2,12.36,200,2,13.81,100,1,13.82,10,1,13.95,2,1,14.12,100,1,14.56,800,2,14.6,700,1,14.61,100,1,14.65,100,1,14.68,700,1,14.72,200,2,ARL,289055901
2025-07-17T15:34:46.800955057Z,2025-07-17T15:34:46.800789632Z,160,2,1108,A,A,13.830000000,100,0,289199221,130,165425,242894153,ARL,0,13.83,100,130,165425,242894153,9.55,1700,17,9.68,100,1,10.61,200,2,11.27,100,1,11.4,100,1,11.76,100,1,11.93,200,2,12.27,100,1,12.34,200,2,12.36,200,2,13.81,100,1,13.82,10,1,13.83,100,1,13.95,2,1,14.12,100,1,14.56,800,2,14.6,700,1,14.61,100,1,14.65,100,1,14.68,700,1,ARL,289199221
2025-07-17T15:34:53.545830704Z,2025-07-17T15:34:53.545665068Z,160,2,1108,C,A,13.820000000,10,0,288724229,130,165636,243011340,ARL,0,13.82,10,130,165636,243011340,9.55,1700,17,9.68,100,1,10.61,200,2,11.27,100,1,11.4,100,1,11.76,100,1,11.93,200,2,12.27,100,1,12.34,200,2,12.36,200,2,13.81,100,1,13.83,100,1,13.95,2,1,14.12,100,1,14.56,800,2,14.6,700,1,14.61,100,1,14.65,100,1,14.68,700,1,14.72,200,2,ARL,288724229
2025-07-17T15:35:05.620763928Z,2025-07-17T15:35:05.620598378Z,160,2,1108,A,A,13.770000000,15,0,289722397,130,165550,243344672,ARL,0,13.77,15,130,165550,243344672,9.55,1700,17,9.68,100,1,10.61,200,2,11.27,100,1,11.4,100,1,11.76,100,1,11.93,200,2,12.27,100,1,12.34,200,2,12.36,200,2,13.77,15,1,13.81,100,1,13.83,100,1,13.95,2,1,14.12,100,1,14.56,800,2,14.6,700,1,14.61,100,1,14.65,100,1,14.68,700,1,ARL,289722397
2025-07-17T15:35:05.712575243Z,2025-07-17T15:35:05.712409728Z,160,2,1108,C,A,13.810000000,100,0,289056097,0,165515,243347940,ARL,0,13.81,100,0,165515,243347940,9.55,1700,17,9.68,100,1,10.61,200,2,11.27,100,1,11.4,100,1,11.76,100,1,11.93,200,2,12.27,100,1,12.34,200,2,12.36,200,2,13.77,15,1,13.83,100,1,13.95,2,1,14.12,100,1,14.56,800,2,14.6,700,1,14.61,100,1,14.65,100,1,14.68,700,1,14.72,200,2,ARL,289056097
2025-07-17T15:35:05.712575243Z,2025-07-17T15:35:05.712409728Z,160,2,1108,A,A,13.780000000,100,0,289726281,130,165515,243347940,ARL,0,13.78,100,130,165515,243347940,9.55,1700,17,9.68,100,1,10.61,200,2,11.27,100,1,11.4,100,1,11.76,100,1,11.93,200,2,12.27,100,1,12.34,200,2,12.36,200,2,13.77,15,1,13.78,100,1,13.83,100,1,13.95,2,1,14.12,100,1,14.56,800,2,14.6,700,1,14.61,100,1,14.65,100,1,14.68,700,1,ARL,289726281
2025-07-17T15:35:05.713315450Z,2025-07-17T15:35:05.713150123Z,160,2,1108,C,A,14.610000000,100,0,237978629,130,165327,243347987,ARL,0,14.61,100,130,165327,243347987,9.55,1700,17,9.68,100,1,10.61,200,2,11.27,100,1,11.4,100,1,11.76,100,1,11.93,200,2,12.27,100,1,12.34,200,2,12.36,200,2,13.77,15,1,13.78,100,1,13.83,100,1,13.95,2,1,14.12,100,1,14.56,800,2,14.6,700,1,14.65,100,1,14.68,700,1,14.72,200,2,ARL,237978629
2025-07-17T15:35:05.713322577Z,2025-07-17T15:35:05.713157077Z,160,2,1108,C,A,14.900000000,100,0,288726085,0,165500,243347988,ARL,0,14.9,100,0,165500,243347988,9.55,1700,17,9.68,100,1,10.61,200,2,11.27,100,1,11.4,100,1,11.76,100,1,11.93,200,2,12.27,100,1,12.34,200,2,12.36,200,2,13.77,15,1,13.78,100,1,13.83,100,1,13.95,2,1,14.12,100,1,14.56,800,2,14.6,700,1,14.65,100,1,14.68,700,1,14.72,200,2,ARL,288726085
2025-07-17T15:35:05.713322577Z,2025-07-17T15:35:05.713157077Z,160,2,1108,A,A,14.850000000,100,0,289726349,130,165500,243347988,ARL,0,14.85,100,130,165500,243347988,9.55,1700,17,9.68,100,1,10.61,200,2,11.27,100,1,11.4,100,1,11.76,100,1,11.93,200,2,12.27,100,1,12.34,200,2,12.36,200,2,13.77,15,1,13.78,100,1,13.83,100,1,13.95,2,1,14.12,100,1,14.56,800,2,14.6,700,1,14.65,100,1,14.68,700,1,14.72,200,2,ARL,289726349
2025-07-17T15:35:05.713677091Z,2025-07-17T15:35:05.713508657Z,160,2,1108,A,A,14.400000000,100,0,289726421,128,168434,243348032,ARL,0,14.4,100,128,168434,243348032,9.55,1700,17,9.68,100,1,10.61,200,2,11.27,100,1,11.4,100,1,11.76,100,1,11.93,200,2,12.27,100,1,12.34,200,2,12.36,200,2,13.77,15,1,13.78,100,1,13.83,100,1,13.95,2,1,14.12,100,1,14.4,100,1,14.56,800,2,14.6,700,1,14.65,100,1,14.68,700,1,ARL,289726421
2025-07-17T15:35:05.729568877Z,2025-07-17T15:35:05.729398505Z,160,2,1108,A,A,13.800000000,100,0,289730309,128,170372,243351264,ARL,0,13.8,100,128,170372,243351264,9.55,1700,17,9.68,100,1,10.61,200,2,11.27,100,1,11.4,100,1,11.76,100,1,11.93,200,2,12.27,100,1,12.34,200,2,12.36,200,2,13.77,15,1,13.78,100,1,13.8,100,1,13.83,100,1,13.95,2,1,14.12,100,1,14.4,100,1,14.56,800,2,14.6,700,1,14.65,100,1,ARL,289730309
2025-07-17T15:35:05.737967956Z,2025-07-17T15:35:05.737802616Z,160,2,1108,C,A,13.830000000,100,0,289199221,130,165340,243352644,ARL,0,13.83,100,130,165340,243352644,9.55,1700,17,9.68,100,1,10.61,200,2,11.27,100,1,11.4,100,1,11.76,100,1,11.93,200,2,12.27,100,1,12.34,200,2,12.36,200,2,13.77,15,1,13.78,100,1,13.8,100,1,13.95,2,1,14.12,100,1,14.4,100,1,14.56,800,2,14.6,700,1,14.65,100,1,14.68,700,1,ARL,289199221
2025-07-17T15:35:06.286572335Z,2025-07-17T15:35:06.286407017Z,160,2,1108,C,A,13.770000000,15,0,289722397,130,165318,243362628,ARL,0,13.77,15,130,165318,243362628,9.55,1700,17,9.68,100,1,10.61,200,2,11.27,100,1,11.4,100,1,11.76,100,1,11.93,200,2,12.27,100,1,12.34,200,2,12.36,200,2,13.78,100,1,13.8,100,1,13.95,2,1,14.12,100,1,14.4,100,1,14.56,800,2,14.6,700,1,14.65,100,1,14.68,700,1,14.72,200,2,ARL,289722397
2025-07-17T15:35:09.788280931Z,2025-07-17T15:35:09.788115219Z,160,2,1108,C,B,13.230000000,2,0,272263853,0,165712,243432828,ARL,0,13.23,2,0,165712,243432828,9.55,1700,17,9.68,100,1,10.61,200,2,11.27,100,1,11.4,100,1,11.76,100,1,11.93,200,2,12.27,100,1,12.34,200,2,12.36,200,2,13.78,100,1,13.8,100,1,13.95,2,1,14.12,100,1,14.4,100,1,14.56,800,2,14.6,700,1,14.65,100,1,14.68,700,1,14.72,200,2,ARL,272263853
2025-07-17T15:35:09.788280931Z,2025-07-17T15:35:09.788115219Z,160,2,1108,A,B,13.140000000,2,0,289828293,130,165712,243432828,ARL,0,13.14,2,130,165712,243432828,9.55,1700,17,9.68,100,1,10.61,200,2,11.27,100,1,11.4,100,1,11.76,100,1,11.93,200,2,12.27,100,1,12.34,200,2,12.36,200,2,13.78,100,1,13.8,100,1,13.95,2,1,14.12,100,1,14.4,100,1,14.56,800,2,14.6,700,1,14.65,100,1,14.68,700,1,14.72,200,2,ARL,289828293
2025-07-17T15:35:11.891867009Z,2025-07-17T15:35:11.891701845Z,160,2,1108,C,A,13.800000000,100,0,289730309,130,165164,243482295,ARL,0,13.8,100,130,165164,243482295,9.55,1700,17,9.68,100,1,10.61,200,2,11.27,100,1,11.4,100,1,11.76,100,1,11.93,200,2,12.27,100,1,12.34,200,2,12.36,200,2,13.78,100,1,13.95,2,1,14.12,100,1,14.4,100,1,14.56,800,2,14.6,700,1,14.65,100,1,14.68,700,1,14.72,200,2,14.81,200,2,ARL,289730309
2025-07-17T15:35:14.301647013Z,2025-07-17T15:35:14.301481698Z,160,2,1108,A,A,14.680000000,700,0,289932801,130,165315,243521615,ARL,0,14.68,700,130,165315,243521615,9.55,1700,17,9.68,100,1,10.61,200,2,11.27,100,1,11.4,100,1,11.76,100,1,11.93,200,2,12.27,100,1,12.34,200,2,12.36,200,2,13.78,100,1,13.95,2,1,14.12,100,1,14.4,100,1,14.56,800,2,14.6,700,1,14.65,100,1,14.68,1400,2,14.72,200,2,14.81,200,2,ARL,289932801
2025-07-17T15:35:14.302443648Z,2025-07-17T15:35:14.302278179Z,160,2,1108,C,A,14.910000000,700,0,147217629,130,165469,243521616,ARL,0,14.91,700,130,165469,243521616,9.55,1700,17,9.68,100,1,10.61,200,2,11.27,100,1,11.4,100,1,11.76,100,1,11.93,200,2,12.27,100,1,12.34,200,2,12.36,200,2,13.78,100,1,13.95,2,1,14.12,100,1,14.4,100,1,14.56,800,2,14.6,700,1,14.65,100,1,14.68,1400,2,14.72,200,2,14.81,200,2,ARL,147217629
2025-07-17T15:35:15.940644416Z,2025-07-17T15:35:15.940479233Z,160,2,1108,A,A,13.820000000,100,0,289976125,130,165183,243557058,ARL,0,13.82,100,130,165183,243557058,9.55,1700,17,9.68,100,1,10.61,200,2,11.27,100,1,11.4,100,1,11.76,100,1,11.93,200,2,12.27,100,1,12.34,200,2,12.36,200,2,13.78,100,1,13.82,100,1,13.95,2,1,14.12,100,1,14.4,100,1,14.56,800,2,14.6,700,1,14.65,100,1,14.68,1400,2,14.72,200,2,ARL,289976125
2025-07-17T15:35:23.746674314Z,2025-07-17T15:35:23.746509184Z,160,2,1108,A,A,13.800000000,100,0,290159301,130,165130,243692012,ARL,0,13.8,100,130,165130,243692012,9.55,1700,17,9.68,100,1,10.61,200,2,11.27,100,1,11.4,100,1,11.76,100,1,11.93,200,2,12.27,100,1,12.34,200,2,12.36,200,2,13.78,100,1,13.8,100,1,13.82,100,1,13.95,2,1,14.12,100,1,14.4,100,1,14.56,800,2,14.6,700,1,14.65,100,1,14.68,1400,2,ARL,290159301
2025-07-17T15:35:23.754618546Z,2025-07-17T15:35:23.754453294Z,160,2,1108,C,A,13.820000000,100,0,289976125,130,165252,243692501,ARL,0,13.82,100,130,165252,243692501,9.55,1700,17,9.68,100,1,10.61,200,2,11.27,100,1,11.4,100,1,11.76,100,1,11.93,200,2,12.27,100,1,12.34,200,2,12.36,200,2,13.78,100,1,13.8,100,1,13.95,2,1,14.12,100,1,14.4,100,1,14.56,800,2,14.6,700,1,14.65,100,1,14.68,1400,2,14.72,200,2,ARL,289976125
2025-07-17T15:35:39.056679600Z,2025-07-17T15:35:39.056513985Z,160,2,1108,C,A,13.800000000,100,0,290159301,130,165615,243992725,ARL,0,13.8,100,130,165615,243992725,9.55,1700,17,9.68,100,1,10.61,200,2,11.27,100,1,11.4,100,1,11.76,100,1,11.93,200,2,12.27,100,1,12.34,200,2,12.36,200,2,13.78,100,1,13.95,2,1,14.12,100,1,14.4,100,1,14.56,800,2,14.6,700,1,14.65,100,1,14.68,1400,2,14.72,200,2,14.81,200,2,ARL,290159301
2025-07-17T15:35:43.128809717Z,2025-07-17T15:35:43.128644252Z,160,2,1108,A,A,13.820000000,100,0,290630573,130,165465,244078096,ARL,0,13.82,100,130,165465,244078096,9.55,1700,17,9.68,100,1,10.61,200,2,11.27,100,1,11.4,100,1,11.76,100,1,11.93,200,2,12.27,100,1,12.34,200,2,12.36,200,2,13.78,100,1,13.82,100,1,13.95,2,1,14.12,100,1,14.4,100,1,14.56,800,2,14.6,700,1,14.65,100,1,14.68,1400,2,14.72,200,2,ARL,290630573
2025-07-17T15:36:30.044094509Z,2025-07-17T15:36:30.043928872Z,160,2,1108,A,A,13.800000000,100,0,291778909,130,165637,245013624,ARL,0,13.8,100,130,165637,245013624,9.55,1700,17,9.68,100,1,10.61,200,2,11.27,100,1,11.4,100,1,11.76,100,1,11.93,200,2,12.27,100,1,12.34,200,2,12.36,200,2,13.78,100,1,13.8,100,1,13.82,100,1,13.95,2,1,14.12,100,1,14.4,100,1,14.56,800,2,14.6,700,1,14.65,100,1,14.68,1400,2,ARL,291778909
2025-07-17T15:36:30.051045453Z,2025-07-17T15:36:30.050880126Z,160,2,1108,C,A,13.820000000,100,0,290630573,130,165327,245013914,ARL,0,13.82,100,130,165327,245013914,9.55,1700,17,9.68,100,1,10.61,200,2,11.27,100,1,11.4,100,1,11.76,100,1,11.93,200,2,12.27,100,1,12.34,200,2,12.36,200,2,13.78,100,1,13.8,100,1,13.95,2,1,14.12,100,1,14.4,100,1,14.56,800,2,14.6,700,1,14.65,100,1,14.68,1400,2,14.72,200,2,ARL,290630573
2025-07-17T15:36:34.298010005Z,2025-07-17T15:36:34.297844579Z,160,2,1108,C,B,13.300000000,100,0,288724429,130,165426,245144122,ARL,0,13.3,100,130,165426,245144122,9.55,1700,17,9.68,100,1,10.61,200,2,11.27,100,1,11.4,100,1,11.76,100,1,11.93,200,2,12.27,100,1,12.34,200,2,12.36,200,2,13.78,100,1,13.8,100,1,13.95,2,1,14.12,100,1,14.4,100,1,14.56,800,2,14.6,700,1,14.65,100,1,14.68,1400,2,14.72,200,2,ARL,288724429
2025-07-17T15:36:35.381330809Z,2025-07-17T15:36:35.381165559Z,160,2,1108,A,B,13.130000000,100,0,291951937,130,165250,245161447,ARL,0,13.13,100,130,165250,245161447,9.55,1700,17,9.68,100,1,10.61,200,2,11.27,100,1,11.4,100,1,11.76,100,1,11.93,200,2,12.27,100,1,12.34,200,2,12.36,200,2,13.78,100,1,13.8,100,1,13.95,2,1,14.12,100,1,14.4,100,1,14.56,800,2,14.6,700,1,14.65,100,1,14.68,1400,2,14.72,200,2,ARL,291951937
2025-07-17T15:36:35.532851032Z,2025-07-17T15:36:35.532685683Z,160,2,1108,A,B,13.270000000,10,0,291964737,130,165349,245174454,ARL,0,13.27,10,130,165349,245174454,9.55,1700,17,9.68,100,1,10.61,200,2,11.27,100,1,11.4,100,1,11.76,100,1,11.93,200,2,12.27,100,1,12.34,200,2,12.36,200,2,13.78,100,1,13.8,100,1,13.95,2,1,14.12,100,1,14.4,100,1,14.56,800,2,14.6,700,1,14.65,100,1,14.68,1400,2,14.72,200,2,ARL,291964737
2025-07-17T15:36:35.532926951Z,2025-07-17T15:36:35.532761335Z,160,2,1108,C,B,12.270000000,100,0,288724485,0,165616,245174461,ARL,0,12.27,100,0,165616,245174461,9.55,1700,17,9.68,100,1,10.61,200,2,11.27,100,1,11.4,100,1,11.76,100,1,11.93,200,2,12.34,200,2,12.36,200,2,12.37,700,1,13.78,100,1,13.8,100,1,13.95,2,1,14.12,100,1,14.4,100,1,14.56,800,2,14.6,700,1,14.65,100,1,14.68,1400,2,14.72,200,2,ARL,288724485
2025-07-17T15:36:35.532926951Z,2025-07-17T15:36:35.532761335Z,160,2,1108,A,B,12.230000000,100,0,291964745,130,165616,245174461,ARL,0,12.23,100,130,165616,245174461,9.55,1700,17,9.68,100,1,10.61,200,2,11.27,100,1,11.4,100,1,11.76,100,1,11.93,200,2,12.23,100,1,12.34,200,2,12.36,200,2,13.78,100,1,13.8,100,1,13.95,2,1,14.12,100,1,14.4,100,1,14.56,800,2,14.6,700,1,14.65,100,1,14.68,1400,2,14.72,200,2,ARL,291964745
2025-07-17T15:36:36.152132527Z,2025-07-17T15:36:36.151966883Z,160,2,1108,C,B,13.130000000,100,0,291951937,0,165644,245183955,ARL,0,13.13,100,0,165644,245183955,9.55,1700,17,9.68,100,1,10.61,200,2,11.27,100,1,11.4,100,1,11.76,100,1,11.93,200,2,12.23,100,1,12.34,200,2,12.36,200,2,13.78,100,1,13.8,100,1,13.95,2,1,14.12,100,1,14.4,100,1,14.56,800,2,14.6,700,1,14.65,100,1,14.68,1400,2,14.72,200,2,ARL,291951937
2025-07-17T15:36:36.152132527Z,2025-07-17T15:36:36.151966883Z,160,2,1108,A,B,13.260000000,100,0,291975017,130,165644,245183955,ARL,0,13.26,100,130,165644,245183955,9.55,1700,17,9.68,100,1,10.61,200,2,11.27,100,1,11.4,100,1,11.76,100,1,11.93,200,2,12.23,100,1,12.34,200,2,12.36,200,2,13.78,100,1,13.8,100,1,13.95,2,1,14.12,100,1,14.4,100,1,14.56,800,2,14.6,700,1,14.65,100,1,14.68,1400,2,14.72,200,2,ARL,291975017
2025-07-17T15:36:46.889917278Z,2025-07-17T15:36:46.889749756Z,160,2,1108,C,B,13.270000000,10,0,291964737,128,167522,245499598,ARL,0,13.27,10,128,167522,245499598,9.55,1700,17,9.68,100,1,10.61,200,2,11.27,100,1,11.4,100,1,11.76,100,1,11.93,200,2,12.23,100,1,12.34,200,2,12.36,200,2,13.78,100,1,13.8,100,1,13.95,2,1,14.12,100,1,14.4,100,1,14.56,800,2,14.6,700,1,14.65,100,1,14.68,1400,2,14.72,200,2,ARL,291964737
2025-07-17T15:36:46.986820391Z,2025-07-17T15:36:46.986655137Z,160,2,1108,C,A,13.800000000,100,0,291778909,130,165254,245503745,ARL,0,13.8,100,130,165254,245503745,9.55,1700,17,9.68,100,1,10.61,200,2,11.27,100,1,11.4,100,1,11.76,100,1,11.93,200,2,12.23,100,1,12.34,200,2,12.36,200,2,13.78,100,1,13.95,2,1,14.12,100,1,14.4,100,1,14.56,800,2,14.6,700,1,14.65,100,1,14.68,1400,2,14.72,200,2,14.81,200,2,ARL,291778909
2025-07-17T15:36:50.997434689Z,2025-07-17T15:36:50.997269299Z,160,2,1108,A,A,13.820000000,100,0,292434813,130,165390,245564901,ARL,0,13.82,100,130,165390,245564901,9.55,1700,17,9.68,100,1,10.61,200,2,11.27,100,1,11.4,100,1,11.76,100,1,11.93,200,2,12.23,100,1,12.34,200,2,12.36,200,2,13.78,100,1,13.82,100,1,13.95,2,1,14.12,100,1,14.4,100,1,14.56,800,2,14.6,700,1,14.65,100,1,14.68,1400,2,14.72,200,2,ARL,292434813
2025-07-17T15:37:40.389737573Z,2025-07-17T15:37:40.389572053Z,160,2,1108,C,B,13.140000000,2,0,289828293,0,165520,246491394,ARL,0,13.14,2,0,165520,246491394,9.55,1700,17,9.68,100,1,10.61,200,2,11.27,100,1,11.4,100,1,11.76,100,1,11.93,200,2,12.23,100,1,12.34,200,2,12.36,200,2,13.78,100,1,13.82,100,1,13.95,2,1,14.12,100,1,14.4,100,1,14.56,800,2,14.6,700,1,14.65,100,1,14.68,1400,2,14.72,200,2,ARL,289828293
2025-07-17T15:37:40.389737573Z,2025-07-17T15:37:40.389572053Z,160,2,1108,A,B,13.040000000,2,0,293594281,130,165520,246491394,ARL,0,13.04,2,130,165520,246491394,9.55,1700,17,9.68,100,1,10.61,200,2,11.27,100,1,11.4,100,1,11.76,100,1,11.93,200,2,12.23,100,1,12.34,200,2,12.36,200,2,13.78,100,1,13.82,100,1,13.95,2,1,14.12,100,1,14.4,100,1,14.56,800,2,14.6,700,1,14.65,100,1,14.68,1400,2,14.72,200,2,ARL,293594281
2025-07-17T15:39:27.070109669Z,2025-07-17T15:39:27.069942913Z,160,2,1108,A,A,13.800000000,100,0,296059685,128,166756,248436908,ARL,0,13.8,100,128,166756,248436908,9.55,1700,17,9.68,100,1,10.61,200,2,11.27,100,1,11.4,100,1,11.76,100,1,11.93,200,2,12.23,100,1,12.34,200,2,12.36,200,2,13.78,100,1,13.8,100,1,13.82,100,1,13.95,2,1,14.12,100,1,14.4,100,1,14.56,800,2,14.6,700,1,14.65,100,1,14.68,1400,2,ARL,296059685
2025-07-17T15:39:27.077565902Z,2025-07-17T15:39:27.077400388Z,160,2,1108,C,A,13.820000000,100,0,292434813,130,165514,248437548,ARL,0,13.82,100,130,165514,248437548,9.55,1700,17,9.68,100,1,10.61,200,2,11.27,100,1,11.4,100,1,11.76,100,1,11.93,200,2,12.23,100,1,12.34,200,2,12.36,200,2,13.78,100,1,13.8,100,1,13.95,2,1,14.12,100,1,14.4,100,1,14.56,800,2,14.6,700,1,14.65,100,1,14.68,1400,2,14.72,200,2,ARL,292434813
2025-07-17T15:39:30.509853083Z,2025-07-17T15:39:30.509687817Z,160,2,1108,A,A,13.760000000,15,0,296136617,130,165266,248491930,ARL,0,13.76,15,130,165266,248491930,9.55,1700,17,9.68,100,1,10.61,200,2,11.27,100,1,11.4,100,1,11.76,100,1,11.93,200,2,12.23,100,1,12.34,200,2,12.36,200,2,13.76,15,1,13.78,100,1,13.8,100,1,13.95,2,1,14.12,100,1,14.4,100,1,14.56,800,2,14.6,700,1,14.65,100,1,14.68,1400,2,ARL,296136617
2025-07-17T15:39:30.573217843Z,2025-07-17T15:39:30.573052284Z,160,2,1108,C,A,13.780000000,100,0,289726281,0,165559,248492793,ARL,0,13.78,100,0,165559,248492793,9.55,1700,17,9.68,100,1,10.61,200,2,11.27,100,1,11.4,100,1,11.76,100,1,11.93,200,2,12.23,100,1,12.34,200,2,12.36,200,2,13.76,15,1,13.8,100,1,13.95,2,1,14.12,100,1,14.4,100,1,14.56,800,2,14.6,700,1,14.65,100,1,14.68,1400,2,14.72,200,2,ARL,289726281
2025-07-17T15:39:30.573217843Z,2025-07-17T15:39:30.573052284Z,160,2,1108,A,A,13.770000000,100,0,296137537,130,165559,248492793,ARL,0,13.77,100,130,165559,248492793,9.55,1700,17,9.68,100,1,10.61,200,2,11.27,100,1,11.4,100,1,11.76,100,1,11.93,200,2,12.23,100,1,12.34,200,2,12.36,200,2,13.76,15,1,13.77,100,1,13.8,100,1,13.95,2,1,14.12,100,1,14.4,100,1,14.56,800,2,14.6,700,1,14.65,100,1,14.68,1400,2,ARL,296137537
2025-07-17T15:39:30.589169820Z,2025-07-17T15:39:30.589004378Z,160,2,1108,C,A,14.120000000,100,0,286680917,130,165442,248493012,ARL,0,14.12,100,130,165442,248493012,9.55,1700,17,9.68,100,1,10.61,200,2,11.27,100,1,11.4,100,1,11.76,100,1,11.93,200,2,12.23,100,1,12.34,200,2,12.36,200,2,13.76,15,1,13.77,100,1,13.8,100,1,13.95,2,1,14.4,100,1,14.56,800,2,14.6,700,1,14.65,100,1,14.68,1400,2,14.72,200,2,ARL,286680917
2025-07-17T15:39:30.589224596Z,2025-07-17T15:39:30.589059301Z,160,2,1108,A,A,14.050000000,100,0,296137769,130,165295,248493014,ARL,0,14.05,100,130,165295,248493014,9.55,1700,17,9.68,100,1,10.61,200,2,11.27,100,1,11.4,100,1,11.76,100,1,11.93,200,2,12.23,100,1,12.34,200,2,12.36,200,2,13.76,15,1,13.77,100,1,13.8,100,1,13.95,2,1,14.05,100,1,14.4,100,1,14.56,800,2,14.6,700,1,14.65,100,1,14.68,1400,2,ARL,296137769
2025-07-17T15:39:31.092010369Z,2025-07-17T15:39:31.091844988Z,160,2,1108,A,A,13.780000000,100,0,296149845,130,165381,248502203,ARL,0,13.78,100,130,165381,248502203,9.55,1700,17,9.68,100,1,10.61,200,2,11.27,100,1,11.4,100,1,11.76,100,1,11.93,200,2,12.23,100,1,12.34,200,2,12.36,200,2,13.76,15,1,13.77,100,1,13.78,100,1,13.8,100,1,13.95,2,1,14.05,100,1,14.4,100,1,14.56,800,2,14.6,700,1,14.65,100,1,ARL,296149845
2025-07-17T15:39:31.098856641Z,2025-07-17T15:39:31.098691429Z,160,2,1108,C,A,13.800000000,100,0,296059685,130,165212,248502510,ARL,0,13.8,100,130,165212,248502510,9.55,1700,17,9.68,100,1,10.61,200,2,11.27,100,1,11.4,100,1,11.76,100,1,11.93,200,2,12.23,100,1,12.34,200,2,12.36,200,2,13.76,15,1,13.77,100,1,13.78,100,1,13.95,2,1,14.05,100,1,14.4,100,1,14.56,800,2,14.6,700,1,14.65,100,1,14.68,1400,2,ARL,296059685
2025-07-17T15:39:40.691151435Z,2025-07-17T15:39:40.690971606Z,160,2,1108,A,A,13.730000000,15,0,296365029,128,179829,248666930,ARL,0,13.73,15,128,179829,248666930,9.55,1700,17,9.68,100,1,10.61,200,2,11.27,100,1,11.4,100,1,11.76,100,1,11.93,200,2,12.23,100,1,12.34,200,2,12.36,200,2,13.73,15,1,13.76,15,1,13.77,100,1,13.78,100,1,13.95,2,1,14.05,100,1,14.4,100,1,14.56,800,2,14.6,700,1,14.65,100,1,ARL,296365029
2025-07-17T15:39:40.696349429Z,2025-07-17T15:39:40.696182148Z,160,2,1108,C,A,13.770000000,100,0,296137537,0,167281,248669978,ARL,0,13.77,100,0,167281,248669978,9.55,1700,17,9.68,100,1,10.61,200,2,11.27,100,1,11.4,100,1,11.76,100,1,11.93,200,2,12.23,100,1,12.34,200,2,12.36,200,2,13.73,15,1,13.76,15,1,13.78,100,1,13.95,2,1,14.05,100,1,14.4,100,1,14.56,800,2,14.6,700,1,14.65,100,1,14.68,1400,2,ARL,296137537
2025-07-17T15:39:40.696349429Z,2025-07-17T15:39:40.696182148Z,160,2,1108,A,A,13.740000000,100,0,296368281,130,167281,248669978,ARL,0,13.74,100,130,167281,248669978,9.55,1700,17,9.68,100,1,10.61,200,2,11.27,100,1,11.4,100,1,11.76,100,1,11.93,200,2,12.23,100,1,12.34,200,2,12.36,200,2,13.73,15,1,13.74,100,1,13.76,15,1,13.78,100,1,13.95,2,1,14.05,100,1,14.4,100,1,14.56,800,2,14.6,700,1,14.65,100,1,ARL,296368281
2025-07-17T15:39:40.697414147Z,2025-07-17T15:39:40.697247480Z,160,2,1108,C,A,14.850000000,100,0,289726349,0,166667,248670386,ARL,0,14.85,100,0,166667,248670386,9.55,1700,17,9.68,100,1,10.61,200,2,11.27,100,1,11.4,100,1,11.76,100,1,11.93,200,2,12.23,100,1,12.34,200,2,12.36,200,2,13.73,15,1,13.74,100,1,13.76,15,1,13.78,100,1,13.95,2,1,14.05,100,1,14.4,100,1,14.56,800,2,14.6,700,1,14.65,100,1,ARL,289726349
2025-07-17T15:39:40.697414147Z,2025-07-17T15:39:40.697247480Z,160,2,1108,A,A,14.810000000,100,0,296368709,128,166667,248670386,ARL,0,14.81,100,128,166667,248670386,9.55,1700,17,9.68,100,1,10.61,200,2,11.27,100,1,11.4,100,1,11.76,100,1,11.93,200,2,12.23,100,1,12.34,200,2,12.36,200,2,13.73,15,1,13.74,100,1,13.76,15,1,13.78,100,1,13.95,2,1,14.05,100,1,14.4,100,1,14.56,800,2,14.6,700,1,14.65,100,1,ARL,296368709
2025-07-17T15:39:40.708810377Z,2025-07-17T15:39:40.708645114Z,160,2,1108,A,A,13.760000000,100,0,296372577,130,165263,248674504,ARL,0,13.76,100,130,165263,248674504,9.55,1700,17,9.68,100,1,10.61,200,2,11.27,100,1,11.4,100,1,11.76,100,1,11.93,200,2,12.23,100,1,12.34,200,2,12.36,200,2,13.73,15,1,13.74,100,1,13.76,115,2,13.78,100,1,13.95,2,1,14.05,100,1,14.4,100,1,14.56,800,2,14.6,700,1,14.65,100,1,ARL,296372577
2025-07-17T15:39:40.731431547Z,2025-07-17T15:39:40.731266408Z,160,2,1108,C,A,13.780000000,100,0,296149845,130,165139,248676672,ARL,0,13.78,100,130,165139,248676672,9.55,1700,17,9.68,100,1,10.61,200,2,11.27,100,1,11.4,100,1,11.76,100,1,11.93,200,2,12.23,100,1,12.34,200,2,12.36,200,2,13.73,15,1,13.74,100,1,13.76,115,2,13.95,2,1,14.05,100,1,14.4,100,1,14.56,800,2,14.6,700,1,14.65,100,1,14.68,1400,2,ARL,296149845
2025-07-17T15:39:40.908095999Z,2025-07-17T15:39:40.907929975Z,160,2,1108,C,A,15.400000000,100,0,146959177,0,166024,248685584,ARL,0,15.4,100,0,166024,248685584,9.55,1700,17,9.68,100,1,10.61,200,2,11.27,100,1,11.4,100,1,11.76,100,1,11.93,200,2,12.23,100,1,12.34,200,2,12.36,200,2,13.73,15,1,13.74,100,1,13.76,115,2,13.95,2,1,14.05,100,1,14.4,100,1,14.56,800,2,14.6,700,1,14.65,100,1,14.68,1400,2,ARL,146959177
2025-07-17T15:39:40.908095999Z,2025-07-17T15:39:40.907929975Z,160,2,1108,A,A,15.120000000,100,0,296387089,130,166024,248685584,ARL,0,15.12,100,130,166024,248685584,9.55,1700,17,9.68,100,1,10.61,200,2,11.27,100,1,11.4,100,1,11.76,100,1,11.93,200,2,12.23,100,1,12.34,200,2,12.36,200,2,13.73,15,1,13.74,100,1,13.76,115,2,13.95,2,1,14.05,100,1,14.4,100,1,14.56,800,2,14.6,700,1,14.65,100,1,14.68,1400,2,ARL,296387089
2025-07-17T15:39:41.085864728Z,2025-07-17T15:39:41.085699437Z,160,2,1108,A,A,14.560000000,100,0,296391881,130,165291,248688410,ARL,0,14.56,100,130,165291,248688410,9.55,1700,17,9.68,100,1,10.61,200,2,11.27,100,1,11.4,100,1,11.76,100,1,11.93,200,2,12.23,100,1,12.34,200,2,12.36,200,2,13.73,15,1,13.74,100,1,13.76,115,2,13.95,2,1,14.05,100,1,14.4,100,1,14.56,900,3,14.6,700,1,14.65,100,1,14.68,1400,2,ARL,296391881
2025-07-17T15:39:41.085877317Z,2025-07-17T15:39:41.085711985Z,160,2,1108,C,A,14.840000000,100,0,146962993,130,165332,248688411,ARL,0,14.84,100,130,165332,248688411,9.55,1700,17,9.68,100,1,10.61,200,2,11.27,100,1,11.4,100,1,11.76,100,1,11.93,200,2,12.23,100,1,12.34,200,2,12.36,200,2,13.73,15,1,13.74,100,1,13.76,115,2,13.95,2,1,14.05,100,1,14.4,100,1,14.56,900,3,14.6,700,1,14.65,100,1,14.68,1400,2,ARL,146962993
2025-07-17T15:39:43.773811774Z,2025-07-17T15:39:43.773645905Z,160,2,1108,C,A,14.720000000,100,0,286680577,0,165869,248737506,ARL,0,14.72,100,0,165869,248737506,9.55,1700,17,9.68,100,1,10.61,200,2,11.27,100,1,11.4,100,1,11.76,100,1,11.93,200,2,12.23,100,1,12.34,200,2,12.36,200,2,13.73,15,1,13.74,100,1,13.76,115,2,13.95,2,1,14.05,100,1,14.4,100,1,14.56,900,3,14.6,700,1,14.65,100,1,14.68,1400,2,ARL,286680577
2025-07-17T15:39:43.773811774Z,2025-07-17T15:39:43.773645905Z,160,2,1108,A,A,14.610000000,100,0,296455037,130,165869,248737506,ARL,0,14.61,100,130,165869,248737506,9.55,1700,17,9.68,100,1,10.61,200,2,11.27,100,1,11.4,100,1,11.76,100,1,11.93,200,2,12.23,100,1,12.34,200,2,12.36,200,2,13.73,15,1,13.74,100,1,13.76,115,2,13.95,2,1,14.05,100,1,14.4,100,1,14.56,900,3,14.6,700,1,14.61,100,1,14.65,100,1,ARL,296455037
2025-07-17T15:39:43.773904473Z,2025-07-17T15:39:43.773738855Z,160,2,1108,C,A,14.720000000,100,0,286680573,0,165618,248737508,ARL,0,14.72,100,0,165618,248737508,9.55,1700,17,9.68,100,1,10.61,200,2,11.27,100,1,11.4,100,1,11.76,100,1,11.93,200,2,12.23,100,1,12.34,200,2,12.36,200,2,13.73,15,1,13.74,100,1,13.76,115,2,13.95,2,1,14.05,100,1,14.4,100,1,14.56,900,3,14.6,700,1,14.61,100,1,14.65,100,1,ARL,286680573
2025-07-17T15:39:43.773904473Z,2025-07-17T15:39:43.773738855Z,160,2,1108,A,A,14.610000000,100,0,296455041,130,165618,248737508,ARL,0,14.61,100,130,165618,248737508,9.55,1700,17,9.68,100,1,10.61,200,2,11.27,100,1,11.4,100,1,11.76,100,1,11.93,200,2,12.23,100,1,12.34,200,2,12.36,200,2,13.73,15,1,13.74,100,1,13.76,115,2,13.95,2,1,14.05,100,1,14.4,100,1,14.56,900,3,14.6,700,1,14.61,200,2,14.65,100,1,ARL,296455041
2025-07-17T15:39:44.428670900Z,2025-07-17T15:39:44.428505546Z,160,2,1108,C,A,13.760000000,15,0,296136617,130,165354,248751670,ARL,0,13.76,15,130,165354,248751670,9.55,1700,17,9.68,100,1,10.61,200,2,11.27,100,1,11.4,100,1,11.76,100,1,11.93,200,2,12.23,100,1,12.34,200,2,12.36,200,2,13.73,15,1,13.74,100,1,13.76,100,1,13.95,2,1,14.05,100,1,14.4,100,1,14.56,900,3,14.6,700,1,14.61,200,2,14.65,100,1,ARL,296136617
2025-07-17T15:39:44.433539292Z,2025-07-17T15:39:44.433372235Z,160,2,1108,C,A,13.730000000,15,0,296365029,128,167057,248752483,ARL,0,13.73,15,128,167057,248752483,9.55,1700,17,9.68,100,1,10.61,200,2,11.27,100,1,11.4,100,1,11.76,100,1,11.93,200,2,12.23,100,1,12.34,200,2,12.36,200,2,13.74,100,1,13.76,100,1,13.95,2,1,14.05,100,1,14.4,100,1,14.56,900,3,14.6,700,1,14.61,200,2,14.65,100,1,14.68,1400,2,ARL,296365029
2025-07-17T15:39:44.436054885Z,2025-07-17T15:39:44.435889060Z,160,2,1108,C,A,13.740000000,100,0,296368281,130,165825,248752938,ARL,0,13.74,100,130,165825,248752938,9.55,1700,17,9.68,100,1,10.61,200,2,11.27,100,1,11.4,100,1,11.76,100,1,11.93,200,2,12.23,100,1,12.34,200,2,12.36,200,2,13.76,100,1,13.95,2,1,14.05,100,1,14.4,100,1,14.56,900,3,14.6,700,1,14.61,200,2,14.65,100,1,14.68,1400,2,14.81,300,3,ARL,296368281
2025-07-17T15:39:44.450239090Z,2025-07-17T15:39:44.450073949Z,160,2,1108,C,A,13.760000000,100,0,296372577,130,165141,248753643,ARL,0,13.76,100,130,165141,248753643,9.55,1700,17,9.68,100,1,10.61,200,2,11.27,100,1,11.4,100,1,11.76,100,1,11.93,200,2,12.23,100,1,12.34,200,2,12.36,200,2,13.95,2,1,14.05,100,1,14.4,100,1,14.56,900,3,14.6,700,1,14.61,200,2,14.65,100,1,14.68,1400,2,14.81,300,3,15.12,100,1,ARL,296372577
2025-07-17T15:39:44.450972330Z,2025-07-17T15:39:44.450806746Z,160,2,1108,C,A,14.810000000,100,0,296368709,0,165584,248753673,ARL,0,14.81,100,0,165584,248753673,9.55,1700,17,9.68,100,1,10.61,200,2,11.27,100,1,11.4,100,1,11.76,100,1,11.93,200,2,12.23,100,1,12.34,200,2,12.36,200,2,13.95,2,1,14.05,100,1,14.4,100,1,14.56,900,3,14.6,700,1,14.61,200,2,14.65,100,1,14.68,1400,2,14.81,200,2,15.12,100,1,ARL,296368709
2025-07-17T15:39:44.450972330Z,2025-07-17T15:39:44.450806746Z,160,2,1108,A,A,15.060000000,100,0,296478965,130,165584,248753673,ARL,0,15.06,100,130,165584,248753673,9.55,1700,17,9.68,100,1,10.61,200,2,11.27,100,1,11.4,100,1,11.76,100,1,11.93,200,2,12.23,100,1,12.34,200,2,12.36,200,2,13.95,2,1,14.05,100,1,14.4,100,1,14.56,900,3,14.6,700,1,14.61,200,2,14.65,100,1,14.68,1400,2,14.81,200,2,15.06,100,1,ARL,296478965
2025-07-17T15:39:44.451075992Z,2025-07-17T15:39:44.450910591Z,160,2,1108,C,A,13.950000000,2,0,287540393,0,165401,248753678,ARL,0,13.95,2,0,165401,248753678,9.55,1700,17,9.68,100,1,10.61,200,2,11.27,100,1,11.4,100,1,11.76,100,1,11.93,200,2,12.23,100,1,12.34,200,2,12.36,200,2,14.05,100,1,14.4,100,1,14.56,900,3,14.6,700,1,14.61,200,2,14.65,100,1,14.68,1400,2,14.81,200,2,15.06,100,1,15.12,100,1,ARL,287540393
2025-07-17T15:39:44.451075992Z,2025-07-17T15:39:44.450910591Z,160,2,1108,A,A,14.070000000,2,0,296478973,130,165401,248753678,ARL,0,14.07,2,130,165401,248753678,9.55,1700,17,9.68,100,1,10.61,200,2,11.27,100,1,11.4,100,1,11.76,100,1,11.93,200,2,12.23,100,1,12.34,200,2,12.36,200,2,14.05,100,1,14.07,2,1,14.4,100,1,14.56,900,3,14.6,700,1,14.61,200,2,14.65,100,1,14.68,1400,2,14.81,200,2,15.06,100,1,ARL,296478973
2025-07-17T15:39:44.455130297Z,2025-07-17T15:39:44.454964327Z,160,2,1108,C,A,14.810000000,100,0,286680741,0,165970,248753748,ARL,0,14.81,100,0,165970,248753748,9.55,1700,17,9.68,100,1,10.61,200,2,11.27,100,1,11.4,100,1,11.76,100,1,11.93,200,2,12.23,100,1,12.34,200,2,12.36,200,2,14.05,100,1,14.07,2,1,14.4,100,1,14.56,900,3,14.6,700,1,14.61,200,2,14.65,100,1,14.68,1400,2,14.81,100,1,15.06,100,1,ARL,286680741
2025-07-17T15:39:44.455130297Z,2025-07-17T15:39:44.454964327Z,160,2,1108,A,A,14.960000000,100,0,296479053,130,165970,248753748,ARL,0,14.96,100,130,165970,248753748,9.55,1700,17,9.68,100,1,10.61,200,2,11.27,100,1,11.4,100,1,11.76,100,1,11.93,200,2,12.23,100,1,12.34,200,2,12.36,200,2,14.05,100,1,14.07,2,1,14.4,100,1,14.56,900,3,14.6,700,1,14.61,200,2,14.65,100,1,14.68,1400,2,14.81,100,1,14.96,100,1,ARL,296479053
2025-07-17T15:39:44.456288062Z,2025-07-17T15:39:44.456122660Z,160,2,1108,C,A,14.650000000,100,0,286680905,130,165402,248753812,ARL,0,14.65,100,130,165402,248753812,9.55,1700,17,9.68,100,1,10.61,200,2,11.27,100,1,11.4,100,1,11.76,100,1,11.93,200,2,12.23,100,1,12.34,200,2,12.36,200,2,14.05,100,1,14.07,2,1,14.4,100,1,14.56,900,3,14.6,700,1,14.61,200,2,14.68,1400,2,14.81,100,1,14.96,100,1,15.06,100,1,ARL,286680905
2025-07-17T15:39:44.456377500Z,2025-07-17T15:39:44.456211953Z,160,2,1108,A,A,14.780000000,100,0,296479285,130,165547,248753815,ARL,0,14.78,100,130,165547,248753815,9.55,1700,17,9.68,100,1,10.61,200,2,11.27,100,1,11.4,100,1,11.76,100,1,11.93,200,2,12.23,100,1,12.34,200,2,12.36,200,2,14.05,100,1,14.07,2,1,14.4,100,1,14.56,900,3,14.6,700,1,14.61,200,2,14.68,1400,2,14.78,100,1,14.81,100,1,14.96,100,1,ARL,296479285
2025-07-17T15:39:44.462055094Z,2025-07-17T15:39:44.461889886Z,160,2,1108,C,A,14.050000000,100,0,296137769,130,165208,248753947,ARL,0,14.05,100,130,165208,248753947,9.55,1700,17,9.68,100,1,10.61,200,2,11.27,100,1,11.4,100,1,11.76,100,1,11.93,200,2,12.23,100,1,12.34,200,2,12.36,200,2,14.07,2,1,14.4,100,1,14.56,900,3,14.6,700,1,14.61,200,2,14.68,1400,2,14.78,100,1,14.81,100,1,14.96,100,1,15.06,100,1,ARL,296137769
2025-07-17T15:39:44.462108809Z,2025-07-17T15:39:44.461943584Z,160,2,1108,A,A,14.260000000,100,0,296479425,130,165225,248753952,ARL,0,14.26,100,130,165225,248753952,9.55,1700,17,9.68,100,1,10.61,200,2,11.27,100,1,11.4,100,1,11.76,100,1,11.93,200,2,12.23,100,1,12.34,200,2,12.36,200,2,14.07,2,1,14.26,100,1,14.4,100,1,14.56,900,3,14.6,700,1,14.61,200,2,14.68,1400,2,14.78,100,1,14.81,100,1,14.96,100,1,ARL,296479425
2025-07-17T15:39:44.478923366Z,2025-07-17T15:39:44.478757958Z,160,2,1108,C,A,17.580000000,100,0,286681057,0,165408,248754361,ARL,0,17.58,100,0,165408,248754361,9.55,1700,17,9.68,100,1,10.61,200,2,11.27,100,1,11.4,100,1,11.76,100,1,11.93,200,2,12.23,100,1,12.34,200,2,12.36,200,2,14.07,2,1,14.26,100,1,14.4,100,1,14.56,900,3,14.6,700,1,14.61,200,2,14.68,1400,2,14.78,100,1,14.81,100,1,14.96,100,1,ARL,286681057
2025-07-17T15:39:44.478923366Z,2025-07-17T15:39:44.478757958Z,160,2,1108,A,A,17.760000000,100,0,296479893,130,165408,248754361,ARL,0,17.76,100,130,165408,248754361,9.55,1700,17,9.68,100,1,10.61,200,2,11.27,100,1,11.4,100,1,11.76,100,1,11.93,200,2,12.23,100,1,12.34,200,2,12.36,200,2,14.07,2,1,14.26,100,1,14.4,100,1,14.56,900,3,14.6,700,1,14.61,200,2,14.68,1400,2,14.78,100,1,14.81,100,1,14.96,100,1,ARL,296479893
2025-07-17T15:39:44.491018431Z,2025-07-17T15:39:44.490852860Z,160,2,1108,C,A,15.920000000,100,0,286681229,0,165571,248754608,ARL,0,15.92,100,0,165571,248754608,9.55,1700,17,9.68,100,1,10.61,200,2,11.27,100,1,11.4,100,1,11.76,100,1,11.93,200,2,12.23,100,1,12.34,200,2,12.36,200,2,14.07,2,1,14.26,100,1,14.4,100,1,14.56,900,3,14.6,700,1,14.61,200,2,14.68,1400,2,14.78,100,1,14.81,100,1,14.96,100,1,ARL,286681229
2025-07-17T15:39:44.491018431Z,2025-07-17T15:39:44.490852860Z,160,2,1108,A,A,16.080000000,100,0,296480097,130,165571,248754608,ARL,0,16.08,100,130,165571,248754608,9.55,1700,17,9.68,100,1,10.61,200,2,11.27,100,1,11.4,100,1,11.76,100,1,11.93,200,2,12.23,100,1,12.34,200,2,12.36,200,2,14.07,2,1,14.26,100,1,14.4,100,1,14.56,900,3,14.6,700,1,14.61,200,2,14.68,1400,2,14.78,100,1,14.81,100,1,14.96,100,1,ARL,296480097
2025-07-17T15:39:44.593773213Z,2025-07-17T15:39:44.593607433Z,160,2,1108,C,A,14.810000000,100,0,286684005,0,165780,248756227,ARL,0,14.81,100,0,165780,248756227,9.55,1700,17,9.68,100,1,10.61,200,2,11.27,100,1,11.4,100,1,11.76,100,1,11.93,200,2,12.23,100,1,12.34,200,2,12.36,200,2,14.07,2,1,14.26,100,1,14.4,100,1,14.56,900,3,14.6,700,1,14.61,200,2,14.68,1400,2,14.78,100,1,14.96,100,1,15.06,100,1,ARL,286684005
2025-07-17T15:39:44.593773213Z,2025-07-17T15:39:44.593607433Z,160,2,1108,A,A,14.960000000,100,0,296482509,130,165780,248756227,ARL,0,14.96,100,130,165780,248756227,9.55,1700,17,9.68,100,1,10.61,200,2,11.27,100,1,11.4,100,1,11.76,100,1,11.93,200,2,12.23,100,1,12.34,200,2,12.36,200,2,14.07,2,1,14.26,100,1,14.4,100,1,14.56,900,3,14.6,700,1,14.61,200,2,14.68,1400,2,14.78,100,1,14.96,200,2,15.06,100,1,ARL,296482509
