ts_recv,ts_event,rtype,publisher_id,instrument_id,action,side,price,size,channel_id,order_id,flags,ts_in_delta,sequence,symbol,depth,price,size,flags,ts_in_delta,sequence,bid_px_00,bid_sz_00,bid_ct_00,ask_px_00,ask_sz_00,ask_ct_00,bid_px_01,bid_sz_01,bid_ct_01,ask_px_01,ask_sz_01,ask_ct_01,bid_px_02,bid_sz_02,bid_ct_02,ask_px_02,ask_sz_02,ask_ct_02,bid_px_03,bid_sz_03,bid_ct_03,ask_px_03,ask_sz_03,ask_ct_03,bid_px_04,bid_sz_04,bid_ct_04,ask_px_04,ask_sz_04,ask_ct_04,bid_px_05,bid_sz_05,bid_ct_05,ask_px_05,ask_sz_05,ask_ct_05,bid_px_06,bid_sz_06,bid_ct_06,ask_px_06,ask_sz_06,ask_ct_06,bid_px_07,bid_sz_07,bid_ct_07,ask_px_07,ask_sz_07,ask_ct_07,bid_px_08,bid_sz_08,bid_ct_08,ask_px_08,ask_sz_08,ask_ct_08,bid_px_09,bid_sz_09,bid_ct_09,ask_px_09,ask_sz_09,ask_ct_09,symbol,order_id
2025-07-17T16:06:51.754576322Z,2025-07-17T16:06:51.754410704Z,160,2,1108,C,A,13.570000000,100,0,331491049,0,165618,276428315,ARL,0,13.57,100,0,165618,276428315,9.55,1700,17,9.68,100,1,10.61,200,2,11.27,100,1,11.4,100,1,11.76,100,1,11.93,200,2,12.1,100,1,12.2,200,2,12.33,100,1,13.54,15,1,13.56,15,1,13.58,100,1,13.84,100,1,13.85,2,1,14.23,100,1,14.27,700,1,14.28,100,1,14.38,100,1,14.48,700,1,ARL,331491049
2025-07-17T16:06:51.754576322Z,2025-07-17T16:06:51.754410704Z,160,2,1108,A,A,13.550000000,100,0,331694265,130,165618,276428315,ARL,0,13.55,100,130,165618,276428315,9.55,1700,17,9.68,100,1,10.61,200,2,11.27,100,1,11.4,100,1,11.76,100,1,11.93,200,2,12.1,100,1,12.2,200,2,12.33,100,1,13.54,15,1,13.55,100,1,13.56,15,1,13.58,100,1,13.84,100,1,13.85,2,1,14.23,100,1,14.27,700,1,14.28,100,1,14.38,100,1,ARL,331694265
2025-07-17T16:06:51.757403109Z,2025-07-17T16:06:51.757237300Z,160,2,1108,C,B,13.000000000,2,0,325967705,0,165809,276428333,ARL,0,13,2,0,165809,276428333,9.55,1700,17,9.68,100,1,10.61,200,2,11.27,100,1,11.4,100,1,11.76,100,1,11.93,200,2,12.1,100,1,12.2,200,2,12.33,100,1,13.54,15,1,13.55,100,1,13.56,15,1,13.58,100,1,13.84,100,1,13.85,2,1,14.23,100,1,14.27,700,1,14.28,100,1,14.38,100,1,ARL,325967705
2025-07-17T16:06:51.757403109Z,2025-07-17T16:06:51.757237300Z,160,2,1108,A,B,12.900000000,2,0,331694297,130,165809,276428333,ARL,0,12.9,2,130,165809,276428333,9.55,1700,17,9.68,100,1,10.61,200,2,11.27,100,1,11.4,100,1,11.76,100,1,11.93,200,2,12.1,100,1,12.2,200,2,12.33,100,1,13.54,15,1,13.55,100,1,13.56,15,1,13.58,100,1,13.84,100,1,13.85,2,1,14.23,100,1,14.27,700,1,14.28,100,1,14.38,100,1,ARL,331694297
2025-07-17T16:06:55.056300861Z,2025-07-17T16:06:55.056135380Z,160,2,1108,C,A,13.540000000,15,0,331666961,130,165481,276516227,ARL,0,13.54,15,130,165481,276516227,9.55,1700,17,9.68,100,1,10.61,200,2,11.27,100,1,11.4,100,1,11.76,100,1,11.93,200,2,12.1,100,1,12.2,200,2,12.33,100,1,13.55,100,1,13.56,15,1,13.58,100,1,13.84,100,1,13.85,2,1,14.23,100,1,14.27,700,1,14.28,100,1,14.38,100,1,14.48,700,1,ARL,331666961
2025-07-17T16:06:55.056466231Z,2025-07-17T16:06:55.056301001Z,160,2,1108,C,A,13.560000000,15,0,331488089,130,165230,276516239,ARL,0,13.56,15,130,165230,276516239,9.55,1700,17,9.68,100,1,10.61,200,2,11.27,100,1,11.4,100,1,11.76,100,1,11.93,200,2,12.1,100,1,12.2,200,2,12.33,100,1,13.55,100,1,13.58,100,1,13.84,100,1,13.85,2,1,14.23,100,1,14.27,700,1,14.28,100,1,14.38,100,1,14.48,700,1,14.52,200,2,ARL,331488089
2025-07-17T16:07:00.010995558Z,2025-07-17T16:07:00.010829521Z,160,2,1108,C,A,13.550000000,100,0,331694265,130,166037,276611719,ARL,0,13.55,100,130,166037,276611719,9.55,1700,17,9.68,100,1,10.61,200,2,11.27,100,1,11.4,100,1,11.76,100,1,11.93,200,2,12.1,100,1,12.2,200,2,12.33,100,1,13.58,100,1,13.84,100,1,13.85,2,1,14.23,100,1,14.27,700,1,14.28,100,1,14.38,100,1,14.48,700,1,14.52,200,2,14.55,200,2,ARL,331694265
2025-07-17T16:07:00.023849180Z,2025-07-17T16:07:00.023683961Z,160,2,1108,C,A,13.580000000,100,0,331667121,130,165219,276613073,ARL,0,13.58,100,130,165219,276613073,9.55,1700,17,9.68,100,1,10.61,200,2,11.27,100,1,11.4,100,1,11.76,100,1,11.93,200,2,12.1,100,1,12.2,200,2,12.33,100,1,13.84,100,1,13.85,2,1,14.23,100,1,14.27,700,1,14.28,100,1,14.38,100,1,14.48,700,1,14.52,200,2,14.55,200,2,14.56,800,2,ARL,331667121
2025-07-17T16:07:00.023917543Z,2025-07-17T16:07:00.023752163Z,160,2,1108,C,A,14.270000000,700,0,331257169,130,165380,276613077,ARL,0,14.27,700,130,165380,276613077,9.55,1700,17,9.68,100,1,10.61,200,2,11.27,100,1,11.4,100,1,11.76,100,1,11.93,200,2,12.1,100,1,12.2,200,2,12.33,100,1,13.84,100,1,13.85,2,1,14.23,100,1,14.28,100,1,14.38,100,1,14.48,700,1,14.52,200,2,14.55,200,2,14.56,800,2,14.6,700,1,ARL,331257169
2025-07-17T16:07:00.023980805Z,2025-07-17T16:07:00.023815326Z,160,2,1108,A,A,14.510000000,700,0,331926981,130,165479,276613078,ARL,0,14.51,700,130,165479,276613078,9.55,1700,17,9.68,100,1,10.61,200,2,11.27,100,1,11.4,100,1,11.76,100,1,11.93,200,2,12.1,100,1,12.2,200,2,12.33,100,1,13.84,100,1,13.85,2,1,14.23,100,1,14.28,100,1,14.38,100,1,14.48,700,1,14.51,700,1,14.52,200,2,14.55,200,2,14.56,800,2,ARL,331926981
2025-07-17T16:07:00.024590283Z,2025-07-17T16:07:00.024424816Z,160,2,1108,C,A,14.620000000,100,0,331491077,0,165467,276613110,ARL,0,14.62,100,0,165467,276613110,9.55,1700,17,9.68,100,1,10.61,200,2,11.27,100,1,11.4,100,1,11.76,100,1,11.93,200,2,12.1,100,1,12.2,200,2,12.33,100,1,13.84,100,1,13.85,2,1,14.23,100,1,14.28,100,1,14.38,100,1,14.48,700,1,14.51,700,1,14.52,200,2,14.55,200,2,14.56,800,2,ARL,331491077
2025-07-17T16:07:00.024590283Z,2025-07-17T16:07:00.024424816Z,160,2,1108,A,A,14.880000000,100,0,331927017,130,165467,276613110,ARL,0,14.88,100,130,165467,276613110,9.55,1700,17,9.68,100,1,10.61,200,2,11.27,100,1,11.4,100,1,11.76,100,1,11.93,200,2,12.1,100,1,12.2,200,2,12.33,100,1,13.84,100,1,13.85,2,1,14.23,100,1,14.28,100,1,14.38,100,1,14.48,700,1,14.51,700,1,14.52,200,2,14.55,200,2,14.56,800,2,ARL,331927017
2025-07-17T16:07:00.025231164Z,2025-07-17T16:07:00.025064913Z,160,2,1108,C,A,14.230000000,100,0,329074833,130,166251,276613157,ARL,0,14.23,100,130,166251,276613157,9.55,1700,17,9.68,100,1,10.61,200,2,11.27,100,1,11.4,100,1,11.76,100,1,11.93,200,2,12.1,100,1,12.2,200,2,12.33,100,1,13.84,100,1,13.85,2,1,14.28,100,1,14.38,100,1,14.48,700,1,14.51,700,1,14.52,200,2,14.55,200,2,14.56,800,2,14.6,700,1,ARL,329074833
2025-07-17T16:07:00.025587549Z,2025-07-17T16:07:00.025422082Z,160,2,1108,A,A,14.460000000,100,0,331927161,130,165467,276613175,ARL,0,14.46,100,130,165467,276613175,9.55,1700,17,9.68,100,1,10.61,200,2,11.27,100,1,11.4,100,1,11.76,100,1,11.93,200,2,12.1,100,1,12.2,200,2,12.33,100,1,13.84,100,1,13.85,2,1,14.28,100,1,14.38,100,1,14.46,100,1,14.48,700,1,14.51,700,1,14.52,200,2,14.55,200,2,14.56,800,2,ARL,331927161
2025-07-17T16:07:00.025793260Z,2025-07-17T16:07:00.025628157Z,160,2,1108,A,A,13.590000000,100,0,331927177,130,165103,276613194,ARL,0,13.59,100,130,165103,276613194,9.55,1700,17,9.68,100,1,10.61,200,2,11.27,100,1,11.4,100,1,11.76,100,1,11.93,200,2,12.1,100,1,12.2,200,2,12.33,100,1,13.59,100,1,13.84,100,1,13.85,2,1,14.28,100,1,14.38,100,1,14.46,100,1,14.48,700,1,14.51,700,1,14.52,200,2,14.55,200,2,ARL,331927177
2025-07-17T16:07:00.026998695Z,2025-07-17T16:07:00.026833761Z,160,2,1108,C,A,13.590000000,100,0,331927177,130,164934,276613224,ARL,0,13.59,100,130,164934,276613224,9.55,1700,17,9.68,100,1,10.61,200,2,11.27,100,1,11.4,100,1,11.76,100,1,11.93,200,2,12.1,100,1,12.2,200,2,12.33,100,1,13.84,100,1,13.85,2,1,14.28,100,1,14.38,100,1,14.46,100,1,14.48,700,1,14.51,700,1,14.52,200,2,14.55,200,2,14.56,800,2,ARL,331927177
2025-07-17T16:07:00.032762182Z,2025-07-17T16:07:00.032596898Z,160,2,1108,C,A,14.380000000,100,0,331051369,130,165284,276613329,ARL,0,14.38,100,130,165284,276613329,9.55,1700,17,9.68,100,1,10.61,200,2,11.27,100,1,11.4,100,1,11.76,100,1,11.93,200,2,12.1,100,1,12.2,200,2,12.33,100,1,13.84,100,1,13.85,2,1,14.28,100,1,14.46,100,1,14.48,700,1,14.51,700,1,14.52,200,2,14.55,200,2,14.56,800,2,14.6,700,1,ARL,331051369
2025-07-17T16:07:00.032876947Z,2025-07-17T16:07:00.032711777Z,160,2,1108,A,A,14.630000000,100,0,331927477,130,165170,276613336,ARL,0,14.63,100,130,165170,276613336,9.55,1700,17,9.68,100,1,10.61,200,2,11.27,100,1,11.4,100,1,11.76,100,1,11.93,200,2,12.1,100,1,12.2,200,2,12.33,100,1,13.84,100,1,13.85,2,1,14.28,100,1,14.46,100,1,14.48,700,1,14.51,700,1,14.52,200,2,14.55,200,2,14.56,800,2,14.6,700,1,ARL,331927477
2025-07-17T16:07:00.045525047Z,2025-07-17T16:07:00.045359807Z,160,2,1108,C,A,13.840000000,100,0,331491269,130,165240,276613663,ARL,0,13.84,100,130,165240,276613663,9.55,1700,17,9.68,100,1,10.61,200,2,11.27,100,1,11.4,100,1,11.76,100,1,11.93,200,2,12.1,100,1,12.2,200,2,12.33,100,1,13.85,2,1,14.28,100,1,14.46,100,1,14.48,700,1,14.51,700,1,14.52,200,2,14.55,200,2,14.56,800,2,14.6,700,1,14.63,100,1,ARL,331491269
2025-07-17T16:07:00.045559272Z,2025-07-17T16:07:00.045394317Z,160,2,1108,C,A,14.510000000,700,0,331926981,130,164955,276613664,ARL,0,14.51,700,130,164955,276613664,9.55,1700,17,9.68,100,1,10.61,200,2,11.27,100,1,11.4,100,1,11.76,100,1,11.93,200,2,12.1,100,1,12.2,200,2,12.33,100,1,13.85,2,1,14.28,100,1,14.46,100,1,14.48,700,1,14.52,200,2,14.55,200,2,14.56,800,2,14.6,700,1,14.63,100,1,14.88,100,1,ARL,331926981
2025-07-17T16:07:00.045574786Z,2025-07-17T16:07:00.045409635Z,160,2,1108,A,A,14.090000000,100,0,331927857,130,165151,276613665,ARL,0,14.09,100,130,165151,276613665,9.55,1700,17,9.68,100,1,10.61,200,2,11.27,100,1,11.4,100,1,11.76,100,1,11.93,200,2,12.1,100,1,12.2,200,2,12.33,100,1,13.85,2,1,14.09,100,1,14.28,100,1,14.46,100,1,14.48,700,1,14.52,200,2,14.55,200,2,14.56,800,2,14.6,700,1,14.63,100,1,ARL,331927857
2025-07-17T16:07:00.046838602Z,2025-07-17T16:07:00.046672908Z,160,2,1108,C,A,14.090000000,100,0,331927857,130,165694,276613680,ARL,0,14.09,100,130,165694,276613680,9.55,1700,17,9.68,100,1,10.61,200,2,11.27,100,1,11.4,100,1,11.76,100,1,11.93,200,2,12.1,100,1,12.2,200,2,12.33,100,1,13.85,2,1,14.28,100,1,14.46,100,1,14.48,700,1,14.52,200,2,14.55,200,2,14.56,800,2,14.6,700,1,14.63,100,1,14.88,100,1,ARL,331927857
2025-07-17T16:07:00.046887005Z,2025-07-17T16:07:00.046721624Z,160,2,1108,A,A,13.860000000,100,0,331927877,130,165381,276613681,ARL,0,13.86,100,130,165381,276613681,9.55,1700,17,9.68,100,1,10.61,200,2,11.27,100,1,11.4,100,1,11.76,100,1,11.93,200,2,12.1,100,1,12.2,200,2,12.33,100,1,13.85,2,1,13.86,100,1,14.28,100,1,14.46,100,1,14.48,700,1,14.52,200,2,14.55,200,2,14.56,800,2,14.6,700,1,14.63,100,1,ARL,331927877
2025-07-17T16:07:00.047708936Z,2025-07-17T16:07:00.047544064Z,160,2,1108,C,A,13.860000000,100,0,331927877,130,164872,276613692,ARL,0,13.86,100,130,164872,276613692,9.55,1700,17,9.68,100,1,10.61,200,2,11.27,100,1,11.4,100,1,11.76,100,1,11.93,200,2,12.1,100,1,12.2,200,2,12.33,100,1,13.85,2,1,14.28,100,1,14.46,100,1,14.48,700,1,14.52,200,2,14.55,200,2,14.56,800,2,14.6,700,1,14.63,100,1,14.88,100,1,ARL,331927877
2025-07-17T16:07:00.047755498Z,2025-07-17T16:07:00.047590313Z,160,2,1108,A,A,14.120000000,100,0,331927921,130,165185,276613693,ARL,0,14.12,100,130,165185,276613693,9.55,1700,17,9.68,100,1,10.61,200,2,11.27,100,1,11.4,100,1,11.76,100,1,11.93,200,2,12.1,100,1,12.2,200,2,12.33,100,1,13.85,2,1,14.12,100,1,14.28,100,1,14.46,100,1,14.48,700,1,14.52,200,2,14.55,200,2,14.56,800,2,14.6,700,1,14.63,100,1,ARL,331927921
2025-07-17T16:07:00.053448670Z,2025-07-17T16:07:00.053283700Z,160,2,1108,C,A,14.120000000,100,0,331927921,130,164970,276613731,ARL,0,14.12,100,130,164970,276613731,9.55,1700,17,9.68,100,1,10.61,200,2,11.27,100,1,11.4,100,1,11.76,100,1,11.93,200,2,12.1,100,1,12.2,200,2,12.33,100,1,13.85,2,1,14.28,100,1,14.46,100,1,14.48,700,1,14.52,200,2,14.55,200,2,14.56,800,2,14.6,700,1,14.63,100,1,14.88,100,1,ARL,331927921
2025-07-17T16:07:00.053495095Z,2025-07-17T16:07:00.053329959Z,160,2,1108,A,A,14.260000000,100,0,331928009,130,165136,276613732,ARL,0,14.26,100,130,165136,276613732,9.55,1700,17,9.68,100,1,10.61,200,2,11.27,100,1,11.4,100,1,11.76,100,1,11.93,200,2,12.1,100,1,12.2,200,2,12.33,100,1,13.85,2,1,14.26,100,1,14.28,100,1,14.46,100,1,14.48,700,1,14.52,200,2,14.55,200,2,14.56,800,2,14.6,700,1,14.63,100,1,ARL,331928009
2025-07-17T16:07:00.057809857Z,2025-07-17T16:07:00.057644427Z,160,2,1108,C,A,14.550000000,100,0,331052197,0,165430,276613800,ARL,0,14.55,100,0,165430,276613800,9.55,1700,17,9.68,100,1,10.61,200,2,11.27,100,1,11.4,100,1,11.76,100,1,11.93,200,2,12.1,100,1,12.2,200,2,12.33,100,1,13.85,2,1,14.26,100,1,14.28,100,1,14.46,100,1,14.48,700,1,14.52,200,2,14.55,100,1,14.56,800,2,14.6,700,1,14.63,100,1,ARL,331052197
2025-07-17T16:07:00.057809857Z,2025-07-17T16:07:00.057644427Z,160,2,1108,A,A,14.960000000,100,0,331928129,130,165430,276613800,ARL,0,14.96,100,130,165430,276613800,9.55,1700,17,9.68,100,1,10.61,200,2,11.27,100,1,11.4,100,1,11.76,100,1,11.93,200,2,12.1,100,1,12.2,200,2,12.33,100,1,13.85,2,1,14.26,100,1,14.28,100,1,14.46,100,1,14.48,700,1,14.52,200,2,14.55,100,1,14.56,800,2,14.6,700,1,14.63,100,1,ARL,331928129
2025-07-17T16:07:00.070490835Z,2025-07-17T16:07:00.070325784Z,160,2,1108,C,A,14.260000000,100,0,331928009,130,165051,276614087,ARL,0,14.26,100,130,165051,276614087,9.55,1700,17,9.68,100,1,10.61,200,2,11.27,100,1,11.4,100,1,11.76,100,1,11.93,200,2,12.1,100,1,12.2,200,2,12.33,100,1,13.85,2,1,14.28,100,1,14.46,100,1,14.48,700,1,14.52,200,2,14.55,100,1,14.56,800,2,14.6,700,1,14.63,100,1,14.88,100,1,ARL,331928009
2025-07-17T16:07:00.070539222Z,2025-07-17T16:07:00.070373975Z,160,2,1108,A,A,14.140000000,100,0,331929033,130,165247,276614089,ARL,0,14.14,100,130,165247,276614089,9.55,1700,17,9.68,100,1,10.61,200,2,11.27,100,1,11.4,100,1,11.76,100,1,11.93,200,2,12.1,100,1,12.2,200,2,12.33,100,1,13.85,2,1,14.14,100,1,14.28,100,1,14.46,100,1,14.48,700,1,14.52,200,2,14.55,100,1,14.56,800,2,14.6,700,1,14.63,100,1,ARL,331929033
2025-07-17T16:07:00.071359350Z,2025-07-17T16:07:00.071194493Z,160,2,1108,C,A,14.140000000,100,0,331929033,130,164857,276614094,ARL,0,14.14,100,130,164857,276614094,9.55,1700,17,9.68,100,1,10.61,200,2,11.27,100,1,11.4,100,1,11.76,100,1,11.93,200,2,12.1,100,1,12.2,200,2,12.33,100,1,13.85,2,1,14.28,100,1,14.46,100,1,14.48,700,1,14.52,200,2,14.55,100,1,14.56,800,2,14.6,700,1,14.63,100,1,14.88,100,1,ARL,331929033
2025-07-17T16:07:00.071405105Z,2025-07-17T16:07:00.071239867Z,160,2,1108,A,A,14.260000000,100,0,331929041,130,165238,276614095,ARL,0,14.26,100,130,165238,276614095,9.55,1700,17,9.68,100,1,10.61,200,2,11.27,100,1,11.4,100,1,11.76,100,1,11.93,200,2,12.1,100,1,12.2,200,2,12.33,100,1,13.85,2,1,14.26,100,1,14.28,100,1,14.46,100,1,14.48,700,1,14.52,200,2,14.55,100,1,14.56,800,2,14.6,700,1,14.63,100,1,ARL,331929041
2025-07-17T16:07:00.074580946Z,2025-07-17T16:07:00.074415631Z,160,2,1108,C,A,14.880000000,100,0,331927017,0,165315,276614119,ARL,0,14.88,100,0,165315,276614119,9.55,1700,17,9.68,100,1,10.61,200,2,11.27,100,1,11.4,100,1,11.76,100,1,11.93,200,2,12.1,100,1,12.2,200,2,12.33,100,1,13.85,2,1,14.26,100,1,14.28,100,1,14.46,100,1,14.48,700,1,14.52,200,2,14.55,100,1,14.56,800,2,14.6,700,1,14.63,100,1,ARL,331927017
2025-07-17T16:07:00.074580946Z,2025-07-17T16:07:00.074415631Z,160,2,1108,A,A,15.060000000,100,0,331929065,130,165315,276614119,ARL,0,15.06,100,130,165315,276614119,9.55,1700,17,9.68,100,1,10.61,200,2,11.27,100,1,11.4,100,1,11.76,100,1,11.93,200,2,12.1,100,1,12.2,200,2,12.33,100,1,13.85,2,1,14.26,100,1,14.28,100,1,14.46,100,1,14.48,700,1,14.52,200,2,14.55,100,1,14.56,800,2,14.6,700,1,14.63,100,1,ARL,331929065
2025-07-17T16:07:00.085131263Z,2025-07-17T16:07:00.084965637Z,160,2,1108,C,A,15.070000000,100,0,326837501,0,165626,276614295,ARL,0,15.07,100,0,165626,276614295,9.55,1700,17,9.68,100,1,10.61,200,2,11.27,100,1,11.4,100,1,11.76,100,1,11.93,200,2,12.1,100,1,12.2,200,2,12.33,100,1,13.85,2,1,14.26,100,1,14.28,100,1,14.46,100,1,14.48,700,1,14.52,200,2,14.55,100,1,14.56,800,2,14.6,700,1,14.63,100,1,ARL,326837501
2025-07-17T16:07:00.085131263Z,2025-07-17T16:07:00.084965637Z,160,2,1108,A,A,15.380000000,100,0,331929445,130,165626,276614295,ARL,0,15.38,100,130,165626,276614295,9.55,1700,17,9.68,100,1,10.61,200,2,11.27,100,1,11.4,100,1,11.76,100,1,11.93,200,2,12.1,100,1,12.2,200,2,12.33,100,1,13.85,2,1,14.26,100,1,14.28,100,1,14.46,100,1,14.48,700,1,14.52,200,2,14.55,100,1,14.56,800,2,14.6,700,1,14.63,100,1,ARL,331929445
2025-07-17T16:07:00.090359757Z,2025-07-17T16:07:00.090194106Z,160,2,1108,C,A,14.550000000,100,0,331051173,0,165651,276614378,ARL,0,14.55,100,0,165651,276614378,9.55,1700,17,9.68,100,1,10.61,200,2,11.27,100,1,11.4,100,1,11.76,100,1,11.93,200,2,12.1,100,1,12.2,200,2,12.33,100,1,13.85,2,1,14.26,100,1,14.28,100,1,14.46,100,1,14.48,700,1,14.52,200,2,14.56,800,2,14.6,700,1,14.63,100,1,14.96,100,1,ARL,331051173
2025-07-17T16:07:00.090359757Z,2025-07-17T16:07:00.090194106Z,160,2,1108,A,A,14.960000000,100,0,331929633,130,165651,276614378,ARL,0,14.96,100,130,165651,276614378,9.55,1700,17,9.68,100,1,10.61,200,2,11.27,100,1,11.4,100,1,11.76,100,1,11.93,200,2,12.1,100,1,12.2,200,2,12.33,100,1,13.85,2,1,14.26,100,1,14.28,100,1,14.46,100,1,14.48,700,1,14.52,200,2,14.56,800,2,14.6,700,1,14.63,100,1,14.96,200,2,ARL,331929633
2025-07-17T16:07:00.102092147Z,2025-07-17T16:07:00.101927028Z,160,2,1108,A,A,14.680000000,700,0,331929977,130,165119,276614699,ARL,0,14.68,700,130,165119,276614699,9.55,1700,17,9.68,100,1,10.61,200,2,11.27,100,1,11.4,100,1,11.76,100,1,11.93,200,2,12.1,100,1,12.2,200,2,12.33,100,1,13.85,2,1,14.26,100,1,14.28,100,1,14.46,100,1,14.48,700,1,14.52,200,2,14.56,800,2,14.6,700,1,14.63,100,1,14.68,700,1,ARL,331929977
2025-07-17T16:07:00.287582448Z,2025-07-17T16:07:00.287416733Z,160,2,1108,C,A,17.290000000,100,0,330789509,0,165715,276617288,ARL,0,17.29,100,0,165715,276617288,9.55,1700,17,9.68,100,1,10.61,200,2,11.27,100,1,11.4,100,1,11.76,100,1,11.93,200,2,12.1,100,1,12.2,200,2,12.33,100,1,13.85,2,1,14.26,100,1,14.28,100,1,14.46,100,1,14.48,700,1,14.52,200,2,14.56,800,2,14.6,700,1,14.63,100,1,14.68,700,1,ARL,330789509
2025-07-17T16:07:00.287582448Z,2025-07-17T16:07:00.287416733Z,160,2,1108,A,A,17.760000000,100,0,331934277,130,165715,276617288,ARL,0,17.76,100,130,165715,276617288,9.55,1700,17,9.68,100,1,10.61,200,2,11.27,100,1,11.4,100,1,11.76,100,1,11.93,200,2,12.1,100,1,12.2,200,2,12.33,100,1,13.85,2,1,14.26,100,1,14.28,100,1,14.46,100,1,14.48,700,1,14.52,200,2,14.56,800,2,14.6,700,1,14.63,100,1,14.68,700,1,ARL,331934277
2025-07-17T16:07:00.293620434Z,2025-07-17T16:07:00.293454856Z,160,2,1108,C,A,15.630000000,100,0,331051145,0,165578,276617317,ARL,0,15.63,100,0,165578,276617317,9.55,1700,17,9.68,100,1,10.61,200,2,11.27,100,1,11.4,100,1,11.76,100,1,11.93,200,2,12.1,100,1,12.2,200,2,12.33,100,1,13.85,2,1,14.26,100,1,14.28,100,1,14.46,100,1,14.48,700,1,14.52,200,2,14.56,800,2,14.6,700,1,14.63,100,1,14.68,700,1,ARL,331051145
2025-07-17T16:07:00.293620434Z,2025-07-17T16:07:00.293454856Z,160,2,1108,A,A,16.080000000,100,0,331934377,130,165578,276617317,ARL,0,16.08,100,130,165578,276617317,9.55,1700,17,9.68,100,1,10.61,200,2,11.27,100,1,11.4,100,1,11.76,100,1,11.93,200,2,12.1,100,1,12.2,200,2,12.33,100,1,13.85,2,1,14.26,100,1,14.28,100,1,14.46,100,1,14.48,700,1,14.52,200,2,14.56,800,2,14.6,700,1,14.63,100,1,14.68,700,1,ARL,331934377
2025-07-17T16:07:00.494657495Z,2025-07-17T16:07:00.494492099Z,160,2,1108,A,A,13.860000000,100,0,331942821,130,165396,276622423,ARL,0,13.86,100,130,165396,276622423,9.55,1700,17,9.68,100,1,10.61,200,2,11.27,100,1,11.4,100,1,11.76,100,1,11.93,200,2,12.1,100,1,12.2,200,2,12.33,100,1,13.85,2,1,13.86,100,1,14.26,100,1,14.28,100,1,14.46,100,1,14.48,700,1,14.52,200,2,14.56,800,2,14.6,700,1,14.63,100,1,ARL,331942821
2025-07-17T16:07:00.495318245Z,2025-07-17T16:07:00.495152219Z,160,2,1108,C,B,12.360000000,100,0,288723817,0,166026,276622452,ARL,0,12.36,100,0,166026,276622452,9.55,1700,17,9.68,100,1,10.61,200,2,11.27,100,1,11.4,100,1,11.76,100,1,11.93,200,2,12.1,100,1,12.2,200,2,12.33,100,1,13.85,2,1,13.86,100,1,14.26,100,1,14.28,100,1,14.46,100,1,14.48,700,1,14.52,200,2,14.56,800,2,14.6,700,1,14.63,100,1,ARL,288723817
2025-07-17T16:07:00.495318245Z,2025-07-17T16:07:00.495152219Z,160,2,1108,A,B,12.490000000,100,0,331942901,130,166026,276622452,ARL,0,12.49,100,130,166026,276622452,9.55,1700,17,9.68,100,1,10.61,200,2,11.27,100,1,11.4,100,1,11.76,100,1,11.93,200,2,12.1,100,1,12.2,200,2,12.33,100,1,13.85,2,1,13.86,100,1,14.26,100,1,14.28,100,1,14.46,100,1,14.48,700,1,14.52,200,2,14.56,800,2,14.6,700,1,14.63,100,1,ARL,331942901
2025-07-17T16:07:00.495398644Z,2025-07-17T16:07:00.495233001Z,160,2,1108,C,A,15.060000000,100,0,331929065,0,165643,276622455,ARL,0,15.06,100,0,165643,276622455,9.55,1700,17,9.68,100,1,10.61,200,2,11.27,100,1,11.4,100,1,11.76,100,1,11.93,200,2,12.1,100,1,12.2,200,2,12.33,100,1,13.85,2,1,13.86,100,1,14.26,100,1,14.28,100,1,14.46,100,1,14.48,700,1,14.52,200,2,14.56,800,2,14.6,700,1,14.63,100,1,ARL,331929065
2025-07-17T16:07:00.495398644Z,2025-07-17T16:07:00.495233001Z,160,2,1108,A,A,14.930000000,100,0,331942913,130,165643,276622455,ARL,0,14.93,100,130,165643,276622455,9.55,1700,17,9.68,100,1,10.61,200,2,11.27,100,1,11.4,100,1,11.76,100,1,11.93,200,2,12.1,100,1,12.2,200,2,12.33,100,1,13.85,2,1,13.86,100,1,14.26,100,1,14.28,100,1,14.46,100,1,14.48,700,1,14.52,200,2,14.56,800,2,14.6,700,1,14.63,100,1,ARL,331942913
2025-07-17T16:07:00.495989598Z,2025-07-17T16:07:00.495823953Z,160,2,1108,C,B,12.360000000,100,0,288723813,0,165645,276622469,ARL,0,12.36,100,0,165645,276622469,9.55,1700,17,9.68,100,1,10.61,200,2,11.27,100,1,11.4,100,1,11.76,100,1,11.93,200,2,12.1,100,1,12.2,200,2,12.33,100,1,13.85,2,1,13.86,100,1,14.26,100,1,14.28,100,1,14.46,100,1,14.48,700,1,14.52,200,2,14.56,800,2,14.6,700,1,14.63,100,1,ARL,288723813
2025-07-17T16:07:00.495989598Z,2025-07-17T16:07:00.495823953Z,160,2,1108,A,B,12.490000000,100,0,331942945,130,165645,276622469,ARL,0,12.49,100,130,165645,276622469,9.55,1700,17,9.68,100,1,10.61,200,2,11.27,100,1,11.4,100,1,11.76,100,1,11.93,200,2,12.1,100,1,12.2,200,2,12.33,100,1,13.85,2,1,13.86,100,1,14.26,100,1,14.28,100,1,14.46,100,1,14.48,700,1,14.52,200,2,14.56,800,2,14.6,700,1,14.63,100,1,ARL,331942945
2025-07-17T16:07:00.496483460Z,2025-07-17T16:07:00.496317847Z,160,2,1108,C,A,17.760000000,100,0,331934277,0,165613,276622478,ARL,0,17.76,100,0,165613,276622478,9.55,1700,17,9.68,100,1,10.61,200,2,11.27,100,1,11.4,100,1,11.76,100,1,11.93,200,2,12.1,100,1,12.2,200,2,12.33,100,1,13.85,2,1,13.86,100,1,14.26,100,1,14.28,100,1,14.46,100,1,14.48,700,1,14.52,200,2,14.56,800,2,14.6,700,1,14.63,100,1,ARL,331934277
2025-07-17T16:07:00.496483460Z,2025-07-17T16:07:00.496317847Z,160,2,1108,A,A,17.610000000,100,0,331942981,130,165613,276622478,ARL,0,17.61,100,130,165613,276622478,9.55,1700,17,9.68,100,1,10.61,200,2,11.27,100,1,11.4,100,1,11.76,100,1,11.93,200,2,12.1,100,1,12.2,200,2,12.33,100,1,13.85,2,1,13.86,100,1,14.26,100,1,14.28,100,1,14.46,100,1,14.48,700,1,14.52,200,2,14.56,800,2,14.6,700,1,14.63,100,1,ARL,331942981
2025-07-17T16:07:00.499666149Z,2025-07-17T16:07:00.499501052Z,160,2,1108,C,A,14.260000000,100,0,331929041,130,165097,276622569,ARL,0,14.26,100,130,165097,276622569,9.55,1700,17,9.68,100,1,10.61,200,2,11.27,100,1,11.4,100,1,11.76,100,1,11.93,200,2,12.1,100,1,12.2,200,2,12.33,100,1,13.85,2,1,13.86,100,1,14.28,100,1,14.46,100,1,14.48,700,1,14.52,200,2,14.56,800,2,14.6,700,1,14.63,100,1,14.68,700,1,ARL,331929041
2025-07-17T16:07:00.499714918Z,2025-07-17T16:07:00.499549738Z,160,2,1108,A,A,14.140000000,100,0,331943133,130,165180,276622571,ARL,0,14.14,100,130,165180,276622571,9.55,1700,17,9.68,100,1,10.61,200,2,11.27,100,1,11.4,100,1,11.76,100,1,11.93,200,2,12.1,100,1,12.2,200,2,12.33,100,1,13.85,2,1,13.86,100,1,14.14,100,1,14.28,100,1,14.46,100,1,14.48,700,1,14.52,200,2,14.56,800,2,14.6,700,1,14.63,100,1,ARL,331943133
2025-07-17T16:07:22.814941809Z,2025-07-17T16:07:22.814776694Z,160,2,1108,A,A,13.690000000,15,0,332385317,130,165115,276946179,ARL,0,13.69,15,130,165115,276946179,9.55,1700,17,9.68,100,1,10.61,200,2,11.27,100,1,11.4,100,1,11.76,100,1,11.93,200,2,12.1,100,1,12.2,200,2,12.33,100,1,13.69,15,1,13.85,2,1,13.86,100,1,14.14,100,1,14.28,100,1,14.46,100,1,14.48,700,1,14.52,200,2,14.56,800,2,14.6,700,1,ARL,332385317
2025-07-17T16:07:22.815057507Z,2025-07-17T16:07:22.814891345Z,160,2,1108,C,A,13.860000000,100,0,331942821,0,166162,276946183,ARL,0,13.86,100,0,166162,276946183,9.55,1700,17,9.68,100,1,10.61,200,2,11.27,100,1,11.4,100,1,11.76,100,1,11.93,200,2,12.1,100,1,12.2,200,2,12.33,100,1,13.69,15,1,13.85,2,1,14.14,100,1,14.28,100,1,14.46,100,1,14.48,700,1,14.52,200,2,14.56,800,2,14.6,700,1,14.63,100,1,ARL,331942821
2025-07-17T16:07:22.815057507Z,2025-07-17T16:07:22.814891345Z,160,2,1108,A,A,13.700000000,100,0,332385325,130,166162,276946183,ARL,0,13.7,100,130,166162,276946183,9.55,1700,17,9.68,100,1,10.61,200,2,11.27,100,1,11.4,100,1,11.76,100,1,11.93,200,2,12.1,100,1,12.2,200,2,12.33,100,1,13.69,15,1,13.7,100,1,13.85,2,1,14.14,100,1,14.28,100,1,14.46,100,1,14.48,700,1,14.52,200,2,14.56,800,2,14.6,700,1,ARL,332385325
2025-07-17T16:07:22.815790890Z,2025-07-17T16:07:22.815625345Z,160,2,1108,C,A,14.930000000,100,0,331942913,0,165545,276946264,ARL,0,14.93,100,0,165545,276946264,9.55,1700,17,9.68,100,1,10.61,200,2,11.27,100,1,11.4,100,1,11.76,100,1,11.93,200,2,12.1,100,1,12.2,200,2,12.33,100,1,13.69,15,1,13.7,100,1,13.85,2,1,14.14,100,1,14.28,100,1,14.46,100,1,14.48,700,1,14.52,200,2,14.56,800,2,14.6,700,1,ARL,331942913
2025-07-17T16:07:22.815790890Z,2025-07-17T16:07:22.815625345Z,160,2,1108,A,A,14.760000000,100,0,332385501,130,165545,276946264,ARL,0,14.76,100,130,165545,276946264,9.55,1700,17,9.68,100,1,10.61,200,2,11.27,100,1,11.4,100,1,11.76,100,1,11.93,200,2,12.1,100,1,12.2,200,2,12.33,100,1,13.69,15,1,13.7,100,1,13.85,2,1,14.14,100,1,14.28,100,1,14.46,100,1,14.48,700,1,14.52,200,2,14.56,800,2,14.6,700,1,ARL,332385501
2025-07-17T16:07:22.817507809Z,2025-07-17T16:07:22.817341789Z,160,2,1108,C,A,14.960000000,100,0,331929633,0,166020,276946309,ARL,0,14.96,100,0,166020,276946309,9.55,1700,17,9.68,100,1,10.61,200,2,11.27,100,1,11.4,100,1,11.76,100,1,11.93,200,2,12.1,100,1,12.2,200,2,12.33,100,1,13.69,15,1,13.7,100,1,13.85,2,1,14.14,100,1,14.28,100,1,14.46,100,1,14.48,700,1,14.52,200,2,14.56,800,2,14.6,700,1,ARL,331929633
2025-07-17T16:07:22.817507809Z,2025-07-17T16:07:22.817341789Z,160,2,1108,A,A,14.660000000,100,0,332385565,130,166020,276946309,ARL,0,14.66,100,130,166020,276946309,9.55,1700,17,9.68,100,1,10.61,200,2,11.27,100,1,11.4,100,1,11.76,100,1,11.93,200,2,12.1,100,1,12.2,200,2,12.33,100,1,13.69,15,1,13.7,100,1,13.85,2,1,14.14,100,1,14.28,100,1,14.46,100,1,14.48,700,1,14.52,200,2,14.56,800,2,14.6,700,1,ARL,332385565
2025-07-17T16:07:22.817624699Z,2025-07-17T16:07:22.817459170Z,160,2,1108,C,A,15.380000000,100,0,331929445,0,165529,276946313,ARL,0,15.38,100,0,165529,276946313,9.55,1700,17,9.68,100,1,10.61,200,2,11.27,100,1,11.4,100,1,11.76,100,1,11.93,200,2,12.1,100,1,12.2,200,2,12.33,100,1,13.69,15,1,13.7,100,1,13.85,2,1,14.14,100,1,14.28,100,1,14.46,100,1,14.48,700,1,14.52,200,2,14.56,800,2,14.6,700,1,ARL,331929445
2025-07-17T16:07:22.817624699Z,2025-07-17T16:07:22.817459170Z,160,2,1108,A,A,15.070000000,100,0,332385569,130,165529,276946313,ARL,0,15.07,100,130,165529,276946313,9.55,1700,17,9.68,100,1,10.61,200,2,11.27,100,1,11.4,100,1,11.76,100,1,11.93,200,2,12.1,100,1,12.2,200,2,12.33,100,1,13.69,15,1,13.7,100,1,13.85,2,1,14.14,100,1,14.28,100,1,14.46,100,1,14.48,700,1,14.52,200,2,14.56,800,2,14.6,700,1,ARL,332385569
2025-07-17T16:07:22.818565766Z,2025-07-17T16:07:22.818400003Z,160,2,1108,C,A,16.080000000,100,0,331934377,0,165763,276946327,ARL,0,16.08,100,0,165763,276946327,9.55,1700,17,9.68,100,1,10.61,200,2,11.27,100,1,11.4,100,1,11.76,100,1,11.93,200,2,12.1,100,1,12.2,200,2,12.33,100,1,13.69,15,1,13.7,100,1,13.85,2,1,14.14,100,1,14.28,100,1,14.46,100,1,14.48,700,1,14.52,200,2,14.56,800,2,14.6,700,1,ARL,331934377
2025-07-17T16:07:22.818565766Z,2025-07-17T16:07:22.818400003Z,160,2,1108,A,A,15.760000000,100,0,332385585,130,165763,276946327,ARL,0,15.76,100,130,165763,276946327,9.55,1700,17,9.68,100,1,10.61,200,2,11.27,100,1,11.4,100,1,11.76,100,1,11.93,200,2,12.1,100,1,12.2,200,2,12.33,100,1,13.69,15,1,13.7,100,1,13.85,2,1,14.14,100,1,14.28,100,1,14.46,100,1,14.48,700,1,14.52,200,2,14.56,800,2,14.6,700,1,ARL,332385585
2025-07-17T16:07:22.819710983Z,2025-07-17T16:07:22.819545360Z,160,2,1108,C,A,17.610000000,100,0,331942981,0,165623,276946336,ARL,0,17.61,100,0,165623,276946336,9.55,1700,17,9.68,100,1,10.61,200,2,11.27,100,1,11.4,100,1,11.76,100,1,11.93,200,2,12.1,100,1,12.2,200,2,12.33,100,1,13.69,15,1,13.7,100,1,13.85,2,1,14.14,100,1,14.28,100,1,14.46,100,1,14.48,700,1,14.52,200,2,14.56,800,2,14.6,700,1,ARL,331942981
2025-07-17T16:07:22.819710983Z,2025-07-17T16:07:22.819545360Z,160,2,1108,A,A,17.400000000,100,0,332385593,130,165623,276946336,ARL,0,17.4,100,130,165623,276946336,9.55,1700,17,9.68,100,1,10.61,200,2,11.27,100,1,11.4,100,1,11.76,100,1,11.93,200,2,12.1,100,1,12.2,200,2,12.33,100,1,13.69,15,1,13.7,100,1,13.85,2,1,14.14,100,1,14.28,100,1,14.46,100,1,14.48,700,1,14.52,200,2,14.56,800,2,14.6,700,1,ARL,332385593
2025-07-17T16:07:22.819772408Z,2025-07-17T16:07:22.819606945Z,160,2,1108,C,A,14.630000000,100,0,331927477,0,165463,276946337,ARL,0,14.63,100,0,165463,276946337,9.55,1700,17,9.68,100,1,10.61,200,2,11.27,100,1,11.4,100,1,11.76,100,1,11.93,200,2,12.1,100,1,12.2,200,2,12.33,100,1,13.69,15,1,13.7,100,1,13.85,2,1,14.14,100,1,14.28,100,1,14.46,100,1,14.48,700,1,14.52,200,2,14.56,800,2,14.6,700,1,ARL,331927477
2025-07-17T16:07:22.819772408Z,2025-07-17T16:07:22.819606945Z,160,2,1108,A,A,14.490000000,100,0,332385597,130,165463,276946337,ARL,0,14.49,100,130,165463,276946337,9.55,1700,17,9.68,100,1,10.61,200,2,11.27,100,1,11.4,100,1,11.76,100,1,11.93,200,2,12.1,100,1,12.2,200,2,12.33,100,1,13.69,15,1,13.7,100,1,13.85,2,1,14.14,100,1,14.28,100,1,14.46,100,1,14.48,700,1,14.49,100,1,14.52,200,2,14.56,800,2,ARL,332385597
2025-07-17T16:07:22.821165451Z,2025-07-17T16:07:22.821000003Z,160,2,1108,C,A,14.140000000,100,0,331943133,130,165448,276946343,ARL,0,14.14,100,130,165448,276946343,9.55,1700,17,9.68,100,1,10.61,200,2,11.27,100,1,11.4,100,1,11.76,100,1,11.93,200,2,12.1,100,1,12.2,200,2,12.33,100,1,13.69,15,1,13.7,100,1,13.85,2,1,14.28,100,1,14.46,100,1,14.48,700,1,14.49,100,1,14.52,200,2,14.56,800,2,14.6,700,1,ARL,331943133
2025-07-17T16:07:22.821218207Z,2025-07-17T16:07:22.821052982Z,160,2,1108,A,A,13.970000000,100,0,332385613,130,165225,276946344,ARL,0,13.97,100,130,165225,276946344,9.55,1700,17,9.68,100,1,10.61,200,2,11.27,100,1,11.4,100,1,11.76,100,1,11.93,200,2,12.1,100,1,12.2,200,2,12.33,100,1,13.69,15,1,13.7,100,1,13.85,2,1,13.97,100,1,14.28,100,1,14.46,100,1,14.48,700,1,14.49,100,1,14.52,200,2,14.56,800,2,ARL,332385613
2025-07-17T16:07:22.832119220Z,2025-07-17T16:07:22.831949887Z,160,2,1108,C,A,14.960000000,100,0,331928129,0,169333,276946801,ARL,0,14.96,100,0,169333,276946801,9.55,1700,17,9.68,100,1,10.61,200,2,11.27,100,1,11.4,100,1,11.76,100,1,11.93,200,2,12.1,100,1,12.2,200,2,12.33,100,1,13.69,15,1,13.7,100,1,13.85,2,1,13.97,100,1,14.28,100,1,14.46,100,1,14.48,700,1,14.49,100,1,14.52,200,2,14.56,800,2,ARL,331928129
2025-07-17T16:07:22.832119220Z,2025-07-17T16:07:22.831949887Z,160,2,1108,A,A,14.660000000,100,0,332386121,128,169333,276946801,ARL,0,14.66,100,128,169333,276946801,9.55,1700,17,9.68,100,1,10.61,200,2,11.27,100,1,11.4,100,1,11.76,100,1,11.93,200,2,12.1,100,1,12.2,200,2,12.33,100,1,13.69,15,1,13.7,100,1,13.85,2,1,13.97,100,1,14.28,100,1,14.46,100,1,14.48,700,1,14.49,100,1,14.52,200,2,14.56,800,2,ARL,332386121
2025-07-17T16:07:28.273823608Z,2025-07-17T16:07:28.273658191Z,160,2,1108,C,A,13.690000000,15,0,332385317,130,165417,277012951,ARL,0,13.69,15,130,165417,277012951,9.55,1700,17,9.68,100,1,10.61,200,2,11.27,100,1,11.4,100,1,11.76,100,1,11.93,200,2,12.1,100,1,12.2,200,2,12.33,100,1,13.7,100,1,13.85,2,1,13.97,100,1,14.28,100,1,14.46,100,1,14.48,700,1,14.49,100,1,14.52,200,2,14.56,800,2,14.6,700,1,ARL,332385317
2025-07-17T16:07:28.700981149Z,2025-07-17T16:07:28.700815737Z,160,2,1108,C,A,13.700000000,100,0,332385325,130,165412,277019711,ARL,0,13.7,100,130,165412,277019711,9.55,1700,17,9.68,100,1,10.61,200,2,11.27,100,1,11.4,100,1,11.76,100,1,11.93,200,2,12.1,100,1,12.2,200,2,12.33,100,1,13.85,2,1,13.97,100,1,14.28,100,1,14.46,100,1,14.48,700,1,14.49,100,1,14.52,200,2,14.56,800,2,14.6,700,1,14.66,200,2,ARL,332385325
2025-07-17T16:07:28.701396669Z,2025-07-17T16:07:28.701230409Z,160,2,1108,C,B,12.900000000,2,0,331694297,0,166260,277019718,ARL,0,12.9,2,0,166260,277019718,9.55,1700,17,9.68,100,1,10.61,200,2,11.27,100,1,11.4,100,1,11.76,100,1,11.93,200,2,12.1,100,1,12.2,200,2,12.33,100,1,13.85,2,1,13.97,100,1,14.28,100,1,14.46,100,1,14.48,700,1,14.49,100,1,14.52,200,2,14.56,800,2,14.6,700,1,14.66,200,2,ARL,331694297
2025-07-17T16:07:28.701396669Z,2025-07-17T16:07:28.701230409Z,160,2,1108,A,B,13.010000000,2,0,332494213,130,166260,277019718,ARL,0,13.01,2,130,166260,277019718,9.55,1700,17,9.68,100,1,10.61,200,2,11.27,100,1,11.4,100,1,11.76,100,1,11.93,200,2,12.1,100,1,12.2,200,2,12.33,100,1,13.85,2,1,13.97,100,1,14.28,100,1,14.46,100,1,14.48,700,1,14.49,100,1,14.52,200,2,14.56,800,2,14.6,700,1,14.66,200,2,ARL,332494213
2025-07-17T16:07:28.701713232Z,2025-07-17T16:07:28.701547540Z,160,2,1108,C,A,14.760000000,100,0,332385501,0,165692,277019720,ARL,0,14.76,100,0,165692,277019720,9.55,1700,17,9.68,100,1,10.61,200,2,11.27,100,1,11.4,100,1,11.76,100,1,11.93,200,2,12.1,100,1,12.2,200,2,12.33,100,1,13.85,2,1,13.97,100,1,14.28,100,1,14.46,100,1,14.48,700,1,14.49,100,1,14.52,200,2,14.56,800,2,14.6,700,1,14.66,200,2,ARL,332385501
2025-07-17T16:07:28.701713232Z,2025-07-17T16:07:28.701547540Z,160,2,1108,A,A,14.820000000,100,0,332494229,130,165692,277019720,ARL,0,14.82,100,130,165692,277019720,9.55,1700,17,9.68,100,1,10.61,200,2,11.27,100,1,11.4,100,1,11.76,100,1,11.93,200,2,12.1,100,1,12.2,200,2,12.33,100,1,13.85,2,1,13.97,100,1,14.28,100,1,14.46,100,1,14.48,700,1,14.49,100,1,14.52,200,2,14.56,800,2,14.6,700,1,14.66,200,2,ARL,332494229
2025-07-17T16:07:28.702166297Z,2025-07-17T16:07:28.702000772Z,160,2,1108,C,A,15.760000000,100,0,332385585,0,165525,277019722,ARL,0,15.76,100,0,165525,277019722,9.55,1700,17,9.68,100,1,10.61,200,2,11.27,100,1,11.4,100,1,11.76,100,1,11.93,200,2,12.1,100,1,12.2,200,2,12.33,100,1,13.85,2,1,13.97,100,1,14.28,100,1,14.46,100,1,14.48,700,1,14.49,100,1,14.52,200,2,14.56,800,2,14.6,700,1,14.66,200,2,ARL,332385585
2025-07-17T16:07:28.702166297Z,2025-07-17T16:07:28.702000772Z,160,2,1108,A,A,16.010000000,100,0,332494245,130,165525,277019722,ARL,0,16.01,100,130,165525,277019722,9.55,1700,17,9.68,100,1,10.61,200,2,11.27,100,1,11.4,100,1,11.76,100,1,11.93,200,2,12.1,100,1,12.2,200,2,12.33,100,1,13.85,2,1,13.97,100,1,14.28,100,1,14.46,100,1,14.48,700,1,14.49,100,1,14.52,200,2,14.56,800,2,14.6,700,1,14.66,200,2,ARL,332494245
2025-07-17T16:07:28.702642020Z,2025-07-17T16:07:28.702476699Z,160,2,1108,C,A,14.660000000,100,0,332386121,0,165321,277019729,ARL,0,14.66,100,0,165321,277019729,9.55,1700,17,9.68,100,1,10.61,200,2,11.27,100,1,11.4,100,1,11.76,100,1,11.93,200,2,12.1,100,1,12.2,200,2,12.33,100,1,13.85,2,1,13.97,100,1,14.28,100,1,14.46,100,1,14.48,700,1,14.49,100,1,14.52,200,2,14.56,800,2,14.6,700,1,14.66,100,1,ARL,332386121
2025-07-17T16:07:28.702642020Z,2025-07-17T16:07:28.702476699Z,160,2,1108,A,A,14.950000000,100,0,332494281,130,165321,277019729,ARL,0,14.95,100,130,165321,277019729,9.55,1700,17,9.68,100,1,10.61,200,2,11.27,100,1,11.4,100,1,11.76,100,1,11.93,200,2,12.1,100,1,12.2,200,2,12.33,100,1,13.85,2,1,13.97,100,1,14.28,100,1,14.46,100,1,14.48,700,1,14.49,100,1,14.52,200,2,14.56,800,2,14.6,700,1,14.66,100,1,ARL,332494281
2025-07-17T16:07:28.703523092Z,2025-07-17T16:07:28.703357714Z,160,2,1108,C,A,14.660000000,100,0,332385565,0,165378,277019733,ARL,0,14.66,100,0,165378,277019733,9.55,1700,17,9.68,100,1,10.61,200,2,11.27,100,1,11.4,100,1,11.76,100,1,11.93,200,2,12.1,100,1,12.2,200,2,12.33,100,1,13.85,2,1,13.97,100,1,14.28,100,1,14.46,100,1,14.48,700,1,14.49,100,1,14.52,200,2,14.56,800,2,14.6,700,1,14.68,700,1,ARL,332385565
2025-07-17T16:07:28.703523092Z,2025-07-17T16:07:28.703357714Z,160,2,1108,A,A,14.950000000,100,0,332494285,130,165378,277019733,ARL,0,14.95,100,130,165378,277019733,9.55,1700,17,9.68,100,1,10.61,200,2,11.27,100,1,11.4,100,1,11.76,100,1,11.93,200,2,12.1,100,1,12.2,200,2,12.33,100,1,13.85,2,1,13.97,100,1,14.28,100,1,14.46,100,1,14.48,700,1,14.49,100,1,14.52,200,2,14.56,800,2,14.6,700,1,14.68,700,1,ARL,332494285
2025-07-17T16:07:28.703920336Z,2025-07-17T16:07:28.703754662Z,160,2,1108,C,A,15.070000000,100,0,332385569,0,165674,277019735,ARL,0,15.07,100,0,165674,277019735,9.55,1700,17,9.68,100,1,10.61,200,2,11.27,100,1,11.4,100,1,11.76,100,1,11.93,200,2,12.1,100,1,12.2,200,2,12.33,100,1,13.85,2,1,13.97,100,1,14.28,100,1,14.46,100,1,14.48,700,1,14.49,100,1,14.52,200,2,14.56,800,2,14.6,700,1,14.68,700,1,ARL,332385569
2025-07-17T16:07:28.703920336Z,2025-07-17T16:07:28.703754662Z,160,2,1108,A,A,15.370000000,100,0,332494289,130,165674,277019735,ARL,0,15.37,100,130,165674,277019735,9.55,1700,17,9.68,100,1,10.61,200,2,11.27,100,1,11.4,100,1,11.76,100,1,11.93,200,2,12.1,100,1,12.2,200,2,12.33,100,1,13.85,2,1,13.97,100,1,14.28,100,1,14.46,100,1,14.48,700,1,14.49,100,1,14.52,200,2,14.56,800,2,14.6,700,1,14.68,700,1,ARL,332494289
2025-07-17T16:07:28.704198103Z,2025-07-17T16:07:28.704032725Z,160,2,1108,C,A,17.400000000,100,0,332385593,0,165378,277019738,ARL,0,17.4,100,0,165378,277019738,9.55,1700,17,9.68,100,1,10.61,200,2,11.27,100,1,11.4,100,1,11.76,100,1,11.93,200,2,12.1,100,1,12.2,200,2,12.33,100,1,13.85,2,1,13.97,100,1,14.28,100,1,14.46,100,1,14.48,700,1,14.49,100,1,14.52,200,2,14.56,800,2,14.6,700,1,14.68,700,1,ARL,332385593
2025-07-17T16:07:28.704198103Z,2025-07-17T16:07:28.704032725Z,160,2,1108,A,A,17.750000000,100,0,332494297,130,165378,277019738,ARL,0,17.75,100,130,165378,277019738,9.55,1700,17,9.68,100,1,10.61,200,2,11.27,100,1,11.4,100,1,11.76,100,1,11.93,200,2,12.1,100,1,12.2,200,2,12.33,100,1,13.85,2,1,13.97,100,1,14.28,100,1,14.46,100,1,14.48,700,1,14.49,100,1,14.52,200,2,14.56,800,2,14.6,700,1,14.68,700,1,ARL,332494297
2025-07-17T16:07:28.724201840Z,2025-07-17T16:07:28.724036175Z,160,2,1108,C,A,13.970000000,100,0,332385613,130,165665,277019926,ARL,0,13.97,100,130,165665,277019926,9.55,1700,17,9.68,100,1,10.61,200,2,11.27,100,1,11.4,100,1,11.76,100,1,11.93,200,2,12.1,100,1,12.2,200,2,12.33,100,1,13.85,2,1,14.28,100,1,14.46,100,1,14.48,700,1,14.49,100,1,14.52,200,2,14.56,800,2,14.6,700,1,14.68,700,1,14.82,100,1,ARL,332385613
2025-07-17T16:07:28.724250835Z,2025-07-17T16:07:28.724085453Z,160,2,1108,A,A,14.200000000,100,0,332494893,130,165382,277019929,ARL,0,14.2,100,130,165382,277019929,9.55,1700,17,9.68,100,1,10.61,200,2,11.27,100,1,11.4,100,1,11.76,100,1,11.93,200,2,12.1,100,1,12.2,200,2,12.33,100,1,13.85,2,1,14.2,100,1,14.28,100,1,14.46,100,1,14.48,700,1,14.49,100,1,14.52,200,2,14.56,800,2,14.6,700,1,14.68,700,1,ARL,332494893
2025-07-17T16:07:28.751828120Z,2025-07-17T16:07:28.751662660Z,160,2,1108,C,A,14.820000000,100,0,332494229,0,165460,277020284,ARL,0,14.82,100,0,165460,277020284,9.55,1700,17,9.68,100,1,10.61,200,2,11.27,100,1,11.4,100,1,11.76,100,1,11.93,200,2,12.1,100,1,12.2,200,2,12.33,100,1,13.85,2,1,14.2,100,1,14.28,100,1,14.46,100,1,14.48,700,1,14.49,100,1,14.52,200,2,14.56,800,2,14.6,700,1,14.68,700,1,ARL,332494229
2025-07-17T16:07:28.751828120Z,2025-07-17T16:07:28.751662660Z,160,2,1108,A,A,15.050000000,100,0,332495781,130,165460,277020284,ARL,0,15.05,100,130,165460,277020284,9.55,1700,17,9.68,100,1,10.61,200,2,11.27,100,1,11.4,100,1,11.76,100,1,11.93,200,2,12.1,100,1,12.2,200,2,12.33,100,1,13.85,2,1,14.2,100,1,14.28,100,1,14.46,100,1,14.48,700,1,14.49,100,1,14.52,200,2,14.56,800,2,14.6,700,1,14.68,700,1,ARL,332495781
2025-07-17T16:07:28.831160987Z,2025-07-17T16:07:28.830995364Z,160,2,1108,C,A,14.490000000,100,0,332385597,130,165623,277021007,ARL,0,14.49,100,130,165623,277021007,9.55,1700,17,9.68,100,1,10.61,200,2,11.27,100,1,11.4,100,1,11.76,100,1,11.93,200,2,12.1,100,1,12.2,200,2,12.33,100,1,13.85,2,1,14.2,100,1,14.28,100,1,14.46,100,1,14.48,700,1,14.52,200,2,14.56,800,2,14.6,700,1,14.68,700,1,14.95,200,2,ARL,332385597
2025-07-17T16:07:28.831291377Z,2025-07-17T16:07:28.831125667Z,160,2,1108,A,A,14.770000000,100,0,332497653,130,165710,277021012,ARL,0,14.77,100,130,165710,277021012,9.55,1700,17,9.68,100,1,10.61,200,2,11.27,100,1,11.4,100,1,11.76,100,1,11.93,200,2,12.1,100,1,12.2,200,2,12.33,100,1,13.85,2,1,14.2,100,1,14.28,100,1,14.46,100,1,14.48,700,1,14.52,200,2,14.56,800,2,14.6,700,1,14.68,700,1,14.77,100,1,ARL,332497653
2025-07-17T16:07:29.214667270Z,2025-07-17T16:07:29.214500816Z,160,2,1108,A,A,13.860000000,100,0,332508813,128,166454,277029015,ARL,0,13.86,100,128,166454,277029015,9.55,1700,17,9.68,100,1,10.61,200,2,11.27,100,1,11.4,100,1,11.76,100,1,11.93,200,2,12.1,100,1,12.2,200,2,12.33,100,1,13.85,2,1,13.86,100,1,14.2,100,1,14.28,100,1,14.46,100,1,14.48,700,1,14.52,200,2,14.56,800,2,14.6,700,1,14.68,700,1,ARL,332508813
2025-07-17T16:07:29.215458844Z,2025-07-17T16:07:29.215292291Z,160,2,1108,C,A,15.050000000,100,0,332495781,0,166553,277029273,ARL,0,15.05,100,0,166553,277029273,9.55,1700,17,9.68,100,1,10.61,200,2,11.27,100,1,11.4,100,1,11.76,100,1,11.93,200,2,12.1,100,1,12.2,200,2,12.33,100,1,13.85,2,1,13.86,100,1,14.2,100,1,14.28,100,1,14.46,100,1,14.48,700,1,14.52,200,2,14.56,800,2,14.6,700,1,14.68,700,1,ARL,332495781
2025-07-17T16:07:29.215458844Z,2025-07-17T16:07:29.215292291Z,160,2,1108,A,A,14.930000000,100,0,332508997,128,166553,277029273,ARL,0,14.93,100,128,166553,277029273,9.55,1700,17,9.68,100,1,10.61,200,2,11.27,100,1,11.4,100,1,11.76,100,1,11.93,200,2,12.1,100,1,12.2,200,2,12.33,100,1,13.85,2,1,13.86,100,1,14.2,100,1,14.28,100,1,14.46,100,1,14.48,700,1,14.52,200,2,14.56,800,2,14.6,700,1,14.68,700,1,ARL,332508997
2025-07-17T16:08:20.816252850Z,2025-07-17T16:08:20.816087447Z,160,2,1108,A,A,13.680000000,15,0,333436357,130,165403,277732167,ARL,0,13.68,15,130,165403,277732167,9.55,1700,17,9.68,100,1,10.61,200,2,11.27,100,1,11.4,100,1,11.76,100,1,11.93,200,2,12.1,100,1,12.2,200,2,12.33,100,1,13.68,15,1,13.85,2,1,13.86,100,1,14.2,100,1,14.28,100,1,14.46,100,1,14.48,700,1,14.52,200,2,14.56,800,2,14.6,700,1,ARL,333436357
2025-07-17T16:08:20.816366205Z,2025-07-17T16:08:20.816200644Z,160,2,1108,C,A,13.860000000,100,0,332508813,0,165561,277732170,ARL,0,13.86,100,0,165561,277732170,9.55,1700,17,9.68,100,1,10.61,200,2,11.27,100,1,11.4,100,1,11.76,100,1,11.93,200,2,12.1,100,1,12.2,200,2,12.33,100,1,13.68,15,1,13.85,2,1,14.2,100,1,14.28,100,1,14.46,100,1,14.48,700,1,14.52,200,2,14.56,800,2,14.6,700,1,14.68,700,1,ARL,332508813
2025-07-17T16:08:20.816366205Z,2025-07-17T16:08:20.816200644Z,160,2,1108,A,A,13.690000000,100,0,333436361,130,165561,277732170,ARL,0,13.69,100,130,165561,277732170,9.55,1700,17,9.68,100,1,10.61,200,2,11.27,100,1,11.4,100,1,11.76,100,1,11.93,200,2,12.1,100,1,12.2,200,2,12.33,100,1,13.68,15,1,13.69,100,1,13.85,2,1,14.2,100,1,14.28,100,1,14.46,100,1,14.48,700,1,14.52,200,2,14.56,800,2,14.6,700,1,ARL,333436361
2025-07-17T16:08:20.817097587Z,2025-07-17T16:08:20.816932150Z,160,2,1108,C,A,14.930000000,100,0,332508997,0,165437,277732194,ARL,0,14.93,100,0,165437,277732194,9.55,1700,17,9.68,100,1,10.61,200,2,11.27,100,1,11.4,100,1,11.76,100,1,11.93,200,2,12.1,100,1,12.2,200,2,12.33,100,1,13.68,15,1,13.69,100,1,13.85,2,1,14.2,100,1,14.28,100,1,14.46,100,1,14.48,700,1,14.52,200,2,14.56,800,2,14.6,700,1,ARL,332508997
2025-07-17T16:08:20.817097587Z,2025-07-17T16:08:20.816932150Z,160,2,1108,A,A,14.750000000,100,0,333436397,130,165437,277732194,ARL,0,14.75,100,130,165437,277732194,9.55,1700,17,9.68,100,1,10.61,200,2,11.27,100,1,11.4,100,1,11.76,100,1,11.93,200,2,12.1,100,1,12.2,200,2,12.33,100,1,13.68,15,1,13.69,100,1,13.85,2,1,14.2,100,1,14.28,100,1,14.46,100,1,14.48,700,1,14.52,200,2,14.56,800,2,14.6,700,1,ARL,333436397
2025-07-17T16:08:20.818725102Z,2025-07-17T16:08:20.818559377Z,160,2,1108,C,A,15.370000000,100,0,332494289,0,165725,277732213,ARL,0,15.37,100,0,165725,277732213,9.55,1700,17,9.68,100,1,10.61,200,2,11.27,100,1,11.4,100,1,11.76,100,1,11.93,200,2,12.1,100,1,12.2,200,2,12.33,100,1,13.68,15,1,13.69,100,1,13.85,2,1,14.2,100,1,14.28,100,1,14.46,100,1,14.48,700,1,14.52,200,2,14.56,800,2,14.6,700,1,ARL,332494289
2025-07-17T16:08:20.818725102Z,2025-07-17T16:08:20.818559377Z,160,2,1108,A,A,15.060000000,100,0,333436421,130,165725,277732213,ARL,0,15.06,100,130,165725,277732213,9.55,1700,17,9.68,100,1,10.61,200,2,11.27,100,1,11.4,100,1,11.76,100,1,11.93,200,2,12.1,100,1,12.2,200,2,12.33,100,1,13.68,15,1,13.69,100,1,13.85,2,1,14.2,100,1,14.28,100,1,14.46,100,1,14.48,700,1,14.52,200,2,14.56,800,2,14.6,700,1,ARL,333436421
2025-07-17T16:08:20.819130820Z,2025-07-17T16:08:20.818965359Z,160,2,1108,C,A,14.950000000,100,0,332494285,0,165461,277732216,ARL,0,14.95,100,0,165461,277732216,9.55,1700,17,9.68,100,1,10.61,200,2,11.27,100,1,11.4,100,1,11.76,100,1,11.93,200,2,12.1,100,1,12.2,200,2,12.33,100,1,13.68,15,1,13.69,100,1,13.85,2,1,14.2,100,1,14.28,100,1,14.46,100,1,14.48,700,1,14.52,200,2,14.56,800,2,14.6,700,1,ARL,332494285
2025-07-17T16:08:20.819130820Z,2025-07-17T16:08:20.818965359Z,160,2,1108,A,A,14.650000000,100,0,333436425,130,165461,277732216,ARL,0,14.65,100,130,165461,277732216,9.55,1700,17,9.68,100,1,10.61,200,2,11.27,100,1,11.4,100,1,11.76,100,1,11.93,200,2,12.1,100,1,12.2,200,2,12.33,100,1,13.68,15,1,13.69,100,1,13.85,2,1,14.2,100,1,14.28,100,1,14.46,100,1,14.48,700,1,14.52,200,2,14.56,800,2,14.6,700,1,ARL,333436425
2025-07-17T16:08:20.819767091Z,2025-07-17T16:08:20.819601669Z,160,2,1108,C,A,17.750000000,100,0,332494297,0,165422,277732221,ARL,0,17.75,100,0,165422,277732221,9.55,1700,17,9.68,100,1,10.61,200,2,11.27,100,1,11.4,100,1,11.76,100,1,11.93,200,2,12.1,100,1,12.2,200,2,12.33,100,1,13.68,15,1,13.69,100,1,13.85,2,1,14.2,100,1,14.28,100,1,14.46,100,1,14.48,700,1,14.52,200,2,14.56,800,2,14.6,700,1,ARL,332494297
2025-07-17T16:08:20.819767091Z,2025-07-17T16:08:20.819601669Z,160,2,1108,A,A,17.390000000,100,0,333436441,130,165422,277732221,ARL,0,17.39,100,130,165422,277732221,9.55,1700,17,9.68,100,1,10.61,200,2,11.27,100,1,11.4,100,1,11.76,100,1,11.93,200,2,12.1,100,1,12.2,200,2,12.33,100,1,13.68,15,1,13.69,100,1,13.85,2,1,14.2,100,1,14.28,100,1,14.46,100,1,14.48,700,1,14.52,200,2,14.56,800,2,14.6,700,1,ARL,333436441
2025-07-17T16:08:20.820666169Z,2025-07-17T16:08:20.820500575Z,160,2,1108,C,A,16.010000000,100,0,332494245,0,165594,277732228,ARL,0,16.01,100,0,165594,277732228,9.55,1700,17,9.68,100,1,10.61,200,2,11.27,100,1,11.4,100,1,11.76,100,1,11.93,200,2,12.1,100,1,12.2,200,2,12.33,100,1,13.68,15,1,13.69,100,1,13.85,2,1,14.2,100,1,14.28,100,1,14.46,100,1,14.48,700,1,14.52,200,2,14.56,800,2,14.6,700,1,ARL,332494245
2025-07-17T16:08:20.820666169Z,2025-07-17T16:08:20.820500575Z,160,2,1108,A,A,15.750000000,100,0,333436449,130,165594,277732228,ARL,0,15.75,100,130,165594,277732228,9.55,1700,17,9.68,100,1,10.61,200,2,11.27,100,1,11.4,100,1,11.76,100,1,11.93,200,2,12.1,100,1,12.2,200,2,12.33,100,1,13.68,15,1,13.69,100,1,13.85,2,1,14.2,100,1,14.28,100,1,14.46,100,1,14.48,700,1,14.52,200,2,14.56,800,2,14.6,700,1,ARL,333436449
2025-07-17T16:08:20.822089544Z,2025-07-17T16:08:20.821924168Z,160,2,1108,C,A,14.200000000,100,0,332494893,130,165376,277732239,ARL,0,14.2,100,130,165376,277732239,9.55,1700,17,9.68,100,1,10.61,200,2,11.27,100,1,11.4,100,1,11.76,100,1,11.93,200,2,12.1,100,1,12.2,200,2,12.33,100,1,13.68,15,1,13.69,100,1,13.85,2,1,14.28,100,1,14.46,100,1,14.48,700,1,14.52,200,2,14.56,800,2,14.6,700,1,14.65,100,1,ARL,332494893
2025-07-17T16:08:20.822139541Z,2025-07-17T16:08:20.821974299Z,160,2,1108,A,A,13.960000000,100,0,333436473,130,165242,277732240,ARL,0,13.96,100,130,165242,277732240,9.55,1700,17,9.68,100,1,10.61,200,2,11.27,100,1,11.4,100,1,11.76,100,1,11.93,200,2,12.1,100,1,12.2,200,2,12.33,100,1,13.68,15,1,13.69,100,1,13.85,2,1,13.96,100,1,14.28,100,1,14.46,100,1,14.48,700,1,14.52,200,2,14.56,800,2,14.6,700,1,ARL,333436473
2025-07-17T16:08:20.830110499Z,2025-07-17T16:08:20.829945074Z,160,2,1108,C,A,14.950000000,100,0,332494281,0,165425,277732299,ARL,0,14.95,100,0,165425,277732299,9.55,1700,17,9.68,100,1,10.61,200,2,11.27,100,1,11.4,100,1,11.76,100,1,11.93,200,2,12.1,100,1,12.2,200,2,12.33,100,1,13.68,15,1,13.69,100,1,13.85,2,1,13.96,100,1,14.28,100,1,14.46,100,1,14.48,700,1,14.52,200,2,14.56,800,2,14.6,700,1,ARL,332494281
2025-07-17T16:08:20.830110499Z,2025-07-17T16:08:20.829945074Z,160,2,1108,A,A,14.650000000,100,0,333436589,130,165425,277732299,ARL,0,14.65,100,130,165425,277732299,9.55,1700,17,9.68,100,1,10.61,200,2,11.27,100,1,11.4,100,1,11.76,100,1,11.93,200,2,12.1,100,1,12.2,200,2,12.33,100,1,13.68,15,1,13.69,100,1,13.85,2,1,13.96,100,1,14.28,100,1,14.46,100,1,14.48,700,1,14.52,200,2,14.56,800,2,14.6,700,1,ARL,333436589
2025-07-17T16:08:20.966229266Z,2025-07-17T16:08:20.966063681Z,160,2,1108,C,A,14.770000000,100,0,332497653,0,165585,277733304,ARL,0,14.77,100,0,165585,277733304,9.55,1700,17,9.68,100,1,10.61,200,2,11.27,100,1,11.4,100,1,11.76,100,1,11.93,200,2,12.1,100,1,12.2,200,2,12.33,100,1,13.68,15,1,13.69,100,1,13.85,2,1,13.96,100,1,14.28,100,1,14.46,100,1,14.48,700,1,14.52,200,2,14.56,800,2,14.6,700,1,ARL,332497653
2025-07-17T16:08:20.966229266Z,2025-07-17T16:08:20.966063681Z,160,2,1108,A,A,14.480000000,100,0,333438545,130,165585,277733304,ARL,0,14.48,100,130,165585,277733304,9.55,1700,17,9.68,100,1,10.61,200,2,11.27,100,1,11.4,100,1,11.76,100,1,11.93,200,2,12.1,100,1,12.2,200,2,12.33,100,1,13.68,15,1,13.69,100,1,13.85,2,1,13.96,100,1,14.28,100,1,14.46,100,1,14.48,800,2,14.52,200,2,14.56,800,2,14.6,700,1,ARL,333438545
2025-07-17T16:08:22.998168186Z,2025-07-17T16:08:22.998002821Z,160,2,1108,C,A,13.680000000,15,0,333436357,130,165365,277766492,ARL,0,13.68,15,130,165365,277766492,9.55,1700,17,9.68,100,1,10.61,200,2,11.27,100,1,11.4,100,1,11.76,100,1,11.93,200,2,12.1,100,1,12.2,200,2,12.33,100,1,13.69,100,1,13.85,2,1,13.96,100,1,14.28,100,1,14.46,100,1,14.48,800,2,14.52,200,2,14.56,800,2,14.6,700,1,14.65,200,2,ARL,333436357
2025-07-17T16:08:27.482509684Z,2025-07-17T16:08:27.482344236Z,160,2,1108,C,A,13.690000000,100,0,333436361,130,165448,277841171,ARL,0,13.69,100,130,165448,277841171,9.55,1700,17,9.68,100,1,10.61,200,2,11.27,100,1,11.4,100,1,11.76,100,1,11.93,200,2,12.1,100,1,12.2,200,2,12.33,100,1,13.85,2,1,13.96,100,1,14.28,100,1,14.46,100,1,14.48,800,2,14.52,200,2,14.56,800,2,14.6,700,1,14.65,200,2,14.68,700,1,ARL,333436361
2025-07-17T16:08:27.483241007Z,2025-07-17T16:08:27.483075481Z,160,2,1108,C,A,14.750000000,100,0,333436397,0,165526,277841175,ARL,0,14.75,100,0,165526,277841175,9.55,1700,17,9.68,100,1,10.61,200,2,11.27,100,1,11.4,100,1,11.76,100,1,11.93,200,2,12.1,100,1,12.2,200,2,12.33,100,1,13.85,2,1,13.96,100,1,14.28,100,1,14.46,100,1,14.48,800,2,14.52,200,2,14.56,800,2,14.6,700,1,14.65,200,2,14.68,700,1,ARL,333436397
2025-07-17T16:08:27.483241007Z,2025-07-17T16:08:27.483075481Z,160,2,1108,A,A,14.990000000,100,0,333581389,130,165526,277841175,ARL,0,14.99,100,130,165526,277841175,9.55,1700,17,9.68,100,1,10.61,200,2,11.27,100,1,11.4,100,1,11.76,100,1,11.93,200,2,12.1,100,1,12.2,200,2,12.33,100,1,13.85,2,1,13.96,100,1,14.28,100,1,14.46,100,1,14.48,800,2,14.52,200,2,14.56,800,2,14.6,700,1,14.65,200,2,14.68,700,1,ARL,333581389
2025-07-17T16:08:27.483585892Z,2025-07-17T16:08:27.483420069Z,160,2,1108,C,A,14.520000000,100,0,328780577,0,165823,277841178,ARL,0,14.52,100,0,165823,277841178,9.55,1700,17,9.68,100,1,10.61,200,2,11.27,100,1,11.4,100,1,11.76,100,1,11.93,200,2,12.1,100,1,12.2,200,2,12.33,100,1,13.85,2,1,13.96,100,1,14.28,100,1,14.46,100,1,14.48,800,2,14.52,100,1,14.56,800,2,14.6,700,1,14.65,200,2,14.68,700,1,ARL,328780577
2025-07-17T16:08:27.483585892Z,2025-07-17T16:08:27.483420069Z,160,2,1108,A,A,14.740000000,100,0,333581393,130,165823,277841178,ARL,0,14.74,100,130,165823,277841178,9.55,1700,17,9.68,100,1,10.61,200,2,11.27,100,1,11.4,100,1,11.76,100,1,11.93,200,2,12.1,100,1,12.2,200,2,12.33,100,1,13.85,2,1,13.96,100,1,14.28,100,1,14.46,100,1,14.48,800,2,14.52,100,1,14.56,800,2,14.6,700,1,14.65,200,2,14.68,700,1,ARL,333581393
2025-07-17T16:08:27.484079224Z,2025-07-17T16:08:27.483913735Z,160,2,1108,C,A,14.650000000,100,0,333436589,0,165489,277841218,ARL,0,14.65,100,0,165489,277841218,9.55,1700,17,9.68,100,1,10.61,200,2,11.27,100,1,11.4,100,1,11.76,100,1,11.93,200,2,12.1,100,1,12.2,200,2,12.33,100,1,13.85,2,1,13.96,100,1,14.28,100,1,14.46,100,1,14.48,800,2,14.52,100,1,14.56,800,2,14.6,700,1,14.65,100,1,14.68,700,1,ARL,333436589
2025-07-17T16:08:27.484079224Z,2025-07-17T16:08:27.483913735Z,160,2,1108,A,A,14.940000000,100,0,333581409,130,165489,277841218,ARL,0,14.94,100,130,165489,277841218,9.55,1700,17,9.68,100,1,10.61,200,2,11.27,100,1,11.4,100,1,11.76,100,1,11.93,200,2,12.1,100,1,12.2,200,2,12.33,100,1,13.85,2,1,13.96,100,1,14.28,100,1,14.46,100,1,14.48,800,2,14.52,100,1,14.56,800,2,14.6,700,1,14.65,100,1,14.68,700,1,ARL,333581409
2025-07-17T16:08:27.484859188Z,2025-07-17T16:08:27.484693568Z,160,2,1108,C,A,17.390000000,100,0,333436441,0,165620,277841226,ARL,0,17.39,100,0,165620,277841226,9.55,1700,17,9.68,100,1,10.61,200,2,11.27,100,1,11.4,100,1,11.76,100,1,11.93,200,2,12.1,100,1,12.2,200,2,12.33,100,1,13.85,2,1,13.96,100,1,14.28,100,1,14.46,100,1,14.48,800,2,14.52,100,1,14.56,800,2,14.6,700,1,14.65,100,1,14.68,700,1,ARL,333436441
2025-07-17T16:08:27.484859188Z,2025-07-17T16:08:27.484693568Z,160,2,1108,A,A,17.730000000,100,0,333581425,130,165620,277841226,ARL,0,17.73,100,130,165620,277841226,9.55,1700,17,9.68,100,1,10.61,200,2,11.27,100,1,11.4,100,1,11.76,100,1,11.93,200,2,12.1,100,1,12.2,200,2,12.33,100,1,13.85,2,1,13.96,100,1,14.28,100,1,14.46,100,1,14.48,800,2,14.52,100,1,14.56,800,2,14.6,700,1,14.65,100,1,14.68,700,1,ARL,333581425
2025-07-17T16:08:27.484965957Z,2025-07-17T16:08:27.484800296Z,160,2,1108,C,A,14.650000000,100,0,333436425,0,165661,277841228,ARL,0,14.65,100,0,165661,277841228,9.55,1700,17,9.68,100,1,10.61,200,2,11.27,100,1,11.4,100,1,11.76,100,1,11.93,200,2,12.1,100,1,12.2,200,2,12.33,100,1,13.85,2,1,13.96,100,1,14.28,100,1,14.46,100,1,14.48,800,2,14.52,100,1,14.56,800,2,14.6,700,1,14.68,700,1,14.74,100,1,ARL,333436425
2025-07-17T16:08:27.484965957Z,2025-07-17T16:08:27.484800296Z,160,2,1108,A,A,14.940000000,100,0,333581429,130,165661,277841228,ARL,0,14.94,100,130,165661,277841228,9.55,1700,17,9.68,100,1,10.61,200,2,11.27,100,1,11.4,100,1,11.76,100,1,11.93,200,2,12.1,100,1,12.2,200,2,12.33,100,1,13.85,2,1,13.96,100,1,14.28,100,1,14.46,100,1,14.48,800,2,14.52,100,1,14.56,800,2,14.6,700,1,14.68,700,1,14.74,100,1,ARL,333581429
2025-07-17T16:08:27.484978859Z,2025-07-17T16:08:27.484813280Z,160,2,1108,C,A,15.750000000,100,0,333436449,0,165579,277841229,ARL,0,15.75,100,0,165579,277841229,9.55,1700,17,9.68,100,1,10.61,200,2,11.27,100,1,11.4,100,1,11.76,100,1,11.93,200,2,12.1,100,1,12.2,200,2,12.33,100,1,13.85,2,1,13.96,100,1,14.28,100,1,14.46,100,1,14.48,800,2,14.52,100,1,14.56,800,2,14.6,700,1,14.68,700,1,14.74,100,1,ARL,333436449
2025-07-17T16:08:27.484978859Z,2025-07-17T16:08:27.484813280Z,160,2,1108,A,A,16.060000000,100,0,333581433,130,165579,277841229,ARL,0,16.06,100,130,165579,277841229,9.55,1700,17,9.68,100,1,10.61,200,2,11.27,100,1,11.4,100,1,11.76,100,1,11.93,200,2,12.1,100,1,12.2,200,2,12.33,100,1,13.85,2,1,13.96,100,1,14.28,100,1,14.46,100,1,14.48,800,2,14.52,100,1,14.56,800,2,14.6,700,1,14.68,700,1,14.74,100,1,ARL,333581433
2025-07-17T16:08:27.485352204Z,2025-07-17T16:08:27.485186411Z,160,2,1108,C,A,15.060000000,100,0,333436421,0,165793,277841231,ARL,0,15.06,100,0,165793,277841231,9.55,1700,17,9.68,100,1,10.61,200,2,11.27,100,1,11.4,100,1,11.76,100,1,11.93,200,2,12.1,100,1,12.2,200,2,12.33,100,1,13.85,2,1,13.96,100,1,14.28,100,1,14.46,100,1,14.48,800,2,14.52,100,1,14.56,800,2,14.6,700,1,14.68,700,1,14.74,100,1,ARL,333436421
2025-07-17T16:08:27.485352204Z,2025-07-17T16:08:27.485186411Z,160,2,1108,A,A,15.360000000,100,0,333581441,130,165793,277841231,ARL,0,15.36,100,130,165793,277841231,9.55,1700,17,9.68,100,1,10.61,200,2,11.27,100,1,11.4,100,1,11.76,100,1,11.93,200,2,12.1,100,1,12.2,200,2,12.33,100,1,13.85,2,1,13.96,100,1,14.28,100,1,14.46,100,1,14.48,800,2,14.52,100,1,14.56,800,2,14.6,700,1,14.68,700,1,14.74,100,1,ARL,333581441
2025-07-17T16:08:27.487263276Z,2025-07-17T16:08:27.487097702Z,160,2,1108,C,A,14.520000000,100,0,328780597,0,165574,277841319,ARL,0,14.52,100,0,165574,277841319,9.55,1700,17,9.68,100,1,10.61,200,2,11.27,100,1,11.4,100,1,11.76,100,1,11.93,200,2,12.1,100,1,12.2,200,2,12.33,100,1,13.85,2,1,13.96,100,1,14.28,100,1,14.46,100,1,14.48,800,2,14.56,800,2,14.6,700,1,14.68,700,1,14.74,100,1,14.94,200,2,ARL,328780597
2025-07-17T16:08:27.487263276Z,2025-07-17T16:08:27.487097702Z,160,2,1108,A,A,14.740000000,100,0,333581481,130,165574,277841319,ARL,0,14.74,100,130,165574,277841319,9.55,1700,17,9.68,100,1,10.61,200,2,11.27,100,1,11.4,100,1,11.76,100,1,11.93,200,2,12.1,100,1,12.2,200,2,12.33,100,1,13.85,2,1,13.96,100,1,14.28,100,1,14.46,100,1,14.48,800,2,14.56,800,2,14.6,700,1,14.68,700,1,14.74,200,2,14.94,200,2,ARL,333581481
2025-07-17T16:08:27.492258906Z,2025-07-17T16:08:27.492093401Z,160,2,1108,C,A,14.480000000,100,0,333438545,130,165505,277841396,ARL,0,14.48,100,130,165505,277841396,9.55,1700,17,9.68,100,1,10.61,200,2,11.27,100,1,11.4,100,1,11.76,100,1,11.93,200,2,12.1,100,1,12.2,200,2,12.33,100,1,13.85,2,1,13.96,100,1,14.28,100,1,14.46,100,1,14.48,700,1,14.56,800,2,14.6,700,1,14.68,700,1,14.74,200,2,14.94,200,2,ARL,333438545
2025-07-17T16:08:27.492385750Z,2025-07-17T16:08:27.492220454Z,160,2,1108,A,A,14.750000000,100,0,333581569,130,165296,277841397,ARL,0,14.75,100,130,165296,277841397,9.55,1700,17,9.68,100,1,10.61,200,2,11.27,100,1,11.4,100,1,11.76,100,1,11.93,200,2,12.1,100,1,12.2,200,2,12.33,100,1,13.85,2,1,13.96,100,1,14.28,100,1,14.46,100,1,14.48,700,1,14.56,800,2,14.6,700,1,14.68,700,1,14.74,200,2,14.75,100,1,ARL,333581569
2025-07-17T16:08:27.496936122Z,2025-07-17T16:08:27.496770678Z,160,2,1108,C,A,13.960000000,100,0,333436473,130,165444,277841427,ARL,0,13.96,100,130,165444,277841427,9.55,1700,17,9.68,100,1,10.61,200,2,11.27,100,1,11.4,100,1,11.76,100,1,11.93,200,2,12.1,100,1,12.2,200,2,12.33,100,1,13.85,2,1,14.28,100,1,14.46,100,1,14.48,700,1,14.56,800,2,14.6,700,1,14.68,700,1,14.74,200,2,14.75,100,1,14.94,200,2,ARL,333436473
2025-07-17T16:08:27.496987832Z,2025-07-17T16:08:27.496822540Z,160,2,1108,A,A,14.190000000,100,0,333581625,130,165292,277841428,ARL,0,14.19,100,130,165292,277841428,9.55,1700,17,9.68,100,1,10.61,200,2,11.27,100,1,11.4,100,1,11.76,100,1,11.93,200,2,12.1,100,1,12.2,200,2,12.33,100,1,13.85,2,1,14.19,100,1,14.28,100,1,14.46,100,1,14.48,700,1,14.56,800,2,14.6,700,1,14.68,700,1,14.74,200,2,14.75,100,1,ARL,333581625
2025-07-17T16:08:27.501093618Z,2025-07-17T16:08:27.500928061Z,160,2,1108,C,A,13.850000000,2,0,331155889,0,165557,277841469,ARL,0,13.85,2,0,165557,277841469,9.55,1700,17,9.68,100,1,10.61,200,2,11.27,100,1,11.4,100,1,11.76,100,1,11.93,200,2,12.1,100,1,12.2,200,2,12.33,100,1,14.19,100,1,14.28,100,1,14.46,100,1,14.48,700,1,14.56,800,2,14.6,700,1,14.68,700,1,14.74,200,2,14.75,100,1,14.94,200,2,ARL,331155889
2025-07-17T16:08:27.501093618Z,2025-07-17T16:08:27.500928061Z,160,2,1108,A,A,13.980000000,2,0,333581677,130,165557,277841469,ARL,0,13.98,2,130,165557,277841469,9.55,1700,17,9.68,100,1,10.61,200,2,11.27,100,1,11.4,100,1,11.76,100,1,11.93,200,2,12.1,100,1,12.2,200,2,12.33,100,1,13.98,2,1,14.19,100,1,14.28,100,1,14.46,100,1,14.48,700,1,14.56,800,2,14.6,700,1,14.68,700,1,14.74,200,2,14.75,100,1,ARL,333581677
2025-07-17T16:08:27.516614373Z,2025-07-17T16:08:27.516449334Z,160,2,1108,C,A,14.190000000,100,0,333581625,130,165039,277841551,ARL,0,14.19,100,130,165039,277841551,9.55,1700,17,9.68,100,1,10.61,200,2,11.27,100,1,11.4,100,1,11.76,100,1,11.93,200,2,12.1,100,1,12.2,200,2,12.33,100,1,13.98,2,1,14.28,100,1,14.46,100,1,14.48,700,1,14.56,800,2,14.6,700,1,14.68,700,1,14.74,200,2,14.75,100,1,14.94,200,2,ARL,333581625
2025-07-17T16:08:27.516662099Z,2025-07-17T16:08:27.516496962Z,160,2,1108,A,A,14.260000000,100,0,333581765,130,165137,277841552,ARL,0,14.26,100,130,165137,277841552,9.55,1700,17,9.68,100,1,10.61,200,2,11.27,100,1,11.4,100,1,11.76,100,1,11.93,200,2,12.1,100,1,12.2,200,2,12.33,100,1,13.98,2,1,14.26,100,1,14.28,100,1,14.46,100,1,14.48,700,1,14.56,800,2,14.6,700,1,14.68,700,1,14.74,200,2,14.75,100,1,ARL,333581765
2025-07-17T16:08:27.533938450Z,2025-07-17T16:08:27.533773259Z,160,2,1108,C,A,14.990000000,100,0,333581389,0,165191,277841588,ARL,0,14.99,100,0,165191,277841588,9.55,1700,17,9.68,100,1,10.61,200,2,11.27,100,1,11.4,100,1,11.76,100,1,11.93,200,2,12.1,100,1,12.2,200,2,12.33,100,1,13.98,2,1,14.26,100,1,14.28,100,1,14.46,100,1,14.48,700,1,14.56,800,2,14.6,700,1,14.68,700,1,14.74,200,2,14.75,100,1,ARL,333581389
2025-07-17T16:08:27.533938450Z,2025-07-17T16:08:27.533773259Z,160,2,1108,A,A,15.040000000,100,0,333581845,130,165191,277841588,ARL,0,15.04,100,130,165191,277841588,9.55,1700,17,9.68,100,1,10.61,200,2,11.27,100,1,11.4,100,1,11.76,100,1,11.93,200,2,12.1,100,1,12.2,200,2,12.33,100,1,13.98,2,1,14.26,100,1,14.28,100,1,14.46,100,1,14.48,700,1,14.56,800,2,14.6,700,1,14.68,700,1,14.74,200,2,14.75,100,1,ARL,333581845
2025-07-17T16:08:27.987678739Z,2025-07-17T16:08:27.987513451Z,160,2,1108,A,A,13.990000000,100,0,333590057,130,165288,277846288,ARL,0,13.99,100,130,165288,277846288,9.55,1700,17,9.68,100,1,10.61,200,2,11.27,100,1,11.4,100,1,11.76,100,1,11.93,200,2,12.1,100,1,12.2,200,2,12.33,100,1,13.98,2,1,13.99,100,1,14.26,100,1,14.28,100,1,14.46,100,1,14.48,700,1,14.56,800,2,14.6,700,1,14.68,700,1,14.74,200,2,ARL,333590057
2025-07-17T16:08:58.024979382Z,2025-07-17T16:08:58.024814068Z,160,2,1108,A,A,13.810000000,15,0,334141429,130,165314,278261182,ARL,0,13.81,15,130,165314,278261182,9.55,1700,17,9.68,100,1,10.61,200,2,11.27,100,1,11.4,100,1,11.76,100,1,11.93,200,2,12.1,100,1,12.2,200,2,12.33,100,1,13.81,15,1,13.98,2,1,13.99,100,1,14.26,100,1,14.28,100,1,14.46,100,1,14.48,700,1,14.56,800,2,14.6,700,1,14.68,700,1,ARL,334141429
2025-07-17T16:09:00.222675234Z,2025-07-17T16:09:00.222509491Z,160,2,1108,C,A,13.990000000,100,0,333590057,0,165743,278295684,ARL,0,13.99,100,0,165743,278295684,9.55,1700,17,9.68,100,1,10.61,200,2,11.27,100,1,11.4,100,1,11.76,100,1,11.93,200,2,12.1,100,1,12.2,200,2,12.33,100,1,13.81,15,1,13.98,2,1,14.26,100,1,14.28,100,1,14.46,100,1,14.48,700,1,14.56,800,2,14.6,700,1,14.68,700,1,14.74,200,2,ARL,333590057
2025-07-17T16:09:00.222675234Z,2025-07-17T16:09:00.222509491Z,160,2,1108,A,A,13.820000000,100,0,334189729,130,165743,278295684,ARL,0,13.82,100,130,165743,278295684,9.55,1700,17,9.68,100,1,10.61,200,2,11.27,100,1,11.4,100,1,11.76,100,1,11.93,200,2,12.1,100,1,12.2,200,2,12.33,100,1,13.81,15,1,13.82,100,1,13.98,2,1,14.26,100,1,14.28,100,1,14.46,100,1,14.48,700,1,14.56,800,2,14.6,700,1,14.68,700,1,ARL,334189729
2025-07-17T16:09:00.223436757Z,2025-07-17T16:09:00.223269382Z,160,2,1108,C,A,15.040000000,100,0,333581845,0,167375,278295848,ARL,0,15.04,100,0,167375,278295848,9.55,1700,17,9.68,100,1,10.61,200,2,11.27,100,1,11.4,100,1,11.76,100,1,11.93,200,2,12.1,100,1,12.2,200,2,12.33,100,1,13.81,15,1,13.82,100,1,13.98,2,1,14.26,100,1,14.28,100,1,14.46,100,1,14.48,700,1,14.56,800,2,14.6,700,1,14.68,700,1,ARL,333581845
2025-07-17T16:09:00.223436757Z,2025-07-17T16:09:00.223269382Z,160,2,1108,A,A,14.890000000,100,0,334189777,128,167375,278295848,ARL,0,14.89,100,128,167375,278295848,9.55,1700,17,9.68,100,1,10.61,200,2,11.27,100,1,11.4,100,1,11.76,100,1,11.93,200,2,12.1,100,1,12.2,200,2,12.33,100,1,13.81,15,1,13.82,100,1,13.98,2,1,14.26,100,1,14.28,100,1,14.46,100,1,14.48,700,1,14.56,800,2,14.6,700,1,14.68,700,1,ARL,334189777
2025-07-17T16:09:00.226504346Z,2025-07-17T16:09:00.226338384Z,160,2,1108,C,A,14.750000000,100,0,333581569,0,165962,278296281,ARL,0,14.75,100,0,165962,278296281,9.55,1700,17,9.68,100,1,10.61,200,2,11.27,100,1,11.4,100,1,11.76,100,1,11.93,200,2,12.1,100,1,12.2,200,2,12.33,100,1,13.81,15,1,13.82,100,1,13.98,2,1,14.26,100,1,14.28,100,1,14.46,100,1,14.48,700,1,14.56,800,2,14.6,700,1,14.68,700,1,ARL,333581569
2025-07-17T16:09:00.226504346Z,2025-07-17T16:09:00.226338384Z,160,2,1108,A,A,14.610000000,100,0,334190189,130,165962,278296281,ARL,0,14.61,100,130,165962,278296281,9.55,1700,17,9.68,100,1,10.61,200,2,11.27,100,1,11.4,100,1,11.76,100,1,11.93,200,2,12.1,100,1,12.2,200,2,12.33,100,1,13.81,15,1,13.82,100,1,13.98,2,1,14.26,100,1,14.28,100,1,14.46,100,1,14.48,700,1,14.56,800,2,14.6,700,1,14.61,100,1,ARL,334190189
2025-07-17T16:09:00.227929061Z,2025-07-17T16:09:00.227763275Z,160,2,1108,C,A,14.260000000,100,0,333581765,130,165786,278296402,ARL,0,14.26,100,130,165786,278296402,9.55,1700,17,9.68,100,1,10.61,200,2,11.27,100,1,11.4,100,1,11.76,100,1,11.93,200,2,12.1,100,1,12.2,200,2,12.33,100,1,13.81,15,1,13.82,100,1,13.98,2,1,14.28,100,1,14.46,100,1,14.48,700,1,14.56,800,2,14.6,700,1,14.61,100,1,14.68,700,1,ARL,333581765
2025-07-17T16:09:00.227983483Z,2025-07-17T16:09:00.227818153Z,160,2,1108,A,A,14.100000000,100,0,334190225,130,165330,278296411,ARL,0,14.1,100,130,165330,278296411,9.55,1700,17,9.68,100,1,10.61,200,2,11.27,100,1,11.4,100,1,11.76,100,1,11.93,200,2,12.1,100,1,12.2,200,2,12.33,100,1,13.81,15,1,13.82,100,1,13.98,2,1,14.1,100,1,14.28,100,1,14.46,100,1,14.48,700,1,14.56,800,2,14.6,700,1,14.61,100,1,ARL,334190225
2025-07-17T16:09:00.232908882Z,2025-07-17T16:09:00.232743323Z,160,2,1108,C,A,14.940000000,100,0,333581429,0,165559,278296544,ARL,0,14.94,100,0,165559,278296544,9.55,1700,17,9.68,100,1,10.61,200,2,11.27,100,1,11.4,100,1,11.76,100,1,11.93,200,2,12.1,100,1,12.2,200,2,12.33,100,1,13.81,15,1,13.82,100,1,13.98,2,1,14.1,100,1,14.28,100,1,14.46,100,1,14.48,700,1,14.56,800,2,14.6,700,1,14.61,100,1,ARL,333581429
2025-07-17T16:09:00.232908882Z,2025-07-17T16:09:00.232743323Z,160,2,1108,A,A,14.790000000,100,0,334190353,130,165559,278296544,ARL,0,14.79,100,130,165559,278296544,9.55,1700,17,9.68,100,1,10.61,200,2,11.27,100,1,11.4,100,1,11.76,100,1,11.93,200,2,12.1,100,1,12.2,200,2,12.33,100,1,13.81,15,1,13.82,100,1,13.98,2,1,14.1,100,1,14.28,100,1,14.46,100,1,14.48,700,1,14.56,800,2,14.6,700,1,14.61,100,1,ARL,334190353
2025-07-17T16:09:00.326293286Z,2025-07-17T16:09:00.326127587Z,160,2,1108,C,A,17.730000000,100,0,333581425,0,165699,278298302,ARL,0,17.73,100,0,165699,278298302,9.55,1700,17,9.68,100,1,10.61,200,2,11.27,100,1,11.4,100,1,11.76,100,1,11.93,200,2,12.1,100,1,12.2,200,2,12.33,100,1,13.81,15,1,13.82,100,1,13.98,2,1,14.1,100,1,14.28,100,1,14.46,100,1,14.48,700,1,14.56,800,2,14.6,700,1,14.61,100,1,ARL,333581425
2025-07-17T16:09:00.326293286Z,2025-07-17T16:09:00.326127587Z,160,2,1108,A,A,17.560000000,100,0,334192253,130,165699,278298302,ARL,0,17.56,100,130,165699,278298302,9.55,1700,17,9.68,100,1,10.61,200,2,11.27,100,1,11.4,100,1,11.76,100,1,11.93,200,2,12.1,100,1,12.2,200,2,12.33,100,1,13.81,15,1,13.82,100,1,13.98,2,1,14.1,100,1,14.28,100,1,14.46,100,1,14.48,700,1,14.56,800,2,14.6,700,1,14.61,100,1,ARL,334192253
2025-07-17T16:09:00.335607827Z,2025-07-17T16:09:00.335442266Z,160,2,1108,C,A,16.060000000,100,0,333581433,0,165561,278298372,ARL,0,16.06,100,0,165561,278298372,9.55,1700,17,9.68,100,1,10.61,200,2,11.27,100,1,11.4,100,1,11.76,100,1,11.93,200,2,12.1,100,1,12.2,200,2,12.33,100,1,13.81,15,1,13.82,100,1,13.98,2,1,14.1,100,1,14.28,100,1,14.46,100,1,14.48,700,1,14.56,800,2,14.6,700,1,14.61,100,1,ARL,333581433
2025-07-17T16:09:00.335607827Z,2025-07-17T16:09:00.335442266Z,160,2,1108,A,A,15.900000000,100,0,334192405,130,165561,278298372,ARL,0,15.9,100,130,165561,278298372,9.55,1700,17,9.68,100,1,10.61,200,2,11.27,100,1,11.4,100,1,11.76,100,1,11.93,200,2,12.1,100,1,12.2,200,2,12.33,100,1,13.81,15,1,13.82,100,1,13.98,2,1,14.1,100,1,14.28,100,1,14.46,100,1,14.48,700,1,14.56,800,2,14.6,700,1,14.61,100,1,ARL,334192405
2025-07-17T16:09:00.695776010Z,2025-07-17T16:09:00.695610142Z,160,2,1108,C,A,14.940000000,100,0,333581409,0,165868,278304343,ARL,0,14.94,100,0,165868,278304343,9.55,1700,17,9.68,100,1,10.61,200,2,11.27,100,1,11.4,100,1,11.76,100,1,11.93,200,2,12.1,100,1,12.2,200,2,12.33,100,1,13.81,15,1,13.82,100,1,13.98,2,1,14.1,100,1,14.28,100,1,14.46,100,1,14.48,700,1,14.56,800,2,14.6,700,1,14.61,100,1,ARL,333581409
2025-07-17T16:09:00.695776010Z,2025-07-17T16:09:00.695610142Z,160,2,1108,A,A,14.790000000,100,0,334199009,130,165868,278304343,ARL,0,14.79,100,130,165868,278304343,9.55,1700,17,9.68,100,1,10.61,200,2,11.27,100,1,11.4,100,1,11.76,100,1,11.93,200,2,12.1,100,1,12.2,200,2,12.33,100,1,13.81,15,1,13.82,100,1,13.98,2,1,14.1,100,1,14.28,100,1,14.46,100,1,14.48,700,1,14.56,800,2,14.6,700,1,14.61,100,1,ARL,334199009
2025-07-17T16:09:08.719690693Z,2025-07-17T16:09:08.719524374Z,160,2,1108,A,A,13.750000000,15,0,334366613,130,166319,278436950,ARL,0,13.75,15,130,166319,278436950,9.55,1700,17,9.68,100,1,10.61,200,2,11.27,100,1,11.4,100,1,11.76,100,1,11.93,200,2,12.1,100,1,12.2,200,2,12.33,100,1,13.75,15,1,13.81,15,1,13.82,100,1,13.98,2,1,14.1,100,1,14.28,100,1,14.46,100,1,14.48,700,1,14.56,800,2,14.6,700,1,ARL,334366613
2025-07-17T16:09:08.719871410Z,2025-07-17T16:09:08.719706070Z,160,2,1108,C,A,13.820000000,100,0,334189729,0,165340,278436967,ARL,0,13.82,100,0,165340,278436967,9.55,1700,17,9.68,100,1,10.61,200,2,11.27,100,1,11.4,100,1,11.76,100,1,11.93,200,2,12.1,100,1,12.2,200,2,12.33,100,1,13.75,15,1,13.81,15,1,13.98,2,1,14.1,100,1,14.28,100,1,14.46,100,1,14.48,700,1,14.56,800,2,14.6,700,1,14.61,100,1,ARL,334189729
2025-07-17T16:09:08.719871410Z,2025-07-17T16:09:08.719706070Z,160,2,1108,A,A,13.760000000,100,0,334366617,130,165340,278436967,ARL,0,13.76,100,130,165340,278436967,9.55,1700,17,9.68,100,1,10.61,200,2,11.27,100,1,11.4,100,1,11.76,100,1,11.93,200,2,12.1,100,1,12.2,200,2,12.33,100,1,13.75,15,1,13.76,100,1,13.81,15,1,13.98,2,1,14.1,100,1,14.28,100,1,14.46,100,1,14.48,700,1,14.56,800,2,14.6,700,1,ARL,334366617
2025-07-17T16:09:08.720607932Z,2025-07-17T16:09:08.720442245Z,160,2,1108,C,A,14.890000000,100,0,334189777,0,165687,278436994,ARL,0,14.89,100,0,165687,278436994,9.55,1700,17,9.68,100,1,10.61,200,2,11.27,100,1,11.4,100,1,11.76,100,1,11.93,200,2,12.1,100,1,12.2,200,2,12.33,100,1,13.75,15,1,13.76,100,1,13.81,15,1,13.98,2,1,14.1,100,1,14.28,100,1,14.46,100,1,14.48,700,1,14.56,800,2,14.6,700,1,ARL,334189777
2025-07-17T16:09:08.720607932Z,2025-07-17T16:09:08.720442245Z,160,2,1108,A,A,14.830000000,100,0,334366645,130,165687,278436994,ARL,0,14.83,100,130,165687,278436994,9.55,1700,17,9.68,100,1,10.61,200,2,11.27,100,1,11.4,100,1,11.76,100,1,11.93,200,2,12.1,100,1,12.2,200,2,12.33,100,1,13.75,15,1,13.76,100,1,13.81,15,1,13.98,2,1,14.1,100,1,14.28,100,1,14.46,100,1,14.48,700,1,14.56,800,2,14.6,700,1,ARL,334366645
2025-07-17T16:09:18.819300735Z,2025-07-17T16:09:18.819135505Z,160,2,1108,C,A,13.810000000,15,0,334141429,130,165230,278596985,ARL,0,13.81,15,130,165230,278596985,9.55,1700,17,9.68,100,1,10.61,200,2,11.27,100,1,11.4,100,1,11.76,100,1,11.93,200,2,12.1,100,1,12.2,200,2,12.33,100,1,13.75,15,1,13.76,100,1,13.98,2,1,14.1,100,1,14.28,100,1,14.46,100,1,14.48,700,1,14.56,800,2,14.6,700,1,14.61,100,1,ARL,334141429
2025-07-17T16:09:19.927205023Z,2025-07-17T16:09:19.927039122Z,160,2,1108,A,A,13.730000000,15,0,334583329,130,165901,278621672,ARL,0,13.73,15,130,165901,278621672,9.55,1700,17,9.68,100,1,10.61,200,2,11.27,100,1,11.4,100,1,11.76,100,1,11.93,200,2,12.1,100,1,12.2,200,2,12.33,100,1,13.73,15,1,13.75,15,1,13.76,100,1,13.98,2,1,14.1,100,1,14.28,100,1,14.46,100,1,14.48,700,1,14.56,800,2,14.6,700,1,ARL,334583329
2025-07-17T16:09:19.927910703Z,2025-07-17T16:09:19.927745104Z,160,2,1108,C,A,14.740000000,100,0,333581393,0,165599,278621693,ARL,0,14.74,100,0,165599,278621693,9.55,1700,17,9.68,100,1,10.61,200,2,11.27,100,1,11.4,100,1,11.76,100,1,11.93,200,2,12.1,100,1,12.2,200,2,12.33,100,1,13.73,15,1,13.75,15,1,13.76,100,1,13.98,2,1,14.1,100,1,14.28,100,1,14.46,100,1,14.48,700,1,14.56,800,2,14.6,700,1,ARL,333581393
2025-07-17T16:09:19.927910703Z,2025-07-17T16:09:19.927745104Z,160,2,1108,A,A,14.620000000,100,0,334583349,130,165599,278621693,ARL,0,14.62,100,130,165599,278621693,9.55,1700,17,9.68,100,1,10.61,200,2,11.27,100,1,11.4,100,1,11.76,100,1,11.93,200,2,12.1,100,1,12.2,200,2,12.33,100,1,13.73,15,1,13.75,15,1,13.76,100,1,13.98,2,1,14.1,100,1,14.28,100,1,14.46,100,1,14.48,700,1,14.56,800,2,14.6,700,1,ARL,334583349
2025-07-17T16:09:19.928319369Z,2025-07-17T16:09:19.928153837Z,160,2,1108,C,A,14.740000000,100,0,333581481,0,165532,278621695,ARL,0,14.74,100,0,165532,278621695,9.55,1700,17,9.68,100,1,10.61,200,2,11.27,100,1,11.4,100,1,11.76,100,1,11.93,200,2,12.1,100,1,12.2,200,2,12.33,100,1,13.73,15,1,13.75,15,1,13.76,100,1,13.98,2,1,14.1,100,1,14.28,100,1,14.46,100,1,14.48,700,1,14.56,800,2,14.6,700,1,ARL,333581481
2025-07-17T16:09:19.928319369Z,2025-07-17T16:09:19.928153837Z,160,2,1108,A,A,14.620000000,100,0,334583361,130,165532,278621695,ARL,0,14.62,100,130,165532,278621695,9.55,1700,17,9.68,100,1,10.61,200,2,11.27,100,1,11.4,100,1,11.76,100,1,11.93,200,2,12.1,100,1,12.2,200,2,12.33,100,1,13.73,15,1,13.75,15,1,13.76,100,1,13.98,2,1,14.1,100,1,14.28,100,1,14.46,100,1,14.48,700,1,14.56,800,2,14.6,700,1,ARL,334583361
2025-07-17T16:09:20.284861075Z,2025-07-17T16:09:20.284695585Z,160,2,1108,C,A,13.760000000,100,0,334366617,0,165490,278629057,ARL,0,13.76,100,0,165490,278629057,9.55,1700,17,9.68,100,1,10.61,200,2,11.27,100,1,11.4,100,1,11.76,100,1,11.93,200,2,12.1,100,1,12.2,200,2,12.33,100,1,13.73,15,1,13.75,15,1,13.98,2,1,14.1,100,1,14.28,100,1,14.46,100,1,14.48,700,1,14.56,800,2,14.6,700,1,14.61,100,1,ARL,334366617
2025-07-17T16:09:20.284861075Z,2025-07-17T16:09:20.284695585Z,160,2,1108,A,A,13.740000000,100,0,334593569,130,165490,278629057,ARL,0,13.74,100,130,165490,278629057,9.55,1700,17,9.68,100,1,10.61,200,2,11.27,100,1,11.4,100,1,11.76,100,1,11.93,200,2,12.1,100,1,12.2,200,2,12.33,100,1,13.73,15,1,13.74,100,1,13.75,15,1,13.98,2,1,14.1,100,1,14.28,100,1,14.46,100,1,14.48,700,1,14.56,800,2,14.6,700,1,ARL,334593569
2025-07-17T16:09:20.293271620Z,2025-07-17T16:09:20.293106270Z,160,2,1108,C,A,14.100000000,100,0,334190225,130,165350,278629219,ARL,0,14.1,100,130,165350,278629219,9.55,1700,17,9.68,100,1,10.61,200,2,11.27,100,1,11.4,100,1,11.76,100,1,11.93,200,2,12.1,100,1,12.2,200,2,12.33,100,1,13.73,15,1,13.74,100,1,13.75,15,1,13.98,2,1,14.28,100,1,14.46,100,1,14.48,700,1,14.56,800,2,14.6,700,1,14.61,100,1,ARL,334190225
2025-07-17T16:09:20.293326641Z,2025-07-17T16:09:20.293161454Z,160,2,1108,A,A,14.010000000,100,0,334593753,130,165187,278629220,ARL,0,14.01,100,130,165187,278629220,9.55,1700,17,9.68,100,1,10.61,200,2,11.27,100,1,11.4,100,1,11.76,100,1,11.93,200,2,12.1,100,1,12.2,200,2,12.33,100,1,13.73,15,1,13.74,100,1,13.75,15,1,13.98,2,1,14.01,100,1,14.28,100,1,14.46,100,1,14.48,700,1,14.56,800,2,14.6,700,1,ARL,334593753
2025-07-17T16:09:20.818813935Z,2025-07-17T16:09:20.818648795Z,160,2,1108,C,A,13.730000000,15,0,334583329,130,165140,278640667,ARL,0,13.73,15,130,165140,278640667,9.55,1700,17,9.68,100,1,10.61,200,2,11.27,100,1,11.4,100,1,11.76,100,1,11.93,200,2,12.1,100,1,12.2,200,2,12.33,100,1,13.74,100,1,13.75,15,1,13.98,2,1,14.01,100,1,14.28,100,1,14.46,100,1,14.48,700,1,14.56,800,2,14.6,700,1,14.61,100,1,ARL,334583329
2025-07-17T16:09:20.818926356Z,2025-07-17T16:09:20.818761228Z,160,2,1108,C,A,13.750000000,15,0,334366613,130,165128,278640670,ARL,0,13.75,15,130,165128,278640670,9.55,1700,17,9.68,100,1,10.61,200,2,11.27,100,1,11.4,100,1,11.76,100,1,11.93,200,2,12.1,100,1,12.2,200,2,12.33,100,1,13.74,100,1,13.98,2,1,14.01,100,1,14.28,100,1,14.46,100,1,14.48,700,1,14.56,800,2,14.6,700,1,14.61,100,1,14.62,200,2,ARL,334366613
2025-07-17T16:09:28.986122432Z,2025-07-17T16:09:28.985956629Z,160,2,1108,C,A,13.980000000,2,0,333581677,0,165803,278784943,ARL,0,13.98,2,0,165803,278784943,9.55,1700,17,9.68,100,1,10.61,200,2,11.27,100,1,11.4,100,1,11.76,100,1,11.93,200,2,12.1,100,1,12.2,200,2,12.33,100,1,13.74,100,1,14.01,100,1,14.28,100,1,14.46,100,1,14.48,700,1,14.56,800,2,14.6,700,1,14.61,100,1,14.62,200,2,14.68,700,1,ARL,333581677
2025-07-17T16:09:28.986122432Z,2025-07-17T16:09:28.985956629Z,160,2,1108,A,A,13.900000000,2,0,334804177,130,165803,278784943,ARL,0,13.9,2,130,165803,278784943,9.55,1700,17,9.68,100,1,10.61,200,2,11.27,100,1,11.4,100,1,11.76,100,1,11.93,200,2,12.1,100,1,12.2,200,2,12.33,100,1,13.74,100,1,13.9,2,1,14.01,100,1,14.28,100,1,14.46,100,1,14.48,700,1,14.56,800,2,14.6,700,1,14.61,100,1,14.62,200,2,ARL,334804177
2025-07-17T16:09:40.821687905Z,2025-07-17T16:09:40.821522565Z,160,2,1108,A,A,13.700000000,15,0,335003269,130,165340,278938091,ARL,0,13.7,15,130,165340,278938091,9.55,1700,17,9.68,100,1,10.61,200,2,11.27,100,1,11.4,100,1,11.76,100,1,11.93,200,2,12.1,100,1,12.2,200,2,12.33,100,1,13.7,15,1,13.74,100,1,13.9,2,1,14.01,100,1,14.28,100,1,14.46,100,1,14.48,700,1,14.56,800,2,14.6,700,1,14.61,100,1,ARL,335003269
2025-07-17T16:09:40.853604577Z,2025-07-17T16:09:40.853439053Z,160,2,1108,C,A,13.740000000,100,0,334593569,0,165524,278938747,ARL,0,13.74,100,0,165524,278938747,9.55,1700,17,9.68,100,1,10.61,200,2,11.27,100,1,11.4,100,1,11.76,100,1,11.93,200,2,12.1,100,1,12.2,200,2,12.33,100,1,13.7,15,1,13.9,2,1,14.01,100,1,14.28,100,1,14.46,100,1,14.48,700,1,14.56,800,2,14.6,700,1,14.61,100,1,14.62,200,2,ARL,334593569
2025-07-17T16:09:40.853604577Z,2025-07-17T16:09:40.853439053Z,160,2,1108,A,A,13.710000000,100,0,335003813,130,165524,278938747,ARL,0,13.71,100,130,165524,278938747,9.55,1700,17,9.68,100,1,10.61,200,2,11.27,100,1,11.4,100,1,11.76,100,1,11.93,200,2,12.1,100,1,12.2,200,2,12.33,100,1,13.7,15,1,13.71,100,1,13.9,2,1,14.01,100,1,14.28,100,1,14.46,100,1,14.48,700,1,14.56,800,2,14.6,700,1,14.61,100,1,ARL,335003813
2025-07-17T16:09:40.854356022Z,2025-07-17T16:09:40.854190408Z,160,2,1108,C,A,14.830000000,100,0,334366645,0,165614,278938765,ARL,0,14.83,100,0,165614,278938765,9.55,1700,17,9.68,100,1,10.61,200,2,11.27,100,1,11.4,100,1,11.76,100,1,11.93,200,2,12.1,100,1,12.2,200,2,12.33,100,1,13.7,15,1,13.71,100,1,13.9,2,1,14.01,100,1,14.28,100,1,14.46,100,1,14.48,700,1,14.56,800,2,14.6,700,1,14.61,100,1,ARL,334366645
2025-07-17T16:09:40.854356022Z,2025-07-17T16:09:40.854190408Z,160,2,1108,A,A,14.770000000,100,0,335003845,130,165614,278938765,ARL,0,14.77,100,130,165614,278938765,9.55,1700,17,9.68,100,1,10.61,200,2,11.27,100,1,11.4,100,1,11.76,100,1,11.93,200,2,12.1,100,1,12.2,200,2,12.33,100,1,13.7,15,1,13.71,100,1,13.9,2,1,14.01,100,1,14.28,100,1,14.46,100,1,14.48,700,1,14.56,800,2,14.6,700,1,14.61,100,1,ARL,335003845
2025-07-17T16:09:40.855724422Z,2025-07-17T16:09:40.855558831Z,160,2,1108,C,A,17.560000000,100,0,334192253,0,165591,278938788,ARL,0,17.56,100,0,165591,278938788,9.55,1700,17,9.68,100,1,10.61,200,2,11.27,100,1,11.4,100,1,11.76,100,1,11.93,200,2,12.1,100,1,12.2,200,2,12.33,100,1,13.7,15,1,13.71,100,1,13.9,2,1,14.01,100,1,14.28,100,1,14.46,100,1,14.48,700,1,14.56,800,2,14.6,700,1,14.61,100,1,ARL,334192253
2025-07-17T16:09:40.855724422Z,2025-07-17T16:09:40.855558831Z,160,2,1108,A,A,17.420000000,100,0,335003849,130,165591,278938788,ARL,0,17.42,100,130,165591,278938788,9.55,1700,17,9.68,100,1,10.61,200,2,11.27,100,1,11.4,100,1,11.76,100,1,11.93,200,2,12.1,100,1,12.2,200,2,12.33,100,1,13.7,15,1,13.71,100,1,13.9,2,1,14.01,100,1,14.28,100,1,14.46,100,1,14.48,700,1,14.56,800,2,14.6,700,1,14.61,100,1,ARL,335003849
2025-07-17T16:09:50.820949131Z,2025-07-17T16:09:50.820783486Z,160,2,1108,A,A,13.670000000,15,0,335178437,130,165645,279081140,ARL,0,13.67,15,130,165645,279081140,9.55,1700,17,9.68,100,1,10.61,200,2,11.27,100,1,11.4,100,1,11.76,100,1,11.93,200,2,12.1,100,1,12.2,200,2,12.33,100,1,13.67,15,1,13.7,15,1,13.71,100,1,13.9,2,1,14.01,100,1,14.28,100,1,14.46,100,1,14.48,700,1,14.56,800,2,14.6,700,1,ARL,335178437
2025-07-17T16:09:52.678777358Z,2025-07-17T16:09:52.678611805Z,160,2,1108,C,A,13.710000000,100,0,335003813,0,165553,279109959,ARL,0,13.71,100,0,165553,279109959,9.55,1700,17,9.68,100,1,10.61,200,2,11.27,100,1,11.4,100,1,11.76,100,1,11.93,200,2,12.1,100,1,12.2,200,2,12.33,100,1,13.67,15,1,13.7,15,1,13.9,2,1,14.01,100,1,14.28,100,1,14.46,100,1,14.48,700,1,14.56,800,2,14.6,700,1,14.61,100,1,ARL,335003813
2025-07-17T16:09:52.678777358Z,2025-07-17T16:09:52.678611805Z,160,2,1108,A,A,13.680000000,100,0,335220349,130,165553,279109959,ARL,0,13.68,100,130,165553,279109959,9.55,1700,17,9.68,100,1,10.61,200,2,11.27,100,1,11.4,100,1,11.76,100,1,11.93,200,2,12.1,100,1,12.2,200,2,12.33,100,1,13.67,15,1,13.68,100,1,13.7,15,1,13.9,2,1,14.01,100,1,14.28,100,1,14.46,100,1,14.48,700,1,14.56,800,2,14.6,700,1,ARL,335220349
2025-07-17T16:09:52.679844338Z,2025-07-17T16:09:52.679678566Z,160,2,1108,C,A,15.900000000,100,0,334192405,0,165772,279109991,ARL,0,15.9,100,0,165772,279109991,9.55,1700,17,9.68,100,1,10.61,200,2,11.27,100,1,11.4,100,1,11.76,100,1,11.93,200,2,12.1,100,1,12.2,200,2,12.33,100,1,13.67,15,1,13.68,100,1,13.7,15,1,13.9,2,1,14.01,100,1,14.28,100,1,14.46,100,1,14.48,700,1,14.56,800,2,14.6,700,1,ARL,334192405
2025-07-17T16:09:52.679844338Z,2025-07-17T16:09:52.679678566Z,160,2,1108,A,A,15.740000000,100,0,335220497,130,165772,279109991,ARL,0,15.74,100,130,165772,279109991,9.55,1700,17,9.68,100,1,10.61,200,2,11.27,100,1,11.4,100,1,11.76,100,1,11.93,200,2,12.1,100,1,12.2,200,2,12.33,100,1,13.67,15,1,13.68,100,1,13.7,15,1,13.9,2,1,14.01,100,1,14.28,100,1,14.46,100,1,14.48,700,1,14.56,800,2,14.6,700,1,ARL,335220497
2025-07-17T16:09:52.679936826Z,2025-07-17T16:09:52.679769832Z,160,2,1108,C,A,14.790000000,100,0,334190353,0,166994,279109996,ARL,0,14.79,100,0,166994,279109996,9.55,1700,17,9.68,100,1,10.61,200,2,11.27,100,1,11.4,100,1,11.76,100,1,11.93,200,2,12.1,100,1,12.2,200,2,12.33,100,1,13.67,15,1,13.68,100,1,13.7,15,1,13.9,2,1,14.01,100,1,14.28,100,1,14.46,100,1,14.48,700,1,14.56,800,2,14.6,700,1,ARL,334190353
2025-07-17T16:09:52.679936826Z,2025-07-17T16:09:52.679769832Z,160,2,1108,A,A,14.640000000,100,0,335220525,130,166994,279109996,ARL,0,14.64,100,130,166994,279109996,9.55,1700,17,9.68,100,1,10.61,200,2,11.27,100,1,11.4,100,1,11.76,100,1,11.93,200,2,12.1,100,1,12.2,200,2,12.33,100,1,13.67,15,1,13.68,100,1,13.7,15,1,13.9,2,1,14.01,100,1,14.28,100,1,14.46,100,1,14.48,700,1,14.56,800,2,14.6,700,1,ARL,335220525
2025-07-17T16:09:52.680837736Z,2025-07-17T16:09:52.680672148Z,160,2,1108,C,A,15.360000000,100,0,333581441,0,165588,279110032,ARL,0,15.36,100,0,165588,279110032,9.55,1700,17,9.68,100,1,10.61,200,2,11.27,100,1,11.4,100,1,11.76,100,1,11.93,200,2,12.1,100,1,12.2,200,2,12.33,100,1,13.67,15,1,13.68,100,1,13.7,15,1,13.9,2,1,14.01,100,1,14.28,100,1,14.46,100,1,14.48,700,1,14.56,800,2,14.6,700,1,ARL,333581441
2025-07-17T16:09:52.680837736Z,2025-07-17T16:09:52.680672148Z,160,2,1108,A,A,15.050000000,100,0,335220549,130,165588,279110032,ARL,0,15.05,100,130,165588,279110032,9.55,1700,17,9.68,100,1,10.61,200,2,11.27,100,1,11.4,100,1,11.76,100,1,11.93,200,2,12.1,100,1,12.2,200,2,12.33,100,1,13.67,15,1,13.68,100,1,13.7,15,1,13.9,2,1,14.01,100,1,14.28,100,1,14.46,100,1,14.48,700,1,14.56,800,2,14.6,700,1,ARL,335220549
2025-07-17T16:09:52.682009938Z,2025-07-17T16:09:52.681844377Z,160,2,1108,C,A,14.610000000,100,0,334190189,130,165561,279110066,ARL,0,14.61,100,130,165561,279110066,9.55,1700,17,9.68,100,1,10.61,200,2,11.27,100,1,11.4,100,1,11.76,100,1,11.93,200,2,12.1,100,1,12.2,200,2,12.33,100,1,13.67,15,1,13.68,100,1,13.7,15,1,13.9,2,1,14.01,100,1,14.28,100,1,14.46,100,1,14.48,700,1,14.56,800,2,14.6,700,1,ARL,334190189
2025-07-17T16:09:52.682127530Z,2025-07-17T16:09:52.681961200Z,160,2,1108,A,A,14.470000000,100,0,335220561,130,166330,279110068,ARL,0,14.47,100,130,166330,279110068,9.55,1700,17,9.68,100,1,10.61,200,2,11.27,100,1,11.4,100,1,11.76,100,1,11.93,200,2,12.1,100,1,12.2,200,2,12.33,100,1,13.67,15,1,13.68,100,1,13.7,15,1,13.9,2,1,14.01,100,1,14.28,100,1,14.46,100,1,14.47,100,1,14.48,700,1,14.56,800,2,ARL,335220561
2025-07-17T16:09:52.683922707Z,2025-07-17T16:09:52.683757265Z,160,2,1108,C,A,14.790000000,100,0,334199009,0,165442,279110090,ARL,0,14.79,100,0,165442,279110090,9.55,1700,17,9.68,100,1,10.61,200,2,11.27,100,1,11.4,100,1,11.76,100,1,11.93,200,2,12.1,100,1,12.2,200,2,12.33,100,1,13.67,15,1,13.68,100,1,13.7,15,1,13.9,2,1,14.01,100,1,14.28,100,1,14.46,100,1,14.47,100,1,14.48,700,1,14.56,800,2,ARL,334199009
2025-07-17T16:09:52.683922707Z,2025-07-17T16:09:52.683757265Z,160,2,1108,A,A,14.640000000,100,0,335220629,130,165442,279110090,ARL,0,14.64,100,130,165442,279110090,9.55,1700,17,9.68,100,1,10.61,200,2,11.27,100,1,11.4,100,1,11.76,100,1,11.93,200,2,12.1,100,1,12.2,200,2,12.33,100,1,13.67,15,1,13.68,100,1,13.7,15,1,13.9,2,1,14.01,100,1,14.28,100,1,14.46,100,1,14.47,100,1,14.48,700,1,14.56,800,2,ARL,335220629
2025-07-17T16:10:04.521471804Z,2025-07-17T16:10:04.521306513Z,160,2,1108,C,A,13.670000000,15,0,335178437,130,165291,279306715,ARL,0,13.67,15,130,165291,279306715,9.55,1700,17,9.68,100,1,10.61,200,2,11.27,100,1,11.4,100,1,11.76,100,1,11.93,200,2,12.1,100,1,12.2,200,2,12.33,100,1,13.68,100,1,13.7,15,1,13.9,2,1,14.01,100,1,14.28,100,1,14.46,100,1,14.47,100,1,14.48,700,1,14.56,800,2,14.6,700,1,ARL,335178437
2025-07-17T16:10:04.561854856Z,2025-07-17T16:10:04.561688313Z,160,2,1108,C,A,13.700000000,15,0,335003269,128,166543,279312083,ARL,0,13.7,15,128,166543,279312083,9.55,1700,17,9.68,100,1,10.61,200,2,11.27,100,1,11.4,100,1,11.76,100,1,11.93,200,2,12.1,100,1,12.2,200,2,12.33,100,1,13.68,100,1,13.9,2,1,14.01,100,1,14.28,100,1,14.46,100,1,14.47,100,1,14.48,700,1,14.56,800,2,14.6,700,1,14.62,200,2,ARL,335003269
2025-07-17T16:10:32.822660498Z,2025-07-17T16:10:32.822495087Z,160,2,1108,A,A,13.650000000,15,0,335996705,130,165411,279705339,ARL,0,13.65,15,130,165411,279705339,9.55,1700,17,9.68,100,1,10.61,200,2,11.27,100,1,11.4,100,1,11.76,100,1,11.93,200,2,12.1,100,1,12.2,200,2,12.33,100,1,13.65,15,1,13.68,100,1,13.9,2,1,14.01,100,1,14.28,100,1,14.46,100,1,14.47,100,1,14.48,700,1,14.56,800,2,14.6,700,1,ARL,335996705
2025-07-17T16:10:32.822923138Z,2025-07-17T16:10:32.822757517Z,160,2,1108,C,A,13.680000000,100,0,335220349,0,165621,279705347,ARL,0,13.68,100,0,165621,279705347,9.55,1700,17,9.68,100,1,10.61,200,2,11.27,100,1,11.4,100,1,11.76,100,1,11.93,200,2,12.1,100,1,12.2,200,2,12.33,100,1,13.65,15,1,13.9,2,1,14.01,100,1,14.28,100,1,14.46,100,1,14.47,100,1,14.48,700,1,14.56,800,2,14.6,700,1,14.62,200,2,ARL,335220349
2025-07-17T16:10:32.822923138Z,2025-07-17T16:10:32.822757517Z,160,2,1108,A,A,13.660000000,100,0,335996709,130,165621,279705347,ARL,0,13.66,100,130,165621,279705347,9.55,1700,17,9.68,100,1,10.61,200,2,11.27,100,1,11.4,100,1,11.76,100,1,11.93,200,2,12.1,100,1,12.2,200,2,12.33,100,1,13.65,15,1,13.66,100,1,13.9,2,1,14.01,100,1,14.28,100,1,14.46,100,1,14.47,100,1,14.48,700,1,14.56,800,2,14.6,700,1,ARL,335996709
2025-07-17T16:10:32.823656903Z,2025-07-17T16:10:32.823491276Z,160,2,1108,C,A,14.770000000,100,0,335003845,0,165627,279705362,ARL,0,14.77,100,0,165627,279705362,9.55,1700,17,9.68,100,1,10.61,200,2,11.27,100,1,11.4,100,1,11.76,100,1,11.93,200,2,12.1,100,1,12.2,200,2,12.33,100,1,13.65,15,1,13.66,100,1,13.9,2,1,14.01,100,1,14.28,100,1,14.46,100,1,14.47,100,1,14.48,700,1,14.56,800,2,14.6,700,1,ARL,335003845
2025-07-17T16:10:32.823656903Z,2025-07-17T16:10:32.823491276Z,160,2,1108,A,A,14.720000000,100,0,335996725,130,165627,279705362,ARL,0,14.72,100,130,165627,279705362,9.55,1700,17,9.68,100,1,10.61,200,2,11.27,100,1,11.4,100,1,11.76,100,1,11.93,200,2,12.1,100,1,12.2,200,2,12.33,100,1,13.65,15,1,13.66,100,1,13.9,2,1,14.01,100,1,14.28,100,1,14.46,100,1,14.47,100,1,14.48,700,1,14.56,800,2,14.6,700,1,ARL,335996725
2025-07-17T16:10:32.830200844Z,2025-07-17T16:10:32.830032662Z,160,2,1108,C,A,14.010000000,100,0,334593753,130,168182,279705485,ARL,0,14.01,100,130,168182,279705485,9.55,1700,17,9.68,100,1,10.61,200,2,11.27,100,1,11.4,100,1,11.76,100,1,11.93,200,2,12.1,100,1,12.2,200,2,12.33,100,1,13.65,15,1,13.66,100,1,13.9,2,1,14.28,100,1,14.46,100,1,14.47,100,1,14.48,700,1,14.56,800,2,14.6,700,1,14.62,200,2,ARL,334593753
2025-07-17T16:10:32.830250720Z,2025-07-17T16:10:32.830085472Z,160,2,1108,A,A,13.930000000,100,0,335996777,130,165248,279705486,ARL,0,13.93,100,130,165248,279705486,9.55,1700,17,9.68,100,1,10.61,200,2,11.27,100,1,11.4,100,1,11.76,100,1,11.93,200,2,12.1,100,1,12.2,200,2,12.33,100,1,13.65,15,1,13.66,100,1,13.9,2,1,13.93,100,1,14.28,100,1,14.46,100,1,14.47,100,1,14.48,700,1,14.56,800,2,14.6,700,1,ARL,335996777
2025-07-17T16:10:42.822354869Z,2025-07-17T16:10:42.822189504Z,160,2,1108,A,A,13.630000000,15,0,336161333,130,165365,279834760,ARL,0,13.63,15,130,165365,279834760,9.55,1700,17,9.68,100,1,10.61,200,2,11.27,100,1,11.4,100,1,11.76,100,1,11.93,200,2,12.1,100,1,12.2,200,2,12.33,100,1,13.63,15,1,13.65,15,1,13.66,100,1,13.9,2,1,13.93,100,1,14.28,100,1,14.46,100,1,14.47,100,1,14.48,700,1,14.56,800,2,ARL,336161333
2025-07-17T16:10:42.822424663Z,2025-07-17T16:10:42.822258887Z,160,2,1108,C,A,13.660000000,100,0,335996709,0,165776,279834761,ARL,0,13.66,100,0,165776,279834761,9.55,1700,17,9.68,100,1,10.61,200,2,11.27,100,1,11.4,100,1,11.76,100,1,11.93,200,2,12.1,100,1,12.2,200,2,12.33,100,1,13.63,15,1,13.65,15,1,13.9,2,1,13.93,100,1,14.28,100,1,14.46,100,1,14.47,100,1,14.48,700,1,14.56,800,2,14.6,700,1,ARL,335996709
2025-07-17T16:10:42.822424663Z,2025-07-17T16:10:42.822258887Z,160,2,1108,A,A,13.640000000,100,0,336161337,130,165776,279834761,ARL,0,13.64,100,130,165776,279834761,9.55,1700,17,9.68,100,1,10.61,200,2,11.27,100,1,11.4,100,1,11.76,100,1,11.93,200,2,12.1,100,1,12.2,200,2,12.33,100,1,13.63,15,1,13.64,100,1,13.65,15,1,13.9,2,1,13.93,100,1,14.28,100,1,14.46,100,1,14.47,100,1,14.48,700,1,14.56,800,2,ARL,336161337
2025-07-17T16:10:42.823163929Z,2025-07-17T16:10:42.822998664Z,160,2,1108,C,A,14.460000000,100,0,331927161,130,165265,279834765,ARL,0,14.46,100,130,165265,279834765,9.55,1700,17,9.68,100,1,10.61,200,2,11.27,100,1,11.4,100,1,11.76,100,1,11.93,200,2,12.1,100,1,12.2,200,2,12.33,100,1,13.63,15,1,13.64,100,1,13.65,15,1,13.9,2,1,13.93,100,1,14.28,100,1,14.47,100,1,14.48,700,1,14.56,800,2,14.6,700,1,ARL,331927161
2025-07-17T16:10:42.823517444Z,2025-07-17T16:10:42.823352130Z,160,2,1108,A,A,14.250000000,100,0,336161365,130,165314,279834767,ARL,0,14.25,100,130,165314,279834767,9.55,1700,17,9.68,100,1,10.61,200,2,11.27,100,1,11.4,100,1,11.76,100,1,11.93,200,2,12.1,100,1,12.2,200,2,12.33,100,1,13.63,15,1,13.64,100,1,13.65,15,1,13.9,2,1,13.93,100,1,14.25,100,1,14.28,100,1,14.47,100,1,14.48,700,1,14.56,800,2,ARL,336161365
2025-07-17T16:10:46.534055942Z,2025-07-17T16:10:46.533890361Z,160,2,1108,C,A,14.620000000,100,0,334583349,0,165581,279921726,ARL,0,14.62,100,0,165581,279921726,9.55,1700,17,9.68,100,1,10.61,200,2,11.27,100,1,11.4,100,1,11.76,100,1,11.93,200,2,12.1,100,1,12.2,200,2,12.33,100,1,13.63,15,1,13.64,100,1,13.65,15,1,13.9,2,1,13.93,100,1,14.25,100,1,14.28,100,1,14.47,100,1,14.48,700,1,14.56,800,2,ARL,334583349
2025-07-17T16:10:46.534055942Z,2025-07-17T16:10:46.533890361Z,160,2,1108,A,A,14.510000000,100,0,336259225,130,165581,279921726,ARL,0,14.51,100,130,165581,279921726,9.55,1700,17,9.68,100,1,10.61,200,2,11.27,100,1,11.4,100,1,11.76,100,1,11.93,200,2,12.1,100,1,12.2,200,2,12.33,100,1,13.63,15,1,13.64,100,1,13.65,15,1,13.9,2,1,13.93,100,1,14.25,100,1,14.28,100,1,14.47,100,1,14.48,700,1,14.51,100,1,ARL,336259225
2025-07-17T16:10:46.538158874Z,2025-07-17T16:10:46.537992315Z,160,2,1108,C,A,13.650000000,15,0,335996705,128,166559,279921911,ARL,0,13.65,15,128,166559,279921911,9.55,1700,17,9.68,100,1,10.61,200,2,11.27,100,1,11.4,100,1,11.76,100,1,11.93,200,2,12.1,100,1,12.2,200,2,12.33,100,1,13.63,15,1,13.64,100,1,13.9,2,1,13.93,100,1,14.25,100,1,14.28,100,1,14.47,100,1,14.48,700,1,14.51,100,1,14.56,800,2,ARL,335996705
2025-07-17T16:10:46.561246030Z,2025-07-17T16:10:46.561080616Z,160,2,1108,C,A,14.620000000,100,0,334583361,0,165414,279924883,ARL,0,14.62,100,0,165414,279924883,9.55,1700,17,9.68,100,1,10.61,200,2,11.27,100,1,11.4,100,1,11.76,100,1,11.93,200,2,12.1,100,1,12.2,200,2,12.33,100,1,13.63,15,1,13.64,100,1,13.9,2,1,13.93,100,1,14.25,100,1,14.28,100,1,14.47,100,1,14.48,700,1,14.51,100,1,14.56,800,2,ARL,334583361
2025-07-17T16:10:46.561246030Z,2025-07-17T16:10:46.561080616Z,160,2,1108,A,A,14.510000000,100,0,336261905,130,165414,279924883,ARL,0,14.51,100,130,165414,279924883,9.55,1700,17,9.68,100,1,10.61,200,2,11.27,100,1,11.4,100,1,11.76,100,1,11.93,200,2,12.1,100,1,12.2,200,2,12.33,100,1,13.63,15,1,13.64,100,1,13.9,2,1,13.93,100,1,14.25,100,1,14.28,100,1,14.47,100,1,14.48,700,1,14.51,200,2,14.56,800,2,ARL,336261905
2025-07-17T16:10:47.543404001Z,2025-07-17T16:10:47.543238729Z,160,2,1108,A,A,13.610000000,15,0,336278197,130,165272,279938097,ARL,0,13.61,15,130,165272,279938097,9.55,1700,17,9.68,100,1,10.61,200,2,11.27,100,1,11.4,100,1,11.76,100,1,11.93,200,2,12.1,100,1,12.2,200,2,12.33,100,1,13.61,15,1,13.63,15,1,13.64,100,1,13.9,2,1,13.93,100,1,14.25,100,1,14.28,100,1,14.47,100,1,14.48,700,1,14.51,200,2,ARL,336278197
2025-07-17T16:10:48.657456395Z,2025-07-17T16:10:48.657290980Z,160,2,1108,C,A,13.640000000,100,0,336161337,0,165415,279952266,ARL,0,13.64,100,0,165415,279952266,9.55,1700,17,9.68,100,1,10.61,200,2,11.27,100,1,11.4,100,1,11.76,100,1,11.93,200,2,12.1,100,1,12.2,200,2,12.33,100,1,13.61,15,1,13.63,15,1,13.9,2,1,13.93,100,1,14.25,100,1,14.28,100,1,14.47,100,1,14.48,700,1,14.51,200,2,14.56,800,2,ARL,336161337
2025-07-17T16:10:48.657456395Z,2025-07-17T16:10:48.657290980Z,160,2,1108,A,A,13.620000000,100,0,336295769,130,165415,279952266,ARL,0,13.62,100,130,165415,279952266,9.55,1700,17,9.68,100,1,10.61,200,2,11.27,100,1,11.4,100,1,11.76,100,1,11.93,200,2,12.1,100,1,12.2,200,2,12.33,100,1,13.61,15,1,13.62,100,1,13.63,15,1,13.9,2,1,13.93,100,1,14.25,100,1,14.28,100,1,14.47,100,1,14.48,700,1,14.51,200,2,ARL,336295769
2025-07-17T16:10:48.658199425Z,2025-07-17T16:10:48.658033954Z,160,2,1108,C,A,14.720000000,100,0,335996725,0,165471,279952282,ARL,0,14.72,100,0,165471,279952282,9.55,1700,17,9.68,100,1,10.61,200,2,11.27,100,1,11.4,100,1,11.76,100,1,11.93,200,2,12.1,100,1,12.2,200,2,12.33,100,1,13.61,15,1,13.62,100,1,13.63,15,1,13.9,2,1,13.93,100,1,14.25,100,1,14.28,100,1,14.47,100,1,14.48,700,1,14.51,200,2,ARL,335996725
2025-07-17T16:10:48.658199425Z,2025-07-17T16:10:48.658033954Z,160,2,1108,A,A,14.680000000,100,0,336295845,130,165471,279952282,ARL,0,14.68,100,130,165471,279952282,9.55,1700,17,9.68,100,1,10.61,200,2,11.27,100,1,11.4,100,1,11.76,100,1,11.93,200,2,12.1,100,1,12.2,200,2,12.33,100,1,13.61,15,1,13.62,100,1,13.63,15,1,13.9,2,1,13.93,100,1,14.25,100,1,14.28,100,1,14.47,100,1,14.48,700,1,14.51,200,2,ARL,336295845
2025-07-17T16:10:51.059044292Z,2025-07-17T16:10:51.058878264Z,160,2,1108,C,A,13.610000000,15,0,336278197,128,166028,280001840,ARL,0,13.61,15,128,166028,280001840,9.55,1700,17,9.68,100,1,10.61,200,2,11.27,100,1,11.4,100,1,11.76,100,1,11.93,200,2,12.1,100,1,12.2,200,2,12.33,100,1,13.62,100,1,13.63,15,1,13.9,2,1,13.93,100,1,14.25,100,1,14.28,100,1,14.47,100,1,14.48,700,1,14.51,200,2,14.56,800,2,ARL,336278197
2025-07-17T16:10:51.059183923Z,2025-07-17T16:10:51.059016199Z,160,2,1108,C,A,13.630000000,15,0,336161333,128,167724,280001873,ARL,0,13.63,15,128,167724,280001873,9.55,1700,17,9.68,100,1,10.61,200,2,11.27,100,1,11.4,100,1,11.76,100,1,11.93,200,2,12.1,100,1,12.2,200,2,12.33,100,1,13.62,100,1,13.9,2,1,13.93,100,1,14.25,100,1,14.28,100,1,14.47,100,1,14.48,700,1,14.51,200,2,14.56,800,2,14.6,700,1,ARL,336161333
2025-07-17T16:10:51.059608753Z,2025-07-17T16:10:51.059443298Z,160,2,1108,C,A,13.620000000,100,0,336295769,130,165455,280001952,ARL,0,13.62,100,130,165455,280001952,9.55,1700,17,9.68,100,1,10.61,200,2,11.27,100,1,11.4,100,1,11.76,100,1,11.93,200,2,12.1,100,1,12.2,200,2,12.33,100,1,13.9,2,1,13.93,100,1,14.25,100,1,14.28,100,1,14.47,100,1,14.48,700,1,14.51,200,2,14.56,800,2,14.6,700,1,14.64,200,2,ARL,336295769
2025-07-17T16:10:51.170710609Z,2025-07-17T16:10:51.170545251Z,160,2,1108,A,A,13.910000000,100,0,336351081,130,165358,280003702,ARL,0,13.91,100,130,165358,280003702,9.55,1700,17,9.68,100,1,10.61,200,2,11.27,100,1,11.4,100,1,11.76,100,1,11.93,200,2,12.1,100,1,12.2,200,2,12.33,100,1,13.9,2,1,13.91,100,1,13.93,100,1,14.25,100,1,14.28,100,1,14.47,100,1,14.48,700,1,14.51,200,2,14.56,800,2,14.6,700,1,ARL,336351081
2025-07-17T16:10:52.958453641Z,2025-07-17T16:10:52.958288317Z,160,2,1108,A,A,13.600000000,15,0,336402845,130,165324,280050139,ARL,0,13.6,15,130,165324,280050139,9.55,1700,17,9.68,100,1,10.61,200,2,11.27,100,1,11.4,100,1,11.76,100,1,11.93,200,2,12.1,100,1,12.2,200,2,12.33,100,1,13.6,15,1,13.9,2,1,13.91,100,1,13.93,100,1,14.25,100,1,14.28,100,1,14.47,100,1,14.48,700,1,14.51,200,2,14.56,800,2,ARL,336402845
2025-07-17T16:10:53.102037173Z,2025-07-17T16:10:53.101871639Z,160,2,1108,C,A,13.910000000,100,0,336351081,0,165534,280057228,ARL,0,13.91,100,0,165534,280057228,9.55,1700,17,9.68,100,1,10.61,200,2,11.27,100,1,11.4,100,1,11.76,100,1,11.93,200,2,12.1,100,1,12.2,200,2,12.33,100,1,13.6,15,1,13.9,2,1,13.93,100,1,14.25,100,1,14.28,100,1,14.47,100,1,14.48,700,1,14.51,200,2,14.56,800,2,14.6,700,1,ARL,336351081
2025-07-17T16:10:53.102037173Z,2025-07-17T16:10:53.101871639Z,160,2,1108,A,A,13.610000000,100,0,336410125,130,165534,280057228,ARL,0,13.61,100,130,165534,280057228,9.55,1700,17,9.68,100,1,10.61,200,2,11.27,100,1,11.4,100,1,11.76,100,1,11.93,200,2,12.1,100,1,12.2,200,2,12.33,100,1,13.6,15,1,13.61,100,1,13.9,2,1,13.93,100,1,14.25,100,1,14.28,100,1,14.47,100,1,14.48,700,1,14.51,200,2,14.56,800,2,ARL,336410125
2025-07-17T16:10:54.959307592Z,2025-07-17T16:10:54.959141873Z,160,2,1108,C,A,13.900000000,2,0,334804177,0,165719,280084546,ARL,0,13.9,2,0,165719,280084546,9.55,1700,17,9.68,100,1,10.61,200,2,11.27,100,1,11.4,100,1,11.76,100,1,11.93,200,2,12.1,100,1,12.2,200,2,12.33,100,1,13.6,15,1,13.61,100,1,13.93,100,1,14.25,100,1,14.28,100,1,14.47,100,1,14.48,700,1,14.51,200,2,14.56,800,2,14.6,700,1,ARL,334804177
2025-07-17T16:10:54.959307592Z,2025-07-17T16:10:54.959141873Z,160,2,1108,A,A,13.820000000,2,0,336447325,130,165719,280084546,ARL,0,13.82,2,130,165719,280084546,9.55,1700,17,9.68,100,1,10.61,200,2,11.27,100,1,11.4,100,1,11.76,100,1,11.93,200,2,12.1,100,1,12.2,200,2,12.33,100,1,13.6,15,1,13.61,100,1,13.82,2,1,13.93,100,1,14.25,100,1,14.28,100,1,14.47,100,1,14.48,700,1,14.51,200,2,14.56,800,2,ARL,336447325
2025-07-17T16:10:59.518035805Z,2025-07-17T16:10:59.517870358Z,160,2,1108,A,A,13.580000000,15,0,336555153,130,165447,280173685,ARL,0,13.58,15,130,165447,280173685,9.55,1700,17,9.68,100,1,10.61,200,2,11.27,100,1,11.4,100,1,11.76,100,1,11.93,200,2,12.1,100,1,12.2,200,2,12.33,100,1,13.58,15,1,13.6,15,1,13.61,100,1,13.82,2,1,13.93,100,1,14.25,100,1,14.28,100,1,14.47,100,1,14.48,700,1,14.51,200,2,ARL,336555153
2025-07-17T16:11:00.215885294Z,2025-07-17T16:11:00.215719725Z,160,2,1108,C,A,13.610000000,100,0,336410125,0,165569,280184406,ARL,0,13.61,100,0,165569,280184406,9.55,1700,17,9.68,100,1,10.61,200,2,11.27,100,1,11.4,100,1,11.76,100,1,11.93,200,2,12.1,100,1,12.2,200,2,12.33,100,1,13.58,15,1,13.6,15,1,13.82,2,1,13.93,100,1,14.25,100,1,14.28,100,1,14.47,100,1,14.48,700,1,14.51,200,2,14.56,800,2,ARL,336410125
2025-07-17T16:11:00.215885294Z,2025-07-17T16:11:00.215719725Z,160,2,1108,A,A,13.590000000,100,0,336567189,130,165569,280184406,ARL,0,13.59,100,130,165569,280184406,9.55,1700,17,9.68,100,1,10.61,200,2,11.27,100,1,11.4,100,1,11.76,100,1,11.93,200,2,12.1,100,1,12.2,200,2,12.33,100,1,13.58,15,1,13.59,100,1,13.6,15,1,13.82,2,1,13.93,100,1,14.25,100,1,14.28,100,1,14.47,100,1,14.48,700,1,14.51,200,2,ARL,336567189
2025-07-17T16:11:00.216622121Z,2025-07-17T16:11:00.216456547Z,160,2,1108,C,A,14.680000000,100,0,336295845,0,165574,280184418,ARL,0,14.68,100,0,165574,280184418,9.55,1700,17,9.68,100,1,10.61,200,2,11.27,100,1,11.4,100,1,11.76,100,1,11.93,200,2,12.1,100,1,12.2,200,2,12.33,100,1,13.58,15,1,13.59,100,1,13.6,15,1,13.82,2,1,13.93,100,1,14.25,100,1,14.28,100,1,14.47,100,1,14.48,700,1,14.51,200,2,ARL,336295845
2025-07-17T16:11:00.216622121Z,2025-07-17T16:11:00.216456547Z,160,2,1108,A,A,14.640000000,100,0,336567213,130,165574,280184418,ARL,0,14.64,100,130,165574,280184418,9.55,1700,17,9.68,100,1,10.61,200,2,11.27,100,1,11.4,100,1,11.76,100,1,11.93,200,2,12.1,100,1,12.2,200,2,12.33,100,1,13.58,15,1,13.59,100,1,13.6,15,1,13.82,2,1,13.93,100,1,14.25,100,1,14.28,100,1,14.47,100,1,14.48,700,1,14.51,200,2,ARL,336567213
2025-07-17T16:11:00.228999377Z,2025-07-17T16:11:00.228833925Z,160,2,1108,C,A,13.930000000,100,0,335996777,130,165452,280184613,ARL,0,13.93,100,130,165452,280184613,9.55,1700,17,9.68,100,1,10.61,200,2,11.27,100,1,11.4,100,1,11.76,100,1,11.93,200,2,12.1,100,1,12.2,200,2,12.33,100,1,13.58,15,1,13.59,100,1,13.6,15,1,13.82,2,1,14.25,100,1,14.28,100,1,14.47,100,1,14.48,700,1,14.51,200,2,14.56,800,2,ARL,335996777
2025-07-17T16:11:00.229051124Z,2025-07-17T16:11:00.228885790Z,160,2,1108,A,A,13.860000000,100,0,336567333,130,165334,280184614,ARL,0,13.86,100,130,165334,280184614,9.55,1700,17,9.68,100,1,10.61,200,2,11.27,100,1,11.4,100,1,11.76,100,1,11.93,200,2,12.1,100,1,12.2,200,2,12.33,100,1,13.58,15,1,13.59,100,1,13.6,15,1,13.82,2,1,13.86,100,1,14.25,100,1,14.28,100,1,14.47,100,1,14.48,700,1,14.51,200,2,ARL,336567333
2025-07-17T16:11:00.313087129Z,2025-07-17T16:11:00.312921679Z,160,2,1108,C,A,17.420000000,100,0,335003849,0,165450,280188038,ARL,0,17.42,100,0,165450,280188038,9.55,1700,17,9.68,100,1,10.61,200,2,11.27,100,1,11.4,100,1,11.76,100,1,11.93,200,2,12.1,100,1,12.2,200,2,12.33,100,1,13.58,15,1,13.59,100,1,13.6,15,1,13.82,2,1,13.86,100,1,14.25,100,1,14.28,100,1,14.47,100,1,14.48,700,1,14.51,200,2,ARL,335003849
2025-07-17T16:11:00.313087129Z,2025-07-17T16:11:00.312921679Z,160,2,1108,A,A,17.260000000,100,0,336570921,130,165450,280188038,ARL,0,17.26,100,130,165450,280188038,9.55,1700,17,9.68,100,1,10.61,200,2,11.27,100,1,11.4,100,1,11.76,100,1,11.93,200,2,12.1,100,1,12.2,200,2,12.33,100,1,13.58,15,1,13.59,100,1,13.6,15,1,13.82,2,1,13.86,100,1,14.25,100,1,14.28,100,1,14.47,100,1,14.48,700,1,14.51,200,2,ARL,336570921
2025-07-17T16:11:00.366811541Z,2025-07-17T16:11:00.366645846Z,160,2,1108,A,A,13.620000000,1,0,336572049,130,165695,280189435,ARL,0,13.62,1,130,165695,280189435,9.55,1700,17,9.68,100,1,10.61,200,2,11.27,100,1,11.4,100,1,11.76,100,1,11.93,200,2,12.1,100,1,12.2,200,2,12.33,100,1,13.58,15,1,13.59,100,1,13.6,15,1,13.62,1,1,13.82,2,1,13.86,100,1,14.25,100,1,14.28,100,1,14.47,100,1,14.48,700,1,ARL,336572049
2025-07-17T16:11:00.367374773Z,2025-07-17T16:11:00.367209243Z,160,2,1108,C,B,12.490000000,100,0,331942945,0,165530,280189439,ARL,0,12.49,100,0,165530,280189439,9.55,1700,17,9.68,100,1,10.61,200,2,11.27,100,1,11.4,100,1,11.76,100,1,11.93,200,2,12.1,100,1,12.2,200,2,12.33,100,1,13.58,15,1,13.59,100,1,13.6,15,1,13.62,1,1,13.82,2,1,13.86,100,1,14.25,100,1,14.28,100,1,14.47,100,1,14.48,700,1,ARL,331942945
2025-07-17T16:11:00.367374773Z,2025-07-17T16:11:00.367209243Z,160,2,1108,A,B,12.360000000,100,0,336572057,130,165530,280189439,ARL,0,12.36,100,130,165530,280189439,9.55,1700,17,9.68,100,1,10.61,200,2,11.27,100,1,11.4,100,1,11.76,100,1,11.93,200,2,12.1,100,1,12.2,200,2,12.33,100,1,13.58,15,1,13.59,100,1,13.6,15,1,13.62,1,1,13.82,2,1,13.86,100,1,14.25,100,1,14.28,100,1,14.47,100,1,14.48,700,1,ARL,336572057
2025-07-17T16:11:00.367485094Z,2025-07-17T16:11:00.367319059Z,160,2,1108,C,B,12.490000000,100,0,331942901,0,166035,280189441,ARL,0,12.49,100,0,166035,280189441,9.55,1700,17,9.68,100,1,10.61,200,2,11.27,100,1,11.4,100,1,11.76,100,1,11.93,200,2,12.1,100,1,12.2,200,2,12.33,100,1,13.58,15,1,13.59,100,1,13.6,15,1,13.62,1,1,13.82,2,1,13.86,100,1,14.25,100,1,14.28,100,1,14.47,100,1,14.48,700,1,ARL,331942901
2025-07-17T16:11:00.367485094Z,2025-07-17T16:11:00.367319059Z,160,2,1108,A,B,12.360000000,100,0,336572069,130,166035,280189441,ARL,0,12.36,100,130,166035,280189441,9.55,1700,17,9.68,100,1,10.61,200,2,11.27,100,1,11.4,100,1,11.76,100,1,11.93,200,2,12.1,100,1,12.2,200,2,12.33,100,1,13.58,15,1,13.59,100,1,13.6,15,1,13.62,1,1,13.82,2,1,13.86,100,1,14.25,100,1,14.28,100,1,14.47,100,1,14.48,700,1,ARL,336572069
2025-07-17T16:11:00.466868624Z,2025-07-17T16:11:00.466703632Z,160,2,1108,C,A,13.620000000,1,0,336572049,130,164992,280191783,ARL,0,13.62,1,130,164992,280191783,9.55,1700,17,9.68,100,1,10.61,200,2,11.27,100,1,11.4,100,1,11.76,100,1,11.93,200,2,12.1,100,1,12.2,200,2,12.33,100,1,13.58,15,1,13.59,100,1,13.6,15,1,13.82,2,1,13.86,100,1,14.25,100,1,14.28,100,1,14.47,100,1,14.48,700,1,14.51,200,2,ARL,336572049
2025-07-17T16:11:06.626831799Z,2025-07-17T16:11:06.626666474Z,160,2,1108,A,A,14.270000000,700,0,336747457,130,165325,280342316,ARL,0,14.27,700,130,165325,280342316,9.55,1700,17,9.68,100,1,10.61,200,2,11.27,100,1,11.4,100,1,11.76,100,1,11.93,200,2,12.1,100,1,12.2,200,2,12.33,100,1,13.58,15,1,13.59,100,1,13.6,15,1,13.82,2,1,13.86,100,1,14.25,100,1,14.27,700,1,14.28,100,1,14.47,100,1,14.48,700,1,ARL,336747457
2025-07-17T16:11:06.626906700Z,2025-07-17T16:11:06.626741446Z,160,2,1108,C,A,14.680000000,700,0,331929977,130,165254,280342318,ARL,0,14.68,700,130,165254,280342318,9.55,1700,17,9.68,100,1,10.61,200,2,11.27,100,1,11.4,100,1,11.76,100,1,11.93,200,2,12.1,100,1,12.2,200,2,12.33,100,1,13.58,15,1,13.59,100,1,13.6,15,1,13.82,2,1,13.86,100,1,14.25,100,1,14.27,700,1,14.28,100,1,14.47,100,1,14.48,700,1,ARL,331929977
2025-07-17T16:11:08.308034538Z,2025-07-17T16:11:08.307868957Z,160,2,1108,C,A,13.600000000,15,0,336402845,130,165581,280374785,ARL,0,13.6,15,130,165581,280374785,9.55,1700,17,9.68,100,1,10.61,200,2,11.27,100,1,11.4,100,1,11.76,100,1,11.93,200,2,12.1,100,1,12.2,200,2,12.33,100,1,13.58,15,1,13.59,100,1,13.82,2,1,13.86,100,1,14.25,100,1,14.27,700,1,14.28,100,1,14.47,100,1,14.48,700,1,14.51,200,2,ARL,336402845
2025-07-17T16:11:09.568536292Z,2025-07-17T16:11:09.568370995Z,160,2,1108,A,A,13.560000000,15,0,336816813,130,165297,280401189,ARL,0,13.56,15,130,165297,280401189,9.55,1700,17,9.68,100,1,10.61,200,2,11.27,100,1,11.4,100,1,11.76,100,1,11.93,200,2,12.1,100,1,12.2,200,2,12.33,100,1,13.56,15,1,13.58,15,1,13.59,100,1,13.82,2,1,13.86,100,1,14.25,100,1,14.27,700,1,14.28,100,1,14.47,100,1,14.48,700,1,ARL,336816813
2025-07-17T16:11:10.341953971Z,2025-07-17T16:11:10.341788521Z,160,2,1108,C,A,13.590000000,100,0,336567189,0,165450,280411396,ARL,0,13.59,100,0,165450,280411396,9.55,1700,17,9.68,100,1,10.61,200,2,11.27,100,1,11.4,100,1,11.76,100,1,11.93,200,2,12.1,100,1,12.2,200,2,12.33,100,1,13.56,15,1,13.58,15,1,13.82,2,1,13.86,100,1,14.25,100,1,14.27,700,1,14.28,100,1,14.47,100,1,14.48,700,1,14.51,200,2,ARL,336567189
2025-07-17T16:11:10.341953971Z,2025-07-17T16:11:10.341788521Z,160,2,1108,A,A,13.570000000,100,0,336828765,130,165450,280411396,ARL,0,13.57,100,130,165450,280411396,9.55,1700,17,9.68,100,1,10.61,200,2,11.27,100,1,11.4,100,1,11.76,100,1,11.93,200,2,12.1,100,1,12.2,200,2,12.33,100,1,13.56,15,1,13.57,100,1,13.58,15,1,13.82,2,1,13.86,100,1,14.25,100,1,14.27,700,1,14.28,100,1,14.47,100,1,14.48,700,1,ARL,336828765
2025-07-17T16:11:14.610701450Z,2025-07-17T16:11:14.610535763Z,160,2,1108,C,A,13.580000000,15,0,336555153,130,165687,280482371,ARL,0,13.58,15,130,165687,280482371,9.55,1700,17,9.68,100,1,10.61,200,2,11.27,100,1,11.4,100,1,11.76,100,1,11.93,200,2,12.1,100,1,12.2,200,2,12.33,100,1,13.56,15,1,13.57,100,1,13.82,2,1,13.86,100,1,14.25,100,1,14.27,700,1,14.28,100,1,14.47,100,1,14.48,700,1,14.51,200,2,ARL,336555153
2025-07-17T16:11:16.025458231Z,2025-07-17T16:11:16.025292936Z,160,2,1108,C,A,13.560000000,15,0,336816813,130,165295,280514282,ARL,0,13.56,15,130,165295,280514282,9.55,1700,17,9.68,100,1,10.61,200,2,11.27,100,1,11.4,100,1,11.76,100,1,11.93,200,2,12.1,100,1,12.2,200,2,12.33,100,1,13.57,100,1,13.82,2,1,13.86,100,1,14.25,100,1,14.27,700,1,14.28,100,1,14.47,100,1,14.48,700,1,14.51,200,2,14.56,800,2,ARL,336816813
2025-07-17T16:11:50.026837358Z,2025-07-17T16:11:50.026672014Z,160,2,1108,A,A,13.550000000,15,0,337690189,130,165344,281078802,ARL,0,13.55,15,130,165344,281078802,9.55,1700,17,9.68,100,1,10.61,200,2,11.27,100,1,11.4,100,1,11.76,100,1,11.93,200,2,12.1,100,1,12.2,200,2,12.33,100,1,13.55,15,1,13.57,100,1,13.82,2,1,13.86,100,1,14.25,100,1,14.27,700,1,14.28,100,1,14.47,100,1,14.48,700,1,14.51,200,2,ARL,337690189
2025-07-17T16:11:50.027004977Z,2025-07-17T16:11:50.026839463Z,160,2,1108,C,A,13.570000000,100,0,336828765,0,165514,281078803,ARL,0,13.57,100,0,165514,281078803,9.55,1700,17,9.68,100,1,10.61,200,2,11.27,100,1,11.4,100,1,11.76,100,1,11.93,200,2,12.1,100,1,12.2,200,2,12.33,100,1,13.55,15,1,13.82,2,1,13.86,100,1,14.25,100,1,14.27,700,1,14.28,100,1,14.47,100,1,14.48,700,1,14.51,200,2,14.56,800,2,ARL,336828765
2025-07-17T16:11:50.027004977Z,2025-07-17T16:11:50.026839463Z,160,2,1108,A,A,13.560000000,100,0,337690193,130,165514,281078803,ARL,0,13.56,100,130,165514,281078803,9.55,1700,17,9.68,100,1,10.61,200,2,11.27,100,1,11.4,100,1,11.76,100,1,11.93,200,2,12.1,100,1,12.2,200,2,12.33,100,1,13.55,15,1,13.56,100,1,13.82,2,1,13.86,100,1,14.25,100,1,14.27,700,1,14.28,100,1,14.47,100,1,14.48,700,1,14.51,200,2,ARL,337690193
2025-07-17T16:11:50.033010798Z,2025-07-17T16:11:50.032845393Z,160,2,1108,C,A,15.740000000,100,0,335220497,0,165405,281078903,ARL,0,15.74,100,0,165405,281078903,9.55,1700,17,9.68,100,1,10.61,200,2,11.27,100,1,11.4,100,1,11.76,100,1,11.93,200,2,12.1,100,1,12.2,200,2,12.33,100,1,13.55,15,1,13.56,100,1,13.82,2,1,13.86,100,1,14.25,100,1,14.27,700,1,14.28,100,1,14.47,100,1,14.48,700,1,14.51,200,2,ARL,335220497
2025-07-17T16:11:50.033010798Z,2025-07-17T16:11:50.032845393Z,160,2,1108,A,A,15.600000000,100,0,337690641,130,165405,281078903,ARL,0,15.6,100,130,165405,281078903,9.55,1700,17,9.68,100,1,10.61,200,2,11.27,100,1,11.4,100,1,11.76,100,1,11.93,200,2,12.1,100,1,12.2,200,2,12.33,100,1,13.55,15,1,13.56,100,1,13.82,2,1,13.86,100,1,14.25,100,1,14.27,700,1,14.28,100,1,14.47,100,1,14.48,700,1,14.51,200,2,ARL,337690641
2025-07-17T16:11:53.859909462Z,2025-07-17T16:11:53.859743991Z,160,2,1108,A,A,13.530000000,15,0,337772837,130,165471,281142794,ARL,0,13.53,15,130,165471,281142794,9.55,1700,17,9.68,100,1,10.61,200,2,11.27,100,1,11.4,100,1,11.76,100,1,11.93,200,2,12.1,100,1,12.2,200,2,12.33,100,1,13.53,15,1,13.55,15,1,13.56,100,1,13.82,2,1,13.86,100,1,14.25,100,1,14.27,700,1,14.28,100,1,14.47,100,1,14.48,700,1,ARL,337772837
2025-07-17T16:11:54.662527332Z,2025-07-17T16:11:54.662361841Z,160,2,1108,C,A,13.560000000,100,0,337690193,0,165491,281156215,ARL,0,13.56,100,0,165491,281156215,9.55,1700,17,9.68,100,1,10.61,200,2,11.27,100,1,11.4,100,1,11.76,100,1,11.93,200,2,12.1,100,1,12.2,200,2,12.33,100,1,13.53,15,1,13.55,15,1,13.82,2,1,13.86,100,1,14.25,100,1,14.27,700,1,14.28,100,1,14.47,100,1,14.48,700,1,14.51,200,2,ARL,337690193
2025-07-17T16:11:54.662527332Z,2025-07-17T16:11:54.662361841Z,160,2,1108,A,A,13.540000000,100,0,337790717,130,165491,281156215,ARL,0,13.54,100,130,165491,281156215,9.55,1700,17,9.68,100,1,10.61,200,2,11.27,100,1,11.4,100,1,11.76,100,1,11.93,200,2,12.1,100,1,12.2,200,2,12.33,100,1,13.53,15,1,13.54,100,1,13.55,15,1,13.82,2,1,13.86,100,1,14.25,100,1,14.27,700,1,14.28,100,1,14.47,100,1,14.48,700,1,ARL,337790717
2025-07-17T16:11:54.663278200Z,2025-07-17T16:11:54.663112543Z,160,2,1108,C,A,14.640000000,100,0,336567213,0,165657,281156222,ARL,0,14.64,100,0,165657,281156222,9.55,1700,17,9.68,100,1,10.61,200,2,11.27,100,1,11.4,100,1,11.76,100,1,11.93,200,2,12.1,100,1,12.2,200,2,12.33,100,1,13.53,15,1,13.54,100,1,13.55,15,1,13.82,2,1,13.86,100,1,14.25,100,1,14.27,700,1,14.28,100,1,14.47,100,1,14.48,700,1,ARL,336567213
2025-07-17T16:11:54.663278200Z,2025-07-17T16:11:54.663112543Z,160,2,1108,A,A,14.590000000,100,0,337790737,130,165657,281156222,ARL,0,14.59,100,130,165657,281156222,9.55,1700,17,9.68,100,1,10.61,200,2,11.27,100,1,11.4,100,1,11.76,100,1,11.93,200,2,12.1,100,1,12.2,200,2,12.33,100,1,13.53,15,1,13.54,100,1,13.55,15,1,13.82,2,1,13.86,100,1,14.25,100,1,14.27,700,1,14.28,100,1,14.47,100,1,14.48,700,1,ARL,337790737
2025-07-17T16:11:54.664134026Z,2025-07-17T16:11:54.663968656Z,160,2,1108,C,A,14.640000000,100,0,335220525,0,165370,281156223,ARL,0,14.64,100,0,165370,281156223,9.55,1700,17,9.68,100,1,10.61,200,2,11.27,100,1,11.4,100,1,11.76,100,1,11.93,200,2,12.1,100,1,12.2,200,2,12.33,100,1,13.53,15,1,13.54,100,1,13.55,15,1,13.82,2,1,13.86,100,1,14.25,100,1,14.27,700,1,14.28,100,1,14.47,100,1,14.48,700,1,ARL,335220525
2025-07-17T16:11:54.664134026Z,2025-07-17T16:11:54.663968656Z,160,2,1108,A,A,14.490000000,100,0,337790745,130,165370,281156223,ARL,0,14.49,100,130,165370,281156223,9.55,1700,17,9.68,100,1,10.61,200,2,11.27,100,1,11.4,100,1,11.76,100,1,11.93,200,2,12.1,100,1,12.2,200,2,12.33,100,1,13.53,15,1,13.54,100,1,13.55,15,1,13.82,2,1,13.86,100,1,14.25,100,1,14.27,700,1,14.28,100,1,14.47,100,1,14.48,700,1,ARL,337790745
2025-07-17T16:11:54.666326600Z,2025-07-17T16:11:54.666160990Z,160,2,1108,C,A,14.470000000,100,0,335220561,0,165610,281156243,ARL,0,14.47,100,0,165610,281156243,9.55,1700,17,9.68,100,1,10.61,200,2,11.27,100,1,11.4,100,1,11.76,100,1,11.93,200,2,12.1,100,1,12.2,200,2,12.33,100,1,13.53,15,1,13.54,100,1,13.55,15,1,13.82,2,1,13.86,100,1,14.25,100,1,14.27,700,1,14.28,100,1,14.48,700,1,14.49,100,1,ARL,335220561
2025-07-17T16:11:54.666326600Z,2025-07-17T16:11:54.666160990Z,160,2,1108,A,A,14.330000000,100,0,337790761,130,165610,281156243,ARL,0,14.33,100,130,165610,281156243,9.55,1700,17,9.68,100,1,10.61,200,2,11.27,100,1,11.4,100,1,11.76,100,1,11.93,200,2,12.1,100,1,12.2,200,2,12.33,100,1,13.53,15,1,13.54,100,1,13.55,15,1,13.82,2,1,13.86,100,1,14.25,100,1,14.27,700,1,14.28,100,1,14.33,100,1,14.48,700,1,ARL,337790761
2025-07-17T16:11:54.667504546Z,2025-07-17T16:11:54.667339002Z,160,2,1108,C,A,14.640000000,100,0,335220629,0,165544,281156250,ARL,0,14.64,100,0,165544,281156250,9.55,1700,17,9.68,100,1,10.61,200,2,11.27,100,1,11.4,100,1,11.76,100,1,11.93,200,2,12.1,100,1,12.2,200,2,12.33,100,1,13.53,15,1,13.54,100,1,13.55,15,1,13.82,2,1,13.86,100,1,14.25,100,1,14.27,700,1,14.28,100,1,14.33,100,1,14.48,700,1,ARL,335220629
2025-07-17T16:11:54.667504546Z,2025-07-17T16:11:54.667339002Z,160,2,1108,A,A,14.490000000,100,0,337790777,130,165544,281156250,ARL,0,14.49,100,130,165544,281156250,9.55,1700,17,9.68,100,1,10.61,200,2,11.27,100,1,11.4,100,1,11.76,100,1,11.93,200,2,12.1,100,1,12.2,200,2,12.33,100,1,13.53,15,1,13.54,100,1,13.55,15,1,13.82,2,1,13.86,100,1,14.25,100,1,14.27,700,1,14.28,100,1,14.33,100,1,14.48,700,1,ARL,337790777
2025-07-17T16:11:59.382515678Z,2025-07-17T16:11:59.382350338Z,160,2,1108,C,A,13.550000000,15,0,337690189,130,165340,281270010,ARL,0,13.55,15,130,165340,281270010,9.55,1700,17,9.68,100,1,10.61,200,2,11.27,100,1,11.4,100,1,11.76,100,1,11.93,200,2,12.1,100,1,12.2,200,2,12.33,100,1,13.53,15,1,13.54,100,1,13.82,2,1,13.86,100,1,14.25,100,1,14.27,700,1,14.28,100,1,14.33,100,1,14.48,700,1,14.49,200,2,ARL,337690189
2025-07-17T16:12:02.982078719Z,2025-07-17T16:12:02.981913204Z,160,2,1108,A,A,13.510000000,15,0,338041605,130,165515,281348152,ARL,0,13.51,15,130,165515,281348152,9.55,1700,17,9.68,100,1,10.61,200,2,11.27,100,1,11.4,100,1,11.76,100,1,11.93,200,2,12.1,100,1,12.2,200,2,12.33,100,1,13.51,15,1,13.53,15,1,13.54,100,1,13.82,2,1,13.86,100,1,14.25,100,1,14.27,700,1,14.28,100,1,14.33,100,1,14.48,700,1,ARL,338041605
2025-07-17T16:12:03.064162605Z,2025-07-17T16:12:03.063997054Z,160,2,1108,C,A,13.540000000,100,0,337790717,0,165551,281351122,ARL,0,13.54,100,0,165551,281351122,9.55,1700,17,9.68,100,1,10.61,200,2,11.27,100,1,11.4,100,1,11.76,100,1,11.93,200,2,12.1,100,1,12.2,200,2,12.33,100,1,13.51,15,1,13.53,15,1,13.82,2,1,13.86,100,1,14.25,100,1,14.27,700,1,14.28,100,1,14.33,100,1,14.48,700,1,14.49,200,2,ARL,337790717
2025-07-17T16:12:03.064162605Z,2025-07-17T16:12:03.063997054Z,160,2,1108,A,A,13.520000000,100,0,338044041,130,165551,281351122,ARL,0,13.52,100,130,165551,281351122,9.55,1700,17,9.68,100,1,10.61,200,2,11.27,100,1,11.4,100,1,11.76,100,1,11.93,200,2,12.1,100,1,12.2,200,2,12.33,100,1,13.51,15,1,13.52,100,1,13.53,15,1,13.82,2,1,13.86,100,1,14.25,100,1,14.27,700,1,14.28,100,1,14.33,100,1,14.48,700,1,ARL,338044041
2025-07-17T16:12:03.068467146Z,2025-07-17T16:12:03.068301745Z,160,2,1108,C,B,13.010000000,2,0,332494213,0,165401,281351235,ARL,0,13.01,2,0,165401,281351235,9.55,1700,17,9.68,100,1,10.61,200,2,11.27,100,1,11.4,100,1,11.76,100,1,11.93,200,2,12.1,100,1,12.2,200,2,12.33,100,1,13.51,15,1,13.52,100,1,13.53,15,1,13.82,2,1,13.86,100,1,14.25,100,1,14.27,700,1,14.28,100,1,14.33,100,1,14.48,700,1,ARL,332494213
2025-07-17T16:12:03.068467146Z,2025-07-17T16:12:03.068301745Z,160,2,1108,A,B,12.920000000,2,0,338044113,130,165401,281351235,ARL,0,12.92,2,130,165401,281351235,9.55,1700,17,9.68,100,1,10.61,200,2,11.27,100,1,11.4,100,1,11.76,100,1,11.93,200,2,12.1,100,1,12.2,200,2,12.33,100,1,13.51,15,1,13.52,100,1,13.53,15,1,13.82,2,1,13.86,100,1,14.25,100,1,14.27,700,1,14.28,100,1,14.33,100,1,14.48,700,1,ARL,338044113
2025-07-17T16:12:03.075200038Z,2025-07-17T16:12:03.075034550Z,160,2,1108,C,A,13.860000000,100,0,336567333,130,165488,281351372,ARL,0,13.86,100,130,165488,281351372,9.55,1700,17,9.68,100,1,10.61,200,2,11.27,100,1,11.4,100,1,11.76,100,1,11.93,200,2,12.1,100,1,12.2,200,2,12.33,100,1,13.51,15,1,13.52,100,1,13.53,15,1,13.82,2,1,14.25,100,1,14.27,700,1,14.28,100,1,14.33,100,1,14.48,700,1,14.49,200,2,ARL,336567333
2025-07-17T16:12:03.075260529Z,2025-07-17T16:12:03.075095341Z,160,2,1108,A,A,13.790000000,100,0,338044233,130,165188,281351373,ARL,0,13.79,100,130,165188,281351373,9.55,1700,17,9.68,100,1,10.61,200,2,11.27,100,1,11.4,100,1,11.76,100,1,11.93,200,2,12.1,100,1,12.2,200,2,12.33,100,1,13.51,15,1,13.52,100,1,13.53,15,1,13.79,100,1,13.82,2,1,14.25,100,1,14.27,700,1,14.28,100,1,14.33,100,1,14.48,700,1,ARL,338044233
2025-07-17T16:12:06.775177637Z,2025-07-17T16:12:06.775011783Z,160,2,1108,C,A,14.510000000,100,0,336259225,0,165854,281422697,ARL,0,14.51,100,0,165854,281422697,9.55,1700,17,9.68,100,1,10.61,200,2,11.27,100,1,11.4,100,1,11.76,100,1,11.93,200,2,12.1,100,1,12.2,200,2,12.33,100,1,13.51,15,1,13.52,100,1,13.53,15,1,13.79,100,1,13.82,2,1,14.25,100,1,14.27,700,1,14.28,100,1,14.33,100,1,14.48,700,1,ARL,336259225
2025-07-17T16:12:06.775177637Z,2025-07-17T16:12:06.775011783Z,160,2,1108,A,A,14.400000000,100,0,338139585,130,165854,281422697,ARL,0,14.4,100,130,165854,281422697,9.55,1700,17,9.68,100,1,10.61,200,2,11.27,100,1,11.4,100,1,11.76,100,1,11.93,200,2,12.1,100,1,12.2,200,2,12.33,100,1,13.51,15,1,13.52,100,1,13.53,15,1,13.79,100,1,13.82,2,1,14.25,100,1,14.27,700,1,14.28,100,1,14.33,100,1,14.4,100,1,ARL,338139585
2025-07-17T16:12:06.775614536Z,2025-07-17T16:12:06.775449017Z,160,2,1108,C,A,14.510000000,100,0,336261905,0,165519,281422702,ARL,0,14.51,100,0,165519,281422702,9.55,1700,17,9.68,100,1,10.61,200,2,11.27,100,1,11.4,100,1,11.76,100,1,11.93,200,2,12.1,100,1,12.2,200,2,12.33,100,1,13.51,15,1,13.52,100,1,13.53,15,1,13.79,100,1,13.82,2,1,14.25,100,1,14.27,700,1,14.28,100,1,14.33,100,1,14.4,100,1,ARL,336261905
2025-07-17T16:12:06.775614536Z,2025-07-17T16:12:06.775449017Z,160,2,1108,A,A,14.400000000,100,0,338139601,130,165519,281422702,ARL,0,14.4,100,130,165519,281422702,9.55,1700,17,9.68,100,1,10.61,200,2,11.27,100,1,11.4,100,1,11.76,100,1,11.93,200,2,12.1,100,1,12.2,200,2,12.33,100,1,13.51,15,1,13.52,100,1,13.53,15,1,13.79,100,1,13.82,2,1,14.25,100,1,14.27,700,1,14.28,100,1,14.33,100,1,14.4,200,2,ARL,338139601
2025-07-17T16:12:06.779705717Z,2025-07-17T16:12:06.779540143Z,160,2,1108,C,A,13.530000000,15,0,337772837,130,165574,281422782,ARL,0,13.53,15,130,165574,281422782,9.55,1700,17,9.68,100,1,10.61,200,2,11.27,100,1,11.4,100,1,11.76,100,1,11.93,200,2,12.1,100,1,12.2,200,2,12.33,100,1,13.51,15,1,13.52,100,1,13.79,100,1,13.82,2,1,14.25,100,1,14.27,700,1,14.28,100,1,14.33,100,1,14.4,200,2,14.48,700,1,ARL,337772837
2025-07-17T16:12:07.784698893Z,2025-07-17T16:12:07.784533539Z,160,2,1108,A,A,13.490000000,15,0,338167057,130,165354,281443568,ARL,0,13.49,15,130,165354,281443568,9.55,1700,17,9.68,100,1,10.61,200,2,11.27,100,1,11.4,100,1,11.76,100,1,11.93,200,2,12.1,100,1,12.2,200,2,12.33,100,1,13.49,15,1,13.51,15,1,13.52,100,1,13.79,100,1,13.82,2,1,14.25,100,1,14.27,700,1,14.28,100,1,14.33,100,1,14.4,200,2,ARL,338167057
2025-07-17T16:12:08.585194585Z,2025-07-17T16:12:08.585029039Z,160,2,1108,C,A,13.520000000,100,0,338044041,0,165546,281451898,ARL,0,13.52,100,0,165546,281451898,9.55,1700,17,9.68,100,1,10.61,200,2,11.27,100,1,11.4,100,1,11.76,100,1,11.93,200,2,12.1,100,1,12.2,200,2,12.33,100,1,13.49,15,1,13.51,15,1,13.79,100,1,13.82,2,1,14.25,100,1,14.27,700,1,14.28,100,1,14.33,100,1,14.4,200,2,14.48,700,1,ARL,338044041
2025-07-17T16:12:08.585194585Z,2025-07-17T16:12:08.585029039Z,160,2,1108,A,A,13.500000000,100,0,338180793,130,165546,281451898,ARL,0,13.5,100,130,165546,281451898,9.55,1700,17,9.68,100,1,10.61,200,2,11.27,100,1,11.4,100,1,11.76,100,1,11.93,200,2,12.1,100,1,12.2,200,2,12.33,100,1,13.49,15,1,13.5,100,1,13.51,15,1,13.79,100,1,13.82,2,1,14.25,100,1,14.27,700,1,14.28,100,1,14.33,100,1,14.4,200,2,ARL,338180793
2025-07-17T16:12:08.585942049Z,2025-07-17T16:12:08.585776508Z,160,2,1108,C,A,14.590000000,100,0,337790737,0,165541,281451903,ARL,0,14.59,100,0,165541,281451903,9.55,1700,17,9.68,100,1,10.61,200,2,11.27,100,1,11.4,100,1,11.76,100,1,11.93,200,2,12.1,100,1,12.2,200,2,12.33,100,1,13.49,15,1,13.5,100,1,13.51,15,1,13.79,100,1,13.82,2,1,14.25,100,1,14.27,700,1,14.28,100,1,14.33,100,1,14.4,200,2,ARL,337790737
2025-07-17T16:12:08.585942049Z,2025-07-17T16:12:08.585776508Z,160,2,1108,A,A,14.550000000,100,0,338180841,130,165541,281451903,ARL,0,14.55,100,130,165541,281451903,9.55,1700,17,9.68,100,1,10.61,200,2,11.27,100,1,11.4,100,1,11.76,100,1,11.93,200,2,12.1,100,1,12.2,200,2,12.33,100,1,13.49,15,1,13.5,100,1,13.51,15,1,13.79,100,1,13.82,2,1,14.25,100,1,14.27,700,1,14.28,100,1,14.33,100,1,14.4,200,2,ARL,338180841
2025-07-17T16:12:18.789922022Z,2025-07-17T16:12:18.789756367Z,160,2,1108,C,A,13.820000000,2,0,336447325,0,165655,281613266,ARL,0,13.82,2,0,165655,281613266,9.55,1700,17,9.68,100,1,10.61,200,2,11.27,100,1,11.4,100,1,11.76,100,1,11.93,200,2,12.1,100,1,12.2,200,2,12.33,100,1,13.49,15,1,13.5,100,1,13.51,15,1,13.79,100,1,14.25,100,1,14.27,700,1,14.28,100,1,14.33,100,1,14.4,200,2,14.48,700,1,ARL,336447325
2025-07-17T16:12:18.789922022Z,2025-07-17T16:12:18.789756367Z,160,2,1108,A,A,13.740000000,2,0,338371797,130,165655,281613266,ARL,0,13.74,2,130,165655,281613266,9.55,1700,17,9.68,100,1,10.61,200,2,11.27,100,1,11.4,100,1,11.76,100,1,11.93,200,2,12.1,100,1,12.2,200,2,12.33,100,1,13.49,15,1,13.5,100,1,13.51,15,1,13.74,2,1,13.79,100,1,14.25,100,1,14.27,700,1,14.28,100,1,14.33,100,1,14.4,200,2,ARL,338371797
2025-07-17T16:12:19.370986404Z,2025-07-17T16:12:19.370820933Z,160,2,1108,A,A,14.270000000,700,0,338382329,130,165471,281622545,ARL,0,14.27,700,130,165471,281622545,9.55,1700,17,9.68,100,1,10.61,200,2,11.27,100,1,11.4,100,1,11.76,100,1,11.93,200,2,12.1,100,1,12.2,200,2,12.33,100,1,13.49,15,1,13.5,100,1,13.51,15,1,13.74,2,1,13.79,100,1,14.25,100,1,14.27,1400,2,14.28,100,1,14.33,100,1,14.4,200,2,ARL,338382329
2025-07-17T16:12:19.371041049Z,2025-07-17T16:12:19.370875240Z,160,2,1108,C,A,14.600000000,700,0,282920685,130,165809,281622547,ARL,0,14.6,700,130,165809,281622547,9.55,1700,17,9.68,100,1,10.61,200,2,11.27,100,1,11.4,100,1,11.76,100,1,11.93,200,2,12.1,100,1,12.2,200,2,12.33,100,1,13.49,15,1,13.5,100,1,13.51,15,1,13.74,2,1,13.79,100,1,14.25,100,1,14.27,1400,2,14.28,100,1,14.33,100,1,14.4,200,2,ARL,282920685
2025-07-17T16:12:19.696689718Z,2025-07-17T16:12:19.696521343Z,160,2,1108,C,A,13.490000000,15,0,338167057,128,168375,281630053,ARL,0,13.49,15,128,168375,281630053,9.55,1700,17,9.68,100,1,10.61,200,2,11.27,100,1,11.4,100,1,11.76,100,1,11.93,200,2,12.1,100,1,12.2,200,2,12.33,100,1,13.5,100,1,13.51,15,1,13.74,2,1,13.79,100,1,14.25,100,1,14.27,1400,2,14.28,100,1,14.33,100,1,14.4,200,2,14.48,700,1,ARL,338167057
2025-07-17T16:12:19.711773364Z,2025-07-17T16:12:19.711591494Z,160,2,1108,C,A,13.510000000,15,0,338041605,128,181870,281634812,ARL,0,13.51,15,128,181870,281634812,9.55,1700,17,9.68,100,1,10.61,200,2,11.27,100,1,11.4,100,1,11.76,100,1,11.93,200,2,12.1,100,1,12.2,200,2,12.33,100,1,13.5,100,1,13.74,2,1,13.79,100,1,14.25,100,1,14.27,1400,2,14.28,100,1,14.33,100,1,14.4,200,2,14.48,700,1,14.49,200,2,ARL,338041605
2025-07-17T16:12:32.761277424Z,2025-07-17T16:12:32.761112078Z,160,2,1108,A,A,13.480000000,15,0,338707945,130,165346,281880398,ARL,0,13.48,15,130,165346,281880398,9.55,1700,17,9.68,100,1,10.61,200,2,11.27,100,1,11.4,100,1,11.76,100,1,11.93,200,2,12.1,100,1,12.2,200,2,12.33,100,1,13.48,15,1,13.5,100,1,13.74,2,1,13.79,100,1,14.25,100,1,14.27,1400,2,14.28,100,1,14.33,100,1,14.4,200,2,14.48,700,1,ARL,338707945
2025-07-17T16:12:32.761413202Z,2025-07-17T16:12:32.761246859Z,160,2,1108,C,A,13.500000000,100,0,338180793,0,166343,281880409,ARL,0,13.5,100,0,166343,281880409,9.55,1700,17,9.68,100,1,10.61,200,2,11.27,100,1,11.4,100,1,11.76,100,1,11.93,200,2,12.1,100,1,12.2,200,2,12.33,100,1,13.48,15,1,13.74,2,1,13.79,100,1,14.25,100,1,14.27,1400,2,14.28,100,1,14.33,100,1,14.4,200,2,14.48,700,1,14.49,200,2,ARL,338180793
2025-07-17T16:12:32.761413202Z,2025-07-17T16:12:32.761246859Z,160,2,1108,A,A,13.490000000,100,0,338707949,130,166343,281880409,ARL,0,13.49,100,130,166343,281880409,9.55,1700,17,9.68,100,1,10.61,200,2,11.27,100,1,11.4,100,1,11.76,100,1,11.93,200,2,12.1,100,1,12.2,200,2,12.33,100,1,13.48,15,1,13.49,100,1,13.74,2,1,13.79,100,1,14.25,100,1,14.27,1400,2,14.28,100,1,14.33,100,1,14.4,200,2,14.48,700,1,ARL,338707949
2025-07-17T16:12:32.779055996Z,2025-07-17T16:12:32.778890447Z,160,2,1108,C,A,15.120000000,100,0,296387089,0,165549,281880579,ARL,0,15.12,100,0,165549,281880579,9.55,1700,17,9.68,100,1,10.61,200,2,11.27,100,1,11.4,100,1,11.76,100,1,11.93,200,2,12.1,100,1,12.2,200,2,12.33,100,1,13.48,15,1,13.49,100,1,13.74,2,1,13.79,100,1,14.25,100,1,14.27,1400,2,14.28,100,1,14.33,100,1,14.4,200,2,14.48,700,1,ARL,296387089
2025-07-17T16:12:32.779055996Z,2025-07-17T16:12:32.778890447Z,160,2,1108,A,A,14.840000000,100,0,338708241,130,165549,281880579,ARL,0,14.84,100,130,165549,281880579,9.55,1700,17,9.68,100,1,10.61,200,2,11.27,100,1,11.4,100,1,11.76,100,1,11.93,200,2,12.1,100,1,12.2,200,2,12.33,100,1,13.48,15,1,13.49,100,1,13.74,2,1,13.79,100,1,14.25,100,1,14.27,1400,2,14.28,100,1,14.33,100,1,14.4,200,2,14.48,700,1,ARL,338708241
2025-07-17T16:12:32.804318005Z,2025-07-17T16:12:32.804152457Z,160,2,1108,A,A,15.380000000,100,0,338709513,130,165548,281880972,ARL,0,15.38,100,130,165548,281880972,9.55,1700,17,9.68,100,1,10.61,200,2,11.27,100,1,11.4,100,1,11.76,100,1,11.93,200,2,12.1,100,1,12.2,200,2,12.33,100,1,13.48,15,1,13.49,100,1,13.74,2,1,13.79,100,1,14.25,100,1,14.27,1400,2,14.28,100,1,14.33,100,1,14.4,200,2,14.48,700,1,ARL,338709513
2025-07-17T16:12:32.804332586Z,2025-07-17T16:12:32.804166092Z,160,2,1108,C,A,15.660000000,100,0,326730513,130,166494,281880973,ARL,0,15.66,100,130,166494,281880973,9.55,1700,17,9.68,100,1,10.61,200,2,11.27,100,1,11.4,100,1,11.76,100,1,11.93,200,2,12.1,100,1,12.2,200,2,12.33,100,1,13.48,15,1,13.49,100,1,13.74,2,1,13.79,100,1,14.25,100,1,14.27,1400,2,14.28,100,1,14.33,100,1,14.4,200,2,14.48,700,1,ARL,326730513
2025-07-17T16:12:40.993064296Z,2025-07-17T16:12:40.992898990Z,160,2,1108,C,A,13.490000000,100,0,338707949,130,165306,282007871,ARL,0,13.49,100,130,165306,282007871,9.55,1700,17,9.68,100,1,10.61,200,2,11.27,100,1,11.4,100,1,11.76,100,1,11.93,200,2,12.1,100,1,12.2,200,2,12.33,100,1,13.48,15,1,13.74,2,1,13.79,100,1,14.25,100,1,14.27,1400,2,14.28,100,1,14.33,100,1,14.4,200,2,14.48,700,1,14.49,200,2,ARL,338707949
2025-07-17T16:12:40.993332664Z,2025-07-17T16:12:40.993167418Z,160,2,1108,C,A,14.270000000,700,0,338382329,130,165246,282007875,ARL,0,14.27,700,130,165246,282007875,9.55,1700,17,9.68,100,1,10.61,200,2,11.27,100,1,11.4,100,1,11.76,100,1,11.93,200,2,12.1,100,1,12.2,200,2,12.33,100,1,13.48,15,1,13.74,2,1,13.79,100,1,14.25,100,1,14.27,700,1,14.28,100,1,14.33,100,1,14.4,200,2,14.48,700,1,14.49,200,2,ARL,338382329
2025-07-17T16:12:40.993333790Z,2025-07-17T16:12:40.993168470Z,160,2,1108,C,A,14.270000000,700,0,336747457,130,165320,282007876,ARL,0,14.27,700,130,165320,282007876,9.55,1700,17,9.68,100,1,10.61,200,2,11.27,100,1,11.4,100,1,11.76,100,1,11.93,200,2,12.1,100,1,12.2,200,2,12.33,100,1,13.48,15,1,13.74,2,1,13.79,100,1,14.25,100,1,14.28,100,1,14.33,100,1,14.4,200,2,14.48,700,1,14.49,200,2,14.55,100,1,ARL,336747457
2025-07-17T16:12:40.993379626Z,2025-07-17T16:12:40.993214193Z,160,2,1108,A,A,14.540000000,700,0,338864169,130,165433,282007877,ARL,0,14.54,700,130,165433,282007877,9.55,1700,17,9.68,100,1,10.61,200,2,11.27,100,1,11.4,100,1,11.76,100,1,11.93,200,2,12.1,100,1,12.2,200,2,12.33,100,1,13.48,15,1,13.74,2,1,13.79,100,1,14.25,100,1,14.28,100,1,14.33,100,1,14.4,200,2,14.48,700,1,14.49,200,2,14.54,700,1,ARL,338864169
2025-07-17T16:12:40.993393440Z,2025-07-17T16:12:40.993227993Z,160,2,1108,A,A,14.470000000,700,0,338864173,130,165447,282007878,ARL,0,14.47,700,130,165447,282007878,9.55,1700,17,9.68,100,1,10.61,200,2,11.27,100,1,11.4,100,1,11.76,100,1,11.93,200,2,12.1,100,1,12.2,200,2,12.33,100,1,13.48,15,1,13.74,2,1,13.79,100,1,14.25,100,1,14.28,100,1,14.33,100,1,14.4,200,2,14.47,700,1,14.48,700,1,14.49,200,2,ARL,338864173
2025-07-17T16:12:40.993432115Z,2025-07-17T16:12:40.993266591Z,160,2,1108,A,A,15.710000000,100,0,338864177,130,165524,282007879,ARL,0,15.71,100,130,165524,282007879,9.55,1700,17,9.68,100,1,10.61,200,2,11.27,100,1,11.4,100,1,11.76,100,1,11.93,200,2,12.1,100,1,12.2,200,2,12.33,100,1,13.48,15,1,13.74,2,1,13.79,100,1,14.25,100,1,14.28,100,1,14.33,100,1,14.4,200,2,14.47,700,1,14.48,700,1,14.49,200,2,ARL,338864177
2025-07-17T16:12:40.993445042Z,2025-07-17T16:12:40.993279810Z,160,2,1108,C,A,15.380000000,100,0,338709513,130,165232,282007880,ARL,0,15.38,100,130,165232,282007880,9.55,1700,17,9.68,100,1,10.61,200,2,11.27,100,1,11.4,100,1,11.76,100,1,11.93,200,2,12.1,100,1,12.2,200,2,12.33,100,1,13.48,15,1,13.74,2,1,13.79,100,1,14.25,100,1,14.28,100,1,14.33,100,1,14.4,200,2,14.47,700,1,14.48,700,1,14.49,200,2,ARL,338709513
2025-07-17T16:12:40.993818130Z,2025-07-17T16:12:40.993652511Z,160,2,1108,C,A,14.550000000,100,0,338180841,0,165619,282007882,ARL,0,14.55,100,0,165619,282007882,9.55,1700,17,9.68,100,1,10.61,200,2,11.27,100,1,11.4,100,1,11.76,100,1,11.93,200,2,12.1,100,1,12.2,200,2,12.33,100,1,13.48,15,1,13.74,2,1,13.79,100,1,14.25,100,1,14.28,100,1,14.33,100,1,14.4,200,2,14.47,700,1,14.48,700,1,14.49,200,2,ARL,338180841
2025-07-17T16:12:40.993818130Z,2025-07-17T16:12:40.993652511Z,160,2,1108,A,A,14.850000000,100,0,338864189,130,165619,282007882,ARL,0,14.85,100,130,165619,282007882,9.55,1700,17,9.68,100,1,10.61,200,2,11.27,100,1,11.4,100,1,11.76,100,1,11.93,200,2,12.1,100,1,12.2,200,2,12.33,100,1,13.48,15,1,13.74,2,1,13.79,100,1,14.25,100,1,14.28,100,1,14.33,100,1,14.4,200,2,14.47,700,1,14.48,700,1,14.49,200,2,ARL,338864189
2025-07-17T16:12:40.994783297Z,2025-07-17T16:12:40.994617858Z,160,2,1108,C,A,14.490000000,100,0,337790745,0,165439,282007892,ARL,0,14.49,100,0,165439,282007892,9.55,1700,17,9.68,100,1,10.61,200,2,11.27,100,1,11.4,100,1,11.76,100,1,11.93,200,2,12.1,100,1,12.2,200,2,12.33,100,1,13.48,15,1,13.74,2,1,13.79,100,1,14.25,100,1,14.28,100,1,14.33,100,1,14.4,200,2,14.47,700,1,14.48,700,1,14.49,100,1,ARL,337790745
2025-07-17T16:12:40.994783297Z,2025-07-17T16:12:40.994617858Z,160,2,1108,A,A,14.760000000,100,0,338864217,130,165439,282007892,ARL,0,14.76,100,130,165439,282007892,9.55,1700,17,9.68,100,1,10.61,200,2,11.27,100,1,11.4,100,1,11.76,100,1,11.93,200,2,12.1,100,1,12.2,200,2,12.33,100,1,13.48,15,1,13.74,2,1,13.79,100,1,14.25,100,1,14.28,100,1,14.33,100,1,14.4,200,2,14.47,700,1,14.48,700,1,14.49,100,1,ARL,338864217
2025-07-17T16:12:40.995078856Z,2025-07-17T16:12:40.994913404Z,160,2,1108,C,A,14.840000000,100,0,338708241,0,165452,282007894,ARL,0,14.84,100,0,165452,282007894,9.55,1700,17,9.68,100,1,10.61,200,2,11.27,100,1,11.4,100,1,11.76,100,1,11.93,200,2,12.1,100,1,12.2,200,2,12.33,100,1,13.48,15,1,13.74,2,1,13.79,100,1,14.25,100,1,14.28,100,1,14.33,100,1,14.4,200,2,14.47,700,1,14.48,700,1,14.49,100,1,ARL,338708241
2025-07-17T16:12:40.995078856Z,2025-07-17T16:12:40.994913404Z,160,2,1108,A,A,15.170000000,100,0,338864221,130,165452,282007894,ARL,0,15.17,100,130,165452,282007894,9.55,1700,17,9.68,100,1,10.61,200,2,11.27,100,1,11.4,100,1,11.76,100,1,11.93,200,2,12.1,100,1,12.2,200,2,12.33,100,1,13.48,15,1,13.74,2,1,13.79,100,1,14.25,100,1,14.28,100,1,14.33,100,1,14.4,200,2,14.47,700,1,14.48,700,1,14.49,100,1,ARL,338864221
2025-07-17T16:12:40.995349303Z,2025-07-17T16:12:40.995183768Z,160,2,1108,C,A,15.600000000,100,0,337690641,0,165535,282007898,ARL,0,15.6,100,0,165535,282007898,9.55,1700,17,9.68,100,1,10.61,200,2,11.27,100,1,11.4,100,1,11.76,100,1,11.93,200,2,12.1,100,1,12.2,200,2,12.33,100,1,13.48,15,1,13.74,2,1,13.79,100,1,14.25,100,1,14.28,100,1,14.33,100,1,14.4,200,2,14.47,700,1,14.48,700,1,14.49,100,1,ARL,337690641
2025-07-17T16:12:40.995349303Z,2025-07-17T16:12:40.995183768Z,160,2,1108,A,A,15.860000000,100,0,338864245,130,165535,282007898,ARL,0,15.86,100,130,165535,282007898,9.55,1700,17,9.68,100,1,10.61,200,2,11.27,100,1,11.4,100,1,11.76,100,1,11.93,200,2,12.1,100,1,12.2,200,2,12.33,100,1,13.48,15,1,13.74,2,1,13.79,100,1,14.25,100,1,14.28,100,1,14.33,100,1,14.4,200,2,14.47,700,1,14.48,700,1,14.49,100,1,ARL,338864245
2025-07-17T16:12:40.996460080Z,2025-07-17T16:12:40.996294601Z,160,2,1108,C,A,17.260000000,100,0,336570921,0,165479,282007909,ARL,0,17.26,100,0,165479,282007909,9.55,1700,17,9.68,100,1,10.61,200,2,11.27,100,1,11.4,100,1,11.76,100,1,11.93,200,2,12.1,100,1,12.2,200,2,12.33,100,1,13.48,15,1,13.74,2,1,13.79,100,1,14.25,100,1,14.28,100,1,14.33,100,1,14.4,200,2,14.47,700,1,14.48,700,1,14.49,100,1,ARL,336570921
2025-07-17T16:12:40.996460080Z,2025-07-17T16:12:40.996294601Z,160,2,1108,A,A,17.520000000,100,0,338864289,130,165479,282007909,ARL,0,17.52,100,130,165479,282007909,9.55,1700,17,9.68,100,1,10.61,200,2,11.27,100,1,11.4,100,1,11.76,100,1,11.93,200,2,12.1,100,1,12.2,200,2,12.33,100,1,13.48,15,1,13.74,2,1,13.79,100,1,14.25,100,1,14.28,100,1,14.33,100,1,14.4,200,2,14.47,700,1,14.48,700,1,14.49,100,1,ARL,338864289
2025-07-17T16:12:40.997300700Z,2025-07-17T16:12:40.997135307Z,160,2,1108,C,A,14.330000000,100,0,337790761,130,165393,282007914,ARL,0,14.33,100,130,165393,282007914,9.55,1700,17,9.68,100,1,10.61,200,2,11.27,100,1,11.4,100,1,11.76,100,1,11.93,200,2,12.1,100,1,12.2,200,2,12.33,100,1,13.48,15,1,13.74,2,1,13.79,100,1,14.25,100,1,14.28,100,1,14.4,200,2,14.47,700,1,14.48,700,1,14.49,100,1,14.54,700,1,ARL,337790761
2025-07-17T16:12:40.997422356Z,2025-07-17T16:12:40.997257014Z,160,2,1108,A,A,14.580000000,100,0,338864317,130,165342,282007916,ARL,0,14.58,100,130,165342,282007916,9.55,1700,17,9.68,100,1,10.61,200,2,11.27,100,1,11.4,100,1,11.76,100,1,11.93,200,2,12.1,100,1,12.2,200,2,12.33,100,1,13.48,15,1,13.74,2,1,13.79,100,1,14.25,100,1,14.28,100,1,14.4,200,2,14.47,700,1,14.48,700,1,14.49,100,1,14.54,700,1,ARL,338864317
2025-07-17T16:12:41.004229622Z,2025-07-17T16:12:41.004063876Z,160,2,1108,C,A,14.490000000,100,0,337790777,0,165746,282007959,ARL,0,14.49,100,0,165746,282007959,9.55,1700,17,9.68,100,1,10.61,200,2,11.27,100,1,11.4,100,1,11.76,100,1,11.93,200,2,12.1,100,1,12.2,200,2,12.33,100,1,13.48,15,1,13.74,2,1,13.79,100,1,14.25,100,1,14.28,100,1,14.4,200,2,14.47,700,1,14.48,700,1,14.54,700,1,14.56,800,2,ARL,337790777
2025-07-17T16:12:41.004229622Z,2025-07-17T16:12:41.004063876Z,160,2,1108,A,A,14.760000000,100,0,338864405,130,165746,282007959,ARL,0,14.76,100,130,165746,282007959,9.55,1700,17,9.68,100,1,10.61,200,2,11.27,100,1,11.4,100,1,11.76,100,1,11.93,200,2,12.1,100,1,12.2,200,2,12.33,100,1,13.48,15,1,13.74,2,1,13.79,100,1,14.25,100,1,14.28,100,1,14.4,200,2,14.47,700,1,14.48,700,1,14.54,700,1,14.56,800,2,ARL,338864405
2025-07-17T16:12:41.005576053Z,2025-07-17T16:12:41.005406614Z,160,2,1108,A,A,13.490000000,100,0,338864581,128,169439,282008256,ARL,0,13.49,100,128,169439,282008256,9.55,1700,17,9.68,100,1,10.61,200,2,11.27,100,1,11.4,100,1,11.76,100,1,11.93,200,2,12.1,100,1,12.2,200,2,12.33,100,1,13.48,15,1,13.49,100,1,13.74,2,1,13.79,100,1,14.25,100,1,14.28,100,1,14.4,200,2,14.47,700,1,14.48,700,1,14.54,700,1,ARL,338864581
2025-07-17T16:12:41.010638351Z,2025-07-17T16:12:41.010473041Z,160,2,1108,C,A,14.760000000,100,0,338864405,0,165310,282008884,ARL,0,14.76,100,0,165310,282008884,9.55,1700,17,9.68,100,1,10.61,200,2,11.27,100,1,11.4,100,1,11.76,100,1,11.93,200,2,12.1,100,1,12.2,200,2,12.33,100,1,13.48,15,1,13.49,100,1,13.74,2,1,13.79,100,1,14.25,100,1,14.28,100,1,14.4,200,2,14.47,700,1,14.48,700,1,14.54,700,1,ARL,338864405
2025-07-17T16:12:41.010638351Z,2025-07-17T16:12:41.010473041Z,160,2,1108,A,A,14.440000000,100,0,338865133,130,165310,282008884,ARL,0,14.44,100,130,165310,282008884,9.55,1700,17,9.68,100,1,10.61,200,2,11.27,100,1,11.4,100,1,11.76,100,1,11.93,200,2,12.1,100,1,12.2,200,2,12.33,100,1,13.48,15,1,13.49,100,1,13.74,2,1,13.79,100,1,14.25,100,1,14.28,100,1,14.4,200,2,14.44,100,1,14.47,700,1,14.48,700,1,ARL,338865133
2025-07-17T16:12:41.011160341Z,2025-07-17T16:12:41.010994859Z,160,2,1108,C,A,13.790000000,100,0,338044233,130,165482,282008914,ARL,0,13.79,100,130,165482,282008914,9.55,1700,17,9.68,100,1,10.61,200,2,11.27,100,1,11.4,100,1,11.76,100,1,11.93,200,2,12.1,100,1,12.2,200,2,12.33,100,1,13.48,15,1,13.49,100,1,13.74,2,1,14.25,100,1,14.28,100,1,14.4,200,2,14.44,100,1,14.47,700,1,14.48,700,1,14.54,700,1,ARL,338044233
2025-07-17T16:12:41.011211986Z,2025-07-17T16:12:41.011046717Z,160,2,1108,A,A,14.060000000,100,0,338865141,130,165269,282008916,ARL,0,14.06,100,130,165269,282008916,9.55,1700,17,9.68,100,1,10.61,200,2,11.27,100,1,11.4,100,1,11.76,100,1,11.93,200,2,12.1,100,1,12.2,200,2,12.33,100,1,13.48,15,1,13.49,100,1,13.74,2,1,14.06,100,1,14.25,100,1,14.28,100,1,14.4,200,2,14.44,100,1,14.47,700,1,14.48,700,1,ARL,338865141
2025-07-17T16:12:41.011555342Z,2025-07-17T16:12:41.011390077Z,160,2,1108,C,A,14.760000000,100,0,338864217,0,165265,282008942,ARL,0,14.76,100,0,165265,282008942,9.55,1700,17,9.68,100,1,10.61,200,2,11.27,100,1,11.4,100,1,11.76,100,1,11.93,200,2,12.1,100,1,12.2,200,2,12.33,100,1,13.48,15,1,13.49,100,1,13.74,2,1,14.06,100,1,14.25,100,1,14.28,100,1,14.4,200,2,14.44,100,1,14.47,700,1,14.48,700,1,ARL,338864217
2025-07-17T16:12:41.011555342Z,2025-07-17T16:12:41.011390077Z,160,2,1108,A,A,14.440000000,100,0,338865165,130,165265,282008942,ARL,0,14.44,100,130,165265,282008942,9.55,1700,17,9.68,100,1,10.61,200,2,11.27,100,1,11.4,100,1,11.76,100,1,11.93,200,2,12.1,100,1,12.2,200,2,12.33,100,1,13.48,15,1,13.49,100,1,13.74,2,1,14.06,100,1,14.25,100,1,14.28,100,1,14.4,200,2,14.44,200,2,14.47,700,1,14.48,700,1,ARL,338865165
2025-07-17T16:12:41.012044919Z,2025-07-17T16:12:41.011879795Z,160,2,1108,C,A,14.060000000,100,0,338865141,130,165124,282008953,ARL,0,14.06,100,130,165124,282008953,9.55,1700,17,9.68,100,1,10.61,200,2,11.27,100,1,11.4,100,1,11.76,100,1,11.93,200,2,12.1,100,1,12.2,200,2,12.33,100,1,13.48,15,1,13.49,100,1,13.74,2,1,14.25,100,1,14.28,100,1,14.4,200,2,14.44,200,2,14.47,700,1,14.48,700,1,14.54,700,1,ARL,338865141
2025-07-17T16:12:41.012094494Z,2025-07-17T16:12:41.011929033Z,160,2,1108,A,A,13.760000000,100,0,338865177,130,165461,282008954,ARL,0,13.76,100,130,165461,282008954,9.55,1700,17,9.68,100,1,10.61,200,2,11.27,100,1,11.4,100,1,11.76,100,1,11.93,200,2,12.1,100,1,12.2,200,2,12.33,100,1,13.48,15,1,13.49,100,1,13.74,2,1,13.76,100,1,14.25,100,1,14.28,100,1,14.4,200,2,14.44,200,2,14.47,700,1,14.48,700,1,ARL,338865177
2025-07-17T16:12:41.014974491Z,2025-07-17T16:12:41.014809197Z,160,2,1108,C,A,17.520000000,100,0,338864289,0,165294,282008990,ARL,0,17.52,100,0,165294,282008990,9.55,1700,17,9.68,100,1,10.61,200,2,11.27,100,1,11.4,100,1,11.76,100,1,11.93,200,2,12.1,100,1,12.2,200,2,12.33,100,1,13.48,15,1,13.49,100,1,13.74,2,1,13.76,100,1,14.25,100,1,14.28,100,1,14.4,200,2,14.44,200,2,14.47,700,1,14.48,700,1,ARL,338864289
2025-07-17T16:12:41.014974491Z,2025-07-17T16:12:41.014809197Z,160,2,1108,A,A,17.140000000,100,0,338865253,130,165294,282008990,ARL,0,17.14,100,130,165294,282008990,9.55,1700,17,9.68,100,1,10.61,200,2,11.27,100,1,11.4,100,1,11.76,100,1,11.93,200,2,12.1,100,1,12.2,200,2,12.33,100,1,13.48,15,1,13.49,100,1,13.74,2,1,13.76,100,1,14.25,100,1,14.28,100,1,14.4,200,2,14.44,200,2,14.47,700,1,14.48,700,1,ARL,338865253
2025-07-17T16:12:41.017837378Z,2025-07-17T16:12:41.017672033Z,160,2,1108,C,A,15.860000000,100,0,338864245,0,165345,282009053,ARL,0,15.86,100,0,165345,282009053,9.55,1700,17,9.68,100,1,10.61,200,2,11.27,100,1,11.4,100,1,11.76,100,1,11.93,200,2,12.1,100,1,12.2,200,2,12.33,100,1,13.48,15,1,13.49,100,1,13.74,2,1,13.76,100,1,14.25,100,1,14.28,100,1,14.4,200,2,14.44,200,2,14.47,700,1,14.48,700,1,ARL,338864245
2025-07-17T16:12:41.017837378Z,2025-07-17T16:12:41.017672033Z,160,2,1108,A,A,15.520000000,100,0,338865301,130,165345,282009053,ARL,0,15.52,100,130,165345,282009053,9.55,1700,17,9.68,100,1,10.61,200,2,11.27,100,1,11.4,100,1,11.76,100,1,11.93,200,2,12.1,100,1,12.2,200,2,12.33,100,1,13.48,15,1,13.49,100,1,13.74,2,1,13.76,100,1,14.25,100,1,14.28,100,1,14.4,200,2,14.44,200,2,14.47,700,1,14.48,700,1,ARL,338865301
2025-07-17T16:12:41.032270817Z,2025-07-17T16:12:41.032105565Z,160,2,1108,C,A,15.170000000,100,0,338864221,0,165252,282009412,ARL,0,15.17,100,0,165252,282009412,9.55,1700,17,9.68,100,1,10.61,200,2,11.27,100,1,11.4,100,1,11.76,100,1,11.93,200,2,12.1,100,1,12.2,200,2,12.33,100,1,13.48,15,1,13.49,100,1,13.74,2,1,13.76,100,1,14.25,100,1,14.28,100,1,14.4,200,2,14.44,200,2,14.47,700,1,14.48,700,1,ARL,338864221
2025-07-17T16:12:41.032270817Z,2025-07-17T16:12:41.032105565Z,160,2,1108,A,A,14.840000000,100,0,338866081,130,165252,282009412,ARL,0,14.84,100,130,165252,282009412,9.55,1700,17,9.68,100,1,10.61,200,2,11.27,100,1,11.4,100,1,11.76,100,1,11.93,200,2,12.1,100,1,12.2,200,2,12.33,100,1,13.48,15,1,13.49,100,1,13.74,2,1,13.76,100,1,14.25,100,1,14.28,100,1,14.4,200,2,14.44,200,2,14.47,700,1,14.48,700,1,ARL,338866081
2025-07-17T16:12:41.032312420Z,2025-07-17T16:12:41.032147083Z,160,2,1108,A,A,15.380000000,100,0,338866089,130,165337,282009414,ARL,0,15.38,100,130,165337,282009414,9.55,1700,17,9.68,100,1,10.61,200,2,11.27,100,1,11.4,100,1,11.76,100,1,11.93,200,2,12.1,100,1,12.2,200,2,12.33,100,1,13.48,15,1,13.49,100,1,13.74,2,1,13.76,100,1,14.25,100,1,14.28,100,1,14.4,200,2,14.44,200,2,14.47,700,1,14.48,700,1,ARL,338866089
2025-07-17T16:12:41.032324438Z,2025-07-17T16:12:41.032159348Z,160,2,1108,C,A,15.710000000,100,0,338864177,130,165090,282009415,ARL,0,15.71,100,130,165090,282009415,9.55,1700,17,9.68,100,1,10.61,200,2,11.27,100,1,11.4,100,1,11.76,100,1,11.93,200,2,12.1,100,1,12.2,200,2,12.33,100,1,13.48,15,1,13.49,100,1,13.74,2,1,13.76,100,1,14.25,100,1,14.28,100,1,14.4,200,2,14.44,200,2,14.47,700,1,14.48,700,1,ARL,338864177
2025-07-17T16:12:41.043406383Z,2025-07-17T16:12:41.043241012Z,160,2,1108,C,A,14.850000000,100,0,338864189,0,165371,282009482,ARL,0,14.85,100,0,165371,282009482,9.55,1700,17,9.68,100,1,10.61,200,2,11.27,100,1,11.4,100,1,11.76,100,1,11.93,200,2,12.1,100,1,12.2,200,2,12.33,100,1,13.48,15,1,13.49,100,1,13.74,2,1,13.76,100,1,14.25,100,1,14.28,100,1,14.4,200,2,14.44,200,2,14.47,700,1,14.48,700,1,ARL,338864189
2025-07-17T16:12:41.043406383Z,2025-07-17T16:12:41.043241012Z,160,2,1108,A,A,14.540000000,100,0,338866245,130,165371,282009482,ARL,0,14.54,100,130,165371,282009482,9.55,1700,17,9.68,100,1,10.61,200,2,11.27,100,1,11.4,100,1,11.76,100,1,11.93,200,2,12.1,100,1,12.2,200,2,12.33,100,1,13.48,15,1,13.49,100,1,13.74,2,1,13.76,100,1,14.25,100,1,14.28,100,1,14.4,200,2,14.44,200,2,14.47,700,1,14.48,700,1,ARL,338866245
2025-07-17T16:12:42.001347844Z,2025-07-17T16:12:42.001182016Z,160,2,1108,C,A,14.580000000,100,0,338864317,0,165828,282033913,ARL,0,14.58,100,0,165828,282033913,9.55,1700,17,9.68,100,1,10.61,200,2,11.27,100,1,11.4,100,1,11.76,100,1,11.93,200,2,12.1,100,1,12.2,200,2,12.33,100,1,13.48,15,1,13.49,100,1,13.74,2,1,13.76,100,1,14.25,100,1,14.28,100,1,14.4,200,2,14.44,200,2,14.47,700,1,14.48,700,1,ARL,338864317
2025-07-17T16:12:42.001347844Z,2025-07-17T16:12:42.001182016Z,160,2,1108,A,A,14.280000000,100,0,338894329,130,165828,282033913,ARL,0,14.28,100,130,165828,282033913,9.55,1700,17,9.68,100,1,10.61,200,2,11.27,100,1,11.4,100,1,11.76,100,1,11.93,200,2,12.1,100,1,12.2,200,2,12.33,100,1,13.48,15,1,13.49,100,1,13.74,2,1,13.76,100,1,14.25,100,1,14.28,200,2,14.4,200,2,14.44,200,2,14.47,700,1,14.48,700,1,ARL,338894329
2025-07-17T16:12:42.762154469Z,2025-07-17T16:12:42.761989222Z,160,2,1108,A,A,13.460000000,15,0,338904977,130,165247,282042242,ARL,0,13.46,15,130,165247,282042242,9.55,1700,17,9.68,100,1,10.61,200,2,11.27,100,1,11.4,100,1,11.76,100,1,11.93,200,2,12.1,100,1,12.2,200,2,12.33,100,1,13.46,15,1,13.48,15,1,13.49,100,1,13.74,2,1,13.76,100,1,14.25,100,1,14.28,200,2,14.4,200,2,14.44,200,2,14.47,700,1,ARL,338904977
2025-07-17T16:12:43.022127902Z,2025-07-17T16:12:43.021951997Z,160,2,1108,C,A,13.490000000,100,0,338864581,0,175905,282057719,ARL,0,13.49,100,0,175905,282057719,9.55,1700,17,9.68,100,1,10.61,200,2,11.27,100,1,11.4,100,1,11.76,100,1,11.93,200,2,12.1,100,1,12.2,200,2,12.33,100,1,13.46,15,1,13.48,15,1,13.74,2,1,13.76,100,1,14.25,100,1,14.28,200,2,14.4,200,2,14.44,200,2,14.47,700,1,14.48,700,1,ARL,338864581
2025-07-17T16:12:43.022127902Z,2025-07-17T16:12:43.021951997Z,160,2,1108,A,A,13.470000000,100,0,338918217,128,175905,282057719,ARL,0,13.47,100,128,175905,282057719,9.55,1700,17,9.68,100,1,10.61,200,2,11.27,100,1,11.4,100,1,11.76,100,1,11.93,200,2,12.1,100,1,12.2,200,2,12.33,100,1,13.46,15,1,13.47,100,1,13.48,15,1,13.74,2,1,13.76,100,1,14.25,100,1,14.28,200,2,14.4,200,2,14.44,200,2,14.47,700,1,ARL,338918217
2025-07-17T16:12:43.022612177Z,2025-07-17T16:12:43.022444956Z,160,2,1108,A,A,15.690000000,100,0,338918553,128,167221,282058085,ARL,0,15.69,100,128,167221,282058085,9.55,1700,17,9.68,100,1,10.61,200,2,11.27,100,1,11.4,100,1,11.76,100,1,11.93,200,2,12.1,100,1,12.2,200,2,12.33,100,1,13.46,15,1,13.47,100,1,13.48,15,1,13.74,2,1,13.76,100,1,14.25,100,1,14.28,200,2,14.4,200,2,14.44,200,2,14.47,700,1,ARL,338918553
2025-07-17T16:12:43.022627592Z,2025-07-17T16:12:43.022461725Z,160,2,1108,C,A,15.380000000,100,0,338866089,130,165867,282058088,ARL,0,15.38,100,130,165867,282058088,9.55,1700,17,9.68,100,1,10.61,200,2,11.27,100,1,11.4,100,1,11.76,100,1,11.93,200,2,12.1,100,1,12.2,200,2,12.33,100,1,13.46,15,1,13.47,100,1,13.48,15,1,13.74,2,1,13.76,100,1,14.25,100,1,14.28,200,2,14.4,200,2,14.44,200,2,14.47,700,1,ARL,338866089
2025-07-17T16:12:43.049284355Z,2025-07-17T16:12:43.049119139Z,160,2,1108,A,A,15.360000000,100,0,338926929,130,165216,282065940,ARL,0,15.36,100,130,165216,282065940,9.55,1700,17,9.68,100,1,10.61,200,2,11.27,100,1,11.4,100,1,11.76,100,1,11.93,200,2,12.1,100,1,12.2,200,2,12.33,100,1,13.46,15,1,13.47,100,1,13.48,15,1,13.74,2,1,13.76,100,1,14.25,100,1,14.28,200,2,14.4,200,2,14.44,200,2,14.47,700,1,ARL,338926929
2025-07-17T16:12:43.049298989Z,2025-07-17T16:12:43.049132842Z,160,2,1108,C,A,15.690000000,100,0,338918553,128,166147,282065943,ARL,0,15.69,100,128,166147,282065943,9.55,1700,17,9.68,100,1,10.61,200,2,11.27,100,1,11.4,100,1,11.76,100,1,11.93,200,2,12.1,100,1,12.2,200,2,12.33,100,1,13.46,15,1,13.47,100,1,13.48,15,1,13.74,2,1,13.76,100,1,14.25,100,1,14.28,200,2,14.4,200,2,14.44,200,2,14.47,700,1,ARL,338918553
2025-07-17T16:12:43.154952375Z,2025-07-17T16:12:43.154787212Z,160,2,1108,A,A,14.270000000,100,0,338932853,130,165163,282073056,ARL,0,14.27,100,130,165163,282073056,9.55,1700,17,9.68,100,1,10.61,200,2,11.27,100,1,11.4,100,1,11.76,100,1,11.93,200,2,12.1,100,1,12.2,200,2,12.33,100,1,13.46,15,1,13.47,100,1,13.48,15,1,13.74,2,1,13.76,100,1,14.25,100,1,14.27,100,1,14.28,200,2,14.4,200,2,14.44,200,2,ARL,338932853
2025-07-17T16:12:43.154965183Z,2025-07-17T16:12:43.154800020Z,160,2,1108,C,A,14.560000000,100,0,296391881,130,165163,282073058,ARL,0,14.56,100,130,165163,282073058,9.55,1700,17,9.68,100,1,10.61,200,2,11.27,100,1,11.4,100,1,11.76,100,1,11.93,200,2,12.1,100,1,12.2,200,2,12.33,100,1,13.46,15,1,13.47,100,1,13.48,15,1,13.74,2,1,13.76,100,1,14.25,100,1,14.27,100,1,14.28,200,2,14.4,200,2,14.44,200,2,ARL,296391881
2025-07-17T16:12:43.915552526Z,2025-07-17T16:12:43.915387059Z,160,2,1108,C,A,14.280000000,100,0,302681357,130,165467,282085822,ARL,0,14.28,100,130,165467,282085822,9.55,1700,17,9.68,100,1,10.61,200,2,11.27,100,1,11.4,100,1,11.76,100,1,11.93,200,2,12.1,100,1,12.2,200,2,12.33,100,1,13.46,15,1,13.47,100,1,13.48,15,1,13.74,2,1,13.76,100,1,14.25,100,1,14.27,100,1,14.28,100,1,14.4,200,2,14.44,200,2,ARL,302681357
2025-07-17T16:12:43.915555340Z,2025-07-17T16:12:43.915389642Z,160,2,1108,A,A,14.000000000,100,0,338945933,130,165698,282085823,ARL,0,14,100,130,165698,282085823,9.55,1700,17,9.68,100,1,10.61,200,2,11.27,100,1,11.4,100,1,11.76,100,1,11.93,200,2,12.1,100,1,12.2,200,2,12.33,100,1,13.46,15,1,13.47,100,1,13.48,15,1,13.74,2,1,13.76,100,1,14,100,1,14.25,100,1,14.27,100,1,14.28,100,1,14.4,200,2,ARL,338945933
2025-07-17T16:12:50.729244449Z,2025-07-17T16:12:50.729079105Z,160,2,1108,C,A,13.460000000,15,0,338904977,130,165344,282168721,ARL,0,13.46,15,130,165344,282168721,9.55,1700,17,9.68,100,1,10.61,200,2,11.27,100,1,11.4,100,1,11.76,100,1,11.93,200,2,12.1,100,1,12.2,200,2,12.33,100,1,13.47,100,1,13.48,15,1,13.74,2,1,13.76,100,1,14,100,1,14.25,100,1,14.27,100,1,14.28,100,1,14.4,200,2,14.44,200,2,ARL,338904977
2025-07-17T16:12:50.729418237Z,2025-07-17T16:12:50.729252907Z,160,2,1108,C,A,13.480000000,15,0,338707945,130,165330,282168744,ARL,0,13.48,15,130,165330,282168744,9.55,1700,17,9.68,100,1,10.61,200,2,11.27,100,1,11.4,100,1,11.76,100,1,11.93,200,2,12.1,100,1,12.2,200,2,12.33,100,1,13.47,100,1,13.74,2,1,13.76,100,1,14,100,1,14.25,100,1,14.27,100,1,14.28,100,1,14.4,200,2,14.44,200,2,14.47,700,1,ARL,338707945
2025-07-17T16:12:50.729575741Z,2025-07-17T16:12:50.729409745Z,160,2,1108,A,A,13.470000000,96,0,339054149,130,165996,282168754,ARL,0,13.47,96,130,165996,282168754,9.55,1700,17,9.68,100,1,10.61,200,2,11.27,100,1,11.4,100,1,11.76,100,1,11.93,200,2,12.1,100,1,12.2,200,2,12.33,100,1,13.47,196,2,13.74,2,1,13.76,100,1,14,100,1,14.25,100,1,14.27,100,1,14.28,100,1,14.4,200,2,14.44,200,2,14.47,700,1,ARL,339054149
2025-07-17T16:12:53.021914652Z,2025-07-17T16:12:53.021749348Z,160,2,1108,A,A,13.460000000,15,0,339096733,130,165304,282194154,ARL,0,13.46,15,130,165304,282194154,9.55,1700,17,9.68,100,1,10.61,200,2,11.27,100,1,11.4,100,1,11.76,100,1,11.93,200,2,12.1,100,1,12.2,200,2,12.33,100,1,13.46,15,1,13.47,196,2,13.74,2,1,13.76,100,1,14,100,1,14.25,100,1,14.27,100,1,14.28,100,1,14.4,200,2,14.44,200,2,ARL,339096733
2025-07-17T16:12:53.021959141Z,2025-07-17T16:12:53.021793735Z,160,2,1108,C,A,13.470000000,100,0,338918217,130,165406,282194157,ARL,0,13.47,100,130,165406,282194157,9.55,1700,17,9.68,100,1,10.61,200,2,11.27,100,1,11.4,100,1,11.76,100,1,11.93,200,2,12.1,100,1,12.2,200,2,12.33,100,1,13.46,15,1,13.47,96,1,13.74,2,1,13.76,100,1,14,100,1,14.25,100,1,14.27,100,1,14.28,100,1,14.4,200,2,14.44,200,2,ARL,338918217
2025-07-17T16:12:53.022230122Z,2025-07-17T16:12:53.022064745Z,160,2,1108,C,A,13.470000000,96,0,339054149,130,165377,282194159,ARL,0,13.47,96,130,165377,282194159,9.55,1700,17,9.68,100,1,10.61,200,2,11.27,100,1,11.4,100,1,11.76,100,1,11.93,200,2,12.1,100,1,12.2,200,2,12.33,100,1,13.46,15,1,13.74,2,1,13.76,100,1,14,100,1,14.25,100,1,14.27,100,1,14.28,100,1,14.4,200,2,14.44,200,2,14.47,700,1,ARL,339054149
2025-07-17T16:12:53.022572023Z,2025-07-17T16:12:53.022406202Z,160,2,1108,A,A,15.690000000,100,0,339096757,130,165821,282194161,ARL,0,15.69,100,130,165821,282194161,9.55,1700,17,9.68,100,1,10.61,200,2,11.27,100,1,11.4,100,1,11.76,100,1,11.93,200,2,12.1,100,1,12.2,200,2,12.33,100,1,13.46,15,1,13.74,2,1,13.76,100,1,14,100,1,14.25,100,1,14.27,100,1,14.28,100,1,14.4,200,2,14.44,200,2,14.47,700,1,ARL,339096757
2025-07-17T16:12:53.022584264Z,2025-07-17T16:12:53.022418950Z,160,2,1108,C,A,15.360000000,100,0,338926929,130,165314,282194162,ARL,0,15.36,100,130,165314,282194162,9.55,1700,17,9.68,100,1,10.61,200,2,11.27,100,1,11.4,100,1,11.76,100,1,11.93,200,2,12.1,100,1,12.2,200,2,12.33,100,1,13.46,15,1,13.74,2,1,13.76,100,1,14,100,1,14.25,100,1,14.27,100,1,14.28,100,1,14.4,200,2,14.44,200,2,14.47,700,1,ARL,338926929
2025-07-17T16:12:53.022962940Z,2025-07-17T16:12:53.022797046Z,160,2,1108,C,A,14.540000000,100,0,338866245,0,165894,282194167,ARL,0,14.54,100,0,165894,282194167,9.55,1700,17,9.68,100,1,10.61,200,2,11.27,100,1,11.4,100,1,11.76,100,1,11.93,200,2,12.1,100,1,12.2,200,2,12.33,100,1,13.46,15,1,13.74,2,1,13.76,100,1,14,100,1,14.25,100,1,14.27,100,1,14.28,100,1,14.4,200,2,14.44,200,2,14.47,700,1,ARL,338866245
2025-07-17T16:12:53.022962940Z,2025-07-17T16:12:53.022797046Z,160,2,1108,A,A,14.830000000,100,0,339096773,130,165894,282194167,ARL,0,14.83,100,130,165894,282194167,9.55,1700,17,9.68,100,1,10.61,200,2,11.27,100,1,11.4,100,1,11.76,100,1,11.93,200,2,12.1,100,1,12.2,200,2,12.33,100,1,13.46,15,1,13.74,2,1,13.76,100,1,14,100,1,14.25,100,1,14.27,100,1,14.28,100,1,14.4,200,2,14.44,200,2,14.47,700,1,ARL,339096773
2025-07-17T16:12:53.023589530Z,2025-07-17T16:12:53.023423468Z,160,2,1108,C,A,14.440000000,100,0,338865165,0,166062,282194181,ARL,0,14.44,100,0,166062,282194181,9.55,1700,17,9.68,100,1,10.61,200,2,11.27,100,1,11.4,100,1,11.76,100,1,11.93,200,2,12.1,100,1,12.2,200,2,12.33,100,1,13.46,15,1,13.74,2,1,13.76,100,1,14,100,1,14.25,100,1,14.27,100,1,14.28,100,1,14.4,200,2,14.44,100,1,14.47,700,1,ARL,338865165
2025-07-17T16:12:53.023589530Z,2025-07-17T16:12:53.023423468Z,160,2,1108,A,A,14.730000000,100,0,339096797,130,166062,282194181,ARL,0,14.73,100,130,166062,282194181,9.55,1700,17,9.68,100,1,10.61,200,2,11.27,100,1,11.4,100,1,11.76,100,1,11.93,200,2,12.1,100,1,12.2,200,2,12.33,100,1,13.46,15,1,13.74,2,1,13.76,100,1,14,100,1,14.25,100,1,14.27,100,1,14.28,100,1,14.4,200,2,14.44,100,1,14.47,700,1,ARL,339096797
2025-07-17T16:12:53.024069153Z,2025-07-17T16:12:53.023903582Z,160,2,1108,C,A,17.140000000,100,0,338865253,0,165571,282194183,ARL,0,17.14,100,0,165571,282194183,9.55,1700,17,9.68,100,1,10.61,200,2,11.27,100,1,11.4,100,1,11.76,100,1,11.93,200,2,12.1,100,1,12.2,200,2,12.33,100,1,13.46,15,1,13.74,2,1,13.76,100,1,14,100,1,14.25,100,1,14.27,100,1,14.28,100,1,14.4,200,2,14.44,100,1,14.47,700,1,ARL,338865253
2025-07-17T16:12:53.024069153Z,2025-07-17T16:12:53.023903582Z,160,2,1108,A,A,17.480000000,100,0,339096809,130,165571,282194183,ARL,0,17.48,100,130,165571,282194183,9.55,1700,17,9.68,100,1,10.61,200,2,11.27,100,1,11.4,100,1,11.76,100,1,11.93,200,2,12.1,100,1,12.2,200,2,12.33,100,1,13.46,15,1,13.74,2,1,13.76,100,1,14,100,1,14.25,100,1,14.27,100,1,14.28,100,1,14.4,200,2,14.44,100,1,14.47,700,1,ARL,339096809
2025-07-17T16:12:53.025583784Z,2025-07-17T16:12:53.025418159Z,160,2,1108,C,A,14.840000000,100,0,338866081,0,165625,282194188,ARL,0,14.84,100,0,165625,282194188,9.55,1700,17,9.68,100,1,10.61,200,2,11.27,100,1,11.4,100,1,11.76,100,1,11.93,200,2,12.1,100,1,12.2,200,2,12.33,100,1,13.46,15,1,13.74,2,1,13.76,100,1,14,100,1,14.25,100,1,14.27,100,1,14.28,100,1,14.4,200,2,14.44,100,1,14.47,700,1,ARL,338866081
2025-07-17T16:12:53.025583784Z,2025-07-17T16:12:53.025418159Z,160,2,1108,A,A,15.140000000,100,0,339096813,130,165625,282194188,ARL,0,15.14,100,130,165625,282194188,9.55,1700,17,9.68,100,1,10.61,200,2,11.27,100,1,11.4,100,1,11.76,100,1,11.93,200,2,12.1,100,1,12.2,200,2,12.33,100,1,13.46,15,1,13.74,2,1,13.76,100,1,14,100,1,14.25,100,1,14.27,100,1,14.28,100,1,14.4,200,2,14.44,100,1,14.47,700,1,ARL,339096813
2025-07-17T16:12:53.025651983Z,2025-07-17T16:12:53.025486466Z,160,2,1108,C,A,14.440000000,100,0,338865133,0,165517,282194189,ARL,0,14.44,100,0,165517,282194189,9.55,1700,17,9.68,100,1,10.61,200,2,11.27,100,1,11.4,100,1,11.76,100,1,11.93,200,2,12.1,100,1,12.2,200,2,12.33,100,1,13.46,15,1,13.74,2,1,13.76,100,1,14,100,1,14.25,100,1,14.27,100,1,14.28,100,1,14.4,200,2,14.47,700,1,14.48,700,1,ARL,338865133
2025-07-17T16:12:53.025651983Z,2025-07-17T16:12:53.025486466Z,160,2,1108,A,A,14.730000000,100,0,339096817,130,165517,282194189,ARL,0,14.73,100,130,165517,282194189,9.55,1700,17,9.68,100,1,10.61,200,2,11.27,100,1,11.4,100,1,11.76,100,1,11.93,200,2,12.1,100,1,12.2,200,2,12.33,100,1,13.46,15,1,13.74,2,1,13.76,100,1,14,100,1,14.25,100,1,14.27,100,1,14.28,100,1,14.4,200,2,14.47,700,1,14.48,700,1,ARL,339096817
2025-07-17T16:12:53.027715026Z,2025-07-17T16:12:53.027549524Z,160,2,1108,C,A,14.280000000,100,0,338894329,130,165502,282194224,ARL,0,14.28,100,130,165502,282194224,9.55,1700,17,9.68,100,1,10.61,200,2,11.27,100,1,11.4,100,1,11.76,100,1,11.93,200,2,12.1,100,1,12.2,200,2,12.33,100,1,13.46,15,1,13.74,2,1,13.76,100,1,14,100,1,14.25,100,1,14.27,100,1,14.4,200,2,14.47,700,1,14.48,700,1,14.54,700,1,ARL,338894329
2025-07-17T16:12:53.027866777Z,2025-07-17T16:12:53.027701439Z,160,2,1108,A,A,14.550000000,100,0,339096833,130,165338,282194226,ARL,0,14.55,100,130,165338,282194226,9.55,1700,17,9.68,100,1,10.61,200,2,11.27,100,1,11.4,100,1,11.76,100,1,11.93,200,2,12.1,100,1,12.2,200,2,12.33,100,1,13.46,15,1,13.74,2,1,13.76,100,1,14,100,1,14.25,100,1,14.27,100,1,14.4,200,2,14.47,700,1,14.48,700,1,14.54,700,1,ARL,339096833
2025-07-17T16:12:53.027987030Z,2025-07-17T16:12:53.027821450Z,160,2,1108,C,A,15.520000000,100,0,338865301,0,165580,282194228,ARL,0,15.52,100,0,165580,282194228,9.55,1700,17,9.68,100,1,10.61,200,2,11.27,100,1,11.4,100,1,11.76,100,1,11.93,200,2,12.1,100,1,12.2,200,2,12.33,100,1,13.46,15,1,13.74,2,1,13.76,100,1,14,100,1,14.25,100,1,14.27,100,1,14.4,200,2,14.47,700,1,14.48,700,1,14.54,700,1,ARL,338865301
2025-07-17T16:12:53.027987030Z,2025-07-17T16:12:53.027821450Z,160,2,1108,A,A,15.830000000,100,0,339096837,130,165580,282194228,ARL,0,15.83,100,130,165580,282194228,9.55,1700,17,9.68,100,1,10.61,200,2,11.27,100,1,11.4,100,1,11.76,100,1,11.93,200,2,12.1,100,1,12.2,200,2,12.33,100,1,13.46,15,1,13.74,2,1,13.76,100,1,14,100,1,14.25,100,1,14.27,100,1,14.4,200,2,14.47,700,1,14.48,700,1,14.54,700,1,ARL,339096837
2025-07-17T16:12:53.033266537Z,2025-07-17T16:12:53.033101265Z,160,2,1108,C,A,13.760000000,100,0,338865177,130,165272,282194348,ARL,0,13.76,100,130,165272,282194348,9.55,1700,17,9.68,100,1,10.61,200,2,11.27,100,1,11.4,100,1,11.76,100,1,11.93,200,2,12.1,100,1,12.2,200,2,12.33,100,1,13.46,15,1,13.74,2,1,14,100,1,14.25,100,1,14.27,100,1,14.4,200,2,14.47,700,1,14.48,700,1,14.54,700,1,14.55,100,1,ARL,338865177
2025-07-17T16:12:53.033302848Z,2025-07-17T16:12:53.033137644Z,160,2,1108,C,A,14.470000000,700,0,338864173,130,165204,282194349,ARL,0,14.47,700,130,165204,282194349,9.55,1700,17,9.68,100,1,10.61,200,2,11.27,100,1,11.4,100,1,11.76,100,1,11.93,200,2,12.1,100,1,12.2,200,2,12.33,100,1,13.46,15,1,13.74,2,1,14,100,1,14.25,100,1,14.27,100,1,14.4,200,2,14.48,700,1,14.54,700,1,14.55,100,1,14.56,700,1,ARL,338864173
2025-07-17T16:12:53.033318818Z,2025-07-17T16:12:53.033153612Z,160,2,1108,A,A,14.040000000,100,0,339096893,130,165206,282194350,ARL,0,14.04,100,130,165206,282194350,9.55,1700,17,9.68,100,1,10.61,200,2,11.27,100,1,11.4,100,1,11.76,100,1,11.93,200,2,12.1,100,1,12.2,200,2,12.33,100,1,13.46,15,1,13.74,2,1,14,100,1,14.04,100,1,14.25,100,1,14.27,100,1,14.4,200,2,14.48,700,1,14.54,700,1,14.55,100,1,ARL,339096893
2025-07-17T16:12:53.033349323Z,2025-07-17T16:12:53.033183560Z,160,2,1108,A,A,14.680000000,700,0,339096897,130,165763,282194351,ARL,0,14.68,700,130,165763,282194351,9.55,1700,17,9.68,100,1,10.61,200,2,11.27,100,1,11.4,100,1,11.76,100,1,11.93,200,2,12.1,100,1,12.2,200,2,12.33,100,1,13.46,15,1,13.74,2,1,14,100,1,14.04,100,1,14.25,100,1,14.27,100,1,14.4,200,2,14.48,700,1,14.54,700,1,14.55,100,1,ARL,339096897
2025-07-17T16:12:53.033762072Z,2025-07-17T16:12:53.033596046Z,160,2,1108,C,A,13.740000000,2,0,338371797,0,166026,282194354,ARL,0,13.74,2,0,166026,282194354,9.55,1700,17,9.68,100,1,10.61,200,2,11.27,100,1,11.4,100,1,11.76,100,1,11.93,200,2,12.1,100,1,12.2,200,2,12.33,100,1,13.46,15,1,14,100,1,14.04,100,1,14.25,100,1,14.27,100,1,14.4,200,2,14.48,700,1,14.54,700,1,14.55,100,1,14.56,700,1,ARL,338371797
2025-07-17T16:12:53.033762072Z,2025-07-17T16:12:53.033596046Z,160,2,1108,A,A,13.980000000,2,0,339096909,130,166026,282194354,ARL,0,13.98,2,130,166026,282194354,9.55,1700,17,9.68,100,1,10.61,200,2,11.27,100,1,11.4,100,1,11.76,100,1,11.93,200,2,12.1,100,1,12.2,200,2,12.33,100,1,13.46,15,1,13.98,2,1,14,100,1,14.04,100,1,14.25,100,1,14.27,100,1,14.4,200,2,14.48,700,1,14.54,700,1,14.55,100,1,ARL,339096909
2025-07-17T16:12:53.034000646Z,2025-07-17T16:12:53.033835120Z,160,2,1108,C,A,14.250000000,100,0,336161365,130,165526,282194360,ARL,0,14.25,100,130,165526,282194360,9.55,1700,17,9.68,100,1,10.61,200,2,11.27,100,1,11.4,100,1,11.76,100,1,11.93,200,2,12.1,100,1,12.2,200,2,12.33,100,1,13.46,15,1,13.98,2,1,14,100,1,14.04,100,1,14.27,100,1,14.4,200,2,14.48,700,1,14.54,700,1,14.55,100,1,14.56,700,1,ARL,336161365
2025-07-17T16:12:53.034142471Z,2025-07-17T16:12:53.033977054Z,160,2,1108,C,A,14.730000000,100,0,339096797,0,165417,282194361,ARL,0,14.73,100,0,165417,282194361,9.55,1700,17,9.68,100,1,10.61,200,2,11.27,100,1,11.4,100,1,11.76,100,1,11.93,200,2,12.1,100,1,12.2,200,2,12.33,100,1,13.46,15,1,13.98,2,1,14,100,1,14.04,100,1,14.27,100,1,14.4,200,2,14.48,700,1,14.54,700,1,14.55,100,1,14.56,700,1,ARL,339096797
2025-07-17T16:12:53.034142471Z,2025-07-17T16:12:53.033977054Z,160,2,1108,A,A,14.960000000,100,0,339096917,130,165417,282194361,ARL,0,14.96,100,130,165417,282194361,9.55,1700,17,9.68,100,1,10.61,200,2,11.27,100,1,11.4,100,1,11.76,100,1,11.93,200,2,12.1,100,1,12.2,200,2,12.33,100,1,13.46,15,1,13.98,2,1,14,100,1,14.04,100,1,14.27,100,1,14.4,200,2,14.48,700,1,14.54,700,1,14.55,100,1,14.56,700,1,ARL,339096917
2025-07-17T16:12:53.034178176Z,2025-07-17T16:12:53.034012618Z,160,2,1108,C,A,15.830000000,100,0,339096837,0,165558,282194362,ARL,0,15.83,100,0,165558,282194362,9.55,1700,17,9.68,100,1,10.61,200,2,11.27,100,1,11.4,100,1,11.76,100,1,11.93,200,2,12.1,100,1,12.2,200,2,12.33,100,1,13.46,15,1,13.98,2,1,14,100,1,14.04,100,1,14.27,100,1,14.4,200,2,14.48,700,1,14.54,700,1,14.55,100,1,14.56,700,1,ARL,339096837
2025-07-17T16:12:53.034178176Z,2025-07-17T16:12:53.034012618Z,160,2,1108,A,A,16.080000000,100,0,339096921,130,165558,282194362,ARL,0,16.08,100,130,165558,282194362,9.55,1700,17,9.68,100,1,10.61,200,2,11.27,100,1,11.4,100,1,11.76,100,1,11.93,200,2,12.1,100,1,12.2,200,2,12.33,100,1,13.46,15,1,13.98,2,1,14,100,1,14.04,100,1,14.27,100,1,14.4,200,2,14.48,700,1,14.54,700,1,14.55,100,1,14.56,700,1,ARL,339096921
2025-07-17T16:12:53.034353140Z,2025-07-17T16:12:53.034187864Z,160,2,1108,A,A,14.600000000,100,0,339096925,130,165276,282194365,ARL,0,14.6,100,130,165276,282194365,9.55,1700,17,9.68,100,1,10.61,200,2,11.27,100,1,11.4,100,1,11.76,100,1,11.93,200,2,12.1,100,1,12.2,200,2,12.33,100,1,13.46,15,1,13.98,2,1,14,100,1,14.04,100,1,14.27,100,1,14.4,200,2,14.48,700,1,14.54,700,1,14.55,100,1,14.56,700,1,ARL,339096925
2025-07-17T16:12:53.035411748Z,2025-07-17T16:12:53.035246187Z,160,2,1108,C,A,15.050000000,100,0,335220549,0,165561,282194373,ARL,0,15.05,100,0,165561,282194373,9.55,1700,17,9.68,100,1,10.61,200,2,11.27,100,1,11.4,100,1,11.76,100,1,11.93,200,2,12.1,100,1,12.2,200,2,12.33,100,1,13.46,15,1,13.98,2,1,14,100,1,14.04,100,1,14.27,100,1,14.4,200,2,14.48,700,1,14.54,700,1,14.55,100,1,14.56,700,1,ARL,335220549
2025-07-17T16:12:53.035411748Z,2025-07-17T16:12:53.035246187Z,160,2,1108,A,A,15.380000000,100,0,339096929,130,165561,282194373,ARL,0,15.38,100,130,165561,282194373,9.55,1700,17,9.68,100,1,10.61,200,2,11.27,100,1,11.4,100,1,11.76,100,1,11.93,200,2,12.1,100,1,12.2,200,2,12.33,100,1,13.46,15,1,13.98,2,1,14,100,1,14.04,100,1,14.27,100,1,14.4,200,2,14.48,700,1,14.54,700,1,14.55,100,1,14.56,700,1,ARL,339096929
2025-07-17T16:12:53.036307382Z,2025-07-17T16:12:53.036142164Z,160,2,1108,C,A,17.480000000,100,0,339096809,0,165218,282194381,ARL,0,17.48,100,0,165218,282194381,9.55,1700,17,9.68,100,1,10.61,200,2,11.27,100,1,11.4,100,1,11.76,100,1,11.93,200,2,12.1,100,1,12.2,200,2,12.33,100,1,13.46,15,1,13.98,2,1,14,100,1,14.04,100,1,14.27,100,1,14.4,200,2,14.48,700,1,14.54,700,1,14.55,100,1,14.56,700,1,ARL,339096809
2025-07-17T16:12:53.036307382Z,2025-07-17T16:12:53.036142164Z,160,2,1108,A,A,17.760000000,100,0,339096949,130,165218,282194381,ARL,0,17.76,100,130,165218,282194381,9.55,1700,17,9.68,100,1,10.61,200,2,11.27,100,1,11.4,100,1,11.76,100,1,11.93,200,2,12.1,100,1,12.2,200,2,12.33,100,1,13.46,15,1,13.98,2,1,14,100,1,14.04,100,1,14.27,100,1,14.4,200,2,14.48,700,1,14.54,700,1,14.55,100,1,14.56,700,1,ARL,339096949
2025-07-17T16:12:53.040045217Z,2025-07-17T16:12:53.039879965Z,160,2,1108,C,A,14.730000000,100,0,339096817,0,165252,282194416,ARL,0,14.73,100,0,165252,282194416,9.55,1700,17,9.68,100,1,10.61,200,2,11.27,100,1,11.4,100,1,11.76,100,1,11.93,200,2,12.1,100,1,12.2,200,2,12.33,100,1,13.46,15,1,13.98,2,1,14,100,1,14.04,100,1,14.27,100,1,14.4,200,2,14.48,700,1,14.54,700,1,14.55,100,1,14.56,700,1,ARL,339096817
2025-07-17T16:12:53.040045217Z,2025-07-17T16:12:53.039879965Z,160,2,1108,A,A,14.960000000,100,0,339096977,130,165252,282194416,ARL,0,14.96,100,130,165252,282194416,9.55,1700,17,9.68,100,1,10.61,200,2,11.27,100,1,11.4,100,1,11.76,100,1,11.93,200,2,12.1,100,1,12.2,200,2,12.33,100,1,13.46,15,1,13.98,2,1,14,100,1,14.04,100,1,14.27,100,1,14.4,200,2,14.48,700,1,14.54,700,1,14.55,100,1,14.56,700,1,ARL,339096977
2025-07-17T16:12:53.043727225Z,2025-07-17T16:12:53.043562198Z,160,2,1108,C,A,14.040000000,100,0,339096893,130,165027,282194436,ARL,0,14.04,100,130,165027,282194436,9.55,1700,17,9.68,100,1,10.61,200,2,11.27,100,1,11.4,100,1,11.76,100,1,11.93,200,2,12.1,100,1,12.2,200,2,12.33,100,1,13.46,15,1,13.98,2,1,14,100,1,14.27,100,1,14.4,200,2,14.48,700,1,14.54,700,1,14.55,100,1,14.56,700,1,14.6,100,1,ARL,339096893
2025-07-17T16:12:53.043775299Z,2025-07-17T16:12:53.043610101Z,160,2,1108,A,A,14.260000000,100,0,339097005,130,165198,282194438,ARL,0,14.26,100,130,165198,282194438,9.55,1700,17,9.68,100,1,10.61,200,2,11.27,100,1,11.4,100,1,11.76,100,1,11.93,200,2,12.1,100,1,12.2,200,2,12.33,100,1,13.46,15,1,13.98,2,1,14,100,1,14.26,100,1,14.27,100,1,14.4,200,2,14.48,700,1,14.54,700,1,14.55,100,1,14.56,700,1,ARL,339097005
2025-07-17T16:12:53.073052597Z,2025-07-17T16:12:53.072887133Z,160,2,1108,C,A,14.830000000,100,0,339096773,0,165464,282194725,ARL,0,14.83,100,0,165464,282194725,9.55,1700,17,9.68,100,1,10.61,200,2,11.27,100,1,11.4,100,1,11.76,100,1,11.93,200,2,12.1,100,1,12.2,200,2,12.33,100,1,13.46,15,1,13.98,2,1,14,100,1,14.26,100,1,14.27,100,1,14.4,200,2,14.48,700,1,14.54,700,1,14.55,100,1,14.56,700,1,ARL,339096773
2025-07-17T16:12:53.073052597Z,2025-07-17T16:12:53.072887133Z,160,2,1108,A,A,15.060000000,100,0,339097245,130,165464,282194725,ARL,0,15.06,100,130,165464,282194725,9.55,1700,17,9.68,100,1,10.61,200,2,11.27,100,1,11.4,100,1,11.76,100,1,11.93,200,2,12.1,100,1,12.2,200,2,12.33,100,1,13.46,15,1,13.98,2,1,14,100,1,14.26,100,1,14.27,100,1,14.4,200,2,14.48,700,1,14.54,700,1,14.55,100,1,14.56,700,1,ARL,339097245
2025-07-17T16:12:53.332729487Z,2025-07-17T16:12:53.332564148Z,160,2,1108,C,A,14.000000000,100,0,338945933,130,165339,282196976,ARL,0,14,100,130,165339,282196976,9.55,1700,17,9.68,100,1,10.61,200,2,11.27,100,1,11.4,100,1,11.76,100,1,11.93,200,2,12.1,100,1,12.2,200,2,12.33,100,1,13.46,15,1,13.98,2,1,14.26,100,1,14.27,100,1,14.4,200,2,14.48,700,1,14.54,700,1,14.55,100,1,14.56,700,1,14.6,100,1,ARL,338945933
2025-07-17T16:12:53.332730508Z,2025-07-17T16:12:53.332565150Z,160,2,1108,A,A,14.530000000,100,0,339100477,130,165358,282196977,ARL,0,14.53,100,130,165358,282196977,9.55,1700,17,9.68,100,1,10.61,200,2,11.27,100,1,11.4,100,1,11.76,100,1,11.93,200,2,12.1,100,1,12.2,200,2,12.33,100,1,13.46,15,1,13.98,2,1,14.26,100,1,14.27,100,1,14.4,200,2,14.48,700,1,14.53,100,1,14.54,700,1,14.55,100,1,14.56,700,1,ARL,339100477
2025-07-17T16:12:53.587788615Z,2025-07-17T16:12:53.587623157Z,160,2,1108,A,A,14.810000000,100,0,339103269,130,165458,282200199,ARL,0,14.81,100,130,165458,282200199,9.55,1700,17,9.68,100,1,10.61,200,2,11.27,100,1,11.4,100,1,11.76,100,1,11.93,200,2,12.1,100,1,12.2,200,2,12.33,100,1,13.46,15,1,13.98,2,1,14.26,100,1,14.27,100,1,14.4,200,2,14.48,700,1,14.53,100,1,14.54,700,1,14.55,100,1,14.56,700,1,ARL,339103269
2025-07-17T16:12:53.587810242Z,2025-07-17T16:12:53.587644886Z,160,2,1108,C,A,14.270000000,100,0,338932853,130,165356,282200200,ARL,0,14.27,100,130,165356,282200200,9.55,1700,17,9.68,100,1,10.61,200,2,11.27,100,1,11.4,100,1,11.76,100,1,11.93,200,2,12.1,100,1,12.2,200,2,12.33,100,1,13.46,15,1,13.98,2,1,14.26,100,1,14.4,200,2,14.48,700,1,14.53,100,1,14.54,700,1,14.55,100,1,14.56,700,1,14.6,100,1,ARL,338932853
2025-07-17T16:12:54.015217279Z,2025-07-17T16:12:54.015051915Z,160,2,1108,A,A,13.470000000,100,0,339110853,130,165364,282207405,ARL,0,13.47,100,130,165364,282207405,9.55,1700,17,9.68,100,1,10.61,200,2,11.27,100,1,11.4,100,1,11.76,100,1,11.93,200,2,12.1,100,1,12.2,200,2,12.33,100,1,13.46,15,1,13.47,100,1,13.98,2,1,14.26,100,1,14.4,200,2,14.48,700,1,14.53,100,1,14.54,700,1,14.55,100,1,14.56,700,1,ARL,339110853
2025-07-17T16:12:54.015951319Z,2025-07-17T16:12:54.015785325Z,160,2,1108,C,A,14.600000000,100,0,339096925,130,165994,282207428,ARL,0,14.6,100,130,165994,282207428,9.55,1700,17,9.68,100,1,10.61,200,2,11.27,100,1,11.4,100,1,11.76,100,1,11.93,200,2,12.1,100,1,12.2,200,2,12.33,100,1,13.46,15,1,13.47,100,1,13.98,2,1,14.26,100,1,14.4,200,2,14.48,700,1,14.53,100,1,14.54,700,1,14.55,100,1,14.56,700,1,ARL,339096925
2025-07-17T16:12:54.015954059Z,2025-07-17T16:12:54.015788678Z,160,2,1108,C,A,15.060000000,100,0,339097245,0,165381,282207429,ARL,0,15.06,100,0,165381,282207429,9.55,1700,17,9.68,100,1,10.61,200,2,11.27,100,1,11.4,100,1,11.76,100,1,11.93,200,2,12.1,100,1,12.2,200,2,12.33,100,1,13.46,15,1,13.47,100,1,13.98,2,1,14.26,100,1,14.4,200,2,14.48,700,1,14.53,100,1,14.54,700,1,14.55,100,1,14.56,700,1,ARL,339097245
2025-07-17T16:12:54.015954059Z,2025-07-17T16:12:54.015788678Z,160,2,1108,A,A,14.520000000,100,0,339110897,130,165381,282207429,ARL,0,14.52,100,130,165381,282207429,9.55,1700,17,9.68,100,1,10.61,200,2,11.27,100,1,11.4,100,1,11.76,100,1,11.93,200,2,12.1,100,1,12.2,200,2,12.33,100,1,13.46,15,1,13.47,100,1,13.98,2,1,14.26,100,1,14.4,200,2,14.48,700,1,14.52,100,1,14.53,100,1,14.54,700,1,14.55,100,1,ARL,339110897
2025-07-17T16:12:54.016305036Z,2025-07-17T16:12:54.016139684Z,160,2,1108,A,A,14.070000000,100,0,339110909,130,165352,282207437,ARL,0,14.07,100,130,165352,282207437,9.55,1700,17,9.68,100,1,10.61,200,2,11.27,100,1,11.4,100,1,11.76,100,1,11.93,200,2,12.1,100,1,12.2,200,2,12.33,100,1,13.46,15,1,13.47,100,1,13.98,2,1,14.07,100,1,14.26,100,1,14.4,200,2,14.48,700,1,14.52,100,1,14.53,100,1,14.54,700,1,ARL,339110909
2025-07-17T16:12:54.017154493Z,2025-07-17T16:12:54.016988897Z,160,2,1108,C,A,14.960000000,100,0,339096917,0,165596,282207488,ARL,0,14.96,100,0,165596,282207488,9.55,1700,17,9.68,100,1,10.61,200,2,11.27,100,1,11.4,100,1,11.76,100,1,11.93,200,2,12.1,100,1,12.2,200,2,12.33,100,1,13.46,15,1,13.47,100,1,13.98,2,1,14.07,100,1,14.26,100,1,14.4,200,2,14.48,700,1,14.52,100,1,14.53,100,1,14.54,700,1,ARL,339096917
2025-07-17T16:12:54.017154493Z,2025-07-17T16:12:54.016988897Z,160,2,1108,A,A,14.420000000,100,0,339110981,130,165596,282207488,ARL,0,14.42,100,130,165596,282207488,9.55,1700,17,9.68,100,1,10.61,200,2,11.27,100,1,11.4,100,1,11.76,100,1,11.93,200,2,12.1,100,1,12.2,200,2,12.33,100,1,13.46,15,1,13.47,100,1,13.98,2,1,14.07,100,1,14.26,100,1,14.4,200,2,14.42,100,1,14.48,700,1,14.52,100,1,14.53,100,1,ARL,339110981
2025-07-17T16:12:54.017381126Z,2025-07-17T16:12:54.017215883Z,160,2,1108,C,A,13.980000000,2,0,339096909,0,165243,282207495,ARL,0,13.98,2,0,165243,282207495,9.55,1700,17,9.68,100,1,10.61,200,2,11.27,100,1,11.4,100,1,11.76,100,1,11.93,200,2,12.1,100,1,12.2,200,2,12.33,100,1,13.46,15,1,13.47,100,1,14.07,100,1,14.26,100,1,14.4,200,2,14.42,100,1,14.48,700,1,14.52,100,1,14.53,100,1,14.54,700,1,ARL,339096909
2025-07-17T16:12:54.017381126Z,2025-07-17T16:12:54.017215883Z,160,2,1108,A,A,13.730000000,2,0,339110993,130,165243,282207495,ARL,0,13.73,2,130,165243,282207495,9.55,1700,17,9.68,100,1,10.61,200,2,11.27,100,1,11.4,100,1,11.76,100,1,11.93,200,2,12.1,100,1,12.2,200,2,12.33,100,1,13.46,15,1,13.47,100,1,13.73,2,1,14.07,100,1,14.26,100,1,14.4,200,2,14.42,100,1,14.48,700,1,14.52,100,1,14.53,100,1,ARL,339110993
2025-07-17T16:12:54.017787766Z,2025-07-17T16:12:54.017622232Z,160,2,1108,C,A,15.380000000,100,0,339096929,0,165534,282207502,ARL,0,15.38,100,0,165534,282207502,9.55,1700,17,9.68,100,1,10.61,200,2,11.27,100,1,11.4,100,1,11.76,100,1,11.93,200,2,12.1,100,1,12.2,200,2,12.33,100,1,13.46,15,1,13.47,100,1,13.73,2,1,14.07,100,1,14.26,100,1,14.4,200,2,14.42,100,1,14.48,700,1,14.52,100,1,14.53,100,1,ARL,339096929
2025-07-17T16:12:54.017787766Z,2025-07-17T16:12:54.017622232Z,160,2,1108,A,A,14.820000000,100,0,339111005,130,165534,282207502,ARL,0,14.82,100,130,165534,282207502,9.55,1700,17,9.68,100,1,10.61,200,2,11.27,100,1,11.4,100,1,11.76,100,1,11.93,200,2,12.1,100,1,12.2,200,2,12.33,100,1,13.46,15,1,13.47,100,1,13.73,2,1,14.07,100,1,14.26,100,1,14.4,200,2,14.42,100,1,14.48,700,1,14.52,100,1,14.53,100,1,ARL,339111005
2025-07-17T16:12:54.020179178Z,2025-07-17T16:12:54.020013940Z,160,2,1108,C,A,14.260000000,100,0,339097005,130,165238,282207539,ARL,0,14.26,100,130,165238,282207539,9.55,1700,17,9.68,100,1,10.61,200,2,11.27,100,1,11.4,100,1,11.76,100,1,11.93,200,2,12.1,100,1,12.2,200,2,12.33,100,1,13.46,15,1,13.47,100,1,13.73,2,1,14.07,100,1,14.4,200,2,14.42,100,1,14.48,700,1,14.52,100,1,14.53,100,1,14.54,700,1,ARL,339097005
2025-07-17T16:12:54.020233019Z,2025-07-17T16:12:54.020067630Z,160,2,1108,A,A,13.740000000,100,0,339111029,130,165389,282207540,ARL,0,13.74,100,130,165389,282207540,9.55,1700,17,9.68,100,1,10.61,200,2,11.27,100,1,11.4,100,1,11.76,100,1,11.93,200,2,12.1,100,1,12.2,200,2,12.33,100,1,13.46,15,1,13.47,100,1,13.73,2,1,13.74,100,1,14.07,100,1,14.4,200,2,14.42,100,1,14.48,700,1,14.52,100,1,14.53,100,1,ARL,339111029
2025-07-17T16:12:54.023027943Z,2025-07-17T16:12:54.022862493Z,160,2,1108,C,A,17.760000000,100,0,339096949,0,165450,282207651,ARL,0,17.76,100,0,165450,282207651,9.55,1700,17,9.68,100,1,10.61,200,2,11.27,100,1,11.4,100,1,11.76,100,1,11.93,200,2,12.1,100,1,12.2,200,2,12.33,100,1,13.46,15,1,13.47,100,1,13.73,2,1,13.74,100,1,14.07,100,1,14.4,200,2,14.42,100,1,14.48,700,1,14.52,100,1,14.53,100,1,ARL,339096949
2025-07-17T16:12:54.023027943Z,2025-07-17T16:12:54.022862493Z,160,2,1108,A,A,17.110000000,100,0,339111097,130,165450,282207651,ARL,0,17.11,100,130,165450,282207651,9.55,1700,17,9.68,100,1,10.61,200,2,11.27,100,1,11.4,100,1,11.76,100,1,11.93,200,2,12.1,100,1,12.2,200,2,12.33,100,1,13.46,15,1,13.47,100,1,13.73,2,1,13.74,100,1,14.07,100,1,14.4,200,2,14.42,100,1,14.48,700,1,14.52,100,1,14.53,100,1,ARL,339111097
2025-07-17T16:12:54.026187354Z,2025-07-17T16:12:54.026021681Z,160,2,1108,C,A,16.080000000,100,0,339096921,0,165673,282207700,ARL,0,16.08,100,0,165673,282207700,9.55,1700,17,9.68,100,1,10.61,200,2,11.27,100,1,11.4,100,1,11.76,100,1,11.93,200,2,12.1,100,1,12.2,200,2,12.33,100,1,13.46,15,1,13.47,100,1,13.73,2,1,13.74,100,1,14.07,100,1,14.4,200,2,14.42,100,1,14.48,700,1,14.52,100,1,14.53,100,1,ARL,339096921
2025-07-17T16:12:54.026187354Z,2025-07-17T16:12:54.026021681Z,160,2,1108,A,A,15.500000000,100,0,339111149,130,165673,282207700,ARL,0,15.5,100,130,165673,282207700,9.55,1700,17,9.68,100,1,10.61,200,2,11.27,100,1,11.4,100,1,11.76,100,1,11.93,200,2,12.1,100,1,12.2,200,2,12.33,100,1,13.46,15,1,13.47,100,1,13.73,2,1,13.74,100,1,14.07,100,1,14.4,200,2,14.42,100,1,14.48,700,1,14.52,100,1,14.53,100,1,ARL,339111149
2025-07-17T16:12:54.029232379Z,2025-07-17T16:12:54.029066847Z,160,2,1108,C,A,14.550000000,100,0,339096833,0,165532,282207737,ARL,0,14.55,100,0,165532,282207737,9.55,1700,17,9.68,100,1,10.61,200,2,11.27,100,1,11.4,100,1,11.76,100,1,11.93,200,2,12.1,100,1,12.2,200,2,12.33,100,1,13.46,15,1,13.47,100,1,13.73,2,1,13.74,100,1,14.07,100,1,14.4,200,2,14.42,100,1,14.48,700,1,14.52,100,1,14.53,100,1,ARL,339096833
2025-07-17T16:12:54.029232379Z,2025-07-17T16:12:54.029066847Z,160,2,1108,A,A,14.260000000,100,0,339111189,130,165532,282207737,ARL,0,14.26,100,130,165532,282207737,9.55,1700,17,9.68,100,1,10.61,200,2,11.27,100,1,11.4,100,1,11.76,100,1,11.93,200,2,12.1,100,1,12.2,200,2,12.33,100,1,13.46,15,1,13.47,100,1,13.73,2,1,13.74,100,1,14.07,100,1,14.26,100,1,14.4,200,2,14.42,100,1,14.48,700,1,14.52,100,1,ARL,339111189
2025-07-17T16:12:54.055257401Z,2025-07-17T16:12:54.055092122Z,160,2,1108,A,A,15.360000000,100,0,339112469,130,165279,282209385,ARL,0,15.36,100,130,165279,282209385,9.55,1700,17,9.68,100,1,10.61,200,2,11.27,100,1,11.4,100,1,11.76,100,1,11.93,200,2,12.1,100,1,12.2,200,2,12.33,100,1,13.46,15,1,13.47,100,1,13.73,2,1,13.74,100,1,14.07,100,1,14.26,100,1,14.4,200,2,14.42,100,1,14.48,700,1,14.52,100,1,ARL,339112469
2025-07-17T16:12:54.055269406Z,2025-07-17T16:12:54.055104415Z,160,2,1108,C,A,15.690000000,100,0,339096757,130,164991,282209392,ARL,0,15.69,100,130,164991,282209392,9.55,1700,17,9.68,100,1,10.61,200,2,11.27,100,1,11.4,100,1,11.76,100,1,11.93,200,2,12.1,100,1,12.2,200,2,12.33,100,1,13.46,15,1,13.47,100,1,13.73,2,1,13.74,100,1,14.07,100,1,14.26,100,1,14.4,200,2,14.42,100,1,14.48,700,1,14.52,100,1,ARL,339096757
2025-07-17T16:12:54.069779810Z,2025-07-17T16:12:54.069614114Z,160,2,1108,C,A,14.960000000,100,0,339096977,0,165696,282210148,ARL,0,14.96,100,0,165696,282210148,9.55,1700,17,9.68,100,1,10.61,200,2,11.27,100,1,11.4,100,1,11.76,100,1,11.93,200,2,12.1,100,1,12.2,200,2,12.33,100,1,13.46,15,1,13.47,100,1,13.73,2,1,13.74,100,1,14.07,100,1,14.26,100,1,14.4,200,2,14.42,100,1,14.48,700,1,14.52,100,1,ARL,339096977
2025-07-17T16:12:54.069779810Z,2025-07-17T16:12:54.069614114Z,160,2,1108,A,A,14.420000000,100,0,339112945,130,165696,282210148,ARL,0,14.42,100,130,165696,282210148,9.55,1700,17,9.68,100,1,10.61,200,2,11.27,100,1,11.4,100,1,11.76,100,1,11.93,200,2,12.1,100,1,12.2,200,2,12.33,100,1,13.46,15,1,13.47,100,1,13.73,2,1,13.74,100,1,14.07,100,1,14.26,100,1,14.4,200,2,14.42,200,2,14.48,700,1,14.52,100,1,ARL,339112945
2025-07-17T16:12:54.072881596Z,2025-07-17T16:12:54.072716256Z,160,2,1108,C,A,15.140000000,100,0,339096813,0,165340,282210181,ARL,0,15.14,100,0,165340,282210181,9.55,1700,17,9.68,100,1,10.61,200,2,11.27,100,1,11.4,100,1,11.76,100,1,11.93,200,2,12.1,100,1,12.2,200,2,12.33,100,1,13.46,15,1,13.47,100,1,13.73,2,1,13.74,100,1,14.07,100,1,14.26,100,1,14.4,200,2,14.42,200,2,14.48,700,1,14.52,100,1,ARL,339096813
2025-07-17T16:12:54.072881596Z,2025-07-17T16:12:54.072716256Z,160,2,1108,A,A,14.820000000,100,0,339112981,130,165340,282210181,ARL,0,14.82,100,130,165340,282210181,9.55,1700,17,9.68,100,1,10.61,200,2,11.27,100,1,11.4,100,1,11.76,100,1,11.93,200,2,12.1,100,1,12.2,200,2,12.33,100,1,13.46,15,1,13.47,100,1,13.73,2,1,13.74,100,1,14.07,100,1,14.26,100,1,14.4,200,2,14.42,200,2,14.48,700,1,14.52,100,1,ARL,339112981
2025-07-17T16:12:54.694796063Z,2025-07-17T16:12:54.694630780Z,160,2,1108,A,A,14.270000000,100,0,339126221,130,165283,282224916,ARL,0,14.27,100,130,165283,282224916,9.55,1700,17,9.68,100,1,10.61,200,2,11.27,100,1,11.4,100,1,11.76,100,1,11.93,200,2,12.1,100,1,12.2,200,2,12.33,100,1,13.46,15,1,13.47,100,1,13.73,2,1,13.74,100,1,14.07,100,1,14.26,100,1,14.27,100,1,14.4,200,2,14.42,200,2,14.48,700,1,ARL,339126221
2025-07-17T16:12:54.694809520Z,2025-07-17T16:12:54.694644316Z,160,2,1108,C,A,14.810000000,100,0,339103269,130,165204,282224917,ARL,0,14.81,100,130,165204,282224917,9.55,1700,17,9.68,100,1,10.61,200,2,11.27,100,1,11.4,100,1,11.76,100,1,11.93,200,2,12.1,100,1,12.2,200,2,12.33,100,1,13.46,15,1,13.47,100,1,13.73,2,1,13.74,100,1,14.07,100,1,14.26,100,1,14.27,100,1,14.4,200,2,14.42,200,2,14.48,700,1,ARL,339103269
2025-07-17T16:12:55.255327586Z,2025-07-17T16:12:55.255162003Z,160,2,1108,A,A,14.000000000,100,0,339133353,130,165583,282231441,ARL,0,14,100,130,165583,282231441,9.55,1700,17,9.68,100,1,10.61,200,2,11.27,100,1,11.4,100,1,11.76,100,1,11.93,200,2,12.1,100,1,12.2,200,2,12.33,100,1,13.46,15,1,13.47,100,1,13.73,2,1,13.74,100,1,14,100,1,14.07,100,1,14.26,100,1,14.27,100,1,14.4,200,2,14.42,200,2,ARL,339133353
2025-07-17T16:12:55.255328269Z,2025-07-17T16:12:55.255163083Z,160,2,1108,C,A,14.530000000,100,0,339100477,130,165186,282231442,ARL,0,14.53,100,130,165186,282231442,9.55,1700,17,9.68,100,1,10.61,200,2,11.27,100,1,11.4,100,1,11.76,100,1,11.93,200,2,12.1,100,1,12.2,200,2,12.33,100,1,13.46,15,1,13.47,100,1,13.73,2,1,13.74,100,1,14,100,1,14.07,100,1,14.26,100,1,14.27,100,1,14.4,200,2,14.42,200,2,ARL,339100477
2025-07-17T16:12:58.302183447Z,2025-07-17T16:12:58.302017238Z,160,2,1108,C,A,13.460000000,15,0,339096733,128,166209,282279351,ARL,0,13.46,15,128,166209,282279351,9.55,1700,17,9.68,100,1,10.61,200,2,11.27,100,1,11.4,100,1,11.76,100,1,11.93,200,2,12.1,100,1,12.2,200,2,12.33,100,1,13.47,100,1,13.73,2,1,13.74,100,1,14,100,1,14.07,100,1,14.26,100,1,14.27,100,1,14.4,200,2,14.42,200,2,14.48,700,1,ARL,339096733
2025-07-17T16:12:58.420887746Z,2025-07-17T16:12:58.420710579Z,160,2,1108,C,A,13.470000000,100,0,339110853,128,177167,282288716,ARL,0,13.47,100,128,177167,282288716,9.55,1700,17,9.68,100,1,10.61,200,2,11.27,100,1,11.4,100,1,11.76,100,1,11.93,200,2,12.1,100,1,12.2,200,2,12.33,100,1,13.73,2,1,13.74,100,1,14,100,1,14.07,100,1,14.26,100,1,14.27,100,1,14.4,200,2,14.42,200,2,14.48,700,1,14.52,100,1,ARL,339110853
2025-07-17T16:12:58.420950587Z,2025-07-17T16:12:58.420776003Z,160,2,1108,A,A,13.470000000,96,0,339201549,128,174584,282288757,ARL,0,13.47,96,128,174584,282288757,9.55,1700,17,9.68,100,1,10.61,200,2,11.27,100,1,11.4,100,1,11.76,100,1,11.93,200,2,12.1,100,1,12.2,200,2,12.33,100,1,13.47,96,1,13.73,2,1,13.74,100,1,14,100,1,14.07,100,1,14.26,100,1,14.27,100,1,14.4,200,2,14.42,200,2,14.48,700,1,ARL,339201549
2025-07-17T16:12:58.421338553Z,2025-07-17T16:12:58.421165414Z,160,2,1108,C,A,13.470000000,96,0,339201549,130,173139,282289082,ARL,0,13.47,96,130,173139,282289082,9.55,1700,17,9.68,100,1,10.61,200,2,11.27,100,1,11.4,100,1,11.76,100,1,11.93,200,2,12.1,100,1,12.2,200,2,12.33,100,1,13.73,2,1,13.74,100,1,14,100,1,14.07,100,1,14.26,100,1,14.27,100,1,14.4,200,2,14.42,200,2,14.48,700,1,14.52,100,1,ARL,339201549
2025-07-17T16:12:58.421379924Z,2025-07-17T16:12:58.421205027Z,160,2,1108,A,A,15.670000000,100,0,339202065,128,174897,282289111,ARL,0,15.67,100,128,174897,282289111,9.55,1700,17,9.68,100,1,10.61,200,2,11.27,100,1,11.4,100,1,11.76,100,1,11.93,200,2,12.1,100,1,12.2,200,2,12.33,100,1,13.73,2,1,13.74,100,1,14,100,1,14.07,100,1,14.26,100,1,14.27,100,1,14.4,200,2,14.42,200,2,14.48,700,1,14.52,100,1,ARL,339202065
2025-07-17T16:12:58.421423275Z,2025-07-17T16:12:58.421248082Z,160,2,1108,C,A,15.360000000,100,0,339112469,128,175193,282289154,ARL,0,15.36,100,128,175193,282289154,9.55,1700,17,9.68,100,1,10.61,200,2,11.27,100,1,11.4,100,1,11.76,100,1,11.93,200,2,12.1,100,1,12.2,200,2,12.33,100,1,13.73,2,1,13.74,100,1,14,100,1,14.07,100,1,14.26,100,1,14.27,100,1,14.4,200,2,14.42,200,2,14.48,700,1,14.52,100,1,ARL,339112469
2025-07-17T16:12:58.421756726Z,2025-07-17T16:12:58.421581692Z,160,2,1108,C,A,14.070000000,100,0,339110909,130,175034,282289338,ARL,0,14.07,100,130,175034,282289338,9.55,1700,17,9.68,100,1,10.61,200,2,11.27,100,1,11.4,100,1,11.76,100,1,11.93,200,2,12.1,100,1,12.2,200,2,12.33,100,1,13.73,2,1,13.74,100,1,14,100,1,14.26,100,1,14.27,100,1,14.4,200,2,14.42,200,2,14.48,700,1,14.52,100,1,14.54,700,1,ARL,339110909
2025-07-17T16:12:58.422145785Z,2025-07-17T16:12:58.421969675Z,160,2,1108,A,A,14.350000000,100,0,339202733,128,176110,282289650,ARL,0,14.35,100,128,176110,282289650,9.55,1700,17,9.68,100,1,10.61,200,2,11.27,100,1,11.4,100,1,11.76,100,1,11.93,200,2,12.1,100,1,12.2,200,2,12.33,100,1,13.73,2,1,13.74,100,1,14,100,1,14.26,100,1,14.27,100,1,14.35,100,1,14.4,200,2,14.42,200,2,14.48,700,1,14.52,100,1,ARL,339202733
2025-07-17T16:12:58.422247877Z,2025-07-17T16:12:58.422073305Z,160,2,1108,C,A,14.520000000,100,0,339110897,0,174572,282289747,ARL,0,14.52,100,0,174572,282289747,9.55,1700,17,9.68,100,1,10.61,200,2,11.27,100,1,11.4,100,1,11.76,100,1,11.93,200,2,12.1,100,1,12.2,200,2,12.33,100,1,13.73,2,1,13.74,100,1,14,100,1,14.26,100,1,14.27,100,1,14.35,100,1,14.4,200,2,14.42,200,2,14.48,700,1,14.54,700,1,ARL,339110897
2025-07-17T16:12:58.422247877Z,2025-07-17T16:12:58.422073305Z,160,2,1108,A,A,14.810000000,100,0,339202805,128,174572,282289747,ARL,0,14.81,100,128,174572,282289747,9.55,1700,17,9.68,100,1,10.61,200,2,11.27,100,1,11.4,100,1,11.76,100,1,11.93,200,2,12.1,100,1,12.2,200,2,12.33,100,1,13.73,2,1,13.74,100,1,14,100,1,14.26,100,1,14.27,100,1,14.35,100,1,14.4,200,2,14.42,200,2,14.48,700,1,14.54,700,1,ARL,339202805
2025-07-17T16:12:58.424958370Z,2025-07-17T16:12:58.424789366Z,160,2,1108,C,A,14.400000000,100,0,338139585,0,169004,282290622,ARL,0,14.4,100,0,169004,282290622,9.55,1700,17,9.68,100,1,10.61,200,2,11.27,100,1,11.4,100,1,11.76,100,1,11.93,200,2,12.1,100,1,12.2,200,2,12.33,100,1,13.73,2,1,13.74,100,1,14,100,1,14.26,100,1,14.27,100,1,14.35,100,1,14.4,100,1,14.42,200,2,14.48,700,1,14.54,700,1,ARL,338139585
2025-07-17T16:12:58.424958370Z,2025-07-17T16:12:58.424789366Z,160,2,1108,A,A,14.570000000,100,0,339203693,128,169004,282290622,ARL,0,14.57,100,128,169004,282290622,9.55,1700,17,9.68,100,1,10.61,200,2,11.27,100,1,11.4,100,1,11.76,100,1,11.93,200,2,12.1,100,1,12.2,200,2,12.33,100,1,13.73,2,1,13.74,100,1,14,100,1,14.26,100,1,14.27,100,1,14.35,100,1,14.4,100,1,14.42,200,2,14.48,700,1,14.54,700,1,ARL,339203693
2025-07-17T16:12:58.425450176Z,2025-07-17T16:12:58.425283932Z,160,2,1108,C,A,14.400000000,100,0,338139601,0,166244,282290769,ARL,0,14.4,100,0,166244,282290769,9.55,1700,17,9.68,100,1,10.61,200,2,11.27,100,1,11.4,100,1,11.76,100,1,11.93,200,2,12.1,100,1,12.2,200,2,12.33,100,1,13.73,2,1,13.74,100,1,14,100,1,14.26,100,1,14.27,100,1,14.35,100,1,14.42,200,2,14.48,700,1,14.54,700,1,14.56,700,1,ARL,338139601
2025-07-17T16:12:58.425450176Z,2025-07-17T16:12:58.425283932Z,160,2,1108,A,A,14.570000000,100,0,339203897,128,166244,282290769,ARL,0,14.57,100,128,166244,282290769,9.55,1700,17,9.68,100,1,10.61,200,2,11.27,100,1,11.4,100,1,11.76,100,1,11.93,200,2,12.1,100,1,12.2,200,2,12.33,100,1,13.73,2,1,13.74,100,1,14,100,1,14.26,100,1,14.27,100,1,14.35,100,1,14.42,200,2,14.48,700,1,14.54,700,1,14.56,700,1,ARL,339203897
2025-07-17T16:12:58.426423622Z,2025-07-17T16:12:58.426258092Z,160,2,1108,C,A,14.260000000,100,0,339111189,130,165530,282290946,ARL,0,14.26,100,130,165530,282290946,9.55,1700,17,9.68,100,1,10.61,200,2,11.27,100,1,11.4,100,1,11.76,100,1,11.93,200,2,12.1,100,1,12.2,200,2,12.33,100,1,13.73,2,1,13.74,100,1,14,100,1,14.27,100,1,14.35,100,1,14.42,200,2,14.48,700,1,14.54,700,1,14.56,700,1,14.57,200,2,ARL,339111189
2025-07-17T16:12:58.426544477Z,2025-07-17T16:12:58.426378483Z,160,2,1108,A,A,14.530000000,100,0,339204077,130,165994,282290959,ARL,0,14.53,100,130,165994,282290959,9.55,1700,17,9.68,100,1,10.61,200,2,11.27,100,1,11.4,100,1,11.76,100,1,11.93,200,2,12.1,100,1,12.2,200,2,12.33,100,1,13.73,2,1,13.74,100,1,14,100,1,14.27,100,1,14.35,100,1,14.42,200,2,14.48,700,1,14.53,100,1,14.54,700,1,14.56,700,1,ARL,339204077
2025-07-17T16:12:58.430830694Z,2025-07-17T16:12:58.430665639Z,160,2,1108,C,A,13.740000000,100,0,339111029,130,165055,282291933,ARL,0,13.74,100,130,165055,282291933,9.55,1700,17,9.68,100,1,10.61,200,2,11.27,100,1,11.4,100,1,11.76,100,1,11.93,200,2,12.1,100,1,12.2,200,2,12.33,100,1,13.73,2,1,14,100,1,14.27,100,1,14.35,100,1,14.42,200,2,14.48,700,1,14.53,100,1,14.54,700,1,14.56,700,1,14.57,200,2,ARL,339111029
2025-07-17T16:12:58.430888526Z,2025-07-17T16:12:58.430720526Z,160,2,1108,A,A,14.010000000,100,0,339205213,128,168000,282291946,ARL,0,14.01,100,128,168000,282291946,9.55,1700,17,9.68,100,1,10.61,200,2,11.27,100,1,11.4,100,1,11.76,100,1,11.93,200,2,12.1,100,1,12.2,200,2,12.33,100,1,13.73,2,1,14,100,1,14.01,100,1,14.27,100,1,14.35,100,1,14.42,200,2,14.48,700,1,14.53,100,1,14.54,700,1,14.56,700,1,ARL,339205213
2025-07-17T16:12:58.432901795Z,2025-07-17T16:12:58.432736189Z,160,2,1108,C,A,14.820000000,100,0,339111005,0,165606,282292390,ARL,0,14.82,100,0,165606,282292390,9.55,1700,17,9.68,100,1,10.61,200,2,11.27,100,1,11.4,100,1,11.76,100,1,11.93,200,2,12.1,100,1,12.2,200,2,12.33,100,1,13.73,2,1,14,100,1,14.01,100,1,14.27,100,1,14.35,100,1,14.42,200,2,14.48,700,1,14.53,100,1,14.54,700,1,14.56,700,1,ARL,339111005
2025-07-17T16:12:58.432901795Z,2025-07-17T16:12:58.432736189Z,160,2,1108,A,A,15.380000000,100,0,339206141,130,165606,282292390,ARL,0,15.38,100,130,165606,282292390,9.55,1700,17,9.68,100,1,10.61,200,2,11.27,100,1,11.4,100,1,11.76,100,1,11.93,200,2,12.1,100,1,12.2,200,2,12.33,100,1,13.73,2,1,14,100,1,14.01,100,1,14.27,100,1,14.35,100,1,14.42,200,2,14.48,700,1,14.53,100,1,14.54,700,1,14.56,700,1,ARL,339206141
2025-07-17T16:12:58.438073339Z,2025-07-17T16:12:58.437907652Z,160,2,1108,C,B,12.920000000,2,0,338044113,0,165687,282292938,ARL,0,12.92,2,0,165687,282292938,9.55,1700,17,9.68,100,1,10.61,200,2,11.27,100,1,11.4,100,1,11.76,100,1,11.93,200,2,12.1,100,1,12.2,200,2,12.33,100,1,13.73,2,1,14,100,1,14.01,100,1,14.27,100,1,14.35,100,1,14.42,200,2,14.48,700,1,14.53,100,1,14.54,700,1,14.56,700,1,ARL,338044113
2025-07-17T16:12:58.438073339Z,2025-07-17T16:12:58.437907652Z,160,2,1108,A,B,13.020000000,2,0,339207125,130,165687,282292938,ARL,0,13.02,2,130,165687,282292938,9.55,1700,17,9.68,100,1,10.61,200,2,11.27,100,1,11.4,100,1,11.76,100,1,11.93,200,2,12.1,100,1,12.2,200,2,12.33,100,1,13.73,2,1,14,100,1,14.01,100,1,14.27,100,1,14.35,100,1,14.42,200,2,14.48,700,1,14.53,100,1,14.54,700,1,14.56,700,1,ARL,339207125
2025-07-17T16:12:58.438076762Z,2025-07-17T16:12:58.437911392Z,160,2,1108,C,A,13.730000000,2,0,339110993,0,165370,282292939,ARL,0,13.73,2,0,165370,282292939,9.55,1700,17,9.68,100,1,10.61,200,2,11.27,100,1,11.4,100,1,11.76,100,1,11.93,200,2,12.1,100,1,12.2,200,2,12.33,100,1,14,100,1,14.01,100,1,14.27,100,1,14.35,100,1,14.42,200,2,14.48,700,1,14.53,100,1,14.54,700,1,14.56,700,1,14.57,200,2,ARL,339110993
2025-07-17T16:12:58.438076762Z,2025-07-17T16:12:58.437911392Z,160,2,1108,A,A,13.980000000,2,0,339207129,130,165370,282292939,ARL,0,13.98,2,130,165370,282292939,9.55,1700,17,9.68,100,1,10.61,200,2,11.27,100,1,11.4,100,1,11.76,100,1,11.93,200,2,12.1,100,1,12.2,200,2,12.33,100,1,13.98,2,1,14,100,1,14.01,100,1,14.27,100,1,14.35,100,1,14.42,200,2,14.48,700,1,14.53,100,1,14.54,700,1,14.56,700,1,ARL,339207129
2025-07-17T16:12:58.438843944Z,2025-07-17T16:12:58.438678961Z,160,2,1108,C,A,14.010000000,100,0,339205213,130,164983,282293023,ARL,0,14.01,100,130,164983,282293023,9.55,1700,17,9.68,100,1,10.61,200,2,11.27,100,1,11.4,100,1,11.76,100,1,11.93,200,2,12.1,100,1,12.2,200,2,12.33,100,1,13.98,2,1,14,100,1,14.27,100,1,14.35,100,1,14.42,200,2,14.48,700,1,14.53,100,1,14.54,700,1,14.56,700,1,14.57,200,2,ARL,339205213
2025-07-17T16:12:58.438894336Z,2025-07-17T16:12:58.438728994Z,160,2,1108,A,A,14.240000000,100,0,339207197,130,165342,282293026,ARL,0,14.24,100,130,165342,282293026,9.55,1700,17,9.68,100,1,10.61,200,2,11.27,100,1,11.4,100,1,11.76,100,1,11.93,200,2,12.1,100,1,12.2,200,2,12.33,100,1,13.98,2,1,14,100,1,14.24,100,1,14.27,100,1,14.35,100,1,14.42,200,2,14.48,700,1,14.53,100,1,14.54,700,1,14.56,700,1,ARL,339207197
2025-07-17T16:12:58.441834497Z,2025-07-17T16:12:58.441669159Z,160,2,1108,C,A,14.420000000,100,0,339110981,0,165338,282293191,ARL,0,14.42,100,0,165338,282293191,9.55,1700,17,9.68,100,1,10.61,200,2,11.27,100,1,11.4,100,1,11.76,100,1,11.93,200,2,12.1,100,1,12.2,200,2,12.33,100,1,13.98,2,1,14,100,1,14.24,100,1,14.27,100,1,14.35,100,1,14.42,100,1,14.48,700,1,14.53,100,1,14.54,700,1,14.56,700,1,ARL,339110981
2025-07-17T16:12:58.441834497Z,2025-07-17T16:12:58.441669159Z,160,2,1108,A,A,14.960000000,100,0,339207505,130,165338,282293191,ARL,0,14.96,100,130,165338,282293191,9.55,1700,17,9.68,100,1,10.61,200,2,11.27,100,1,11.4,100,1,11.76,100,1,11.93,200,2,12.1,100,1,12.2,200,2,12.33,100,1,13.98,2,1,14,100,1,14.24,100,1,14.27,100,1,14.35,100,1,14.42,100,1,14.48,700,1,14.53,100,1,14.54,700,1,14.56,700,1,ARL,339207505
2025-07-17T16:12:58.454376675Z,2025-07-17T16:12:58.454211242Z,160,2,1108,C,A,17.110000000,100,0,339111097,0,165433,282293811,ARL,0,17.11,100,0,165433,282293811,9.55,1700,17,9.68,100,1,10.61,200,2,11.27,100,1,11.4,100,1,11.76,100,1,11.93,200,2,12.1,100,1,12.2,200,2,12.33,100,1,13.98,2,1,14,100,1,14.24,100,1,14.27,100,1,14.35,100,1,14.42,100,1,14.48,700,1,14.53,100,1,14.54,700,1,14.56,700,1,ARL,339111097
2025-07-17T16:12:58.454376675Z,2025-07-17T16:12:58.454211242Z,160,2,1108,A,A,17.760000000,100,0,339208377,130,165433,282293811,ARL,0,17.76,100,130,165433,282293811,9.55,1700,17,9.68,100,1,10.61,200,2,11.27,100,1,11.4,100,1,11.76,100,1,11.93,200,2,12.1,100,1,12.2,200,2,12.33,100,1,13.98,2,1,14,100,1,14.24,100,1,14.27,100,1,14.35,100,1,14.42,100,1,14.48,700,1,14.53,100,1,14.54,700,1,14.56,700,1,ARL,339208377
2025-07-17T16:12:58.472292476Z,2025-07-17T16:12:58.472126777Z,160,2,1108,C,A,15.500000000,100,0,339111149,0,165699,282294411,ARL,0,15.5,100,0,165699,282294411,9.55,1700,17,9.68,100,1,10.61,200,2,11.27,100,1,11.4,100,1,11.76,100,1,11.93,200,2,12.1,100,1,12.2,200,2,12.33,100,1,13.98,2,1,14,100,1,14.24,100,1,14.27,100,1,14.35,100,1,14.42,100,1,14.48,700,1,14.53,100,1,14.54,700,1,14.56,700,1,ARL,339111149
2025-07-17T16:12:58.472292476Z,2025-07-17T16:12:58.472126777Z,160,2,1108,A,A,16.080000000,100,0,339209241,130,165699,282294411,ARL,0,16.08,100,130,165699,282294411,9.55,1700,17,9.68,100,1,10.61,200,2,11.27,100,1,11.4,100,1,11.76,100,1,11.93,200,2,12.1,100,1,12.2,200,2,12.33,100,1,13.98,2,1,14,100,1,14.24,100,1,14.27,100,1,14.35,100,1,14.42,100,1,14.48,700,1,14.53,100,1,14.54,700,1,14.56,700,1,ARL,339209241
2025-07-17T16:12:58.472624779Z,2025-07-17T16:12:58.472458830Z,160,2,1108,C,A,14.810000000,100,0,339202805,0,165949,282294423,ARL,0,14.81,100,0,165949,282294423,9.55,1700,17,9.68,100,1,10.61,200,2,11.27,100,1,11.4,100,1,11.76,100,1,11.93,200,2,12.1,100,1,12.2,200,2,12.33,100,1,13.98,2,1,14,100,1,14.24,100,1,14.27,100,1,14.35,100,1,14.42,100,1,14.48,700,1,14.53,100,1,14.54,700,1,14.56,700,1,ARL,339202805
2025-07-17T16:12:58.472624779Z,2025-07-17T16:12:58.472458830Z,160,2,1108,A,A,15.040000000,100,0,339209257,130,165949,282294423,ARL,0,15.04,100,130,165949,282294423,9.55,1700,17,9.68,100,1,10.61,200,2,11.27,100,1,11.4,100,1,11.76,100,1,11.93,200,2,12.1,100,1,12.2,200,2,12.33,100,1,13.98,2,1,14,100,1,14.24,100,1,14.27,100,1,14.35,100,1,14.42,100,1,14.48,700,1,14.53,100,1,14.54,700,1,14.56,700,1,ARL,339209257
2025-07-17T16:12:58.571845708Z,2025-07-17T16:12:58.571679985Z,160,2,1108,C,A,14.820000000,100,0,339112981,0,165723,282298942,ARL,0,14.82,100,0,165723,282298942,9.55,1700,17,9.68,100,1,10.61,200,2,11.27,100,1,11.4,100,1,11.76,100,1,11.93,200,2,12.1,100,1,12.2,200,2,12.33,100,1,13.98,2,1,14,100,1,14.24,100,1,14.27,100,1,14.35,100,1,14.42,100,1,14.48,700,1,14.53,100,1,14.54,700,1,14.56,700,1,ARL,339112981
2025-07-17T16:12:58.571845708Z,2025-07-17T16:12:58.571679985Z,160,2,1108,A,A,15.380000000,100,0,339215205,130,165723,282298942,ARL,0,15.38,100,130,165723,282298942,9.55,1700,17,9.68,100,1,10.61,200,2,11.27,100,1,11.4,100,1,11.76,100,1,11.93,200,2,12.1,100,1,12.2,200,2,12.33,100,1,13.98,2,1,14,100,1,14.24,100,1,14.27,100,1,14.35,100,1,14.42,100,1,14.48,700,1,14.53,100,1,14.54,700,1,14.56,700,1,ARL,339215205
2025-07-17T16:12:58.619404102Z,2025-07-17T16:12:58.619238614Z,160,2,1108,C,A,14.420000000,100,0,339112945,0,165488,282299781,ARL,0,14.42,100,0,165488,282299781,9.55,1700,17,9.68,100,1,10.61,200,2,11.27,100,1,11.4,100,1,11.76,100,1,11.93,200,2,12.1,100,1,12.2,200,2,12.33,100,1,13.98,2,1,14,100,1,14.24,100,1,14.27,100,1,14.35,100,1,14.48,700,1,14.53,100,1,14.54,700,1,14.56,700,1,14.57,200,2,ARL,339112945
2025-07-17T16:12:58.619404102Z,2025-07-17T16:12:58.619238614Z,160,2,1108,A,A,14.960000000,100,0,339216161,130,165488,282299781,ARL,0,14.96,100,130,165488,282299781,9.55,1700,17,9.68,100,1,10.61,200,2,11.27,100,1,11.4,100,1,11.76,100,1,11.93,200,2,12.1,100,1,12.2,200,2,12.33,100,1,13.98,2,1,14,100,1,14.24,100,1,14.27,100,1,14.35,100,1,14.48,700,1,14.53,100,1,14.54,700,1,14.56,700,1,14.57,200,2,ARL,339216161
2025-07-17T16:12:58.986093948Z,2025-07-17T16:12:58.985928594Z,160,2,1108,C,B,13.020000000,2,0,339207125,0,165354,282305386,ARL,0,13.02,2,0,165354,282305386,9.55,1700,17,9.68,100,1,10.61,200,2,11.27,100,1,11.4,100,1,11.76,100,1,11.93,200,2,12.1,100,1,12.2,200,2,12.33,100,1,13.98,2,1,14,100,1,14.24,100,1,14.27,100,1,14.35,100,1,14.48,700,1,14.53,100,1,14.54,700,1,14.56,700,1,14.57,200,2,ARL,339207125
2025-07-17T16:12:58.986093948Z,2025-07-17T16:12:58.985928594Z,160,2,1108,A,B,12.860000000,2,0,339222617,130,165354,282305386,ARL,0,12.86,2,130,165354,282305386,9.55,1700,17,9.68,100,1,10.61,200,2,11.27,100,1,11.4,100,1,11.76,100,1,11.93,200,2,12.1,100,1,12.2,200,2,12.33,100,1,13.98,2,1,14,100,1,14.24,100,1,14.27,100,1,14.35,100,1,14.48,700,1,14.53,100,1,14.54,700,1,14.56,700,1,14.57,200,2,ARL,339222617
2025-07-17T16:12:59.063108412Z,2025-07-17T16:12:59.062943193Z,160,2,1108,A,A,13.990000000,100,0,339224109,130,165219,282306400,ARL,0,13.99,100,130,165219,282306400,9.55,1700,17,9.68,100,1,10.61,200,2,11.27,100,1,11.4,100,1,11.76,100,1,11.93,200,2,12.1,100,1,12.2,200,2,12.33,100,1,13.98,2,1,13.99,100,1,14,100,1,14.24,100,1,14.27,100,1,14.35,100,1,14.48,700,1,14.53,100,1,14.54,700,1,14.56,700,1,ARL,339224109
2025-07-17T16:12:59.082855570Z,2025-07-17T16:12:59.082690430Z,160,2,1108,C,A,14.000000000,100,0,339133353,130,165140,282307908,ARL,0,14,100,130,165140,282307908,9.55,1700,17,9.68,100,1,10.61,200,2,11.27,100,1,11.4,100,1,11.76,100,1,11.93,200,2,12.1,100,1,12.2,200,2,12.33,100,1,13.98,2,1,13.99,100,1,14.24,100,1,14.27,100,1,14.35,100,1,14.48,700,1,14.53,100,1,14.54,700,1,14.56,700,1,14.57,200,2,ARL,339133353
2025-07-17T16:12:59.082856640Z,2025-07-17T16:12:59.082691385Z,160,2,1108,A,A,14.530000000,100,0,339225769,130,165255,282307909,ARL,0,14.53,100,130,165255,282307909,9.55,1700,17,9.68,100,1,10.61,200,2,11.27,100,1,11.4,100,1,11.76,100,1,11.93,200,2,12.1,100,1,12.2,200,2,12.33,100,1,13.98,2,1,13.99,100,1,14.24,100,1,14.27,100,1,14.35,100,1,14.48,700,1,14.53,200,2,14.54,700,1,14.56,700,1,14.57,200,2,ARL,339225769
2025-07-17T16:12:59.088794570Z,2025-07-17T16:12:59.088629294Z,160,2,1108,A,A,14.810000000,100,0,339225885,130,165276,282308093,ARL,0,14.81,100,130,165276,282308093,9.55,1700,17,9.68,100,1,10.61,200,2,11.27,100,1,11.4,100,1,11.76,100,1,11.93,200,2,12.1,100,1,12.2,200,2,12.33,100,1,13.98,2,1,13.99,100,1,14.24,100,1,14.27,100,1,14.35,100,1,14.48,700,1,14.53,200,2,14.54,700,1,14.56,700,1,14.57,200,2,ARL,339225885
2025-07-17T16:12:59.088808117Z,2025-07-17T16:12:59.088642718Z,160,2,1108,C,A,14.270000000,100,0,339126221,130,165399,282308094,ARL,0,14.27,100,130,165399,282308094,9.55,1700,17,9.68,100,1,10.61,200,2,11.27,100,1,11.4,100,1,11.76,100,1,11.93,200,2,12.1,100,1,12.2,200,2,12.33,100,1,13.98,2,1,13.99,100,1,14.24,100,1,14.35,100,1,14.48,700,1,14.53,200,2,14.54,700,1,14.56,700,1,14.57,200,2,14.68,700,1,ARL,339126221
2025-07-17T16:12:59.092927842Z,2025-07-17T16:12:59.092762564Z,160,2,1108,C,A,14.350000000,100,0,339202733,130,165278,282308154,ARL,0,14.35,100,130,165278,282308154,9.55,1700,17,9.68,100,1,10.61,200,2,11.27,100,1,11.4,100,1,11.76,100,1,11.93,200,2,12.1,100,1,12.2,200,2,12.33,100,1,13.98,2,1,13.99,100,1,14.24,100,1,14.48,700,1,14.53,200,2,14.54,700,1,14.56,700,1,14.57,200,2,14.68,700,1,14.81,100,1,ARL,339202733
2025-07-17T16:12:59.093278915Z,2025-07-17T16:12:59.093113488Z,160,2,1108,A,A,14.600000000,100,0,339226021,130,165427,282308163,ARL,0,14.6,100,130,165427,282308163,9.55,1700,17,9.68,100,1,10.61,200,2,11.27,100,1,11.4,100,1,11.76,100,1,11.93,200,2,12.1,100,1,12.2,200,2,12.33,100,1,13.98,2,1,13.99,100,1,14.24,100,1,14.48,700,1,14.53,200,2,14.54,700,1,14.56,700,1,14.57,200,2,14.6,100,1,14.68,700,1,ARL,339226021
2025-07-17T16:12:59.430486012Z,2025-07-17T16:12:59.430320610Z,160,2,1108,C,A,14.530000000,100,0,339204077,0,165402,282313368,ARL,0,14.53,100,0,165402,282313368,9.55,1700,17,9.68,100,1,10.61,200,2,11.27,100,1,11.4,100,1,11.76,100,1,11.93,200,2,12.1,100,1,12.2,200,2,12.33,100,1,13.98,2,1,13.99,100,1,14.24,100,1,14.48,700,1,14.53,100,1,14.54,700,1,14.56,700,1,14.57,200,2,14.6,100,1,14.68,700,1,ARL,339204077
2025-07-17T16:12:59.430486012Z,2025-07-17T16:12:59.430320610Z,160,2,1108,A,A,14.770000000,100,0,339232213,130,165402,282313368,ARL,0,14.77,100,130,165402,282313368,9.55,1700,17,9.68,100,1,10.61,200,2,11.27,100,1,11.4,100,1,11.76,100,1,11.93,200,2,12.1,100,1,12.2,200,2,12.33,100,1,13.98,2,1,13.99,100,1,14.24,100,1,14.48,700,1,14.53,100,1,14.54,700,1,14.56,700,1,14.57,200,2,14.6,100,1,14.68,700,1,ARL,339232213
2025-07-17T16:13:04.825902166Z,2025-07-17T16:13:04.825736034Z,160,2,1108,A,A,13.660000000,15,0,339332865,128,166132,282392593,ARL,0,13.66,15,128,166132,282392593,9.55,1700,17,9.68,100,1,10.61,200,2,11.27,100,1,11.4,100,1,11.76,100,1,11.93,200,2,12.1,100,1,12.2,200,2,12.33,100,1,13.66,15,1,13.98,2,1,13.99,100,1,14.24,100,1,14.48,700,1,14.53,100,1,14.54,700,1,14.56,700,1,14.57,200,2,14.6,100,1,ARL,339332865
2025-07-17T16:13:06.189275812Z,2025-07-17T16:13:06.189110140Z,160,2,1108,C,B,12.860000000,2,0,339222617,0,165672,282411935,ARL,0,12.86,2,0,165672,282411935,9.55,1700,17,9.68,100,1,10.61,200,2,11.27,100,1,11.4,100,1,11.76,100,1,11.93,200,2,12.1,100,1,12.2,200,2,12.33,100,1,13.66,15,1,13.98,2,1,13.99,100,1,14.24,100,1,14.48,700,1,14.53,100,1,14.54,700,1,14.56,700,1,14.57,200,2,14.6,100,1,ARL,339222617
2025-07-17T16:13:06.189275812Z,2025-07-17T16:13:06.189110140Z,160,2,1108,A,B,12.960000000,2,0,339356397,130,165672,282411935,ARL,0,12.96,2,130,165672,282411935,9.55,1700,17,9.68,100,1,10.61,200,2,11.27,100,1,11.4,100,1,11.76,100,1,11.93,200,2,12.1,100,1,12.2,200,2,12.33,100,1,13.66,15,1,13.98,2,1,13.99,100,1,14.24,100,1,14.48,700,1,14.53,100,1,14.54,700,1,14.56,700,1,14.57,200,2,14.6,100,1,ARL,339356397
2025-07-17T16:13:06.224898389Z,2025-07-17T16:13:06.224732787Z,160,2,1108,C,A,13.990000000,100,0,339224109,0,165602,282413599,ARL,0,13.99,100,0,165602,282413599,9.55,1700,17,9.68,100,1,10.61,200,2,11.27,100,1,11.4,100,1,11.76,100,1,11.93,200,2,12.1,100,1,12.2,200,2,12.33,100,1,13.66,15,1,13.98,2,1,14.24,100,1,14.48,700,1,14.53,100,1,14.54,700,1,14.56,700,1,14.57,200,2,14.6,100,1,14.68,700,1,ARL,339224109
